Workbook

Sheet Read_Me
B1: WDFW Coastal Razor Clam: Consolidated Ingress / Egress (Egress Survey) Data
B2: Compiled 09 July 2026 from every ingress/egress source located in the project file set plus the uploaded Access database Razor_Clam_Ingress.accdb. Every number in this workbook is traceable to a named file and sheet; nothing is estimated except where a sheet is explicitly labelled 'Reconstructed'.
B3: What an egress survey is
B4: Staff are posted at each beach access point from three hours before published low water until two hours after, counting cars on and cars off in 15 minute intervals. The cumulative difference (cars on minus cars off) is the number of cars on the beach at any instant. Dividing that by the total cars on for the whole window gives the '% available for beach count' curve. That curve is the expansion table used to derive the correction factor applied to the roving beach count.
B5: Sheets
B6: File_Manifest ...... every file examined, its content hash, its role, and whether it is a duplicate.
B7: Survey_Inventory ... one row per survey record (44 records covering 27 distinct surveys: 6 Long Beach, 7 Twin Harbors, 6 Copalis, 8 Mocrocks, 0 Kalaloch). Filter use_for_pooling = Yes for a clean, non-duplicated set.
B8: Coverage ........... surveys per beach per year, and per beach per condition. Shows the 2012-2021 blackout and the total absence of Kalaloch.
B9: Survey_Counts ...... the raw 15-minute cars-on / cars-off counts in long format, with live formulas for cumulative counts, cars on beach, and % available.
B10: Pct_Available_Matrix the % available curve for every survey, bins down the rows, surveys across the columns.
B11: Published_Tables ... the eight dated evening expansion tables and the five Master_Tables reference tables, as published.
B12: Table_Provenance ... which surveys compose each published and reference table, and the verification result. All thirteen reproduce exactly from the surveys named.
... B28: This workbook does not re-derive the operational correction factors and does not touch the harvest database. It is a source-of-truth compilation.

Sheet File_Manifest
A1: File | B1: Type | C1: Role | D1: md5 (12) | E1: Size (bytes) | F1: Notes / duplicate of
A2: Razor_Clam_Ingress.accdb | B2: Access database | C2: Primary | D2: ed2fb9d05693 | E2: 2490368 | F2: 20 egress events, 2004-2011, all five beaches in the lookup but Kalaloch has none. Tables: Event Data, Cars On, Cars Off, LUT Beach Name, LUT Sampler. [uploaded]
A3: Ingress_form_April_2004.xlsx | B3: Survey workbook | C3: Primary | D3: 5d010e744dda | E3: 47552 | F3: Five surveys, April 2004: Longbeach South (Seaview), Longbeach North (Oysterville), Twin Harbors, Copalis, Mocrocks. Also blank per-approach field sheets.
A4: EGRESS_MASTER.xlsx | B4: Survey workbook | C4: Duplicate | D4: 54d768612b25 | E4: 53172 | F4: Survey sheets are cell-for-cell identical to Ingress_form_April_2004.xlsx. Adds derived 'Copalis Table' and 'Mocrocks Table'. [= Ingress_form_April_2004.xlsx]
A5: Ingress_form_Nov_2006.xls | B5: Survey workbook | C5: Primary | D5: 11c973a04648 | E5: 38912 | F5: Mocrocks, 04-Nov-2006, evening, poor weather.
A6: 20061104Mockrocks.xls | B6: Survey workbook | C6: Duplicate | D6: 11c973a04648 | E6: 38912 | F6: Byte-identical to Ingress_form_Nov_2006.xls. [md5 11c973a04648]
A7: Ingress_form_November_13_2008.xls | B7: Survey workbook | C7: Primary | D7: 9844d0b89276 | E7: 59392 | F7: Copalis and Mocrocks, 13-Nov-2008, evening (low water 1h44m after sunset).
A8: 2008113MocrocksCopalis.xls | B8: Survey workbook | C8: Duplicate | D8: 9f00d5673476 | E8: 59392 | F8: Cell-for-cell identical to Ingress_form_November_13_2008.xls (different byte stream).
A9: Ingress__Copalis__April_02_2022.xlsx | B9: Survey workbook | C9: Primary | D9: 895dde5a36d9 | E9: 27388 | F9: Copalis, Ocean City North approach, 02-Apr-2022.
A10: Ingress__Mocrocks__April_03_2022.xlsx | B10: Survey workbook | C10: Primary | D10: e2d351b1ab45 | E10: 24952 | F10: Mocrocks, Roosevelt App. South, 03-Apr-2022.
A11: Ingress__Copalis__April_24_2023.xlsx | B11: Survey workbook | C11: Primary | D11: 354335c3c28e | E11: 26209 | F11: Copalis, Ocean City North approach, 24-Apr-2023.
A12: Ingress__Mocrocks__April_25_2023.xlsx | B12: Survey workbook | C12: Primary | D12: e90675cd713a | E12: 24969 | F12: Mocrocks, Roosevelt App. South, 25-Apr-2023.
A13: lb98s.xlsx | B13: Legacy summary | C13: Primary | D13: c8448a873688 | E13: 11162 | F13: Long Beach, Oysterville NORTH ONLY, 27-Mar-1998. Quattro Pro conversion.
... A36: AM_vs_PM_tides.xls | B36: Not ingress data | C36: Excluded | D36: 729488f4fa58 | E36: 14848 | F36: Days open on AM vs PM tides by season, 1998-2002. No car counts.

Sheet Survey_Inventory
A1: survey_key | B1: beach | C1: approach / sub-beach | D1: date | E1: day | F1: condition | G1: tide_time | H1: tide_ft | I1: sampler(s) | J1: weather | K1: wind | L1: surf | M1: window_first_bin | N1: window_last_bin | O1: n_bins | P1: total_cars_on | Q1: total_cars_off | R1: cars_left_in_area | S1: implied_discrepancy | T1: peak_pct_available | U1: peak_bin | V1: use_for_pooling | W1: reason_excluded | X1: source_type | Y1: source_file | Z1: source_sheet | AA1: notes | AB1: qc_flag
A2: DB-18 | B2: Copalis | C2: (not recorded) | D2: 38100 | E2: Friday | F2: Daylight | G2: 09:43 | H2: -0.3 | I2: Terry Wilson | J2: Overcast, with showers | K2: SW, 5 - 15 | L2: Low+ | M2: Prior to start | N2: 1:00 - 1:15 | O2: 18 | P2: 374 | Q2: 368 | R2: 12 | S2: =P2-Q2-R2 -> -6 | T2: 0.54545455 | U2: 1:15 - 1:00 | V2: No | W2: Superseded by WB-COP-2004-04-23 (same survey, primary source) | X2: Access DB | Y2: Razor_Clam_Ingress.accdb | Z2: Event Data ID=18
A3: WB-COP-2004-04-23 | B3: Copalis | C3: Ocean City Approach | D3: 38100 | E3: Friday | F3: Daylight | G3: 09:43 | H3: -0.3 | I3: T. Wilson | J3: Overcast with showers | K3: SW 5-15 mph | L3: Low+ | M3: Prior to start | N3: 1:00 - 1:15 | O3: 18 | P3: 374 | Q3: 368 | R3: 12 | S3: =P3-Q3-R3 -> -6 | T3: 0.54545455 | U3: 1:15 - 1:00 | V3: Yes | X3: Survey workbook | Y3: Ingress_form_April_2004.xlsx (=EGRESS_MASTER.xlsx) | Z3: Copalis
A4: DB-17 | B4: Copalis | C4: (not recorded) | D4: 39765 | E4: Thursday | F4: Evening | G4: 18:27 | H4: -1.6 | I4: Clayton Parson | J4: Clear skies, no rain | K4: SW, 0 - 5 | L4: High | M4: Prior to start | N4: 0:45 - 1:00 | O4: 17 | P4: 231 | Q4: 223 | R4: 10 | S4: =P4-Q4-R4 -> -2 | T4: 0.35064935 | U4: 2:00 - 1:45 | V4: No | W4: Superseded by WB-COP-2008-11-13 (same survey, primary source) | X4: Access DB | Y4: Razor_Clam_Ingress.accdb | Z4: Event Data ID=17
A5: WB-COP-2008-11-13 | B5: Copalis | C5: Ocean City Approach | D5: 39765 | E5: Thursday | F5: Evening | G5: 18:27 | H5: -1.6 | I5: C. Parson | J5: Clear skies, no rain. Sunset 4:43 PM | K5: SW 0-5 mph | L5: High | M5: Prior to start | N5: 0:45 - 1:00 | O5: 17 | P5: 231 | Q5: 223 | R5: 10 | S5: =P5-Q5-R5 -> -2 | T5: 0.35064935 | U5: 2:00 - 1:45 | V5: Yes | X5: Survey workbook | Y5: Ingress_form_November_13_2008.xls (=2008113MocrocksCopalis.xls) | Z5: Copalis
A6: DB-20 | B6: Copalis | C6: (not recorded) | D6: 40459 | E6: Friday | F6: Evening | G6: 19:42 | H6: -1.4 | I6: John Deibert | J6: Overcast with occasional sunbreaks | K6: S, 5 - 15 | L6: Moderate, 6 - 8 ft. | M6: Prior to start | N6: 0:45 - 1:00 | O6: 19 | P6: 486 | Q6: 447 | R6: 57 | S6: =P6-Q6-R6 -> -18 | T6: 0.57407407 | U6: 1:45 - 1:30 | V6: Yes | X6: Access DB | Y6: Razor_Clam_Ingress.accdb | Z6: Event Data ID=20
A7: DB-19 | B7: Copalis | C7: (not recorded) | D7: 40655 | E7: Friday | F7: Daylight | G7: 10:33 | H7: -0.8 | I7: Travis Haring | M7: Prior to start | N7: 0:45 - 1:00 | O7: 17 | P7: 393 | Q7: 336 | R7: 60 | S7: =P7-Q7-R7 -> -3 | T7: 0.66157761 | U7: 1:00 - 0:45 | V7: Yes | X7: Access DB | Y7: Razor_Clam_Ingress.accdb | Z7: Event Data ID=19
A8: WB-COP-2022-04-02 | B8: Copalis | C8: Ocean City North | D8: 44653 | E8: Saturday | F8: Daylight | G8: 08:07 | H8: 0 | I8: Blumenthal | J8: Sunrise 6:51 AM | M8: Prior to start | N8: 0:45 - 1:00 | O8: 17 | P8: 426 | Q8: 301 | R8: 132 | S8: =P8-Q8-R8 -> -7 | T8: 0.68779343 | U8: 0:45 - 0:30 | V8: Yes | X8: Survey workbook | Y8: Ingress__Copalis__April_02_2022.xlsx | Z8: Calculation Sheet
A9: WB-COP-2023-04-24 | B9: Copalis | C9: Ocean City North | D9: 45040 | E9: Monday | F9: Daylight | G9: 10:14 | H9: -0.4 | I9: BB / TZ / CF | J9: Sunrise 6:13 AM | M9: Prior to start | N9: 0:45 - 1:00 | O9: 17 | P9: 212 | Q9: 171 | R9: 51 | S9: =P9-Q9-R9 -> -10 | T9: 0.81132075 | U9: 0:45 - 0:30 | V9: Yes | X9: Survey workbook | Y9: Ingress__Copalis__April_24_2023.xlsx | Z9: Calculation Sheet
A10: WB-LB-1990-05-11 | B10: Longbeach | C10: Oysterville approach, NORTH ONLY | D10: 33004 | E10: Friday | F10: Evening | G10: 17:57 | H10: -0.2 | M10: Prior to start | N10: 1:30 - 1:45 | O10: 19 | P10: 2344 | Q10: 2258 | R10: 93 | S10: =P10-Q10-R10 -> -7 | T10: 0.76663823 | U10: 0:45 - 0:30 | V10: No | W10: Counts identical to WB-LB-1998-03-27; date conflict unresolved | X10: Survey workbook (legacy) | Y10: 19900511longbeachnorthonly.xlsx | Z10: Sheet1 | AA10: Counts are identical to lb98s.xlsx (27-MAR-1998). One of the two dates is wrong. DO NOT POOL BOTH. | AB10: Counts byte-identical to lb98s.xlsx (27-MAR-1998). Exactly one of the two dates is correct.
A11: WB-LB-1998-03-27 | B11: Longbeach | C11: Oysterville approach, NORTH ONLY | D11: 35881 | E11: Friday | F11: Evening | G11: 17:57 | H11: -0.2 | J11: Mod-high surf; showers; partly cloudy; SW wind 0-5 mph; cold | K11: SW 0-5 mph | L11: Mod-high | M11: Prior to start | N11: 1:30 - 1:45 | O11: 19 | P11: 2344 | Q11: 2258 | R11: 93 | S11: =P11-Q11-R11 -> -7 | T11: 0.76663823 | U11: 0:45 - 0:30 | V11: Yes | X11: Survey workbook (legacy) | Y11: lb98s.xlsx | Z11: Sheet1 | AA11: Majority of effort was north of the Oysterville approach this season. Byte-identical counts appear in 19900511longbeachnorthonly.xlsx dated 11-MAY-90. | AB11: '% avail' in source divides by accumulated cars-on at the 0:45-1:00 row (2333), not the window total (2344).
A12: DB-08 | B12: Longbeach | C12: (not recorded) | D12: 38099 | E12: Thursday | F12: Daylight | G12: 09:06 | H12: -0.5 | I12: Polo Sanchez | M12: Prior to start | N12: 0:45 - 1:00 | O12: 17 | P12: 929 | Q12: 865 | R12: 62 | S12: =P12-Q12-R12 -> 2 | T12: 0.5780409 | U12: 1:30 - 1:15 | V12: No | W12: Superseded by WB-LB-2004-04-22 (same survey, primary source) | X12: Access DB | Y12: Razor_Clam_Ingress.accdb | Z12: Event Data ID=8
A13: WB-LB-2004-04-22 | B13: Longbeach | C13: Oysterville Approach, north to Leadbetter Point | D13: 38099 | E13: Thursday | F13: Daylight | G13: 09:06 | H13: -0.5 | I13: Sanchez | M13: Prior to start | N13: 0:45 - 1:00 | O13: 17 | P13: 929 | Q13: 865 | R13: 62 | S13: =P13-Q13-R13 -> 2 | T13: 0.5780409 | U13: 1:30 - 1:15 | V13: Yes | X13: Survey workbook | Y13: Ingress_form_April_2004.xlsx (=EGRESS_MASTER.xlsx) | Z13: Longbeach - North
A14: DB-06 | B14: Longbeach | C14: (not recorded) | D14: 38100 | E14: Friday | F14: Daylight | G14: 09:43 | H14: -0.3 | I14: John Deibert | M14: Prior to start | N14: 1:30 - 1:45 | O14: 21 | P14: 85 | Q14: 79 | R14: 3 | S14: =P14-Q14-R14 -> 3 | T14: 0.37647059 | U14: 0:45 - 0:30 | V14: No | W14: Superseded by WB-LB-2004-04-23 (same survey, primary source) | X14: Access DB | Y14: Razor_Clam_Ingress.accdb | Z14: Event Data ID=6 | AB14: Prior-to-start value (3) entered twice: once in 'Prior to start' and once in '3:15 - 3:00'. Inflates total cars-on 82 -> 85 (+3.7%).
A15: WB-LB-2004-04-23 | B15: Longbeach | C15: Seaview Approach, south to Beard's Hollow | D15: 38100 | E15: Friday | F15: Daylight | G15: 09:43 | H15: -0.3 | I15: Deibert | M15: Prior to start | N15: 1:30 - 1:45 | O15: 20 | P15: 82 | Q15: 79 | R15: 3 | S15: =P15-Q15-R15 -> 0 | T15: 0.35365854 | U15: 0:45 - 0:30 | V15: Yes | X15: Survey workbook | Y15: Ingress_form_April_2004.xlsx (=EGRESS_MASTER.xlsx) | Z15: Longbeach - South
A16: DB-09 | B16: Longbeach | C16: (not recorded) | D16: 39823 | E16: Saturday | F16: Evening | G16: 17:58 | H16: -1.1 | I16: Alan Sarich | J16: Light to Heavy rain | K16: S, 5 mph increasing to 30 mph by 7:00 pm | M16: Prior to start | N16: 1:00 - 1:15 | O16: 20 | P16: 972 | Q16: 956 | R16: 14 | S16: =P16-Q16-R16 -> 2 | T16: 0.74794239 | U16: 1:45 - 1:30 | V16: Yes | X16: Access DB | Y16: Razor_Clam_Ingress.accdb | Z16: Event Data ID=9
A17: DB-07 | B17: Longbeach | C17: (not recorded) | D17: 40564 | E17: Friday | F17: Evening | G17: 19:38 | H17: -1.1 | I17: John Deibert | J17: Overcast, Occasional drizzle | K17: S, 0 - 5 | L17: Moderate | M17: Prior to start | N17: 0:45 - 1:00 | O17: 19 | P17: 280 | Q17: 261 | R17: 25 | S17: =P17-Q17-R17 -> -6 | T17: 0.61785714 | U17: 1:30 - 1:15 | V17: Yes | X17: Access DB | Y17: Razor_Clam_Ingress.accdb | Z17: Event Data ID=7
A18: DB-10 | B18: Longbeach | C18: (not recorded) | D18: 40652 | E18: Tuesday | F18: Daylight | G18: 08:07 | H18: -1.8 | I18: John Deibert | J18: Partly cloudy with occasional showers | K18: 5 - 15 | L18: Low | M18: Prior to start | N18: 0:45 - 1:00 | O18: 19 | P18: 503 | Q18: 492 | R18: 13 | S18: =P18-Q18-R18 -> -2 | T18: 0.57057654 | U18: 1:15 - 1:00 | V18: Yes | X18: Access DB | Y18: Razor_Clam_Ingress.accdb | Z18: Event Data ID=10
A19: WB-MOC-1998-04-01 | B19: Mocrocks | C19: Moclips + Trestle + Roosevelt (3 approaches combined) | D19: 35886 | E19: Wednesday | F19: Daylight | G19: 08:42 (header) / 09:39 implied by bins | H19: -0.5 | J19: Low-mod surf; clear, no wind | K19: None | L19: Low-mod | M19: Prior to start | N19: 1:00 - 1:15 | O19: 14 | P19: 1732 | Q19: 1417 | R19: 303 | S19: =P19-Q19-R19 -> 12 | T19: 0.70842956 | U19: 1:00 - 0:45 | V19: Yes | X19: Survey workbook (legacy) | Y19: moc98s.xlsx | Z19: summary | AA19: Header tide time (0842) is inconsistent with the actual-time bins, which imply low water at 0939. Avg catch 14.4; 2.31 people/car. THIS SURVEY IS THE SOURCE OF THE 'KALALOCH' TABLE. | AB19: Header tide time 0842 is inconsistent with the bin labels, which imply low water ~0939. THIS SURVEY IS THE SOLE SOURCE OF THE 'KALALOCH DAYLIGHT TABLE'.
A20: WB-MOC-1998-04-01-MOCLIPS | B20: Mocrocks | C20: MOCLIPS | D20: 35886 | E20: Wednesday | F20: Daylight | G20: 08:42 | H20: -0.5 | M20: Prior to start | N20: 0:30 - 0:45 | O20: 12 | P20: 74 | Q20: 67 | S20: =P20-Q20-R20 -> 7 | T20: 0.59459459 | U20: 0:45 - 0:30 | V20: No | W20: Component approach of the same-day summary survey | X20: Survey workbook (legacy, per-approach) | Y20: moc98s.xlsx | Z20: MOCLIPS | AA20: Component approach of the same-day summary survey. Do not pool with the summary. | AB20: Prior-to-start cars-on under-recorded on the approach sheets; 15-minute bins reconcile exactly to the summary. On-beach goes negative in some bins.
A21: WB-MOC-1998-04-01-ROOSEVELT | B21: Mocrocks | C21: ROOSEVELT | D21: 35886 | E21: Wednesday | F21: Daylight | G21: 08:42 | H21: -0.5 | M21: Prior to start | N21: 0:45 - 1:00 | O21: 13 | P21: 909 | Q21: 1089 | S21: =P21-Q21-R21 -> -180 | T21: 0.60176018 | U21: 1:15 - 1:00 | V21: No | W21: Component approach of the same-day summary survey | X21: Survey workbook (legacy, per-approach) | Y21: moc98s.xlsx | Z21: ROOSEVELT | AA21: Component approach of the same-day summary survey. Do not pool with the summary. | AB21: Prior-to-start cars-on under-recorded on the approach sheets; 15-minute bins reconcile exactly to the summary. On-beach goes negative in some bins.
A22: WB-MOC-1998-04-01-TRESTLE | B22: Mocrocks | C22: TRESTLE | D22: 35886 | E22: Wednesday | F22: Daylight | G22: 08:42 | H22: -0.5 | M22: Prior to start | N22: 0:45 - 1:00 | O22: 13 | P22: 262 | Q22: 261 | S22: =P22-Q22-R22 -> 1 | T22: 0.58396947 | U22: 1:00 - 0:45 | V22: No | W22: Component approach of the same-day summary survey | X22: Survey workbook (legacy, per-approach) | Y22: moc98s.xlsx | Z22: TRESTLE | AA22: Component approach of the same-day summary survey. Do not pool with the summary. | AB22: Prior-to-start cars-on under-recorded on the approach sheets; 15-minute bins reconcile exactly to the summary. On-beach goes negative in some bins.
A23: DB-01 | B23: Mocrocks | C23: (not recorded) | D23: 38101 | E23: Saturday | F23: Daylight | G23: 10:22 | H23: 0 | J23: Clear skies and sunny. Cold early but very warm later. | K23: West. 0 - 5 | L23: Low. 4 ft. | M23: 3:15 - 3:00 | N23: 0:45 - 1:00 | O23: 17 | P23: 707 | Q23: 562 | R23: 137 | S23: =P23-Q23-R23 -> 8 | T23: 0.62942008 | U23: 1:30 - 1:15 | V23: No | W23: Superseded by WB-MOC-2004-04-24 (same survey, primary source) | X23: Access DB | Y23: Razor_Clam_Ingress.accdb | Z23: Event Data ID=1 | AA23: Stopped the count because most people left were no longer clam digging. They were staying on the beach having picnics and flying kites. | AB23: Prior-to-start (39 cars on) stored in the '3:15 - 3:00' column. Workbook is authoritative.
A24: WB-MOC-2004-04-24 | B24: Mocrocks | C24: Roosevelt Beach Approach | D24: 38101 | E24: Saturday | F24: Daylight | G24: 10:22 | H24: 0 | I24: J. Deibert | J24: Clear, sunny; cold early, warm later | K24: W 0-5 mph | L24: Low, ~4 ft | M24: Prior to start | N24: 0:45 - 1:00 | O24: 17 | P24: 707 | Q24: 562 | R24: 137 | S24: =P24-Q24-R24 -> 8 | T24: 0.62942008 | U24: 1:30 - 1:15 | V24: Yes | X24: Survey workbook | Y24: Ingress_form_April_2004.xlsx (=EGRESS_MASTER.xlsx) | Z24: Mocrocks | AA24: Count stopped early: remaining people were picnicking / kite flying, not digging.
A25: DB-02 | B25: Mocrocks | C25: (not recorded) | D25: 39025 | E25: Saturday | F25: Evening | G25: 17:23 | H25: -1.1 | J25: Rain hard at times. Break in weather at 2:37 pm. Partly cloudy | K25: SW 5 - 20 | L25: High | M25: 3:15 - 3:00 | N25: 0:45 - 1:00 | O25: 17 | P25: 259 | Q25: 251 | R25: 21 | S25: =P25-Q25-R25 -> -13 | T25: 0.71428571 | U25: 1:15 - 1:00 | V25: No | W25: Superseded by WB-MOC-2006-11-04 (same survey, primary source) | X25: Access DB | Y25: Razor_Clam_Ingress.accdb | Z25: Event Data ID=2 | AB25: Prior-to-start (11 cars on) stored in the '3:15 - 3:00' column. Workbook is authoritative.
A26: WB-MOC-2006-11-04 | B26: Mocrocks | C26: Roosevelt Beach Approach | D26: 39025 | E26: Saturday | F26: Evening | G26: 17:23 | H26: -1.1 | I26: L. Wargo | J26: Windy, rain hard at times; break at 2:37 PM, partly cloudy. Sunset 4:56 PM | K26: SW 5-20 mph | L26: High | M26: Prior to start | N26: 0:45 - 1:00 | O26: 17 | P26: 259 | Q26: 251 | R26: 21 | S26: =P26-Q26-R26 -> -13 | T26: 0.71428571 | U26: 1:15 - 1:00 | V26: Yes | X26: Survey workbook | Y26: Ingress_form_Nov_2006.xls (=20061104Mockrocks.xls) | Z26: Mocrocks | AA26: Rain resumed 4:23-4:38 PM; dark near 5:30 PM.
A27: DB-03 | B27: Mocrocks | C27: (not recorded) | D27: 39765 | E27: Thursday | F27: Evening | G27: 18:27 | H27: -1.6 | J27: Clear skies, no rain | K27: SW, 0 - 5 | L27: High | M27: 3:15 - 3:00 | N27: 0:15 - 0:30 | O27: 15 | P27: 194 | Q27: 162 | R27: 30 | S27: =P27-Q27-R27 -> 2 | T27: 0.58247423 | U27: 1:45 - 1:30 | V27: No | W27: Superseded by WB-MOC-2008-11-13 (same survey, primary source) | X27: Access DB | Y27: Razor_Clam_Ingress.accdb | Z27: Event Data ID=3 | AB27: Prior-to-start (27 cars on) stored in the '3:15 - 3:00' column. Workbook is authoritative.
A28: WB-MOC-2008-11-13 | B28: Mocrocks | C28: Roosevelt Approach, south to Copalis River | D28: 39765 | E28: Thursday | F28: Evening | G28: 18:27 | H28: -1.6 | I28: J. Beck | J28: Clear skies, no rain. Sunset 4:43 PM | K28: SW 0-5 mph | L28: High | M28: Prior to start | N28: 0:15 - 0:30 | O28: 15 | P28: 194 | Q28: 162 | R28: 30 | S28: =P28-Q28-R28 -> 2 | T28: 0.58247423 | U28: 1:45 - 1:30 | V28: Yes | X28: Survey workbook | Y28: Ingress_form_November_13_2008.xls (=2008113MocrocksCopalis.xls) | Z28: Mocrocks
A29: DB-04 | B29: Mocrocks | C29: (not recorded) | D29: 40460 | E29: Saturday | F29: Evening | G29: 20:28 | H29: -1.5 | J29: Stormy, Rain light to moderate, Heavy at times. | K29: SW, 15 - 30 | L29: High | M29: 3:15 - 3:00 | N29: 0:30 - 0:45 | O29: 16 | P29: 190 | Q29: 177 | R29: 13 | S29: =P29-Q29-R29 -> 0 | T29: 0.66842105 | U29: 2:00 - 1:45 | V29: Yes | X29: Access DB | Y29: Razor_Clam_Ingress.accdb | Z29: Event Data ID=4 | AB29: '3:15 - 3:00' cell holds Prior-to-start + 3:30-3:15 + 3:15-3:00 collapsed (on 55 = 25+15+15; off 8 = 1+3+4). True split recovered from the 03-Nov-2010 published table; see Reconstructed_Surveys.
A30: DB-05 | B30: Mocrocks | C30: (not recorded) | D30: 40654 | E30: Thursday | F30: Daylight | G30: 09:43 | H30: -1.4 | M30: 3:15 - 3:00 | N30: 0:45 - 1:00 | O30: 17 | P30: 185 | Q30: 173 | R30: 33 | S30: =P30-Q30-R30 -> -21 | T30: 0.64864865 | U30: 1:15 - 1:00 | V30: Yes | X30: Access DB | Y30: Razor_Clam_Ingress.accdb | Z30: Event Data ID=5 | AB30: Prior-to-start (6 cars on) stored in '3:15 - 3:00'. ALSO: cars-on at '1:00 - 0:45' is 3; independent evidence (Ingress.Egress.review.xls) implies 23. Total on would be 205, not 185.
A31: WB-MOC-2022-04-03 | B31: Mocrocks | C31: Roosevelt App. South | D31: 44654 | E31: Sunday | F31: Daylight | G31: 08:45 | H31: -0.1 | I31: Parson | J31: Sunrise 6:49 AM | M31: Prior to start | N31: 0:45 - 1:00 | O31: 17 | P31: 239 | Q31: 198 | R31: 43 | S31: =P31-Q31-R31 -> -2 | T31: 0.65690377 | U31: 0:45 - 0:30 | V31: Yes | X31: Survey workbook | Y31: Ingress__Mocrocks__April_03_2022.xlsx | Z31: Calculation Sheet
A32: WB-MOC-2023-04-25 | B32: Mocrocks | C32: Roosevelt App. South | D32: 45041 | E32: Tuesday | F32: Daylight | G32: 11:01 | H32: 0.1 | I32: Janna Goulding | J32: Sunny, Low+ surf, N wind 0-5 mph. Sunrise 6:11 AM | M32: Prior to start | N32: 0:45 - 1:00 | O32: 17 | P32: 219 | Q32: 188 | R32: 34 | S32: =P32-Q32-R32 -> -3 | T32: 0.73515982 | U32: 1:00 - 0:45 | V32: Yes | X32: Survey workbook | Y32: Ingress__Mocrocks__April_25_2023.xlsx | Z32: Calculation Sheet
A33: WB-TH-1998-03-31 | B33: Twin Harbors | C33: Bonge + Grayland + County Line + Midway + North Cove (5 approaches combined) | D33: 35885 | E33: Tuesday | F33: Daylight | G33: 08:48 (header) / 09:03 implied by bins | H33: -0.9 | J33: Low-mod surf; clear, W wind 0-5 mph | K33: W 0-5 mph | L33: Low-mod | M33: Prior to start | N33: 1:00 - 1:15 | O33: 14 | P33: 2133 | Q33: 1844 | R33: 288 | S33: =P33-Q33-R33 -> 1 | T33: 0.61837787 | U33: 1:15 - 1:00 | V33: Yes | X33: Survey workbook (legacy) | Y33: th98s.xlsx | Z33: summary | AA33: Avg catch 12.8; 2.26 people/car. | AB33: '% avail' in source divides by 2130, not the window total 2133. Header tide time 0848 is inconsistent with the bin labels (imply low water ~0903).
A34: WB-TH-1998-03-31-BONGE | B34: Twin Harbors | C34: BONGE | D34: 35885 | E34: Tuesday | F34: Daylight | G34: 08:48 | H34: -0.9 | M34: Prior to start | N34: 1:00 - 1:15 | O34: 14 | P34: 47 | Q34: 36 | S34: =P34-Q34-R34 -> 11 | T34: 0.53191489 | U34: 0:30 - 0:15 | V34: No | W34: Component approach of the same-day summary survey | X34: Survey workbook (legacy, per-approach) | Y34: th98s.xlsx | Z34: bonge | AA34: Component approach of the same-day summary survey. Do not pool with the summary. | AB34: Prior-to-start cars-on under-recorded on the approach sheets; 15-minute bins reconcile exactly to the summary. On-beach goes negative in some bins.
A35: WB-TH-1998-03-31-COUNTY_LINE | B35: Twin Harbors | C35: COUNTY LINE | D35: 35885 | E35: Tuesday | F35: Daylight | G35: 08:48 | H35: -0.9 | M35: Prior to start | N35: 1:00 - 1:15 | O35: 14 | P35: 402 | Q35: 460 | S35: =P35-Q35-R35 -> -58 | T35: 0.67164179 | U35: 1:15 - 1:00 | V35: No | W35: Component approach of the same-day summary survey | X35: Survey workbook (legacy, per-approach) | Y35: th98s.xlsx | Z35: county line | AA35: Component approach of the same-day summary survey. Do not pool with the summary. | AB35: Prior-to-start cars-on under-recorded on the approach sheets; 15-minute bins reconcile exactly to the summary. On-beach goes negative in some bins.
A36: WB-TH-1998-03-31-GRAYLAND | B36: Twin Harbors | C36: GRAYLAND | D36: 35885 | E36: Tuesday | F36: Daylight | G36: 08:48 | H36: -0.9 | M36: Prior to start | N36: 1:00 - 1:15 | O36: 14 | P36: 306 | Q36: 264 | S36: =P36-Q36-R36 -> 42 | T36: 0.69281046 | U36: 0:45 - 0:30 | V36: No | W36: Component approach of the same-day summary survey | X36: Survey workbook (legacy, per-approach) | Y36: th98s.xlsx | Z36: grayland | AA36: Component approach of the same-day summary survey. Do not pool with the summary. | AB36: Prior-to-start cars-on under-recorded on the approach sheets; 15-minute bins reconcile exactly to the summary. On-beach goes negative in some bins.
A37: WB-TH-1998-03-31-MIDWAY | B37: Twin Harbors | C37: MIDWAY | D37: 35885 | E37: Tuesday | F37: Daylight | G37: 08:48 | H37: -0.9 | M37: Prior to start | N37: 1:00 - 1:15 | O37: 14 | P37: 594 | Q37: 710 | S37: =P37-Q37-R37 -> -116 | T37: 0.46464646 | U37: 1:15 - 1:00 | V37: No | W37: Component approach of the same-day summary survey | X37: Survey workbook (legacy, per-approach) | Y37: th98s.xlsx | Z37: midway | AA37: Component approach of the same-day summary survey. Do not pool with the summary. | AB37: Prior-to-start cars-on under-recorded on the approach sheets; 15-minute bins reconcile exactly to the summary. On-beach goes negative in some bins.
A38: WB-TH-1998-03-31-NORTH_COVE | B38: Twin Harbors | C38: NORTH COVE | D38: 35885 | E38: Tuesday | F38: Daylight | G38: 08:48 | H38: -0.9 | M38: Prior to start | N38: 1:00 - 1:15 | O38: 14 | P38: 358 | Q38: 372 | S38: =P38-Q38-R38 -> -14 | T38: 0.46089385 | U38: 1:00 - 0:45 | V38: No | W38: Component approach of the same-day summary survey | X38: Survey workbook (legacy, per-approach) | Y38: th98s.xlsx | Z38: north cove | AA38: Component approach of the same-day summary survey. Do not pool with the summary. | AB38: Prior-to-start cars-on under-recorded on the approach sheets; 15-minute bins reconcile exactly to the summary. On-beach goes negative in some bins.
A39: DB-12 | B39: Twin Harbors | C39: (not recorded) | D39: 38098 | E39: Wednesday | F39: Daylight | G39: 08:30 | H39: -0.6 | I39: John Deibert | M39: Prior to start | N39: 1:45 - 2:00 | O39: 21 | P39: 435 | Q39: 413 | R39: 25 | S39: =P39-Q39-R39 -> -3 | T39: 0.62298851 | U39: 0:45 - 0:30 | V39: No | W39: Superseded by WB-TH-2004-04-21 (same survey, primary source) | X39: Access DB | Y39: Razor_Clam_Ingress.accdb | Z39: Event Data ID=12 | AA39: This Ingress / Egress was completed by John Deibert and Dan Ayres. Each counted a different approach and combined their numbers to get the final count.
A40: WB-TH-2004-04-21 | B40: Twin Harbors | C40: Grayland + Bonge (two approaches combined) | D40: 38098 | E40: Wednesday | F40: Daylight | G40: 08:30 | H40: -0.6 | I40: Deibert, Ayres | M40: Prior to start | N40: 1:45 - 2:00 | O40: 21 | P40: 435 | Q40: 413 | R40: 25 | S40: =P40-Q40-R40 -> -3 | T40: 0.62298851 | U40: 0:45 - 0:30 | V40: Yes | X40: Survey workbook | Y40: Ingress_form_April_2004.xlsx (=EGRESS_MASTER.xlsx) | Z40: Twin Harbors | AA40: Counted by two staff on different approaches; numbers combined.
...

Sheet Coverage
B1: Survey coverage (use_for_pooling = Yes only)
B2: Counts are live COUNTIFS over Survey_Inventory. Change the filter there and these update.
B4: A. Surveys per beach per year
B5: beach | C5: 1998 | D5: 2004 | E5: 2006 | F5: 2008 | G5: 2009 | H5: 2010 | I5: 2011 | J5: 2022 | K5: 2023 | L5: 2012-2021 | M5: TOTAL
B6: Longbeach | C6: =COUNTIFS(Survey_Inventory!$B$2:$B$45,$B6,Survey_Inventory!$V$2:$V$45,"Yes",Survey_Inventory!$D$2:$D$45,">="&DATE(1998,1,1),Survey_Inventory!$D$2:$D$45,"<="&DATE(1998,12,31)) -> 1 | D6: =COUNTIFS(Survey_Inventory!$B$2:$B$45,$B6,Survey_Inventory!$V$2:$V$45,"Yes",Survey_Inventory!$D$2:$D$45,">="&DATE(2004,1,1),Survey_Inventory!$D$2:$D$45,"<="&DATE(2004,12,31)) -> 2 | E6: =COUNTIFS(Survey_Inventory!$B$2:$B$45,$B6,Survey_Inventory!$V$2:$V$45,"Yes",Survey_Inventory!$D$2:$D$45,">="&DATE(2006,1,1),Survey_Inventory!$D$2:$D$45,"<="&DATE(2006,12,31)) -> 0 | F6: =COUNTIFS(Survey_Inventory!$B$2:$B$45,$B6,Survey_Inventory!$V$2:$V$45,"Yes",Survey_Inventory!$D$2:$D$45,">="&DATE(2008,1,1),Survey_Inventory!$D$2:$D$45,"<="&DATE(2008,12,31)) -> 0 | G6: =COUNTIFS(Survey_Inventory!$B$2:$B$45,$B6,Survey_Inventory!$V$2:$V$45,"Yes",Survey_Inventory!$D$2:$D$45,">="&DATE(2009,1,1),Survey_Inventory!$D$2:$D$45,"<="&DATE(2009,12,31)) -> 1 | H6: =COUNTIFS(Survey_Inventory!$B$2:$B$45,$B6,Survey_Inventory!$V$2:$V$45,"Yes",Survey_Inventory!$D$2:$D$45,">="&DATE(2010,1,1),Survey_Inventory!$D$2:$D$45,"<="&DATE(2010,12,31)) -> 0 | I6: =COUNTIFS(Survey_Inventory!$B$2:$B$45,$B6,Survey_Inventory!$V$2:$V$45,"Yes",Survey_Inventory!$D$2:$D$45,">="&DATE(2011,1,1),Survey_Inventory!$D$2:$D$45,"<="&DATE(2011,12,31)) -> 2 | J6: =COUNTIFS(Survey_Inventory!$B$2:$B$45,$B6,Survey_Inventory!$V$2:$V$45,"Yes",Survey_Inventory!$D$2:$D$45,">="&DATE(2022,1,1),Survey_Inventory!$D$2:$D$45,"<="&DATE(2022,12,31)) -> 0 | K6: =COUNTIFS(Survey_Inventory!$B$2:$B$45,$B6,Survey_Inventory!$V$2:$V$45,"Yes",Survey_Inventory!$D$2:$D$45,">="&DATE(2023,1,1),Survey_Inventory!$D$2:$D$45,"<="&DATE(2023,12,31)) -> 0 | L6: =COUNTIFS(Survey_Inventory!$B$2:$B$45,$B6,Survey_Inventory!$V$2:$V$45,"Yes",Survey_Inventory!$D$2:$D$45,">="&DATE(2012,1,1),Survey_Inventory!$D$2:$D$45,"<="&DATE(2021,12,31)) -> 0 | M6: =COUNTIFS(Survey_Inventory!$B$2:$B$45,$B6,Survey_Inventory!$V$2:$V$45,"Yes") -> 6
B7: Twin Harbors | C7: =COUNTIFS(Survey_Inventory!$B$2:$B$45,$B7,Survey_Inventory!$V$2:$V$45,"Yes",Survey_Inventory!$D$2:$D$45,">="&DATE(1998,1,1),Survey_Inventory!$D$2:$D$45,"<="&DATE(1998,12,31)) -> 1 | D7: =COUNTIFS(Survey_Inventory!$B$2:$B$45,$B7,Survey_Inventory!$V$2:$V$45,"Yes",Survey_Inventory!$D$2:$D$45,">="&DATE(2004,1,1),Survey_Inventory!$D$2:$D$45,"<="&DATE(2004,12,31)) -> 1 | E7: =COUNTIFS(Survey_Inventory!$B$2:$B$45,$B7,Survey_Inventory!$V$2:$V$45,"Yes",Survey_Inventory!$D$2:$D$45,">="&DATE(2006,1,1),Survey_Inventory!$D$2:$D$45,"<="&DATE(2006,12,31)) -> 0 | F7: =COUNTIFS(Survey_Inventory!$B$2:$B$45,$B7,Survey_Inventory!$V$2:$V$45,"Yes",Survey_Inventory!$D$2:$D$45,">="&DATE(2008,1,1),Survey_Inventory!$D$2:$D$45,"<="&DATE(2008,12,31)) -> 0 | G7: =COUNTIFS(Survey_Inventory!$B$2:$B$45,$B7,Survey_Inventory!$V$2:$V$45,"Yes",Survey_Inventory!$D$2:$D$45,">="&DATE(2009,1,1),Survey_Inventory!$D$2:$D$45,"<="&DATE(2009,12,31)) -> 0 | H7: =COUNTIFS(Survey_Inventory!$B$2:$B$45,$B7,Survey_Inventory!$V$2:$V$45,"Yes",Survey_Inventory!$D$2:$D$45,">="&DATE(2010,1,1),Survey_Inventory!$D$2:$D$45,"<="&DATE(2010,12,31)) -> 1 | I7: =COUNTIFS(Survey_Inventory!$B$2:$B$45,$B7,Survey_Inventory!$V$2:$V$45,"Yes",Survey_Inventory!$D$2:$D$45,">="&DATE(2011,1,1),Survey_Inventory!$D$2:$D$45,"<="&DATE(2011,12,31)) -> 4 | J7: =COUNTIFS(Survey_Inventory!$B$2:$B$45,$B7,Survey_Inventory!$V$2:$V$45,"Yes",Survey_Inventory!$D$2:$D$45,">="&DATE(2022,1,1),Survey_Inventory!$D$2:$D$45,"<="&DATE(2022,12,31)) -> 0 | K7: =COUNTIFS(Survey_Inventory!$B$2:$B$45,$B7,Survey_Inventory!$V$2:$V$45,"Yes",Survey_Inventory!$D$2:$D$45,">="&DATE(2023,1,1),Survey_Inventory!$D$2:$D$45,"<="&DATE(2023,12,31)) -> 0 | L7: =COUNTIFS(Survey_Inventory!$B$2:$B$45,$B7,Survey_Inventory!$V$2:$V$45,"Yes",Survey_Inventory!$D$2:$D$45,">="&DATE(2012,1,1),Survey_Inventory!$D$2:$D$45,"<="&DATE(2021,12,31)) -> 0 | M7: =COUNTIFS(Survey_Inventory!$B$2:$B$45,$B7,Survey_Inventory!$V$2:$V$45,"Yes") -> 7
B8: Copalis | C8: =COUNTIFS(Survey_Inventory!$B$2:$B$45,$B8,Survey_Inventory!$V$2:$V$45,"Yes",Survey_Inventory!$D$2:$D$45,">="&DATE(1998,1,1),Survey_Inventory!$D$2:$D$45,"<="&DATE(1998,12,31)) -> 0 | D8: =COUNTIFS(Survey_Inventory!$B$2:$B$45,$B8,Survey_Inventory!$V$2:$V$45,"Yes",Survey_Inventory!$D$2:$D$45,">="&DATE(2004,1,1),Survey_Inventory!$D$2:$D$45,"<="&DATE(2004,12,31)) -> 1 | E8: =COUNTIFS(Survey_Inventory!$B$2:$B$45,$B8,Survey_Inventory!$V$2:$V$45,"Yes",Survey_Inventory!$D$2:$D$45,">="&DATE(2006,1,1),Survey_Inventory!$D$2:$D$45,"<="&DATE(2006,12,31)) -> 0 | F8: =COUNTIFS(Survey_Inventory!$B$2:$B$45,$B8,Survey_Inventory!$V$2:$V$45,"Yes",Survey_Inventory!$D$2:$D$45,">="&DATE(2008,1,1),Survey_Inventory!$D$2:$D$45,"<="&DATE(2008,12,31)) -> 1 | G8: =COUNTIFS(Survey_Inventory!$B$2:$B$45,$B8,Survey_Inventory!$V$2:$V$45,"Yes",Survey_Inventory!$D$2:$D$45,">="&DATE(2009,1,1),Survey_Inventory!$D$2:$D$45,"<="&DATE(2009,12,31)) -> 0 | H8: =COUNTIFS(Survey_Inventory!$B$2:$B$45,$B8,Survey_Inventory!$V$2:$V$45,"Yes",Survey_Inventory!$D$2:$D$45,">="&DATE(2010,1,1),Survey_Inventory!$D$2:$D$45,"<="&DATE(2010,12,31)) -> 1 | I8: =COUNTIFS(Survey_Inventory!$B$2:$B$45,$B8,Survey_Inventory!$V$2:$V$45,"Yes",Survey_Inventory!$D$2:$D$45,">="&DATE(2011,1,1),Survey_Inventory!$D$2:$D$45,"<="&DATE(2011,12,31)) -> 1 | J8: =COUNTIFS(Survey_Inventory!$B$2:$B$45,$B8,Survey_Inventory!$V$2:$V$45,"Yes",Survey_Inventory!$D$2:$D$45,">="&DATE(2022,1,1),Survey_Inventory!$D$2:$D$45,"<="&DATE(2022,12,31)) -> 1 | K8: =COUNTIFS(Survey_Inventory!$B$2:$B$45,$B8,Survey_Inventory!$V$2:$V$45,"Yes",Survey_Inventory!$D$2:$D$45,">="&DATE(2023,1,1),Survey_Inventory!$D$2:$D$45,"<="&DATE(2023,12,31)) -> 1 | L8: =COUNTIFS(Survey_Inventory!$B$2:$B$45,$B8,Survey_Inventory!$V$2:$V$45,"Yes",Survey_Inventory!$D$2:$D$45,">="&DATE(2012,1,1),Survey_Inventory!$D$2:$D$45,"<="&DATE(2021,12,31)) -> 0 | M8: =COUNTIFS(Survey_Inventory!$B$2:$B$45,$B8,Survey_Inventory!$V$2:$V$45,"Yes") -> 6
B9: Mocrocks | C9: =COUNTIFS(Survey_Inventory!$B$2:$B$45,$B9,Survey_Inventory!$V$2:$V$45,"Yes",Survey_Inventory!$D$2:$D$45,">="&DATE(1998,1,1),Survey_Inventory!$D$2:$D$45,"<="&DATE(1998,12,31)) -> 1 | D9: =COUNTIFS(Survey_Inventory!$B$2:$B$45,$B9,Survey_Inventory!$V$2:$V$45,"Yes",Survey_Inventory!$D$2:$D$45,">="&DATE(2004,1,1),Survey_Inventory!$D$2:$D$45,"<="&DATE(2004,12,31)) -> 1 | E9: =COUNTIFS(Survey_Inventory!$B$2:$B$45,$B9,Survey_Inventory!$V$2:$V$45,"Yes",Survey_Inventory!$D$2:$D$45,">="&DATE(2006,1,1),Survey_Inventory!$D$2:$D$45,"<="&DATE(2006,12,31)) -> 1 | F9: =COUNTIFS(Survey_Inventory!$B$2:$B$45,$B9,Survey_Inventory!$V$2:$V$45,"Yes",Survey_Inventory!$D$2:$D$45,">="&DATE(2008,1,1),Survey_Inventory!$D$2:$D$45,"<="&DATE(2008,12,31)) -> 1 | G9: =COUNTIFS(Survey_Inventory!$B$2:$B$45,$B9,Survey_Inventory!$V$2:$V$45,"Yes",Survey_Inventory!$D$2:$D$45,">="&DATE(2009,1,1),Survey_Inventory!$D$2:$D$45,"<="&DATE(2009,12,31)) -> 0 | H9: =COUNTIFS(Survey_Inventory!$B$2:$B$45,$B9,Survey_Inventory!$V$2:$V$45,"Yes",Survey_Inventory!$D$2:$D$45,">="&DATE(2010,1,1),Survey_Inventory!$D$2:$D$45,"<="&DATE(2010,12,31)) -> 1 | I9: =COUNTIFS(Survey_Inventory!$B$2:$B$45,$B9,Survey_Inventory!$V$2:$V$45,"Yes",Survey_Inventory!$D$2:$D$45,">="&DATE(2011,1,1),Survey_Inventory!$D$2:$D$45,"<="&DATE(2011,12,31)) -> 1 | J9: =COUNTIFS(Survey_Inventory!$B$2:$B$45,$B9,Survey_Inventory!$V$2:$V$45,"Yes",Survey_Inventory!$D$2:$D$45,">="&DATE(2022,1,1),Survey_Inventory!$D$2:$D$45,"<="&DATE(2022,12,31)) -> 1 | K9: =COUNTIFS(Survey_Inventory!$B$2:$B$45,$B9,Survey_Inventory!$V$2:$V$45,"Yes",Survey_Inventory!$D$2:$D$45,">="&DATE(2023,1,1),Survey_Inventory!$D$2:$D$45,"<="&DATE(2023,12,31)) -> 1 | L9: =COUNTIFS(Survey_Inventory!$B$2:$B$45,$B9,Survey_Inventory!$V$2:$V$45,"Yes",Survey_Inventory!$D$2:$D$45,">="&DATE(2012,1,1),Survey_Inventory!$D$2:$D$45,"<="&DATE(2021,12,31)) -> 0 | M9: =COUNTIFS(Survey_Inventory!$B$2:$B$45,$B9,Survey_Inventory!$V$2:$V$45,"Yes") -> 8
B10: Kalaloch | C10: =COUNTIFS(Survey_Inventory!$B$2:$B$45,$B10,Survey_Inventory!$V$2:$V$45,"Yes",Survey_Inventory!$D$2:$D$45,">="&DATE(1998,1,1),Survey_Inventory!$D$2:$D$45,"<="&DATE(1998,12,31)) -> 0 | D10: =COUNTIFS(Survey_Inventory!$B$2:$B$45,$B10,Survey_Inventory!$V$2:$V$45,"Yes",Survey_Inventory!$D$2:$D$45,">="&DATE(2004,1,1),Survey_Inventory!$D$2:$D$45,"<="&DATE(2004,12,31)) -> 0 | E10: =COUNTIFS(Survey_Inventory!$B$2:$B$45,$B10,Survey_Inventory!$V$2:$V$45,"Yes",Survey_Inventory!$D$2:$D$45,">="&DATE(2006,1,1),Survey_Inventory!$D$2:$D$45,"<="&DATE(2006,12,31)) -> 0 | F10: =COUNTIFS(Survey_Inventory!$B$2:$B$45,$B10,Survey_Inventory!$V$2:$V$45,"Yes",Survey_Inventory!$D$2:$D$45,">="&DATE(2008,1,1),Survey_Inventory!$D$2:$D$45,"<="&DATE(2008,12,31)) -> 0 | G10: =COUNTIFS(Survey_Inventory!$B$2:$B$45,$B10,Survey_Inventory!$V$2:$V$45,"Yes",Survey_Inventory!$D$2:$D$45,">="&DATE(2009,1,1),Survey_Inventory!$D$2:$D$45,"<="&DATE(2009,12,31)) -> 0 | H10: =COUNTIFS(Survey_Inventory!$B$2:$B$45,$B10,Survey_Inventory!$V$2:$V$45,"Yes",Survey_Inventory!$D$2:$D$45,">="&DATE(2010,1,1),Survey_Inventory!$D$2:$D$45,"<="&DATE(2010,12,31)) -> 0 | I10: =COUNTIFS(Survey_Inventory!$B$2:$B$45,$B10,Survey_Inventory!$V$2:$V$45,"Yes",Survey_Inventory!$D$2:$D$45,">="&DATE(2011,1,1),Survey_Inventory!$D$2:$D$45,"<="&DATE(2011,12,31)) -> 0 | J10: =COUNTIFS(Survey_Inventory!$B$2:$B$45,$B10,Survey_Inventory!$V$2:$V$45,"Yes",Survey_Inventory!$D$2:$D$45,">="&DATE(2022,1,1),Survey_Inventory!$D$2:$D$45,"<="&DATE(2022,12,31)) -> 0 | K10: =COUNTIFS(Survey_Inventory!$B$2:$B$45,$B10,Survey_Inventory!$V$2:$V$45,"Yes",Survey_Inventory!$D$2:$D$45,">="&DATE(2023,1,1),Survey_Inventory!$D$2:$D$45,"<="&DATE(2023,12,31)) -> 0 | L10: =COUNTIFS(Survey_Inventory!$B$2:$B$45,$B10,Survey_Inventory!$V$2:$V$45,"Yes",Survey_Inventory!$D$2:$D$45,">="&DATE(2012,1,1),Survey_Inventory!$D$2:$D$45,"<="&DATE(2021,12,31)) -> 0 | M10: =COUNTIFS(Survey_Inventory!$B$2:$B$45,$B10,Survey_Inventory!$V$2:$V$45,"Yes") -> 0
B12: B. Surveys per beach per condition
B13: beach | C13: Daylight | D13: Evening | E13: TOTAL
B14: Longbeach | C14: =COUNTIFS(Survey_Inventory!$B$2:$B$45,$B14,Survey_Inventory!$V$2:$V$45,"Yes",Survey_Inventory!$F$2:$F$45,"Daylight") -> 3 | D14: =COUNTIFS(Survey_Inventory!$B$2:$B$45,$B14,Survey_Inventory!$V$2:$V$45,"Yes",Survey_Inventory!$F$2:$F$45,"Evening") -> 3 | E14: =SUM(C14:D14) -> 6
B15: Twin Harbors | C15: =COUNTIFS(Survey_Inventory!$B$2:$B$45,$B15,Survey_Inventory!$V$2:$V$45,"Yes",Survey_Inventory!$F$2:$F$45,"Daylight") -> 5 | D15: =COUNTIFS(Survey_Inventory!$B$2:$B$45,$B15,Survey_Inventory!$V$2:$V$45,"Yes",Survey_Inventory!$F$2:$F$45,"Evening") -> 2 | E15: =SUM(C15:D15) -> 7
B16: Copalis | C16: =COUNTIFS(Survey_Inventory!$B$2:$B$45,$B16,Survey_Inventory!$V$2:$V$45,"Yes",Survey_Inventory!$F$2:$F$45,"Daylight") -> 4 | D16: =COUNTIFS(Survey_Inventory!$B$2:$B$45,$B16,Survey_Inventory!$V$2:$V$45,"Yes",Survey_Inventory!$F$2:$F$45,"Evening") -> 2 | E16: =SUM(C16:D16) -> 6
B17: Mocrocks | C17: =COUNTIFS(Survey_Inventory!$B$2:$B$45,$B17,Survey_Inventory!$V$2:$V$45,"Yes",Survey_Inventory!$F$2:$F$45,"Daylight") -> 5 | D17: =COUNTIFS(Survey_Inventory!$B$2:$B$45,$B17,Survey_Inventory!$V$2:$V$45,"Yes",Survey_Inventory!$F$2:$F$45,"Evening") -> 3 | E17: =SUM(C17:D17) -> 8
B18: Kalaloch | C18: =COUNTIFS(Survey_Inventory!$B$2:$B$45,$B18,Survey_Inventory!$V$2:$V$45,"Yes",Survey_Inventory!$F$2:$F$45,"Daylight") -> 0 | D18: =COUNTIFS(Survey_Inventory!$B$2:$B$45,$B18,Survey_Inventory!$V$2:$V$45,"Yes",Survey_Inventory!$F$2:$F$45,"Evening") -> 0 | E18: =SUM(C18:D18) -> 0
B20: Notes
B21: Kalaloch: zero surveys. Its expansion table is the Mocrocks 01-Apr-1998 survey (Data_Issues #1).
B22: 2012-2021: zero surveys in hand, yet the Long Beach, Twin Harbors, Copalis and Mocrocks evening tables were all revised in 2012-2013. Reconstructed_Surveys recovers the four missing surveys bin by bin from the published tables.
B23: Long Beach and Twin Harbors have four daylight surveys each but no daylight expansion table anywhere in the file set (Data_Issues #12).
B24: The 1990 Long Beach record is excluded because its counts are identical to the 1998 record (Data_Issues #6). If the 1990 date proves correct, swap the two exclusions.

Sheet Survey_Counts
A1: survey_key | B1: bin_ord | C1: bin | D1: min_from_low | E1: beach | F1: condition | G1: date | H1: cars_on | I1: cars_off | J1: cum_cars_on | K1: cum_cars_off | L1: cars_on_beach | M1: total_cars_on | N1: pct_available | O1: pct_available_as_reported | P1: check_delta | Q1: not_recorded_in_source
A2: DB-18 | B2: 0 | C2: Prior to start | E2: Copalis | F2: Daylight | G2: 38100 | H2: 11 | I2: 1 | J2: =SUMIFS($H$2:$H$1200,$A$2:$A$1200,$A2,$B$2:$B$1200,"<="&$B2) -> 11 | K2: =SUMIFS($I$2:$I$1200,$A$2:$A$1200,$A2,$B$2:$B$1200,"<="&$B2) -> 1 | L2: =J2-K2 -> 10 | M2: =SUMIF($A$2:$A$1200,$A2,$H$2:$H$1200) -> 374 | N2: =IF(M2=0,"",L2/M2) -> 0.026737968 | P2: =IF(OR(N2="",O2=""),"",N2-O2)
A3: DB-18 | B3: 3 | C3: 3:00 - 2:45 | D3: -180 | E3: Copalis | F3: Daylight | G3: 38100 | H3: 23 | I3: 0 | J3: =SUMIFS($H$2:$H$1200,$A$2:$A$1200,$A3,$B$2:$B$1200,"<="&$B3) -> 34 | K3: =SUMIFS($I$2:$I$1200,$A$2:$A$1200,$A3,$B$2:$B$1200,"<="&$B3) -> 1 | L3: =J3-K3 -> 33 | M3: =SUMIF($A$2:$A$1200,$A3,$H$2:$H$1200) -> 374 | N3: =IF(M3=0,"",L3/M3) -> 0.088235294 | P3: =IF(OR(N3="",O3=""),"",N3-O3)
A4: DB-18 | B4: 4 | C4: 2:45 - 2:30 | D4: -165 | E4: Copalis | F4: Daylight | G4: 38100 | H4: 25 | I4: 0 | J4: =SUMIFS($H$2:$H$1200,$A$2:$A$1200,$A4,$B$2:$B$1200,"<="&$B4) -> 59 | K4: =SUMIFS($I$2:$I$1200,$A$2:$A$1200,$A4,$B$2:$B$1200,"<="&$B4) -> 1 | L4: =J4-K4 -> 58 | M4: =SUMIF($A$2:$A$1200,$A4,$H$2:$H$1200) -> 374 | N4: =IF(M4=0,"",L4/M4) -> 0.15508021 | P4: =IF(OR(N4="",O4=""),"",N4-O4)
A5: DB-18 | B5: 5 | C5: 2:30 - 2:15 | D5: -150 | E5: Copalis | F5: Daylight | G5: 38100 | H5: 39 | I5: 5 | J5: =SUMIFS($H$2:$H$1200,$A$2:$A$1200,$A5,$B$2:$B$1200,"<="&$B5) -> 98 | K5: =SUMIFS($I$2:$I$1200,$A$2:$A$1200,$A5,$B$2:$B$1200,"<="&$B5) -> 6 | L5: =J5-K5 -> 92 | M5: =SUMIF($A$2:$A$1200,$A5,$H$2:$H$1200) -> 374 | N5: =IF(M5=0,"",L5/M5) -> 0.2459893 | P5: =IF(OR(N5="",O5=""),"",N5-O5)
A6: DB-18 | B6: 6 | C6: 2:15 - 2:00 | D6: -135 | E6: Copalis | F6: Daylight | G6: 38100 | H6: 38 | I6: 4 | J6: =SUMIFS($H$2:$H$1200,$A$2:$A$1200,$A6,$B$2:$B$1200,"<="&$B6) -> 136 | K6: =SUMIFS($I$2:$I$1200,$A$2:$A$1200,$A6,$B$2:$B$1200,"<="&$B6) -> 10 | L6: =J6-K6 -> 126 | M6: =SUMIF($A$2:$A$1200,$A6,$H$2:$H$1200) -> 374 | N6: =IF(M6=0,"",L6/M6) -> 0.3368984 | P6: =IF(OR(N6="",O6=""),"",N6-O6)
A7: DB-18 | B7: 7 | C7: 2:00 - 1:45 | D7: -120 | E7: Copalis | F7: Daylight | G7: 38100 | H7: 24 | I7: 16 | J7: =SUMIFS($H$2:$H$1200,$A$2:$A$1200,$A7,$B$2:$B$1200,"<="&$B7) -> 160 | K7: =SUMIFS($I$2:$I$1200,$A$2:$A$1200,$A7,$B$2:$B$1200,"<="&$B7) -> 26 | L7: =J7-K7 -> 134 | M7: =SUMIF($A$2:$A$1200,$A7,$H$2:$H$1200) -> 374 | N7: =IF(M7=0,"",L7/M7) -> 0.35828877 | P7: =IF(OR(N7="",O7=""),"",N7-O7)
A8: DB-18 | B8: 8 | C8: 1:45 - 1:30 | D8: -105 | E8: Copalis | F8: Daylight | G8: 38100 | H8: 51 | I8: 18 | J8: =SUMIFS($H$2:$H$1200,$A$2:$A$1200,$A8,$B$2:$B$1200,"<="&$B8) -> 211 | K8: =SUMIFS($I$2:$I$1200,$A$2:$A$1200,$A8,$B$2:$B$1200,"<="&$B8) -> 44 | L8: =J8-K8 -> 167 | M8: =SUMIF($A$2:$A$1200,$A8,$H$2:$H$1200) -> 374 | N8: =IF(M8=0,"",L8/M8) -> 0.44652406 | P8: =IF(OR(N8="",O8=""),"",N8-O8)
A9: DB-18 | B9: 9 | C9: 1:30 - 1:15 | D9: -90 | E9: Copalis | F9: Daylight | G9: 38100 | H9: 49 | I9: 20 | J9: =SUMIFS($H$2:$H$1200,$A$2:$A$1200,$A9,$B$2:$B$1200,"<="&$B9) -> 260 | K9: =SUMIFS($I$2:$I$1200,$A$2:$A$1200,$A9,$B$2:$B$1200,"<="&$B9) -> 64 | L9: =J9-K9 -> 196 | M9: =SUMIF($A$2:$A$1200,$A9,$H$2:$H$1200) -> 374 | N9: =IF(M9=0,"",L9/M9) -> 0.52406417 | P9: =IF(OR(N9="",O9=""),"",N9-O9)
A10: DB-18 | B10: 10 | C10: 1:15 - 1:00 | D10: -75 | E10: Copalis | F10: Daylight | G10: 38100 | H10: 36 | I10: 28 | J10: =SUMIFS($H$2:$H$1200,$A$2:$A$1200,$A10,$B$2:$B$1200,"<="&$B10) -> 296 | K10: =SUMIFS($I$2:$I$1200,$A$2:$A$1200,$A10,$B$2:$B$1200,"<="&$B10) -> 92 | L10: =J10-K10 -> 204 | M10: =SUMIF($A$2:$A$1200,$A10,$H$2:$H$1200) -> 374 | N10: =IF(M10=0,"",L10/M10) -> 0.54545455 | P10: =IF(OR(N10="",O10=""),"",N10-O10)
A11: DB-18 | B11: 11 | C11: 1:00 - 0:45 | D11: -60 | E11: Copalis | F11: Daylight | G11: 38100 | H11: 21 | I11: 30 | J11: =SUMIFS($H$2:$H$1200,$A$2:$A$1200,$A11,$B$2:$B$1200,"<="&$B11) -> 317 | K11: =SUMIFS($I$2:$I$1200,$A$2:$A$1200,$A11,$B$2:$B$1200,"<="&$B11) -> 122 | L11: =J11-K11 -> 195 | M11: =SUMIF($A$2:$A$1200,$A11,$H$2:$H$1200) -> 374 | N11: =IF(M11=0,"",L11/M11) -> 0.52139037 | P11: =IF(OR(N11="",O11=""),"",N11-O11)
A12: DB-18 | B12: 12 | C12: 0:45 - 0:30 | D12: -45 | E12: Copalis | F12: Daylight | G12: 38100 | H12: 20 | I12: 40 | J12: =SUMIFS($H$2:$H$1200,$A$2:$A$1200,$A12,$B$2:$B$1200,"<="&$B12) -> 337 | K12: =SUMIFS($I$2:$I$1200,$A$2:$A$1200,$A12,$B$2:$B$1200,"<="&$B12) -> 162 | L12: =J12-K12 -> 175 | M12: =SUMIF($A$2:$A$1200,$A12,$H$2:$H$1200) -> 374 | N12: =IF(M12=0,"",L12/M12) -> 0.46791444 | P12: =IF(OR(N12="",O12=""),"",N12-O12)
A13: DB-18 | B13: 13 | C13: 0:30 - 0:15 | D13: -30 | E13: Copalis | F13: Daylight | G13: 38100 | H13: 11 | I13: 61 | J13: =SUMIFS($H$2:$H$1200,$A$2:$A$1200,$A13,$B$2:$B$1200,"<="&$B13) -> 348 | K13: =SUMIFS($I$2:$I$1200,$A$2:$A$1200,$A13,$B$2:$B$1200,"<="&$B13) -> 223 | L13: =J13-K13 -> 125 | M13: =SUMIF($A$2:$A$1200,$A13,$H$2:$H$1200) -> 374 | N13: =IF(M13=0,"",L13/M13) -> 0.3342246 | P13: =IF(OR(N13="",O13=""),"",N13-O13)
A14: DB-18 | B14: 14 | C14: 0:15 - 0:00 | D14: -15 | E14: Copalis | F14: Daylight | G14: 38100 | H14: 8 | I14: 34 | J14: =SUMIFS($H$2:$H$1200,$A$2:$A$1200,$A14,$B$2:$B$1200,"<="&$B14) -> 356 | K14: =SUMIFS($I$2:$I$1200,$A$2:$A$1200,$A14,$B$2:$B$1200,"<="&$B14) -> 257 | L14: =J14-K14 -> 99 | M14: =SUMIF($A$2:$A$1200,$A14,$H$2:$H$1200) -> 374 | N14: =IF(M14=0,"",L14/M14) -> 0.26470588 | P14: =IF(OR(N14="",O14=""),"",N14-O14)
... A19: DB-18 | B19: 19 | C19: 1:00 - 1:15 | D19: 60 | E19: Copalis | F19: Daylight | G19: 38100 | H19: 2 | I19: 16 | J19: =SUMIFS($H$2:$H$1200,$A$2:$A$1200,$A19,$B$2:$B$1200,"<="&$B19) -> 374 | K19: =SUMIFS($I$2:$I$1200,$A$2:$A$1200,$A19,$B$2:$B$1200,"<="&$B19) -> 368 | L19: =J19-K19 -> 6 | M19: =SUMIF($A$2:$A$1200,$A19,$H$2:$H$1200) -> 374 | N19: =IF(M19=0,"",L19/M19) -> 0.016042781 | P19: =IF(OR(N19="",O19=""),"",N19-O19)
A20: WB-COP-2004-04-23 | B20: 0 | C20: Prior to start | E20: Copalis | F20: Daylight | G20: 38100 | H20: 11 | I20: 1 | J20: =SUMIFS($H$2:$H$1200,$A$2:$A$1200,$A20,$B$2:$B$1200,"<="&$B20) -> 11 | K20: =SUMIFS($I$2:$I$1200,$A$2:$A$1200,$A20,$B$2:$B$1200,"<="&$B20) -> 1 | L20: =J20-K20 -> 10 | M20: =SUMIF($A$2:$A$1200,$A20,$H$2:$H$1200) -> 374 | N20: =IF(M20=0,"",L20/M20) -> 0.026737968 | O20: 0.026737968 | P20: =IF(OR(N20="",O20=""),"",N20-O20) -> 3.469447e-18
A21: WB-COP-2004-04-23 | B21: 3 | C21: 3:00 - 2:45 | D21: -180 | E21: Copalis | F21: Daylight | G21: 38100 | H21: 23 | I21: 0 | J21: =SUMIFS($H$2:$H$1200,$A$2:$A$1200,$A21,$B$2:$B$1200,"<="&$B21) -> 34 | K21: =SUMIFS($I$2:$I$1200,$A$2:$A$1200,$A21,$B$2:$B$1200,"<="&$B21) -> 1 | L21: =J21-K21 -> 33 | M21: =SUMIF($A$2:$A$1200,$A21,$H$2:$H$1200) -> 374 | N21: =IF(M21=0,"",L21/M21) -> 0.088235294 | O21: 0.088235294 | P21: =IF(OR(N21="",O21=""),"",N21-O21) -> -4.1633363e-17
A22: WB-COP-2004-04-23 | B22: 4 | C22: 2:45 - 2:30 | D22: -165 | E22: Copalis | F22: Daylight | G22: 38100 | H22: 25 | I22: 0 | J22: =SUMIFS($H$2:$H$1200,$A$2:$A$1200,$A22,$B$2:$B$1200,"<="&$B22) -> 59 | K22: =SUMIFS($I$2:$I$1200,$A$2:$A$1200,$A22,$B$2:$B$1200,"<="&$B22) -> 1 | L22: =J22-K22 -> 58 | M22: =SUMIF($A$2:$A$1200,$A22,$H$2:$H$1200) -> 374 | N22: =IF(M22=0,"",L22/M22) -> 0.15508021 | O22: 0.15508021 | P22: =IF(OR(N22="",O22=""),"",N22-O22) -> 3.3306691e-16
A23: WB-COP-2004-04-23 | B23: 5 | C23: 2:30 - 2:15 | D23: -150 | E23: Copalis | F23: Daylight | G23: 38100 | H23: 39 | I23: 5 | J23: =SUMIFS($H$2:$H$1200,$A$2:$A$1200,$A23,$B$2:$B$1200,"<="&$B23) -> 98 | K23: =SUMIFS($I$2:$I$1200,$A$2:$A$1200,$A23,$B$2:$B$1200,"<="&$B23) -> 6 | L23: =J23-K23 -> 92 | M23: =SUMIF($A$2:$A$1200,$A23,$H$2:$H$1200) -> 374 | N23: =IF(M23=0,"",L23/M23) -> 0.2459893 | O23: 0.2459893 | P23: =IF(OR(N23="",O23=""),"",N23-O23) -> 2.4980018e-16
A24: WB-COP-2004-04-23 | B24: 6 | C24: 2:15 - 2:00 | D24: -135 | E24: Copalis | F24: Daylight | G24: 38100 | H24: 38 | I24: 4 | J24: =SUMIFS($H$2:$H$1200,$A$2:$A$1200,$A24,$B$2:$B$1200,"<="&$B24) -> 136 | K24: =SUMIFS($I$2:$I$1200,$A$2:$A$1200,$A24,$B$2:$B$1200,"<="&$B24) -> 10 | L24: =J24-K24 -> 126 | M24: =SUMIF($A$2:$A$1200,$A24,$H$2:$H$1200) -> 374 | N24: =IF(M24=0,"",L24/M24) -> 0.3368984 | O24: 0.3368984 | P24: =IF(OR(N24="",O24=""),"",N24-O24) -> 1.6653345e-16
A25: WB-COP-2004-04-23 | B25: 7 | C25: 2:00 - 1:45 | D25: -120 | E25: Copalis | F25: Daylight | G25: 38100 | H25: 24 | I25: 16 | J25: =SUMIFS($H$2:$H$1200,$A$2:$A$1200,$A25,$B$2:$B$1200,"<="&$B25) -> 160 | K25: =SUMIFS($I$2:$I$1200,$A$2:$A$1200,$A25,$B$2:$B$1200,"<="&$B25) -> 26 | L25: =J25-K25 -> 134 | M25: =SUMIF($A$2:$A$1200,$A25,$H$2:$H$1200) -> 374 | N25: =IF(M25=0,"",L25/M25) -> 0.35828877 | O25: 0.35828877 | P25: =IF(OR(N25="",O25=""),"",N25-O25) -> -5.5511151e-17
A26: WB-COP-2004-04-23 | B26: 8 | C26: 1:45 - 1:30 | D26: -105 | E26: Copalis | F26: Daylight | G26: 38100 | H26: 51 | I26: 18 | J26: =SUMIFS($H$2:$H$1200,$A$2:$A$1200,$A26,$B$2:$B$1200,"<="&$B26) -> 211 | K26: =SUMIFS($I$2:$I$1200,$A$2:$A$1200,$A26,$B$2:$B$1200,"<="&$B26) -> 44 | L26: =J26-K26 -> 167 | M26: =SUMIF($A$2:$A$1200,$A26,$H$2:$H$1200) -> 374 | N26: =IF(M26=0,"",L26/M26) -> 0.44652406 | O26: 0.44652406 | P26: =IF(OR(N26="",O26=""),"",N26-O26) -> 0
A27: WB-COP-2004-04-23 | B27: 9 | C27: 1:30 - 1:15 | D27: -90 | E27: Copalis | F27: Daylight | G27: 38100 | H27: 49 | I27: 20 | J27: =SUMIFS($H$2:$H$1200,$A$2:$A$1200,$A27,$B$2:$B$1200,"<="&$B27) -> 260 | K27: =SUMIFS($I$2:$I$1200,$A$2:$A$1200,$A27,$B$2:$B$1200,"<="&$B27) -> 64 | L27: =J27-K27 -> 196 | M27: =SUMIF($A$2:$A$1200,$A27,$H$2:$H$1200) -> 374 | N27: =IF(M27=0,"",L27/M27) -> 0.52406417 | O27: 0.52406417 | P27: =IF(OR(N27="",O27=""),"",N27-O27) -> -3.3306691e-16
A28: WB-COP-2004-04-23 | B28: 10 | C28: 1:15 - 1:00 | D28: -75 | E28: Copalis | F28: Daylight | G28: 38100 | H28: 36 | I28: 28 | J28: =SUMIFS($H$2:$H$1200,$A$2:$A$1200,$A28,$B$2:$B$1200,"<="&$B28) -> 296 | K28: =SUMIFS($I$2:$I$1200,$A$2:$A$1200,$A28,$B$2:$B$1200,"<="&$B28) -> 92 | L28: =J28-K28 -> 204 | M28: =SUMIF($A$2:$A$1200,$A28,$H$2:$H$1200) -> 374 | N28: =IF(M28=0,"",L28/M28) -> 0.54545455 | O28: 0.54545455 | P28: =IF(OR(N28="",O28=""),"",N28-O28) -> 4.4408921e-16
A29: WB-COP-2004-04-23 | B29: 11 | C29: 1:00 - 0:45 | D29: -60 | E29: Copalis | F29: Daylight | G29: 38100 | H29: 21 | I29: 30 | J29: =SUMIFS($H$2:$H$1200,$A$2:$A$1200,$A29,$B$2:$B$1200,"<="&$B29) -> 317 | K29: =SUMIFS($I$2:$I$1200,$A$2:$A$1200,$A29,$B$2:$B$1200,"<="&$B29) -> 122 | L29: =J29-K29 -> 195 | M29: =SUMIF($A$2:$A$1200,$A29,$H$2:$H$1200) -> 374 | N29: =IF(M29=0,"",L29/M29) -> 0.52139037 | O29: 0.52139037 | P29: =IF(OR(N29="",O29=""),"",N29-O29) -> -2.220446e-16
A30: WB-COP-2004-04-23 | B30: 12 | C30: 0:45 - 0:30 | D30: -45 | E30: Copalis | F30: Daylight | G30: 38100 | H30: 20 | I30: 40 | J30: =SUMIFS($H$2:$H$1200,$A$2:$A$1200,$A30,$B$2:$B$1200,"<="&$B30) -> 337 | K30: =SUMIFS($I$2:$I$1200,$A$2:$A$1200,$A30,$B$2:$B$1200,"<="&$B30) -> 162 | L30: =J30-K30 -> 175 | M30: =SUMIF($A$2:$A$1200,$A30,$H$2:$H$1200) -> 374 | N30: =IF(M30=0,"",L30/M30) -> 0.46791444 | O30: 0.46791444 | P30: =IF(OR(N30="",O30=""),"",N30-O30) -> -2.220446e-16
A31: WB-COP-2004-04-23 | B31: 13 | C31: 0:30 - 0:15 | D31: -30 | E31: Copalis | F31: Daylight | G31: 38100 | H31: 11 | I31: 61 | J31: =SUMIFS($H$2:$H$1200,$A$2:$A$1200,$A31,$B$2:$B$1200,"<="&$B31) -> 348 | K31: =SUMIFS($I$2:$I$1200,$A$2:$A$1200,$A31,$B$2:$B$1200,"<="&$B31) -> 223 | L31: =J31-K31 -> 125 | M31: =SUMIF($A$2:$A$1200,$A31,$H$2:$H$1200) -> 374 | N31: =IF(M31=0,"",L31/M31) -> 0.3342246 | O31: 0.3342246 | P31: =IF(OR(N31="",O31=""),"",N31-O31) -> 2.7755576e-16
A32: WB-COP-2004-04-23 | B32: 14 | C32: 0:15 - 0:00 | D32: -15 | E32: Copalis | F32: Daylight | G32: 38100 | H32: 8 | I32: 34 | J32: =SUMIFS($H$2:$H$1200,$A$2:$A$1200,$A32,$B$2:$B$1200,"<="&$B32) -> 356 | K32: =SUMIFS($I$2:$I$1200,$A$2:$A$1200,$A32,$B$2:$B$1200,"<="&$B32) -> 257 | L32: =J32-K32 -> 99 | M32: =SUMIF($A$2:$A$1200,$A32,$H$2:$H$1200) -> 374 | N32: =IF(M32=0,"",L32/M32) -> 0.26470588 | O32: 0.26470588 | P32: =IF(OR(N32="",O32=""),"",N32-O32) -> 1.6653345e-16
... A37: WB-COP-2004-04-23 | B37: 19 | C37: 1:00 - 1:15 | D37: 60 | E37: Copalis | F37: Daylight | G37: 38100 | H37: 2 | I37: 16 | J37: =SUMIFS($H$2:$H$1200,$A$2:$A$1200,$A37,$B$2:$B$1200,"<="&$B37) -> 374 | K37: =SUMIFS($I$2:$I$1200,$A$2:$A$1200,$A37,$B$2:$B$1200,"<="&$B37) -> 368 | L37: =J37-K37 -> 6 | M37: =SUMIF($A$2:$A$1200,$A37,$H$2:$H$1200) -> 374 | N37: =IF(M37=0,"",L37/M37) -> 0.016042781 | O37: 0.016042781 | P37: =IF(OR(N37="",O37=""),"",N37-O37) -> 3.469447e-18
A38: DB-17 | B38: 0 | C38: Prior to start | E38: Copalis | F38: Evening | G38: 39765 | H38: 16 | I38: 0 | J38: =SUMIFS($H$2:$H$1200,$A$2:$A$1200,$A38,$B$2:$B$1200,"<="&$B38) -> 16 | K38: =SUMIFS($I$2:$I$1200,$A$2:$A$1200,$A38,$B$2:$B$1200,"<="&$B38) -> 0 | L38: =J38-K38 -> 16 | M38: =SUMIF($A$2:$A$1200,$A38,$H$2:$H$1200) -> 231 | N38: =IF(M38=0,"",L38/M38) -> 0.069264069 | P38: =IF(OR(N38="",O38=""),"",N38-O38) | Q38: off
A39: DB-17 | B39: 3 | C39: 3:00 - 2:45 | D39: -180 | E39: Copalis | F39: Evening | G39: 39765 | H39: 7 | I39: 3 | J39: =SUMIFS($H$2:$H$1200,$A$2:$A$1200,$A39,$B$2:$B$1200,"<="&$B39) -> 23 | K39: =SUMIFS($I$2:$I$1200,$A$2:$A$1200,$A39,$B$2:$B$1200,"<="&$B39) -> 3 | L39: =J39-K39 -> 20 | M39: =SUMIF($A$2:$A$1200,$A39,$H$2:$H$1200) -> 231 | N39: =IF(M39=0,"",L39/M39) -> 0.086580087 | P39: =IF(OR(N39="",O39=""),"",N39-O39)
A40: DB-17 | B40: 4 | C40: 2:45 - 2:30 | D40: -165 | E40: Copalis | F40: Evening | G40: 39765 | H40: 16 | I40: 2 | J40: =SUMIFS($H$2:$H$1200,$A$2:$A$1200,$A40,$B$2:$B$1200,"<="&$B40) -> 39 | K40: =SUMIFS($I$2:$I$1200,$A$2:$A$1200,$A40,$B$2:$B$1200,"<="&$B40) -> 5 | L40: =J40-K40 -> 34 | M40: =SUMIF($A$2:$A$1200,$A40,$H$2:$H$1200) -> 231 | N40: =IF(M40=0,"",L40/M40) -> 0.14718615 | P40: =IF(OR(N40="",O40=""),"",N40-O40)
A41: DB-17 | B41: 5 | C41: 2:30 - 2:15 | D41: -150 | E41: Copalis | F41: Evening | G41: 39765 | H41: 25 | I41: 0 | J41: =SUMIFS($H$2:$H$1200,$A$2:$A$1200,$A41,$B$2:$B$1200,"<="&$B41) -> 64 | K41: =SUMIFS($I$2:$I$1200,$A$2:$A$1200,$A41,$B$2:$B$1200,"<="&$B41) -> 5 | L41: =J41-K41 -> 59 | M41: =SUMIF($A$2:$A$1200,$A41,$H$2:$H$1200) -> 231 | N41: =IF(M41=0,"",L41/M41) -> 0.25541126 | P41: =IF(OR(N41="",O41=""),"",N41-O41)
A42: DB-17 | B42: 6 | C42: 2:15 - 2:00 | D42: -135 | E42: Copalis | F42: Evening | G42: 39765 | H42: 23 | I42: 7 | J42: =SUMIFS($H$2:$H$1200,$A$2:$A$1200,$A42,$B$2:$B$1200,"<="&$B42) -> 87 | K42: =SUMIFS($I$2:$I$1200,$A$2:$A$1200,$A42,$B$2:$B$1200,"<="&$B42) -> 12 | L42: =J42-K42 -> 75 | M42: =SUMIF($A$2:$A$1200,$A42,$H$2:$H$1200) -> 231 | N42: =IF(M42=0,"",L42/M42) -> 0.32467532 | P42: =IF(OR(N42="",O42=""),"",N42-O42)
A43: DB-17 | B43: 7 | C43: 2:00 - 1:45 | D43: -120 | E43: Copalis | F43: Evening | G43: 39765 | H43: 15 | I43: 9 | J43: =SUMIFS($H$2:$H$1200,$A$2:$A$1200,$A43,$B$2:$B$1200,"<="&$B43) -> 102 | K43: =SUMIFS($I$2:$I$1200,$A$2:$A$1200,$A43,$B$2:$B$1200,"<="&$B43) -> 21 | L43: =J43-K43 -> 81 | M43: =SUMIF($A$2:$A$1200,$A43,$H$2:$H$1200) -> 231 | N43: =IF(M43=0,"",L43/M43) -> 0.35064935 | P43: =IF(OR(N43="",O43=""),"",N43-O43)
A44: DB-17 | B44: 8 | C44: 1:45 - 1:30 | D44: -105 | E44: Copalis | F44: Evening | G44: 39765 | H44: 22 | I44: 25 | J44: =SUMIFS($H$2:$H$1200,$A$2:$A$1200,$A44,$B$2:$B$1200,"<="&$B44) -> 124 | K44: =SUMIFS($I$2:$I$1200,$A$2:$A$1200,$A44,$B$2:$B$1200,"<="&$B44) -> 46 | L44: =J44-K44 -> 78 | M44: =SUMIF($A$2:$A$1200,$A44,$H$2:$H$1200) -> 231 | N44: =IF(M44=0,"",L44/M44) -> 0.33766234 | P44: =IF(OR(N44="",O44=""),"",N44-O44)
A45: DB-17 | B45: 9 | C45: 1:30 - 1:15 | D45: -90 | E45: Copalis | F45: Evening | G45: 39765 | H45: 28 | I45: 25 | J45: =SUMIFS($H$2:$H$1200,$A$2:$A$1200,$A45,$B$2:$B$1200,"<="&$B45) -> 152 | K45: =SUMIFS($I$2:$I$1200,$A$2:$A$1200,$A45,$B$2:$B$1200,"<="&$B45) -> 71 | L45: =J45-K45 -> 81 | M45: =SUMIF($A$2:$A$1200,$A45,$H$2:$H$1200) -> 231 | N45: =IF(M45=0,"",L45/M45) -> 0.35064935 | P45: =IF(OR(N45="",O45=""),"",N45-O45)
A46: DB-17 | B46: 10 | C46: 1:15 - 1:00 | D46: -75 | E46: Copalis | F46: Evening | G46: 39765 | H46: 26 | I46: 26 | J46: =SUMIFS($H$2:$H$1200,$A$2:$A$1200,$A46,$B$2:$B$1200,"<="&$B46) -> 178 | K46: =SUMIFS($I$2:$I$1200,$A$2:$A$1200,$A46,$B$2:$B$1200,"<="&$B46) -> 97 | L46: =J46-K46 -> 81 | M46: =SUMIF($A$2:$A$1200,$A46,$H$2:$H$1200) -> 231 | N46: =IF(M46=0,"",L46/M46) -> 0.35064935 | P46: =IF(OR(N46="",O46=""),"",N46-O46)
A47: DB-17 | B47: 11 | C47: 1:00 - 0:45 | D47: -60 | E47: Copalis | F47: Evening | G47: 39765 | H47: 10 | I47: 23 | J47: =SUMIFS($H$2:$H$1200,$A$2:$A$1200,$A47,$B$2:$B$1200,"<="&$B47) -> 188 | K47: =SUMIFS($I$2:$I$1200,$A$2:$A$1200,$A47,$B$2:$B$1200,"<="&$B47) -> 120 | L47: =J47-K47 -> 68 | M47: =SUMIF($A$2:$A$1200,$A47,$H$2:$H$1200) -> 231 | N47: =IF(M47=0,"",L47/M47) -> 0.29437229 | P47: =IF(OR(N47="",O47=""),"",N47-O47)
A48: DB-17 | B48: 12 | C48: 0:45 - 0:30 | D48: -45 | E48: Copalis | F48: Evening | G48: 39765 | H48: 13 | I48: 19 | J48: =SUMIFS($H$2:$H$1200,$A$2:$A$1200,$A48,$B$2:$B$1200,"<="&$B48) -> 201 | K48: =SUMIFS($I$2:$I$1200,$A$2:$A$1200,$A48,$B$2:$B$1200,"<="&$B48) -> 139 | L48: =J48-K48 -> 62 | M48: =SUMIF($A$2:$A$1200,$A48,$H$2:$H$1200) -> 231 | N48: =IF(M48=0,"",L48/M48) -> 0.26839827 | P48: =IF(OR(N48="",O48=""),"",N48-O48)
...

Sheet Pct_Available_Matrix
D1: Copalis | E1: Copalis | F1: Copalis | G1: Copalis | H1: Copalis | I1: Copalis | J1: Copalis | K1: Copalis | L1: Longbeach | M1: Longbeach | N1: Longbeach | O1: Longbeach | P1: Longbeach | Q1: Longbeach | R1: Longbeach | S1: Longbeach | T1: Longbeach | U1: Mocrocks | V1: Mocrocks | W1: Mocrocks | X1: Mocrocks | Y1: Mocrocks | Z1: Mocrocks | AA1: Mocrocks | AB1: Mocrocks | AC1: Mocrocks | AD1: Mocrocks | AE1: Mocrocks | AF1: Mocrocks | AG1: Mocrocks | AH1: Mocrocks | AI1: Twin Harbors | AJ1: Twin Harbors | AK1: Twin Harbors | AL1: Twin Harbors | AM1: Twin Harbors | AN1: Twin Harbors | AO1: Twin Harbors | AP1: Twin Harbors | AQ1: Twin Harbors | AR1: Twin Harbors | AS1: Twin Harbors | AT1: Twin Harbors | AU1: Twin Harbors
D2: 2004-04-23 Day [excl] | E2: 2004-04-23 Day | F2: 2008-11-13 Eve [excl] | G2: 2008-11-13 Eve | H2: 2010-10-08 Eve | I2: 2011-04-22 Day | J2: 2022-04-02 Day | K2: 2023-04-24 Day | L2: 1990-05-11 Eve [excl] | M2: 1998-03-27 Eve | N2: 2004-04-22 Day [excl] | O2: 2004-04-22 Day | P2: 2004-04-23 Day [excl] | Q2: 2004-04-23 Day | R2: 2009-01-10 Eve | S2: 2011-01-21 Eve | T2: 2011-04-19 Day | U2: 1998-04-01 Day | V2: 1998-04-01 Day [excl] | W2: 1998-04-01 Day [excl] | X2: 1998-04-01 Day [excl] | Y2: 2004-04-24 Day [excl] | Z2: 2004-04-24 Day | AA2: 2006-11-04 Eve [excl] | AB2: 2006-11-04 Eve | AC2: 2008-11-13 Eve [excl] | AD2: 2008-11-13 Eve | AE2: 2010-10-09 Eve | AF2: 2011-04-21 Day | AG2: 2022-04-03 Day | AH2: 2023-04-25 Day | AI2: 1998-03-31 Day | AJ2: 1998-03-31 Day [excl] | AK2: 1998-03-31 Day [excl] | AL2: 1998-03-31 Day [excl] | AM2: 1998-03-31 Day [excl] | AN2: 1998-03-31 Day [excl] | AO2: 2004-04-21 Day [excl] | AP2: 2004-04-21 Day | AQ2: 2010-04-27 Day | AR2: 2011-01-22 Eve | AS2: 2011-02-17 Eve | AT2: 2011-04-07 Day | AU2: 2011-04-20 Day
A3: bin_ord | B3: bin | C3: min_from_low | D3: DB-18 | E3: WB-COP-2004-04-23 | F3: DB-17 | G3: WB-COP-2008-11-13 | H3: DB-20 | I3: DB-19 | J3: WB-COP-2022-04-02 | K3: WB-COP-2023-04-24 | L3: WB-LB-1990-05-11 | M3: WB-LB-1998-03-27 | N3: DB-08 | O3: WB-LB-2004-04-22 | P3: DB-06 | Q3: WB-LB-2004-04-23 | R3: DB-09 | S3: DB-07 | T3: DB-10 | U3: WB-MOC-1998-04-01 | V3: WB-MOC-1998-04-01-MOCLIPS | W3: WB-MOC-1998-04-01-ROOSEVELT | X3: WB-MOC-1998-04-01-TRESTLE | Y3: DB-01 | Z3: WB-MOC-2004-04-24 | AA3: DB-02 | AB3: WB-MOC-2006-11-04 | AC3: DB-03 | AD3: WB-MOC-2008-11-13 | AE3: DB-04 | AF3: DB-05 | AG3: WB-MOC-2022-04-03 | AH3: WB-MOC-2023-04-25 | AI3: WB-TH-1998-03-31 | AJ3: WB-TH-1998-03-31-BONGE | AK3: WB-TH-1998-03-31-COUNTY_LINE | AL3: WB-TH-1998-03-31-GRAYLAND | AM3: WB-TH-1998-03-31-MIDWAY | AN3: WB-TH-1998-03-31-NORTH_COVE | AO3: DB-12 | AP3: WB-TH-2004-04-21 | AQ3: DB-13 | AR3: DB-16 | AS3: DB-15 | AT3: DB-14 | AU3: DB-11
