Workbook

Sheet harvest
A1: 2007 FALL / 2008 SPRING RAZOR CLAM HARVEST TOTALS (number of clams): NON-INDIAN FISHERY
A2: (FINAL ESTIMATE) | O2: 39667 | P2: update
A4: DATE | C4: DAY | D4: TIDE | E4: TIME | G4: Longbeach | I4: Twin Harbors | K4: Copalis | M4: Mocrocks | O4: Kalaloch | Q4: Daily Totals
A5: October | B5: 25 | C5: Thu | D5: -1.1 | E5: 0.77083333 | G5: CLOSED | I5: 59809.699 | K5: CLOSED | M5: CLOSED | O5: CLOSED | Q5: 34356.508
A6: October | B6: 26 | C6: Fri | D6: -1.7 | E6: 0.80972222 | G6: 73328.176 | I6: 35723.474 | K6: 54755 | M6: 69732 | O6: CLOSED | Q6: 155570.43
A7: October | B7: 27 | C7: Sat | D7: -1.9 | E7: 0.84305556 | G7: 205165.53 | I7: 59831.192 | K7: 77105 | M7: 45317 | O7: CLOSED | Q7: 324233.77
A8: October | B8: 28 | C8: Sun | D8: -1.8 | E8: 0.87708333 | G8: CLOSED | I8: 53554.693 | K8: CLOSED | M8: CLOSED | O8: CLOSED | Q8: 27406.538
A10: November | B10: 23 | C10: Fri | D10: -1.3 | E10: 0.72291667 | G10: 192287.05 | I10: 47047.31 | K10: 76690 | M10: 54433 | O10: CLOSED | Q10: 299944.35
A11: November | B11: 24 | C11: Sat | D11: -1.7 | E11: 0.75763889 | G11: 135678.56 | I11: 49794.214 | K11: 52027 | M11: 35545 | O11: CLOSED | Q11: 246318.23
A12: November | B12: 25 | C12: Sun | D12: -1.8 | E12: 0.79166667 | G12: CLOSED | I12: 24088.361 | K12: CLOSED | M12: CLOSED | O12: CLOSED | Q12: 21209.72
A13: November | B13: 26 | C13: Mon | D13: -1.6 | E13: 0.79166667 | G13: CLOSED | I13: 1145.5877 | K13: CLOSED | M13: CLOSED | O13: CLOSED | Q13: 945.87122
A15: December | B15: 21 | C15: Fri | D15: -0.4 | E15: 0.675 | G15: 33797.129 | I15: 14001.183 | K15: 27481 | M15: 19911 | O15: CLOSED | Q15: 78687.181
A16: December | B16: 22 | C16: Sat | D16: -0.9 | E16: 0.7125 | G16: 29818.254 | H16: * | I16: =+(K16+M16)*(I11+I10)/(K10+K11+M10+M11) -> 29509.664 | K16: 42683 | M16: 23958 | O16: CLOSED | Q16: 115688.55
A17: December | B17: 23 | C17: Sun | D17: -1.2 | E17: 0.74861111 | G17: CLOSED | I17: 2113.1077 | K17: CLOSED | M17: CLOSED | O17: CLOSED | Q17: 1962.4456
A19: January | B19: 18 | C19: Fri | D19: 0.6 | E19: 0.62222222 | G19: CLOSED | I19: 26136.3 | K19: CLOSED | M19: CLOSED | O19: CLOSED | Q19: 22404.456
A20: January | B20: 19 | C20: Sat | D20: 0.1 | E20: 0.66527778 | G20: 34947.519 | I20: 37135.742 | K20: 115271 | M20: CLOSED | O20: CLOSED | Q20: 157258.45
A21: January | B21: 20 | C21: Sun | D21: -0.4 | E21: 0.70347222 | G21: 68469.643 | I21: 25534.907 | K21: 73652 | M21: CLOSED | O21: CLOSED | Q21: 135957.95
A22: January | B22: 21 | C22: Mon | D22: -0.6 | E22: 0.73888889 | G22: CLOSED | I22: 22584.489 | K22: CLOSED | M22: CLOSED | O22: CLOSED | Q22: 19713.285
A24: February | B24: 6 | C24: Wed | D24: 0.1 | E24: 0.76041667 | G24: CLOSED | I24: 837.37327 | K24: CLOSED | M24: CLOSED | O24: CLOSED | Q24: 797.38094
A25: February | B25: 7 | C25: Thu | D25: 0 | E25: 0.78611111 | G25: CLOSED | I25: 1076.1656 | K25: CLOSED | M25: CLOSED | O25: CLOSED | Q25: 1050.8924
A26: February | B26: 8 | C26: Fri | D26: 0.1 | E26: 0.81041667 | G26: 383.54854 | I26: 255.09111 | K26: CLOSED | M26: CLOSED | O26: CLOSED | Q26: 410.16665
A27: February | B27: 9 | C27: Sat | D27: 0.4 | E27: 0.83472222 | F27: * | G27: =+I27*(G30+G31+G36+G37+G38)/(I30+I31+I36+I37+I38) -> 3039.4623 | I27: 1822.3679 | K27: CLOSED | M27: CLOSED | O27: CLOSED | Q27: 4616.5868
A29: March | B29: 7 | C29: Fri | D29: 0.3 | E29: 0.76458333 | G29: CLOSED | I29: 29915.74 | K29: CLOSED | M29: CLOSED | O29: CLOSED | Q29: 25644.253
A30: March | B30: 8 | C30: Sat | D30: 0.5 | E30: 0.79027778 | G30: 40586.108 | I30: 46979.241 | K30: CLOSED | M30: CLOSED | O30: CLOSED | Q30: 64392.864
A31: March | B31: 9 | C31: Sun | D31: 0.3 | E31: 0.35277778 | G31: 42208.673 | I31: 24822.715 | K31: CLOSED | M31: CLOSED | O31: CLOSED | Q31: 49425.306
A32: March | B32: 10 | C32: Mon | D32: 0.0 | E32: 0.38333333 | G32: CLOSED | I32: 15829.48 | K32: CLOSED | M32: CLOSED | O32: CLOSED | Q32: 12047.28
A33: March | B33: 11 | C33: Tue | D33: -0.1 | E33: 0.41597222 | G33: CLOSED | I33: 679.30776 | K33: CLOSED | M33: CLOSED | O33: CLOSED | Q33: 709.26646
A34: March | B34: 12 | C34: Wed | D34: 0.0 | E34: 0.45208333 | G34: CLOSED | I34: 14656.503 | K34: CLOSED | M34: CLOSED | O34: CLOSED | Q34: 12557.388
A36: April | B36: 6 | C36: Sun | D36: -0.7 | E36: 0.30763889 | G36: 68841.333 | I36: 29518.871 | K36: CLOSED | M36: CLOSED | O36: CLOSED | Q36: 82456.641
A37: April | B37: 7 | C37: Mon | D37: -1.2 | E37: 0.33958333 | G37: 46176.301 | I37: 15321.946 | K37: CLOSED | M37: CLOSED | O37: CLOSED | Q37: 51064.717
A38: April | B38: 8 | C38: Tue | D38: -1.5 | E38: 0.37152778 | G38: 43416.464 | I38: 27990.63 | K38: CLOSED | M38: CLOSED | O38: CLOSED | Q38: 59868.564
A39: April | B39: 9 | C39: Wed | D39: -1.4 | E39: 0.40486111 | G39: CLOSED | I39: 18683.42 | K39: CLOSED | M39: CLOSED | O39: CLOSED | Q39: 16339.393
A41: April | B41: 19 | C41: Sat | D41: -0.1 | E41: 0.27777778 | G41: 13403.596 | I41: 8296.9248 | K41: 42634 | M41: 28286 | O41: CLOSED | Q41: 76540.21
A42: April | B42: 20 | C42: Sun | D42: -0.4 | E42: 0.3 | G42: 27669.047 | I42: 19033.785 | K42: 71891 | M42: 33582 | O42: CLOSED | Q42: 128110.86
A43: April | B43: 21 | C43: Mon | D43: -0.6 | E43: 0.32986111 | G43: CLOSED | I43: 22813.506 | K43: CLOSED | M43: CLOSED | O43: CLOSED | Q43: 18427.867
A44: April | B44: 22 | C44: Tue | D44: -0.6 | E44: 0.35416667 | G44: CLOSED | H44: * | I44: 22500 | K44: CLOSED | M44: CLOSED | O44: CLOSED | Q44: 18000
A45: April | B45: 23 | C45: Wed | D45: -0.5 | E45: 0.37916667 | G45: CLOSED | H45: * | I45: 23000 | K45: CLOSED | M45: CLOSED | O45: CLOSED | Q45: 18500
A47: May | B47: 3 | C47: Sat | D47: -0.3 | E47: 0.22708333 | F47: * | G47: 112339.12 | H47: * | I47: 45720 | K47: CLOSED | M47: CLOSED | O47: CLOSED | Q47: 124389.16
A48: May | B48: 4 | C48: Sun | D48: -1.2 | E48: 0.26111111 | F48: * | G48: 106989.88 | H48: * | I48: 29845 | K48: 48270 | M48: 35034 | O48: CLOSED | Q48: 173026.07
A49: May | B49: 5 | C49: Mon | D49: -1.9 | E49: 0.29444444 | G49: 51261.584 | I49: 14363.148 | K49: 26632 | M49: 16972 | O49: CLOSED | Q49: 90530.079
...

Sheet cpue
A1: 2007 FALL / 2008 SPRING RAZOR CLAM CPUE TOTALS (clams per digger trip): NON-INDIAN FISHERY
A2: (FINAL ESTIMATE) | N2: 39667 | P2: update
A4: DATE | C4: DAY | D4: TIDE | E4: TIME | G4: Longbeach | I4: Twin Harbors | K4: Copalis | M4: Mocrocks | O4: Kalaloch | Q4: Daily Totals
A5: October | B5: 25 | C5: Thu | D5: -1.1 | E5: 0.77083333 | G5: CLOSED | I5: =+harvest!I5/effort!I5 -> 14.552239 | K5: CLOSED | M5: CLOSED | O5: CLOSED | Q5: 15
A6: October | B6: 26 | C6: Fri | D6: -1.7 | E6: 0.80972222 | G6: =+harvest!G6/effort!G6 -> 14.822222 | I6: =+harvest!I6/effort!I6 -> 15.085714 | K6: =+harvest!K6/effort!K6 -> 15.00137 | M6: =+harvest!M6/effort!M6 -> 14.748731 | O6: CLOSED | Q6: 14.88926
A7: October | B7: 27 | C7: Sat | D7: -1.9 | E7: 0.84305556 | G7: =+harvest!G7/effort!G7 -> 15 | I7: =+harvest!I7/effort!I7 -> 15 | K7: 14.847222 | M7: 15 | O7: CLOSED | Q7: 14.976893
A8: October | B8: 28 | C8: Sun | D8: -1.8 | E8: 0.87708333 | G8: CLOSED | I8: =+harvest!I8/effort!I8 -> 12.916667 | K8: CLOSED | M8: CLOSED | O8: CLOSED | Q8: 12.78305
A10: November | B10: 23 | C10: Fri | D10: -1.3 | E10: 0.72291667 | G10: =+harvest!G10/effort!G10 -> 15.012346 | I10: =+harvest!I10/effort!I10 -> 15 | K10: 15 | M10: 15 | O10: CLOSED | Q10: 14.264836
A11: November | B11: 24 | C11: Sat | D11: -1.7 | E11: 0.75763889 | G11: =+harvest!G11/effort!G11 -> 13.769231 | I11: =+harvest!I11/effort!I11 -> 10.470588 | K11: 14.064103 | M11: 14.915094 | O11: CLOSED | Q11: 12.711825
A12: November | B12: 25 | C12: Sun | D12: -1.8 | E12: 0.79166667 | G12: CLOSED | I12: =+harvest!I12/effort!I12 -> 13.583333 | K12: CLOSED | M12: CLOSED | O12: CLOSED | Q12: 13.952234
A13: November | B13: 26 | C13: Mon | D13: -1.6 | E13: 0.79166667 | G13: CLOSED | I13: =+harvest!I13/effort!I13 -> 8.0666667 | K13: CLOSED | M13: CLOSED | O13: CLOSED | Q13: 8.6330638
A15: December | B15: 21 | C15: Fri | D15: -0.4 | E15: 0.675 | G15: =+harvest!G15/effort!G15 -> 9.2842105 | I15: =+harvest!I15/effort!I15 -> 13.903226 | K15: 14.72973 | M15: 15.2 | O15: CLOSED | Q15: 12.085231
A16: December | B16: 22 | C16: Sat | D16: -0.9 | E16: 0.7125 | G16: =+harvest!G16/effort!G16 -> 6.9047619 | H16: * | I16: =+harvest!I16/effort!I16 -> 12.133973 | K16: 15 | M16: 13.6875 | O16: CLOSED | Q16: 10.456471
A17: December | B17: 23 | C17: Sun | D17: -1.2 | E17: 0.74861111 | G17: CLOSED | I17: =+harvest!I17/effort!I17 -> 3.5625 | K17: CLOSED | M17: CLOSED | O17: CLOSED | Q17: 3.8595847
A19: January | B19: 18 | C19: Fri | D19: 0.6 | E19: 0.62222222 | G19: CLOSED | I19: =+harvest!I19/effort!I19 -> 14.361111 | K19: CLOSED | M19: CLOSED | O19: CLOSED | Q19: 14.361111
A20: January | B20: 19 | C20: Sat | D20: 0.1 | E20: 0.66527778 | G20: =+harvest!G20/effort!G20 -> 4.8455882 | I20: =+harvest!I20/effort!I20 -> 11.442623 | K20: 14.780488 | M20: CLOSED | O20: CLOSED | Q20: 10.196638
A21: January | B21: 20 | C21: Sun | D21: -0.4 | E21: 0.70347222 | G21: =+harvest!G21/effort!G21 -> 9.9090909 | I21: =+harvest!I21/effort!I21 -> 12.214286 | K21: 14.920354 | M21: CLOSED | O21: CLOSED | Q21: 11.060176
A22: January | B22: 21 | C22: Mon | D22: -0.6 | E22: 0.73888889 | G22: CLOSED | I22: =+harvest!I22/effort!I22 -> 14 | K22: CLOSED | M22: CLOSED | O22: CLOSED | Q22: 14.255632
A24: February | B24: 6 | C24: Wed | D24: 0.1 | E24: 0.76041667 | G24: CLOSED | I24: =+harvest!I24/effort!I24 -> 2.8461538 | K24: CLOSED | M24: CLOSED | O24: CLOSED | Q24: 3.1616576
A25: February | B25: 7 | C25: Thu | D25: 0 | E25: 0.78611111 | G25: CLOSED | I25: =+harvest!I25/effort!I25 -> 3.6956522 | K25: CLOSED | M25: CLOSED | O25: CLOSED | Q25: 4.2099788
A26: February | B26: 8 | C26: Fri | D26: 0.1 | E26: 0.81041667 | G26: =+harvest!G26/effort!G26 -> 0.73170732 | I26: =+harvest!I26/effort!I26 -> 0.94444444 | K26: CLOSED | M26: CLOSED | O26: CLOSED | Q26: 1.0633233
A27: February | B27: 9 | C27: Sat | D27: 0.4 | E27: 0.83472222 | F27: * | G27: =+harvest!G27/effort!G27 -> 5.0643742 | I27: =+harvest!I27/effort!I27 -> 5.2727273 | K27: CLOSED | M27: CLOSED | O27: CLOSED | Q27: 6.8195074
A29: March | B29: 7 | C29: Fri | D29: 0.3 | E29: 0.76458333 | G29: CLOSED | I29: =+harvest!I29/effort!I29 -> 13.948718 | K29: CLOSED | M29: CLOSED | O29: CLOSED | Q29: 13.948718
A30: March | B30: 8 | C30: Sat | D30: 0.5 | E30: 0.79027778 | G30: =+harvest!G30/effort!G30 -> 4.4941176 | I30: =+harvest!I30/effort!I30 -> 7.5833333 | K30: CLOSED | M30: CLOSED | O30: CLOSED | Q30: 4.9615525
A31: March | B31: 9 | C31: Sun | D31: 0.3 | E31: 0.35277778 | G31: =+harvest!G31/effort!G31 -> 8.546875 | I31: =+harvest!I31/effort!I31 -> 6.3962264 | K31: CLOSED | M31: CLOSED | O31: CLOSED | Q31: 6.6084259
A32: March | B32: 10 | C32: Mon | D32: 0.0 | E32: 0.38333333 | G32: CLOSED | I32: =+harvest!I32/effort!I32 -> 11.614035 | K32: CLOSED | M32: CLOSED | O32: CLOSED | Q32: 10.311342
A33: March | B33: 11 | C33: Tue | D33: -0.1 | E33: 0.41597222 | G33: CLOSED | I33: =+harvest!I33/effort!I33 -> 0.6875 | K33: CLOSED | M33: CLOSED | O33: CLOSED | Q33: 0.83738515
A34: March | B34: 12 | C34: Wed | D34: 0.0 | E34: 0.45208333 | G34: CLOSED | I34: =+harvest!I34/effort!I34 -> 13.586207 | K34: CLOSED | M34: CLOSED | O34: CLOSED | Q34: 13.579283
A36: April | B36: 6 | C36: Sun | D36: -0.7 | E36: 0.30763889 | G36: =+harvest!G36/effort!G36 -> 12.785714 | I36: =+harvest!I36/effort!I36 -> 12.208791 | K36: CLOSED | M36: CLOSED | O36: CLOSED | Q36: 12.742832
A37: April | B37: 7 | C37: Mon | D37: -1.2 | E37: 0.33958333 | G37: =+harvest!G37/effort!G37 -> 9.7413793 | I37: =+harvest!I37/effort!I37 -> 9.3571429 | K37: CLOSED | M37: CLOSED | O37: CLOSED | Q37: 9.4033366
A38: April | B38: 8 | C38: Tue | D38: -1.5 | E38: 0.37152778 | G38: =+harvest!G38/effort!G38 -> 11.55102 | I38: =+harvest!I38/effort!I38 -> 14.666667 | K38: CLOSED | M38: CLOSED | O38: CLOSED | Q38: 12.309011
A39: April | B39: 9 | C39: Wed | D39: -1.4 | E39: 0.40486111 | G39: CLOSED | I39: =+harvest!I39/effort!I39 -> 14.045455 | K39: CLOSED | M39: CLOSED | O39: CLOSED | Q39: 13.706289
A41: April | B41: 19 | C41: Sat | D41: -0.1 | E41: 0.27777778 | G41: =+harvest!G41/effort!G41 -> 2.9298246 | I41: =+harvest!I41/effort!I41 -> 3.9512195 | K41: 12.538462 | M41: 9.2911392 | O41: CLOSED | Q41: 7.0415938
A42: April | B42: 20 | C42: Sun | D42: -0.4 | E42: 0.3 | G42: =+harvest!G42/effort!G42 -> 5.8930481 | I42: =+harvest!I42/effort!I42 -> 12.028169 | K42: 15.571429 | M42: 14.932203 | O42: CLOSED | Q42: 11.761626
A43: April | B43: 21 | C43: Mon | D43: -0.6 | E43: 0.32986111 | G43: CLOSED | I43: =+harvest!I43/effort!I43 -> 15 | K43: CLOSED | M43: CLOSED | O43: CLOSED | Q43: 15
A44: April | B44: 22 | C44: Tue | D44: -0.6 | E44: 0.35416667 | G44: CLOSED | I44: =+harvest!I44/effort!I44 -> 15 | K44: CLOSED | M44: CLOSED | O44: CLOSED | Q44: 15
A45: April | B45: 23 | C45: Wed | D45: -0.5 | E45: 0.37916667 | G45: CLOSED | I45: =+harvest!I45/effort!I45 -> 14.83871 | K45: CLOSED | M45: CLOSED | O45: CLOSED | Q45: 14.8
A47: May | B47: 3 | C47: Sat | D47: -0.3 | E47: 0.22708333 | F47: * | G47: =+harvest!G47/effort!G47 -> 14.348094 | H47: * | I47: =+harvest!I47/effort!I47 -> 15 | K47: CLOSED | M47: CLOSED | O47: CLOSED | Q47: 14.531344
A48: May | B48: 4 | C48: Sun | D48: -1.2 | E48: 0.26111111 | F48: * | G48: =+harvest!G48/effort!G48 -> 14.349174 | H48: * | I48: =+harvest!I48/effort!I48 -> 14.6875 | K48: 15 | M48: 15 | O48: CLOSED | Q48: 14.675932
A49: May | B49: 5 | C49: Mon | D49: -1.9 | E49: 0.29444444 | G49: =+harvest!G49/effort!G49 -> 14.164948 | I49: =+harvest!I49/effort!I49 -> 15 | K49: 15 | M49: 15 | O49: CLOSED | Q49: 14.675932
...

Sheet effort
A1: 2007 FALL / 2008 SPRING RAZOR CLAM EFFORT TOTALS (number of diggers): NON-INDIAN FISHERY
A2: (FINAL ESTIMATE) | N2: 39667 | P2: update
A4: DATE | C4: DAY | D4: TIDE | E4: TIME | G4: Longbeach | I4: Twin Harbors | K4: Copalis | M4: Mocrocks | O4: Kalaloch | Q4: Daily Totals
A5: October | B5: 25 | C5: Thu | D5: -1.1 | E5: 0.77083333 | G5: CLOSED | I5: 4109.9998 | K5: CLOSED | M5: CLOSED | O5: CLOSED | Q5: 2290.4339
A6: October | B6: 26 | C6: Fri | D6: -1.7 | E6: 0.80972222 | G6: 4947.1783 | I6: 2368.0333 | K6: 3650 | M6: 4728 | O6: CLOSED | Q6: 10448.5
A7: October | B7: 27 | C7: Sat | D7: -1.9 | E7: 0.84305556 | G7: 13677.702 | I7: 3988.7461 | K7: 5184 | M7: 3021 | O7: CLOSED | Q7: 21648.934
A8: October | B8: 28 | C8: Sun | D8: -1.8 | E8: 0.87708333 | G8: CLOSED | I8: 4146.1698 | K8: CLOSED | M8: CLOSED | O8: CLOSED | Q8: 2143.9749
A10: November | B10: 23 | C10: Fri | D10: -1.3 | E10: 0.72291667 | G10: 12808.595 | I10: 3136.4874 | K10: 5113 | M10: 3630 | O10: CLOSED | Q10: 21026.835
A11: November | B11: 24 | C11: Sat | D11: -1.7 | E11: 0.75763889 | G11: 9853.7499 | I11: 4755.6272 | K11: 3699 | M11: 2385 | O11: CLOSED | Q11: 19377.094
A12: November | B12: 25 | C12: Sun | D12: -1.8 | E12: 0.79166667 | G12: CLOSED | I12: 1773.3763 | K12: CLOSED | M12: CLOSED | O12: CLOSED | Q12: 1520.1666
A13: November | B13: 26 | C13: Mon | D13: -1.6 | E13: 0.79166667 | G13: CLOSED | I13: 142.01501 | K13: CLOSED | M13: CLOSED | O13: CLOSED | Q13: 109.56379
A15: December | B15: 21 | C15: Fri | D15: -0.4 | E15: 0.675 | G15: 3640.2803 | I15: 1007.0456 | K15: 1861 | M15: 1310 | O15: CLOSED | Q15: 6511.02
A16: December | B16: 22 | C16: Sat | D16: -0.9 | E16: 0.7125 | G16: 4318.5057 | H16: * | I16: =+(K16+M16)*(I11+I10)/(K10+K11+M10+M11) -> 2431.987 | K16: 2846 | M16: 1723 | O16: CLOSED | Q16: 11063.823
A17: December | B17: 23 | C17: Sun | D17: -1.2 | E17: 0.74861111 | G17: CLOSED | I17: 593.15304 | K17: CLOSED | M17: CLOSED | O17: CLOSED | Q17: 508.46031
A19: January | B19: 18 | C19: Fri | D19: 0.6 | E19: 0.62222222 | G19: CLOSED | I19: 1819.9358 | K19: CLOSED | M19: CLOSED | O19: CLOSED | Q19: 1560.0782
A20: January | B20: 19 | C20: Sat | D20: 0.1 | E20: 0.66527778 | G20: 7212.2346 | I20: 3245.3872 | K20: 7795 | M20: CLOSED | O20: CLOSED | Q20: 15422.579
A21: January | B21: 20 | C21: Sun | D21: -0.4 | E21: 0.70347222 | G21: 6909.7805 | I21: 2090.5772 | K21: 4944 | M21: CLOSED | O21: CLOSED | Q21: 12292.566
A22: January | B22: 21 | C22: Mon | D22: -0.6 | E22: 0.73888889 | G22: CLOSED | I22: 1613.1778 | K22: CLOSED | M22: CLOSED | O22: CLOSED | Q22: 1382.8419
A24: February | B24: 6 | C24: Wed | D24: 0.1 | E24: 0.76041667 | G24: CLOSED | I24: 294.21223 | K24: CLOSED | M24: CLOSED | O24: CLOSED | Q24: 252.20345
A25: February | B25: 7 | C25: Thu | D25: 0 | E25: 0.78611111 | G25: CLOSED | I25: 291.19776 | K25: CLOSED | M25: CLOSED | O25: CLOSED | Q25: 249.6194
A26: February | B26: 8 | C26: Fri | D26: 0.1 | E26: 0.81041667 | G26: 524.18301 | I26: 270.09647 | K26: CLOSED | M26: CLOSED | O26: CLOSED | Q26: 385.74029
A27: February | B27: 9 | C27: Sat | D27: 0.4 | E27: 0.83472222 | F27: * | G27: =+I27*(G30+G31+G36+G37+G38)/(I30+I31+I36+I37+I38) -> 600.16543 | I27: 345.62151 | K27: CLOSED | M27: CLOSED | O27: CLOSED | Q27: 676.96779
A29: March | B29: 7 | C29: Fri | D29: 0.3 | E29: 0.76458333 | G29: CLOSED | I29: 2144.6946 | K29: CLOSED | M29: CLOSED | O29: CLOSED | Q29: 1838.4667
A30: March | B30: 8 | C30: Sat | D30: 0.5 | E30: 0.79027778 | G30: 9030.9402 | I30: 6195.0647 | K30: CLOSED | M30: CLOSED | O30: CLOSED | Q30: 12978.37
A31: March | B31: 9 | C31: Sun | D31: 0.3 | E31: 0.35277778 | G31: 4938.4919 | I31: 3880.8374 | K31: CLOSED | M31: CLOSED | O31: CLOSED | Q31: 7479.1344
A32: March | B32: 10 | C32: Mon | D32: 0.0 | E32: 0.38333333 | G32: CLOSED | I32: 1362.9613 | K32: CLOSED | M32: CLOSED | O32: CLOSED | Q32: 1168.3523
A33: March | B33: 11 | C33: Tue | D33: -0.1 | E33: 0.41597222 | G33: CLOSED | I33: 988.08401 | K33: CLOSED | M33: CLOSED | O33: CLOSED | Q33: 847.00149
A34: March | B34: 12 | C34: Wed | D34: 0.0 | E34: 0.45208333 | G34: CLOSED | I34: 1078.7782 | K34: CLOSED | M34: CLOSED | O34: CLOSED | Q34: 924.74598
A36: April | B36: 6 | C36: Sun | D36: -0.7 | E36: 0.30763889 | G36: 5384.2384 | I36: 2417.8373 | K36: CLOSED | M36: CLOSED | O36: CLOSED | Q36: 6470.8256
A37: April | B37: 7 | C37: Mon | D37: -1.2 | E37: 0.33958333 | G37: 4740.222 | I37: 1637.4599 | K37: CLOSED | M37: CLOSED | O37: CLOSED | Q37: 5430.4891
A38: April | B38: 8 | C38: Tue | D38: -1.5 | E38: 0.37152778 | G38: 3758.6691 | I38: 1908.4521 | K38: CLOSED | M38: CLOSED | O38: CLOSED | Q38: 4863.7996
A39: April | B39: 9 | C39: Wed | D39: -1.4 | E39: 0.40486111 | G39: CLOSED | I39: 1330.2111 | K39: CLOSED | M39: CLOSED | O39: CLOSED | Q39: 1192.1092
A41: April | B41: 19 | C41: Sat | D41: -0.1 | E41: 0.27777778 | G41: 4574.88 | I41: 2099.839 | K41: 3670 | M41: 2722 | O41: CLOSED | Q41: 10869.728
A42: April | B42: 20 | C42: Sun | D42: -0.4 | E42: 0.3 | G42: 4695.2012 | I42: 1582.4341 | K42: 4640 | M42: 2251 | O42: CLOSED | Q42: 10892.275
A43: April | B43: 21 | C43: Mon | D43: -0.6 | E43: 0.32986111 | G43: CLOSED | I43: 1520.9004 | K43: CLOSED | M43: CLOSED | O43: CLOSED | Q43: 1228.5244
A44: April | B44: 22 | C44: Tue | D44: -0.6 | E44: 0.35416667 | G44: CLOSED | H44: * | I44: 1500 | K44: CLOSED | M44: CLOSED | O44: CLOSED | Q44: 1200
A45: April | B45: 23 | C45: Wed | D45: -0.5 | E45: 0.37916667 | G45: CLOSED | H45: * | I45: 1550 | K45: CLOSED | M45: CLOSED | O45: CLOSED | Q45: 1250
A47: May | B47: 3 | C47: Sat | D47: -0.3 | E47: 0.22708333 | F47: * | G47: 7829.55 | H47: * | I47: 3048 | K47: CLOSED | M47: CLOSED | O47: CLOSED | Q47: 8560.0587
A48: May | B48: 4 | C48: Sun | D48: -1.2 | E48: 0.26111111 | F48: * | G48: 7456.17 | H48: * | I48: 2032 | K48: 3218 | M48: 2336 | O48: CLOSED | Q48: 11789.784
A49: May | B49: 5 | C49: Mon | D49: -1.9 | E49: 0.29444444 | G49: 3618.9037 | I49: 957.54318 | K49: 1775 | M49: 1131 | O49: CLOSED | Q49: 6168.6083
...

Sheet Wastage - TH
A1: EventID | B1: BeachName | C1: Date | D1: SumOfWastage | E1: SumOfTotHarvest
A2: 30 | B2: Twin Harbors | C2: 39380 | D2: 2392 | E2: 59809.699
A3: 31 | B3: Twin Harbors | C3: 39381 | D3: 1607 | E3: 35723.474
A4: 32 | B4: Twin Harbors | C4: 39382 | D4: 2094 | E4: 59831.192
A5: 34 | B5: Twin Harbors | C5: 39409 | D5: 2348 | E5: 46973.541
A6: 80 | B6: Twin Harbors | C6: 39409 | D6: 2353 | E6: 47047.31
A7: 38 | B7: Twin Harbors | C7: 39437 | D7: 140 | E7: 14001.183
A8: 41 | B8: Twin Harbors | C8: 39466 | D8: 372 | E8: 37135.742
A9: 446 | B9: Twin Harbors | C9: 39514 | D9: 717 | E9: 29915.74
A10: 453 | B10: Twin Harbors | C10: 39545 | D10: 409 | E10: 15321.946
A11: 454 | B11: Twin Harbors | C11: 39546 | D11: 560 | E11: 27990.63
A12: 455 | B12: Twin Harbors | C12: 39547 | D12: 934 | E12: 18683.42
A13: 459 | B13: Twin Harbors | C13: 39573 | D13: 1292 | E13: 14363.148
D15: =SUM(D2:D14) -> 15218 | E15: =SUM(E2:E14) -> 406797.03

Sheet Wastage - LB
A1: EventID | B1: BeachName | C1: Date | D1: SumOfWastage | E1: SumOfTotHarvest
A2: 661 | B2: LongBeach | C2: 39516 | D2: 421 | E2: 42208.673
A3: 664 | B3: LongBeach | C3: 39546 | D3: 433 | E3: 43416.464
A4: 668 | B4: LongBeach | C4: 39575 | D4: 2633 | E4: 57404.237
D7: =SUM(D2:D6) -> 3487 | E7: =SUM(E2:E6) -> 143029.37

Sheet table
A1: 2007-2008 State (non-Indian) Recreational Razor Clam Effort, Harvest and CPUE totals.
E2: LONG BEACH | H2: TWIN HARBORS | K2: COPALIS | O2: MOCROCKS | Q2: KALALOCH | T2: DAILY TOTALS
A3: DATE | B3: DAY | C3: TIDE | D3: TIME | E3: Effort | F3: Harvest | G3: CPUE | H3: Effort | I3: Harvest | J3: CPUE | K3: Effort | L3: Harvest | M3: CPUE | N3: Effort | O3: Harvest | P3: CPUE | Q3: Effort | R3: Harvest | S3: CPUE | T3: Effort | U3: Harvest
A4: 39380 | B4: Fri | C4: -1.1 | D4: 0.77083333 | E4: =+effort!G5 -> CLOSED | F4: =+harvest!G5 -> CLOSED | G4: =+cpue!G5 -> CLOSED | H4: =+effort!I5 -> 4109.9998 | I4: =+harvest!I5 -> 59809.699 | J4: =+cpue!I5 -> 14.552239 | K4: =+effort!K5 -> CLOSED | L4: =+harvest!K5 -> CLOSED | M4: =+cpue!K5 -> CLOSED | N4: =+effort!M5 -> CLOSED | O4: =+harvest!M5 -> CLOSED | P4: =+cpue!M5 -> CLOSED | Q4: CLOSED | R4: CLOSED | S4: CLOSED | T4: =+H4 -> 4109.9998 | U4: =+I4 -> 59809.699
A5: 39381 | B5: Sat | C5: -1.7 | D5: 0.80972222 | E5: =+effort!G6 -> 4947.1783 | F5: =+harvest!G6 -> 73328.176 | G5: =+cpue!G6 -> 14.822222 | H5: =+effort!I6 -> 2368.0333 | I5: =+harvest!I6 -> 35723.474 | J5: =+cpue!I6 -> 15.085714 | K5: =+effort!K6 -> 3650 | L5: =+harvest!K6 -> 54755 | M5: =+cpue!K6 -> 15.00137 | N5: =+effort!M6 -> 4728 | O5: =+harvest!M6 -> 69732 | P5: =+cpue!M6 -> 14.748731 | Q5: CLOSED | R5: CLOSED | S5: CLOSED | T5: =+E5+H5+K5+N5 -> 15693.212 | U5: =+F5+I5+L5+O5 -> 233538.65
A6: 39382 | B6: Sun | C6: -1.9 | D6: 0.84305556 | E6: =+effort!G7 -> 13677.702 | F6: =+harvest!G7 -> 205165.53 | G6: =+cpue!G7 -> 15 | H6: =+effort!I7 -> 3988.7461 | I6: =+harvest!I7 -> 59831.192 | J6: =+cpue!I7 -> 15 | K6: =+effort!K7 -> 5184 | L6: =+harvest!K7 -> 77105 | M6: =+cpue!K7 -> 14.847222 | N6: =+effort!M7 -> 3021 | O6: =+harvest!M7 -> 45317 | P6: =+cpue!M7 -> 15 | Q6: CLOSED | R6: CLOSED | S6: CLOSED | T6: =+E6+H6+K6+N6 -> 25871.448 | U6: =+F6+I6+L6+O6 -> 387418.73
A7: 39383 | B7: Mon | C7: -1.8 | D7: 0.87708333 | E7: =+effort!G8 -> CLOSED | F7: =+harvest!G8 -> CLOSED | G7: =+cpue!G8 -> CLOSED | H7: =+effort!I8 -> 4146.1698 | I7: =+harvest!I8 -> 53554.693 | J7: =+cpue!I8 -> 12.916667 | K7: =+effort!K8 -> CLOSED | L7: =+harvest!K8 -> CLOSED | M7: =+cpue!K8 -> CLOSED | N7: =+effort!M8 -> CLOSED | O7: =+harvest!M8 -> CLOSED | P7: =+cpue!M8 -> CLOSED | Q7: CLOSED | R7: CLOSED | S7: CLOSED | T7: =+H7 -> 4146.1698 | U7: =+I7 -> 53554.693
A8: Tide Series Totals | E8: =SUM(E5:E7) -> 18624.881 | F8: =SUM(F5:F7) -> 278493.71 | G8: =+F8/E8 -> 14.952778 | H8: =SUM(H4:H7) -> 14612.949 | I8: =SUM(I4:I7) -> 208919.06 | J8: =+I8/H8 -> 14.296844 | K8: =SUM(K5:K7) -> 8834 | L8: =SUM(L5:L7) -> 131860 | N8: =SUM(N5:N7) -> 7749 | O8: =SUM(O5:O7) -> 115049 | P8: =+O8/N8 -> 14.846948 | Q8: 0 | R8: 0 | S8: #DIV/0! | T8: =SUM(T4:T7) -> 49820.83 | U8: =SUM(U4:U7) -> 734321.77
A9: 39409 | B9: Fri | C9: -1.3 | D9: 0.72291667 | E9: =+effort!G10 -> 12808.595 | F9: =+harvest!G10 -> 192287.05 | G9: =+cpue!G10 -> 15.012346 | H9: =+effort!I10 -> 3136.4874 | I9: =+harvest!I10 -> 47047.31 | J9: =+cpue!I10 -> 15 | K9: =+effort!K10 -> 5113 | L9: =+harvest!K10 -> 76690 | M9: =+cpue!K10 -> 15 | N9: =+effort!M10 -> 3630 | O9: =+harvest!M10 -> 54433 | P9: =+cpue!M10 -> 15 | Q9: CLOSED | R9: CLOSED | S9: CLOSED | T9: =+E9+H9+K9+N9 -> 24688.082 | U9: =+F9+I9+L9+O9 -> 370457.36
A10: 39410 | B10: Sat | C10: -1.7 | D10: 0.75763889 | E10: =+effort!G11 -> 9853.7499 | F10: =+harvest!G11 -> 135678.56 | G10: =+cpue!G11 -> 13.769231 | H10: =+effort!I11 -> 4755.6272 | I10: =+harvest!I11 -> 49794.214 | J10: =+cpue!I11 -> 10.470588 | K10: =+effort!K11 -> 3699 | L10: =+harvest!K11 -> 52027 | M10: =+cpue!K11 -> 14.064103 | N10: =+effort!M11 -> 2385 | O10: =+harvest!M11 -> 35545 | P10: =+cpue!M11 -> 14.915094 | Q10: CLOSED | R10: CLOSED | S10: CLOSED | T10: =+E10+H10+K10+N10 -> 20693.377 | U10: =+F10+I10+L10+O10 -> 273044.77
A11: 39411 | B11: Sun | C11: -1.8 | D11: 0.79166667 | E11: =+effort!G12 -> CLOSED | F11: =+harvest!G12 -> CLOSED | G11: =+cpue!G12 -> CLOSED | H11: =+effort!I12 -> 1773.3763 | I11: =+harvest!I12 -> 24088.361 | J11: =+cpue!I12 -> 13.583333 | K11: =+effort!K12 -> CLOSED | L11: =+harvest!K12 -> CLOSED | M11: =+cpue!K12 -> CLOSED | N11: =+effort!M12 -> CLOSED | O11: =+harvest!M12 -> CLOSED | P11: =+cpue!M12 -> CLOSED | Q11: CLOSED | R11: CLOSED | S11: CLOSED | T11: =+H11 -> 1773.3763 | U11: =+I11 -> 24088.361
A12: 39412 | B12: Mon | C12: -1.5 | D12: 0.825 | E12: =+effort!G13 -> CLOSED | F12: =+harvest!G13 -> CLOSED | G12: =+cpue!G13 -> CLOSED | H12: =+effort!I13 -> 142.01501 | I12: =+harvest!I13 -> 1145.5877 | J12: =+cpue!I13 -> 8.0666667 | K12: =+effort!K13 -> CLOSED | L12: =+harvest!K13 -> CLOSED | M12: =+cpue!K13 -> CLOSED | N12: =+effort!M13 -> CLOSED | O12: =+harvest!M13 -> CLOSED | P12: =+cpue!M13 -> CLOSED | Q12: CLOSED | R12: CLOSED | S12: CLOSED | T12: =+H12 -> 142.01501 | U12: =+I12 -> 1145.5877
A13: Tide Series Totals | E13: =SUM(E9:E12) -> 22662.345 | F13: =SUM(F9:F12) -> 327965.61 | G13: =+F13/E13 -> 14.47183 | H13: =SUM(H9:H12) -> 9807.5058 | I13: =SUM(I9:I12) -> 122075.47 | J13: =+I13/H13 -> 12.447148 | K13: =SUM(K9:K12) -> 8812 | L13: =SUM(L9:L12) -> 128717 | N13: =SUM(N9:N12) -> 6015 | O13: =SUM(O9:O12) -> 89978 | Q13: 0 | R13: 0 | S13: 0 | T13: =SUM(T9:T12) -> 47296.85 | U13: =SUM(U9:U12) -> 668736.08
A14: 39437 | B14: Fri | C14: -0.4 | D14: 0.675 | E14: =+effort!G15 -> 3640.2803 | F14: =+harvest!G15 -> 33797.129 | G14: =+cpue!G15 -> 9.2842105 | H14: =+effort!I15 -> 1007.0456 | I14: =+harvest!I15 -> 14001.183 | J14: =+cpue!I15 -> 13.903226 | K14: =+effort!K15 -> 1861 | L14: =+harvest!K15 -> 27481 | M14: =+cpue!K15 -> 14.72973 | N14: =+effort!M15 -> 1310 | O14: =+harvest!M15 -> 19911 | P14: =+cpue!M15 -> 15.2 | Q14: CLOSED | R14: CLOSED | S14: CLOSED | T14: =+E14+H14+K14+N14 -> 7818.326 | U14: =+F14+I14+L14+O14 -> 95190.312
A15: 39438 | B15: Sat | C15: -0.9 | D15: 0.7125 | E15: =+effort!G16 -> 4318.5057 | F15: =+harvest!G16 -> 29818.254 | G15: =+cpue!G16 -> 6.9047619 | H15: =+effort!I16 -> 2431.987 | I15: =+harvest!I16 -> 29509.664 | J15: =+cpue!I16 -> 12.133973 | K15: =+effort!K16 -> 2846 | L15: =+harvest!K16 -> 42683 | M15: =+cpue!K16 -> 15 | N15: =+effort!M16 -> 1723 | O15: =+harvest!M16 -> 23958 | P15: =+cpue!M16 -> 13.6875 | Q15: CLOSED | R15: CLOSED | S15: CLOSED | T15: =+E15+H15+K15+N15 -> 11319.493 | U15: =+F15+I15+L15+O15 -> 125968.92
A16: 39439 | B16: Sun | C16: -1.2 | D16: 0.74861111 | E16: =+effort!G17 -> CLOSED | F16: =+harvest!G17 -> CLOSED | G16: =+cpue!G17 -> CLOSED | H16: =+effort!I17 -> 593.15304 | I16: =+harvest!I17 -> 2113.1077 | J16: =+cpue!I17 -> 3.5625 | K16: =+effort!K17 -> CLOSED | L16: =+harvest!K17 -> CLOSED | M16: =+cpue!K17 -> CLOSED | N16: =+effort!M17 -> CLOSED | O16: =+harvest!M17 -> CLOSED | P16: =+cpue!M17 -> CLOSED | Q16: CLOSED | R16: CLOSED | S16: CLOSED | T16: =+H16 -> 593.15304 | U16: =+I16 -> 2113.1077
A17: Tide Series Totals | E17: =SUM(E14:E16) -> 7958.786 | F17: =SUM(F14:F16) -> 63615.383 | G17: =+F17/E17 -> 7.9931013 | H17: =SUM(H14:H16) -> 4032.1857 | I17: =SUM(I14:I16) -> 45623.955 | J17: =+I17/H17 -> 11.314944 | K17: =SUM(K14:K16) -> 4707 | L17: =SUM(L14:L16) -> 70164 | N17: =SUM(N14:N16) -> 3033 | O17: =SUM(O14:O16) -> 43869 | P17: =+O17/N17 -> 14.463897 | Q17: 0 | R17: 0 | S17: 0 | T17: =SUM(T14:T16) -> 19730.972 | U17: =SUM(U14:U16) -> 223272.34
A18: 39465 | B18: Fri | C18: 0.6 | D18: 0.62222222 | E18: =+effort!G19 -> CLOSED | F18: =+harvest!G19 -> CLOSED | G18: =+cpue!G19 -> CLOSED | H18: =+effort!I19 -> 1819.9358 | I18: =+harvest!I19 -> 26136.3 | J18: =+cpue!I19 -> 14.361111 | K18: =+effort!K19 -> CLOSED | L18: =+harvest!K19 -> CLOSED | M18: =+cpue!K19 -> CLOSED | N18: =+effort!M19 -> CLOSED | O18: =+harvest!M19 -> CLOSED | P18: =+cpue!M19 -> CLOSED | Q18: CLOSED | R18: CLOSED | S18: CLOSED | T18: =+H18 -> 1819.9358 | U18: =+I18 -> 26136.3
A19: 39466 | B19: Sat | C19: 0.1 | D19: 0.66527778 | E19: =+effort!G20 -> 7212.2346 | F19: =+harvest!G20 -> 34947.519 | G19: =+cpue!G20 -> 4.8455882 | H19: =+effort!I20 -> 3245.3872 | I19: =+harvest!I20 -> 37135.742 | J19: =+cpue!I20 -> 11.442623 | K19: =+effort!K20 -> 7795 | L19: =+harvest!K20 -> 115271 | M19: =+cpue!K20 -> 14.780488 | N19: =+effort!M20 -> CLOSED | O19: =+harvest!M20 -> CLOSED | P19: =+cpue!M20 -> CLOSED | Q19: CLOSED | R19: CLOSED | S19: CLOSED | T19: =+E19+H19+K19 -> 18252.622 | U19: =+F19+I19+L19 -> 187354.26
A20: 39467 | B20: Sun | C20: -0.4 | D20: 0.70347222 | E20: =+effort!G21 -> 6909.7805 | F20: =+harvest!G21 -> 68469.643 | G20: =+cpue!G21 -> 9.9090909 | H20: =+effort!I21 -> 2090.5772 | I20: =+harvest!I21 -> 25534.907 | J20: =+cpue!I21 -> 12.214286 | K20: =+effort!K21 -> 4944 | L20: =+harvest!K21 -> 73652 | M20: =+cpue!K21 -> 14.920354 | N20: =+effort!M21 -> CLOSED | O20: =+harvest!M21 -> CLOSED | P20: =+cpue!M21 -> CLOSED | Q20: CLOSED | R20: CLOSED | S20: CLOSED | T20: =+E20+H20+K20 -> 13944.358 | U20: =+F20+I20+L20 -> 167656.55
A21: 39468 | B21: Mon | C21: -0.6 | D21: 0.73888889 | E21: =+effort!G22 -> CLOSED | F21: =+harvest!G22 -> CLOSED | G21: =+cpue!G22 -> CLOSED | H21: =+effort!I22 -> 1613.1778 | I21: =+harvest!I22 -> 22584.489 | J21: =+cpue!I22 -> 14 | K21: =+effort!K22 -> CLOSED | L21: =+harvest!K22 -> CLOSED | M21: =+cpue!K22 -> CLOSED | N21: =+effort!M22 -> CLOSED | O21: =+harvest!M22 -> CLOSED | P21: =+cpue!M22 -> CLOSED | Q21: CLOSED | R21: CLOSED | S21: CLOSED | T21: =+H21 -> 1613.1778 | U21: =+I21 -> 22584.489
A22: Tide Series Totals | E22: =SUM(E19:E21) -> 14122.015 | F22: =SUM(F19:F21) -> 103417.16 | G22: =+F22/E22 -> 7.3231165 | H22: =SUM(H18:H21) -> 8769.078 | I22: =SUM(I18:I21) -> 111391.44 | J22: =+I22/H22 -> 12.702754 | K22: =SUM(K19:K21) -> 12739 | L22: =SUM(L19:L21) -> 188923 | Q22: 0 | R22: 0 | S22: 0 | T22: =SUM(T18:T21) -> 35630.093 | U22: =SUM(U18:U21) -> 403731.6
A23: 39484 | B23: Wed | C23: 0.1 | D23: 0.76041667 | E23: =+effort!G24 -> CLOSED | F23: =+harvest!G24 -> CLOSED | G23: =+cpue!G24 -> CLOSED | H23: =+effort!I24 -> 294.21223 | I23: =+harvest!I24 -> 837.37327 | J23: =+cpue!I24 -> 2.8461538 | K23: =+effort!K24 -> CLOSED | L23: =+harvest!K24 -> CLOSED | M23: =+cpue!K24 -> CLOSED | N23: =+effort!M24 -> CLOSED | O23: =+harvest!M24 -> CLOSED | P23: =+cpue!M24 -> CLOSED | Q23: CLOSED | R23: CLOSED | S23: CLOSED | T23: =+H23 -> 294.21223 | U23: =+I23 -> 837.37327
A24: 39485 | B24: Thu | C24: 0 | D24: 0.78611111 | E24: =+effort!G25 -> CLOSED | F24: =+harvest!G25 -> CLOSED | G24: =+cpue!G25 -> CLOSED | H24: =+effort!I25 -> 291.19776 | I24: =+harvest!I25 -> 1076.1656 | J24: =+cpue!I25 -> 3.6956522 | K24: =+effort!K25 -> CLOSED | L24: =+harvest!K25 -> CLOSED | M24: =+cpue!K25 -> CLOSED | N24: =+effort!M25 -> CLOSED | O24: =+harvest!M25 -> CLOSED | P24: =+cpue!M25 -> CLOSED | Q24: CLOSED | R24: CLOSED | S24: CLOSED | T24: =+H24 -> 291.19776 | U24: =+I24 -> 1076.1656
A25: 39486 | B25: Fri | C25: 0.1 | D25: 0.81041667 | E25: =+effort!G26 -> 524.18301 | F25: =+harvest!G26 -> 383.54854 | G25: =+cpue!G26 -> 0.73170732 | H25: =+effort!I26 -> 270.09647 | I25: =+harvest!I26 -> 255.09111 | J25: =+cpue!I26 -> 0.94444444 | K25: =+effort!K26 -> CLOSED | L25: =+harvest!K26 -> CLOSED | M25: =+cpue!K26 -> CLOSED | N25: =+effort!M26 -> CLOSED | O25: =+harvest!M26 -> CLOSED | P25: =+cpue!M26 -> CLOSED | Q25: CLOSED | R25: CLOSED | S25: CLOSED | T25: =+E25+H25 -> 794.27948 | U25: =+F25+I25 -> 638.63966
A26: 39487 | B26: Sat | C26: 0.4 | D26: 0.83472222 | E26: =+effort!G27 -> 600.16543 | F26: =+harvest!G27 -> 3039.4623 | G26: =+cpue!G27 -> 5.0643742 | H26: =+effort!I27 -> 345.62151 | I26: =+harvest!I27 -> 1822.3679 | J26: =+cpue!I27 -> 5.2727273 | K26: =+effort!K27 -> CLOSED | L26: =+harvest!K27 -> CLOSED | M26: =+cpue!K27 -> CLOSED | N26: =+effort!M27 -> CLOSED | O26: =+harvest!M27 -> CLOSED | P26: =+cpue!M27 -> CLOSED | Q26: CLOSED | R26: CLOSED | S26: CLOSED | T26: =+E26+H26 -> 945.78694 | U26: =+F26+I26 -> 4861.8303
A27: Tide Series Totals | E27: =SUM(E25:E26) -> 1124.3484 | F27: =SUM(F25:F26) -> 3423.0109 | G27: =+F27/E27 -> 3.0444395 | H27: =SUM(H23:H26) -> 1201.128 | I27: =SUM(I23:I26) -> 3990.998 | J27: =+I27/H27 -> 3.3227084 | Q27: 0 | R27: 0 | S27: 0 | T27: =SUM(T23:T26) -> 2325.4764 | U27: =SUM(U23:U26) -> 7414.0088
A28: 39514 | B28: Fri | C28: 0.3 | D28: 0.76458333 | E28: =+effort!G29 -> CLOSED | F28: =+harvest!G29 -> CLOSED | G28: =+cpue!G29 -> CLOSED | H28: =+effort!I29 -> 2144.6946 | I28: =+harvest!I29 -> 29915.74 | J28: =+cpue!I29 -> 13.948718 | K28: =+effort!K29 -> CLOSED | L28: =+harvest!K29 -> CLOSED | M28: =+cpue!K29 -> CLOSED | N28: =+effort!M29 -> CLOSED | O28: =+harvest!M29 -> CLOSED | P28: =+cpue!M29 -> CLOSED | Q28: CLOSED | R28: CLOSED | S28: CLOSED | T28: =+H28 -> 2144.6946 | U28: =+I28 -> 29915.74
A29: 39515 | B29: Sat | C29: 0.5 | D29: 0.79027778 | E29: =+effort!G30 -> 9030.9402 | F29: =+harvest!G30 -> 40586.108 | G29: =+cpue!G30 -> 4.4941176 | H29: =+effort!I30 -> 6195.0647 | I29: =+harvest!I30 -> 46979.241 | J29: =+cpue!I30 -> 7.5833333 | K29: =+effort!K30 -> CLOSED | L29: =+harvest!K30 -> CLOSED | M29: =+cpue!K30 -> CLOSED | N29: =+effort!M30 -> CLOSED | O29: =+harvest!M30 -> CLOSED | P29: =+cpue!M30 -> CLOSED | Q29: CLOSED | R29: CLOSED | S29: CLOSED | T29: =+E29+H29 -> 15226.005 | U29: =+F29+I29 -> 87565.348
A30: 39516 | B30: Sun | C30: 0.3 | D30: 0.35277778 | E30: =+effort!G31 -> 4938.4919 | F30: =+harvest!G31 -> 42208.673 | G30: =+cpue!G31 -> 8.546875 | H30: =+effort!I31 -> 3880.8374 | I30: =+harvest!I31 -> 24822.715 | J30: =+cpue!I31 -> 6.3962264 | K30: =+effort!K31 -> CLOSED | L30: =+harvest!K31 -> CLOSED | M30: =+cpue!K31 -> CLOSED | N30: =+effort!M31 -> CLOSED | O30: =+harvest!M31 -> CLOSED | P30: =+cpue!M31 -> CLOSED | Q30: CLOSED | R30: CLOSED | S30: CLOSED | T30: =+E30+H30 -> 8819.3293 | U30: =+F30+I30 -> 67031.388
A31: 39517 | B31: Mon | C31: 0.0 | D31: 0.38333333 | E31: =+effort!G32 -> CLOSED | F31: =+harvest!G32 -> CLOSED | G31: =+cpue!G32 -> CLOSED | H31: =+effort!I32 -> 1362.9613 | I31: =+harvest!I32 -> 15829.48 | J31: =+cpue!I32 -> 11.614035 | K31: =+effort!K32 -> CLOSED | L31: =+harvest!K32 -> CLOSED | M31: =+cpue!K32 -> CLOSED | N31: =+effort!M32 -> CLOSED | O31: =+harvest!M32 -> CLOSED | P31: =+cpue!M32 -> CLOSED | Q31: CLOSED | R31: CLOSED | S31: CLOSED | T31: =+H31 -> 1362.9613 | U31: =+I31 -> 15829.48
A32: 39518 | B32: Tue | C32: -0.1 | D32: 0.41597222 | E32: =+effort!G33 -> CLOSED | F32: =+harvest!G33 -> CLOSED | G32: =+cpue!G33 -> CLOSED | H32: =+effort!I33 -> 988.08401 | I32: =+harvest!I33 -> 679.30776 | J32: =+cpue!I33 -> 0.6875 | K32: =+effort!K33 -> CLOSED | L32: =+harvest!K33 -> CLOSED | M32: =+cpue!K33 -> CLOSED | N32: =+effort!M33 -> CLOSED | O32: =+harvest!M33 -> CLOSED | P32: =+cpue!M33 -> CLOSED | Q32: CLOSED | R32: CLOSED | S32: CLOSED | T32: =+H32 -> 988.08401 | U32: =+I32 -> 679.30776
A33: 39519 | B33: Wed | C33: 0.0 | D33: 0.45208333 | E33: =+effort!G34 -> CLOSED | F33: =+harvest!G34 -> CLOSED | G33: =+cpue!G34 -> CLOSED | H33: =+effort!I34 -> 1078.7782 | I33: =+harvest!I34 -> 14656.503 | J33: =+cpue!I34 -> 13.586207 | K33: =+effort!K34 -> CLOSED | L33: =+harvest!K34 -> CLOSED | M33: =+cpue!K34 -> CLOSED | N33: =+effort!M34 -> CLOSED | O33: =+harvest!M34 -> CLOSED | P33: =+cpue!M34 -> CLOSED | Q33: CLOSED | R33: CLOSED | S33: CLOSED | T33: =+H33 -> 1078.7782 | U33: =+I33 -> 14656.503
A34: Tide Series Totals | E34: =SUM(E29:E33) -> 13969.432 | F34: =SUM(F29:F33) -> 82794.781 | G34: =+F34/E34 -> 5.9268537 | H34: =SUM(H28:H33) -> 15650.42 | I34: =SUM(I28:I33) -> 132882.99 | J34: =+I34/H34 -> 8.4906977 | Q34: 0 | R34: 0 | S34: 0 | T34: =SUM(T28:T33) -> 29619.852 | U34: =SUM(U28:U33) -> 215677.77
A35: 39544 | B35: Sun | C35: -0.7 | D35: 0.30763889 | E35: =+effort!G36 -> 5384.2384 | F35: =+harvest!G36 -> 68841.333 | G35: =+cpue!G36 -> 12.785714 | H35: =+effort!I36 -> 2417.8373 | I35: =+harvest!I36 -> 29518.871 | J35: =+cpue!I36 -> 12.208791 | K35: =+effort!K36 -> CLOSED | L35: =+harvest!K36 -> CLOSED | M35: =+cpue!K36 -> CLOSED | N35: =+effort!M36 -> CLOSED | O35: =+harvest!M36 -> CLOSED | P35: =+cpue!M36 -> CLOSED | Q35: CLOSED | R35: CLOSED | S35: CLOSED | T35: =+E35+H35 -> 7802.0756 | U35: =+F35+I35 -> 98360.204
A36: 39545 | B36: Mon | C36: -1.2 | D36: 0.33958333 | E36: =+effort!G37 -> 4740.222 | F36: =+harvest!G37 -> 46176.301 | G36: =+cpue!G37 -> 9.7413793 | H36: =+effort!I37 -> 1637.4599 | I36: =+harvest!I37 -> 15321.946 | J36: =+cpue!I37 -> 9.3571429 | K36: =+effort!K37 -> CLOSED | L36: =+harvest!K37 -> CLOSED | M36: =+cpue!K37 -> CLOSED | N36: =+effort!M37 -> CLOSED | O36: =+harvest!M37 -> CLOSED | P36: =+cpue!M37 -> CLOSED | Q36: CLOSED | R36: CLOSED | S36: CLOSED | T36: =+E36+H36 -> 6377.6819 | U36: =+F36+I36 -> 61498.246
A37: 39546 | B37: Tue | C37: -1.5 | D37: 0.37152778 | E37: =+effort!G38 -> 3758.6691 | F37: =+harvest!G38 -> 43416.464 | G37: =+cpue!G38 -> 11.55102 | H37: =+effort!I38 -> 1908.4521 | I37: =+harvest!I38 -> 27990.63 | J37: =+cpue!I38 -> 14.666667 | K37: =+effort!K38 -> CLOSED | L37: =+harvest!K38 -> CLOSED | M37: =+cpue!K38 -> CLOSED | N37: =+effort!M38 -> CLOSED | O37: =+harvest!M38 -> CLOSED | P37: =+cpue!M38 -> CLOSED | Q37: CLOSED | R37: CLOSED | S37: CLOSED | T37: =+E37+H37 -> 5667.1212 | U37: =+F37+I37 -> 71407.094
A38: 39547 | B38: Wed | C38: -1.4 | D38: 0.40486111 | E38: =+effort!G39 -> CLOSED | F38: =+harvest!G39 -> CLOSED | G38: =+cpue!G39 -> CLOSED | H38: =+effort!I39 -> 1330.2111 | I38: =+harvest!I39 -> 18683.42 | J38: =+cpue!I39 -> 14.045455 | K38: =+effort!K39 -> CLOSED | L38: =+harvest!K39 -> CLOSED | M38: =+cpue!K39 -> CLOSED | N38: =+effort!M39 -> CLOSED | O38: =+harvest!M39 -> CLOSED | P38: =+cpue!M39 -> CLOSED | Q38: CLOSED | R38: CLOSED | S38: CLOSED | T38: =+H38 -> 1330.2111 | U38: =+I38 -> 18683.42
A39: Tide Series Totals | E39: =SUM(E35:E38) -> 13883.13 | F39: =SUM(F35:F38) -> 158434.1 | G39: =+F39/E39 -> 11.411987 | H39: =SUM(H35:H38) -> 7293.9603 | I39: =SUM(I35:I38) -> 91514.867 | J39: =+I39/H39 -> 12.546664 | Q39: 0 | R39: 0 | S39: 0 | T39: =SUM(T35:T38) -> 21177.09 | U39: =SUM(U35:U38) -> 249948.96
A40: 39557 | B40: Sat | C40: -0.1 | D40: 0.27777778 | E40: =+effort!G41 -> 4574.88 | F40: =+harvest!G41 -> 13403.596 | G40: =+cpue!G41 -> 2.9298246 | H40: =+effort!I41 -> 2099.839 | I40: =+harvest!I41 -> 8296.9248 | J40: =+cpue!I41 -> 3.9512195 | K40: =+effort!K41 -> 3670 | L40: =+harvest!K41 -> 42634 | M40: =+cpue!K41 -> 12.538462 | N40: =+effort!M41 -> 2722 | O40: =+harvest!M41 -> 28286 | P40: =+cpue!M41 -> 9.2911392 | Q40: CLOSED | R40: CLOSED | S40: CLOSED | T40: =+E40+H40+K40+N40 -> 13066.719 | U40: =+F40+I40+L40+O40 -> 92620.521
...

Sheet Wastage
A1: Wastage for Fall 2007 through Spring 2008 Non - Tribal Razor Clam Fishery
A3: Longbeach | H3: Twin Harbors | O3: Copalis | V3: Mocrocks | AC3: Kalaloch
A4: Date | B4: Area | C4: Holes Checked | D4: Clams found | E4: # of Mortalities | F4: Wastage % | H4: Date | I4: Area | J4: Holes Checked | K4: Clams found | L4: # of Mortalities | M4: Wastage % | O4: Date | P4: Area | Q4: Holes Checked | R4: Clams found | S4: # of Mortalities | T4: Wastage % | V4: Date | W4: Area | X4: Holes Checked | Y4: Clams found | Z4: # of Mortalities | AA4: Wastage % | AC4: Date | AD4: Area | AE4: Holes Checked | AF4: Clams found | AG4: # of Mortalities | AH4: Wastage %
A5: 39546 | B5: 12600 | C5: 100 | D5: 1 | E5: 1 | F5: 0.01 | H5: 39380 | I5: 22307 | J5: 100 | K5: 4 | L5: 4 | M5: 0.04 | O5: 39382 | P5: 32007 | Q5: 100 | R5: 1 | S5: 1 | T5: 0.01 | V5: 39572 | W5: 32007 | X5: 100 | Y5: 7 | Z5: 7 | AA5: 0.07 | AH5: #DIV/0!
H6: 39381 | I6: 22307 | J6: 100 | K6: 1 | L6: 1 | M6: 0.01 | T6: #DIV/0! | V6: 39573 | W6: 31005 | X6: 100 | Y6: 3 | Z6: 3 | AA6: 0.03 | AH6: #DIV/0!
H7: 39381 | I7: 22309 | J7: 100 | K7: 9 | L7: 9 | M7: 0.09 | T7: #DIV/0! | AH7: #DIV/0!
H8: 39382 | I8: 21200 | J8: 100 | K8: 2 | L8: 2 | M8: 0.02 | T8: #DIV/0! | AH8: #DIV/0!
H9: 39382 | I9: 22307 | J9: 100 | K9: 5 | L9: 5 | M9: 0.05 | AH9: #DIV/0!
A10: Totals | C10: 100 | D10: 1 | E10: 1 | F10: 0.01 | V10: Totals | X10: 200 | Y10: 10 | Z10: 10 | AA10: 0.05
O11: Totals | Q11: 100 | R11: 1 | S11: 1 | T11: 0.01
A12: Longbeach
A13: Date | B13: Area | C13: Holes Checked | D13: Clams found | E13: # of Mortalities | F13: Wastage % | O13: Copalis | V13: Mocrocks
A14: 39575 | B14: 12600 | C14: 100 | D14: 8 | E14: 5 | F14: 0.05 | H14: Totals | J14: 500 | K14: 21 | L14: 21 | M14: 0.042 | O14: Date | P14: Area | Q14: Holes Checked | R14: Clams found | S14: # of Mortalities | T14: Wastage % | V14: Date | W14: Area | X14: Holes Checked | Y14: Clams found | Z14: # of Mortalities | AA14: Wastage %
O15: 39437 | P15: 32009 | Q15: 100 | R15: 0 | S15: 0 | T15: 0 | V15: 39592 | W15: 41300 | X15: 100 | Y15: 7 | Z15: 7 | AA15: 0.07
H16: Twin Harbors | T16: #DIV/0! | V16: 39592 | W16: 42500 | X16: 100 | Y16: 8 | Z16: 8 | AA16: 0.08
H17: Date | I17: Area | J17: Holes Checked | K17: Clams found | L17: # of Mortalities | M17: Wastage % | V17: 39592 | W17: 42600 | X17: 50 | Y17: 4 | Z17: 4 | AA17: 0.08
H18: 39437 | I18: 22309 | J18: 100 | K18: 1 | L18: 1 | M18: 0.01
A19: Totals | C19: 100 | D19: 8 | E19: 5 | F19: 0.05 | M19: #DIV/0!
M20: #DIV/0! | V20: Totals | X20: 250 | Y20: 19 | Z20: 19 | AA20: 0.076
A21: Longbeach | O21: Totals | Q21: 100 | R21: 0 | S21: 0 | T21: 0
A22: Date | B22: Area | C22: Holes Checked | D22: Clams found | E22: # of Mortalities | F22: Wastage % | V22: Mocrocks
H23: Totals | J23: 100 | K23: 1 | L23: 1 | M23: 0.01 | O23: Copalis | V23: Date | W23: Area | X23: Holes Checked | Y23: Clams found | Z23: # of Mortalities | AA23: Wastage %
O24: Date | P24: Area | Q24: Holes Checked | R24: Clams found | S24: # of Mortalities | T24: Wastage %
H25: Twin Harbors | O25: 39467 | P25: 32005 | Q25: 100 | R25: 4 | S25: 4 | T25: 0.04
H26: Date | I26: Area | J26: Holes Checked | K26: Clams found | L26: # of Mortalities | M26: Wastage % | O26: 39467 | P26: 32007 | Q26: 100 | R26: 1 | S26: 1 | T26: 0.01
H27: 39514 | I27: 21200 | J27: 100 | K27: 2 | L27: 2 | M27: 0.02 | T27: #DIV/0!
H28: 39514 | I28: 22307 | J28: 100 | K28: 1 | L28: 1 | M28: 0.01 | T28: #DIV/0!
H29: 39514 | I29: 22309 | J29: 50 | K29: 3 | L29: 3 | M29: 0.06 | T29: #DIV/0!
H30: 39516 | I30: 22309 | J30: 100 | K30: 3 | L30: 3 | M30: 0.03 | V30: Totals | X30: 0 | Y30: 0 | Z30: 0 | AA30: #DIV/0!
O31: Totals | Q31: 200 | R31: 5 | S31: 5 | T31: 0.025
A32: Totals | C32: 0 | D32: 0 | E32: 0 | H32: Totals | J32: 350 | K32: 9 | L32: 9 | M32: 0.025714286 | AC32: Totals | AE32: 0 | AF32: 0 | AG32: 0 | AH32: #DIV/0!
O33: Copalis
A34: Longbeach | H34: Twin Harbors | O34: Date | P34: Area | Q34: Holes Checked | R34: Clams found | S34: # of Mortalities | T34: Wastage %
A35: Date | B35: Area | C35: Holes Checked | D35: Clams found | E35: # of Mortalities | F35: Wastage % | H35: Date | I35: Area | J35: Holes Checked | K35: Clams found | L35: # of Mortalities | M35: Wastage % | O35: 39572 | P35: 32007 | Q35: 100 | R35: 7 | S35: 7 | T35: 0.07
H36: 39545 | I36: 21200 | J36: 100 | K36: 3 | L36: 3 | M36: 0.03 | O36: 39573 | P36: 31005 | Q36: 100 | R36: 3 | S36: 3 | T36: 0.03
H37: 39545 | I37: 22307 | J37: 50 | K37: 1 | L37: 1 | M37: 0.02
H38: 39546 | I38: 22309 | J38: 100 | K38: 2 | L38: 2 | M38: 0.02
H39: 39547 | I39: 22309 | J39: 100 | K39: 5 | L39: 5 | M39: 0.05
O40: Totals | Q40: 200 | R40: 10 | S40: 10 | T40: 0.05
H41: Totals | J41: 350 | K41: 11 | L41: 11 | M41: 0.031428571
...

Sheet 2007-2008 TAC
A1: 2007 FALL - 2008 SPRING NON-TRIBAL TOTAL ALLOWABLE CATCH (TAC)
A4: LONG BEACH | B4: 1245337
A5: TWIN HARBORS | B5: 1180370
A6: COPALIS | B6: 712696
A7: MOCROCKS | B7: 375464
A8: KALALOCH | B8: 34527
A9: COASTWIDE TAC | B9: =SUM(B4:B8) -> 3548394

Sheet State-Tribal Update
A1: 2007 - 2008 Non-Indian recreational razor clam effort, harvest and CPUE totals / Co-managed beaches only.
E2: COPALIS | I2: MOCROCKS | M2: KALALOCH | Q2: DAILY TOTALS
A3: DATE | B3: DAY | C3: TIDE | D3: TIME | E3: Effort | F3: Harvest | G3: CPUE | H3: Avg. Size | I3: Effort | J3: Harvest | K3: CPUE | L3: Avg. Size | M3: Effort | N3: Harvest | O3: CPUE | P3: Avg. Size | Q3: Effort | R3: Harvest
A4: =table!A5 -> 39381 | B4: =table!B5 -> Sat | C4: =table!C5 -> -1.7 | D4: =table!D5 -> 0.80972222 | E4: =table!K5 -> 3650 | F4: =table!L5 -> 54755 | G4: =table!M5 -> 15.00137 | I4: =table!N5 -> 4728 | J4: =table!O5 -> 69732 | K4: =table!P5 -> 14.748731 | M4: closed | N4: closed | Q4: =E4+I4 -> 8378 | R4: =F4+J4 -> 124487
A5: =table!A6 -> 39382 | B5: =table!B6 -> Sun | C5: =table!C6 -> -1.9 | D5: =table!D6 -> 0.84305556 | E5: =table!K6 -> 5184 | F5: =table!L6 -> 77105 | G5: =table!M6 -> 14.847222 | I5: =table!N6 -> 3021 | J5: =table!O6 -> 45317 | K5: =table!P6 -> 15 | M5: closed | N5: closed | Q5: =E5+I5 -> 8205 | R5: =F5+J5 -> 122422
A6: Tide Series Totals | E6: =SUM(E4:E5) -> 8834 | F6: =SUM(F4:F5) -> 131860 | G6: =table!M8 -> 0 | H6: 112.7 | I6: =SUM(I4:I5) -> 7749 | J6: =SUM(J4:J5) -> 115049 | K6: =table!P8 -> 14.846948 | L6: 121.3 | M6: 0 | N6: 0 | O6: 0 | Q6: =SUM(Q4:Q5) -> 16583 | R6: =SUM(R4:R5) -> 246909
A7: 39409 | B7: =table!B9 -> Fri | C7: =table!C9 -> -1.3 | D7: =table!D9 -> 0.72291667 | E7: =table!K9 -> 5113 | F7: =table!L9 -> 76690 | G7: =table!M9 -> 15 | I7: =table!N9 -> 3630 | J7: =table!O9 -> 54433 | K7: =table!P9 -> 15 | M7: closed | N7: closed | Q7: =E7+I7 -> 8743 | R7: =F7+J7 -> 131123
A8: 39410 | B8: =table!B10 -> Sat | C8: =table!C10 -> -1.7 | D8: =table!D10 -> 0.75763889 | E8: =table!K10 -> 3699 | F8: =table!L10 -> 52027 | G8: =table!M10 -> 14.064103 | I8: =table!N10 -> 2385 | J8: =table!O10 -> 35545 | K8: =table!P10 -> 14.915094 | M8: closed | N8: closed | Q8: =E8+I8 -> 6084 | R8: =F8+J8 -> 87572
A9: Tide Series Totals | E9: =SUM(E7:E8) -> 8812 | F9: =SUM(F7:F8) -> 128717 | G9: =table!M13 -> 0 | H9: 111.6 | I9: =SUM(I7:I8) -> 6015 | J9: =SUM(J7:J8) -> 89978 | K9: =table!P13 -> 0 | L9: 119.2 | M9: 0 | N9: 0 | O9: 0 | Q9: =SUM(Q7:Q8) -> 14827 | R9: =SUM(R7:R8) -> 218695
A10: 39437 | B10: =harvest!C15 -> Fri | C10: -0.4 | D10: =harvest!E15 -> 0.675 | E10: =effort!K15 -> 1861 | F10: =harvest!K15 -> 27481 | G10: =cpue!K15 -> 14.72973 | I10: =effort!M15 -> 1310 | J10: =harvest!M15 -> 19911 | K10: =cpue!M15 -> 15.2 | M10: closed | N10: closed | Q10: =E10+I10 -> 3171 | R10: =F10+J10 -> 47392
A11: 39438 | B11: =harvest!C16 -> Sat | C11: -0.9 | D11: =harvest!E16 -> 0.7125 | E11: =effort!K16 -> 2846 | F11: =harvest!K16 -> 42683 | G11: =cpue!K16 -> 15 | I11: =effort!M16 -> 1723 | J11: =harvest!M16 -> 23958 | K11: =cpue!M16 -> 13.6875 | M11: closed | N11: closed | Q11: =E11+I11 -> 4569 | R11: =F11+J11 -> 66641
A12: Tide Series Totals | E12: =SUM(E10:E11) -> 4707 | F12: =SUM(F10:F11) -> 70164 | G12: =table!M17 -> 0 | H12: 115.02 | I12: =SUM(I10:I11) -> 3033 | J12: =SUM(J10:J11) -> 43869 | K12: =table!P17 -> 14.463897 | L12: 120.12 | M12: =SUM(M10:M11) -> 0 | N12: =SUM(N10:N11) -> 0 | O12: 0 | Q12: =SUM(Q10:Q11) -> 7740 | R12: =SUM(R10:R11) -> 114033
A13: 39466 | B13: Sat | C13: 0.1 | D13: 0.66527778 | E13: 6072.0018 | F13: 89747.148 | G13: 14.780488 | I13: closed | J13: closed | K13: closed | M13: closed | N13: closed | Q13: =E13 -> 6072.0018 | R13: =F13 -> 89747.148
A14: 39467 | B14: Sun | C14: -0.4 | D14: 0.70347222 | E14: 4635.4663 | F14: 69048.344 | G14: 14.920354 | I14: closed | J14: closed | K14: closed | M14: closed | N14: closed | Q14: =E14 -> 4635.4663 | R14: =F14 -> 69048.344
A15: Tide Series Totals | E15: =SUM(E13:E14) -> 10707.468 | F15: =SUM(F13:F14) -> 158795.49 | G15: =table!M22 -> 0 | H15: 115.45 | I15: 0 | J15: 0 | K15: 0 | M15: 0 | N15: 0 | O15: 0 | Q15: =SUM(Q13:Q14) -> 10707.468 | R15: =SUM(R13:R14) -> 158795.49
A16: 39557 | B16: Sat | C16: -0.1 | D16: 0.27777778 | E16: 2859.0855 | F16: 35848.534 | G16: 12.538462 | I16: 2330.1171 | J16: 24209.845 | K16: 9.2911392 | M16: closed | N16: closed | Q16: =E16+I16 -> 5189.2026 | R16: =F16+J16 -> 60058.378
A17: 39558 | B17: Sun | C17: -0.4 | D17: 0.3 | E17: 3613.9848 | F17: 56068.939 | G17: 15.571429 | I17: 1926.4896 | J17: 28742.666 | K17: 14.932203 | M17: closed | N17: closed | Q17: =E17+I17 -> 5540.4745 | R17: =F17+J17 -> 84811.605
A18: Tide Series Totals | E18: =SUM(E16:E17) -> 6473.0703 | F18: =SUM(F16:F17) -> 91917.473 | G18: =table!M45 -> 0 | H18: 118.65 | I18: =SUM(I16:I17) -> 4256.6067 | J18: =SUM(J16:J17) -> 52952.511 | K18: =table!P45 -> 12.44078 | L18: 127.67 | M18: 0 | N18: 0 | O18: 0 | Q18: =SUM(Q16:Q17) -> 10729.677 | R18: =SUM(R16:R17) -> 144869.98
A19: 8 | B19: Sun | C19: -1.2 | D19: 0.26111111 | E19: 2506.6361 | F19: 37599.542 | G19: 15 | I19: 1843.3937 | J19: 27650.906 | K19: 15 | M19: closed | N19: closed | Q19: =E19+I19 -> 4350.0298 | R19: =F19+J19 -> 65250.448
A20: 39573 | B20: Mon | C20: -1.9 | D20: 0.29444444 | E20: 1382.9848 | F20: 20744.773 | G20: 15 | I20: 893.02216 | J20: 13395.332 | K20: 15 | M20: closed | N20: closed | Q20: =E20+I20 -> 2276.007 | R20: =F20+J20 -> 34140.105
A21: Tide Series Totals | E21: =SUM(E19:E20) -> 3889.621 | F21: =SUM(F19:F20) -> 58344.314 | G21: =table!M51 -> 0 | H21: 124.28 | I21: =SUM(I19:I20) -> 2736.4159 | J21: =SUM(J19:J20) -> 41046.238 | K21: =table!P51 -> 15.000288 | L21: 132.05 | M21: 0 | N21: 0 | O21: 0 | Q21: =SUM(Q19:Q20) -> 6626.0368 | R21: =SUM(R19:R20) -> 99390.553
A22: 39592 | B22: Sat | C22: -0.5 | D22: 0.41527778 | E22: 3814.8039 | F22: 56040.114 | G22: 14.741935 | I22: 3148.9835 | J22: 47234.752 | K22: 15 | M22: closed | N22: closed | Q22: =E22+I22 -> 6963.7874 | R22: =F22+J22 -> 103274.87
A23: Tide Series Totals | E23: =SUM(E22) -> 3814.8039 | F23: =SUM(F22) -> 56040.114 | G23: =table!M53 -> 0 | H23: 113.84 | I23: =I22 -> 3148.9835 | J23: =J22 -> 47234.752 | K23: =table!P53 -> 14.998112 | L23: 119.36 | M23: 0 | N23: 0 | O23: 0 | Q23: =SUM(Q22:Q22) -> 6963.7874 | R23: =SUM(R22:R22) -> 103274.87
A24: SEASON TOTALS: | E24: =SUM(E6+E9+E12+E15+E18+E21+E23) -> 47237.963 | F24: =SUM(F6+F9+F12+F15+F18+F21+F23) -> 695838.39 | G24: =F24/E24 -> 14.730491 | I24: =SUM(I6+I9+I12+I15+I18+I21+I23) -> 26939.006 | J24: =SUM(J6+J9+J12+J15+J18+J21+J23) -> 390129.5 | K24: =J24/I24 -> 14.481956 | M24: =SUM(M6+M9+M12+M15+M18+M21) -> 0 | N24: =SUM(N6+N9+N12+N15+N18+N21+N23) -> 0 | O24: 0 | Q24: =SUM(Q6+Q9+Q12+Q15+Q18+Q21+Q23) -> 74176.969 | R24: =SUM(R6+R9+R12+R15+R18+R21+R23) -> 1085967.9
A25: Estimated Wastage Rate: | F25: =harvest!K56 -> 0 | J25: =harvest!M56 -> 0 | N25: =harvest!O56 -> 0
A26: Estimated Total Wastage: | F26: =harvest!K57 -> 16416 | J26: =harvest!M57 -> 26899 | N26: =harvest!O57 -> 0
A27: SEASON TOTALS (including wastage): | F27: =F24+F26 -> 712254.39 | J27: =J24+J26 -> 417028.5 | N27: =harvest!O58 -> 0
A28: % of State's Share of TAC Harvested | F28: =harvest!K60 -> 1.1211568 | J28: =harvest!M60 -> 1.1859113 | N28: =harvest!O60 -> 0
A29: Clams remaning in State's Share of TAC | F29: =harvest!K61 -> -86348 | J29: =harvest!M61 -> -69803 | N29: =harvest!O61 -> 34527
