Workbook

Sheet harvest
A1: 2008 FALL / 2009 SPRING RAZOR CLAM HARVEST TOTALS (number of clams): NON-INDIAN FISHERY
A2: (FINAL ESTIMATE) | O2: =TODAY() -> 41516 | P2: update
A4: DATE | C4: DAY | D4: TIDE | E4: TIME | G4: Longbeach | I4: Twin Harbors | K4: Copalis | M4: Mocrocks | O4: Kalaloch | Q4: Daily Totals
A5: October | B5: 16 | C5: Thu | D5: -1.5 | E5: 0.85416667 | G5: CLOSED | H5: * | I5: =+K5*I6/K6 -> 27954.765 | K5: 29912 | M5: 28766 | O5: CLOSED | Q5: =I5+K5+M5 -> 86632.765
A6: October | B6: 17 | C6: Fri | D6: -1.5 | E6: 0.88680556 | G6: 65673.67 | I6: 26913.657 | K6: 28798 | M6: 15026 | O6: CLOSED | Q6: =G6+I6+K6+M6 -> 136411.33
A7: October | B7: 18 | C7: Sat | D7: -1.2 | E7: 0.92222222 | G7: 94400.281 | H7: * | I7: =+K7*I6/K6 -> 35803.258 | K7: 38310 | L7: * | M7: =+(K7)*(M6+M5)/(K5+K6) -> 28575.567 | O7: CLOSED | Q7: =G7+I7+K7+M7 -> 197089.11
A9: November | B9: 13 | C9: Thu | D9: -1.6 | E9: 0.76875 | G9: CLOSED | I9: CLOSED | K9: 24384 | M9: 14366 | O9: CLOSED | Q9: =K9+M9 -> 38750
A10: November | B10: 14 | C10: Fri | D10: -1.8 | E10: 0.80208333 | G10: 63089.889 | I10: 25752.938 | K10: 66392 | M10: 17157 | O10: CLOSED | Q10: =G10+I10+K10+M10 -> 172391.83
A11: November | B11: 15 | C11: Sat | D11: -1.6 | E11: 0.83611111 | G11: 107131.61 | I11: 28247.937 | K11: 48480 | M11: 32934 | O11: CLOSED | Q11: =G11+I11+K11+M11 -> 216793.55
A12: November | B12: 16 | C12: Sun | D12: -1.2 | E12: 0.87083333 | F12: * | G12: 27577.466 | H12: * | I12: =+(K12+M12)*(I11+I10)/(K10+K11+M10+M11) -> 8258.4221 | K12: 20170 | M12: 5058 | O12: CLOSED | Q12: =G12+I12+K12+M12 -> 61063.888
A14: December | B14: 11 | C14: Thu | D14: -1.1 | E14: 0.72430556 | G14: CLOSED | I14: CLOSED | K14: 23147 | M14: 18702 | O14: CLOSED | Q14: =K14+M14 -> 41849
A15: December | B15: 12 | C15: Fri | D15: -1.5 | E15: 0.75902778 | G15: 734.63159 | H15: * | I15: =+K15*I16/K16 -> 51.762065 | K15: 229 | L15: * | M15: =+K15*(M14+M16)/(K14+K16) -> 118.3539 | O15: CLOSED | Q15: =G15+I15+K15+M15 -> 1133.7476
A16: December | B16: 13 | C16: Sat | D16: -1.6 | E16: 0.79305556 | G16: 9213.43 | I16: 6909.6705 | K16: 30569 | M16: 9060 | O16: CLOSED | Q16: =G16+I16+K16+M16 -> 55752.101
A17: December | B17: 14 | C17: Sun | D17: -1.4 | E17: 0.82638889 | F17: * | G17: 715.20784 | H17: * | I17: =+K17*I16/K16 -> 276.44107 | K17: 1223 | L17: * | M17: =+K17*(M16+M14)/(K16+K14) -> 632.08217 | O17: CLOSED | Q17: =G17+I17+K17+M17 -> 2846.7311
A19: January | B19: 8 | C19: Thu | D19: -0.2 | E19: 0.67569444 | G19: CLOSED | H19: * | I19: =+I20/2 -> 3494.5016 | K19: =+K20/2 -> 11507 | M19: =+M20/2 -> 6686.5 | O19: CLOSED | Q19: =+I19+K19+M19 -> 21688.002
A20: January | B20: 9 | C20: Fri | D20: -0.8 | E20: 0.71319444 | G20: 38254.519 | I20: 6989.0032 | K20: 23014 | M20: 13373 | O20: CLOSED | Q20: =+G20+I20+K20+M20 -> 81630.522
A21: January | B21: 10 | C21: Sat | D21: -1.1 | E21: 0.74861111 | G21: 28266.724 | I21: 7601.665 | K21: 49358 | M21: 24103 | O21: CLOSED | Q21: =+G21+I21+K21+M21 -> 109329.39
A22: January | B22: 11 | C22: Sun | D22: -1.2 | E22: 0.78125 | F22: * | G22: 14012.625 | H22: * | I22: =+(K22+M22)*(I21+I20)/(K20+K21+M20+M21) -> 4103.393 | K22: 20928 | M22: 9965 | O22: CLOSED | Q22: =+G22+I22+K22+M22 -> 49009.018
A24: February | B24: 6 | C24: Fri | D24: -0.1 | E24: 0.66319444 | G24: CLOSED | I24: 32532.833 | K24: 46064 | M24: 36754 | O24: CLOSED | Q24: =+I24+K24+M24 -> 115350.83
A25: February | B25: 7 | C25: Sat | D25: -0.4 | E25: 0.70138889 | G25: 140955.08 | I25: 68371.927 | K25: 108534 | M25: 118708 | O25: CLOSED | Q25: =+G25+I25+K25+M25 -> 436569.01
A26: February | B26: 8 | C26: Sun | D26: -0.6 | E26: 0.73541667 | G26: 62911.148 | H26: * | I26: =(K26+M26)*(I24+I25)/(K24+K25+M24+M25) -> 43330.208 | K26: 95622 | M26: 37523 | O26: CLOSED | Q26: =+G26+I26+K26+M26 -> 239386.36
A28: March | B28: 27 | C28: Fri | D28: 0 | E28: 0.32569444 | G28: CLOSED | I28: 41438.171 | K28: CLOSED | M28: 44725 | O28: CLOSED | Q28: =I28+M28 -> 86163.171
A29: March | B29: 28 | C29: Sat | D29: -0.4 | E29: 0.35347222 | G29: 62183.769 | H29: * | I29: =+(K29+M29)*(I25+I24)/(K24+K25+M24+M25) -> 61532.508 | K29: 112127 | M29: 76950 | O29: CLOSED | Q29: =G29+I29+K29+M29 -> 312793.28
A30: March | B30: 29 | C30: Sun | D30: -0.6 | E30: 0.38333333 | G30: 99542.476 | H30: * | I30: =+(K30+M30)*(I25+I24)/(K24+K25+M24+M25) -> 53833.663 | K30: 109258 | M30: 56162 | O30: CLOSED | Q30: =G30+I30+K30+M30 -> 318796.14
A32: April | B32: 10 | C32: Fri | D32: -0.7 | E32: 0.32291667 | G32: CLOSED | I32: 44364.702 | K32: CLOSED | M32: CLOSED | O32: CLOSED | Q32: =+I32 -> 44364.702
A33: April | B33: 11 | C33: Sat | D33: -0.7 | E33: 0.35069444 | G33: 125791.46 | I33: 62187.4 | K33: CLOSED | M33: CLOSED | O33: CLOSED | Q33: =+G33+I33 -> 187978.86
A34: April | B34: 12 | C34: Sun | D34: -0.5 | E34: 0.37847222 | G34: 19535.656 | I34: 12081.398 | K34: CLOSED | M34: CLOSED | O34: CLOSED | Q34: =+G34+I34 -> 31617.054
A36: April | B36: 25 | C36: 39928 | D36: -1.3 | E36: 0.31041667 | G36: 101760.96 | H36: * | I36: =(K36+M36)*I38/(M38+K38) -> 56511.053 | K36: 144271 | M36: 82807 | O36: CLOSED | Q36: =+G36+I36+K36+M36 -> 385350.01
A37: April | B37: 26 | C37: 39929 | D37: -1.6 | E37: 0.34027778 | F37: * | G37: =(K37+M37)*G36/(K36+M36) -> 87264.332 | H37: * | I37: =(K37+M37)*I38/(K38+M38) -> 48460.62 | K37: 126966 | M37: 67763 | O37: CLOSED | Q37: =+G37+I37+K37+M37 -> 330453.95
A38: April | B38: 27 | C38: 39930 | D38: -1.7 | E38: 0.37152778 | G38: 84864.404 | I38: 18946.351 | K38: 50615 | M38: 25517 | O38: CLOSED | Q38: =+G38+I38+K38+M38 -> 179942.75
A40: May | B40: 9 | C40: 39942 | D40: -1.2 | E40: 0.30763889 | G40: 63221.911 | H40: * | I40: =+(K40+M40)*I38/(K38+M38) -> 22742.241 | K40: 63672 | M40: 27713 | O40: CLOSED | Q40: =G40+I40+K40+M40 -> 177349.15
A41: May | B41: 10 | C41: 39943 | D41: -1.2 | E41: 0.33472222 | G41: 91926.223 | I41: 45905.096 | K41: CLOSED | M41: CLOSED | O41: CLOSED | Q41: =G41+I41 -> 137831.32
A44: FALL 2008 - SPRING 2009 SEASON TOTALS: | G44: =SUM(G5:G43) -> 1389027.5 | I44: =SUM(I5:I43) -> 794595.58 | K44: =SUM(K5:K43) -> 1273550 | M44: =SUM(M5:M43) -> 799144.5 | O44: =SUM(O5:O43) -> 0 | Q44: =G44+I44+K44+M44+O44 -> 4256317.6
A45: ESTIMATED WASTAGE RATE: | G45: =+'LB - Wastage'!F7 -> 0.095878983 | I45: =+'TH - Wastage'!F8 -> 0.048542128 | K45: =+'Cop - Wastage'!F9 -> 0.043807967 | M45: =+'Moc - Wastage'!F8 -> 0.075847441 | O45: 0
A46: ESTIMATED TOTAL WASTAGE: | G46: =+'LB - Wastage'!D7 -> 38768 | I46: =+'TH - Wastage'!D8 -> 10632 | K46: =+'Cop - Wastage'!D9 -> 28448 | M46: =+'Moc - Wastage'!D8 -> 26604 | O46: 0 | Q46: =G46+I46+K46+M46+O46 -> 104452
A47: SEASON TOTAL INCLUDING WASTAGE: | G47: =G44+G46 -> 1427795.5 | I47: =I44+I46 -> 805227.58 | K47: =K44+K46 -> 1301998 | M47: =M44+M46 -> 825748.5 | O47: =O44+O46 -> 0 | Q47: =G47+I47+K47+M47+O47 -> 4360769.6
A48: Fall 2008 / Spring 2009 Harvest Rate (clams/day): | G48: =G47/22 -> 64899.794 | I48: =I47/27 -> 29823.244 | K48: =K47/24 -> 54249.917 | M48: =M47/25 -> 33029.94 | O48: =O47/1 -> 0 | Q48: =G48+I48+K48+M48+O48 -> 182002.9
A49: % of TAC Harvested: | G49: =G47/'2008-2009 TAC'!B4 -> 1.3559543 | I49: =I47/'2008-2009 TAC'!B5 -> 1.1973698 | K49: =K47/'2008-2009 TAC'!B6 -> 1.3449906 | M49: =M47/'2008-2009 TAC'!B7 -> 1.1767593 | O49: =O47/'2008-2009 TAC'!B8 -> 0 | Q49: =Q47/'2008-2009 TAC'!B9 -> 1.2264132
A50: clams left in TAC : | G50: ='2008-2009 TAC'!B4-G47 -> -374813.48 | I50: ='2008-2009 TAC'!B5-I47 -> -132730.58 | K50: ='2008-2009 TAC'!B6-K47 -> -333963 | M50: ='2008-2009 TAC'!B7-M47 -> -124034.5 | O50: ='2008-2009 TAC'!B8-O47 -> 160482 | Q50: =G50+I50+K50+M50+O50 -> -805059.56
A51: *- estimate based on comparison of other beaches. + - no harvest due to very heavy surf and storm warnings.
...

Sheet cpue
A1: 2008 FALL / 2009 SPRING RAZOR CLAM CPUE TOTALS (clams per digger trip): NON-INDIAN FISHERY
A2: =harvest!A2 -> (FINAL ESTIMATE) | N2: =TODAY() -> 41516 | P2: update
A4: DATE | C4: DAY | D4: TIDE | E4: TIME | G4: Longbeach | I4: Twin Harbors | K4: Copalis | M4: Mocrocks | O4: Kalaloch | Q4: Daily Totals
A5: October | B5: 16 | C5: Thu | D5: -1.5 | E5: 0.85416667 | G5: CLOSED | H5: * | I5: =harvest!I5/effort!I5 -> 14.544839 | K5: =harvest!K5/effort!K5 -> 14.691552 | M5: =harvest!M5/effort!M5 -> 14.889234 | O5: CLOSED | Q5: =harvest!Q5/effort!Q5 -> 14.70852
A6: October | B6: 17 | C6: Fri | D6: -1.5 | E6: 0.88680556 | G6: =harvest!G6/effort!G6 -> 14.577395 | I6: =harvest!I6/effort!I6 -> 14.583333 | K6: =harvest!K6/effort!K6 -> 14.730435 | M6: =harvest!M6/effort!M6 -> 14.996008 | O6: CLOSED | Q6: =harvest!Q6/effort!Q6 -> 14.655782
A7: October | B7: 18 | C7: Sat | D7: -1.2 | E7: 0.92222222 | G7: =harvest!G7/effort!G7 -> 12.22973 | H7: * | I7: =harvest!I7/effort!I7 -> 14.45405 | K7: =harvest!K7/effort!K7 -> 14.599848 | L7: * | M7: =harvest!M7/effort!M7 -> 14.813328 | O7: CLOSED | Q7: =harvest!Q7/effort!Q7 -> 13.362877
A9: November | B9: 13 | C9: Thu | D9: -1.6 | E9: 0.76875 | G9: CLOSED | I9: CLOSED | K9: =harvest!K9/effort!K9 -> 14.99631 | M9: =harvest!M9/effort!M9 -> 14.674157 | O9: CLOSED | Q9: =harvest!Q9/effort!Q9 -> 14.87524
A10: November | B10: 14 | C10: Fri | D10: -1.8 | E10: 0.80208333 | G10: =harvest!G10/effort!G10 -> 14.569767 | I10: =harvest!I10/effort!I10 -> 13.227584 | K10: =harvest!K10/effort!K10 -> 14.537333 | M10: =harvest!M10/effort!M10 -> 14.321369 | O10: CLOSED | Q10: =harvest!Q10/effort!Q10 -> 14.315757
A11: November | B11: 15 | C11: Sat | D11: -1.6 | E11: 0.83611111 | G11: =harvest!G11/effort!G11 -> 11.738636 | I11: =harvest!I11/effort!I11 -> 13.895833 | K11: =harvest!K11/effort!K11 -> 15.051226 | M11: =harvest!M11/effort!M11 -> 14.50837 | O11: CLOSED | Q11: =harvest!Q11/effort!Q11 -> 13.020442
A12: November | B12: 16 | C12: Sun | D12: -1.2 | E12: 0.87083333 | F12: * | G12: =harvest!G12/effort!G12 -> 13.248601 | H12: * | I12: =harvest!I12/effort!I12 -> 13.886722 | K12: =harvest!K12/effort!K12 -> 14.996283 | M12: =harvest!M12/effort!M12 -> 15.008902 | O12: CLOSED | Q12: =harvest!Q12/effort!Q12 -> 14.011144
A14: December | B14: 11 | C14: Thu | D14: -1.1 | E14: 0.72430556 | G14: CLOSED | I14: CLOSED | K14: =harvest!K14/effort!K14 -> 15.001296 | M14: =harvest!M14/effort!M14 -> 14.772512 | O14: CLOSED | Q14: =harvest!Q14/effort!Q14 -> 14.898184
A15: December | B15: 12 | C15: Fri | D15: -1.5 | E15: 0.75902778 | G15: =harvest!G15/effort!G15 -> 3.6 | H15: * | I15: =harvest!I15/effort!I15 -> 0.51293587 | K15: =harvest!K15/effort!K15 -> 0.5 | L15: * | M15: =harvest!M15/effort!M15 -> 0.51473576 | O15: CLOSED | Q15: =harvest!Q15/effort!Q15 -> 1.1418443
A16: December | B16: 13 | C16: Sat | D16: -1.6 | E16: 0.79305556 | G16: =harvest!G16/effort!G16 -> 6.4090909 | I16: =harvest!I16/effort!I16 -> 13.115798 | K16: =harvest!K16/effort!K16 -> 12.785027 | M16: =harvest!M16/effort!M16 -> 12.778561 | O16: CLOSED | Q16: =harvest!Q16/effort!Q16 -> 11.008679
A17: December | B17: 14 | C17: Sun | D17: -1.4 | E17: 0.82638889 | F17: * | G17: =harvest!G17/effort!G17 -> 8.2659813 | H17: * | I17: =harvest!I17/effort!I17 -> 15.300502 | K17: =harvest!K17/effort!K17 -> 14.914634 | L17: * | M17: =harvest!M17/effort!M17 -> 15.354191 | O17: CLOSED | Q17: =harvest!Q17/effort!Q17 -> 12.498904
A19: January | B19: 8 | C19: Thu | D19: -0.2 | E19: 0.67569444 | G19: CLOSED | H19: * | I19: =harvest!I19/effort!I19 -> 14.470588 | K19: =harvest!K19/effort!K19 -> 14.81906 | M19: =harvest!M19/effort!M19 -> 14.992152 | O19: CLOSED | Q19: =harvest!Q19/effort!Q19 -> 14.81431
A20: January | B20: 9 | C20: Fri | D20: -0.8 | E20: 0.71319444 | G20: =harvest!G20/effort!G20 -> 14.125 | I20: =harvest!I20/effort!I20 -> 14.470588 | K20: =harvest!K20/effort!K20 -> 14.81906 | M20: =harvest!M20/effort!M20 -> 14.992152 | O20: CLOSED | Q20: =harvest!Q20/effort!Q20 -> 14.48309
A21: January | B21: 10 | C21: Sat | D21: -1.1 | E21: 0.74861111 | G21: =harvest!G21/effort!G21 -> 6.4038462 | I21: =harvest!I21/effort!I21 -> 7.8181818 | K21: =harvest!K21/effort!K21 -> 13.90758 | M21: =harvest!M21/effort!M21 -> 13.353463 | O21: CLOSED | Q21: =harvest!Q21/effort!Q21 -> 10.179333
A22: January | B22: 11 | C22: Sun | D22: -1.2 | E22: 0.78125 | G22: =harvest!G22/effort!G22 -> 9.6359107 | H22: * | I22: =harvest!I22/effort!I22 -> 10.897141 | K22: =harvest!K22/effort!K22 -> 15.456425 | M22: =harvest!M22/effort!M22 -> 15.00753 | O22: CLOSED | Q22: =harvest!Q22/effort!Q22 -> 12.733698
A24: February | B24: 6 | C24: Fri | D24: -0.1 | E24: 0.66319444 | G24: CLOSED | I24: =harvest!I24/effort!I24 -> 15 | K24: =harvest!K24/effort!K24 -> 15.268147 | M24: =harvest!M24/effort!M24 -> 15.001633 | O24: CLOSED | Q24: =harvest!Q24/effort!Q24 -> 15.106471
A25: February | B25: 7 | C25: Sat | D25: -0.4 | E25: 0.70138889 | G25: =harvest!G25/effort!G25 -> 6.5909091 | I25: =harvest!I25/effort!I25 -> 14.0375 | K25: =harvest!K25/effort!K25 -> 14.222776 | M25: =harvest!M25/effort!M25 -> 14.457192 | O25: CLOSED | Q25: =harvest!Q25/effort!Q25 -> 10.370069
A26: February | B26: 8 | C26: Sun | D26: -0.6 | E26: 0.73541667 | G26: =harvest!G26/effort!G26 -> 8.5319149 | H26: * | I26: =harvest!I26/effort!I26 -> 13.731456 | K26: =harvest!K26/effort!K26 -> 13.58267 | M26: =harvest!M26/effort!M26 -> 14.9375 | O26: CLOSED | Q26: =harvest!Q26/effort!Q26 -> 11.920937
A28: March | B28: 27 | C28: Fri | D28: 0 | E28: 0.32569444 | G28: CLOSED | I28: =harvest!I28/effort!I28 -> 15 | K28: CLOSED | M28: =harvest!M28/effort!M28 -> 14.799801 | O28: CLOSED | Q28: =harvest!Q28/effort!Q28 -> 14.895411
A29: March | B29: 28 | C29: Sat | D29: -0.4 | E29: 0.35347222 | G29: =harvest!G29/effort!G29 -> 3.673913 | H29: * | I29: 5.9 | K29: =harvest!K29/effort!K29 -> 8.8975559 | M29: =harvest!M29/effort!M29 -> 13.782912 | O29: CLOSED | Q29: =harvest!Q29/effort!Q29 -> 7.6071639
A30: March | B30: 29 | C30: Sun | D30: -0.6 | E30: 0.38333333 | G30: =harvest!G30/effort!G30 -> 11.12 | H30: * | I30: 12.75 | K30: =harvest!K30/effort!K30 -> 14.728768 | M30: =harvest!M30/effort!M30 -> 14.873411 | O30: CLOSED | Q30: =harvest!Q30/effort!Q30 -> 13.370276
A32: April | B32: 10 | C32: Fri | D32: -0.7 | E32: 0.32291667 | G32: CLOSED | I32: =harvest!I32/effort!I32 -> 15 | K32: CLOSED | M32: CLOSED | O32: CLOSED | Q32: =harvest!Q32/effort!Q32 -> 15
A33: April | B33: 11 | C33: Sat | D33: -0.7 | E33: 0.35069444 | G33: =harvest!G33/effort!G33 -> 15 | I33: =harvest!I33/effort!I33 -> 14.145455 | K33: CLOSED | M33: CLOSED | O33: CLOSED | Q33: =harvest!Q33/effort!Q33 -> 14.706094
A34: April | B34: 12 | C34: Sun | D34: -0.5 | E34: 0.37847222 | G34: =harvest!G34/effort!G34 -> 7.6666667 | I34: =harvest!I34/effort!I34 -> 9.1463415 | K34: CLOSED | M34: CLOSED | O34: CLOSED | Q34: =harvest!Q34/effort!Q34 -> 8.1718327
A36: April | B36: 25 | C36: Sat | D36: -1.3 | E36: 0.31041667 | G36: =harvest!G36/effort!G36 -> 10.441176 | H36: * | I36: =harvest!I36/effort!I36 -> 14.984372 | K36: =harvest!K36/effort!K36 -> 15.000104 | M36: =harvest!M36/effort!M36 -> 15.001268 | O36: CLOSED | Q36: =harvest!Q36/effort!Q36 -> 13.447703
A37: April | B37: 26 | C37: Sun | D37: -1.6 | E37: 0.34027778 | F37: * | G37: =harvest!G37/effort!G37 -> 10.331724 | H37: * | I37: =harvest!I37/effort!I37 -> 14.827293 | K37: =harvest!K37/effort!K37 -> 14.842881 | M37: =harvest!M37/effort!M37 -> 14.844031 | O37: CLOSED | Q37: =harvest!Q37/effort!Q37 -> 13.306733
A38: April | B38: 27 | C38: Mon | D38: -1.7 | E38: 0.37152778 | G38: =harvest!G38/effort!G38 -> 12.953846 | I38: =harvest!I38/effort!I38 -> 15 | K38: =harvest!K38/effort!K38 -> 15.023746 | M38: =harvest!M38/effort!M38 -> 15.001176 | O38: CLOSED | Q38: =harvest!Q38/effort!Q38 -> 13.965961
A40: May | B40: 9 | C40: 39942 | D40: -1.2 | E40: 0.30763889 | G40: =harvest!G40/effort!G40 -> 13.79661 | H40: * | I40: 15 | K40: =harvest!K40/effort!K40 -> 14.999293 | M40: =harvest!M40/effort!M40 -> 14.939623 | O40: CLOSED | Q40: =harvest!Q40/effort!Q40 -> 14.534293
A41: May | B41: 10 | C41: 39943 | D41: -1.2 | E41: 0.33472222 | G41: =harvest!G41/effort!G41 -> 14.176471 | I41: =harvest!I41/effort!I41 -> 15 | K41: CLOSED | M41: CLOSED | O41: CLOSED | Q41: =harvest!Q41/effort!Q41 -> 14.440519
A44: SEASON TOTALS : | G44: =harvest!G44/effort!G44 -> 9.9608306 | I44: =harvest!I44/effort!I44 -> 13.757133 | K44: =harvest!K44/effort!K44 -> 13.757028 | M44: =harvest!M44/effort!M44 -> 14.557654 | O44: =harvest!O44/effort!O44 -> #DIV/0! | Q44: =harvest!Q47/effort!Q44 -> 12.651742
A45: *- estimate based on comparison of other beaches. + - no harvest due to very heavy surf and storm warnings.
A46: page 2 of 3

Sheet effort
A1: 2008 FALL / 2009 SPRING RAZOR CLAM EFFORT TOTALS (number of diggers): NON-INDIAN FISHERY
A2: =harvest!A2 -> (FINAL ESTIMATE) | N2: =TODAY() -> 41516 | P2: update
A4: DATE | C4: DAY | D4: TIDE | E4: TIME | G4: Longbeach | I4: Twin Harbors | K4: Copalis | M4: Mocrocks | O4: Kalaloch | Q4: Daily Totals
A5: October | B5: 16 | C5: Thu | D5: -1.5 | E5: 0.85416667 | G5: CLOSED | H5: * | I5: =+K5*I6/K6 -> 1921.9714 | K5: 2036 | M5: 1932 | O5: CLOSED | Q5: =SUM(G5,I5,K5,M5,O5) -> 5889.9714
A6: October | B6: 17 | C6: Fri | D6: -1.5 | E6: 0.88680556 | G6: 4505.1719 | I6: 1845.5079 | K6: 1955 | M6: 1002 | O6: CLOSED | Q6: =SUM(G6,I6,K6,M6,O6) -> 9307.6798
A7: October | B7: 18 | C7: Sat | D7: -1.2 | E7: 0.92222222 | G7: 7718.918 | H7: * | I7: =+K7*I6/K6 -> 2477.0398 | K7: 2624 | L7: * | M7: =+(K7)*(M6+M5)/(K5+K6) -> 1929.0443 | O7: CLOSED | Q7: =SUM(G7,I7,K7,M7,O7) -> 14749.002
A9: November | B9: 13 | C9: Thu | D9: -1.6 | E9: 0.76875 | G9: CLOSED | I9: CLOSED | K9: 1626 | M9: 979 | O9: CLOSED | Q9: =SUM(G9,I9,K9,M9,O9) -> 2605
A10: November | B10: 14 | C10: Fri | D10: -1.8 | E10: 0.80208333 | G10: 4330.1919 | I10: 1946.9117 | K10: 4567 | M10: 1198 | O10: CLOSED | Q10: =SUM(G10,I10,K10,M10,O10) -> 12042.104
A11: November | B11: 15 | C11: Sat | D11: -1.6 | E11: 0.83611111 | G11: 9126.4105 | I11: 2032.835 | K11: 3221 | M11: 2270 | O11: CLOSED | Q11: =SUM(G11,I11,K11,M11,O11) -> 16650.246
A12: November | B12: 16 | C12: Sun | D12: -1.2 | E12: 0.87083333 | F12: * | G12: 2081.538 | H12: * | I12: =+(K12+M12)*(I11+I10)/(K10+K11+M10+M11) -> 594.69918 | K12: 1345 | M12: 337 | O12: CLOSED | Q12: =SUM(G12,I12,K12,M12,O12) -> 4358.2372
A14: December | B14: 11 | C14: Thu | D14: -1.1 | E14: 0.72430556 | G14: CLOSED | I14: CLOSED | K14: 1543 | M14: 1266 | O14: CLOSED | Q14: =SUM(K14,M14) -> 2809
A15: December | B15: 12 | C15: Fri | D15: -1.5 | E15: 0.75902778 | G15: 204.06433 | H15: * | I15: =+K15*I16/K16 -> 100.91333 | K15: 458 | L15: * | M15: =+K15*(M14+M16)/(K14+K16) -> 229.93137 | O15: CLOSED | Q15: =G15+I15+K15+M15 -> 992.90902
A16: December | B16: 13 | C16: Sat | D16: -1.6 | E16: 0.79305556 | G16: 1437.5565 | I16: 526.82045 | K16: 2391 | M16: 709 | O16: CLOSED | Q16: =G16+I16+K16+M16 -> 5064.3769
A17: December | B17: 14 | C17: Sun | D17: -1.4 | E17: 0.82638889 | F17: * | G17: 86.524251 | H17: * | I17: =+K17*I16/K16 -> 18.067452 | K17: 82 | L17: * | M17: =+K17*(M16+M14)/(K16+K14) -> 41.166751 | O17: CLOSED | Q17: =G17+I17+K17+M17 -> 227.75845
A19: January | B19: 8 | C19: Thu | D19: -0.2 | E19: 0.67569444 | G19: CLOSED | H19: * | I19: =+I20/2 -> 241.48995 | K19: =+K20/2 -> 776.5 | M19: =+M20/2 -> 446 | O19: CLOSED | Q19: =I19+K19+M19 -> 1463.9899
A20: January | B20: 9 | C20: Fri | D20: -0.8 | E20: 0.71319444 | G20: 2708.2845 | I20: 482.9799 | K20: 1553 | M20: 892 | O20: CLOSED | Q20: =G20+I20+K20+M20 -> 5636.2644
A21: January | B21: 10 | C21: Sat | D21: -1.1 | E21: 0.74861111 | G21: 4414.023 | I21: 972.30599 | K21: 3549 | M21: 1805 | O21: CLOSED | Q21: =G21+I21+K21+M21 -> 10740.329
A22: January | B22: 11 | C22: Sun | D22: -1.2 | E22: 0.78125 | F22: * | G22: 1454.2087 | H22: * | I22: =+(K22+M22)*(I21+I20)/(K20+K21+M20+M21) -> 376.55686 | K22: 1354 | M22: 664 | O22: CLOSED | Q22: =G22+I22+K22+M22 -> 3848.7655
A24: February | B24: 6 | C24: Fri | D24: -0.1 | E24: 0.66319444 | G24: CLOSED | I24: 2168.8556 | K24: 3017 | M24: 2450 | O24: CLOSED | Q24: =I24+K24+M24 -> 7635.8556
A25: February | B25: 7 | C25: Sat | D25: -0.4 | E25: 0.70138889 | G25: 21386.288 | I25: 4870.6627 | K25: 7631 | M25: 8211 | O25: CLOSED | Q25: =G25+I25+K25+M25 -> 42098.951
A26: February | B26: 8 | C26: Sun | D26: -0.6 | E26: 0.73541667 | G26: 7373.6259 | H26: * | I26: =(K26+M26)*(I24+I25)/(K24+K25+M24+M25) -> 3155.5436 | K26: 7040 | M26: 2512 | O26: CLOSED | Q26: =G26+I26+K26+M26 -> 20081.169
A28: March | B28: 27 | C28: Fri | D28: 0 | E28: 0.32569444 | G28: CLOSED | I28: 2762.5447 | K28: CLOSED | M28: 3022 | O28: CLOSED | Q28: =I28+M28 -> 5784.5447
A29: March | B29: 28 | C29: Sat | D29: -0.4 | E29: 0.35347222 | G29: 16925.76 | H29: * | I29: =+(K29+M29)*(I25+I24)/(K24+K25+M24+M25) -> 6007.4916 | K29: 12602 | M29: 5583 | O29: CLOSED | Q29: =G29+I29+K29+M29 -> 41118.251
A30: March | B30: 29 | C30: Sun | D30: -0.6 | E30: 0.38333333 | G30: 8951.6615 | H30: * | I30: =+(K30+M30)*(I25+I24)/(K24+K25+M24+M25) -> 3697.9852 | K30: 7418 | M30: 3776 | O30: CLOSED | Q30: =G30+I30+K30+M30 -> 23843.647
A32: April | B32: 10 | C32: Fri | D32: -0.7 | E32: 0.32291667 | G32: CLOSED | I32: 2957.6468 | K32: CLOSED | M32: CLOSED | O32: CLOSED | Q32: =+I32 -> 2957.6468
A33: April | B33: 11 | C33: Sat | D33: -0.7 | E33: 0.35069444 | G33: 8386.0971 | I33: 4396.2815 | K33: CLOSED | M33: CLOSED | O33: CLOSED | Q33: =+G33+I33 -> 12782.379
A34: April | B34: 12 | C34: Sun | D34: -0.5 | E34: 0.37847222 | G34: 2548.129 | I34: 1320.8995 | K34: CLOSED | M34: CLOSED | O34: CLOSED | Q34: =+G34+I34 -> 3869.0285
A36: April | B36: 25 | C36: Sat | D36: -1.3 | E36: 0.31041667 | G36: 9746.1202 | H36: * | I36: =(K36+M36)*I38/(M38+K38) -> 3771.3328 | K36: 9618 | M36: 5520 | O36: CLOSED | Q36: =+G36+I36+K36+M36 -> 28655.453
A37: April | B37: 26 | C37: Sun | D37: -1.6 | E37: 0.34027778 | F37: * | G37: =(K37+M37)*G36/(K36+M36) -> 8446.2512 | H37: * | I37: =(K37+M37)*I38/(K38+M38) -> 3268.3389 | K37: 8554 | M37: 4565 | O37: CLOSED | Q37: =+G37+I37+K37+M37 -> 24833.59
A38: April | B38: 27 | C38: Mon | D38: -1.7 | E38: 0.37152778 | G38: 6551.2901 | I38: 1263.0901 | K38: 3369 | M38: 1701 | O38: CLOSED | Q38: =+G38+I38+K38+M38 -> 12884.38
A40: May | B40: 9 | C40: 39942 | D40: -1.2 | E40: 0.30763889 | G40: 4582.4235 | H40: * | I40: =+(K40+M40)*I38/(K38+M38) -> 1519.6942 | K40: 4245 | M40: 1855 | O40: CLOSED | Q40: =G40+I40+K40+M40 -> 12202.118
A41: May | B41: 10 | C41: 39943 | D41: -1.2 | E41: 0.33472222 | G41: 6484.4224 | I41: 3060.3397 | K41: CLOSED | M41: CLOSED | O41: CLOSED | Q41: =G41+I41 -> 9544.7621
A44: SEASON TOTALS : | G44: =SUM(G5:G43) -> 139448.96 | I44: =SUM(I5:I43) -> 57758.806 | K44: =SUM(K5:K43) -> 92574.5 | M44: =SUM(M5:M43) -> 54895.142 | O44: =SUM(O5:O43) -> 0 | Q44: =SUM(Q5:Q43) -> 344677.41
A45: *- estimate based on comparison of other beaches. + - no harvest due to very heavy surf and storm warnings.
A46: page 3 of 3

Sheet table
A1: 2008-2009 State (non-Indian) Recreational Razor Clam Effort, Harvest and CPUE totals.
E2: LONG BEACH | H2: TWIN HARBORS | K2: COPALIS | O2: MOCROCKS | Q2: KALALOCH | T2: DAILY TOTALS
A3: DATE | B3: DAY | C3: TIDE | D3: TIME | E3: Effort | F3: Harvest | G3: CPUE | H3: Effort | I3: Harvest | J3: CPUE | K3: Effort | L3: Harvest | M3: CPUE | N3: Effort | O3: Harvest | P3: CPUE | Q3: Effort | R3: Harvest | S3: CPUE | T3: Effort | U3: Harvest
A4: 39737 | B4: Thu | C4: -1.5 | D4: 0.85416667 | E4: =effort!G5 -> CLOSED | F4: =harvest!G5 -> CLOSED | G4: =cpue!G5 -> CLOSED | H4: =effort!I5 -> 1921.9714 | I4: =harvest!I5 -> 27954.765 | J4: =cpue!I5 -> 14.544839 | K4: =effort!K5 -> 2036 | L4: =harvest!K5 -> 29912 | M4: =cpue!K5 -> 14.691552 | N4: =effort!M5 -> 1932 | O4: =harvest!M5 -> 28766 | P4: =cpue!M5 -> 14.889234 | Q4: =effort!O5 -> CLOSED | R4: =harvest!O5 -> CLOSED | S4: =cpue!O5 -> CLOSED | T4: =+H4+K4+N4 -> 5889.9714 | U4: =+I4+L4+O4 -> 86632.765
A5: 39738 | B5: Fri | C5: -1.5 | D5: 0.88680556 | E5: =effort!G6 -> 4505.1719 | F5: =harvest!G6 -> 65673.67 | G5: =cpue!G6 -> 14.577395 | H5: =effort!I6 -> 1845.5079 | I5: =harvest!I6 -> 26913.657 | J5: =cpue!I6 -> 14.583333 | K5: =effort!K6 -> 1955 | L5: =harvest!K6 -> 28798 | M5: =cpue!K6 -> 14.730435 | N5: =effort!M6 -> 1002 | O5: =harvest!M6 -> 15026 | P5: =cpue!M6 -> 14.996008 | Q5: =effort!O6 -> CLOSED | R5: =harvest!O6 -> CLOSED | S5: =cpue!O6 -> CLOSED | T5: =E5+H5+K5+N5 -> 9307.6798 | U5: =F5+I5+L5+O5 -> 136411.33
A6: 39739 | B6: Sat | C6: -1.2 | D6: 0.92222222 | E6: =effort!G7 -> 7718.918 | F6: =harvest!G7 -> 94400.281 | G6: =cpue!G7 -> 12.22973 | H6: =effort!I7 -> 2477.0398 | I6: =harvest!I7 -> 35803.258 | J6: =cpue!I7 -> 14.45405 | K6: =effort!K7 -> 2624 | L6: =harvest!K7 -> 38310 | M6: =cpue!K7 -> 14.599848 | N6: =effort!M7 -> 1929.0443 | O6: =harvest!M7 -> 28575.567 | P6: =cpue!M7 -> 14.813328 | Q6: =effort!O7 -> CLOSED | R6: =harvest!O7 -> CLOSED | S6: =cpue!O7 -> CLOSED | T6: =E6+H6+K6+N6 -> 14749.002 | U6: =F6+I6+L6+O6 -> 197089.11
A7: Tide Series Totals | E7: =SUM(E4:E6) -> 12224.09 | F7: =SUM(F4:F6) -> 160073.95 | G7: =F7/E7 -> 13.094959 | H7: =SUM(H4:H6) -> 6244.5192 | I7: =SUM(I4:I6) -> 90671.68 | J7: =I7/H7 -> 14.520202 | K7: =SUM(K4:K6) -> 6615 | L7: =SUM(L4:L6) -> 97020 | M7: =L7/K7 -> 14.666667 | N7: =SUM(N4:N6) -> 4863.0443 | O7: =SUM(O4:O6) -> 72367.567 | P7: =O7/N7 -> 14.881124 | Q7: =SUM(Q4:Q6) -> 0 | R7: =SUM(R4:R6) -> 0 | S7: =R7/Q7 -> #DIV/0! | T7: =E7+H7+K7+N7+Q7 -> 29946.653 | U7: =F7+I7+L7+O7+R7 -> 420133.2
A8: 39765 | B8: Thu | C8: -1.6 | D8: 0.76875 | E8: =effort!G9 -> CLOSED | F8: =harvest!G9 -> CLOSED | G8: =cpue!G9 -> CLOSED | H8: =effort!I9 -> CLOSED | I8: =harvest!I9 -> CLOSED | J8: =cpue!I9 -> CLOSED | K8: =effort!K9 -> 1626 | L8: =harvest!K9 -> 24384 | M8: =cpue!K9 -> 14.99631 | N8: =effort!M9 -> 979 | O8: =harvest!M9 -> 14366 | P8: =cpue!M9 -> 14.674157 | Q8: =effort!O9 -> CLOSED | R8: =harvest!O9 -> CLOSED | S8: =cpue!O9 -> CLOSED | T8: =K8+N8 -> 2605 | U8: =L8+O8 -> 38750
A9: 39766 | B9: Fri | C9: -1.8 | D9: 0.80208333 | E9: =effort!G10 -> 4330.1919 | F9: =harvest!G10 -> 63089.889 | G9: =cpue!G10 -> 14.569767 | H9: =effort!I10 -> 1946.9117 | I9: =harvest!I10 -> 25752.938 | J9: =cpue!I10 -> 13.227584 | K9: =effort!K10 -> 4567 | L9: =harvest!K10 -> 66392 | M9: =cpue!K10 -> 14.537333 | N9: =effort!M10 -> 1198 | O9: =harvest!M10 -> 17157 | P9: =cpue!M10 -> 14.321369 | Q9: =effort!O10 -> CLOSED | R9: =harvest!O10 -> CLOSED | S9: =cpue!O10 -> CLOSED | T9: =E9+H9+K9+N9 -> 12042.104 | U9: =F9+I9+L9+O9 -> 172391.83
A10: 39767 | B10: Sat | C10: -1.6 | D10: 0.83611111 | E10: =effort!G11 -> 9126.4105 | F10: =harvest!G11 -> 107131.61 | G10: =cpue!G11 -> 11.738636 | H10: =effort!I11 -> 2032.835 | I10: =harvest!I11 -> 28247.937 | J10: =cpue!I11 -> 13.895833 | K10: =effort!K11 -> 3221 | L10: =harvest!K11 -> 48480 | M10: =cpue!K11 -> 15.051226 | N10: =effort!M11 -> 2270 | O10: =harvest!M11 -> 32934 | P10: =cpue!M11 -> 14.50837 | Q10: =effort!O11 -> CLOSED | R10: =harvest!O11 -> CLOSED | S10: =cpue!O11 -> CLOSED | T10: =E10+H10+K10+N10 -> 16650.246 | U10: =F10+I10+L10+O10 -> 216793.55
A11: 39768 | B11: Sun | C11: -1.2 | D11: 0.87083333 | E11: =effort!G12 -> 2081.538 | F11: =harvest!G12 -> 27577.466 | G11: =cpue!G12 -> 13.248601 | H11: =effort!I12 -> 594.69918 | I11: =harvest!I12 -> 8258.4221 | J11: =cpue!I12 -> 13.886722 | K11: =effort!K12 -> 1345 | L11: =harvest!K12 -> 20170 | M11: =cpue!K12 -> 14.996283 | N11: =effort!M12 -> 337 | O11: =harvest!M12 -> 5058 | P11: =cpue!M12 -> 15.008902 | Q11: =effort!O12 -> CLOSED | R11: =harvest!O12 -> CLOSED | S11: =cpue!O12 -> CLOSED | T11: =E11+H11+K11+N11 -> 4358.2372 | U11: =F11+I11+L11+O11 -> 61063.888
A12: Tide Series Totals | E12: =SUM(E8:E11) -> 15538.14 | F12: =SUM(F8:F11) -> 197798.97 | G12: =F12/E12 -> 12.7299 | H12: =SUM(H8:H11) -> 4574.4459 | I12: =SUM(I8:I11) -> 62259.297 | J12: =I12/H12 -> 13.610238 | K12: =SUM(K8:K11) -> 10759 | L12: =SUM(L8:L11) -> 159426 | M12: =L12/K12 -> 14.81792 | N12: =SUM(N8:N11) -> 4784 | O12: =SUM(O8:O11) -> 69515 | P12: =O12/N12 -> 14.530727 | Q12: =SUM(Q8:Q11) -> 0 | R12: =SUM(R8:R11) -> 0 | S12: 0 | T12: =E12+H12+K12+N12+Q12 -> 35655.586 | U12: =F12+I12+L12+O12+R12 -> 488999.27
A13: 39793 | B13: Thu | C13: -1.1 | D13: 0.72430556 | E13: =effort!G14 -> CLOSED | F13: =harvest!G14 -> CLOSED | G13: =cpue!G14 -> CLOSED | H13: =effort!I14 -> CLOSED | I13: =harvest!I14 -> CLOSED | J13: =cpue!I14 -> CLOSED | K13: =effort!K14 -> 1543 | L13: =harvest!K14 -> 23147 | M13: =cpue!K14 -> 15.001296 | N13: =effort!M14 -> 1266 | O13: =harvest!M14 -> 18702 | P13: =cpue!M14 -> 14.772512 | Q13: =effort!O14 -> CLOSED | R13: =harvest!O14 -> CLOSED | S13: =cpue!O14 -> CLOSED | T13: =K13+N13 -> 2809 | U13: =L13+O13 -> 41849
A14: 39794 | B14: Fri | C14: -1.5 | D14: 0.75902778 | E14: =effort!G15 -> 204.06433 | F14: =harvest!G15 -> 734.63159 | G14: =cpue!G15 -> 3.6 | H14: =effort!I15 -> 100.91333 | I14: =harvest!I15 -> 51.762065 | J14: =cpue!I15 -> 0.51293587 | K14: =effort!K15 -> 458 | L14: =harvest!K15 -> 229 | M14: =cpue!K15 -> 0.5 | N14: =effort!M15 -> 229.93137 | O14: =harvest!M15 -> 118.3539 | P14: =cpue!M15 -> 0.51473576 | Q14: =effort!O15 -> CLOSED | R14: =harvest!O15 -> CLOSED | S14: =cpue!O15 -> CLOSED | T14: =E14+H14+K14+N14 -> 992.90902 | U14: =F14+I14+L14+O14 -> 1133.7476
A15: 39795 | B15: Sat | C15: -1.6 | D15: 0.79305556 | E15: =effort!G16 -> 1437.5565 | F15: =harvest!G16 -> 9213.43 | G15: =cpue!G16 -> 6.4090909 | H15: =effort!I16 -> 526.82045 | I15: =harvest!I16 -> 6909.6705 | J15: =cpue!I16 -> 13.115798 | K15: =effort!K16 -> 2391 | L15: =harvest!K16 -> 30569 | M15: =cpue!K16 -> 12.785027 | N15: =effort!M16 -> 709 | O15: =harvest!M16 -> 9060 | P15: =cpue!M16 -> 12.778561 | Q15: =effort!O16 -> CLOSED | R15: =harvest!O16 -> CLOSED | S15: =cpue!O16 -> CLOSED | T15: =E15+H15+K15+N15 -> 5064.3769 | U15: =F15+I15+L15+O15 -> 55752.101
A16: 39796 | B16: Sun | C16: -1.4 | D16: 0.82638889 | E16: =effort!G17 -> 86.524251 | F16: =harvest!G17 -> 715.20784 | G16: =cpue!G17 -> 8.2659813 | H16: =effort!I17 -> 18.067452 | I16: =harvest!I17 -> 276.44107 | J16: =cpue!I17 -> 15.300502 | K16: =effort!K17 -> 82 | L16: =harvest!K17 -> 1223 | M16: =cpue!K17 -> 14.914634 | N16: =effort!M17 -> 41.166751 | O16: =harvest!M17 -> 632.08217 | P16: =cpue!M17 -> 15.354191 | Q16: =effort!O17 -> CLOSED | R16: =harvest!O17 -> CLOSED | S16: =cpue!O17 -> CLOSED | T16: =E16+H16+K16+N16 -> 227.75845 | U16: =F16+I16+L16+O16 -> 2846.7311
A17: Tide Series Totals | E17: =SUM(E13:E16) -> 1728.145 | F17: =SUM(F13:F16) -> 10663.269 | G17: =F17/E17 -> 6.1703556 | H17: =SUM(H13:H16) -> 645.80122 | I17: =SUM(I13:I16) -> 7237.8737 | J17: =I17/H17 -> 11.207587 | K17: =SUM(K13:K16) -> 4474 | L17: =SUM(L13:L16) -> 55168 | M17: =L17/K17 -> 12.3308 | N17: =SUM(N13:N16) -> 2246.0981 | O17: =SUM(O13:O16) -> 28512.436 | P17: =O17/N17 -> 12.694208 | T17: =E17+H17+K17+N17+Q17 -> 9094.0444 | U17: =F17+I17+L17+O17+R17 -> 101581.58
A18: 39821 | B18: Thu | C18: -0.2 | D18: 0.67569444 | E18: =effort!G19 -> CLOSED | F18: =harvest!G19 -> CLOSED | G18: =cpue!G19 -> CLOSED | H18: =effort!I19 -> 241.48995 | I18: =harvest!I19 -> 3494.5016 | J18: =cpue!I19 -> 14.470588 | K18: =effort!K19 -> 776.5 | L18: =harvest!K19 -> 11507 | M18: =cpue!K19 -> 14.81906 | N18: =effort!M19 -> 446 | O18: =harvest!M19 -> 6686.5 | P18: =cpue!M19 -> 14.992152 | Q18: =effort!O19 -> CLOSED | R18: =harvest!O19 -> CLOSED | S18: =cpue!O19 -> CLOSED | T18: =K18+N18 -> 1222.5 | U18: =I18+L18+O18 -> 21688.002
A19: 39822 | B19: Fri | C19: -0.8 | D19: 0.71319444 | E19: =effort!G20 -> 2708.2845 | F19: =harvest!G20 -> 38254.519 | G19: =cpue!G20 -> 14.125 | H19: =effort!I20 -> 482.9799 | I19: =harvest!I20 -> 6989.0032 | J19: =cpue!I20 -> 14.470588 | K19: =effort!K20 -> 1553 | L19: =harvest!K20 -> 23014 | M19: =cpue!K20 -> 14.81906 | N19: =effort!M20 -> 892 | O19: =harvest!M20 -> 13373 | P19: =cpue!M20 -> 14.992152 | Q19: =effort!O20 -> CLOSED | R19: =harvest!O20 -> CLOSED | S19: =cpue!O20 -> CLOSED | T19: =E19+H19+K19+N19 -> 5636.2644 | U19: =F19+I19+L19+O19 -> 81630.522
A20: 39823 | B20: Sat | C20: -1.1 | D20: 0.74861111 | E20: =+H20+K20+N20 -> 6326.306 | F20: =harvest!G21 -> 28266.724 | G20: =cpue!G21 -> 6.4038462 | H20: =effort!I21 -> 972.30599 | I20: =harvest!I21 -> 7601.665 | J20: =cpue!I21 -> 7.8181818 | K20: =effort!K21 -> 3549 | L20: =harvest!K21 -> 49358 | M20: =cpue!K21 -> 13.90758 | N20: =effort!M21 -> 1805 | O20: =harvest!M21 -> 24103 | P20: =cpue!M21 -> 13.353463 | Q20: =effort!O21 -> CLOSED | R20: =harvest!O21 -> CLOSED | S20: =cpue!O21 -> CLOSED | T20: =K20+N20 -> 5354 | U20: =F20+I20+L20+O20 -> 109329.39
A21: 39824 | B21: Sun | C21: -1.2 | D21: 0.78125 | E21: =effort!G22 -> 1454.2087 | F21: =harvest!G22 -> 14012.625 | G21: =cpue!G22 -> 9.6359107 | H21: =effort!I22 -> 376.55686 | I21: =harvest!I22 -> 4103.393 | J21: =cpue!I22 -> 10.897141 | K21: =effort!K22 -> 1354 | L21: =harvest!K22 -> 20928 | M21: =cpue!K22 -> 15.456425 | N21: =effort!M22 -> 664 | O21: =harvest!M22 -> 9965 | P21: =cpue!M22 -> 15.00753 | Q21: =effort!O22 -> CLOSED | R21: =harvest!O22 -> CLOSED | S21: =cpue!O22 -> CLOSED | T21: =E21+H21+K21+N21 -> 3848.7655 | U21: =F21+I21+L21+O21 -> 49009.018
A22: Tide Series Totals | E22: =SUM(E18:E21) -> 10488.799 | F22: =SUM(F18:F21) -> 80533.868 | G22: =F22/E22 -> 7.6780827 | H22: =SUM(H18:H21) -> 2073.3327 | I22: =SUM(I18:I21) -> 22188.563 | J22: =I22/H22 -> 10.701882 | K22: =SUM(K18:K21) -> 7232.5 | L22: =SUM(L18:L21) -> 104807 | M22: =L22/K22 -> 14.491116 | N22: =SUM(N18:N21) -> 3807 | O22: =SUM(O18:O21) -> 54127.5 | P22: =O22/N22 -> 14.217888 | T22: =E22+H22+K22+N22+Q22 -> 23601.632 | U22: =F22+I22+L22+O22+R22 -> 261656.93
A23: 39850 | B23: Fri | C23: -0.1 | D23: 0.66319444 | E23: =effort!G24 -> CLOSED | F23: =harvest!G24 -> CLOSED | G23: =cpue!G24 -> CLOSED | H23: =effort!I24 -> 2168.8556 | I23: =harvest!I24 -> 32532.833 | J23: =cpue!I24 -> 15 | K23: =effort!K24 -> 3017 | L23: =harvest!K24 -> 46064 | M23: =cpue!K24 -> 15.268147 | N23: =effort!M24 -> 2450 | O23: =harvest!M24 -> 36754 | P23: =cpue!M24 -> 15.001633 | Q23: =effort!O24 -> CLOSED | R23: =harvest!O24 -> CLOSED | S23: =cpue!O24 -> CLOSED | T23: =K23+N23 -> 5467 | U23: =I23+L23+O23 -> 115350.83
A24: 39851 | B24: Sat | C24: -0.4 | D24: 0.70138889 | E24: =effort!G25 -> 21386.288 | F24: =harvest!G25 -> 140955.08 | G24: =cpue!G25 -> 6.5909091 | H24: =effort!I25 -> 4870.6627 | I24: =harvest!I25 -> 68371.927 | J24: =cpue!I25 -> 14.0375 | K24: =effort!K25 -> 7631 | L24: =harvest!K25 -> 108534 | M24: =cpue!K25 -> 14.222776 | N24: =effort!M25 -> 8211 | O24: =harvest!M25 -> 118708 | P24: =cpue!M25 -> 14.457192 | Q24: =effort!O25 -> CLOSED | R24: =harvest!O25 -> CLOSED | S24: =cpue!O25 -> CLOSED | T24: =E24+H24+K24+N24 -> 42098.951 | U24: =F24+I24+L24+O24 -> 436569.01
A25: 39852 | B25: Sun | C25: -0.6 | D25: 0.73541667 | E25: =effort!G26 -> 7373.6259 | F25: =harvest!G26 -> 62911.148 | G25: =cpue!G26 -> 8.5319149 | H25: =effort!I26 -> 3155.5436 | I25: =harvest!I26 -> 43330.208 | J25: =cpue!I26 -> 13.731456 | K25: =effort!K26 -> 7040 | L25: =harvest!K26 -> 95622 | M25: =cpue!K26 -> 13.58267 | N25: =effort!M26 -> 2512 | O25: =harvest!M26 -> 37523 | P25: =cpue!M26 -> 14.9375 | Q25: =effort!O26 -> CLOSED | R25: =harvest!O26 -> CLOSED | S25: =cpue!O26 -> CLOSED | T25: =E25+H25+K25+N25 -> 20081.169 | U25: =F25+I25+L25+O25 -> 239386.36
A26: Tide Series Totals | E26: =SUM(E23:E25) -> 28759.914 | F26: =SUM(F23:F25) -> 203866.23 | G26: =F26/E26 -> 7.0885549 | H26: =SUM(H23:H25) -> 10195.062 | I26: =SUM(I23:I25) -> 144234.97 | J26: =I26/H26 -> 14.147533 | K26: =SUM(K23:K25) -> 17688 | L26: =SUM(L23:L25) -> 250220 | M26: =L26/K26 -> 14.146314 | N26: =SUM(N23:N25) -> 13173 | O26: =SUM(O23:O25) -> 192985 | P26: =O26/N26 -> 14.650042 | Q26: =SUM(Q23:Q25) -> 0 | R26: =SUM(R23:R25) -> 0 | T26: =E26+H26+K26+N26+Q26 -> 69815.976 | U26: =F26+I26+L26+O26+R26 -> 791306.2
A27: 39899 | B27: Fri | C27: 0 | D27: 0.32569444 | E27: =effort!G28 -> CLOSED | F27: =harvest!G28 -> CLOSED | G27: =cpue!G28 -> CLOSED | H27: =effort!I28 -> 2762.5447 | I27: =harvest!I28 -> 41438.171 | J27: =cpue!I28 -> 15 | K27: =effort!K28 -> CLOSED | L27: =harvest!K28 -> CLOSED | M27: =cpue!K28 -> CLOSED | N27: =effort!M28 -> 3022 | O27: =harvest!M28 -> 44725 | P27: =cpue!M28 -> 14.799801 | Q27: =effort!O28 -> CLOSED | R27: =harvest!O28 -> CLOSED | S27: =cpue!O28 -> CLOSED | T27: =SUM(H27,K27,N27) -> 5784.5447 | U27: =SUM(I27,O27) -> 86163.171
A28: 39900 | B28: Sat | C28: -0.4 | D28: 0.35347222 | E28: =effort!G29 -> 16925.76 | F28: =harvest!G29 -> 62183.769 | G28: =cpue!G29 -> 3.673913 | H28: =effort!I29 -> 6007.4916 | I28: =harvest!I29 -> 61532.508 | J28: =cpue!I29 -> 5.9 | K28: =effort!K29 -> 12602 | L28: =harvest!K29 -> 112127 | M28: =cpue!K29 -> 8.8975559 | N28: =effort!M29 -> 5583 | O28: =harvest!M29 -> 76950 | P28: =cpue!M29 -> 13.782912 | Q28: =effort!O29 -> CLOSED | R28: =harvest!O29 -> CLOSED | S28: =cpue!O29 -> CLOSED | T28: =SUM(E28,H28,K28,N28) -> 41118.251 | U28: =SUM(F28,I28,L28,O28) -> 312793.28
A29: 39901 | B29: Sun | C29: -0.6 | D29: 0.38333333 | E29: =effort!G30 -> 8951.6615 | F29: =harvest!G30 -> 99542.476 | G29: =cpue!G30 -> 11.12 | H29: =effort!I30 -> 3697.9852 | I29: =harvest!I30 -> 53833.663 | J29: =cpue!I30 -> 12.75 | K29: =effort!K30 -> 7418 | L29: =harvest!K30 -> 109258 | M29: =cpue!K30 -> 14.728768 | N29: =effort!M30 -> 3776 | O29: =harvest!M30 -> 56162 | P29: =cpue!M30 -> 14.873411 | Q29: =effort!O30 -> CLOSED | R29: =harvest!O30 -> CLOSED | S29: =cpue!O30 -> CLOSED | T29: =SUM(E29,H29,K29,N29) -> 23843.647 | U29: =SUM(F29,I29,L29,O29) -> 318796.14
A30: Tide Series Totals | E30: =SUM(E27:E29) -> 25877.421 | F30: =SUM(F27:F29) -> 161726.25 | G30: =F30/E30 -> 6.2497049 | H30: =SUM(H27:H29) -> 12468.022 | I30: =SUM(I27:I29) -> 156804.34 | J30: =I30/H30 -> 12.576522 | K30: =SUM(K27:K29) -> 20020 | L30: =SUM(L27:L29) -> 221385 | M30: =L30/K30 -> 11.058192 | N30: =SUM(N27:N29) -> 12381 | O30: =SUM(O27:O29) -> 177837 | P30: =O30/N30 -> 14.363702 | Q30: =SUM(Q27:Q29) -> 0 | R30: =SUM(R27:R29) -> 0 | T30: =E30+H30+K30+N30+Q30 -> 70746.443 | U30: =F30+I30+L30+O30+R30 -> 717752.59
A31: 39913 | B31: Fri | C31: -0.1 | D31: 0.66319444 | E31: =effort!G32 -> CLOSED | F31: =harvest!G32 -> CLOSED | G31: =cpue!G32 -> CLOSED | H31: =effort!I32 -> 2957.6468 | I31: =harvest!I32 -> 44364.702 | J31: =cpue!I32 -> 15 | K31: =effort!K32 -> CLOSED | L31: =harvest!K32 -> CLOSED | M31: =cpue!K32 -> CLOSED | N31: =effort!M32 -> CLOSED | O31: =harvest!M32 -> CLOSED | P31: =cpue!M32 -> CLOSED | Q31: =effort!O32 -> CLOSED | R31: =harvest!O32 -> CLOSED | S31: =cpue!O32 -> CLOSED | T31: =H31 -> 2957.6468 | U31: =I31 -> 44364.702
A32: 39914 | B32: Sat | C32: -0.4 | D32: 0.70138889 | E32: =effort!G33 -> 8386.0971 | F32: =harvest!G33 -> 125791.46 | G32: =cpue!G33 -> 15 | H32: =effort!I33 -> 4396.2815 | I32: =harvest!I33 -> 62187.4 | J32: =cpue!I33 -> 14.145455 | K32: =effort!K33 -> CLOSED | L32: =harvest!K33 -> CLOSED | M32: =cpue!K33 -> CLOSED | N32: =effort!M33 -> CLOSED | O32: =harvest!M33 -> CLOSED | P32: =cpue!M33 -> CLOSED | Q32: =effort!O33 -> CLOSED | R32: =harvest!O33 -> CLOSED | S32: =cpue!O33 -> CLOSED | T32: =E32+H32 -> 12782.379 | U32: =F32+I32 -> 187978.86
A33: 39915 | B33: Sun | C33: -0.6 | D33: 0.73541667 | E33: =effort!G34 -> 2548.129 | F33: =harvest!G34 -> 19535.656 | G33: =cpue!G34 -> 7.6666667 | H33: =effort!I34 -> 1320.8995 | I33: =harvest!I34 -> 12081.398 | J33: =cpue!I34 -> 9.1463415 | K33: =effort!K34 -> CLOSED | L33: =harvest!K34 -> CLOSED | M33: =cpue!K34 -> CLOSED | N33: =effort!M34 -> CLOSED | O33: =harvest!M34 -> CLOSED | P33: =cpue!M34 -> CLOSED | Q33: =effort!O34 -> CLOSED | R33: =harvest!O34 -> CLOSED | S33: =cpue!O34 -> CLOSED | T33: =E33+H33 -> 3869.0285 | U33: =F33+I33 -> 31617.054
A34: Tide Series Totals | E34: =SUM(E31:E33) -> 10934.226 | F34: =SUM(F31:F33) -> 145327.11 | G34: =F34/E34 -> 13.291029 | H34: =SUM(H31:H33) -> 8674.8278 | I34: =SUM(I31:I33) -> 118633.5 | J34: =I34/H34 -> 13.675603 | K34: =SUM(K31:K33) -> 0 | L34: =SUM(L31:L33) -> 0 | M34: =L34/K34 -> #DIV/0! | N34: =SUM(N31:N33) -> 0 | O34: =SUM(O31:O33) -> 0 | P34: =O34/N34 -> #DIV/0! | Q34: =SUM(Q31:Q33) -> 0 | R34: =SUM(R31:R33) -> 0 | T34: =E34+H34+K34+N34+Q34 -> 19609.054 | U34: =F34+I34+L34+O34+R34 -> 263960.61
A35: 39928 | B35: Fri | C35: -0.1 | D35: 0.66319444 | E35: =effort!G36 -> 9746.1202 | F35: =harvest!G36 -> 101760.96 | G35: =cpue!G36 -> 10.441176 | H35: =effort!I36 -> 3771.3328 | I35: =harvest!I36 -> 56511.053 | J35: =cpue!I36 -> 14.984372 | K35: =effort!K36 -> 9618 | L35: =harvest!K36 -> 144271 | M35: =cpue!K36 -> 15.000104 | N35: =effort!M36 -> 5520 | O35: =harvest!M36 -> 82807 | P35: =cpue!M36 -> 15.001268 | Q35: =effort!O36 -> CLOSED | R35: =harvest!O36 -> CLOSED | S35: =cpue!O36 -> CLOSED | T35: =E35+H35+K35+N35 -> 28655.453 | U35: =F35+I35+L35+O35 -> 385350.01
A36: 39929 | B36: Sat | C36: -0.4 | D36: 0.70138889 | E36: =effort!G37 -> 8446.2512 | F36: =harvest!G37 -> 87264.332 | G36: =cpue!G37 -> 10.331724 | H36: =effort!I37 -> 3268.3389 | I36: =harvest!I37 -> 48460.62 | J36: =cpue!I37 -> 14.827293 | K36: =effort!K37 -> 8554 | L36: =harvest!K37 -> 126966 | M36: =cpue!K37 -> 14.842881 | N36: =effort!M37 -> 4565 | O36: =harvest!M37 -> 67763 | P36: =cpue!M37 -> 14.844031 | Q36: =effort!O37 -> CLOSED | R36: =harvest!O37 -> CLOSED | S36: =cpue!O37 -> CLOSED | T36: =E36+H36+K36+N36 -> 24833.59 | U36: =F36+I36+L36+O36 -> 330453.95
A37: 39930 | B37: Sun | C37: -0.6 | D37: 0.73541667 | E37: =effort!G38 -> 6551.2901 | F37: =harvest!G38 -> 84864.404 | G37: =cpue!G38 -> 12.953846 | H37: =effort!I38 -> 1263.0901 | I37: =harvest!I38 -> 18946.351 | J37: =cpue!I38 -> 15 | K37: =effort!K38 -> 3369 | L37: =harvest!K38 -> 50615 | M37: =cpue!K38 -> 15.023746 | N37: =effort!M38 -> 1701 | O37: =harvest!M38 -> 25517 | P37: =cpue!M38 -> 15.001176 | Q37: =effort!O38 -> CLOSED | R37: =harvest!O38 -> CLOSED | S37: =cpue!O38 -> CLOSED | T37: =E37+H37+K37+N37 -> 12884.38 | U37: =F37+I37+L37+O37 -> 179942.75
A38: Tide Series Totals | E38: =SUM(E35:E37) -> 24743.661 | F38: =SUM(F35:F37) -> 273889.7 | G38: =F38/E38 -> 11.069085 | H38: =SUM(H35:H37) -> 8302.7618 | I38: =SUM(I35:I37) -> 123918.02 | J38: =I38/H38 -> 14.924916 | K38: =SUM(K35:K37) -> 21541 | L38: =SUM(L35:L37) -> 321852 | M38: =L38/K38 -> 14.941368 | N38: =SUM(N35:N37) -> 11786 | O38: =SUM(O35:O37) -> 176087 | P38: =O38/N38 -> 14.940353 | Q38: =SUM(Q35:Q37) -> 0 | R38: =SUM(R35:R37) -> 0 | T38: =E38+H38+K38+N38+Q38 -> 66373.423 | U38: =F38+I38+L38+O38+R38 -> 895746.72
A39: 39942 | B39: Sat | C39: -1.2 | D39: 0.30763889 | E39: =effort!G40 -> 4582.4235 | F39: =harvest!G40 -> 63221.911 | G39: =cpue!G40 -> 13.79661 | H39: =effort!I40 -> 1519.6942 | I39: =harvest!I40 -> 22742.241 | J39: =cpue!I40 -> 15 | K39: =effort!K40 -> 4245 | L39: =harvest!K40 -> 63672 | M39: =cpue!K40 -> 14.999293 | N39: =effort!M40 -> 1855 | O39: =harvest!M40 -> 27713 | P39: =cpue!M40 -> 14.939623 | Q39: =effort!O40 -> CLOSED | R39: =harvest!O40 -> CLOSED | S39: =cpue!O40 -> CLOSED | T39: =E39+H39+K39+N39 -> 12202.118 | U39: =F39+I39+L39+O39 -> 177349.15
A40: 39943 | B40: Sun | C40: -1.2 | D40: 0.33472222 | E40: =effort!G41 -> 6484.4224 | F40: =harvest!G41 -> 91926.223 | G40: =cpue!G41 -> 14.176471 | H40: =effort!I41 -> 3060.3397 | I40: =harvest!I41 -> 45905.096 | J40: =cpue!I41 -> 15 | K40: =effort!K41 -> CLOSED | L40: =harvest!K41 -> CLOSED | M40: =cpue!K41 -> CLOSED | N40: =effort!M41 -> CLOSED | O40: =harvest!M41 -> CLOSED | P40: =cpue!M41 -> CLOSED | Q40: =effort!O41 -> CLOSED | R40: =harvest!O41 -> CLOSED | S40: =cpue!O41 -> CLOSED | T40: =E40+H40 -> 9544.7621 | U40: =F40+I40 -> 137831.32
...

Sheet State-Tribal Update
A1: 2008 - 2009 Non-Indian recreational razor clam effort, harvest and CPUE totals / Co-managed beaches only.
E2: COPALIS | I2: MOCROCKS | M2: KALALOCH | Q2: DAILY TOTALS
A3: DATE | B3: DAY | C3: TIDE | D3: TIME | E3: Effort | F3: Harvest | G3: CPUE | H3: Avg. Size | I3: Effort | J3: Harvest | K3: CPUE | L3: Avg. Size | M3: Effort | N3: Harvest | O3: CPUE | P3: Avg. Size | Q3: Effort | R3: Harvest
A4: 39737 | B4: Thu | C4: -1.5 | D4: 0.85416667 | E4: =table!K4 -> 2036 | F4: =table!L4 -> 29912 | G4: =table!M4 -> 14.691552 | I4: =table!N4 -> 1932 | J4: =table!O4 -> 28766 | K4: =table!P4 -> 14.889234 | M4: CLOSED | N4: CLOSED | O4: CLOSED | Q4: =E4+I4 -> 3968 | R4: =F4+J4 -> 58678
A5: 39738 | B5: Fri | C5: -1.5 | D5: 0.88680556 | E5: =table!K5 -> 1955 | F5: =table!L5 -> 28798 | G5: =table!M5 -> 14.730435 | I5: =table!N5 -> 1002 | J5: =table!O5 -> 15026 | K5: =table!P5 -> 14.996008 | M5: CLOSED | N5: CLOSED | O5: CLOSED | Q5: =E5+I5 -> 2957 | R5: =F5+J5 -> 43824
A6: 39739 | B6: Sat | C6: -1.2 | D6: 0.92222222 | E6: =table!K6 -> 2624 | F6: =table!L6 -> 38310 | G6: =table!M6 -> 14.599848 | I6: =table!N6 -> 1929.0443 | J6: =table!O6 -> 28575.567 | K6: =table!P6 -> 14.813328 | M6: CLOSED | N6: CLOSED | O6: CLOSED | Q6: =E6+I6 -> 4553.0443 | R6: =F6+J6 -> 66885.567
A7: Tide Series Totals | E7: =SUM(E4:E6) -> 6615 | F7: =SUM(F4:F6) -> 97020 | G7: =F7/E7 -> 14.666667 | I7: =SUM(I4:I6) -> 4863.0443 | J7: =SUM(J4:J6) -> 72367.567 | K7: =J7/I7 -> 14.881124 | M7: 0 | N7: 0 | O7: 0 | Q7: =SUM(Q4:Q6) -> 11478.044 | R7: =SUM(R4:R6) -> 169387.57
A8: 39765 | B8: Thu | C8: -1.6 | D8: 0.76875 | E8: =table!K8 -> 1626 | F8: =table!L8 -> 24384 | G8: =table!M8 -> 14.99631 | I8: =table!N8 -> 979 | J8: =table!O8 -> 14366 | K8: =table!P8 -> 14.674157 | M8: CLOSED | N8: CLOSED | O8: CLOSED | Q8: =E8+I8 -> 2605 | R8: =F8+J8 -> 38750
A9: 39766 | B9: Fri | C9: -1.8 | D9: 0.80208333 | E9: =table!K9 -> 4567 | F9: =table!L9 -> 66392 | G9: =table!M9 -> 14.537333 | I9: =table!N9 -> 1198 | J9: =table!O9 -> 17157 | K9: =table!P9 -> 14.321369 | M9: CLOSED | N9: CLOSED | O9: CLOSED | Q9: =E9+I9 -> 5765 | R9: =F9+J9 -> 83549
A10: 39767 | B10: Sat | C10: -1.6 | D10: 0.83611111 | E10: =table!K10 -> 3221 | F10: =table!L10 -> 48480 | G10: =table!M10 -> 15.051226 | I10: =table!N10 -> 2270 | J10: =table!O10 -> 32934 | K10: =table!P10 -> 14.50837 | M10: CLOSED | N10: CLOSED | O10: CLOSED | Q10: =E10+I10 -> 5491 | R10: =F10+J10 -> 81414
A11: 39768 | B11: Sun | C11: -1.2 | D11: 0.87083333 | E11: =table!K11 -> 1345 | F11: =table!L11 -> 20170 | G11: =table!M11 -> 14.996283 | I11: =table!N11 -> 337 | J11: =table!O11 -> 5058 | K11: =table!P11 -> 15.008902 | M11: CLOSED | N11: CLOSED | O11: CLOSED | Q11: =E11+I11 -> 1682 | R11: =F11+J11 -> 25228
A12: Tide Series Totals | E12: =SUM(E8:E11) -> 10759 | F12: =SUM(F8:F11) -> 159426 | G12: =F12/E12 -> 14.81792 | I12: =SUM(I8:I11) -> 4784 | J12: =SUM(J8:J11) -> 69515 | K12: =J12/I12 -> 14.530727 | M12: 0 | N12: 0 | O12: 0 | Q12: =SUM(Q8:Q11) -> 15543 | R12: =SUM(R8:R11) -> 228941
A13: 39793 | B13: Thu | C13: -1.1 | D13: 0.72430556 | E13: =table!K13 -> 1543 | F13: =table!L13 -> 23147 | G13: =table!M13 -> 15.001296 | I13: =table!N13 -> 1266 | J13: =table!O13 -> 18702 | K13: =table!P13 -> 14.772512 | M13: CLOSED | N13: CLOSED | O13: CLOSED | Q13: =E13+I13 -> 2809 | R13: =F13+J13 -> 41849
A14: 39794 | B14: Fri | C14: -1.5 | D14: 0.75902778 | E14: =table!K14 -> 458 | F14: =table!L14 -> 229 | G14: =table!M14 -> 0.5 | I14: =table!N14 -> 229.93137 | J14: =table!O14 -> 118.3539 | K14: =table!P14 -> 0.51473576 | M14: CLOSED | N14: CLOSED | O14: CLOSED | Q14: =E14+I14 -> 687.93137 | R14: =F14+J14 -> 347.3539
A15: 39795 | B15: Sat | C15: -1.6 | D15: 0.79305556 | E15: =table!K15 -> 2391 | F15: =table!L15 -> 30569 | G15: =table!M15 -> 12.785027 | I15: =table!N15 -> 709 | J15: =table!O15 -> 9060 | K15: =table!P15 -> 12.778561 | M15: CLOSED | N15: CLOSED | O15: CLOSED | Q15: =E15+I15 -> 3100 | R15: =F15+J15 -> 39629
A16: 39796 | B16: Sun | C16: -1.4 | D16: 0.82638889 | E16: =table!K16 -> 82 | F16: =table!L16 -> 1223 | G16: =table!M16 -> 14.914634 | I16: =table!N16 -> 41.166751 | J16: =table!O16 -> 632.08217 | K16: =table!P16 -> 15.354191 | M16: CLOSED | N16: CLOSED | O16: CLOSED | Q16: =E16+I16 -> 123.16675 | R16: =F16+J16 -> 1855.0822
A17: Tide Series Totals | E17: =SUM(E13:E16) -> 4474 | F17: =SUM(F13:F16) -> 55168 | G17: =F17/E17 -> 12.3308 | I17: =SUM(I13:I16) -> 2246.0981 | J17: =SUM(J13:J16) -> 28512.436 | K17: =J17/I17 -> 12.694208 | M17: =SUM(M13:M16) -> 0 | N17: =SUM(N13:N16) -> 0 | O17: 0 | Q17: =SUM(Q13:Q16) -> 6720.0981 | R17: =SUM(R13:R16) -> 83680.436
A18: 39822 | B18: Thu | C18: -0.2 | D18: 0.67569444 | E18: =table!K18 -> 776.5 | F18: =table!L18 -> 11507 | G18: =table!M18 -> 14.81906 | I18: =table!N18 -> 446 | J18: =table!O18 -> 6686.5 | K18: =table!P18 -> 14.992152 | M18: CLOSED | N18: CLOSED | O18: CLOSED | Q18: =E18+I18 -> 1222.5 | R18: =F18+J18 -> 18193.5
A19: 39823 | B19: Fri | C19: -0.8 | D19: 0.71319444 | E19: =table!K19 -> 1553 | F19: =table!L19 -> 23014 | G19: =table!M19 -> 14.81906 | I19: =table!N19 -> 892 | J19: =table!O19 -> 13373 | K19: =table!P19 -> 14.992152 | M19: CLOSED | N19: CLOSED | O19: CLOSED | Q19: =E19+I19 -> 2445 | R19: =F19+J19 -> 36387
A20: 39824 | B20: Sat | C20: -1.1 | D20: 0.74861111 | E20: =table!K20 -> 3549 | F20: =table!L20 -> 49358 | G20: =table!M20 -> 13.90758 | I20: =table!N20 -> 1805 | J20: =table!O20 -> 24103 | K20: =table!P20 -> 13.353463 | M20: CLOSED | N20: CLOSED | O20: CLOSED | Q20: =E20+I20 -> 5354 | R20: =F20+J20 -> 73461
A21: 39825 | B21: Sun | C21: -1.2 | D21: 0.78125 | E21: =table!K21 -> 1354 | F21: =table!L21 -> 20928 | G21: =table!M21 -> 15.456425 | I21: =table!N21 -> 664 | J21: =table!O21 -> 9965 | K21: =table!P21 -> 15.00753 | M21: CLOSED | N21: CLOSED | O21: CLOSED | Q21: =E21+I21 -> 2018 | R21: =F21+J21 -> 30893
A22: Tide Series Totals | E22: =SUM(E18:E21) -> 7232.5 | F22: =SUM(F18:F21) -> 104807 | G22: =F22/E22 -> 14.491116 | I22: =SUM(I18:I21) -> 3807 | J22: =SUM(J18:J21) -> 54127.5 | K22: =J22/I22 -> 14.217888 | M22: 0 | N22: 0 | O22: 0 | Q22: =SUM(Q18:Q21) -> 11039.5 | R22: =SUM(R18:R21) -> 158934.5
A23: 39850 | B23: Fri | C23: -0.1 | D23: 0.66319444 | E23: =table!K23 -> 3017 | F23: =table!L23 -> 46064 | G23: =table!M23 -> 15.268147 | I23: =table!N23 -> 2450 | J23: =table!O23 -> 36754 | K23: =table!P23 -> 15.001633 | M23: CLOSED | N23: CLOSED | O23: CLOSED | Q23: =E23+I23 -> 5467 | R23: =F23+J23 -> 82818
A24: 39851 | B24: Sat | C24: -0.4 | D24: 0.70138889 | E24: =table!K24 -> 7631 | F24: =table!L24 -> 108534 | G24: =table!M24 -> 14.222776 | I24: =table!N24 -> 8211 | J24: =table!O24 -> 118708 | K24: =table!P24 -> 14.457192 | M24: CLOSED | N24: CLOSED | O24: CLOSED | Q24: =E24+I24 -> 15842 | R24: =F24+J24 -> 227242
A25: 39852 | B25: Sun | C25: -0.6 | D25: 0.73541667 | E25: =table!K25 -> 7040 | F25: =table!L25 -> 95622 | G25: =table!M25 -> 13.58267 | I25: =table!N25 -> 2512 | J25: =table!O25 -> 37523 | K25: =table!P25 -> 14.9375 | M25: CLOSED | N25: CLOSED | O25: CLOSED | Q25: =E25+I25 -> 9552 | R25: =F25+J25 -> 133145
A26: Tide Series Totals | E26: =SUM(E23:E25) -> 17688 | F26: =SUM(F23:F25) -> 250220 | G26: =F26/E26 -> 14.146314 | I26: =SUM(I23:I25) -> 13173 | J26: =SUM(J23:J25) -> 192985 | K26: =J26/I26 -> 14.650042 | M26: 0 | N26: 0 | O26: 0 | Q26: =SUM(Q23:Q25) -> 30861 | R26: =SUM(R23:R25) -> 443205
A27: 39899 | B27: Fri | C27: 0 | D27: 0.32569444 | E27: =table!K27 -> CLOSED | F27: =table!L27 -> CLOSED | G27: =table!M27 -> CLOSED | I27: =table!N27 -> 3022 | J27: =table!O27 -> 44725 | K27: =table!P27 -> 14.799801 | M27: CLOSED | N27: CLOSED | O27: CLOSED | Q27: =I27 -> 3022 | R27: =J27 -> 44725
A28: 39900 | B28: Sat | C28: -0.4 | D28: 0.35347222 | E28: =table!K28 -> 12602 | F28: =table!L28 -> 112127 | G28: =table!M28 -> 8.8975559 | I28: =table!N28 -> 5583 | J28: =table!O28 -> 76950 | K28: =table!P28 -> 13.782912 | M28: CLOSED | N28: CLOSED | O28: CLOSED | Q28: =E28+I28 -> 18185 | R28: =F28+J28 -> 189077
A29: 39901 | B29: Sun | C29: -0.6 | D29: 0.38333333 | E29: =table!K29 -> 7418 | F29: =table!L29 -> 109258 | G29: =table!M29 -> 14.728768 | I29: =table!N29 -> 3776 | J29: =table!O29 -> 56162 | K29: =table!P29 -> 14.873411 | M29: CLOSED | N29: CLOSED | O29: CLOSED | Q29: =E29+I29 -> 11194 | R29: =F29+J29 -> 165420
A30: Tide Series Totals | E30: =SUM(E28:E29) -> 20020 | F30: =SUM(F28:F29) -> 221385 | G30: =F30/E30 -> 11.058192 | I30: =SUM(I27:I29) -> 12381 | J30: =SUM(J27:J29) -> 177837 | K30: =J30/I30 -> 14.363702 | M30: 0 | N30: 0 | O30: 0 | Q30: =SUM(Q27:Q29) -> 32401 | R30: =SUM(R27:R29) -> 399222
A31: 39913 | B31: Fri | C31: -0.7 | D31: 0.32291667 | E31: =table!K31 -> CLOSED | F31: =table!L31 -> CLOSED | G31: =table!M31 -> CLOSED | I31: =table!N31 -> CLOSED | J31: =table!O31 -> CLOSED | K31: =table!P31 -> CLOSED | M31: CLOSED | N31: CLOSED | O31: CLOSED
A32: 39914 | B32: Sat | C32: -0.7 | D32: 0.35069444 | E32: =table!K32 -> CLOSED | F32: =table!L32 -> CLOSED | G32: =table!M32 -> CLOSED | I32: =table!N32 -> CLOSED | J32: =table!O32 -> CLOSED | K32: =table!P32 -> CLOSED | M32: CLOSED | N32: CLOSED | O32: CLOSED
A33: 39915 | B33: Sun | C33: -0.5 | D33: 0.37847222 | E33: =table!K33 -> CLOSED | F33: =table!L33 -> CLOSED | G33: =table!M33 -> CLOSED | I33: =table!N33 -> CLOSED | J33: =table!O33 -> CLOSED | K33: =table!P33 -> CLOSED | M33: CLOSED | N33: CLOSED | O33: CLOSED
A34: Tide Series Totals | E34: =SUM(E32:E33) -> 0 | F34: =SUM(F32:F33) -> 0 | G34: =F34/E34 -> #DIV/0! | I34: =SUM(I31:I33) -> 0 | J34: =SUM(J31:J33) -> 0 | K34: =J34/I34 -> #DIV/0! | M34: 0 | N34: 0 | O34: 0 | Q34: =SUM(Q31:Q33) -> 0 | R34: =SUM(R31:R33) -> 0
A35: 39928 | B35: Sat | C35: -1.3 | D35: 0.31041667 | E35: =table!K35 -> 9618 | F35: =table!L35 -> 144271 | G35: =table!M35 -> 15.000104 | I35: =table!N35 -> 5520 | J35: =table!O35 -> 82807 | K35: =table!P35 -> 15.001268 | M35: CLOSED | N35: CLOSED | O35: CLOSED | Q35: =E35+I35 -> 15138 | R35: =F35+J35 -> 227078
A36: 39929 | B36: Sun | C36: -1.6 | D36: 0.34027778 | E36: =table!K36 -> 8554 | F36: =table!L36 -> 126966 | G36: =table!M36 -> 14.842881 | I36: =table!N36 -> 4565 | J36: =table!O36 -> 67763 | K36: =table!P36 -> 14.844031 | M36: CLOSED | N36: CLOSED | O36: CLOSED | Q36: =E36+I36 -> 13119 | R36: =F36+J36 -> 194729
A37: 39930 | B37: Mon | C37: -1.7 | D37: 0.37152778 | E37: =table!K37 -> 3369 | F37: =table!L37 -> 50615 | G37: =table!M37 -> 15.023746 | I37: =table!N37 -> 1701 | J37: =table!O37 -> 25517 | K37: =table!P37 -> 15.001176 | M37: CLOSED | N37: CLOSED | O37: CLOSED | Q37: =E37+I37 -> 5070 | R37: =F37+J37 -> 76132
A38: Tide Series Totals | E38: =SUM(E35:E37) -> 21541 | F38: =SUM(F35:F37) -> 321852 | G38: =F38/E38 -> 14.941368 | I38: =SUM(I35:I37) -> 11786 | J38: =SUM(J35:J37) -> 176087 | K38: =J38/I38 -> 14.940353 | Q38: =SUM(Q35:Q37) -> 33327 | R38: =SUM(R35:R37) -> 497939
A39: 39942 | B39: Sat | C39: -1.2 | D39: 0.30763889 | E39: =table!K39 -> 4245 | F39: =table!L39 -> 63672 | G39: =table!M39 -> 14.999293 | I39: =table!N39 -> 1855 | J39: =table!O39 -> 27713 | K39: =table!P39 -> 14.939623 | M39: CLOSED | N39: CLOSED | O39: CLOSED | Q39: =E39+I39 -> 6100 | R39: =F39+J39 -> 91385
A40: 39943 | B40: Sun | C40: -1.2 | D40: 0.33472222 | E40: =table!K40 -> CLOSED | F40: =table!L40 -> CLOSED | G40: =table!M40 -> CLOSED | I40: =table!N40 -> CLOSED | J40: =table!O40 -> CLOSED | K40: =table!P40 -> CLOSED | M40: CLOSED | N40: CLOSED | O40: CLOSED
...

Sheet LB - Wastage
A1: EventID | B1: BeachName | C1: Date | D1: SumOfWastage | E1: SumOfTotHarvest
A2: 146 | B2: LongBeach | C2: 39914 | D2: 16982 | E2: 125791.46
A3: 152 | B3: LongBeach | C3: 39928 | D3: 10685 | E3: 101760.96
A4: 158 | B4: LongBeach | C4: 39930 | D4: 6506 | E4: 84864.404
A5: 163 | B5: LongBeach | C5: 39943 | D5: 4595 | E5: 91926.223
D7: =SUM(D2:D6) -> 38768 | E7: =SUM(E2:E6) -> 404343.04 | F7: =+D7/E7 -> 0.095878983

Sheet Sheet1
A1: EventID | B1: BeachName | C1: Date | D1: SumOfNHoles | E1: SumOfNClams | F1: SumOfNMorts | G1: Wastage%
A2: 138 | B2: Copalis | C2: 39901 | D2: 200 | E2: 8 | F2: 8 | G2: 0.04
A3: 139 | B3: Mocrocks | C3: 39899 | D3: 90 | E3: 7 | F3: 7 | G3: 0.077777778
A4: 142 | B4: Twin Harbors | C4: 39899 | D4: 200 | E4: 17 | F4: 17 | G4: 0.085
A8: BeachName | B8: Date | C8: SumOfTotHarvest | D8: Wastage% | E8: ClamsWasted
A9: Copalis | B9: 39900 | C9: 82639 | D9: 0.04 | E9: 3305.56
A10: Copalis | B10: 39901 | C10: 82051 | D10: 0.04 | E10: 3282.04
A11: Mocrocks | B11: 39899 | C11: 37803 | D11: 0.077777778 | E11: 2940.2333
A12: Mocrocks | B12: 39900 | C12: 65608 | D12: 0.077777778 | E12: 5102.8444
A13: Mocrocks | B13: 39901 | C13: 46659 | D13: 0.077777778 | E13: 3629.0333
A14: Twin Harbors | B14: 39899 | C14: 35010 | D14: 0.085 | E14: 2975.85
A16: BeachName | B16: Date | C16: SumOfTotHarvest | D16: Wastage% | E16: ClamsWasted
A17: LongBeach | B17: 39914 | C17: 68010 | D17: 0.135 | E17: 9181.35
A18: LongBeach | B18: 39915 | C18: 15746 | D18: 0.135 | E18: 2125.71
A19: Twin Harbors | B19: 39913 | C19: 33045 | D19: 0.04 | E19: 1321.8
A20: Twin Harbors | B20: 39914 | C20: 53230 | D20: 0.04 | E20: 2129.2
A21: Twin Harbors | B21: 39915 | C21: 9603 | D21: 0.04 | E21: 384.12
A24: BeachName | B24: Date | C24: SumOfTotHarvest | D24: Wastage% | E24: ClamsWasted
A25: Copalis | B25: 39928 | C25: 110295 | D25: 0.046666667 | E25: 5147.1
A26: Copalis | B26: 39929 | C26: 97063 | D26: 0.046666667 | E26: 4529.6067
A27: LongBeach | B27: 39914 | C27: 68010 | D27: 0.105 | E27: 7141.05
A28: LongBeach | B28: 39915 | C28: 15746 | D28: 0.105 | E28: 1653.33
A29: LongBeach | B29: 39928 | C29: 76930 | D29: 0.105 | E29: 8077.65
A30: Mocrocks | B30: 39928 | C30: 69135 | D30: 0.0375 | E30: 2592.5625
A31: Mocrocks | B31: 39929 | C31: 55899 | D31: 0.0375 | E31: 2096.2125
A33: BeachName | B33: Date | C33: Sum Of EstCorEffort | D33: Sum Of TotHarvest | E33: Avg Of CPUE | F33: Count Of Spreadsheet
A34: Copalis | B34: 39930 | C34: 2558 | D34: 38432 | E34: 14.998871 | F34: 6
A35: LongBeach | B35: 39930 | C35: 4930 | D35: 62774 | E35: 12.208905 | F35: 7
A36: Mocrocks | B36: 39930 | C36: 1439 | D36: 21585 | E36: 15 | F36: 6
A37: Twin Harbors | B37: 39930 | C37: 1081 | D37: 16215 | E37: 15 | F37: 4
A39: BeachName | B39: Date | C39: SumOfTotHarvest | D39: Wastage% | E39: ClamsWasted
A40: Copalis | B40: 39928 | C40: 110295 | D40: 0.042666667 | E40: 4705.92
A41: Copalis | B41: 39929 | C41: 97063 | D41: 0.042666667 | E41: 4141.3547
A42: Copalis | B42: 39930 | C42: 38432 | D42: 0.042666667 | E42: 1639.7653
A43: LongBeach | B43: 39928 | C43: 76930 | D43: 0.088 | E43: 6769.84
A44: LongBeach | B44: 39930 | C44: 62774 | D44: 0.088 | E44: 5524.112
A45: Mocrocks | B45: 39928 | C45: 69135 | D45: 0.0375 | E45: 2592.5625
A46: Mocrocks | B46: 39929 | C46: 55899 | D46: 0.0375 | E46: 2096.2125
A47: Mocrocks | B47: 39930 | C47: 21585 | D47: 0.0375 | E47: 809.4375
A48: Twin Harbors | B48: 39930 | C48: 16215 | D48: 0.01 | E48: 162.15

Sheet TH - Wastage
A1: EventID | B1: BeachName | C1: Date | D1: SumOfWastage | E1: SumOfTotHarvest
A2: 484 | B2: Twin Harbors | C2: 39851 | D2: 2393 | E2: 68371.927
A3: 142 | B3: Twin Harbors | C3: 39899 | D3: 3522 | E3: 41438.171
A4: 145 | B4: Twin Harbors | C4: 39913 | D4: 1775 | E4: 44364.702
A5: 157 | B5: Twin Harbors | C5: 39930 | D5: 189 | E5: 18946.351
A6: 162 | B6: Twin Harbors | C6: 39943 | D6: 2753 | E6: 45905.096
D8: =SUM(D2:D7) -> 10632 | E8: =SUM(E2:E7) -> 219026.25 | F8: =+D8/E8 -> 0.048542128

Sheet Cop - Wastage
A1: EventID | B1: BeachName | C1: Date | D1: SumOfWastage | E1: SumOfTotHarvest
A2: 474 | B2: Copalis | C2: 39850 | D2: 0 | E2: 46064.141
A3: 475 | B3: Copalis | C3: 39851 | D3: 3257 | E3: 108533.81
A4: 138 | B4: Copalis | C4: 39901 | D4: 4370 | E4: 109257.99
A5: 150 | B5: Copalis | C5: 39928 | D5: 9137 | E5: 144271.22
A6: 154 | B6: Copalis | C6: 39929 | D6: 3809 | E6: 126965.66
A7: 156 | B7: Copalis | C7: 39930 | D7: 1349 | E7: 50614.684
A8: 160 | B8: Copalis | C8: 39942 | D8: 3185 | E8: 63672.098
D9: 28448 | E9: =SUM(E2:E8) -> 649379.61 | F9: =+D9/E9 -> 0.043807967

Sheet Moc - Wastage
A1: EventID | B1: BeachName | C1: Date | D1: SumOfWastage | E1: SumOfTotHarvest
A2: 128 | B2: Mocrocks | C2: 39850 | D2: 1471 | E2: 36753.921
A3: 131 | B3: Mocrocks | C3: 39851 | D3: 2376 | E3: 118707.8
A4: 139 | B4: Mocrocks | C4: 39899 | D4: 3480 | E4: 44725.102
A5: 151 | B5: Mocrocks | C5: 39928 | D5: 3037 | E5: 82806.949
A6: 153 | B6: Mocrocks | C6: 39929 | D6: 2710 | E6: 67762.952
D8: 26604 | E8: =SUM(E2:E7) -> 350756.73 | F8: =+D8/E8 -> 0.075847441

Sheet Wastage
A1: Wastage for Fall 2008 through Spring 2009 Non - Tribal Razor Clam Fishery
