Workbook

Sheet Harvest
A1: Date | B1: Day | C1: Tide | D1: Time | E1: Longbeach | G1: Twin Harbors | I1: Copalis | K1: Mocrocks | M1: Kalaloch | O1: Daily Totals
A2: 40102 | B2: =+A2 -> 40102 | C2: -0.2 | D2: 0.79097222 | F2: 26480 | H2: 14564 | J2: 67449 | L2: CLOSED | N2: CLOSED | O2: =+F2+H2+J2 -> 108493
A3: 40103 | B3: =+A3 -> 40103 | C3: -0.7 | D3: 0.78055556 | F3: 64965 | H3: 25353 | J3: 100367 | L3: 46405 | N3: 5826.3051 | O3: =+F3+H3+J3+L3+N3 -> 242916.31
A4: 40104 | B4: =+A4 -> 40104 | C4: -1 | D4: 0.80972222 | E4: * | F4: =(H4+J4)*(F2+F3)/(H2+H3+J2+J3) -> 27625.473 | H4: 20115 | J4: 42641 | L4: 18037 | N4: 2814.1557 | O4: =+F4+H4+J4+L4+N4 -> 111232.63
A5: 40105 | B5: =+A5 -> 40105 | C5: -1.1 | D5: 0.83819444 | F5: CLOSED | H5: 19410 | J5: CLOSED | L5: CLOSED | N5: CLOSED | O5: =+H5 -> 19410
A7: 40121 | B7: =+A7 -> 40121 | C7: -1.2 | D7: 0.8125 | F7: 12676 | H7: 15951 | J7: CLOSED | L7: CLOSED | N7: CLOSED | O7: =F7+H7 -> 28627
A8: 40122 | B8: =+A8 -> 40122 | C8: -1.1 | D8: 0.84444444 | F8: CLOSED | H8: 1600 | J8: CLOSED | L8: CLOSED | N8: CLOSED | O8: =H8 -> 1600
A9: 40123 | B9: =+A9 -> 40123 | C9: -0.8 | D9: 0.87916667 | F9: 1776.3788 | G9: * | H9: 650.90338 | J9: CLOSED | L9: CLOSED | N9: CLOSED | O9: =F9+H9 -> 2427.2822
A10: 40124 | B10: =+A10 -> 40124 | C10: -0.4 | D10: 0.91666667 | F10: =H10*F7/H7 -> 5903.7053 | H10: 7429 | J10: CLOSED | L10: CLOSED | N10: CLOSED | O10: =F10+H10 -> 13332.705
A12: 40131 | B12: =+A12 -> 40131 | C12: -0.4 | D12: 0.69861111 | F12: 62016 | H12: 24308 | J12: 59043 | L12: 39565 | N12: CLOSED | O12: =F12+H12+J12+L12 -> 184932
A13: 40132 | B13: =+A13 -> 40132 | C13: -0.8 | D13: 0.72916667 | F13: 21871 | H13: 6430 | J13: 43442 | L13: 15162 | N13: CLOSED | O13: =F13+H13+J13+L13 -> 86905
A14: 40133 | B14: =+A14 -> 40133 | C14: -1 | D14: 0.75694444 | E14: * | F14: =J14*(F12+F13)/(J12+J13) -> 1620.6885 | G14: * | H14: =J14*(H12+H13)/(J12+J13) -> 593.8551 | J14: 1980 | K14: * | L14: =J14*(L12+L13)/(J12+J13) -> 1057.3202 | M14: + | N14: 0 | O14: =F14+H14+J14+L14+N14 -> 5251.8638
A15: 40134 | B15: =+A15 -> 40134 | C15: -0.9 | D15: 0.78402778 | F15: CLOSED | H15: 2901 | J15: CLOSED | L15: CLOSED | N15: CLOSED | O15: =H15 -> 2901
A17: 40149 | B17: =+A17 -> 40149 | C17: -1.5 | D17: 0.77222222 | F17: 20288 | H17: 9801 | J17: CLOSED | L17: CLOSED | N17: CLOSED | O17: =F17+H17 -> 30089
A18: 40150 | B18: =+A18 -> 40150 | C18: -1.6 | D18: 0.80347222 | F18: CLOSED | H18: 5295 | J18: 20455 | L18: 7196 | N18: CLOSED | O18: =H18+J18+L18 -> 32946
A19: 40151 | B19: =+A19 -> 40151 | C19: -1.5 | D19: 0.83611111 | F19: 13077 | G19: * | H19: =(J19+L19)*(H18+H20)/(J18+L18+J20+L20) -> 6245.2478 | J19: 21434 | L19: 12344 | N19: 1908.9138 | O19: =F19+H19+J19+L19+N19 -> 55009.162
A20: 40152 | B20: =+A20 -> 40152 | C20: -1.1 | D20: 0.86875 | E20: * | F20: =H20*F17/H17 -> 11877.619 | H20: 5738 | J20: 20200 | L20: 11822 | N20: 2735.7263 | O20: =F20+H20+J20+L20+N20 -> 52373.345
A22: 40178 | B22: =+A22 -> 40178 | C22: -1.6 | D22: 0.7625 | F22: 25927 | H22: 4351 | J22: 28707 | L22: 12106 | N22: 573.56355 | O22: =F22+H22+J22+L22+N22 -> 71664.564
A23: 40179 | B23: =+A23 -> 40179 | C23: -1.8 | D23: 0.79236111 | E23: * | F23: =(J23+L23)*(F22+F24)/(J22+L22+J24+L24) -> 18908.155 | G23: * | H23: =(J23+L23)*(H22+H24)/(J22+L22+J24+L24) -> 3361.5674 | J23: 19791 | L23: 16258 | N23: 660.59983 | O23: =F23+H23+J23+L23+N23 -> 58979.322
A24: 40180 | B24: =+A24 -> 40180 | C24: -1.6 | D24: 0.82291667 | F24: 41925 | H24: 7712 | J24: 62498 | L24: 26051 | N24: CLOSED | O24: =F24+H24+J24+L24 -> 138186
A25: 40181 | B25: =+A25 -> 40181 | C25: -1.2 | D25: 0.85347222 | F25: CLOSED | H25: 5250 | J25: CLOSED | L25: CLOSED | N25: CLOSED | O25: =H25 -> 5250
A27: 40206 | B27: =A27 -> 40206 | C27: -1.1 | D27: 0.71736111 | F27: CLOSED | H27: 12915 | J27: CLOSED | L27: CLOSED | N27: CLOSED | O27: =H27 -> 12915
A28: 40207 | B28: =A28 -> 40207 | C28: -1.5 | D28: 0.74861111 | F28: CLOSED | H28: 25275 | J28: 65435 | L28: 28597 | N28: CLOSED | O28: =H28+J28+L28 -> 119307
A29: 40208 | B29: =A29 -> 40208 | C29: -1.5 | D29: 0.77847222 | F29: CLOSED | H29: 37350 | J29: 64017 | L29: 42276 | N29: 1075.0327 | O29: =H29+J29+L29+N29 -> 144718.03
A30: 40209 | B30: =A30 -> 40209 | C30: -1.2 | D30: 0.80763889 | F30: CLOSED | H30: 5848.2177 | J30: 33358 | L30: 13902 | N30: 1108.1596 | O30: =H30+J30+L30+N30 -> 54216.377
A32: 40235 | B32: =A32 -> 40235 | C32: -0.7 | D32: 0.70069444 | F32: 40476 | H32: 19245 | J32: 61050 | L32: 25870 | N32: CLOSED | O32: =F32+H32+J32+L32 -> 146641
A33: 40236 | B33: =A33 -> 40236 | C33: -0.9 | D33: 0.73194444 | F33: 69000 | H33: 8000 | J33: 42500 | L33: 10000 | N33: 338.78341 | O33: =F33+H33+J33+L33+N33 -> 129838.78
A34: 40237 | B34: =A34 -> 40237 | C34: -0.8 | D34: 0.76111111 | F34: 69915 | H34: 26623 | J34: 141678 | L34: 33868 | N34: 2373.1992 | O34: =F34+H34+J34+L34+N34 -> 274457.2
A35: 40238 | B35: =A35 -> 40238 | C35: -0.4 | D35: 0.78888889 | F35: 4702 | H35: 12984 | J35: CLOSED | L35: CLOSED | N35: CLOSED | O35: =F35+H35 -> 17686
A37: 40263 | B37: =A37 -> 40263 | C37: 0.1 | D37: 0.68680556 | F37: 61344 | H37: 17021 | J37: CLOSED | L37: CLOSED | N37: 2835.6659 | O37: =F37+H37+N37 -> 81200.666
A38: 40264 | B38: =A38 -> 40264 | C38: -0.1 | D38: 0.72152778 | E38: * | F38: =(J38+L38)*F39/(J39+L39) -> 56443.799 | H38: 53531 | J38: 113112 | L38: 74693 | N38: 6094.241 | O38: =F38+H38+J38+L38+N38 -> 303874.04
A39: 40265 | B39: =A39 -> 40265 | C39: 0 | D39: 0.75277778 | F39: 9435 | G39: * | H39: =(J39+L39)*H38/(J38+L38) -> 8948.1041 | J39: 18036 | L39: 13357 | N39: CLOSED | O39: =F39+H39+J39+L39 -> 49776.104
A40: 40266 | B40: =A40 -> 40266 | C40: -0.1 | D40: 0.27430556 | F40: 186 | H40: 0 | J40: CLOSED | L40: CLOSED | N40: CLOSED | O40: =F40+H40 -> 186
A41: 40267 | B41: =A41 -> 40267 | C41: -0.7 | D41: 0.30694444 | F41: 8811 | G41: * | H41: =F41*H42/F42 -> 4760.7512 | J41: CLOSED | L41: CLOSED | N41: CLOSED | O41: =F41+H41 -> 13571.751
A42: 40268 | B42: =A42 -> 40268 | C42: -1 | D42: 0.33819444 | F42: 27456 | H42: 14835 | J42: CLOSED | L42: CLOSED | N42: CLOSED | O42: =F42+H42 -> 42291
A43: 40269 | B43: =A43 -> 40269 | C43: -1 | D43: 0.36944444 | F43: 29372 | G43: * | H43: =F43*H42/F42 -> 15870.251 | J43: CLOSED | L43: CLOSED | N43: CLOSED | O43: =F43+H43 -> 45242.251
A45: 40284 | B45: =A45 -> 40284 | C45: -0.7 | D45: 0.35555556 | F45: 49598 | H45: 26202 | J45: CLOSED | L45: CLOSED | N45: CLOSED | O45: =F45+H45 -> 75800
A46: 40285 | B46: =A46 -> 40285 | C46: -0.7 | D46: 0.38333333 | F46: 106682 | H46: 75878 | J46: CLOSED | L46: CLOSED | N46: 4603.9197 | O46: =F46+H46+N46 -> 187163.92
A47: 40286 | B47: =A47 -> 40286 | C47: -0.6 | D47: 0.41527778 | F47: 92567 | H47: 79617 | J47: CLOSED | L47: CLOSED | N47: 7992.6457 | O47: =F47+H47+N47 -> 180176.65
A49: 40295 | B49: =A49 -> 40295 | C49: -1 | D49: 0.26458333 | F49: 10575 | H49: 7443 | J49: CLOSED | L49: CLOSED | N49: CLOSED | O49: =F49+H49 -> 18018
...

Sheet CPUE
A1: Date | B1: Day | C1: Tide | D1: Time | E1: Longbeach | G1: Twin Harbors | I1: Copalis | K1: Mocrocks | M1: Kalaloch | O1: Daily Totals
A2: 40102 | B2: =+A2 -> 40102 | C2: -0.2 | D2: 0.79097222 | F2: =+Harvest!F2/Effort!F2 -> 10.466403 | H2: =+Harvest!H2/Effort!H2 -> 11.88898 | J2: =+Harvest!J2/Effort!J2 -> 13.69801 | L2: CLOSED | N2: CLOSED | O2: =Harvest!O2/Effort!O2 -> 12.500634
A3: 40103 | B3: =+A3 -> 40103 | C3: -0.7 | D3: 0.78055556 | F3: =+Harvest!F3/Effort!F3 -> 15 | H3: =+Harvest!H3/Effort!H3 -> 13.204688 | J3: =+Harvest!J3/Effort!J3 -> 14.818692 | L3: =+Harvest!L3/Effort!L3 -> 13.273741 | N3: =+Harvest!N3/Effort!N3 -> 13.635766 | O3: =Harvest!O3/Effort!O3 -> 14.333645
A4: 40104 | B4: =+A4 -> 40104 | C4: -1 | D4: 0.80972222 | E4: * | F4: =+Harvest!F4/Effort!F4 -> 14.22532 | H4: =+Harvest!H4/Effort!H4 -> 15 | J4: =+Harvest!J4/Effort!J4 -> 14.909441 | L4: =+Harvest!L4/Effort!L4 -> 15.005824 | N4: =+Harvest!N4/Effort!N4 -> 14.606859 | O4: =Harvest!O4/Effort!O4 -> 14.756932
A5: 40105 | B5: =+A5 -> 40105 | C5: -1.1 | D5: 0.83819444 | F5: CLOSED | H5: =+Harvest!H5/Effort!H5 -> 15 | J5: CLOSED | L5: CLOSED | N5: CLOSED | O5: =Harvest!O5/Effort!O5 -> 15
A7: 40121 | B7: =+A7 -> 40121 | C7: -1.2 | D7: 0.8125 | F7: =+Harvest!F7/Effort!F7 -> 14.654335 | H7: =+Harvest!H7/Effort!H7 -> 14.977465 | J7: CLOSED | L7: CLOSED | N7: CLOSED | O7: =Harvest!O7/Effort!O7 -> 14.832642
A8: 40122 | B8: =+A8 -> 40122 | C8: -1.1 | D8: 0.84444444 | F8: CLOSED | H8: =+Harvest!H8/Effort!H8 -> 10.25641 | J8: CLOSED | L8: CLOSED | N8: CLOSED | O8: =Harvest!O8/Effort!O8 -> 10.25641
A9: 40123 | B9: =+A9 -> 40123 | C9: -0.8 | D9: 0.87916667 | F9: =+Harvest!F9/Effort!F9 -> 4.8211508 | G9: * | H9: =+Harvest!H9/Effort!H9 -> 4.4889888 | J9: CLOSED | L9: CLOSED | N9: CLOSED | O9: =Harvest!O9/Effort!O9 -> 4.7273481
A10: 40124 | B10: =+A10 -> 40124 | C10: -0.4 | D10: 0.91666667 | F10: =+Harvest!F10/Effort!F10 -> 11.994594 | H10: =+Harvest!H10/Effort!H10 -> 12.259076 | J10: CLOSED | L10: CLOSED | N10: CLOSED | O10: =Harvest!O10/Effort!O10 -> 12.140539
A12: 40131 | B12: =+A12 -> 40131 | C12: -0.4 | D12: 0.69861111 | F12: =+Harvest!F12/Effort!F12 -> 14.482952 | H12: =+Harvest!H12/Effort!H12 -> 14.026544 | J12: =+Harvest!J12/Effort!J12 -> 15.000762 | L12: =+Harvest!L12/Effort!L12 -> 14.998105 | N12: CLOSED | O12: =Harvest!O12/Effort!O12 -> 14.689967
A13: 40132 | B13: =+A13 -> 40132 | C13: -0.8 | D13: 0.72916667 | F13: =+Harvest!F13/Effort!F13 -> 12.75277 | H13: =+Harvest!H13/Effort!H13 -> 10.288 | J13: =+Harvest!J13/Effort!J13 -> 11.333681 | L13: =+Harvest!L13/Effort!L13 -> 11.443019 | N13: CLOSED | O13: =Harvest!O13/Effort!O13 -> 11.590424
A14: 40133 | B14: =+A14 -> 40133 | C14: -1 | D14: 0.75694444 | E14: * | F14: =+Harvest!F14/Effort!F14 -> 5.3835161 | G14: * | H14: =+Harvest!H14/Effort!H14 -> 5.0169203 | J14: =+Harvest!J14/Effort!J14 -> 5.0769231 | K14: * | L14: =+Harvest!L14/Effort!L14 -> 5.3147516 | M14: + | N14: 0 | O14: =Harvest!O14/Effort!O14 -> 5.0971274
A15: 40134 | B15: =+A15 -> 40134 | C15: -0.9 | D15: 0.78402778 | F15: CLOSED | H15: =+Harvest!H15/Effort!H15 -> 10.250883 | J15: CLOSED | L15: CLOSED | N15: CLOSED | O15: =Harvest!O15/Effort!O15 -> 10.250883
A17: 40149 | B17: =+A17 -> 40149 | C17: -1.5 | D17: 0.77222222 | F17: =+Harvest!F17/Effort!F17 -> 14.532951 | H17: =+Harvest!H17/Effort!H17 -> 15.0553 | J17: CLOSED | L17: CLOSED | N17: CLOSED | O17: =Harvest!O17/Effort!O17 -> 14.699072
A18: 40150 | B18: =+A18 -> 40150 | C18: -1.6 | D18: 0.80347222 | F18: CLOSED | H18: =+Harvest!H18/Effort!H18 -> 13.542199 | J18: =+Harvest!J18/Effort!J18 -> 14.996334 | L18: =+Harvest!L18/Effort!L18 -> 13.131387 | N18: CLOSED | O18: =Harvest!O18/Effort!O18 -> 14.305688
A19: 40151 | B19: =+A19 -> 40151 | C19: -1.5 | D19: 0.83611111 | F19: =+Harvest!F19/Effort!F19 -> 14.627517 | G19: * | H19: =+Harvest!H19/Effort!H19 -> 13.443564 | J19: =+Harvest!J19/Effort!J19 -> 14.443396 | L19: =+Harvest!L19/Effort!L19 -> 13.062434 | N19: =+Harvest!N19/Effort!N19 -> 11.788098 | O19: =Harvest!O19/Effort!O19 -> 13.928173
A20: 40152 | B20: =+A20 -> 40152 | C20: -1.1 | D20: 0.86875 | E20: * | F20: =+Harvest!F20/Effort!F20 -> 14.461928 | H20: =+Harvest!H20/Effort!H20 -> 14.981723 | J20: =+Harvest!J20/Effort!J20 -> 14.996288 | L20: =+Harvest!L20/Effort!L20 -> 15.002538 | N20: =+Harvest!N20/Effort!N20 -> 12.47764 | O20: =Harvest!O20/Effort!O20 -> 14.717596
A22: 40178 | B22: =+A22 -> 40178 | C22: -1.6 | D22: 0.7625 | F22: =+Harvest!F22/Effort!F22 -> 12.803457 | H22: =+Harvest!H22/Effort!H22 -> 5.4049689 | J22: =+Harvest!J22/Effort!J22 -> 8.7950368 | L22: =+Harvest!L22/Effort!L22 -> 8.1412239 | N22: =+Harvest!N22/Effort!N22 -> 1.9137194 | O22: =Harvest!O22/Effort!O22 -> 9.0936668
A23: 40179 | B23: =+A23 -> 40179 | C23: -1.8 | D23: 0.79236111 | E23: * | F23: =+Harvest!F23/Effort!F23 -> 4.565972 | G23: * | H23: =+Harvest!H23/Effort!H23 -> 2.6365685 | J23: =+Harvest!J23/Effort!J23 -> 3.034964 | L23: =+Harvest!L23/Effort!L23 -> 5.7327221 | N23: =+Harvest!N23/Effort!N23 -> 3.2571429 | O23: =Harvest!O23/Effort!O23 -> 3.9382834
A24: 40180 | B24: =+A24 -> 40180 | C24: -1.6 | D24: 0.82291667 | F24: =+Harvest!F24/Effort!F24 -> 15 | H24: =+Harvest!H24/Effort!H24 -> 11.357879 | J24: =+Harvest!J24/Effort!J24 -> 14.99832 | L24: =+Harvest!L24/Effort!L24 -> 13.203751 | N24: CLOSED | O24: =Harvest!O24/Effort!O24 -> 14.373414
A25: 40181 | B25: =+A25 -> 40181 | C25: -1.2 | D25: 0.85347222 | F25: CLOSED | H25: =+Harvest!H25/Effort!H25 -> 15 | J25: CLOSED | L25: CLOSED | N25: CLOSED | O25: =Harvest!O25/Effort!O25 -> 15
A27: 40206 | B27: =A27 -> 40206 | C27: -1.1 | D27: 0.71736111 | F27: CLOSED | H27: =+Harvest!H27/Effort!H27 -> 15 | J27: CLOSED | L27: CLOSED | N27: CLOSED | O27: =Harvest!O27/Effort!O27 -> 15
A28: 40207 | B28: =A28 -> 40207 | C28: -1.5 | D28: 0.74861111 | F28: CLOSED | H28: =+Harvest!H28/Effort!H28 -> 15 | J28: =+Harvest!J28/Effort!J28 -> 14.29336 | L28: =+Harvest!L28/Effort!L28 -> 12.025652 | N28: CLOSED | O28: =Harvest!O28/Effort!O28 -> 13.807083
A29: 40208 | B29: =A29 -> 40208 | C29: -1.5 | D29: 0.77847222 | F29: CLOSED | H29: =+Harvest!H29/Effort!H29 -> 15 | J29: =+Harvest!J29/Effort!J29 -> 12.216985 | L29: =+Harvest!L29/Effort!L29 -> 12.368637 | N29: =+Harvest!N29/Effort!N29 -> 4.7046358 | O29: =Harvest!O29/Effort!O29 -> 12.720781
A30: 40209 | B30: =A30 -> 40209 | C30: -1.2 | D30: 0.80763889 | F30: CLOSED | H30: =+Harvest!H30/Effort!H30 -> 10.830033 | J30: =+Harvest!J30/Effort!J30 -> 12.187797 | L30: =+Harvest!L30/Effort!L30 -> 14.996764 | N30: =+Harvest!N30/Effort!N30 -> 9.9259259 | O30: =Harvest!O30/Effort!O30 -> 12.562758
A32: 40235 | B32: =A32 -> 40235 | C32: -0.7 | D32: 0.70069444 | F32: =+Harvest!F32/Effort!F32 -> 14.974473 | H32: =+Harvest!H32/Effort!H32 -> 15 | J32: =+Harvest!J32/Effort!J32 -> 14.933953 | L32: =+Harvest!L32/Effort!L32 -> 14.997101 | N32: CLOSED | O32: =Harvest!O32/Effort!O32 -> 14.964894
A33: 40236 | B33: =A33 -> 40236 | C33: -0.9 | D33: 0.73194444 | E33: * | F33: 15 | G33: * | H33: 15 | I33: * | J33: 15 | K33: * | L33: 15 | N33: =+Harvest!N33/Effort!N33 -> 2.6261682 | O33: =Harvest!O33/Effort!O33 -> 14.702609
A34: 40237 | B34: =A34 -> 40237 | C34: -0.8 | D34: 0.76111111 | F34: =+Harvest!F34/Effort!F34 -> 15 | H34: =+Harvest!H34/Effort!H34 -> 14.252141 | J34: =+Harvest!J34/Effort!J34 -> 14.844719 | L34: =+Harvest!L34/Effort!L34 -> 14.750871 | N34: =+Harvest!N34/Effort!N34 -> 14.346154 | O34: =Harvest!O34/Effort!O34 -> 14.80797
A35: 40238 | B35: =A35 -> 40238 | C35: -0.4 | D35: 0.78888889 | F35: =+Harvest!F35/Effort!F35 -> 3.3323884 | H35: =+Harvest!H35/Effort!H35 -> 13.036145 | J35: CLOSED | L35: CLOSED | N35: CLOSED
A37: 40263 | B37: =A37 -> 40263 | C37: 0.1 | D37: 0.68680556 | F37: =+Harvest!F37/Effort!F37 -> 14.788814 | H37: =+Harvest!H37/Effort!H37 -> 14.762359 | J37: CLOSED | L37: CLOSED | N37: =+Harvest!N37/Effort!N37 -> 11.867876 | O37: =Harvest!O37/Effort!O37 -> 14.657329
A38: 40264 | B38: =A38 -> 40264 | C38: -0.1 | D38: 0.72152778 | E38: * | F38: =+Harvest!F38/Effort!F38 -> 10.666873 | H38: =+Harvest!H38/Effort!H38 -> 14.734655 | J38: =+Harvest!J38/Effort!J38 -> 13.84141 | L38: =+Harvest!L38/Effort!L38 -> 14.069128 | N38: =+Harvest!N38/Effort!N38 -> 11.859813 | O38: =Harvest!O38/Effort!O38 -> 13.2584
A39: 40265 | B39: =A39 -> 40265 | C39: 0 | D39: 0.75277778 | F39: =+Harvest!F39/Effort!F39 -> 3.9626207 | G39: * | H39: =+Harvest!H39/Effort!H39 -> 5.4737547 | J39: =+Harvest!J39/Effort!J39 -> 4.3376623 | L39: =+Harvest!L39/Effort!L39 -> 7.0005241 | N39: CLOSED | O39: =Harvest!O39/Effort!O39 -> 4.9372588
A40: 40266 | B40: =A40 -> 40266 | C40: -0.1 | D40: 0.27430556 | F40: =+Harvest!F40/Effort!F40 -> 1.0689655 | H40: =+Harvest!H40/Effort!H40 -> 0 | J40: CLOSED | L40: CLOSED | N40: CLOSED | O40: =Harvest!O40/Effort!O40 -> 0.69924812
A41: 40267 | B41: =A41 -> 40267 | C41: -0.7 | D41: 0.30694444 | F41: =+Harvest!F41/Effort!F41 -> 5.266587 | G41: * | H41: =+Harvest!H41/Effort!H41 -> 6.6724296 | J41: CLOSED | L41: CLOSED | N41: CLOSED | O41: =Harvest!O41/Effort!O41 -> 5.6868948
A42: 40268 | B42: =A42 -> 40268 | C42: -1 | D42: 0.33819444 | F42: =+Harvest!F42/Effort!F42 -> 11.839586 | H42: =+Harvest!H42/Effort!H42 -> 15 | J42: CLOSED | L42: CLOSED | N42: CLOSED | O42: =Harvest!O42/Effort!O42 -> 12.784462
A43: 40269 | B43: =A43 -> 40269 | C43: -1 | D43: 0.36944444 | E43: * | F43: =+Harvest!F43/Effort!F43 -> 10.523827 | G43: * | H43: =+Harvest!H43/Effort!H43 -> 13.333017 | J43: CLOSED | L43: CLOSED | N43: CLOSED | O43: =Harvest!O43/Effort!O43 -> 11.363696
A45: 40284 | B45: =A45 -> 40284 | C45: -0.7 | D45: 0.35555556 | F45: =+Harvest!F45/Effort!F45 -> 14.721876 | H45: =+Harvest!H45/Effort!H45 -> 14.492257 | J45: CLOSED | L45: CLOSED | N45: CLOSED | O45: =Harvest!O45/Effort!O45 -> 14.641684
A46: 40285 | B46: =A46 -> 40285 | C46: -0.7 | D46: 0.38333333 | F46: =+Harvest!F46/Effort!F46 -> 14.605969 | H46: =+Harvest!H46/Effort!H46 -> 14.747911 | J46: CLOSED | L46: CLOSED | N46: =+Harvest!N46/Effort!N46 -> 7.8068182 | O46: =Harvest!O46/Effort!O46 -> 14.354459
A47: 40286 | B47: =A47 -> 40286 | C47: -0.6 | D47: 0.41527778 | F47: =+Harvest!F47/Effort!F47 -> 14.100076 | H47: =+Harvest!H47/Effort!H47 -> 14.965602 | J47: CLOSED | L47: CLOSED | N47: =+Harvest!N47/Effort!N47 -> 12.506353 | O47: =Harvest!O47/Effort!O47 -> 14.38641
A49: 40295 | B49: =A49 -> 40295 | C49: -1 | D49: 0.26458333 | F49: =+Harvest!F49/Effort!F49 -> 15 | H49: =+Harvest!H49/Effort!H49 -> 14.797217 | J49: CLOSED | L49: CLOSED | N49: CLOSED | O49: =Harvest!O49/Effort!O49 -> 14.915563
...

Sheet Effort
A1: Date | B1: Day | C1: Tide | D1: Time | E1: Longbeach | G1: Twin Harbors | I1: Copalis | K1: Mocrocks | M1: Kalaloch | O1: Daily Totals
A2: 40102 | B2: =+A2 -> 40102 | C2: -0.2 | D2: 0.79097222 | F2: 2530 | H2: 1225 | J2: 4924 | L2: CLOSED | N2: CLOSED | O2: =+F2+H2+J2 -> 8679
A3: 40103 | B3: =+A3 -> 40103 | C3: -0.7 | D3: 0.78055556 | F3: 4331 | H3: 1920 | J3: 6773 | L3: 3496 | N3: 427.28109 | O3: =+F3+H3+J3+L3+N3 -> 16947.281
A4: 40104 | B4: =+A4 -> 40104 | C4: -1 | D4: 0.80972222 | E4: * | F4: =(H4+J4)*(F2+F3)/(H2+H3+J2+J3) -> 1941.9931 | H4: 1341 | J4: 2860 | L4: 1202 | N4: 192.65988 | O4: =+F4+H4+J4+L4+N4 -> 7537.6529
A5: 40105 | B5: =+A5 -> 40105 | C5: -1.1 | D5: 0.83819444 | F5: CLOSED | H5: 1294 | J5: CLOSED | L5: CLOSED | N5: CLOSED | O5: =+H5 -> 1294
A7: 40121 | B7: =+A7 -> 40121 | C7: -1.2 | D7: 0.8125 | F7: 865 | H7: 1065 | J7: CLOSED | L7: CLOSED | N7: CLOSED | O7: =F7+H7 -> 1930
A8: 40122 | B8: =+A8 -> 40122 | C8: -1.1 | D8: 0.84444444 | F8: CLOSED | H8: 156 | J8: CLOSED | L8: CLOSED | N8: CLOSED | O8: =H8 -> 156
A9: 40123 | B9: =+A9 -> 40123 | C9: -0.8 | D9: 0.87916667 | F9: 368.45535 | G9: * | H9: 145 | J9: CLOSED | L9: CLOSED | N9: CLOSED | O9: =F9+H9 -> 513.45535
A10: 40124 | B10: =+A10 -> 40124 | C10: -0.4 | D10: 0.91666667 | F10: =H10*F7/H7 -> 492.19718 | H10: 606 | J10: CLOSED | L10: CLOSED | N10: CLOSED | O10: =F10+H10 -> 1098.1972
A12: 40131 | B12: =+A12 -> 40131 | C12: -0.4 | D12: 0.69861111 | F12: 4282 | H12: 1733 | J12: 3936 | L12: 2638 | N12: CLOSED | O12: =F12+H12+J12+L12 -> 12589
A13: 40132 | B13: =+A13 -> 40132 | C13: -0.8 | D13: 0.72916667 | F13: 1715 | H13: 625 | J13: 3833 | L13: 1325 | N13: CLOSED | O13: =F13+H13+J13+L13 -> 7498
A14: 40133 | B14: =+A14 -> 40133 | C14: -1 | D14: 0.75694444 | E14: * | F14: =J14*(F12+F13)/(J12+J13) -> 301.04647 | G14: * | H14: =J14*(H12+H13)/(J12+J13) -> 118.37045 | J14: 390 | K14: * | L14: =J14*(L12+L13)/(J12+J13) -> 198.94066 | M14: + | N14: 22 | O14: =F14+H14+J14+L14+N14 -> 1030.3576
A15: 40134 | B15: =+A15 -> 40134 | C15: -0.9 | D15: 0.78402778 | F15: CLOSED | H15: 283 | J15: CLOSED | L15: CLOSED | N15: CLOSED | O15: =H15 -> 283
A17: 40149 | B17: =+A17 -> 40149 | C17: -1.5 | D17: 0.77222222 | F17: 1396 | H17: 651 | J17: CLOSED | L17: CLOSED | N17: CLOSED | O17: =F17+H17 -> 2047
A18: 40150 | B18: =+A18 -> 40150 | C18: -1.6 | D18: 0.80347222 | F18: CLOSED | H18: 391 | J18: 1364 | L18: 548 | N18: CLOSED | O18: =H18+J18+L18 -> 2303
A19: 40151 | B19: =+A19 -> 40151 | C19: -1.5 | D19: 0.83611111 | F19: 894 | G19: * | H19: =(J19+L19)*(H18+H20)/(J18+L18+J20+L20) -> 464.553 | J19: 1484 | L19: 945 | N19: 161.93569 | O19: =F19+H19+J19+L19+N19 -> 3949.4887
A20: 40152 | B20: =+A20 -> 40152 | C20: -1.1 | D20: 0.86875 | E20: * | F20: =H20*F17/H17 -> 821.30261 | H20: 383 | J20: 1347 | L20: 788 | N20: 219.2503 | O20: =F20+H20+J20+L20+N20 -> 3558.5529
A22: 40178 | B22: =+A22 -> 40178 | C22: -1.6 | D22: 0.7625 | F22: 2025 | H22: 805 | J22: 3264 | L22: 1487 | N22: 299.71141 | O22: =F22+H22+J22+L22+N22 -> 7880.7114
A23: 40179 | B23: =+A23 -> 40179 | C23: -1.8 | D23: 0.79236111 | E23: * | F23: =(J23+L23)*(F22+F24)/(J22+L22+J24+L24) -> 4141.1018 | G23: * | H23: =(J23+L23)*(H22+H24)/(J22+L22+J24+L24) -> 1274.9782 | J23: 6521 | L23: 2836 | N23: 202.81574 | O23: =F23+H23+J23+L23+N23 -> 14975.896
A24: 40180 | B24: =+A24 -> 40180 | C24: -1.6 | D24: 0.82291667 | F24: 2795 | H24: 679 | J24: 4167 | L24: 1973 | N24: CLOSED | O24: =F24+H24+J24+L24 -> 9614
A25: 40181 | B25: =+A25 -> 40181 | C25: -1.2 | D25: 0.85347222 | F25: CLOSED | H25: 350 | J25: CLOSED | L25: CLOSED | N25: CLOSED | O25: =H25 -> 350
A27: 40206 | B27: =A27 -> 40206 | C27: -1.1 | D27: 0.71736111 | F27: CLOSED | H27: 861 | J27: CLOSED | L27: CLOSED | N27: CLOSED | O27: =H27 -> 861
A28: 40207 | B28: =A28 -> 40207 | C28: -1.5 | D28: 0.74861111 | F28: CLOSED | H28: 1685 | J28: 4578 | L28: 2378 | N28: CLOSED | O28: =H28+J28+L28 -> 8641
A29: 40208 | B29: =A29 -> 40208 | C29: -1.5 | D29: 0.77847222 | F29: CLOSED | H29: 2490 | J29: 5240 | L29: 3418 | N29: 228.50498 | O29: =H29+J29+L29+N29 -> 11376.505
A30: 40209 | B30: =A30 -> 40209 | C30: -1.2 | D30: 0.80763889 | F30: CLOSED | H30: 540 | J30: 2737 | L30: 927 | N30: 111.64295 | O30: =H30+J30+L30+N30 -> 4315.6429
A32: 40235 | B32: =A32 -> 40235 | C32: -0.7 | D32: 0.70069444 | F32: 2703 | H32: 1283 | J32: 4088 | L32: 1725 | N32: CLOSED | O32: =F32+H32+J32+L32 -> 9799
A33: 40236 | B33: =A33 -> 40236 | C33: -0.9 | D33: 0.73194444 | E33: * | F33: 4600 | G33: * | H33: 550 | I33: * | J33: =+J34*0.3 -> 2863.2 | K33: * | L33: =+L34*0.3 -> 688.8 | N33: 129.00294 | O33: =F33+H33+J33+L33+N33 -> 8831.0029
A34: 40237 | B34: =A34 -> 40237 | C34: -0.8 | D34: 0.76111111 | F34: 4661 | H34: 1868 | J34: 9544 | L34: 2296 | N34: 165.42407 | O34: =F34+H34+J34+L34+N34 -> 18534.424
A35: 40238 | B35: =A35 -> 40238 | C35: -0.4 | D35: 0.78888889 | F35: 1411 | H35: 996 | J35: CLOSED | L35: CLOSED | N35: CLOSED | O35: =F35+H35 -> 2407
A37: 40263 | B37: =A37 -> 40263 | C37: 0.1 | D37: 0.68680556 | F37: 4148 | H37: 1153 | J37: CLOSED | L37: CLOSED | N37: 238.93626 | O37: =F37+H37+N37 -> 5539.9363
A38: 40264 | B38: =A38 -> 40264 | C38: -0.1 | D38: 0.72152778 | E38: * | F38: =(J38+L38)*F39/(J39+L39) -> 5291.5036 | H38: 3633 | J38: 8172 | L38: 5309 | N38: 513.85641 | O38: =F38+H38+J38+L38+N38 -> 22919.36
A39: 40265 | B39: =A39 -> 40265 | C39: 0 | D39: 0.75277778 | F39: 2381 | G39: * | H39: =(J39+L39)*H38/(J38+L38) -> 1634.7287 | J39: 4158 | L39: 1908 | N39: CLOSED | O39: =F39+H39+J39+L39 -> 10081.729
A40: 40266 | B40: =A40 -> 40266 | C40: -0.1 | D40: 0.27430556 | F40: 174 | H40: 92 | J40: CLOSED | L40: CLOSED | N40: CLOSED | O40: =F40+H40 -> 266
A41: 40267 | B41: =A41 -> 40267 | C41: -0.7 | D41: 0.30694444 | F41: 1673 | G41: * | H41: =F41*H42/F42 -> 713.4959 | J41: CLOSED | L41: CLOSED | N41: CLOSED | O41: =F41+H41 -> 2386.4959
A42: 40268 | B42: =A42 -> 40268 | C42: -1 | D42: 0.33819444 | F42: 2319 | H42: 989 | J42: CLOSED | L42: CLOSED | N42: CLOSED | O42: =F42+H42 -> 3308
A43: 40269 | B43: =A43 -> 40269 | C43: -1 | D43: 0.36944444 | F43: 2791 | G43: * | H43: =F43*H42/F42 -> 1190.2971 | J43: CLOSED | L43: CLOSED | N43: CLOSED | O43: =F43+H43 -> 3981.2971
A45: 40284 | B45: =A45 -> 40284 | C45: -0.7 | D45: 0.35555556 | F45: 3369 | H45: 1808 | J45: CLOSED | L45: CLOSED | N45: CLOSED | O45: =F45+H45 -> 5177
A46: 40285 | B46: =A46 -> 40285 | C46: -0.7 | D46: 0.38333333 | F46: 7304 | H46: 5145 | J46: CLOSED | L46: CLOSED | N46: 589.73061 | O46: =F46+H46+N46 -> 13038.731
A47: 40286 | B47: =A47 -> 40286 | C47: -0.6 | D47: 0.41527778 | F47: 6565 | H47: 5320 | J47: CLOSED | L47: CLOSED | N47: 639.08682 | O47: =F47+H47+N47 -> 12524.087
A49: 40295 | B49: =A49 -> 40295 | C49: -1 | D49: 0.26458333 | F49: 705 | H49: 503 | J49: CLOSED | L49: CLOSED | N49: CLOSED | O49: =F49+H49 -> 1208
...

Sheet Summary Table
A1: 2009-2010 State (non-Indian) Recreational Razor Clam Effort, Harvest and CPUE totals.
E2: LONG BEACH | H2: TWIN HARBORS | K2: COPALIS | N2: MOCROCKS | Q2: KALALOCH | T2: DAILY TOTALS
A3: DATE | B3: DAY | C3: TIDE | D3: TIME | E3: Effort | F3: Harvest | G3: CPUE | H3: Effort | I3: Harvest | J3: CPUE | K3: Effort | L3: Harvest | M3: CPUE | N3: Effort | O3: Harvest | P3: CPUE | Q3: Effort | R3: Harvest | S3: CPUE | T3: Effort | U3: Harvest
A4: 40102 | B4: =+A4 -> 40102 | C4: -0.2 | D4: 0.79097222 | E4: =Effort!F2 -> 2530 | F4: =Harvest!F2 -> 26480 | G4: =CPUE!F2 -> 10.466403 | H4: =Effort!H2 -> 1225 | I4: =Harvest!H2 -> 14564 | J4: =CPUE!H2 -> 11.88898 | K4: =Effort!J2 -> 4924 | L4: =Harvest!J2 -> 67449 | M4: =CPUE!J2 -> 13.69801 | N4: =Effort!L2 -> CLOSED | O4: =Harvest!L2 -> CLOSED | P4: =CPUE!L2 -> CLOSED | Q4: =Effort!N2 -> CLOSED | R4: =Harvest!N2 -> CLOSED | S4: =CPUE!N2 -> CLOSED | T4: =E4+H4+K4 -> 8679 | U4: =F4+I4+L4 -> 108493
A5: 40103 | B5: =+A5 -> 40103 | C5: -0.7 | D5: 0.78055556 | E5: =Effort!F3 -> 4331 | F5: =Harvest!F3 -> 64965 | G5: =CPUE!F3 -> 15 | H5: =Effort!H3 -> 1920 | I5: =Harvest!H3 -> 25353 | J5: =CPUE!H3 -> 13.204688 | K5: =Effort!J3 -> 6773 | L5: =Harvest!J3 -> 100367 | M5: =CPUE!J3 -> 14.818692 | N5: =Effort!L3 -> 3496 | O5: =Harvest!L3 -> 46405 | P5: =CPUE!L3 -> 13.273741 | Q5: =Effort!N3 -> 427.28109 | R5: =Harvest!N3 -> 5826.3051 | S5: =CPUE!N3 -> 13.635766 | T5: =E5+H5+K5+N5+Q5 -> 16947.281 | U5: =F5+I5+L5+O5+R5 -> 242916.31
A6: 40104 | B6: =+A6 -> 40104 | C6: -1 | D6: 0.80972222 | E6: =Effort!F4 -> 1941.9931 | F6: =Harvest!F4 -> 27625.473 | G6: =CPUE!F4 -> 14.22532 | H6: =Effort!H4 -> 1341 | I6: =Harvest!H4 -> 20115 | J6: =CPUE!H4 -> 15 | K6: =Effort!J4 -> 2860 | L6: =Harvest!J4 -> 42641 | M6: =CPUE!J4 -> 14.909441 | N6: =Effort!L4 -> 1202 | O6: =Harvest!L4 -> 18037 | P6: =CPUE!L4 -> 15.005824 | Q6: =Effort!N4 -> 192.65988 | R6: =Harvest!N4 -> 2814.1557 | S6: =CPUE!N4 -> 14.606859 | T6: =E6+H6+K6+N6+Q6 -> 7537.6529 | U6: =F6+I6+L6+O6+R6 -> 111232.63
A7: 40105 | B7: =+A7 -> 40105 | C7: -1.1 | D7: 0.83819444 | E7: =Effort!F5 -> CLOSED | F7: =Harvest!F5 -> CLOSED | G7: =CPUE!F5 -> CLOSED | H7: =Effort!H5 -> 1294 | I7: =Harvest!H5 -> 19410 | J7: =CPUE!H5 -> 15 | K7: =Effort!J5 -> CLOSED | L7: =Harvest!J5 -> CLOSED | M7: =CPUE!J5 -> CLOSED | N7: =Effort!L5 -> CLOSED | O7: =Harvest!L5 -> CLOSED | P7: =CPUE!L5 -> CLOSED | Q7: =Effort!N5 -> CLOSED | R7: =Harvest!N5 -> CLOSED | S7: =CPUE!N5 -> CLOSED | T7: =+H7 -> 1294 | U7: =+I7 -> 19410
A8: Tide Series Totals | E8: =SUM(E4:E7) -> 8802.9931 | F8: =SUM(F4:F7) -> 119070.47 | G8: =F8/E8 -> 13.526135 | H8: =SUM(H4:H7) -> 5780 | I8: =SUM(I4:I7) -> 79442 | J8: =I8/H8 -> 13.744291 | K8: =SUM(K4:K7) -> 14557 | L8: =SUM(L4:L7) -> 210457 | M8: =L8/K8 -> 14.457443 | N8: =SUM(N5:N7) -> 4698 | O8: =SUM(O5:O7) -> 64442 | P8: =O8/N8 -> 13.716901 | Q8: =SUM(Q5:Q7) -> 619.94097 | R8: =SUM(R5:R7) -> 8640.4608 | S8: =R8/Q8 -> 13.937554 | T8: =SUM(T4:T7) -> 34457.934 | U8: =SUM(U4:U7) -> 482051.93
A9: 40121 | B9: 40121 | C9: -1.2 | D9: 0.8125 | E9: =Effort!F7 -> 865 | F9: =Harvest!F7 -> 12676 | G9: =CPUE!F7 -> 14.654335 | H9: =Effort!H7 -> 1065 | I9: =Harvest!H7 -> 15951 | J9: =CPUE!H7 -> 14.977465 | K9: =Effort!J7 -> CLOSED | L9: =Harvest!J7 -> CLOSED | M9: =CPUE!J7 -> CLOSED | N9: =Effort!L7 -> CLOSED | O9: =Harvest!L7 -> CLOSED | P9: =CPUE!L7 -> CLOSED | Q9: =Effort!N7 -> CLOSED | R9: =Harvest!N7 -> CLOSED | S9: =CPUE!N7 -> CLOSED | T9: =E9+H9 -> 1930 | U9: =F9+I9 -> 28627
A10: 40122 | B10: =+A10 -> 40122 | C10: -1.1 | D10: 0.84444444 | E10: =Effort!F8 -> CLOSED | F10: =Harvest!F8 -> CLOSED | G10: =CPUE!F8 -> CLOSED | H10: =Effort!H8 -> 156 | I10: =Harvest!H8 -> 1600 | J10: =CPUE!H8 -> 10.25641 | K10: =Effort!J8 -> CLOSED | L10: =Harvest!J8 -> CLOSED | M10: =CPUE!J8 -> CLOSED | N10: =Effort!L8 -> CLOSED | O10: =Harvest!L8 -> CLOSED | P10: =CPUE!L8 -> CLOSED | Q10: =Effort!N8 -> CLOSED | R10: =Harvest!N8 -> CLOSED | S10: =CPUE!N8 -> CLOSED | T10: =H10 -> 156 | U10: =I10 -> 1600
A11: 40123 | B11: 40123 | C11: -0.8 | D11: 0.87916667 | E11: =Effort!F9 -> 368.45535 | F11: =Harvest!F9 -> 1776.3788 | G11: =CPUE!F9 -> 4.8211508 | H11: =Effort!H9 -> 145 | I11: =Harvest!H9 -> 650.90338 | J11: =CPUE!H9 -> 4.4889888 | K11: =Effort!J9 -> CLOSED | L11: =Harvest!J9 -> CLOSED | M11: =CPUE!J9 -> CLOSED | N11: =Effort!L9 -> CLOSED | O11: =Harvest!L9 -> CLOSED | P11: =CPUE!L9 -> CLOSED | Q11: =Effort!N9 -> CLOSED | R11: =Harvest!N9 -> CLOSED | S11: =CPUE!N9 -> CLOSED | T11: =E11+H11 -> 513.45535 | U11: =F11+I11 -> 2427.2822
A12: 40124 | B12: 40124 | C12: -0.4 | D12: 0.91666667 | E12: =Effort!F10 -> 492.19718 | F12: =Harvest!F10 -> 5903.7053 | G12: =CPUE!F10 -> 11.994594 | H12: =Effort!H10 -> 606 | I12: =Harvest!H10 -> 7429 | J12: =CPUE!H10 -> 12.259076 | K12: =Effort!J10 -> CLOSED | L12: =Harvest!J10 -> CLOSED | M12: =CPUE!J10 -> CLOSED | N12: =Effort!L10 -> CLOSED | O12: =Harvest!L10 -> CLOSED | P12: =CPUE!L10 -> CLOSED | Q12: =Effort!N10 -> CLOSED | R12: =Harvest!N10 -> CLOSED | S12: =CPUE!N10 -> CLOSED | T12: =E12+H12 -> 1098.1972 | U12: =F12+I12 -> 13332.705
A13: Tide Series Totals | E13: =SUM(E9:E12) -> 1725.6525 | F13: =SUM(F9:F12) -> 20356.084 | G13: =F13/E13 -> 11.796166 | H13: =SUM(H9:H12) -> 1972 | I13: =SUM(I9:I12) -> 25630.903 | J13: =I13/H13 -> 12.997416 | T13: =SUM(T9:T12) -> 3697.6525 | U13: =SUM(U9:U12) -> 45986.988
A14: 40131 | B14: 40131 | C14: -0.4 | D14: 0.69861111 | E14: =Effort!F12 -> 4282 | F14: =Harvest!F12 -> 62016 | G14: =CPUE!F12 -> 14.482952 | H14: =Effort!H12 -> 1733 | I14: =Harvest!H12 -> 24308 | J14: =CPUE!H12 -> 14.026544 | K14: =Effort!J12 -> 3936 | L14: =Harvest!J12 -> 59043 | M14: =CPUE!J12 -> 15.000762 | N14: =Effort!L12 -> 2638 | O14: =Harvest!L12 -> 39565 | P14: =CPUE!L12 -> 14.998105 | Q14: =Effort!N12 -> CLOSED | R14: =Harvest!N12 -> CLOSED | S14: =CPUE!N12 -> CLOSED | T14: =E14+H14+K14+N14 -> 12589 | U14: =F14+I14+L14+O14 -> 184932
A15: 40132 | B15: 40132 | C15: -0.8 | D15: 0.72916667 | E15: =Effort!F13 -> 1715 | F15: =Harvest!F13 -> 21871 | G15: =CPUE!F13 -> 12.75277 | H15: =Effort!H13 -> 625 | I15: =Harvest!H13 -> 6430 | J15: =CPUE!H13 -> 10.288 | K15: =Effort!J13 -> 3833 | L15: =Harvest!J13 -> 43442 | M15: =CPUE!J13 -> 11.333681 | N15: =Effort!L13 -> 1325 | O15: =Harvest!L13 -> 15162 | P15: =CPUE!L13 -> 11.443019 | Q15: =Effort!N13 -> CLOSED | R15: =Harvest!N13 -> CLOSED | S15: =CPUE!N13 -> CLOSED | T15: =E15+H15+K15+N15 -> 7498 | U15: =F15+I15+L15+O15 -> 86905
A16: 40133 | B16: 40133 | C16: -1 | D16: 0.75694444 | E16: =Effort!F14 -> 301.04647 | F16: =Harvest!F14 -> 1620.6885 | G16: =CPUE!F14 -> 5.3835161 | H16: =Effort!H14 -> 118.37045 | I16: =Harvest!H14 -> 593.8551 | J16: =CPUE!H14 -> 5.0169203 | K16: =Effort!J14 -> 390 | L16: =Harvest!J14 -> 1980 | M16: =CPUE!J14 -> 5.0769231 | N16: =Effort!L14 -> 198.94066 | O16: =Harvest!L14 -> 1057.3202 | P16: =CPUE!L14 -> 5.3147516 | Q16: =Effort!N14 -> 22 | R16: =Harvest!N14 -> 0 | S16: =CPUE!N14 -> 0 | T16: =E16+H16+K16+N16+Q16 -> 1030.3576 | U16: =F16+I16+L16+O16+R16 -> 5251.8638
A17: 40134 | B17: 40134 | C17: -0.9 | D17: 0.78402778 | E17: =Effort!F15 -> CLOSED | F17: =Harvest!F15 -> CLOSED | G17: =CPUE!F15 -> CLOSED | H17: =Effort!H15 -> 283 | I17: =Harvest!H15 -> 2901 | J17: =CPUE!H15 -> 10.250883 | K17: =Effort!J15 -> CLOSED | L17: =Harvest!J15 -> CLOSED | M17: =CPUE!J15 -> CLOSED | N17: =Effort!L15 -> CLOSED | O17: =Harvest!L15 -> CLOSED | P17: =CPUE!L15 -> CLOSED | Q17: =Effort!N15 -> CLOSED | R17: =Harvest!N15 -> CLOSED | S17: =CPUE!N15 -> CLOSED | T17: =H17 -> 283 | U17: =I17 -> 2901
A18: Tide Series Totals | E18: =SUM(E14:E17) -> 6298.0465 | F18: =SUM(F14:F17) -> 85507.688 | G18: =F18/E18 -> 13.576859 | H18: =SUM(H14:H17) -> 2759.3704 | I18: =SUM(I14:I17) -> 34232.855 | J18: =I18/H18 -> 12.406038 | K18: =SUM(K14:K17) -> 8159 | L18: =SUM(L14:L17) -> 104465 | M18: =L18/K18 -> 12.803652 | N18: =SUM(N14:N17) -> 4161.9407 | O18: =SUM(O14:O17) -> 55784.32 | P18: =O18/N18 -> 13.40344 | Q18: =SUM(Q14:Q17) -> 22 | R18: =SUM(R14:R17) -> 0 | S18: 0 | T18: =SUM(T14:T17) -> 21400.358 | U18: =SUM(U14:U17) -> 279989.86
A19: 40149 | B19: 40149 | C19: -1.5 | D19: 0.77222222 | E19: =Effort!F17 -> 1396 | F19: =Harvest!F17 -> 20288 | G19: =CPUE!F17 -> 14.532951 | H19: =Effort!H17 -> 651 | I19: =Harvest!H17 -> 9801 | J19: =CPUE!H17 -> 15.0553 | K19: =Effort!J17 -> CLOSED | L19: =Harvest!J17 -> CLOSED | M19: =CPUE!J17 -> CLOSED | N19: =Effort!L17 -> CLOSED | O19: =Harvest!L17 -> CLOSED | P19: =CPUE!L17 -> CLOSED | Q19: =Effort!N17 -> CLOSED | R19: =Harvest!N17 -> CLOSED | S19: =CPUE!N17 -> CLOSED | T19: =E19+H19 -> 2047 | U19: =F19+I19 -> 30089
A20: 40150 | B20: 40150 | C20: -1.6 | D20: 0.80347222 | E20: =Effort!F18 -> CLOSED | F20: =Harvest!F18 -> CLOSED | G20: =CPUE!F18 -> CLOSED | H20: =Effort!H18 -> 391 | I20: =Harvest!H18 -> 5295 | J20: =CPUE!H18 -> 13.542199 | K20: =Effort!J18 -> 1364 | L20: =Harvest!J18 -> 20455 | M20: =CPUE!J18 -> 14.996334 | N20: =Effort!L18 -> 548 | O20: =Harvest!L18 -> 7196 | P20: =CPUE!L18 -> 13.131387 | Q20: =Effort!N18 -> CLOSED | R20: =Harvest!N18 -> CLOSED | S20: =CPUE!N18 -> CLOSED | T20: =H20+K20+N20 -> 2303 | U20: =I20+L20+O20 -> 32946
A21: 40151 | B21: 40151 | C21: -1.5 | D21: 0.83611111 | E21: =Effort!F19 -> 894 | F21: =Harvest!F19 -> 13077 | G21: =CPUE!F19 -> 14.627517 | H21: =Effort!H19 -> 464.553 | I21: =Harvest!H19 -> 6245.2478 | J21: =CPUE!H19 -> 13.443564 | K21: =Effort!J19 -> 1484 | L21: =Harvest!J19 -> 21434 | M21: =CPUE!J19 -> 14.443396 | N21: =Effort!L19 -> 945 | O21: =Harvest!L19 -> 12344 | P21: =CPUE!L19 -> 13.062434 | Q21: =Effort!N19 -> 161.93569 | R21: =Harvest!N19 -> 1908.9138 | S21: =CPUE!N19 -> 11.788098 | T21: =E21+H21+K21+N21+Q21 -> 3949.4887 | U21: =F21+I21+L21+O21+R21 -> 55009.162
A22: 40152 | B22: 40152 | C22: -1.1 | D22: 0.86875 | E22: =Effort!F20 -> 821.30261 | F22: =Harvest!F20 -> 11877.619 | G22: =CPUE!F20 -> 14.461928 | H22: =Effort!H20 -> 383 | I22: =Harvest!H20 -> 5738 | J22: =CPUE!H20 -> 14.981723 | K22: =Effort!J20 -> 1347 | L22: =Harvest!J20 -> 20200 | M22: =CPUE!J20 -> 14.996288 | N22: =Effort!L20 -> 788 | O22: =Harvest!L20 -> 11822 | P22: =CPUE!L20 -> 15.002538 | Q22: =Effort!N20 -> 219.2503 | R22: =Harvest!N20 -> 2735.7263 | S22: =CPUE!N20 -> 12.47764 | T22: =E22+H22+K22+N22+Q22 -> 3558.5529 | U22: =F22+I22+L22+O22+R22 -> 52373.345
A23: Tide Series Totals | E23: =SUM(E19:E22) -> 3111.3026 | F23: =SUM(F19:F22) -> 45242.619 | G23: =F23/E23 -> 14.541375 | H23: =SUM(H19:H22) -> 1889.553 | I23: =SUM(I19:I22) -> 27079.248 | J23: =I23/H23 -> 14.331034 | K23: =SUM(K19:K22) -> 4195 | L23: =SUM(L19:L22) -> 62089 | M23: =L23/K23 -> 14.800715 | N23: =SUM(N19:N22) -> 2281 | O23: =SUM(O19:O22) -> 31362 | P23: =O23/N23 -> 13.749233 | Q23: =SUM(Q19:Q22) -> 381.18599 | R23: =SUM(R19:R22) -> 4644.6401 | S23: =R23/Q23 -> 12.184708 | T23: =SUM(T19:T22) -> 11858.042 | U23: =SUM(U19:U22) -> 170417.51
A24: 40178 | B24: =A24 -> 40178 | C24: -1.6 | D24: 0.7625 | E24: =Effort!F22 -> 2025 | F24: =Harvest!F22 -> 25927 | G24: =CPUE!F22 -> 12.803457 | H24: =Effort!H22 -> 805 | I24: =Harvest!H22 -> 4351 | J24: =CPUE!H22 -> 5.4049689 | K24: =Effort!J22 -> 3264 | L24: =Harvest!J22 -> 28707 | M24: =CPUE!J22 -> 8.7950368 | N24: =Effort!L22 -> 1487 | O24: =Harvest!L22 -> 12106 | P24: =CPUE!L22 -> 8.1412239 | Q24: =Effort!N22 -> 299.71141 | R24: =Harvest!N22 -> 573.56355 | S24: =CPUE!N22 -> 1.9137194 | T24: =E24+H24+K24+N24+Q24 -> 7880.7114 | U24: =F24+I24+L24+O24+R24 -> 71664.564
A25: 40179 | B25: =A25 -> 40179 | C25: -1.8 | D25: 0.79236111 | E25: =Effort!F23 -> 4141.1018 | F25: =Harvest!F23 -> 18908.155 | G25: =CPUE!F23 -> 4.565972 | H25: =Effort!H23 -> 1274.9782 | I25: =Harvest!H23 -> 3361.5674 | J25: =CPUE!H23 -> 2.6365685 | K25: =Effort!J23 -> 6521 | L25: =Harvest!J23 -> 19791 | M25: =CPUE!J23 -> 3.034964 | N25: =Effort!L23 -> 2836 | O25: =Harvest!L23 -> 16258 | P25: =CPUE!L23 -> 5.7327221 | Q25: =Effort!N23 -> 202.81574 | R25: =Harvest!N23 -> 660.59983 | S25: =CPUE!N23 -> 3.2571429 | T25: =E25+H25+K25+N25+Q25 -> 14975.896 | U25: =F25+I25+L25+O25+R25 -> 58979.322
A26: 40180 | B26: =A26 -> 40180 | C26: -1.6 | D26: 0.82291667 | E26: =Effort!F24 -> 2795 | F26: =Harvest!F24 -> 41925 | G26: =CPUE!F24 -> 15 | H26: =Effort!H24 -> 679 | I26: =Harvest!H24 -> 7712 | J26: =CPUE!H24 -> 11.357879 | K26: =Effort!J24 -> 4167 | L26: =Harvest!J24 -> 62498 | M26: =CPUE!J24 -> 14.99832 | N26: =Effort!L24 -> 1973 | O26: =Harvest!L24 -> 26051 | P26: =CPUE!L24 -> 13.203751 | Q26: =Effort!N24 -> CLOSED | R26: =Harvest!N24 -> CLOSED | S26: =CPUE!N24 -> CLOSED | T26: =E26+H26+K26+N26 -> 9614 | U26: =F26+I26+L26+O26 -> 138186
A27: 40181 | B27: =A27 -> 40181 | C27: -1.2 | D27: 0.85347222 | E27: =Effort!F25 -> CLOSED | F27: =Harvest!F25 -> CLOSED | G27: =CPUE!F25 -> CLOSED | H27: =Effort!H25 -> 350 | I27: =Harvest!H25 -> 5250 | J27: =CPUE!H25 -> 15 | K27: =Effort!J25 -> CLOSED | L27: =Harvest!J25 -> CLOSED | M27: =CPUE!J25 -> CLOSED | N27: =Effort!L25 -> CLOSED | O27: =Harvest!L25 -> CLOSED | P27: =CPUE!L25 -> CLOSED | Q27: =Effort!N25 -> CLOSED | R27: =Harvest!N25 -> CLOSED | S27: =CPUE!N25 -> CLOSED | T27: =H27 -> 350 | U27: =I27 -> 5250
A28: Tide Series Totals | E28: =SUM(E24:E27) -> 8961.1018 | F28: =SUM(F24:F27) -> 86760.155 | G28: =F28/E28 -> 9.6818624 | H28: =SUM(H24:H27) -> 3108.9782 | I28: =SUM(I24:I27) -> 20674.567 | J28: =I28/H28 -> 6.6499557 | K28: =SUM(K24:K27) -> 13952 | L28: =SUM(L24:L27) -> 110996 | M28: =L28/K28 -> 7.9555619 | N28: =SUM(N24:N27) -> 6296 | O28: =SUM(O24:O27) -> 54415 | P28: =O28/N28 -> 8.6427891 | Q28: =SUM(Q24:Q27) -> 502.52715 | R28: =SUM(R24:R27) -> 1234.1634 | S28: =R28/Q28 -> 2.4559138 | T28: =SUM(T24:T27) -> 32820.607 | U28: =SUM(U24:U27) -> 274079.89
A29: 40206 | B29: =A29 -> 40206 | C29: -1.1 | D29: 0.71736111 | E29: =Effort!F27 -> CLOSED | F29: =Harvest!F27 -> CLOSED | G29: =CPUE!F27 -> CLOSED | H29: =Effort!H27 -> 861 | I29: =Harvest!H27 -> 12915 | J29: =CPUE!H27 -> 15 | K29: =Effort!J27 -> CLOSED | L29: =Harvest!J27 -> CLOSED | M29: =CPUE!J27 -> CLOSED | N29: =Effort!L27 -> CLOSED | O29: =Harvest!L27 -> CLOSED | P29: =CPUE!L27 -> CLOSED | Q29: =Effort!N27 -> CLOSED | R29: =Harvest!N27 -> CLOSED | S29: =CPUE!N27 -> CLOSED | T29: =H29 -> 861 | U29: =I29 -> 12915
A30: 40207 | B30: =A30 -> 40207 | C30: -1.5 | D30: 0.74861111 | E30: =Effort!F28 -> CLOSED | F30: =Harvest!F28 -> CLOSED | G30: =CPUE!F28 -> CLOSED | H30: =Effort!H28 -> 1685 | I30: =Harvest!H28 -> 25275 | J30: =CPUE!H28 -> 15 | K30: =Effort!J28 -> 4578 | L30: =Harvest!J28 -> 65435 | M30: =CPUE!J28 -> 14.29336 | N30: =Effort!L28 -> 2378 | O30: =Harvest!L28 -> 28597 | P30: =CPUE!L28 -> 12.025652 | Q30: =Effort!N28 -> CLOSED | R30: =Harvest!N28 -> CLOSED | S30: =CPUE!N28 -> CLOSED | T30: =H30+K30+N30 -> 8641 | U30: =I30+L30+O30 -> 119307
A31: 40208 | B31: =A31 -> 40208 | C31: -1.5 | D31: 0.77847222 | E31: =Effort!F29 -> CLOSED | F31: =Harvest!F29 -> CLOSED | G31: =CPUE!F29 -> CLOSED | H31: =Effort!H29 -> 2490 | I31: =Harvest!H29 -> 37350 | J31: =CPUE!H29 -> 15 | K31: =Effort!J29 -> 5240 | L31: =Harvest!J29 -> 64017 | M31: =CPUE!J29 -> 12.216985 | N31: =Effort!L29 -> 3418 | O31: =Harvest!L29 -> 42276 | P31: =CPUE!L29 -> 12.368637 | Q31: =Effort!N29 -> 228.50498 | R31: =Harvest!N29 -> 1075.0327 | S31: =CPUE!N29 -> 4.7046358 | T31: =H31+K31+N31+Q31 -> 11376.505 | U31: =I31+L31+O31+R31 -> 144718.03
A32: 40209 | B32: =A32 -> 40209 | C32: -1.2 | D32: 0.80763889 | E32: =Effort!F30 -> CLOSED | F32: =Harvest!F30 -> CLOSED | G32: =CPUE!F30 -> CLOSED | H32: =Effort!H30 -> 540 | I32: =Harvest!H30 -> 5848.2177 | J32: =CPUE!H30 -> 10.830033 | K32: =Effort!J30 -> 2737 | L32: =Harvest!J30 -> 33358 | M32: =CPUE!J30 -> 12.187797 | N32: =Effort!L30 -> 927 | O32: =Harvest!L30 -> 13902 | P32: =CPUE!L30 -> 14.996764 | Q32: =Effort!N30 -> 111.64295 | R32: =Harvest!N30 -> 1108.1596 | S32: =CPUE!N30 -> 9.9259259 | T32: =H32+K32+N32+Q32 -> 4315.6429 | U32: =I32+L32+O32+R32 -> 54216.377
A33: Tide Series Totals | E33: =SUM(E29:E32) -> 0 | F33: =SUM(F29:F32) -> 0 | G33: =F33/E33 -> #DIV/0! | H33: =SUM(H29:H32) -> 5576 | I33: =SUM(I29:I32) -> 81388.218 | J33: =I33/H33 -> 14.596165 | K33: =SUM(K29:K32) -> 12555 | L33: =SUM(L29:L32) -> 162810 | M33: =L33/K33 -> 12.967742 | N33: =SUM(N29:N32) -> 6723 | O33: =SUM(O29:O32) -> 84775 | P33: =O33/N33 -> 12.609698 | Q33: =SUM(Q29:Q32) -> 340.14792 | R33: =SUM(R29:R32) -> 2183.1923 | S33: =R33/Q33 -> 6.4183615 | T33: =SUM(T29:T32) -> 25194.148 | U33: =SUM(U29:U32) -> 331156.41
A34: 40235 | B34: 40235 | C34: -0.7 | D34: 0.70069444 | E34: =Effort!F32 -> 2703 | F34: =Harvest!F32 -> 40476 | G34: =CPUE!F32 -> 14.974473 | H34: =Effort!H32 -> 1283 | I34: =Harvest!H32 -> 19245 | J34: =CPUE!H32 -> 15 | K34: =Effort!J32 -> 4088 | L34: =Harvest!J32 -> 61050 | M34: =CPUE!J32 -> 14.933953 | N34: =Effort!L32 -> 1725 | O34: =Harvest!L32 -> 25870 | P34: =CPUE!L32 -> 14.997101 | Q34: =Effort!N32 -> CLOSED | R34: =Harvest!N32 -> CLOSED | S34: =CPUE!N32 -> CLOSED | T34: =E34+H34+K34+N34 -> 9799 | U34: =F34+I34+L34+O34 -> 146641
A35: 40236 | B35: 40236 | C35: -0.9 | D35: 0.73194444 | E35: =Effort!F33 -> 4600 | F35: =Harvest!F33 -> 69000 | G35: =CPUE!F33 -> 15 | H35: =Effort!H33 -> 550 | I35: =Harvest!H33 -> 8000 | J35: =CPUE!H33 -> 15 | K35: =Effort!J33 -> 2863.2 | L35: =Harvest!J33 -> 42500 | M35: =CPUE!J33 -> 15 | N35: =Effort!L33 -> 688.8 | O35: =Harvest!L33 -> 10000 | P35: =CPUE!L33 -> 15 | Q35: =Effort!N33 -> 129.00294 | R35: =Harvest!N33 -> 338.78341 | S35: =CPUE!N33 -> 2.6261682 | T35: =E35+H35+K35+N35+Q35 -> 8831.0029 | U35: =F35+I35+L35+O35+R35 -> 129838.78
A36: 40237 | B36: 40237 | C36: -0.8 | D36: 0.76111111 | E36: =Effort!F34 -> 4661 | F36: =Harvest!F34 -> 69915 | G36: =CPUE!F34 -> 15 | H36: =Effort!H34 -> 1868 | I36: =Harvest!H34 -> 26623 | J36: =CPUE!H34 -> 14.252141 | K36: =Effort!J34 -> 9544 | L36: =Harvest!J34 -> 141678 | M36: =CPUE!J34 -> 14.844719 | N36: =Effort!L34 -> 2296 | O36: =Harvest!L34 -> 33868 | P36: =CPUE!L34 -> 14.750871 | Q36: =Effort!N34 -> 165.42407 | R36: =Harvest!N34 -> 2373.1992 | S36: =CPUE!N34 -> 14.346154 | T36: =E36+H36+K36+N36+Q36 -> 18534.424 | U36: =F36+I36+L36+O36+R36 -> 274457.2
A37: 40238 | B37: 40238 | C37: -0.4 | D37: 0.78888889 | E37: =Effort!F35 -> 1411 | F37: =Harvest!F35 -> 4702 | G37: =CPUE!F35 -> 3.3323884 | H37: =Effort!H35 -> 996 | I37: =Harvest!H35 -> 12984 | J37: =CPUE!H35 -> 13.036145 | K37: =Effort!J35 -> CLOSED | L37: =Harvest!J35 -> CLOSED | M37: =CPUE!J35 -> CLOSED | N37: =Effort!L35 -> CLOSED | O37: =Harvest!L35 -> CLOSED | P37: =CPUE!L35 -> CLOSED | Q37: =Effort!N35 -> CLOSED | R37: =Harvest!N35 -> CLOSED | S37: =CPUE!N35 -> CLOSED | T37: =E37+H37 -> 2407 | U37: =F37+I37 -> 17686
A38: Tide Series Totals | E38: =SUM(E34:E37) -> 13375 | F38: =SUM(F34:F37) -> 184093 | G38: =F38/E38 -> 13.763963 | H38: =SUM(H34:H37) -> 4697 | I38: =SUM(I34:I37) -> 66852 | J38: =I38/H38 -> 14.232915 | K38: =SUM(K34:K37) -> 16495.2 | L38: =SUM(L34:L37) -> 245228 | M38: =L38/K38 -> 14.866628 | N38: =SUM(N34:N37) -> 4709.8 | O38: =SUM(O34:O37) -> 69738 | P38: =O38/N38 -> 14.806998 | Q38: =SUM(Q34:Q37) -> 294.42701 | R38: =SUM(R34:R37) -> 2711.9826 | S38: =R38/Q38 -> 9.2110524 | T38: =SUM(T34:T37) -> 39571.427 | U38: =SUM(U34:U37) -> 568622.98
A39: 40263 | B39: 40263 | C39: 0.1 | D39: 0.68680556 | E39: =Effort!F37 -> 4148 | F39: =Harvest!F37 -> 61344 | G39: =CPUE!F37 -> 14.788814 | H39: =Effort!H37 -> 1153 | I39: =Harvest!H37 -> 17021 | J39: =CPUE!H37 -> 14.762359 | K39: =Effort!J37 -> CLOSED | L39: =Harvest!J37 -> CLOSED | M39: =CPUE!J37 -> CLOSED | N39: =Effort!L37 -> CLOSED | O39: =Harvest!L37 -> CLOSED | P39: =CPUE!L37 -> CLOSED | Q39: =Effort!N37 -> 238.93626 | R39: =Harvest!N37 -> 2835.6659 | S39: =CPUE!N37 -> 11.867876 | T39: =+E39+H39+Q39 -> 5539.9363 | U39: =+F39+I39+R39 -> 81200.666
A40: 40264 | B40: 40264 | C40: -0.1 | D40: 0.72152778 | E40: =Effort!F38 -> 5291.5036 | F40: =Harvest!F38 -> 56443.799 | G40: =CPUE!F38 -> 10.666873 | H40: =Effort!H38 -> 3633 | I40: =Harvest!H38 -> 53531 | J40: =CPUE!H38 -> 14.734655 | K40: =Effort!J38 -> 8172 | L40: =Harvest!J38 -> 113112 | M40: =CPUE!J38 -> 13.84141 | N40: =Effort!L38 -> 5309 | O40: =Harvest!L38 -> 74693 | P40: =CPUE!L38 -> 14.069128 | Q40: =Effort!N38 -> 513.85641 | R40: =Harvest!N38 -> 6094.241 | S40: =CPUE!N38 -> 11.859813 | T40: =+E40+H40+K40+N40+Q40 -> 22919.36 | U40: =+F40+I40+L40+O40+R40 -> 303874.04
...

Sheet TAC
A1: 2009 FALL - 2010 SPRING NON-TRIBAL TOTAL ALLOWABLE CATCH (TAC)
A4: LONG BEACH | B4: 1683551.1
A5: TWIN HARBORS | B5: 1177736.4
A6: COPALIS | B6: 1021580.9
A7: MOCROCKS | B7: 629631.18
A8: KALALOCH | B8: 448596.62
A9: COASTWIDE TAC | B9: =SUM(B4:B8) -> 4961096.2

Sheet Tribal Update
A1: 2009-2010 State (non-Indian) Recreational Razor Clam Effort, Harvest and CPUE totals - FINAL
E2: COPALIS | I2: MOCROCKS | M2: KALALOCH | Q2: DAILY TOTALS
A3: DATE | B3: DAY | C3: TIDE | D3: TIME | E3: Effort | F3: Harvest | G3: CPUE | H3: Size (mm) | I3: Effort | J3: Harvest | K3: CPUE | L3: Size (mm) | M3: Effort | N3: Harvest | O3: CPUE | P3: Size (mm) | Q3: Effort | R3: Harvest
A4: 40102 | B4: =+A4 -> 40102 | C4: -0.2 | D4: 0.79097222 | E4: =Effort!J2 -> 4924 | F4: =Harvest!J2 -> 67449 | G4: =CPUE!J2 -> 13.69801 | I4: =Effort!L2 -> CLOSED | J4: =Harvest!L2 -> CLOSED | K4: =CPUE!L2 -> CLOSED | M4: =Effort!N2 -> CLOSED | N4: =Harvest!N2 -> CLOSED | O4: =CPUE!N2 -> CLOSED | Q4: =E4 -> 4924 | R4: =F4 -> 67449
A5: 40103 | B5: =+A5 -> 40103 | C5: -0.7 | D5: 0.78055556 | E5: =Effort!J3 -> 6773 | F5: =Harvest!J3 -> 100367 | G5: =CPUE!J3 -> 14.818692 | I5: =Effort!L3 -> 3496 | J5: =Harvest!L3 -> 46405 | K5: =CPUE!L3 -> 13.273741 | M5: =Effort!N3 -> 427.28109 | N5: =Harvest!N3 -> 5826.3051 | O5: =CPUE!N3 -> 13.635766 | Q5: =E5+I5+M5 -> 10696.281 | R5: =F5+J5+N5 -> 152598.31
A6: 40104 | B6: =+A6 -> 40104 | C6: -1 | D6: 0.80972222 | E6: =Effort!J4 -> 2860 | F6: =Harvest!J4 -> 42641 | G6: =CPUE!J4 -> 14.909441 | I6: =Effort!L4 -> 1202 | J6: =Harvest!L4 -> 18037 | K6: =CPUE!L4 -> 15.005824 | M6: =Effort!N4 -> 192.65988 | N6: =Harvest!N4 -> 2814.1557 | O6: =CPUE!N4 -> 14.606859 | Q6: =E6+I6+M6 -> 4254.6599 | R6: =F6+J6+N6 -> 63492.156
A7: 40105 | B7: =+A7 -> 40105 | C7: -1.1 | D7: 0.83819444 | E7: =Effort!J5 -> CLOSED | F7: =Harvest!J5 -> CLOSED | G7: =CPUE!J5 -> CLOSED | I7: =Effort!L5 -> CLOSED | J7: =Harvest!L5 -> CLOSED | K7: =CPUE!L5 -> CLOSED | M7: =Effort!N5 -> CLOSED | N7: =Harvest!N5 -> CLOSED | O7: =CPUE!N5 -> CLOSED | Q7: 0 | R7: 0
A8: Tide Series Totals | E8: =SUM(E4:E7) -> 14557 | F8: =SUM(F4:F7) -> 210457 | G8: =F8/E8 -> 14.457443 | H8: 117.74 | I8: =SUM(I5:I7) -> 4698 | J8: =SUM(J5:J7) -> 64442 | K8: =J8/I8 -> 13.716901 | L8: 124.27 | M8: =SUM(M5:M7) -> 619.94097 | N8: =SUM(N5:N7) -> 8640.4608 | O8: =N8/M8 -> 13.937554 | P8: 103.83 | Q8: =SUM(Q4:Q7) -> 19874.941 | R8: =SUM(R4:R7) -> 283539.46
A9: 40131 | B9: 40131 | C9: -0.4 | D9: 0.69861111 | E9: 3582 | F9: 53730 | G9: 15 | I9: 2232 | J9: 33480 | K9: 15 | M9: CLOSED | N9: CLOSED | O9: CLOSED | Q9: =E9+I9 -> 5814 | R9: =F9+J9 -> 87210
A10: 40132 | B10: 40132 | C10: -0.8 | D10: 0.72916667 | E10: 2196 | F10: 26314 | G10: 11.982696 | I10: 942 | J10: 10426 | K10: 11.067941 | M10: CLOSED | N10: CLOSED | O10: CLOSED | Q10: =E10+I10 -> 3138 | R10: =F10+J10 -> 36740
A11: 40133 | B11: 40133 | C11: -1 | D11: 0.75694444 | E11: 355 | F11: 1695 | G11: 4.7746479 | I11: 195.01038 | J11: 929.74701 | K11: 4.7676795 | M11: 22 | N11: 0 | O11: 0 | Q11: =E11+I11+M11 -> 572.01038 | R11: =F11+J11+N11 -> 2624.747
A12: 40134 | B12: 40134 | C12: -0.9 | D12: 0.78402778 | E12: CLOSED | F12: CLOSED | G12: CLOSED | I12: CLOSED | J12: CLOSED | K12: CLOSED | M12: CLOSED | N12: CLOSED | O12: CLOSED | Q12: 0 | R12: 0
A13: Tide Series Totals | E13: =SUM(E9:E12) -> 6133 | F13: =SUM(F9:F12) -> 81739 | G13: =F13/E13 -> 13.327735 | H13: 123.95 | I13: =SUM(I9:I12) -> 3369.0104 | J13: =SUM(J9:J12) -> 44835.747 | K13: =J13/I13 -> 13.308284 | L13: 123.14 | M13: =SUM(M11:M12) -> 22 | N13: =SUM(N11:N12) -> 0 | O13: =N13/M13 -> 0 | Q13: =SUM(Q9:Q12) -> 9524.0104 | R13: =SUM(R9:R12) -> 126574.75
A14: 40149 | B14: 40149 | C14: -1.5 | D14: 0.77222222 | E14: CLOSED | F14: CLOSED | G14: CLOSED | I14: CLOSED | J14: CLOSED | K14: CLOSED | M14: CLOSED | N14: CLOSED | O14: CLOSED | Q14: 0 | R14: 0
A15: 40150 | B15: 40150 | C15: -1.6 | D15: 0.80347222 | E15: 1231 | F15: 18465 | G15: 15 | I15: 459 | J15: 6181 | K15: 13.466231 | M15: CLOSED | N15: CLOSED | O15: CLOSED | Q15: =E15+I15 -> 1690 | R15: =F15+J15 -> 24646
A16: 40151 | B16: 40151 | C16: -1.5 | D16: 0.83611111 | E16: 1395 | F16: 20242 | G16: 14.510394 | I16: 813 | J16: 10653 | K16: 13.103321 | M16: 161.93569 | N16: 1908.9138 | O16: 11.788098 | Q16: =E16+I16+M16 -> 2369.9357 | R16: =F16+J16+N16 -> 32803.914
A17: 40152 | B17: 40152 | C17: -1.1 | D17: 0.86875 | E17: 1071 | F17: 16065 | G17: 15 | I17: 576 | J17: 8640 | K17: 15 | M17: 219.2503 | N17: 2735.7263 | O17: 12.47764 | Q17: =E17+I17+M17 -> 1866.2503 | R17: =F17+J17+N17 -> 27440.726
A18: Tide Series Totals | E18: =SUM(E15:E17) -> 3697 | F18: =SUM(F15:F17) -> 54772 | G18: =F18/E18 -> 14.815256 | H18: 123.34177 | I18: =SUM(I15:I17) -> 1848 | J18: =SUM(J15:J17) -> 25474 | K18: =J18/I18 -> 13.784632 | L18: 122.88333 | M18: =SUM(M16:M17) -> 381.18599 | N18: =SUM(N16:N17) -> 4644.6401 | O18: =N18/M18 -> 12.184708 | P18: 102.7 | Q18: =SUM(Q14:Q17) -> 5926.186 | R18: =SUM(R14:R17) -> 84890.64
A19: 40178 | B19: =A19 -> 40178 | C19: -1.6 | D19: 0.7625 | E19: 2742 | F19: 24193 | G19: 8.8231218 | I19: 1150 | J19: 8692 | K19: 7.5582609 | M19: 299.71141 | N19: 573.56355 | O19: 1.9137194 | Q19: =E19+I19 -> 3892 | R19: =F19+J19 -> 32885
A20: 40179 | B20: =A20 -> 40179 | C20: -1.8 | D20: 0.79236111 | E20: 3582 | F20: 10871.84 | G20: 3.0351312 | I20: 1884 | J20: 10283 | K20: 5.4580679 | M20: 202.81574 | N20: 660.59983 | O20: 3.2571429 | Q20: =E20+I20 -> 5466 | R20: =F20+J20 -> 21154.84
A21: 40180 | B21: =A21 -> 40180 | C21: -1.6 | D21: 0.82291667 | E21: 3727 | F21: 55905 | G21: 15 | I21: 1578 | J21: 20832 | K21: 13.201521 | M21: CLOSED | N21: CLOSED | O21: CLOSED | Q21: =E21+I21 -> 5305 | R21: =F21+J21 -> 76737
A22: 40181 | B22: =A22 -> 40181 | C22: -1.2 | D22: 0.85347222 | E22: CLOSED | F22: CLOSED | G22: CLOSED | I22: CLOSED | J22: CLOSED | K22: CLOSED | M22: CLOSED | N22: CLOSED | O22: CLOSED | Q22: 0 | R22: 0
A23: Tide Series Totals | E23: =SUM(E19:E22) -> 10051 | F23: =SUM(F19:F22) -> 90969.84 | G23: =F23/E23 -> 9.0508248 | H23: 121.3 | I23: =SUM(I19:I22) -> 4612 | J23: =SUM(J19:J22) -> 39807 | K23: =J23/I23 -> 8.6311795 | L23: 121.16 | M23: 502.52715 | N23: 1234.1634 | O23: 2.4559138 | P23: 100.56 | Q23: =SUM(Q19:Q22) -> 14663 | R23: =SUM(R19:R22) -> 130776.84
A24: 40206 | B24: 40206 | C24: -1.1 | D24: 0.71736111 | E24: CLOSED | F24: CLOSED | G24: CLOSED | I24: CLOSED | J24: CLOSED | K24: CLOSED | M24: CLOSED | N24: CLOSED | O24: CLOSED | Q24: 0 | R24: 0
A25: 40207 | B25: 40207 | C25: -1.5 | D25: 0.74861111 | E25: 3899 | F25: 55727 | G25: 14.292639 | I25: 1690 | J25: 20938 | K25: 12.389349 | M25: CLOSED | N25: CLOSED | O25: CLOSED | Q25: =E25+I25 -> 5589 | R25: =F25+J25 -> 76665
A26: 40208 | B26: 40208 | C26: -1.5 | D26: 0.77847222 | E26: 4402 | F26: 49673 | G26: 11.284189 | I26: 2584 | J26: 32381 | K26: 12.531347 | M26: 228.50498 | N26: 1075.0327 | O26: 4.7046358 | Q26: =E26+I26+M26 -> 7214.505 | R26: =F26+J26+N26 -> 83129.033
A27: 40209 | B27: 40209 | C27: -1.2 | D27: 0.80763889 | E27: 1568 | F27: 18018 | G27: 11.491071 | I27: 994.44801 | J27: 14916.72 | K27: 15 | M27: 111.64295 | N27: 1108.1596 | O27: 9.9259259 | Q27: =E27+I27+M27 -> 2674.091 | R27: =F27+J27+N27 -> 34042.88
A28: Tide Series Totals | E28: =SUM(E24:E27) -> 9869 | F28: =SUM(F24:F27) -> 123418 | G28: =F28/E28 -> 12.505624 | H28: 121.38 | I28: =SUM(I24:I27) -> 5268.448 | J28: =SUM(J24:J27) -> 68235.72 | K28: =J28/I28 -> 12.951769 | L28: 120.85 | M28: 340.14792 | N28: 2183.1923 | O28: 6.4183615 | P28: 102.41 | Q28: =SUM(Q24:Q27) -> 15477.596 | R28: =SUM(R24:R27) -> 193836.91
A29: 40235 | B29: 40235 | C29: -0.7 | D29: 0.70069444 | E29: 3187 | F29: 47579 | G29: 14.929087 | I29: 1560 | J29: 23400 | K29: 15 | M29: CLOSED | N29: CLOSED | O29: CLOSED | Q29: =E29+I29 -> 4747 | R29: =F29+J29 -> 70979
A30: 40236 | B30: 40236 | C30: -0.9 | D30: 0.73194444 | E30: 1500 | F30: 22000 | G30: 15 | I30: 550 | J30: 8000 | K30: 15 | M30: 129.00294 | N30: 338.78341 | O30: 2.6261682 | Q30: =E30+I30+M30 -> 2179.0029 | R30: =F30+J30+N30 -> 30338.783
A31: 40237 | B31: 40237 | C31: -0.8 | D31: 0.76111111 | E31: 5079 | F31: 75395 | G31: 14.844458 | I31: 1843 | J31: 27069 | K31: 14.687466 | M31: 165.42407 | N31: 2373.1992 | O31: 14.346154 | Q31: =E31+I31+M31 -> 7087.4241 | R31: =F31+J31+N31 -> 104837.2
A32: 40238 | B32: 40238 | C32: -0.4 | D32: 0.78888889 | E32: CLOSED | F32: CLOSED | G32: CLOSED | I32: CLOSED | J32: CLOSED | K32: CLOSED | M32: CLOSED | N32: CLOSED | O32: CLOSED | Q32: 0 | R32: 0
A33: Tide Series Totals | E33: =SUM(E29:E32) -> 9766 | F33: =SUM(F29:F32) -> 144974 | G33: =F33/E33 -> 14.844768 | H33: 122.26 | I33: =SUM(I29:I32) -> 3953 | J33: =SUM(J29:J32) -> 58469 | K33: =J33/I33 -> 14.791045 | L33: 119.11 | M33: 294.42701 | N33: 2711.9826 | O33: 9.2110524 | P33: 104.02 | Q33: =SUM(Q29:Q32) -> 14013.427 | R33: =SUM(R29:R32) -> 206154.98
A34: 40263 | B34: 40263 | C34: 0.1 | D34: 0.68680556 | E34: CLOSED | F34: CLOSED | G34: CLOSED | I34: CLOSED | J34: CLOSED | K34: CLOSED | M34: 238.93626 | N34: 2835.6659 | O34: 11.867876 | Q34: =M34 -> 238.93626 | R34: =N34 -> 2835.6659
A35: 40264 | B35: 40264 | C35: -0.1 | D35: 0.72152778 | E35: 6205 | F35: 85952 | G35: 13.852055 | I35: 4730 | J35: 66540 | K35: 14.067653 | M35: 513.85641 | N35: 6094.241 | O35: 11.859813 | Q35: =E35+I35+M35 -> 11448.856 | R35: =F35+J35+N35 -> 158586.24
A36: 40265 | B36: 40265 | C36: 0 | D36: 0.75277778 | E36: 3097 | F36: 13071 | G36: 4.220536 | I36: 1516 | J36: 11425 | K36: 7.5362797 | M36: CLOSED | N36: CLOSED | O36: CLOSED | Q36: =E36+I36 -> 4613 | R36: =F36+J36 -> 24496
A37: Tide Series Totals | E37: =SUM(E35:E36) -> 9302 | F37: =SUM(F35:F36) -> 99023 | G37: =F37/E37 -> 10.645345 | H37: 125.7 | I37: =SUM(I35:I36) -> 6246 | J37: =SUM(J35:J36) -> 77965 | K37: =J37/I37 -> 12.482389 | L37: 127.27 | M37: =SUM(M34:M36) -> 752.79267 | N37: =SUM(N34:N36) -> 8929.9069 | O37: =N37/M37 -> 11.862372 | P37: 106.98 | Q37: =SUM(Q34:Q36) -> 16300.793 | R37: =SUM(R34:R36) -> 185917.91
A38: 40285 | B38: 40264 | C38: -0.7 | D38: 0.38333333 | E38: CLOSED | F38: CLOSED | G38: CLOSED | I38: CLOSED | J38: CLOSED | K38: CLOSED | M38: 590 | N38: 4604 | O38: 7.8 | Q38: =M38 -> 590 | R38: =N38 -> 4604
A39: 40286 | B39: 40265 | C39: -0.6 | D39: 0.41527778 | E39: CLOSED | F39: CLOSED | G39: CLOSED | I39: CLOSED | J39: CLOSED | K39: CLOSED | M39: 639 | N39: 7993 | O39: 12.5 | Q39: =M39 -> 639 | R39: =N39 -> 7993
A40: Tide Series Totals | E40: =SUM(E38:E39) -> 0 | F40: =SUM(F38:F39) -> 0 | G40: =F40/E40 -> #DIV/0! | H40: 125.7 | I40: =SUM(I38:I39) -> 0 | J40: =SUM(J38:J39) -> 0 | K40: =J40/I40 -> #DIV/0! | L40: 127.27 | M40: =SUM(M38:M39) -> 1229 | N40: =SUM(N38:N39) -> 12597 | O40: =N40/M40 -> 10.249797 | P40: 106.7 | Q40: =SUM(Q37:Q39) -> 17529.793 | R40: =SUM(R37:R39) -> 198514.91
...

Sheet TH Wastage
B2: Total Harvest | C2: Wastage% | D2: Clams Wasted | H2: EventID | I2: LocationID | J2: SumOfNHoles | K2: SumOfNClams | L2: SumOfNMorts | M2: Avg. Wastage | N2: =+(L5+L10)/(J5+J10) -> 0.034
A3: 40131 | B3: 24308 | C3: 0.04 | D3: =B3*C3 -> 972.32 | H3: 252 | I3: 21200 | J3: 100 | K3: 2 | L3: 2 | N3: =+L5/J5 -> 0.02
A4: 40132 | B4: 6430 | C4: 0 | D4: =B4*C4 -> 0 | H4: 252 | I4: 22307 | J4: 100 | K4: 3 | L4: 2
A5: 40133 | B5: 650.90338 | C5: 0 | D5: =B5*C5 -> 0 | J5: =SUM(J3:J4) -> 200 | K5: =SUM(K3:K4) -> 5 | L5: =SUM(L3:L4) -> 4
A6: 40134 | B6: 2901 | C6: 0 | D6: =B6*C6 -> 0
D7: =SUM(D3:D6) -> 972.32 | H7: 254 | I7: 21200 | J7: 100 | K7: 6 | L7: 5 | N7: =+L10/J10 -> 0.043333333
H8: 254 | I8: 22307 | J8: 100 | K8: 5 | L8: 5
A9: 40284 | B9: 26202 | C9: 0.02 | D9: =B9*C9 -> 524.04 | H9: 254 | I9: 22309 | J9: 100 | K9: 3 | L9: 3
A10: 40285 | B10: 75878 | C10: 0.034 | D10: =B10*C10 -> 2579.852 | J10: =SUM(J7:J9) -> 300 | K10: =SUM(K7:K9) -> 14 | L10: =SUM(L7:L9) -> 13
A11: 40286 | B11: 79617 | C11: 0.043333333 | D11: =B11*C11 -> 3450.07
D12: =SUM(D9:D11) -> 6553.962
H13: EventID | I13: BeachName | J13: Date | K13: LocationID | L13: NHoles | M13: NClams | N13: NMorts
A14: 40295 | B14: 10068 | C14: 0.042 | D14: =B14*C14 -> 422.856 | H14: 263 | I14: Twin Harbors | J14: 40296 | K14: 21200 | L14: 100 | M14: 3 | N14: 3 | O14: =N14/L14 -> 0.03
A15: 40296 | B15: 17070 | C15: 0.03 | D15: =B15*C15 -> 512.1
A16: 40297 | B16: 13080 | C16: 0.045 | D16: =B16*C16 -> 588.6 | H16: 264 | I16: Twin Harbors | J16: 40297 | K16: 21200 | L16: 100 | M16: 10 | N16: 8
A17: 40298 | B17: 14925 | C17: 0.042 | D17: =B17*C17 -> 626.85 | H17: 264 | I17: Twin Harbors | J17: 40297 | K17: 22307 | L17: 100 | M17: 1 | N17: 1
A18: 40299 | B18: 34517 | C18: 0.045 | D18: =B18*C18 -> 1553.265 | L18: =SUM(L16:L17) -> 200 | M18: =SUM(M16:M17) -> 11 | N18: =SUM(N16:N17) -> 9 | O18: =N18/L18 -> 0.045
A19: 40300 | B19: 35344.283 | C19: 0.042 | D19: =B19*C19 -> 1484.4599
D20: =SUM(D14:D19) -> 5188.1309 | H20: 268 | I20: Twin Harbors | J20: 40299 | K20: 21200 | L20: 100 | M20: 6 | N20: 6
H21: 268 | I21: Twin Harbors | J21: 40299 | K21: 22307 | L21: 100 | M21: 4 | N21: 3
A22: Total wastage for season | D22: =D7+D12+D20+D28 -> 14161.228 | L22: =SUM(L20:L21) -> 200 | M22: =SUM(M20:M21) -> 10 | N22: =SUM(N20:N21) -> 9 | O22: =N22/L22 -> 0.045
D23: =SUM(B3,B9:B11,B14:B19,C26:C27) -> 331009.32 | E23: =D22/D23 -> 0.042781962
J24: AVG wastage for tide series | L24: =L22+L18+L14 -> 500 | M24: =M22+M18+M14 -> 24 | N24: =N22+N18+N14 -> 21 | O24: =N24/L24 -> 0.042
A26: 40313 | B26: 30040.777 | C26: 0.02 | D26: =B26*C26 -> 600.81554
A27: 40314 | B27: 42300 | C27: 0.02 | D27: =B27*C27 -> 846 | H27: EventID | I27: BeachName | J27: Date | K27: LocationID | L27: NHoles | M27: NClams | N27: NMorts
D28: =SUM(D26:D27) -> 1446.8155 | H28: 276 | I28: Twin Harbors | J28: 40314 | K28: 21200 | L28: 100 | M28: 2 | N28: 2 | O28: =N28/L28 -> 0.02

Sheet LB Wastage
B1: Total Harvest | C1: Wastage% | D1: Clams Wasted | G1: EventID | H1: BeachName | I1: Date | J1: LocationID | K1: NHoles | L1: NClams | M1: NMorts
A2: 40284 | B2: 49598 | C2: 0.05 | D2: =B2*C2 -> 2479.9 | G2: 267 | H2: LongBeach | I2: 40298 | J2: 12400 | K2: 100 | L2: 0 | M2: 0
A3: 40285 | B3: 106682 | C3: 0.065 | D3: =B3*C3 -> 6934.33 | G3: 267 | H3: LongBeach | I3: 40298 | J3: 12500 | K3: 100 | L3: 3 | M3: 3
A4: 40286 | B4: 92567 | C4: 0.08 | D4: =B4*C4 -> 7405.36 | G4: 267 | H4: LongBeach | I4: 40298 | J4: 12600 | K4: 100 | L4: 0 | M4: 0
B5: =SUM(B2:B4) -> 248847 | D5: =SUM(D2:D4) -> 16819.59 | K5: =SUM(K2:K4) -> 300 | L5: =SUM(L2:L4) -> 3 | M5: =SUM(M2:M4) -> 3 | N5: =M5/K5 -> 0.01
A8: 40295 | B8: 10575 | C8: 0.01 | D8: =B8*C8 -> 105.75
A9: 40296 | B9: 19638 | C9: 0.01 | D9: =B9*C9 -> 196.38
A10: 40297 | B10: 32732 | C10: 0.01 | D10: =B10*C10 -> 327.32
A11: 40298 | B11: 47910 | C11: 0.01 | D11: =B11*C11 -> 479.1
A12: 40299 | B12: 84345 | C12: 0.01 | D12: =B12*C12 -> 843.45
A13: 40300 | B13: 94080 | C13: 0.01 | D13: =B13*C13 -> 940.8
B14: =SUM(B8:B13) -> 289280 | C14: 0.01 | D14: =B14*C14 -> 2892.8
B17: =B5+B14 -> 538127 | C17: =D5+D14 -> 19712.39 | D17: =C17/B17 -> 0.036631483

Sheet Cop Wastage
A2: 40298 | B2: 28915 | C2: 0.03 | D2: =B2*C2 -> 867.45 | H2: EventID | I2: Date | J2: LocationID | K2: NHoles | L2: NClams | M2: NMorts | N2: % Wastage
A3: 40299 | B3: 76770 | C3: 0.017391304 | D3: =B3*C3 -> 1335.1304 | H3: 259 | I3: 40298 | J3: 33012 | K3: 100 | L3: 3 | M3: 3 | N3: =M3/K3 -> 0.03
