Workbook

Sheet Harvest
A1: Date | B1: Day | C1: Tide | D1: Time | E1: Longbeach | G1: Twin Harbors | I1: Copalis | K1: Mocrocks | M1: Kalaloch | O1: Daily Totals
A2: 40458 | B2: =+A2 -> 40458 | C2: -1 | D2: 0.78819444 | F2: CLOSED | H2: 40766 | J2: CLOSED | L2: CLOSED | N2: CLOSED | O2: =+H2 -> 40766
A3: 40459 | B3: =+A3 -> 40459 | C3: -1.4 | D3: 0.82083333 | F3: 56759 | H3: 26842 | J3: 59524 | L3: 29166 | N3: 3363.3312 | O3: =+F3+H3+J3+L3+N3 -> 175654.33
A4: 40460 | B4: =+A4 -> 40460 | C4: -1.5 | D4: 0.85277778 | E4: * | F4: =+(J4+L4)*F3/(J3+L3) -> 13173.157 | G4: * | H4: =+(J4+L4)*H3/(J3+L3) -> 6229.741 | J4: 12380 | L4: 8204 | N4: 1551.3522 | O4: =+F4+H4+J4+L4+N4 -> 41538.25
A5: 40461 | B5: =+A5 -> 40461 | C5: -1.3 | D5: 0.88541667 | F5: CLOSED | H5: 10719 | J5: CLOSED | L5: CLOSED | N5: CLOSED | O5: =+H5 -> 10719
A7: 40487 | B7: =+A7 -> 40487 | C7: -1.4 | D7: 0.77847222 | F7: 37260 | G7: * | H7: =(J7+L7)*H8/(J8+L8) -> 12577.853 | J7: 56503 | L7: 30058 | N7: 4249.9857 | O7: =+F7+H7+J7+L7+N7 -> 140648.84
A8: 40488 | B8: =+A8 -> 40488 | C8: -1.6 | D8: 0.80972222 | E8: * | F8: =(J8+L8)*F7/(J7+L7) -> 23852.84 | H8: 8052 | J8: 41437 | L8: 13977 | N8: 524.96226 | O8: =+F8+H8+J8+L8+N8 -> 87843.802
A9: 40489 | B9: =+A9 -> 40489 | C9: -1.5 | D9: 0.79930556 | F9: CLOSED | H9: 12021 | J9: CLOSED | L9: CLOSED | N9: CLOSED | O9: =+H9 -> 12021
A10: 40490 | B10: =+A10 -> 40490 | C10: -1.2 | D10: 0.82986111 | F10: CLOSED | H10: 5728 | J10: CLOSED | L10: CLOSED | N10: CLOSED | O10: =+H10 -> 5728
A12: 40502 | B12: =+A12 -> 40502 | C12: -0.4 | D12: 0.73541667 | F12: 28648 | H12: 22251 | J12: CLOSED | L12: CLOSED | N12: CLOSED | O12: =+F12+H12 -> 50899
A13: 40503 | B13: =+A13 -> 40503 | C13: -0.7 | D13: 0.76180556 | F13: 10620 | H13: 5625 | J13: CLOSED | L13: CLOSED | N13: CLOSED | O13: =+F13+H13 -> 16245
A15: 40515 | B15: =+A15 -> 40515 | C15: -0.8 | D15: 0.69652778 | F15: CLOSED | H15: 18750 | J15: CLOSED | L15: CLOSED | N15: CLOSED | O15: =+H15 -> 18750
A16: 40516 | B16: =+A16 -> 40516 | C16: -1.2 | D16: 0.72847222 | F16: 32130 | H16: 28935 | J16: 66481 | L16: 22553 | N16: 2162.5895 | O16: =+F16+H16+J16+L16+N16 -> 152261.59
A17: 40517 | B17: =+A17 -> 40517 | C17: -1.3 | D17: 0.75972222 | F17: 15360 | G17: * | H17: =+(J17+L17)*H16/(J16+L16) -> 11507.832 | J17: 25368 | L17: 10042 | N17: 1042.6654 | O17: =+F17+H17+J17+L17+N17 -> 63320.498
A18: 40518 | B18: =+A18 -> 40518 | C18: -1.2 | D18: 0.78888889 | F18: CLOSED | H18: 5430 | J18: CLOSED | L18: CLOSED | N18: CLOSED | O18: =+H18 -> 5430
A20: 40543 | B20: =+A20 -> 40543 | C20: 0 | D20: 0.65277778 | F20: 68435 | G20: * | H20: =+(J20+L20)*H16/(J16+L16) -> 60964.538 | J20: 127837 | L20: 59753 | N20: 2567.3764 | O20: =+F20+H20+J20+L20+N20 -> 319556.91
A21: 40544 | B21: =+A21 -> 40544 | C21: -0.4 | D21: 0.68888889 | F21: 65284 | G21: * | H21: =+(J21+L21)*H16/(J16+L16) -> 43550.045 | J21: 61643 | L21: 72362 | N21: 543.07584 | O21: =+F21+H21+J21+L21+N21 -> 243382.12
A22: 40545 | B22: =+A22 -> 40545 | C22: -0.7 | D22: 0.72083333 | F22: CLOSED | H22: 9395 | J22: CLOSED | L22: CLOSED | N22: CLOSED | O22: =+H22 -> 9395
A24: 40563 | B24: =+A24 -> 40563 | C24: -1.3 | D24: 0.79097222 | F24: 3652 | H24: 738 | J24: CLOSED | L24: CLOSED | N24: CLOSED | O24: =+F24+H24 -> 4390
A25: 40564 | B25: =+A25 -> 40564 | C25: -1.1 | D25: 0.81805556 | F25: 7684 | H25: 1922.9378 | J25: CLOSED | L25: CLOSED | N25: 123.7801 | O25: =+F25+H25+N25 -> 9730.7178
A26: 40565 | B26: =+A26 -> 40565 | C26: -0.6 | D26: 0.84652778 | F26: 27187 | H26: 13550 | J26: CLOSED | L26: CLOSED | N26: 298.63725 | O26: =+F26+H26+N26 -> 41035.637
A28: 40591 | B28: =+A28 -> 40591 | C28: -0.9 | D28: 0.74513889 | F28: CLOSED | H28: 23720 | J28: CLOSED | L28: CLOSED | N28: CLOSED | O28: =+H28 -> 23720
A29: 40592 | B29: =+A29 -> 40592 | C29: -0.9 | D29: 0.77291667 | F29: 29901 | G29: * | H29: =+(J29+L29)*(H16+H8)/(J8+L8+J16+L16) -> 26271.248 | J29: 81453 | L29: 21146 | N29: 204.48825 | O29: =+F29+H29+J29+L29+N29 -> 158975.74
A30: 40593 | B30: =+A30 -> 40593 | C30: -0.5 | D30: 0.80069444 | F30: 61662 | G30: * | H30: =+(J30+L30)*(H16+H8)/(J8+L8+J16+L16) -> 32891.872 | J30: 83649 | L30: 44806 | N30: 304.88973 | O30: =+F30+H30+J30+L30+N30 -> 223313.76
A32: 40621 | B32: =+A32 -> 40621 | C32: -0.1 | D32: 0.79444444 | F32: 57414 | H32: 12212 | J32: 50610 | L32: 50640 | N32: CLOSED | O32: =+F32+H32+J32+L32 -> 170876
A33: 40622 | B33: =+A33 -> 40622 | C33: -0.5 | D33: 0.31666667 | F33: 43099 | H33: 20431 | J33: 79431 | L33: 26959 | N33: CLOSED | O33: =+F33+H33+J33+L33 -> 169920
A34: 40623 | B34: =+A34 -> 40623 | C34: -0.9 | D34: 0.34930556 | F34: 35088 | H34: 9299 | J34: CLOSED | L34: CLOSED | N34: CLOSED | O34: =+F34+H34 -> 44387
A35: 40624 | B35: =+A35 -> 40624 | C35: -1 | D35: 0.38333333 | F35: 25950 | H35: 9450 | J35: CLOSED | L35: CLOSED | N35: CLOSED | O35: =+F35+H35 -> 35400
A37: 40640 | B37: =+A37 -> 40640 | C37: 0.1 | D37: 0.40069444 | F37: 30618 | H37: 23027 | J37: CLOSED | L37: CLOSED | N37: CLOSED | O37: =+F37+H37 -> 53645
A38: 40641 | B38: =+A38 -> 40641 | C38: 0.2 | D38: 0.42986111 | F38: 48762 | H38: 27976 | J38: CLOSED | L38: CLOSED | N38: CLOSED | O38: =+F38+H38 -> 76738
A39: 40642 | B39: =+A39 -> 40642 | C39: 0.4 | D39: 0.46319444 | F39: 68684 | H39: 45169 | J39: CLOSED | L39: CLOSED | N39: CLOSED | O39: =+F39+H39 -> 113853
A41: 40652 | B41: =+A41 -> 40652 | C41: -1.8 | D41: 0.33819444 | F41: 29264 | H41: 21525 | J41: CLOSED | L41: CLOSED | N41: CLOSED | O41: =+F41+H41 -> 50789
A42: 40653 | B42: =+A42 -> 40653 | C42: -1.7 | D42: 0.37083333 | F42: 35981 | H42: 15315 | J42: CLOSED | L42: CLOSED | N42: CLOSED | O42: =+F42+H42 -> 51296
A43: 40654 | B43: =+A43 -> 40654 | C43: -1.4 | D43: 0.40486111 | F43: 31425 | H43: 14745 | J43: 45645 | L43: 20657 | N43: CLOSED | O43: =+F43+H43+J43+L43 -> 112472
A44: 40655 | B44: =+A44 -> 40655 | C44: -0.8 | D44: 0.43958333 | F44: 32445 | G44: * | H44: =(+J44+L44)*(H43+H45)/(J43+L43+J45+L45) -> 15359.578 | J44: 52168 | L44: 28547 | N44: CLOSED | O44: =+F44+H44+J44+L44 -> 128519.58
A45: 40656 | B45: =+A45 -> 40656 | C45: -0.2 | D45: 0.47708333 | F45: 45480 | H45: 27474 | J45: 106039 | L45: 49521 | N45: CLOSED | O45: =+F45+H45+J45+L45 -> 228514
A47: 40666 | B47: =+A47 -> 40666 | C47: -0.6 | D47: 0.31180556 | F47: 5265 | H47: 4380 | J47: CLOSED | L47: CLOSED | N47: CLOSED | O47: =+F47+H47 -> 9645
A48: 40667 | B48: =+A48 -> 40667 | C48: -0.8 | D48: 0.33611111 | F48: 12630 | H48: 6735 | J48: CLOSED | L48: CLOSED | N48: CLOSED | O48: =+F48+H48 -> 19365
A49: 40668 | B49: =+A49 -> 40668 | C49: -0.8 | D49: 0.36111111 | F49: 14310 | H49: 6840 | J49: CLOSED | L49: CLOSED | N49: CLOSED | O49: =+F49+H49 -> 21150
A50: 40669 | B50: =+A50 -> 40669 | C50: -0.8 | D50: 0.3875 | F50: 24270 | H50: 14070 | J50: CLOSED | L50: CLOSED | N50: CLOSED | O50: =+F50+H50 -> 38340
...

Sheet CPUE
A1: Date | B1: Day | C1: Tide | D1: Time | E1: Longbeach | G1: Twin Harbors | I1: Copalis | K1: Mocrocks | M1: Kalaloch | O1: Daily Totals
A2: 40458 | B2: =+A2 -> 40458 | C2: -1 | D2: 0.78819444 | F2: CLOSED | H2: =+Harvest!H2/Effort!H2 -> 14.648221 | J2: CLOSED | L2: CLOSED | N2: CLOSED | O2: =Harvest!O2/Effort!O2 -> 14.648221
A3: 40459 | B3: =+A3 -> 40459 | C3: -1.4 | D3: 0.82083333 | F3: =+Harvest!F3/Effort!F3 -> 15.035497 | H3: =+Harvest!H3/Effort!H3 -> 14.75646 | J3: =+Harvest!J3/Effort!J3 -> 14.918296 | L3: =+Harvest!L3/Effort!L3 -> 14.410079 | N3: =+Harvest!N3/Effort!N3 -> 14.516129 | O3: =Harvest!O3/Effort!O3 -> 14.836051
A4: 40460 | B4: =+A4 -> 40460 | C4: -1.5 | D4: 0.85277778 | E4: * | F4: =+Harvest!F4/Effort!F4 -> 5.063045 | H4: =+Harvest!H4/Effort!H4 -> 4.9690822 | J4: =+Harvest!J4/Effort!J4 -> 5.0304754 | L4: =+Harvest!L4/Effort!L4 -> 4.871734 | N4: =+Harvest!N4/Effort!N4 -> 9.4444444 | O4: =Harvest!O4/Effort!O4 -> 5.0874877
A5: 40461 | B5: =+A5 -> 40461 | C5: -1.3 | D5: 0.88541667 | F5: CLOSED | H5: =+Harvest!H5/Effort!H5 -> 10.16019 | J5: CLOSED | L5: CLOSED | N5: CLOSED | O5: =Harvest!O5/Effort!O5 -> 10.16019
A7: 40487 | B7: =+A7 -> 40487 | C7: -1.4 | D7: 0.77847222 | F7: =+Harvest!F7/Effort!F7 -> 15 | H7: =+Harvest!H7/Effort!H7 -> 8.5405099 | J7: =+Harvest!J7/Effort!J7 -> 13.737661 | L7: =+Harvest!L7/Effort!L7 -> 15.549922 | N7: =+Harvest!N7/Effort!N7 -> 14.907407 | O7: =Harvest!O7/Effort!O7 -> 13.671393
A8: 40488 | B8: =+A8 -> 40488 | C8: -1.6 | D8: 0.80972222 | F8: =+Harvest!F8/Effort!F8 -> 11.19716 | H8: =+Harvest!H8/Effort!H8 -> 6.3752969 | J8: =+Harvest!J8/Effort!J8 -> 10.201132 | L8: =+Harvest!L8/Effort!L8 -> 12.446126 | N8: =+Harvest!N8/Effort!N8 -> 4.2238806 | O8: =Harvest!O8/Effort!O8 -> 10.094039
A9: 40489 | B9: =+A9 -> 40489 | C9: -1.5 | D9: 0.79930556 | F9: CLOSED | H9: =+Harvest!H9/Effort!H9 -> 13.598416 | J9: CLOSED | L9: CLOSED | N9: CLOSED | O9: =Harvest!O9/Effort!O9 -> 13.598416
A10: 40490 | B10: =+A10 -> 40490 | C10: -1.2 | D10: 0.82986111 | F10: CLOSED | H10: =+Harvest!H10/Effort!H10 -> 14.108374 | J10: CLOSED | L10: CLOSED | N10: CLOSED | O10: =Harvest!O10/Effort!O10 -> 14.108374
A12: 40502 | B12: =+A12 -> 40502 | C12: -0.4 | D12: 0.73541667 | F12: =+Harvest!F12/Effort!F12 -> 15.06204 | H12: =+Harvest!H12/Effort!H12 -> 14.658103 | J12: CLOSED | L12: CLOSED | N12: CLOSED | O12: =Harvest!O12/Effort!O12 -> 14.882749
A13: 40503 | B13: =+A13 -> 40503 | C13: -0.7 | D13: 0.76180556 | F13: =+Harvest!F13/Effort!F13 -> 15 | H13: =+Harvest!H13/Effort!H13 -> 15 | J13: CLOSED | L13: CLOSED | N13: CLOSED | O13: =Harvest!O13/Effort!O13 -> 15
A15: 40515 | B15: =+A15 -> 40515 | C15: -0.8 | D15: 0.69652778 | F15: CLOSED | H15: =+Harvest!H15/Effort!H15 -> 15 | J15: CLOSED | L15: CLOSED | N15: CLOSED | O15: =Harvest!O15/Effort!O15 -> 15
A16: 40516 | B16: =+A16 -> 40516 | C16: -1.2 | D16: 0.72847222 | F16: =+Harvest!F16/Effort!F16 -> 15 | H16: =+Harvest!H16/Effort!H16 -> 15 | J16: =+Harvest!J16/Effort!J16 -> 15.000226 | L16: =+Harvest!L16/Effort!L16 -> 14.995346 | N16: =+Harvest!N16/Effort!N16 -> 11.638298 | O16: =Harvest!O16/Effort!O16 -> 14.938127
A17: 40517 | B17: =+A17 -> 40517 | C17: -1.3 | D17: 0.75972222 | F17: =+Harvest!F17/Effort!F17 -> 15 | G17: * | H17: =+Harvest!H17/Effort!H17 -> 15.005248 | J17: =+Harvest!J17/Effort!J17 -> 15.001774 | L17: =+Harvest!L17/Effort!L17 -> 15.010463 | N17: =+Harvest!N17/Effort!N17 -> 10.875 | O17: =Harvest!O17/Effort!O17 -> 14.910175
A18: 40518 | B18: =+A18 -> 40518 | C18: -1.2 | D18: 0.78888889 | F18: CLOSED | H18: =+Harvest!H18/Effort!H18 -> 15 | J18: CLOSED | L18: CLOSED | N18: CLOSED | O18: =Harvest!O18/Effort!O18 -> 15
A20: 40543 | B20: =+A20 -> 40543 | C20: 0 | D20: 0.65277778 | F20: =+Harvest!F20/Effort!F20 -> 12.841997 | H20: =+Harvest!H20/Effort!H20 -> 12.920292 | J20: =+Harvest!J20/Effort!J20 -> 12.263718 | L20: =+Harvest!L20/Effort!L20 -> 14.588135 | N20: =+Harvest!N20/Effort!N20 -> 6.7575758 | O20: =Harvest!O20/Effort!O20 -> 12.809208
A21: 40544 | B21: =+A21 -> 40544 | C21: -0.4 | D21: 0.68888889 | F21: =+Harvest!F21/Effort!F21 -> 12.047241 | H21: =+Harvest!H21/Effort!H21 -> 12.129064 | J21: =+Harvest!J21/Effort!J21 -> 10.633604 | L21: =+Harvest!L21/Effort!L21 -> 13.777989 | N21: =+Harvest!N21/Effort!N21 -> 1.4 | O21: =Harvest!O21/Effort!O21 -> 11.903384
A22: 40545 | B22: =+A22 -> 40545 | C22: -0.7 | D22: 0.72083333 | F22: CLOSED | H22: =+Harvest!H22/Effort!H22 -> 7.1390578 | J22: CLOSED | L22: CLOSED | N22: CLOSED | O22: =Harvest!O22/Effort!O22 -> 7.1390578
A24: 40563 | B24: =+A24 -> 40563 | C24: -1.3 | D24: 0.79097222 | F24: =+Harvest!F24/Effort!F24 -> 4.5030826 | H24: =+Harvest!H24/Effort!H24 -> 1.3202147 | J24: CLOSED | L24: CLOSED | N24: CLOSED | O24: =Harvest!O24/Effort!O24 -> 3.2043796
A25: 40564 | B25: =+A25 -> 40564 | C25: -1.1 | D25: 0.81805556 | F25: =+Harvest!F25/Effort!F25 -> 7.6230159 | H25: =+Harvest!H25/Effort!H25 -> 3.0338983 | J25: CLOSED | L25: CLOSED | N25: =+Harvest!N25/Effort!N25 -> 0.90322581 | O25: =Harvest!O25/Effort!O25 -> 5.9267964
A26: 40565 | B26: =+A26 -> 40565 | C26: -0.6 | D26: 0.84652778 | F26: =+Harvest!F26/Effort!F26 -> 12.983286 | H26: =+Harvest!H26/Effort!H26 -> 7.0207254 | J26: CLOSED | L26: CLOSED | N26: =+Harvest!N26/Effort!N26 -> 1.5 | O26: =Harvest!O26/Effort!O26 -> 10.197723
A28: 40591 | B28: =+A28 -> 40591 | C28: -0.9 | D28: 0.74513889 | F28: CLOSED | H28: =+Harvest!H28/Effort!H28 -> 14.085511 | J28: CLOSED | L28: CLOSED | N28: CLOSED | O28: =Harvest!O28/Effort!O28 -> 14.085511
A29: 40592 | B29: =+A29 -> 40592 | C29: -0.9 | D29: 0.77291667 | F29: =+Harvest!F29/Effort!F29 -> 14.368573 | G29: * | H29: =+Harvest!H29/Effort!H29 -> 12.726588 | J29: =+Harvest!J29/Effort!J29 -> 15.000552 | L29: =+Harvest!L29/Effort!L29 -> 12.001135 | N29: =+Harvest!N29/Effort!N29 -> 1.7857143 | O29: =Harvest!O29/Effort!O29 -> 13.882169
A30: 40593 | B30: =+A30 -> 40593 | C30: -0.5 | D30: 0.80069444 | F30: =+Harvest!F30/Effort!F30 -> 14.386841 | G30: * | H30: =+Harvest!H30/Effort!H30 -> 12.058931 | J30: =+Harvest!J30/Effort!J30 -> 13.441909 | L30: =+Harvest!L30/Effort!L30 -> 13.660366 | N30: =+Harvest!N30/Effort!N30 -> 2.0571429 | O30: =Harvest!O30/Effort!O30 -> 13.400323
A32: 40621 | B32: =+A32 -> 40621 | C32: -0.1 | D32: 0.79444444 | F32: =+Harvest!F32/Effort!F32 -> 10.950601 | H32: =+Harvest!H32/Effort!H32 -> 5.4860737 | J32: =+Harvest!J32/Effort!J32 -> 12.395298 | L32: =+Harvest!L32/Effort!L32 -> 10.984816 | N32: CLOSED | O32: =Harvest!O32/Effort!O32 -> 10.572701
A33: 40622 | B33: =+A33 -> 40622 | C33: -0.5 | D33: 0.31666667 | F33: =+Harvest!F33/Effort!F33 -> 14.624703 | H33: =+Harvest!H33/Effort!H33 -> 14.03228 | J33: =+Harvest!J33/Effort!J33 -> 14.327381 | L33: =+Harvest!L33/Effort!L33 -> 14.910951 | N33: CLOSED | O33: =Harvest!O33/Effort!O33 -> 14.455125
A34: 40623 | B34: =+A34 -> 40623 | C34: -0.9 | D34: 0.34930556 | F34: =+Harvest!F34/Effort!F34 -> 13.500577 | H34: =+Harvest!H34/Effort!H34 -> 7.5663141 | J34: CLOSED | L34: CLOSED | N34: CLOSED | O34: =Harvest!O34/Effort!O34 -> 11.59535
A35: 40624 | B35: =+A35 -> 40624 | C35: -1 | D35: 0.38333333 | F35: =+Harvest!F35/Effort!F35 -> 15 | H35: =+Harvest!H35/Effort!H35 -> 13.034483 | J35: CLOSED | L35: CLOSED | N35: CLOSED | O35: =Harvest!O35/Effort!O35 -> 14.419552
A37: 40640 | B37: =+A37 -> 40640 | C37: 0.1 | D37: 0.40069444 | F37: =+Harvest!F37/Effort!F37 -> 12.15 | H37: =+Harvest!H37/Effort!H37 -> 13.846663 | J37: CLOSED | L37: CLOSED | N37: CLOSED | O37: =Harvest!O37/Effort!O37 -> 12.824528
A38: 40641 | B38: =+A38 -> 40641 | C38: 0.2 | D38: 0.42986111 | F38: =+Harvest!F38/Effort!F38 -> 11.632156 | H38: =+Harvest!H38/Effort!H38 -> 8 | J38: CLOSED | L38: CLOSED | N38: CLOSED | O38: =Harvest!O38/Effort!O38 -> 9.9802315
A39: 40642 | B39: =+A39 -> 40642 | C39: 0.4 | D39: 0.46319444 | F39: =+Harvest!F39/Effort!F39 -> 12.333273 | H39: =+Harvest!H39/Effort!H39 -> 10.894597 | J39: CLOSED | L39: CLOSED | N39: CLOSED | O39: =Harvest!O39/Effort!O39 -> 11.7193
A41: 40652 | B41: =+A41 -> 40652 | C41: -1.8 | D41: 0.33819444 | F41: =+Harvest!F41/Effort!F41 -> 15.053498 | H41: =+Harvest!H41/Effort!H41 -> 15 | J41: CLOSED | L41: CLOSED | N41: CLOSED | O41: =Harvest!O41/Effort!O41 -> 15.030778
A42: 40653 | B42: =+A42 -> 40653 | C42: -1.7 | D42: 0.37083333 | F42: =+Harvest!F42/Effort!F42 -> 14.9796 | H42: =+Harvest!H42/Effort!H42 -> 15 | J42: CLOSED | L42: CLOSED | N42: CLOSED | O42: =Harvest!O42/Effort!O42 -> 14.985685
A43: 40654 | B43: =+A43 -> 40654 | C43: -1.4 | D43: 0.40486111 | F43: =+Harvest!F43/Effort!F43 -> 15 | H43: =+Harvest!H43/Effort!H43 -> 15 | J43: =+Harvest!J43/Effort!J43 -> 15.029635 | L43: =+Harvest!L43/Effort!L43 -> 15.001452 | N43: CLOSED | O43: =Harvest!O43/Effort!O43 -> 15.01228
A44: 40655 | B44: =+A44 -> 40655 | C44: -0.8 | D44: 0.43958333 | F44: =+Harvest!F44/Effort!F44 -> 15 | G44: * | H44: =+Harvest!H44/Effort!H44 -> 14.533134 | J44: =+Harvest!J44/Effort!J44 -> 14.52743 | L44: =+Harvest!L44/Effort!L44 -> 15.001051 | N44: CLOSED | O44: =Harvest!O44/Effort!O44 -> 14.748858
A45: 40656 | B45: =+A45 -> 40656 | C45: -0.2 | D45: 0.47708333 | F45: =+Harvest!F45/Effort!F45 -> 15 | H45: =+Harvest!H45/Effort!H45 -> 14.691979 | J45: =+Harvest!J45/Effort!J45 -> 14.897303 | L45: =+Harvest!L45/Effort!L45 -> 15.010912 | N45: CLOSED | O45: =Harvest!O45/Effort!O45 -> 14.917031
A47: 40666 | B47: =+A47 -> 40666 | C47: -0.6 | D47: 0.31180556 | F47: =+Harvest!F47/Effort!F47 -> 15 | H47: =+Harvest!H47/Effort!H47 -> 15 | J47: CLOSED | L47: CLOSED | N47: CLOSED | O47: =Harvest!O47/Effort!O47 -> 15
A48: 40667 | B48: =+A48 -> 40667 | C48: -0.8 | D48: 0.33611111 | F48: =+Harvest!F48/Effort!F48 -> 15 | H48: =+Harvest!H48/Effort!H48 -> 15 | J48: CLOSED | L48: CLOSED | N48: CLOSED | O48: =Harvest!O48/Effort!O48 -> 15
A49: 40668 | B49: =+A49 -> 40668 | C49: -0.8 | D49: 0.36111111 | F49: =+Harvest!F49/Effort!F49 -> 15 | H49: =+Harvest!H49/Effort!H49 -> 15 | J49: CLOSED | L49: CLOSED | N49: CLOSED | O49: =Harvest!O49/Effort!O49 -> 15
A50: 40669 | B50: =+A50 -> 40669 | C50: -0.8 | D50: 0.3875 | F50: =+Harvest!F50/Effort!F50 -> 14.559088 | H50: =+Harvest!H50/Effort!H50 -> 15 | J50: CLOSED | L50: CLOSED | N50: CLOSED | O50: =Harvest!O50/Effort!O50 -> 14.71785
...

Sheet Effort
A1: Date | B1: Day | C1: Tide | D1: Time | E1: Longbeach | G1: Twin Harbors | I1: Copalis | K1: Mocrocks | M1: Kalaloch | O1: Daily Totals
A2: 40458 | B2: =+A2 -> 40458 | C2: -1 | D2: 0.78819444 | F2: CLOSED | H2: 2783 | J2: CLOSED | L2: CLOSED | N2: CLOSED | O2: =+H2 -> 2783
A3: 40459 | B3: =+A3 -> 40459 | C3: -1.4 | D3: 0.82083333 | F3: 3775 | H3: 1819 | J3: 3990 | L3: 2024 | N3: 231.69615 | O3: =+F3+H3+J3+L3+N3 -> 11839.696
A4: 40460 | B4: =+A4 -> 40460 | C4: -1.5 | D4: 0.85277778 | E4: * | F4: =+(J4+L4)*F3/(J3+L3) -> 2601.8249 | G4: * | H4: =+(J4+L4)*H3/(J3+L3) -> 1253.7005 | J4: 2461 | L4: 1684 | N4: 164.26083 | O4: =+F4+H4+J4+L4+N4 -> 8164.7863
A5: 40461 | B5: =+A5 -> 40461 | C5: -1.3 | D5: 0.88541667 | F5: CLOSED | H5: 1055 | J5: CLOSED | L5: CLOSED | N5: CLOSED | O5: =+H5 -> 1055
A7: 40487 | B7: =+A7 -> 40487 | C7: -1.4 | D7: 0.77847222 | F7: 2484 | G7: * | H7: =(J7+L7)*H8/(J8+L8) -> 1472.7286 | J7: 4113 | L7: 1933 | N7: 285.09221 | O7: =+F7+H7+J7+L7+N7 -> 10287.821
A8: 40488 | B8: =+A8 -> 40488 | C8: -1.6 | D8: 0.80972222 | E8: * | F8: =(J8+L8)*F7/(J7+L7) -> 2130.258 | H8: 1263 | J8: 4062 | L8: 1123 | N8: 124.28435 | O8: =+F8+H8+J8+L8+N8 -> 8702.5424
A9: 40489 | B9: =+A9 -> 40489 | C9: -1.5 | D9: 0.79930556 | F9: CLOSED | H9: 884 | J9: CLOSED | L9: CLOSED | N9: CLOSED | O9: =+H9 -> 884
A10: 40490 | B10: =+A10 -> 40490 | C10: -1.2 | D10: 0.82986111 | F10: CLOSED | H10: 406 | J10: CLOSED | L10: CLOSED | N10: CLOSED | O10: =+H10 -> 406
A12: 40502 | B12: =+A12 -> 40502 | C12: -0.4 | D12: 0.73541667 | F12: 1902 | H12: 1518 | J12: CLOSED | L12: CLOSED | N12: CLOSED | O12: =+F12+H12 -> 3420
A13: 40503 | B13: =+A13 -> 40503 | C13: -0.7 | D13: 0.76180556 | F13: 708 | H13: 375 | J13: CLOSED | L13: CLOSED | N13: CLOSED | O13: =+F13+H13 -> 1083
A15: 40515 | B15: =+A15 -> 40515 | C15: -0.8 | D15: 0.69652778 | F15: CLOSED | H15: 1250 | J15: CLOSED | L15: CLOSED | N15: CLOSED | O15: =+H15 -> 1250
A16: 40516 | B16: =+A16 -> 40516 | C16: -1.2 | D16: 0.72847222 | F16: 2142 | H16: 1929 | J16: 4432 | L16: 1504 | N16: 185.81665 | O16: =+F16+H16+J16+L16+N16 -> 10192.817
A17: 40517 | B17: =+A17 -> 40517 | C17: -1.3 | D17: 0.75972222 | F17: 1024 | G17: * | H17: =+(J17+L17)*H16/(J16+L16) -> 766.92049 | J17: 1691 | L17: 669 | N17: 95.877275 | O17: =+F17+H17+J17+L17+N17 -> 4246.7978
A18: 40518 | B18: =+A18 -> 40518 | C18: -1.2 | D18: 0.78888889 | F18: CLOSED | H18: 362 | J18: CLOSED | L18: CLOSED | N18: CLOSED | O18: =+H18 -> 362
A20: 40543 | B20: =+A20 -> 40543 | C20: 0 | D20: 0.65277778 | F20: 5329 | G20: * | H20: =+(J20+L20)*H16/(J16+L16) -> 4718.5108 | J20: 10424 | L20: 4096 | N20: 379.92566 | O20: =+F20+H20+J20+L20+N20 -> 24947.436
A21: 40544 | B21: =+A21 -> 40544 | C21: -0.4 | D21: 0.68888889 | F21: 5419 | G21: * | H21: =+(J21+L21)*H16/(J16+L16) -> 3590.5527 | J21: 5797 | L21: 5252 | N21: 387.91131 | O21: =+F21+H21+J21+L21+N21 -> 20446.464
A22: 40545 | B22: =+A22 -> 40545 | C22: -0.7 | D22: 0.72083333 | F22: CLOSED | H22: 1316 | J22: CLOSED | L22: CLOSED | N22: CLOSED | O22: =+H22 -> 1316
A24: 40563 | B24: =+A24 -> 40563 | C24: -1.3 | D24: 0.79097222 | F24: 811 | H24: 559 | J24: CLOSED | L24: CLOSED | N24: CLOSED | O24: =+F24+H24 -> 1370
A25: 40564 | B25: =+A25 -> 40564 | C25: -1.1 | D25: 0.81805556 | F25: 1008 | H25: 633.81747 | J25: CLOSED | L25: CLOSED | N25: 137.04225 | O25: =+F25+H25 -> 1641.8175
A26: 40565 | B26: =+A26 -> 40565 | C26: -0.6 | D26: 0.84652778 | F26: 2094 | H26: 1930 | J26: CLOSED | L26: CLOSED | N26: 199.0915 | O26: =+F26+H26 -> 4024
A28: 40591 | B28: =+A28 -> 40591 | C28: -0.9 | D28: 0.74513889 | F28: CLOSED | H28: 1684 | J28: CLOSED | L28: CLOSED | N28: CLOSED | O28: =+H28 -> 1684
A29: 40592 | B29: =+A29 -> 40592 | C29: -0.9 | D29: 0.77291667 | F29: 2081 | G29: * | H29: =+(J29+L29)*(H16+H8)/(J8+L8+J16+L16) -> 2064.2806 | J29: 5430 | L29: 1762 | N29: 114.51342 | O29: =+F29+H29+J29+L29+N29 -> 11451.794
A30: 40593 | B30: =+A30 -> 40593 | C30: -0.5 | D30: 0.80069444 | F30: 4286 | G30: * | H30: =+(J30+L30)*(H16+H8)/(J8+L8+J16+L16) -> 2727.5943 | J30: 6223 | L30: 3280 | N30: 148.21029 | O30: =+F30+H30+J30+L30+N30 -> 16664.805
A32: 40621 | B32: =+A32 -> 40621 | C32: -0.1 | D32: 0.79444444 | F32: 5243 | H32: 2226 | J32: 4083 | L32: 4610 | N32: CLOSED | O32: =+F32+H32+J32+L32 -> 16162
A33: 40622 | B33: =+A33 -> 40622 | C33: -0.5 | D33: 0.31666667 | F33: 2947 | H33: 1456 | J33: 5544 | L33: 1808 | N33: CLOSED | O33: =+F33+H33+J33+L33 -> 11755
A34: 40623 | B34: =+A34 -> 40623 | C34: -0.9 | D34: 0.34930556 | F34: 2599 | H34: 1229 | J34: CLOSED | L34: CLOSED | N34: CLOSED | O34: =+F34+H34 -> 3828
A35: 40624 | B35: =+A35 -> 40624 | C35: -1 | D35: 0.38333333 | F35: 1730 | H35: 725 | J35: CLOSED | L35: CLOSED | N35: CLOSED | O35: =+F35+H35 -> 2455
A37: 40640 | B37: =+A37 -> 40640 | C37: 0.1 | D37: 0.40069444 | F37: 2520 | H37: 1663 | J37: CLOSED | L37: CLOSED | N37: CLOSED | O37: =+F37+H37 -> 4183
A38: 40641 | B38: =+A38 -> 40641 | C38: 0.2 | D38: 0.42986111 | F38: 4192 | H38: 3497 | J38: CLOSED | L38: CLOSED | N38: CLOSED | O38: =+F38+H38 -> 7689
A39: 40642 | B39: =+A39 -> 40642 | C39: 0.4 | D39: 0.46319444 | F39: 5569 | H39: 4146 | J39: CLOSED | L39: CLOSED | N39: CLOSED | O39: =+F39+H39 -> 9715
A41: 40652 | B41: =+A41 -> 40652 | C41: -1.8 | D41: 0.33819444 | F41: 1944 | H41: 1435 | J41: CLOSED | L41: CLOSED | N41: CLOSED | O41: =+F41+H41 -> 3379
A42: 40653 | B42: =+A42 -> 40653 | C42: -1.7 | D42: 0.37083333 | F42: 2402 | H42: 1021 | J42: CLOSED | L42: CLOSED | N42: CLOSED | O42: =+F42+H42 -> 3423
A43: 40654 | B43: =+A43 -> 40654 | C43: -1.4 | D43: 0.40486111 | F43: 2095 | H43: 983 | J43: 3037 | L43: 1377 | N43: CLOSED | O43: =+F43+H43+J43+L43 -> 7492
A44: 40655 | B44: =+A44 -> 40655 | C44: -0.8 | D44: 0.43958333 | F44: 2163 | G44: * | H44: =(+J44+L44)*(H43+H45)/(J43+L43+J45+L45) -> 1056.8662 | J44: 3591 | L44: 1903 | N44: CLOSED | O44: =+F44+H44+J44+L44 -> 8713.8662
A45: 40656 | B45: =+A45 -> 40656 | C45: -0.2 | D45: 0.47708333 | F45: 3032 | H45: 1870 | J45: 7118 | L45: 3299 | N45: CLOSED | O45: =+F45+H45+J45+L45 -> 15319
A47: 40666 | B47: =+A47 -> 40666 | C47: -0.6 | D47: 0.31180556 | F47: 351 | H47: 292 | J47: CLOSED | L47: CLOSED | N47: CLOSED | O47: =+F47+H47 -> 643
A48: 40667 | B48: =+A48 -> 40667 | C48: -0.8 | D48: 0.33611111 | F48: 842 | H48: 449 | J48: CLOSED | L48: CLOSED | N48: CLOSED | O48: =+F48+H48 -> 1291
A49: 40668 | B49: =+A49 -> 40668 | C49: -0.8 | D49: 0.36111111 | F49: 954 | H49: 456 | J49: CLOSED | L49: CLOSED | N49: CLOSED | O49: =+F49+H49 -> 1410
A50: 40669 | B50: =+A50 -> 40669 | C50: -0.8 | D50: 0.3875 | F50: 1667 | H50: 938 | J50: CLOSED | L50: CLOSED | N50: CLOSED | O50: =+F50+H50 -> 2605
...

Sheet Summary Table
A1: 2010-2011 State (non-Indian) Recreational Razor Clam Effort, Harvest and CPUE totals.
E2: LONG BEACH | H2: TWIN HARBORS | K2: COPALIS | N2: MOCROCKS | Q2: KALALOCH | T2: DAILY TOTALS
A3: DATE | B3: DAY | C3: TIDE | D3: TIME | E3: Effort | F3: Harvest | G3: CPUE | H3: Effort | I3: Harvest | J3: CPUE | K3: Effort | L3: Harvest | M3: CPUE | N3: Effort | O3: Harvest | P3: CPUE | Q3: Effort | R3: Harvest | S3: CPUE | T3: Effort | U3: Harvest
A4: 40458 | B4: 40458 | C4: -1 | D4: 0.78819444 | E4: =Effort!F2 -> CLOSED | F4: =Harvest!F2 -> CLOSED | G4: =CPUE!F2 -> CLOSED | H4: =Effort!H2 -> 2783 | I4: =Harvest!H2 -> 40766 | J4: =CPUE!H2 -> 14.648221 | K4: =Effort!J2 -> CLOSED | L4: =Harvest!J2 -> CLOSED | M4: =CPUE!J2 -> CLOSED | N4: =Effort!L2 -> CLOSED | O4: =Harvest!L2 -> CLOSED | P4: =CPUE!L2 -> CLOSED | Q4: =Effort!N2 -> CLOSED | R4: =Harvest!N2 -> CLOSED | S4: =CPUE!N2 -> CLOSED | T4: =+H4 -> 2783 | U4: =+I4 -> 40766
A5: 40459 | B5: 40459 | C5: -1.4 | D5: 0.82083333 | E5: =Effort!F3 -> 3775 | F5: =Harvest!F3 -> 56759 | G5: =CPUE!F3 -> 15.035497 | H5: =Effort!H3 -> 1819 | I5: =Harvest!H3 -> 26842 | J5: =CPUE!H3 -> 14.75646 | K5: =Effort!J3 -> 3990 | L5: =Harvest!J3 -> 59524 | M5: =CPUE!J3 -> 14.918296 | N5: =Effort!L3 -> 2024 | O5: =Harvest!L3 -> 29166 | P5: =CPUE!L3 -> 14.410079 | Q5: =Effort!N3 -> 231.69615 | R5: =Harvest!N3 -> 3363.3312 | S5: =CPUE!N3 -> 14.516129 | T5: =E5+H5+K5+N5+Q5 -> 11839.696 | U5: =F5+I5+L5+O5+R5 -> 175654.33
A6: 40460 | B6: 40460 | C6: -1.5 | D6: 0.85277778 | E6: =Effort!F4 -> 2601.8249 | F6: =Harvest!F4 -> 13173.157 | G6: =CPUE!F4 -> 5.063045 | H6: =Effort!H4 -> 1253.7005 | I6: =Harvest!H4 -> 6229.741 | J6: =CPUE!H4 -> 4.9690822 | K6: =Effort!J4 -> 2461 | L6: =Harvest!J4 -> 12380 | M6: =CPUE!J4 -> 5.0304754 | N6: =Effort!L4 -> 1684 | O6: =Harvest!L4 -> 8204 | P6: =CPUE!L4 -> 4.871734 | Q6: =Effort!N4 -> 164.26083 | R6: =Harvest!N4 -> 1551.3522 | S6: =CPUE!N4 -> 9.4444444 | T6: =E6+H6+K6+N6+Q6 -> 8164.7863 | U6: =F6+I6+L6+O6+R6 -> 41538.25
A7: 40461 | B7: 40461 | C7: -1.3 | D7: 0.88541667 | E7: =Effort!F5 -> CLOSED | F7: =Harvest!F5 -> CLOSED | G7: =CPUE!F5 -> CLOSED | H7: =Effort!H5 -> 1055 | I7: =Harvest!H5 -> 10719 | J7: =CPUE!H5 -> 10.16019 | K7: =Effort!J5 -> CLOSED | L7: =Harvest!J5 -> CLOSED | M7: =CPUE!J5 -> CLOSED | N7: =Effort!L5 -> CLOSED | O7: =Harvest!L5 -> CLOSED | P7: =CPUE!L5 -> CLOSED | Q7: =Effort!N5 -> CLOSED | R7: =Harvest!N5 -> CLOSED | S7: =CPUE!N5 -> CLOSED | T7: =+H7 -> 1055 | U7: =+I7 -> 10719
A8: Tide Series Totals | E8: =SUM(E4:E7) -> 6376.8249 | F8: =SUM(F4:F7) -> 69932.157 | G8: =F8/E8 -> 10.966611 | H8: =SUM(H4:H7) -> 6910.7005 | I8: =SUM(I4:I7) -> 84556.741 | J8: =I8/H8 -> 12.235625 | K8: =SUM(K4:K7) -> 6451 | L8: =SUM(L4:L7) -> 71904 | M8: =L8/K8 -> 11.146179 | N8: =SUM(N5:N7) -> 3708 | O8: =SUM(O5:O7) -> 37370 | P8: =O8/N8 -> 10.078209 | Q8: =SUM(Q5:Q7) -> 395.95698 | R8: =SUM(R5:R7) -> 4914.6835 | S8: =R8/Q8 -> 12.412165 | T8: =SUM(T4:T7) -> 23842.482 | U8: =SUM(U4:U7) -> 268677.58
A9: 40487 | B9: 40487 | C9: -1.4 | D9: 0.77847222 | E9: =Effort!F7 -> 2484 | F9: =Harvest!F7 -> 37260 | G9: =CPUE!F7 -> 15 | H9: =Effort!H7 -> 1472.7286 | I9: =Harvest!H7 -> 12577.853 | J9: =CPUE!H7 -> 8.5405099 | K9: =Effort!J7 -> 4113 | L9: =Harvest!J7 -> 56503 | M9: =CPUE!J7 -> 13.737661 | N9: =Effort!L7 -> 1933 | O9: =Harvest!L7 -> 30058 | P9: =CPUE!L7 -> 15.549922 | Q9: =Effort!N7 -> 285.09221 | R9: =Harvest!N7 -> 4249.9857 | S9: =CPUE!N7 -> 14.907407 | T9: =E9+H9+K9+N9+Q9 -> 10287.821 | U9: =F9+I9+L9+O9+R9 -> 140648.84
A10: 40488 | B10: 40488 | C10: -1.6 | D10: 0.80972222 | E10: =Effort!F8 -> 2130.258 | F10: =Harvest!F8 -> 23852.84 | G10: =CPUE!F8 -> 11.19716 | H10: =Effort!H8 -> 1263 | I10: =Harvest!H8 -> 8052 | J10: =CPUE!H8 -> 6.3752969 | K10: =Effort!J8 -> 4062 | L10: =Harvest!J8 -> 41437 | M10: =CPUE!J8 -> 10.201132 | N10: =Effort!L8 -> 1123 | O10: =Harvest!L8 -> 13977 | P10: =CPUE!L8 -> 12.446126 | Q10: =Effort!N8 -> 124.28435 | R10: =Harvest!N8 -> 524.96226 | S10: =CPUE!N8 -> 4.2238806 | T10: =E10+H10+K10+N10+Q10 -> 8702.5424 | U10: =F10+I10+L10+O10+R10 -> 87843.802
A11: 40489 | B11: 40489 | C11: -1.5 | D11: 0.79930556 | E11: =Effort!F9 -> CLOSED | F11: =Harvest!F9 -> CLOSED | G11: =CPUE!F9 -> CLOSED | H11: =Effort!H9 -> 884 | I11: =Harvest!H9 -> 12021 | J11: =CPUE!H9 -> 13.598416 | K11: =Effort!J9 -> CLOSED | L11: =Harvest!J9 -> CLOSED | M11: =CPUE!J9 -> CLOSED | N11: =Effort!L9 -> CLOSED | O11: =Harvest!L9 -> CLOSED | P11: =CPUE!L9 -> CLOSED | Q11: =Effort!N9 -> CLOSED | R11: =Harvest!N9 -> CLOSED | S11: =CPUE!N9 -> CLOSED | T11: =+H11 -> 884 | U11: =+I11 -> 12021
A12: 40490 | B12: 40490 | C12: -1.2 | D12: 0.82986111 | E12: =Effort!F10 -> CLOSED | F12: =Harvest!F10 -> CLOSED | G12: =CPUE!F10 -> CLOSED | H12: =Effort!H10 -> 406 | I12: =Harvest!H10 -> 5728 | J12: =CPUE!H10 -> 14.108374 | K12: =Effort!J10 -> CLOSED | L12: =Harvest!J10 -> CLOSED | M12: =CPUE!J10 -> CLOSED | N12: =Effort!L10 -> CLOSED | O12: =Harvest!L10 -> CLOSED | P12: =CPUE!L10 -> CLOSED | Q12: =Effort!N10 -> CLOSED | R12: =Harvest!N10 -> CLOSED | S12: =CPUE!N10 -> CLOSED | T12: =H12 -> 406 | U12: =I12 -> 5728
A13: Tide Series Totals | E13: =SUM(E9:E12) -> 4614.258 | F13: =SUM(F9:F12) -> 61112.84 | G13: =F13/E13 -> 13.244348 | H13: =SUM(H9:H12) -> 4025.7286 | I13: =SUM(I9:I12) -> 38378.853 | J13: =I13/H13 -> 9.5333931 | K13: =SUM(K9:K12) -> 8175 | L13: =SUM(L9:L12) -> 97940 | M13: =L13/K13 -> 11.980428 | N13: =SUM(N9:N12) -> 3056 | O13: =SUM(O9:O12) -> 44035 | P13: =O13/N13 -> 14.409359 | Q13: =SUM(Q9:Q12) -> 409.37656 | R13: =SUM(R9:R12) -> 4774.9479 | S13: =R13/Q13 -> 11.663951 | T13: =SUM(T9:T12) -> 20280.363 | U13: =SUM(U9:U12) -> 246241.64
A14: 40502 | B14: 40502 | C14: -0.4 | D14: 0.73541667 | E14: =Effort!F12 -> 1902 | F14: =Harvest!F12 -> 28648 | G14: =CPUE!F12 -> 15.06204 | H14: =Effort!H12 -> 1518 | I14: =Harvest!H12 -> 22251 | J14: =CPUE!H12 -> 14.658103 | K14: =Effort!J12 -> CLOSED | L14: =Harvest!J12 -> CLOSED | M14: =CPUE!J12 -> CLOSED | N14: =Effort!L12 -> CLOSED | O14: =Harvest!L12 -> CLOSED | P14: =CPUE!L12 -> CLOSED | Q14: =Effort!N12 -> CLOSED | R14: =Harvest!N12 -> CLOSED | S14: =CPUE!N12 -> CLOSED | T14: =+E14+H14 -> 3420 | U14: =+F14+I14 -> 50899
A15: 40503 | B15: 40503 | C15: -0.7 | D15: 0.76180556 | E15: =Effort!F13 -> 708 | F15: =Harvest!F13 -> 10620 | G15: =CPUE!F13 -> 15 | H15: =Effort!H13 -> 375 | I15: =Harvest!H13 -> 5625 | J15: =CPUE!H13 -> 15 | K15: =Effort!J13 -> CLOSED | L15: =Harvest!J13 -> CLOSED | M15: =CPUE!J13 -> CLOSED | N15: =Effort!L13 -> CLOSED | O15: =Harvest!L13 -> CLOSED | P15: =CPUE!L13 -> CLOSED | Q15: =Effort!N13 -> CLOSED | R15: =Harvest!N13 -> CLOSED | S15: =CPUE!N13 -> CLOSED | T15: =+E15+H15 -> 1083 | U15: =+F15+I15 -> 16245
A16: Tide Series Totals | E16: =SUM(E14:E15) -> 2610 | F16: =SUM(F14:F15) -> 39268 | G16: =F16/E16 -> 15.045211 | H16: =SUM(H14:H15) -> 1893 | I16: =SUM(I14:I15) -> 27876 | J16: =I16/H16 -> 14.725832 | K16: =SUM(K14:K15) -> 0 | L16: =SUM(L14:L15) -> 0 | M16: =L16/K16 -> #DIV/0! | N16: =SUM(N14:N15) -> 0 | O16: =SUM(O14:O15) -> 0 | P16: =O16/N16 -> #DIV/0! | Q16: =SUM(Q14:Q15) -> 0 | R16: =SUM(R14:R15) -> 0 | T16: =SUM(T14:T15) -> 4503 | U16: =SUM(U14:U15) -> 67144
A17: 40515 | B17: 40515 | C17: -0.8 | D17: 0.69652778 | E17: =Effort!F15 -> CLOSED | F17: =Harvest!F15 -> CLOSED | G17: =CPUE!F15 -> CLOSED | H17: =Effort!H15 -> 1250 | I17: =Harvest!H15 -> 18750 | J17: =CPUE!H15 -> 15 | K17: =Effort!J15 -> CLOSED | L17: =Harvest!J15 -> CLOSED | M17: =CPUE!J15 -> CLOSED | N17: =Effort!L15 -> CLOSED | O17: =Harvest!L15 -> CLOSED | P17: =CPUE!L15 -> CLOSED | Q17: =Effort!N15 -> CLOSED | R17: =Harvest!N15 -> CLOSED | S17: =CPUE!N15 -> CLOSED | T17: =+H17 -> 1250 | U17: =+I17 -> 18750
A18: 40516 | B18: 40516 | C18: -1.2 | D18: 0.72847222 | E18: =Effort!F16 -> 2142 | F18: =Harvest!F16 -> 32130 | G18: =CPUE!F16 -> 15 | H18: =Effort!H16 -> 1929 | I18: =Harvest!H16 -> 28935 | J18: =CPUE!H16 -> 15 | K18: =Effort!J16 -> 4432 | L18: =Harvest!J16 -> 66481 | M18: =CPUE!J16 -> 15.000226 | N18: =Effort!L16 -> 1504 | O18: =Harvest!L16 -> 22553 | P18: =CPUE!L16 -> 14.995346 | Q18: =Effort!N16 -> 185.81665 | R18: =Harvest!N16 -> 2162.5895 | S18: =CPUE!N16 -> 11.638298 | T18: =E18+H18+K18+N18+Q18 -> 10192.817 | U18: =F18+I18+L18+O18+R18 -> 152261.59
A19: 40517 | B19: 40517 | C19: -1.3 | D19: 0.75972222 | E19: =Effort!F17 -> 1024 | F19: =Harvest!F17 -> 15360 | G19: =CPUE!F17 -> 15 | H19: =Effort!H17 -> 766.92049 | I19: =Harvest!H17 -> 11507.832 | J19: =CPUE!H17 -> 15.005248 | K19: =Effort!J17 -> 1691 | L19: =Harvest!J17 -> 25368 | M19: =CPUE!J17 -> 15.001774 | N19: =Effort!L17 -> 669 | O19: =Harvest!L17 -> 10042 | P19: =CPUE!L17 -> 15.010463 | Q19: =Effort!N17 -> 95.877275 | R19: =Harvest!N17 -> 1042.6654 | S19: =CPUE!N17 -> 10.875 | T19: =E19+H19+K19+N19+Q19 -> 4246.7978 | U19: =F19+I19+L19+O19+R19 -> 63320.498
A20: 40518 | B20: 40518 | C20: -1.2 | D20: 0.78888889 | E20: =Effort!F18 -> CLOSED | F20: =Harvest!F18 -> CLOSED | G20: =CPUE!F18 -> CLOSED | H20: =Effort!H18 -> 362 | I20: =Harvest!H18 -> 5430 | J20: =CPUE!H18 -> 15 | K20: =Effort!J18 -> CLOSED | L20: =Harvest!J18 -> CLOSED | M20: =CPUE!J18 -> CLOSED | N20: =Effort!L18 -> CLOSED | O20: =Harvest!L18 -> CLOSED | P20: =CPUE!L18 -> CLOSED | Q20: =Effort!N18 -> CLOSED | R20: =Harvest!N18 -> CLOSED | S20: =CPUE!N18 -> CLOSED | T20: =+H20 -> 362 | U20: =+I20 -> 5430
A21: Tide Series Totals | E21: =SUM(E17:E20) -> 3166 | F21: =SUM(F17:F20) -> 47490 | G21: =F21/E21 -> 15 | H21: =SUM(H17:H20) -> 4307.9205 | I21: =SUM(I17:I20) -> 64622.832 | J21: =I21/H21 -> 15.000934 | K21: =SUM(K17:K20) -> 6123 | L21: =SUM(L17:L20) -> 91849 | M21: =L21/K21 -> 15.000653 | N21: =SUM(N17:N20) -> 2173 | O21: =SUM(O17:O20) -> 32595 | P21: =O21/N21 -> 15 | Q21: =SUM(Q17:Q20) -> 281.69392 | R21: =SUM(R17:R20) -> 3205.2549 | S21: =R21/Q21 -> 11.378502 | T21: =SUM(T17:T20) -> 16051.614 | U21: =SUM(U17:U20) -> 239762.09
A22: 40543 | B22: 40543 | C22: 0 | D22: 0.65277778 | E22: =Effort!F20 -> 5329 | F22: =Harvest!F20 -> 68435 | G22: =CPUE!F20 -> 12.841997 | H22: =Effort!H20 -> 4718.5108 | I22: =Harvest!H20 -> 60964.538 | J22: =CPUE!H20 -> 12.920292 | K22: =Effort!J20 -> 10424 | L22: =Harvest!J20 -> 127837 | M22: =CPUE!J20 -> 12.263718 | N22: =Effort!L20 -> 4096 | O22: =Harvest!L20 -> 59753 | P22: =CPUE!L20 -> 14.588135 | Q22: =Effort!N20 -> 379.92566 | R22: =Harvest!N20 -> 2567.3764 | S22: =CPUE!N20 -> 6.7575758 | T22: =E22+H22+K22+N22+Q22 -> 24947.436 | U22: =F22+I22+L22+O22+R22 -> 319556.91
A23: 40544 | B23: 40544 | C23: -0.4 | D23: 0.68888889 | E23: =Effort!F21 -> 5419 | F23: =Harvest!F21 -> 65284 | G23: =CPUE!F21 -> 12.047241 | H23: =Effort!H21 -> 3590.5527 | I23: =Harvest!H21 -> 43550.045 | J23: =CPUE!H21 -> 12.129064 | K23: =Effort!J21 -> 5797 | L23: =Harvest!J21 -> 61643 | M23: =CPUE!J21 -> 10.633604 | N23: =Effort!L21 -> 5252 | O23: =Harvest!L21 -> 72362 | P23: =CPUE!L21 -> 13.777989 | Q23: =Effort!N21 -> 387.91131 | R23: =Harvest!N21 -> 543.07584 | S23: =CPUE!N21 -> 1.4 | T23: =E23+H23+K23+N23+Q23 -> 20446.464 | U23: =F23+I23+L23+O23+R23 -> 243382.12
A24: 40545 | B24: 40545 | C24: -0.7 | D24: 0.72083333 | E24: =Effort!F22 -> CLOSED | F24: =Harvest!F22 -> CLOSED | G24: =CPUE!F22 -> CLOSED | H24: =Effort!H22 -> 1316 | I24: =Harvest!H22 -> 9395 | J24: =CPUE!H22 -> 7.1390578 | K24: =Effort!J22 -> CLOSED | L24: =Harvest!J22 -> CLOSED | M24: =CPUE!J22 -> CLOSED | N24: =Effort!L22 -> CLOSED | O24: =Harvest!L22 -> CLOSED | P24: =CPUE!L22 -> CLOSED | Q24: =Effort!N22 -> CLOSED | R24: =Harvest!N22 -> CLOSED | S24: =CPUE!N22 -> CLOSED | T24: =+H24 -> 1316 | U24: =+I24 -> 9395
A25: Tide Series Totals | E25: =SUM(E22:E24) -> 10748 | F25: =SUM(F22:F24) -> 133719 | G25: =F25/E25 -> 12.441291 | H25: =SUM(H22:H24) -> 9625.0635 | I25: =SUM(I22:I24) -> 113909.58 | J25: =I25/H25 -> 11.834684 | K25: =SUM(K22:K24) -> 16221 | L25: =SUM(L22:L24) -> 189480 | M25: =L25/K25 -> 11.681154 | N25: =SUM(N22:N24) -> 9348 | O25: =SUM(O22:O24) -> 132115 | P25: =O25/N25 -> 14.13297 | Q25: =SUM(Q22:Q24) -> 767.83697 | R25: =SUM(R22:R24) -> 3110.4522 | S25: =R25/Q25 -> 4.050928 | T25: =SUM(T22:T24) -> 46709.9 | U25: =SUM(U22:U24) -> 572334.03
A26: 40563 | B26: 40563 | C26: -1.3 | D26: 0.79097222 | E26: =Effort!F24 -> 811 | F26: =Harvest!F24 -> 3652 | G26: =CPUE!F24 -> 4.5030826 | H26: =Effort!H24 -> 559 | I26: =Harvest!H24 -> 738 | J26: =CPUE!H24 -> 1.3202147 | K26: =Effort!J24 -> CLOSED | L26: =Harvest!J24 -> CLOSED | M26: =CPUE!J24 -> CLOSED | N26: =Effort!L24 -> CLOSED | O26: =Harvest!L24 -> CLOSED | P26: =CPUE!L24 -> CLOSED | Q26: =Effort!N24 -> CLOSED | R26: =Harvest!N24 -> CLOSED | S26: =CPUE!N24 -> CLOSED | T26: =E26+H26 -> 1370 | U26: =F26+I26 -> 4390
A27: 40564 | B27: 40564 | C27: -1.1 | D27: 0.81805556 | E27: =Effort!F25 -> 1008 | F27: =Harvest!F25 -> 7684 | G27: =CPUE!F25 -> 7.6230159 | H27: =Effort!H25 -> 633.81747 | I27: =Harvest!H25 -> 1922.9378 | J27: =CPUE!H25 -> 3.0338983 | K27: =Effort!J25 -> CLOSED | L27: =Harvest!J25 -> CLOSED | M27: =CPUE!J25 -> CLOSED | N27: =Effort!L25 -> CLOSED | O27: =Harvest!L25 -> CLOSED | P27: =CPUE!L25 -> CLOSED | Q27: =Effort!N25 -> 137.04225 | R27: =Harvest!N25 -> 123.7801 | S27: =CPUE!N25 -> 0.90322581 | T27: =E27+H27+Q27 -> 1778.8597 | U27: =F27+I27+R27 -> 9730.7178
A28: 40565 | B28: 40565 | C28: -0.6 | D28: 0.84652778 | E28: =Effort!F26 -> 2094 | F28: =Harvest!F26 -> 27187 | G28: =CPUE!F26 -> 12.983286 | H28: =Effort!H26 -> 1930 | I28: =Harvest!H26 -> 13550 | J28: =CPUE!H26 -> 7.0207254 | K28: =Effort!J26 -> CLOSED | L28: =Harvest!J26 -> CLOSED | M28: =CPUE!J26 -> CLOSED | N28: =Effort!L26 -> CLOSED | O28: =Harvest!L26 -> CLOSED | P28: =CPUE!L26 -> CLOSED | Q28: =Effort!N26 -> 199.0915 | R28: =Harvest!N26 -> 298.63725 | S28: =CPUE!N26 -> 1.5 | T28: =E28+H28+Q28 -> 4223.0915 | U28: =F28+I28+R28 -> 41035.637
A29: Tide Series Totals | E29: =SUM(E26:E28) -> 3913 | F29: =SUM(F26:F28) -> 38523 | G29: =F29/E29 -> 9.8448761 | H29: =SUM(H26:H28) -> 3122.8175 | I29: =SUM(I26:I28) -> 16210.938 | J29: =I29/H29 -> 5.1911256 | Q29: =SUM(Q27:Q28) -> 336.13375 | R29: =SUM(R27:R28) -> 422.41734 | S29: =R29/Q29 -> 1.2566942 | T29: =SUM(T26:T28) -> 7371.9512 | U29: =SUM(U26:U28) -> 55156.355
A30: 40591 | B30: 40591 | C30: -0.9 | D30: 0.74513889 | E30: =Effort!F28 -> CLOSED | F30: =Harvest!F28 -> CLOSED | G30: =CPUE!F28 -> CLOSED | H30: =Effort!H28 -> 1684 | I30: =Harvest!H28 -> 23720 | J30: =CPUE!H28 -> 14.085511 | K30: =Effort!J28 -> CLOSED | L30: =Harvest!J28 -> CLOSED | M30: =CPUE!J28 -> CLOSED | N30: =Effort!L28 -> CLOSED | O30: =Harvest!L28 -> CLOSED | P30: =CPUE!L28 -> CLOSED | Q30: =Effort!N28 -> CLOSED | R30: =Harvest!N28 -> CLOSED | S30: =CPUE!N28 -> CLOSED | T30: =+H30 -> 1684 | U30: =+I30 -> 23720
A31: 40592 | B31: 40592 | C31: -0.9 | D31: 0.77291667 | E31: =Effort!F29 -> 2081 | F31: =Harvest!F29 -> 29901 | G31: =CPUE!F29 -> 14.368573 | H31: =Effort!H29 -> 2064.2806 | I31: =Harvest!H29 -> 26271.248 | J31: =CPUE!H29 -> 12.726588 | K31: =Effort!J29 -> 5430 | L31: =Harvest!J29 -> 81453 | M31: =CPUE!J29 -> 15.000552 | N31: =Effort!L29 -> 1762 | O31: =Harvest!L29 -> 21146 | P31: =CPUE!L29 -> 12.001135 | Q31: =Effort!N29 -> 114.51342 | R31: =Harvest!N29 -> 204.48825 | S31: =CPUE!N29 -> 1.7857143 | T31: =E31+H31+K31+N31+Q31 -> 11451.794 | U31: =F31+I31+L31+O31+R31 -> 158975.74
A32: 40593 | B32: 40593 | C32: -0.5 | D32: 0.80069444 | E32: =Effort!F30 -> 4286 | F32: =Harvest!F30 -> 61662 | G32: =CPUE!F30 -> 14.386841 | H32: =Effort!H30 -> 2727.5943 | I32: =Harvest!H30 -> 32891.872 | J32: =CPUE!H30 -> 12.058931 | K32: =Effort!J30 -> 6223 | L32: =Harvest!J30 -> 83649 | M32: =CPUE!J30 -> 13.441909 | N32: =Effort!L30 -> 3280 | O32: =Harvest!L30 -> 44806 | P32: =CPUE!L30 -> 13.660366 | Q32: =Effort!N30 -> 148.21029 | R32: =Harvest!N30 -> 304.88973 | S32: =CPUE!N30 -> 2.0571429 | T32: =E32+H32+K32+N32+Q32 -> 16664.805 | U32: =F32+I32+L32+O32+R32 -> 223313.76
A33: Tide Series Totals | E33: =SUM(E30:E32) -> 6367 | F33: =SUM(F30:F32) -> 91563 | G33: =F33/E33 -> 14.38087 | H33: =SUM(H30:H32) -> 6475.8748 | I33: =SUM(I30:I32) -> 82883.12 | J33: =I33/H33 -> 12.798753 | K33: =SUM(K31:K32) -> 11653 | L33: =SUM(L31:L32) -> 165102 | M33: =L33/K33 -> 14.168197 | N33: =SUM(N31:N32) -> 5042 | O33: =SUM(O31:O32) -> 65952 | P33: =O33/N33 -> 13.080524 | Q33: =SUM(Q31:Q32) -> 262.72371 | R33: =SUM(R31:R32) -> 509.37798 | S33: =R33/Q33 -> 1.9388352 | T33: =E33+H33+K33+N33+Q33 -> 29800.599 | U33: =F33+I33+L33+O33+R33 -> 406009.5
A34: 40621 | B34: 40621 | C34: -0.1 | D34: 0.79444444 | E34: =Effort!F32 -> 5243 | F34: =Harvest!F32 -> 57414 | G34: =CPUE!F32 -> 10.950601 | H34: =Effort!H32 -> 2226 | I34: =Harvest!H32 -> 12212 | J34: =CPUE!H32 -> 5.4860737 | K34: =Effort!J32 -> 4083 | L34: =Harvest!J32 -> 50610 | M34: =CPUE!J32 -> 12.395298 | N34: =Effort!L32 -> 4610 | O34: =Harvest!L32 -> 50640 | P34: =CPUE!L32 -> 10.984816 | Q34: =Effort!N32 -> CLOSED | R34: =Harvest!N32 -> CLOSED | S34: =CPUE!N32 -> CLOSED | T34: =+E34+H34+K34+N34 -> 16162 | U34: =+F34+I34+L34+O34 -> 170876
A35: 40622 | B35: 40622 | C35: -0.5 | D35: 0.31666667 | E35: =Effort!F33 -> 2947 | F35: =Harvest!F33 -> 43099 | G35: =CPUE!F33 -> 14.624703 | H35: =Effort!H33 -> 1456 | I35: =Harvest!H33 -> 20431 | J35: =CPUE!H33 -> 14.03228 | K35: =Effort!J33 -> 5544 | L35: =Harvest!J33 -> 79431 | M35: =CPUE!J33 -> 14.327381 | N35: =Effort!L33 -> 1808 | O35: =Harvest!L33 -> 26959 | P35: =CPUE!L33 -> 14.910951 | Q35: =Effort!N33 -> CLOSED | R35: =Harvest!N33 -> CLOSED | S35: =CPUE!N33 -> CLOSED | T35: =+E35+H35+K35+N35 -> 11755 | U35: =+F35+I35+L35+O35 -> 169920
A36: 40623 | B36: 40623 | C36: -0.9 | D36: 0.34930556 | E36: =Effort!F34 -> 2599 | F36: =Harvest!F34 -> 35088 | G36: =CPUE!F34 -> 13.500577 | H36: =Effort!H34 -> 1229 | I36: =Harvest!H34 -> 9299 | J36: =CPUE!H34 -> 7.5663141 | K36: =Effort!J34 -> CLOSED | L36: =Harvest!J34 -> CLOSED | M36: =CPUE!J34 -> CLOSED | N36: =Effort!L34 -> CLOSED | O36: =Harvest!L34 -> CLOSED | P36: =CPUE!L34 -> CLOSED | Q36: =Effort!N34 -> CLOSED | R36: =Harvest!N34 -> CLOSED | S36: =CPUE!N34 -> CLOSED | T36: =+E36+H36 -> 3828 | U36: =+F36+I36 -> 44387
A37: 40624 | B37: 40624 | C37: -1 | D37: 0.38333333 | E37: =Effort!F35 -> 1730 | F37: =Harvest!F35 -> 25950 | G37: =CPUE!F35 -> 15 | H37: =Effort!H35 -> 725 | I37: =Harvest!H35 -> 9450 | J37: =CPUE!H35 -> 13.034483 | K37: =Effort!J35 -> CLOSED | L37: =Harvest!J35 -> CLOSED | M37: =CPUE!J35 -> CLOSED | N37: =Effort!L35 -> CLOSED | O37: =Harvest!L35 -> CLOSED | P37: =CPUE!L35 -> CLOSED | Q37: =Effort!N35 -> CLOSED | R37: =Harvest!N35 -> CLOSED | S37: =CPUE!N35 -> CLOSED | T37: =+E37+H37 -> 2455 | U37: =+F37+I37 -> 35400
A38: Tide Series Totals | E38: =SUM(E34:E37) -> 12519 | F38: =SUM(F34:F37) -> 161551 | G38: =F38/E38 -> 12.904465 | H38: =SUM(H34:H37) -> 5636 | I38: =SUM(I34:I37) -> 51392 | J38: =I38/H38 -> 9.1185238 | K38: =SUM(K34:K37) -> 9627 | L38: =SUM(L34:L37) -> 130041 | M38: =L38/K38 -> 13.507946 | N38: =SUM(N34:N37) -> 6418 | O38: =SUM(O34:O37) -> 77599 | P38: =O38/N38 -> 12.090838 | T38: =SUM(T34:T37) -> 34200 | U38: =SUM(U34:U37) -> 420583
A39: 40640 | B39: 40640 | C39: 0.1 | D39: 0.40069444 | E39: =Effort!F37 -> 2520 | F39: =Harvest!F37 -> 30618 | G39: =CPUE!F37 -> 12.15 | H39: =Effort!H37 -> 1663 | I39: =Harvest!H37 -> 23027 | J39: =CPUE!H37 -> 13.846663 | K39: =Effort!J37 -> CLOSED | L39: =Harvest!J37 -> CLOSED | M39: =CPUE!J37 -> CLOSED | N39: =Effort!L37 -> CLOSED | O39: =Harvest!L37 -> CLOSED | P39: =CPUE!L37 -> CLOSED | Q39: =Effort!N37 -> CLOSED | R39: =Harvest!N37 -> CLOSED | S39: =CPUE!N37 -> CLOSED | T39: =+E39+H39 -> 4183 | U39: =+F39+I39 -> 53645
A40: 40641 | B40: 40641 | C40: 0.2 | D40: 0.42986111 | E40: =Effort!F38 -> 4192 | F40: =Harvest!F38 -> 48762 | G40: =CPUE!F38 -> 11.632156 | H40: =Effort!H38 -> 3497 | I40: =Harvest!H38 -> 27976 | J40: =CPUE!H38 -> 8 | K40: =Effort!J38 -> CLOSED | L40: =Harvest!J38 -> CLOSED | M40: =CPUE!J38 -> CLOSED | N40: =Effort!L38 -> CLOSED | O40: =Harvest!L38 -> CLOSED | P40: =CPUE!L38 -> CLOSED | Q40: =Effort!N38 -> CLOSED | R40: =Harvest!N38 -> CLOSED | S40: =CPUE!N38 -> CLOSED | T40: =+E40+H40 -> 7689 | U40: =+F40+I40 -> 76738
...

Sheet TAC
A1: 2009 FALL - 2010 SPRING NON-TRIBAL TOTAL ALLOWABLE CATCH (TAC)
A4: LONG BEACH | B4: 1276247.7
A5: TWIN HARBORS | B5: 845427.67
A6: COPALIS | B6: 683167.41
A7: MOCROCKS | B7: 545586.69
A8: KALALOCH | B8: 258924.12
A9: COASTWIDE TAC | B9: =SUM(B4:B8) -> 3609353.6

Sheet Copy Sheet
A1: BeachName | B1: Date | C1: LocationID | D1: CPUE | E1: CorrectionFactor | F1: Calc People | G1: EstCorEffort | H1: TotHarvest
A2: Copalis | B2: 40459 | C2: 31002 | D2: 14.918367 | E2: 1.4313999 | F2: 27 | G2: 38 | H2: 567
A3: Copalis | B3: 40459 | C3: 31005 | D3: 14.666667 | E3: 1.4313999 | F3: 707 | G3: 992 | H3: 14799
A4: Copalis | B4: 40459 | C4: 32007 | D4: 15 | E4: 1.4313999 | F4: 440 | G4: 617 | H4: 9205
A5: Copalis | B5: 40459 | C5: 32009 | D5: 15 | E5: 1.4313999 | F5: 351 | G5: 492 | H5: 7340
A6: Copalis | B6: 40459 | C6: 33012 | D6: 15 | E6: 1.4313999 | F6: 784 | G6: 1100 | H6: 16410
A7: Copalis | B7: 40459 | C7: 33013 | D7: 14.918367 | E7: 1.4313999 | F7: 6 | G7: 8 | H7: 119
G8: =SUM(G2:G7) -> 3247 | H8: =SUM(H2:H7) -> 48440
A10: BeachName | B10: Date | C10: LocationID | D10: CPUE | E10: CorrectionFactor | F10: Calc People | G10: EstCorEffort | H10: TotHarvest
A11: Copalis | B11: 40460 | C11: 31002 | D11: 5.0298507 | E11: 1.4357001 | F11: 22 | G11: 31 | H11: 156
A12: Copalis | B12: 40460 | C12: 31005 | D12: 6.8888889 | E12: 1.4357001 | F12: 636 | G12: 887 | H12: 4461
A13: Copalis | B13: 40460 | C13: 32007 | D13: 4.9545455 | E13: 1.4357001 | F13: 387 | G13: 540 | H13: 2675
A14: Copalis | B14: 40460 | C14: 32009 | D14: 8.3076923 | E14: 1.4357001 | F14: 131 | G14: 183 | H14: 1520
A15: Copalis | B15: 40460 | C15: 33012 | D15: 2.5217391 | E15: 1.4357001 | F15: 334 | G15: 466 | H15: 1175
A16: Copalis | B16: 40460 | C16: 33013 | D16: 5.0298507 | E16: 1.4357001 | F16: 2 | G16: 3 | H16: 15
G17: =SUM(G11:G16) -> 2110 | H17: =SUM(H11:H16) -> 10002
A19: BeachName | B19: Date | C19: LocationID | D19: CPUE | E19: CorrectionFactor | F19: Calc People | G19: EstCorEffort | H19: TotHarvest
A20: Mocrocks | B20: 40459 | C20: 41100 | D20: 15 | E20: 1.43685 | F20: 75 | G20: 106 | H20: 1590
A21: Mocrocks | B21: 40459 | C21: 41200 | D21: 15 | E21: 1.43685 | F21: 87 | G21: 123 | H21: 1772
A22: Mocrocks | B22: 40459 | C22: 41300 | D22: 15 | E22: 1.43685 | F22: 179 | G22: 254 | H22: 3810
A23: Mocrocks | B23: 40459 | C23: 41400 | D23: 13.8 | E23: 1.43685 | F23: 388 | G23: 550 | H23: 7925
A24: Mocrocks | B24: 40459 | C24: 42500 | D24: 13.333333 | E24: 1.43685 | F24: 143 | G24: 203 | H24: 2707
A25: Mocrocks | B25: 40459 | C25: 42600 | D25: 15 | E25: 1.43685 | F25: 284 | G25: 402 | H25: 5792
G26: =SUM(G20:G25) -> 1638 | H26: =SUM(H20:H25) -> 23596
A28: BeachName | B28: Date | C28: LocationID | D28: CPUE | E28: CorrectionFactor | F28: Calc People | G28: EstCorEffort | H28: TotHarvest
A29: Mocrocks | B29: 40460 | C29: 41100 | D29: 4.8727273 | E29: 1.518425 | F29: 39 | G29: 57 | H29: 278
A30: Mocrocks | B30: 40460 | C30: 41200 | D30: 15 | E30: 1.518425 | F30: 20 | G30: 29 | H30: 435
A31: Mocrocks | B31: 40460 | C31: 41300 | D31: 6.5 | E31: 1.518425 | F31: 291 | G31: 426 | H31: 2769
A32: Mocrocks | B32: 40460 | C32: 41400 | D32: 3 | E32: 1.518425 | F32: 290 | G32: 425 | H32: 2071
A33: Mocrocks | B33: 40460 | C33: 42500 | D33: 2.3636364 | E33: 1.518425 | F33: 18 | G33: 26 | H33: 61
A34: Mocrocks | B34: 40460 | C34: 42600 | D34: 3.4 | E34: 1.518425 | F34: 202 | G34: 296 | H34: 1442
G35: =SUM(G29:G34) -> 1259 | H35: =SUM(H29:H34) -> 7056
A37: BeachName | B37: Date | C37: LocationID | D37: CPUE | E37: CorrectionFactor | F37: Calc People | G37: EstCorEffort | H37: TotHarvest
A38: Twin Harbors | B38: 40458 | C38: 21100 | D38: 14.648148 | E38: 1.3793 | F38: 3 | G38: 4 | H38: 59
A39: Twin Harbors | B39: 40458 | C39: 21200 | D39: 14.8 | E39: 1.3793 | F39: 755 | G39: 1041 | H39: 15249
A40: Twin Harbors | B40: 40458 | C40: 22307 | D40: 14.545455 | E40: 1.3793 | F40: 653 | G40: 901 | H40: 13198
A41: Twin Harbors | B41: 40458 | C41: 22309 | D41: 14.647059 | E41: 1.3793 | F41: 607 | G41: 837 | H41: 12260
G42: =SUM(G38:G41) -> 2783 | H42: =SUM(H38:H41) -> 40766
A44: BeachName | B44: Date | C44: LocationID | D44: CPUE | E44: CorrectionFactor | F44: Calc People | G44: EstCorEffort | H44: TotHarvest
A45: Twin Harbors | B45: 40459 | C45: 21100 | D45: 14.666667 | E45: 1.3793 | F45: 12 | G45: 15 | H45: 220
...

Sheet Twin Harbors Data
A1: Date | B1: LocationID | C1: CPUE | D1: CorrectionFactor | E1: Calc People | F1: EstCorEffort | G1: TotHarvest
A2: 40458 | B2: 21100 | C2: 14.648148 | D2: 1.3793 | E2: 3 | F2: 4 | G2: 59
A3: 40458 | B3: 21200 | C3: 14.8 | D3: 1.3793 | E3: 755 | F3: 1041 | G3: 15249
A4: 40458 | B4: 22307 | C4: 14.545455 | D4: 1.3793 | E4: 653 | F4: 901 | G4: 13198
A5: 40458 | B5: 22309 | C5: 14.647059 | D5: 1.3793 | E5: 607 | F5: 837 | G5: 12260
A6: 40459 | B6: 21100 | C6: 14.666667 | D6: 1.3793 | E6: 12 | F6: 15 | G6: 220
A7: 40459 | B7: 21200 | C7: 15 | D7: 1.3793 | E7: 547 | F7: 687 | G7: 10076
A8: 40459 | B8: 22307 | C8: 13.857143 | D8: 1.3793 | E8: 443 | F8: 556 | G8: 8155
A9: 40459 | B9: 22309 | C9: 14.956522 | D9: 1.3793 | E9: 447 | F9: 561 | G9: 8391
A10: 40461 | B10: 21100 | C10: 10.16 | D10: 1.3793 | E10: 0 | F10: 0 | G10: 0
A11: 40461 | B11: 21200 | C11: 9.7142857 | D11: 1.3793 | E11: 254 | F11: 337 | G11: 3424
A12: 40461 | B12: 22307 | C12: 10.142857 | D12: 1.3793 | E12: 326 | F12: 432 | G12: 4389
A13: 40461 | B13: 22309 | C13: 11 | D13: 1.3793 | E13: 216 | F13: 286 | G13: 2906
... A53: 40563 | B53: 22309 | C53: 0.28571429 | D53: 1.5346667 | E53: 110 | F53: 169 | G53: 48
A54: 40564 | B54: 21100 | C54: 3.0338983 | D54: 1.534667 | E54: 0 | F54: =+E54*D54 -> 0 | G54: =+F54*C54 -> 0
A55: 40564 | B55: 21200 | C55: 3.0338983 | D55: 1.534667 | E55: 158.5625 | F55: =+E55*D55 -> 243.34064 | G55: =+F55*C55 -> 738.27074
A56: 40564 | B56: 22307 | C56: 3.0338983 | D56: 1.534667 | E56: 199.125 | F56: =+E56*D56 -> 305.59057 | G56: =+F56*C56 -> 927.1307
A57: 40564 | B57: 22309 | C57: 3.0338983 | D57: 1.534667 | E57: 55.3125 | F57: =+E57*D57 -> 84.886268 | G57: =+F57*C57 -> 257.53631
A58: 40565 | B58: 21100 | C58: 7.66 | D58: 1.46735 | E58: 0 | F58: 0 | G58: 0
A59: 40565 | B59: 21200 | C59: 4.7777778 | D59: 1.46735 | E59: 327 | F59: 428 | G59: 2045
A60: 40565 | B60: 22307 | C60: 12.090909 | D60: 1.46735 | E60: 653 | F60: 856 | G60: 6557
A61: 40565 | B61: 22309 | C61: 3.1 | D61: 1.46735 | E61: 493 | F61: 646 | G61: 4948
A62: 40591 | B62: 21100 | C62: 13.84507 | D62: 1.4254667 | E62: 0 | F62: 0 | G62: 0
A63: 40591 | B63: 21200 | C63: 13.916667 | D63: 1.4254667 | E63: 437 | F63: 606 | G63: 8434
A64: 40591 | B64: 22307 | C64: 12.823529 | D64: 1.4254667 | E64: 461 | F64: 639 | G64: 8847
A65: 40591 | B65: 22309 | C65: 14.666667 | D65: 1.4254667 | E65: 317 | F65: 439 | G65: 6439
A66: 40621 | B66: 21100 | C66: 5.4328358 | D66: 1.46735 | E66: 37 | F66: 47 | G66: 255
A67: 40621 | B67: 21200 | C67: 3.8333333 | D67: 1.46735 | E67: 776 | F67: 978 | G67: 5313
A68: 40621 | B68: 22307 | C68: 8.1333333 | D68: 1.46735 | E68: 865 | F68: 1090 | G68: 5922
A69: 40621 | B69: 22309 | C69: 6.5 | D69: 1.46735 | E69: 88 | F69: 111 | G69: 722
... A81: 40624 | B81: 22309 | C81: 13 | D81: 1.551 | E81: 51 | F81: 79 | G81: 1027

Sheet Tribal Update
A1: 2010-2011 State (non-Indian) Recreational Razor Clam Effort, Harvest and CPUE totals - FINAL
E2: COPALIS | I2: MOCROCKS | M2: KALALOCH | Q2: DAILY TOTALS
A3: DATE | B3: DAY | C3: TIDE | D3: TIME | E3: Effort | F3: Harvest | G3: CPUE | H3: Size (mm) | I3: Effort | J3: Harvest | K3: CPUE | L3: Size (mm) | M3: Effort | N3: Harvest | O3: CPUE | P3: Size (mm) | Q3: Effort | R3: Harvest
A4: 40459 | B4: 40459 | C4: -1.4 | D4: 0.82083333 | E4: =+'Summary Table'!K5 -> 3990 | F4: =+'Summary Table'!L5 -> 59524 | G4: =+'Summary Table'!M5 -> 14.918296 | I4: =+'Summary Table'!N5 -> 2024 | J4: =+'Summary Table'!O5 -> 29166 | K4: =+'Summary Table'!P5 -> 14.410079 | M4: =+'Summary Table'!Q5 -> 231.69615 | N4: =+'Summary Table'!R5 -> 3363.3312 | O4: =+'Summary Table'!S5 -> 14.516129 | Q4: =+E4+I4+M4 -> 6245.6962 | R4: =+F4+J4+N4 -> 92053.331
A5: 40460 | B5: 40460 | C5: -1.5 | D5: 0.85277778 | E5: =+'Summary Table'!K6 -> 2461 | F5: =+'Summary Table'!L6 -> 12380 | G5: =+'Summary Table'!M6 -> 5.0304754 | I5: =+'Summary Table'!N6 -> 1684 | J5: =+'Summary Table'!O6 -> 8204 | K5: =+'Summary Table'!P6 -> 4.871734 | M5: =+'Summary Table'!Q6 -> 164.26083 | N5: =+'Summary Table'!R6 -> 1551.3522 | O5: =+'Summary Table'!S6 -> 9.4444444 | Q5: =+E5+I5+M5 -> 4309.2608 | R5: =+F5+J5+N5 -> 22135.352
A6: Tide Series Totals | E6: =SUM(E4:E5) -> 6451 | F6: =SUM(F4:F5) -> 71904 | G6: =F6/E6 -> 11.146179 | H6: 119.83 | I6: =SUM(I4:I5) -> 3708 | J6: =SUM(J4:J5) -> 37370 | K6: =J6/I6 -> 10.078209 | L6: 117.94 | M6: =SUM(M4:M5) -> 395.95698 | N6: =SUM(N4:N5) -> 4914.6835 | O6: =N6/M6 -> 12.412165 | P6: 105.27 | Q6: =SUM(Q4:Q5) -> 10554.957 | R6: =SUM(R4:R5) -> 114188.68
A7: 40487 | B7: 40487 | C7: -1.4 | D7: 0.77847222 | E7: 2479 | F7: 34019 | G7: 13.722872 | I7: 1513 | J7: 23281 | K7: 15.38731 | M7: 235.22413 | N7: 3415.4543 | O7: 14.52 | Q7: =+E7+I7+M7 -> 4227.2241 | R7: =+F7+J7+N7 -> 60715.454
A8: 40488 | B8: 40488 | C8: -1.6 | D8: 0.80972222 | E8: 3018 | F8: 30023 | G8: 9.9479788 | I8: 945 | J8: 11934 | K8: 12.628571 | M8: 105.20581 | N8: 444.37676 | O8: 4.2238806 | Q8: =+E8+I8+M8 -> 4068.2058 | R8: =+F8+J8+N8 -> 42401.377
A9: Tide Series Totals | E9: =SUM(E7:E8) -> 5497 | F9: =SUM(F7:F8) -> 64042 | G9: =F9/E9 -> 11.650355 | H9: 108.10714 | I9: =SUM(I7:I8) -> 2458 | J9: =SUM(J7:J8) -> 35215 | K9: =J9/I9 -> 14.326688 | L9: 110.55705 | M9: =SUM(M7:M8) -> 340.42993 | N9: =SUM(N7:N8) -> 3859.8311 | O9: =N9/M9 -> 11.338107 | P9: 107.25 | Q9: =SUM(Q7:Q8) -> 8295.4299 | R9: =SUM(R7:R8) -> 103116.83
A10: 40516 | B10: 40516 | C10: -1.2 | D10: 0.72847222 | E10: 2907 | F10: 43605 | G10: 15 | I10: 1271 | J10: 19065 | K10: 15 | M10: 151.13881 | N10: 1758.9985 | O10: 11.638298 | Q10: =+E10+I10+M10 -> 4329.1388 | R10: =+F10+J10+N10 -> 64428.998
A11: 40517 | B11: 40517 | C11: -1.3 | D11: 0.75972222 | E11: 1257 | F11: 18855 | G11: 15 | I11: 573 | J11: 8595 | K11: 15 | M11: 80.19648 | N11: 879.10992 | O11: 10.961951 | Q11: =+E11+I11+M11 -> 1910.1965 | R11: =+F11+J11+N11 -> 28329.11
A12: Tide Series Totals | E12: =SUM(E10:E11) -> 4164 | F12: =SUM(F10:F11) -> 62460 | G12: =F12/E12 -> 15 | H12: 104.91 | I12: =SUM(I10:I11) -> 1844 | J12: =SUM(J10:J11) -> 27660 | K12: =J12/I12 -> 15 | L12: 110.41 | M12: =SUM(M10:M11) -> 231.33529 | N12: =SUM(N10:N11) -> 2638.1084 | O12: =N12/M12 -> 11.40383 | P12: 104.06 | Q12: =SUM(Q10:Q11) -> 6239.3353 | R12: =SUM(R10:R11) -> 92758.108
A13: 40543 | B13: 40543 | C13: 0 | D13: 0.65277778 | E13: 5756 | F13: 70587 | G13: 12.263204 | I13: 2895 | J13: 41981 | K13: 14.501209 | M13: 379.92566 | N13: 2567.3764 | O13: 6.7575758 | Q13: =+E13+I13+M13 -> 9030.9257 | R13: =+F13+J13+N13 -> 115135.38
A14: 40544 | B14: 40544 | C14: -0.4 | D14: 0.68888889 | E14: 3845 | F14: 40889 | G14: 10.63433 | I14: 2890 | J14: 39731 | K14: 13.747751 | M14: 387.91131 | N14: 543.07584 | O14: 1.4 | Q14: =+E14+I14+M14 -> 7122.9113 | R14: =+F14+J14+N14 -> 81163.076
A15: Tide Series Totals | E15: =SUM(E13:E14) -> 9601 | F15: =SUM(F13:F14) -> 111476 | G15: =F15/E15 -> 11.610874 | H15: 102.11 | I15: =SUM(I13:I14) -> 5785 | J15: =SUM(J13:J14) -> 81712 | K15: =J15/I15 -> 14.124806 | L15: 107.34 | M15: =SUM(M13:M14) -> 767.83697 | N15: =SUM(N13:N14) -> 3110.4522 | O15: =N15/M15 -> 4.050928 | P15: 99.98 | Q15: =SUM(Q13:Q14) -> 16153.837 | R15: =SUM(R13:R14) -> 196298.45
A16: 40564 | B16: 40516 | C16: -1.1 | D16: 0.81805556 | E16: CLOSED | F16: CLOSED | G16: CLOSED | I16: CLOSED | J16: CLOSED | K16: CLOSED | M16: 112 | N16: 101 | O16: 0.9 | Q16: =+M16 -> 112 | R16: =+N16 -> 101
A17: 40565 | B17: 40517 | C17: -0.6 | D17: 0.84652778 | E17: CLOSED | F17: CLOSED | G17: CLOSED | I17: CLOSED | J17: CLOSED | K17: CLOSED | M17: 167 | N17: 251 | O17: 1.5 | Q17: =+M17 -> 167 | R17: =+N17 -> 251
A18: Tide Series Totals | M18: =SUM(M16:M17) -> 279 | N18: =SUM(N16:N17) -> 352 | O18: =N18/M18 -> 1.2616487 | P18: 103.53 | Q18: =SUM(Q16:Q17) -> 279 | R18: =SUM(R16:R17) -> 352
A19: 40592 | B19: 40592 | C19: -0.9 | D19: 0.77291667 | E19: 3272 | F19: 49080 | G19: 15 | I19: 1327 | J19: 16688 | K19: 12.575735 | M19: 96 | N19: 171 | O19: 1.78125 | Q19: =+E19+I19+M19 -> 4695 | R19: =+F19+J19+N19 -> 65939
A20: 40593 | B20: 40593 | C20: -0.5 | D20: 0.80069444 | E20: 4515 | F20: 60694 | G20: 13.442746 | I20: 2679 | J20: 36265 | K20: 13.536767 | M20: 124 | N20: 255 | O20: 2.0564516 | Q20: =+E20+I20+M20 -> 7318 | R20: =+F20+J20+N20 -> 97214
A21: Tide Series Totals | E21: =SUM(E19:E20) -> 7787 | F21: =SUM(F19:F20) -> 109774 | G21: =F21/E21 -> 14.097085 | H21: 109.05 | I21: =SUM(I19:I20) -> 4006 | J21: =SUM(J19:J20) -> 52953 | K21: =J21/I21 -> 13.218422 | L21: 109.2 | M21: =SUM(M19:M20) -> 220 | N21: =SUM(N19:N20) -> 426 | O21: =N21/M21 -> 1.9363636 | P21: 104.9 | Q21: =SUM(Q19:Q20) -> 12013 | R21: =SUM(R19:R20) -> 163153
A22: 40621 | B22: 40621 | C22: -0.1 | D22: 0.79444444 | E22: 4491 | F22: 57326 | G22: 12.76464 | I22: 3609 | J22: 37253 | K22: 10.32225 | M22: CLOSED | N22: CLOSED | O22: CLOSED | Q22: =+E22+I22 -> 8100 | R22: =+F22+J22 -> 94579
A23: 40622 | B23: 40622 | C23: -0.5 | D23: 0.31666667 | E23: 3125 | F23: 44772 | G23: 14.32704 | I23: 1521 | J23: 22725 | K23: 14.940828 | M23: CLOSED | N23: CLOSED | O23: CLOSED | Q23: =+E23+I23 -> 4646 | R23: =+F23+J23 -> 67497
A24: Tide Series Totals | E24: =SUM(E22:E23) -> 7616 | F24: =SUM(F22:F23) -> 102098 | G24: =F24/E24 -> 13.405725 | H24: 111.63 | I24: =SUM(I22:I23) -> 5130 | J24: =SUM(J22:J23) -> 59978 | K24: =J24/I24 -> 11.691618 | L24: 108.62 | Q24: =SUM(Q22:Q23) -> 12746 | R24: =SUM(R22:R23) -> 162076
A25: 40654 | B25: 40654 | C25: -1.4 | D25: 0.40486111 | E25: 2323 | F25: 34911 | G25: 15.028412 | I25: 1119 | J25: 16785 | K25: 15 | M25: CLOSED | N25: CLOSED | O25: CLOSED | Q25: =+E25+I25 -> 3442 | R25: =+F25+J25 -> 51696
A26: 40655 | B26: 40655 | C26: -0.8 | D26: 0.43958333 | E26: 2746 | F26: 39892 | G26: 14.527312 | I26: 1609 | J26: 24135 | K26: 15 | M26: CLOSED | N26: CLOSED | O26: CLOSED | Q26: =+E26+I26 -> 4355 | R26: =+F26+J26 -> 64027
A27: 40656 | B27: 40656 | C27: -0.2 | D27: 0.47708333 | E27: 5442 | F27: 81067 | G27: 14.896545 | I27: 2755 | J27: 41341 | K27: 15.005808 | M27: CLOSED | N27: CLOSED | O27: CLOSED | Q27: =+E27+I27 -> 8197 | R27: =+F27+J27 -> 122408
A28: Tide Series Totals | E28: =SUM(E25:E27) -> 10511 | F28: =SUM(F25:F27) -> 155870 | G28: =F28/E28 -> 14.829227 | H28: 121.13 | I28: =SUM(I25:I27) -> 5483 | J28: =SUM(J25:J27) -> 82261 | K28: =J28/I28 -> 15.002918 | L28: 116.27 | Q28: =SUM(Q25:Q27) -> 15994 | R28: =SUM(R25:R27) -> 238131
A29: 40670 | B29: 40670 | C29: -0.6 | D29: 0.41666667 | E29: CLOSED | F29: CLOSED | G29: CLOSED | I29: 1825 | J29: 26125 | K29: 14.315068 | M29: CLOSED | N29: CLOSED | O29: CLOSED | Q29: =I29 -> 1825 | R29: =J29 -> 26125
A30: 40671 | B30: 40671 | C30: -0.4 | D30: 0.44861111 | E30: CLOSED | F30: CLOSED | G30: CLOSED | I30: 1683 | J30: 25245 | K30: 15 | M30: CLOSED | N30: CLOSED | O30: CLOSED | Q30: =I30 -> 1683 | R30: =J30 -> 25245
I31: =SUM(I29:I30) -> 3508 | J31: =SUM(J29:J30) -> 51370 | K31: =J31/I31 -> 14.643672 | L31: 111.08 | Q31: =+I31 -> 3508 | R31: =+J31 -> 51370
A32: 40683 | B32: 40683 | C32: -1.7 | D32: 0.39097222 | E32: CLOSED | F32: CLOSED | G32: CLOSED | I32: 1599 | J32: 23952 | K32: 14.979362 | M32: CLOSED | N32: CLOSED | O32: CLOSED | Q32: =+I32 -> 1599 | R32: =+J32 -> 23952
A33: 40684 | B33: 40684 | C33: -1.1 | D33: 0.42291667 | E33: CLOSED | F33: CLOSED | G33: CLOSED | I33: 2969 | J33: 43949 | K33: 14.802627 | M33: CLOSED | N33: CLOSED | O33: CLOSED | Q33: =+I33 -> 2969 | R33: =+J33 -> 43949
A34: 40685 | B34: 40685 | C34: -0.5 | D34: 0.45555556 | E34: CLOSED | F34: CLOSED | G34: CLOSED | I34: 2070 | J34: 31050 | K34: 15 | M34: CLOSED | N34: CLOSED | O34: CLOSED | Q34: =+I34 -> 2070 | R34: =+J34 -> 31050
I35: 6638 | J35: 98951 | K35: 14.906749 | L35: 115.99 | Q35: =+I35 -> 6638 | R35: =+J35 -> 98951
