Workbook

Sheet Harvest
A1: Date | B1: Day | C1: Tide | D1: Time | E1: Longbeach | G1: Twin Harbors | I1: Copalis | K1: Mocrocks | M1: Kalaloch | O1: Daily Totals
A2: 40844 | B2: =+A2 -> 40844 | C2: -1.8 | D2: 0.85277778 | F2: 27700.083 | H2: 12413.98 | J2: 40131.277 | L2: 15167.372 | N2: CLOSED | O2: =+F2+H2+J2+L2 -> 95412.712
A3: 40845 | B3: =+A3 -> 40845 | C3: -1.5 | D3: 0.88680556 | F3: 41286.084 | H3: 22522.505 | J3: 39546.97 | L3: 17987.682 | N3: CLOSED | O3: =+F3+H3+J3+L3 -> 121343.24
A5: 40858 | B5: =+A5 -> 40858 | C5: -0.4 | D5: 0.78333333 | F5: 20473.723 | H5: 13437.604 | J5: CLOSED | L5: 24195.029 | N5: CLOSED | O5: =+F5+H5+L5 -> 58106.356
A6: 40859 | B6: =+A6 -> 40859 | C6: -0.4 | D6: 0.80763889 | F6: 5500.2201 | H6: 7090.592 | J6: CLOSED | L6: 17280.656 | N6: CLOSED | O6: =+F6+H6+L6 -> 29871.468
A8: 40872 | B8: =+A8 -> 40872 | C8: -1.9 | D8: 0.76875 | F8: 64433.645 | G8: * | H8: =+(F8+L8)*(H5+H6+H9)/(F5+F6+L5+L6+F9+L9) -> 21535.656 | J8: 50966.213 | L8: 27088.795 | N8: CLOSED | O8: =+F8+H8+J8+L8 -> 164024.31
A9: 40873 | B9: =+A9 -> 40873 | C9: -1.8 | D9: 0.80138889 | F9: 42119.098 | H9: 12697.487 | J9: CLOSED | L9: 31634.106 | N9: CLOSED | O9: =+F9+H9+L9 -> 86450.692
A11: 40887 | B11: =+A11 -> 40887 | C11: -0.5 | D11: 0.77083333 | F11: 16446.747 | G11: * | H11: =(H2+H3)*(F11+J11+L11)/(F2+F3+J2+J3+L2+L3) -> 12244.923 | J11: 26597.012 | L11: 20682.325 | N11: CLOSED | O11: =+F11+H11+J11+L11 -> 75971.007
A13: 40899 | B13: =+A13 -> 40899 | C13: -0.9 | D13: 0.69444444 | F13: 28321.855 | H13: 19334.071 | J13: 28993.197 | L13: 20682.325 | N13: CLOSED | O13: =+F13+H13+J13+L13 -> 97331.448
A14: 40900 | B14: =+A14 -> 40900 | C14: -1.4 | D14: 0.72847222 | E14: * | F14: =+F13*(H14+J14+L14)/(H13+J13+L13) -> 19103.921 | H14: 12800.976 | J14: 13065.69 | L14: 20682.325 | N14: CLOSED | O14: =+F14+H14+J14+L14 -> 65652.912
A16: 40928 | B16: =+A16 -> 40928 | C16: -0.5 | D16: 0.68611111 | F16: 7917.0931 | H16: 815.86929 | J16: 3740.7513 | L16: 1861.5008 | N16: CLOSED | O16: =+F16+H16+J16+L16 -> 14335.214
A17: 40929 | B17: =+A17 -> 40929 | C17: -0.8 | D17: 0.72013889 | E17: * | F17: =+J17*(F16+F13)/(J16+J13) -> 22932.084 | G17: * | H17: =+J17*(H16+H13)/(J16+J13) -> 12750.925 | J17: 20714.112 | K17: * | L17: =+J17*(J16+J13)/(L16+L13) -> 30077.178 | N17: CLOSED | O17: =+F17+H17+J17+L17 -> 86474.3
A19: 40957 | B19: =+A19 -> 40957 | C19: 0 | D19: 0.67569444 | F19: 57532.084 | H19: 11362.667 | J19: CLOSED | L19: 51488.695 | N19: CLOSED | O19: =+F19+H19+L19 -> 120383.45
A20: 40958 | B20: =+A20 -> 40958 | C20: -0.2 | D20: 0.70833333 | F20: 149317.31 | H20: 44173.654 | J20: CLOSED | L20: 109323.26 | N20: CLOSED | O20: =+F20+H20+L20 -> 302814.23
A22: 40978 | B22: =+A22 -> 40978 | C22: -0.3 | D22: 0.31875 | F22: 61966.711 | H22: 22781.124 | J22: 48063.471 | L22: 24036.932 | N22: CLOSED | O22: =+F22+H22+J22+L22 -> 156848.24
A23: 40979 | B23: =+A23 -> 40979 | C23: -0.4 | D23: 0.39444444 | F23: 72871.274 | H23: 25083.937 | J23: 47474.802 | L23: 24319.311 | N23: CLOSED | O23: =+F23+H23+J23+L23 -> 169749.33
A25: 40992 | B25: =+A25 -> 40992 | C25: 0.3 | D25: 0.35069444 | F25: 81215.59 | H25: 26562.929 | J25: 59039.348 | L25: 42122.044 | N25: CLOSED | O25: =+F25+H25+J25+L25 -> 208939.91
A26: 40993 | B26: =+A26 -> 40993 | C26: 0.3 | D26: 0.37430556 | F26: 49011.007 | H26: 32734.85 | J26: CLOSED | L26: 54519.961 | N26: CLOSED | O26: =+F26+H26+L26 -> 136265.82
A28: 41006 | B28: =+A28 -> 41006 | C28: -1.2 | D28: 0.31666667 | F28: 210312.07 | H28: 86779.693 | J28: 60601.874 | L28: 67693.737 | N28: 3872.2597 | O28: =+F28+H28+J28+L28+N28 -> 429259.63
A29: 41007 | B29: =+A29 -> 41007 | C29: -1.5 | D29: 0.34930556 | F29: 137285.41 | H29: 35799.299 | J29: CLOSED | L29: 114608.07 | N29: 312.04958 | O29: =+F29+H29+L29+N29 -> 288004.84
A30: 41008 | B30: =+A30 -> 41008 | C30: -1.5 | D30: 0.38263889 | F30: 78053.182 | H30: 35461.19 | J30: CLOSED | L30: CLOSED | N30: 698.15319 | O30: =+F30+H30+N30 -> 114212.52
A32: 41020 | B32: =+A32 -> 41020 | C32: -0.3 | D32: 0.31111111 | F32: 90164.585 | H32: 52318.41 | J32: CLOSED | L32: CLOSED | N32: CLOSED | O32: =+F32+H32 -> 142482.99
A33: 41021 | B33: =+A33 -> 41021 | C33: -0.4 | D33: 0.33402778 | F33: 88566.237 | H33: 40570.487 | J33: CLOSED | L33: CLOSED | N33: CLOSED | O33: =+F33+H33 -> 129136.72
A34: 41022 | B34: 41021 | C34: -0.4 | D34: 0.35763889 | F34: 49092.556 | G34: * | H34: =+F34*(H32+H33)/(F32+F33) -> 25514.085 | J34: 24277.997 | L34: 18846.817 | N34: CLOSED | O34: =+F34+H34+J34+L34 -> 117731.45
A36: 41034 | B36: 41034 | C36: -1.5 | D36: 0.27152778 | F36: CLOSED | H36: 58539.354 | J36: CLOSED | L36: CLOSED | N36: CLOSED | O36: =+H36 -> 58539.354
A37: 41035 | B37: 41035 | C37: -2.1 | D37: 0.30486111 | F37: CLOSED | H37: 53922.802 | J37: CLOSED | L37: CLOSED | N37: CLOSED | O37: =+H37 -> 53922.802
A38: 41036 | B38: 41036 | C38: -2.3 | D38: 0.33819444 | F38: CLOSED | H38: 35842.121 | J38: CLOSED | L38: CLOSED | N38: CLOSED | O38: =+H38 -> 35842.121
A40: FALL 2010 - SPRING 2011 SEASON TOTALS: | F40: =SUM(F2:F39) -> 1421622.6 | H40: =SUM(H2:H39) -> 735091.19 | J40: =SUM(J2:J39) -> 463212.72 | L40: =SUM(L2:L39) -> 734298.12 | N40: =SUM(N3:N39) -> 4882.4624 | O40: =SUM(O2:O39) -> 3359107.1
A41: ESTIMATED WASTAGE RATE: | F41: =+'LB Wastage'!F22 -> 0.015987291 | H41: =+'TH Wastage'!F22 -> 0.049181857 | J41: =+'Cop Wastage'!F22 -> 0.019180165 | L41: =+'Moc Wastage'!I22 -> 0.025771595
A42: ESTIMATED TOTAL WASTAGE: | F42: =+'LB Wastage'!D22 -> 4415 | H42: =+'TH Wastage'!D22 -> 17521 | J42: =+'Cop Wastage'!D22 -> 3076 | L42: =+'Moc Wastage'!G22 -> 8518 | O42: =F42+H42+J42+L42+N42 -> 33530
A43: SEASON TOTAL INCLUDING WASTAGE: | F43: =F40+F42 -> 1426037.6 | H43: =H40+H42 -> 752612.19 | J43: =J40+J42 -> 466288.72 | L43: =L40+L42 -> 742816.12 | N43: =N40+N42 -> 4882.4624 | O43: =O40+O42 -> 3392637.1
A44: Fall 2010 / Spring 2011 Harvest Rate (clams/day): | F44: =AVERAGE(F2:F38) -> 61809.677 | H44: =AVERAGE(H2:H38) -> 28272.738 | J44: =AVERAGE(J2:J38) -> 35631.747 | L44: =AVERAGE(L2:L38) -> 36714.906 | N44: =AVERAGE(N2:N38) -> 1627.4875 | O44: =F44+H44+J44+L44+N44 -> 164056.56
A45: % of TAC Harvested: | F45: =F43/TAC!B4 -> 1.302744 | H45: =H43/TAC!B5 -> 1.22115 | J45: =J43/TAC!B6 -> 1.2555804 | L45: =L43/TAC!B7 -> 1.2261117 | N45: =N43/TAC!B8 -> 0.033774524 | O45: =O43/TAC!B9 -> 1.1976606
A46: clams left in TAC : | F46: =TAC!B4-F43 -> -331396.16 | H46: =TAC!B5-Harvest!H43 -> -136297.88 | J46: =TAC!B6-J43 -> -94915.678 | L46: =TAC!B7-L43 -> -136985.42 | N46: =TAC!B8-N43 -> 139678.05 | O46: =TAC!B9-Harvest!O40 -> -526387.1
A47: *- estimate based on comparison of other beaches. + - no harvest due to very heavy surf and storm warnings.

Sheet Effort
A1: Date | B1: Day | C1: Tide | D1: Time | E1: Longbeach | G1: Twin Harbors | I1: Copalis | K1: Mocrocks | M1: Kalaloch | O1: Daily Totals
A2: 40844 | B2: =+A2 -> 40844 | C2: -1.8 | D2: 0.85277778 | F2: 2083.0462 | H2: 1039.5944 | J2: 3064.0267 | L2: 1055.8278 | N2: CLOSED | O2: =+F2+H2+J2+L2 -> 7242.4952
A3: 40845 | B3: =+A3 -> 40845 | C3: -1.5 | D3: 0.88680556 | F3: 2846.0076 | H3: 1500.1668 | J3: 2636.4647 | L3: 1400.3833 | N3: CLOSED | O3: =+F3+H3+J3+L3 -> 8383.0224
O4: =+F4+H4+J4+L4+N4 -> 0
A5: 40858 | B5: =+A5 -> 40858 | C5: -0.4 | D5: 0.78333333 | F5: 1456.5638 | H5: 1148.5131 | J5: CLOSED | L5: 1726.8147 | N5: CLOSED | O5: =+F5+H5+L5 -> 4331.8917
A6: 40859 | B6: =+A6 -> 40859 | C6: -0.4 | D6: 0.80763889 | F6: 1440.5338 | H6: 826.76863 | J6: CLOSED | L6: 1598.9904 | N6: CLOSED | O6: =+F6+H6+L6 -> 3866.2929
A8: 40872 | B8: =+A8 -> 40872 | C8: -1.9 | D8: 0.76875 | F8: 4738.4193 | G8: * | H8: =+(F8+L8)*(H5+H6+H9)/(F5+F6+L5+L6+F9+L9) -> 1699.7808 | J8: 3486.4376 | L8: 1887.5809 | N8: CLOSED | O8: =+F8+H8+J8+L8 -> 11812.219
A9: 40873 | B9: =+A9 -> 40873 | C9: -1.8 | D9: 0.80138889 | F9: 2800.7584 | H9: 880.58636 | J9: CLOSED | L9: 2108.9404 | N9: CLOSED | O9: =+F9+H9+L9 -> 5790.2852
A11: 40887 | B11: =+A11 -> 40887 | C11: -0.5 | D11: 0.77083333 | F11: 2272.0249 | G11: * | H11: =(H2+H3)*(F11+J11+L11)/(F2+F3+J2+J3+L2+L3) -> 1095.1615 | J11: 1995.6361 | L11: 1375.0022 | N11: CLOSED | O11: =+F11+H11+J11+L11 -> 6737.8247
A13: 40899 | B13: =+A13 -> 40899 | C13: -0.9 | D13: 0.69444444 | F13: 1878.0267 | H13: 1291.5473 | J13: 1958.6515 | L13: 2321.1555 | N13: CLOSED | O13: =+F13+H13+J13+L13 -> 7449.381
A14: 40900 | B14: =+A14 -> 40900 | C14: -1.4 | D14: 0.72847222 | E14: * | F14: =+F13*(H14+J14+L14)/(H13+J13+L13) -> 2276.949 | H14: 1585.2602 | J14: 3056.6523 | L14: 2112.8846 | N14: CLOSED | O14: =+F14+H14+J14+L14 -> 9031.7462
A16: 40928 | B16: =+A16 -> 40928 | C16: -0.5 | D16: 0.68611111 | F16: 1104.0844 | H16: 103.15589 | J16: 538.66818 | L16: 139.61256 | N16: CLOSED | O16: =+F16+H16+J16+L16 -> 1885.521
A17: 40929 | B17: =+A17 -> 40929 | C17: -0.8 | D17: 0.72013889 | E17: * | F17: =+J17*(F16+F13)/(J16+J13) -> 1996.7487 | G17: * | H17: =+J17*(H16+H13)/(J16+J13) -> 933.8591 | J17: 1672.1442 | K17: * | L17: =+J17*(J16+J13)/(L16+L13) -> 1696.9818 | N17: CLOSED | O17: =+F17+H17+J17+L17 -> 6299.7337
A19: 40957 | B19: =+A19 -> 40957 | C19: 0 | D19: 0.67569444 | F19: 6838.8807 | H19: 1858.2378 | J19: CLOSED | L19: 6276.7171 | N19: CLOSED | O19: =+F19+H19+L19 -> 14973.836
A20: 40958 | B20: =+A20 -> 40958 | C20: -0.2 | D20: 0.70833333 | F20: 10016.606 | H20: 4572.3606 | J20: CLOSED | L20: 7752.8048 | N20: CLOSED | O20: =+F20+H20+L20 -> 22341.772
A22: 40978 | B22: =+A22 -> 40978 | C22: -0.3 | D22: 0.31875 | F22: 5360.6629 | H22: 1595.7792 | J22: 3766.1675 | L22: 1997.7925 | N22: CLOSED | O22: =+F22+H22+J22+L22 -> 12720.402
A23: 40979 | B23: =+A23 -> 40979 | C23: -0.4 | D23: 0.39444444 | F23: 6486.3442 | H23: 1716.2694 | J23: 3272.7311 | L23: 1959.798 | N23: CLOSED | O23: =+F23+H23+J23+L23 -> 13435.143
A25: 40992 | B25: =+A25 -> 40992 | C25: 0.3 | D25: 0.35069444 | F25: 5584.755 | H25: 1928.3926 | J25: 4043.0809 | L25: 2819.0842 | N25: CLOSED | O25: =+F25+H25+J25+L25 -> 14375.313
A26: 40993 | B26: =+A26 -> 40993 | C26: 0.3 | D26: 0.37430556 | F26: 5766.0008 | H26: 2214.3078 | J26: CLOSED | L26: 3677.6779 | N26: CLOSED | O26: =+F26+H26+L26 -> 11657.986
A28: 41006 | B28: =+A28 -> 41006 | C28: -1.2 | D28: 0.31666667 | F28: 14020.804 | H28: 5785.3129 | J28: 4040.125 | L28: 4530.8005 | N28: 3872.2597 | O28: =+F28+H28+J28+L28+N28 -> 32249.302
A29: 41007 | B29: =+A29 -> 41007 | C29: -1.5 | D29: 0.34930556 | F29: 10042.051 | H29: 2386.62 | J29: CLOSED | L29: 8013.0084 | N29: 312.04958 | O29: =+F29+H29+L29+N29 -> 20753.729
A30: 41008 | B30: =+A30 -> 41008 | C30: -1.5 | D30: 0.38263889 | F30: 5594.3697 | H30: 2354.8447 | J30: CLOSED | L30: CLOSED | N30: 698.15319 | O30: =+F30+H30+N30 -> 8647.3675
A32: 41020 | B32: =+A32 -> 41020 | C32: -0.3 | D32: 0.31111111 | F32: 6010.9723 | H32: 3487.894 | J32: CLOSED | L32: CLOSED | N32: CLOSED | O32: =+F32+H32 -> 9498.8663
A33: 41021 | B33: =+A33 -> 41021 | C33: -0.4 | D33: 0.33402778 | F33: 5904.4158 | H33: 2704.6992 | J33: CLOSED | L33: CLOSED | N33: CLOSED | O33: =+F33+H33 -> 8609.1149
A34: 41022 | B34: 41021 | C34: -0.4 | D34: 0.35763889 | F34: 3272.837 | H34: =+F34*(H32+H33)/(F32+F33) -> 1700.939 | J34: 1618.5332 | L34: 1256.4545 | N34: CLOSED | O34: =+F34+H34+J34+L34 -> 7848.7636
A36: 41034 | B36: 41034 | C36: -1.5 | D36: 0.27152778 | F36: CLOSED | H36: 3902.6236 | J36: CLOSED | L36: CLOSED | N36: CLOSED | O36: =+H36 -> 3902.6236
A37: 41035 | B37: 41035 | C37: -2.1 | D37: 0.30486111 | F37: CLOSED | H37: 3594.8535 | J37: CLOSED | L37: CLOSED | N37: CLOSED | O37: =+H37 -> 3594.8535
A38: 41036 | B38: 41036 | C38: -2.3 | D38: 0.33819444 | F38: CLOSED | H38: 2389.4747 | J38: CLOSED | L38: CLOSED | N38: CLOSED | O38: =+H38 -> 2389.4747
A40: SEASON TOTALS : | F40: =SUM(F2:F39) -> 109791.86 | H40: =SUM(H2:H39) -> 54297.003 | J40: =SUM(J2:J39) -> 35149.319 | L40: =SUM(L3:L39) -> 54652.484 | N40: =SUM(N3:N39) -> 4882.4624 | O40: =SUM(O2:O38) -> 259828.96
A41: *- estimate based on comparison of other beaches. + - no harvest due to very heavy surf and storm warnings.

Sheet Copy Sheet
A1: BeachName | B1: Date | C1: CPUE | D1: CorrectionFactor | E1: Diggers-People | F1: CalcPeople | G1: EstCorEffort | H1: TotHarvest
A2: Copalis | B2: 40844 | C2: 13.097561 | D2: 0.44658005 | E2: 0.9010989 | F2: 1518.5161 | G2: 3064.0267 | H2: 40131.277
A3: Copalis | B3: 40845 | C3: 15 | D3: 0.47837996 | E3: 0.98333333 | F3: 1282.6087 | G3: 2636.4647 | H3: 39546.97
A4: Copalis | B4: 40872 | C4: 14.618421 | D4: 0.4932667 | E4: 0.97435897 | F4: 1765 | G4: 3486.4376 | H4: 50966.213
A5: Copalis | B5: 40887 | C5: 13.327586 | D5: 0.49650002 | E5: 0.96666667 | F5: 1025 | G5: 1995.6361 | H5: 26597.012
A6: Copalis | B6: 40899 | C6: 14.802632 | D6: 0.49696672 | E6: 0.97435897 | F6: 999 | G6: 1958.6515 | H6: 28993.197
A7: Copalis | B7: 40900 | C7: 4.2745098 | D7: 0.46906662 | E7: 0.96226415 | F7: 1490 | G7: 3056.6523 | H7: 13065.69
A8: Copalis | B8: 40928 | C8: 6.9444444 | D8: 0.41330004 | E8: 0.94736842 | F8: 235 | G8: 538.66818 | H8: 3740.7513
A9: Copalis | B9: 40929 | C9: 12.387755 | D9: 0.49696672 | E9: 1 | F9: 831 | G9: 1672.1442 | H9: 20714.112
A10: Copalis | B10: 40978 | C10: 12.761905 | D10: 0.44116664 | E10: 0.94029851 | F10: 1767 | G10: 3766.1675 | H10: 48063.471
A11: Copalis | B11: 40979 | C11: 14.506173 | D11: 0.51160002 | E11: 0.98780488 | F11: 1695 | G11: 3272.7311 | H11: 47474.802
A12: Copalis | B12: 40992 | C12: 14.602564 | D12: 0.5873667 | E12: 0.93975904 | F12: 2527 | G12: 4043.0809 | H12: 59039.348
A13: Copalis | B13: 41006 | C13: 15 | D13: 0.54723334 | E13: 0.99009901 | F13: 2233 | G13: 4040.125 | H13: 60601.874
... A79: Twin Harbors | B79: 41036 | C79: 15 | D79: 0.51684999 | E79: 1 | F79: 1235 | G79: 2389.4747 | H79: 35842.121

Sheet CPUE
A1: Date | B1: Day | C1: Tide | D1: Time | E1: Longbeach | G1: Twin Harbors | I1: Copalis | K1: Mocrocks | M1: Kalaloch | O1: Daily Totals
A2: 40844 | B2: =+A2 -> 40844 | C2: -1.8 | D2: 0.85277778 | F2: =+Harvest!F2/Effort!F2 -> 13.297872 | H2: =+Harvest!H2/Effort!H2 -> 11.941176 | J2: =+Harvest!J2/Effort!J2 -> 13.097561 | L2: =+Harvest!L2/Effort!L2 -> 14.365385 | N2: CLOSED | O2: =Harvest!O2/Effort!O2 -> 13.174011
A3: 40845 | B3: =+A3 -> 40845 | C3: -1.5 | D3: 0.88680556 | F3: =+Harvest!F3/Effort!F3 -> 14.506667 | H3: =+Harvest!H3/Effort!H3 -> 15.013333 | J3: =+Harvest!J3/Effort!J3 -> 15 | L3: =+Harvest!L3/Effort!L3 -> 12.844828 | N3: CLOSED | O3: =Harvest!O3/Effort!O3 -> 14.47488
A5: 40858 | B5: =+A5 -> 40858 | C5: -0.4 | D5: 0.78333333 | F5: =+Harvest!F5/Effort!F5 -> 14.05618 | H5: =+Harvest!H5/Effort!H5 -> 11.7 | J5: CLOSED | L5: =+Harvest!L5/Effort!L5 -> 14.011364 | N5: CLOSED | O5: =Harvest!O5/Effort!O5 -> 13.413622
A6: 40859 | B6: =+A6 -> 40859 | C6: -0.4 | D6: 0.80763889 | F6: =+Harvest!F6/Effort!F6 -> 3.8181818 | H6: =+Harvest!H6/Effort!H6 -> 8.5762712 | J6: CLOSED | L6: =+Harvest!L6/Effort!L6 -> 10.807229 | N6: CLOSED | O6: =Harvest!O6/Effort!O6 -> 7.7261264
A8: 40872 | B8: =+A8 -> 40872 | C8: -1.9 | D8: 0.76875 | F8: =+Harvest!F8/Effort!F8 -> 13.598131 | G8: * | H8: =+Harvest!H8/Effort!H8 -> 12.669666 | J8: =+Harvest!J8/Effort!J8 -> 14.618421 | L8: =+Harvest!L8/Effort!L8 -> 14.351064 | N8: CLOSED | O8: =Harvest!O8/Effort!O8 -> 13.885986
A9: 40873 | B9: =+A9 -> 40873 | C9: -1.8 | D9: 0.80138889 | F9: =+Harvest!F9/Effort!F9 -> 15.038462 | H9: =+Harvest!H9/Effort!H9 -> 14.419355 | J9: CLOSED | L9: =+Harvest!L9/Effort!L9 -> 15 | N9: CLOSED | O9: =Harvest!O9/Effort!O9 -> 14.930299
A11: 40887 | B11: =+A11 -> 40887 | C11: -0.5 | D11: 0.77083333 | F11: =+Harvest!F11/Effort!F11 -> 7.238806 | G11: * | H11: =+Harvest!H11/Effort!H11 -> 11.180928 | J11: =+Harvest!J11/Effort!J11 -> 13.327586 | L11: =+Harvest!L11/Effort!L11 -> 15.041667 | N11: CLOSED | O11: =Harvest!O11/Effort!O11 -> 11.275302
A13: 40899 | B13: =+A13 -> 40899 | C13: -0.9 | D13: 0.69444444 | F13: =+Harvest!F13/Effort!F13 -> 15.080645 | H13: =+Harvest!H13/Effort!H13 -> 14.969697 | J13: =+Harvest!J13/Effort!J13 -> 14.802632 | L13: =+Harvest!L13/Effort!L13 -> 8.9103576 | N13: CLOSED | O13: =Harvest!O13/Effort!O13 -> 13.06571
A14: 40900 | B14: =+A14 -> 40900 | C14: -1.4 | D14: 0.72847222 | E14: * | F14: =+Harvest!F14/Effort!F14 -> 8.3901398 | H14: =+Harvest!H14/Effort!H14 -> 8.075 | J14: =+Harvest!J14/Effort!J14 -> 4.2745098 | L14: =+Harvest!L14/Effort!L14 -> 9.7886677 | N14: CLOSED | O14: =Harvest!O14/Effort!O14 -> 7.2691273
A16: 40928 | B16: =+A16 -> 40928 | C16: -0.5 | D16: 0.68611111 | F16: =+Harvest!F16/Effort!F16 -> 7.1707317 | H16: =+Harvest!H16/Effort!H16 -> 7.9090909 | J16: =+Harvest!J16/Effort!J16 -> 6.9444444 | L16: =+Harvest!L16/Effort!L16 -> 13.333333 | N16: CLOSED | O16: =Harvest!O16/Effort!O16 -> 7.6027868
A17: 40929 | B17: =+A17 -> 40929 | C17: -0.8 | D17: 0.72013889 | F17: =+Harvest!F17/Effort!F17 -> 11.484712 | H17: =+Harvest!H17/Effort!H17 -> 13.654014 | J17: =+Harvest!J17/Effort!J17 -> 12.387755 | L17: =+Harvest!L17/Effort!L17 -> 17.723925 | N17: CLOSED | O17: =Harvest!O17/Effort!O17 -> 13.72666
A19: 40957 | B19: =+A19 -> 40957 | C19: 0 | D19: 0.67569444 | F19: =+Harvest!F19/Effort!F19 -> 8.4125 | H19: =+Harvest!H19/Effort!H19 -> 6.1147541 | J19: CLOSED | L19: =+Harvest!L19/Effort!L19 -> 8.203125 | N19: CLOSED | O19: =Harvest!O19/Effort!O19 -> 8.0395865
A20: 40958 | B20: =+A20 -> 40958 | C20: -0.2 | D20: 0.70833333 | F20: =+Harvest!F20/Effort!F20 -> 14.906977 | H20: =+Harvest!H20/Effort!H20 -> 9.6610169 | J20: CLOSED | L20: =+Harvest!L20/Effort!L20 -> 14.101124 | N20: CLOSED | O20: =Harvest!O20/Effort!O20 -> 13.553725
A22: 40978 | B22: =+A22 -> 40978 | C22: -0.3 | D22: 0.31875 | F22: =+Harvest!F22/Effort!F22 -> 11.559524 | H22: =+Harvest!H22/Effort!H22 -> 14.275862 | J22: =+Harvest!J22/Effort!J22 -> 12.761905 | L22: =+Harvest!L22/Effort!L22 -> 12.031746 | N22: CLOSED | O22: =Harvest!O22/Effort!O22 -> 12.330446
A23: 40979 | B23: =+A23 -> 40979 | C23: -0.4 | D23: 0.39444444 | F23: =+Harvest!F23/Effort!F23 -> 11.234568 | H23: =+Harvest!H23/Effort!H23 -> 14.615385 | J23: =+Harvest!J23/Effort!J23 -> 14.506173 | L23: =+Harvest!L23/Effort!L23 -> 12.409091 | N23: CLOSED | O23: =Harvest!O23/Effort!O23 -> 12.634724
A25: 40992 | B25: =+A25 -> 40992 | C25: 0.3 | D25: 0.35069444 | F25: =+Harvest!F25/Effort!F25 -> 14.542373 | H25: =+Harvest!H25/Effort!H25 -> 13.774648 | J25: =+Harvest!J25/Effort!J25 -> 14.602564 | L25: =+Harvest!L25/Effort!L25 -> 14.941748 | N25: CLOSED | O25: =Harvest!O25/Effort!O25 -> 14.534634
A26: 40993 | B26: =+A26 -> 40993 | C26: 0.3 | D26: 0.37430556 | F26: =+Harvest!F26/Effort!F26 -> 8.5 | H26: =+Harvest!H26/Effort!H26 -> 14.783333 | J26: CLOSED | L26: =+Harvest!L26/Effort!L26 -> 14.824561 | N26: CLOSED | O26: =Harvest!O26/Effort!O26 -> 11.688624
A28: 41006 | B28: =+A28 -> 41006 | C28: -1.2 | D28: 0.31666667 | F28: =+Harvest!F28/Effort!F28 -> 15 | H28: =+Harvest!H28/Effort!H28 -> 15 | J28: =+Harvest!J28/Effort!J28 -> 15 | L28: =+Harvest!L28/Effort!L28 -> 14.940789 | N28: =+Harvest!N28/Effort!N28 -> 1 | O28: =+Harvest!O28/Effort!O28 -> 13.310664
A29: 41007 | B29: =+A29 -> 41007 | C29: -1.5 | D29: 0.34930556 | F29: =+Harvest!F29/Effort!F29 -> 13.671053 | H29: =+Harvest!H29/Effort!H29 -> 15 | J29: CLOSED | L29: =+Harvest!L29/Effort!L29 -> 14.302752 | N29: =+Harvest!N29/Effort!N29 -> 1 | O29: =+Harvest!O29/Effort!O29 -> 13.877257
A30: 41008 | B30: =+A30 -> 41008 | C30: -1.5 | D30: 0.38263889 | F30: =+Harvest!F30/Effort!F30 -> 13.952096 | H30: =+Harvest!H30/Effort!H30 -> 15.058824 | J30: CLOSED | L30: CLOSED | N30: =+Harvest!N30/Effort!N30 -> 1 | O30: =+Harvest!O30/Effort!O30 -> 13.20778
A32: 41020 | B32: =+A32 -> 41020 | C32: -0.3 | D32: 0.31111111 | F32: =+Harvest!F32/Effort!F32 -> 15 | H32: =+Harvest!H32/Effort!H32 -> 15 | J32: CLOSED | L32: CLOSED | N32: CLOSED | O32: =+Harvest!O32/Effort!O32 -> 15
A33: 41021 | B33: =+A33 -> 41021 | C33: -0.4 | D33: 0.33402778 | F33: =+Harvest!F33/Effort!F33 -> 15 | H33: =+Harvest!H33/Effort!H33 -> 15 | J33: CLOSED | L33: CLOSED | N33: CLOSED | O33: =+Harvest!O33/Effort!O33 -> 15
A34: 41022 | B34: 41021 | C34: -0.4 | D34: 0.35763889 | F34: =+Harvest!F34/Effort!F34 -> 15 | H34: =+Harvest!H34/Effort!H34 -> 15 | J34: =+Harvest!J34/Effort!J34 -> 15 | L34: =+Harvest!L34/Effort!L34 -> 15 | N34: CLOSED | O34: =+Harvest!O34/Effort!O34 -> 15
A36: 41034 | B36: 41034 | C36: -1.5 | D36: 0.27152778 | F36: CLOSED | H36: =+Harvest!H36/Effort!H36 -> 15 | J36: CLOSED | L36: CLOSED | N36: CLOSED | O36: =+Harvest!O36/Effort!O36 -> 15
A37: 41035 | B37: 41035 | C37: -2.1 | D37: 0.30486111 | F37: CLOSED | H37: =+Harvest!H37/Effort!H37 -> 15 | J37: CLOSED | L37: CLOSED | N37: CLOSED | O37: =+Harvest!O37/Effort!O37 -> 15
A38: 41036 | B38: 41036 | C38: -2.3 | D38: 0.33819444 | F38: CLOSED | H38: =+Harvest!H38/Effort!H38 -> 15 | J38: CLOSED | L38: CLOSED | N38: CLOSED | O38: =+Harvest!O38/Effort!O38 -> 15
A40: SEASON TOTALS : | F40: =Harvest!F40/Effort!F40 -> 12.948342 | H40: =Harvest!H40/Effort!H40 -> 13.538338 | J40: =Harvest!J40/Effort!J40 -> 13.178427 | L40: =Harvest!L40/Effort!L40 -> 13.435768 | N40: =Harvest!N40/Effort!N40 -> 1
A41: *- estimate based on comparison of other beaches. + - no harvest due to very heavy surf and storm warnings.

Sheet Summary Table
A1: 2011-2012 State (non-Indian) Recreational Razor Clam Effort, Harvest and CPUE totals.
E2: LONG BEACH | H2: TWIN HARBORS | K2: COPALIS | N2: MOCROCKS | Q2: KALALOCH | T2: DAILY TOTALS
A3: DATE | B3: DAY | C3: TIDE | D3: TIME | E3: Effort | F3: Harvest | G3: CPUE | H3: Effort | I3: Harvest | J3: CPUE | K3: Effort | L3: Harvest | M3: CPUE | N3: Effort | O3: Harvest | P3: CPUE | Q3: Effort | R3: Harvest | S3: CPUE | T3: Effort | U3: Harvest
A4: 40844 | B4: 40844 | C4: -1.8 | D4: 0.85277778 | E4: =Effort!F2 -> 2083.0462 | F4: =Harvest!F2 -> 27700.083 | G4: =CPUE!F2 -> 13.297872 | H4: =Effort!H2 -> 1039.5944 | I4: =Harvest!H2 -> 12413.98 | J4: =CPUE!H2 -> 11.941176 | K4: =Effort!J2 -> 3064.0267 | L4: =Harvest!J2 -> 40131.277 | M4: =CPUE!J2 -> 13.097561 | N4: =Effort!L2 -> 1055.8278 | O4: =Harvest!L2 -> 15167.372 | P4: =CPUE!L2 -> 14.365385 | Q4: =Effort!N2 -> CLOSED | R4: =Harvest!N2 -> CLOSED | S4: =CPUE!N2 -> CLOSED | T4: =+E4+H4+K4+N4 -> 7242.4952 | U4: =+F4+I4+L4+O4 -> 95412.712
A5: 40845 | B5: 40845 | C5: -1.5 | D5: 0.88680556 | E5: =Effort!F3 -> 2846.0076 | F5: =Harvest!F3 -> 41286.084 | G5: =CPUE!F3 -> 14.506667 | H5: =Effort!H3 -> 1500.1668 | I5: =Harvest!H3 -> 22522.505 | J5: =CPUE!H3 -> 15.013333 | K5: =Effort!J3 -> 2636.4647 | L5: =Harvest!J3 -> 39546.97 | M5: =CPUE!J3 -> 15 | N5: =Effort!L3 -> 1400.3833 | O5: =Harvest!L3 -> 17987.682 | P5: =CPUE!L3 -> 12.844828 | Q5: =Effort!N3 -> CLOSED | R5: =Harvest!N3 -> CLOSED | S5: =CPUE!N3 -> CLOSED | T5: =E5+H5+K5+N5 -> 8383.0224 | U5: =F5+I5+L5+O5 -> 121343.24
A6: Tide Series Totals | E6: =SUM(E4:E5) -> 4929.0539 | F6: =SUM(F4:F5) -> 68986.167 | G6: =F6/E6 -> 13.995823 | H6: =SUM(H4:H5) -> 2539.7612 | I6: =SUM(I4:I5) -> 34936.485 | J6: =I6/H6 -> 13.755815 | K6: =SUM(K4:K5) -> 5700.4914 | L6: =SUM(L4:L5) -> 79678.247 | M6: =L6/K6 -> 13.977435 | N6: =SUM(N4:N5) -> 2456.2111 | O6: =SUM(O4:O5) -> 33155.054 | P6: =O6/N6 -> 13.498455 | T6: =SUM(T4:T5) -> 15625.518 | U6: =SUM(U4:U5) -> 216755.95
A7: 40858 | B7: =+A7 -> 40858 | C7: -0.4 | D7: 0.78333333 | E7: =Effort!F5 -> 1456.5638 | F7: =Harvest!F5 -> 20473.723 | G7: =CPUE!F5 -> 14.05618 | H7: =Effort!H5 -> 1148.5131 | I7: =Harvest!H5 -> 13437.604 | J7: =CPUE!H5 -> 11.7 | K7: =Effort!J5 -> CLOSED | L7: =Harvest!J5 -> CLOSED | M7: =CPUE!J5 -> CLOSED | N7: =Effort!L5 -> 1726.8147 | O7: =Harvest!L5 -> 24195.029 | P7: =CPUE!L5 -> 14.011364 | Q7: CLOSED | R7: CLOSED | S7: CLOSED | T7: =E7+H7+N7 -> 4331.8917 | U7: =F7+I7+O7 -> 58106.356
A8: 40859 | B8: =+A8 -> 40859 | C8: -0.4 | D8: 0.80763889 | E8: =Effort!F6 -> 1440.5338 | F8: =Harvest!F6 -> 5500.2201 | G8: =CPUE!F6 -> 3.8181818 | H8: =Effort!H6 -> 826.76863 | I8: =Harvest!H6 -> 7090.592 | J8: =CPUE!H6 -> 8.5762712 | K8: =Effort!J6 -> CLOSED | L8: =Harvest!J6 -> CLOSED | M8: =CPUE!J6 -> CLOSED | N8: =Effort!L6 -> 1598.9904 | O8: =Harvest!L6 -> 17280.656 | P8: =CPUE!L6 -> 10.807229 | Q8: CLOSED | R8: CLOSED | S8: CLOSED | T8: =E8+H8+N8 -> 3866.2929 | U8: =F8+I8+O8 -> 29871.468
A9: Tide Series Totals | E9: =SUM(E7:E8) -> 2897.0977 | F9: =SUM(F7:F8) -> 25973.943 | G9: =F9/E9 -> 8.9655049 | H9: =SUM(H7:H8) -> 1975.2818 | I9: =SUM(I7:I8) -> 20528.196 | J9: =I9/H9 -> 10.39254 | N9: =SUM(N7:N8) -> 3325.8052 | O9: =SUM(O7:O8) -> 41475.685 | P9: =O9/N9 -> 12.47087 | T9: =SUM(T7:T8) -> 8198.1846 | U9: =SUM(U7:U8) -> 87977.824
A10: 40872 | B10: 40872 | C10: -1.9 | D10: 0.76875 | E10: =Effort!F8 -> 4738.4193 | F10: =Harvest!F8 -> 64433.645 | G10: =CPUE!F8 -> 13.598131 | H10: =Effort!H8 -> 1699.7808 | I10: =Harvest!H8 -> 21535.656 | J10: =CPUE!H8 -> 12.669666 | K10: =Effort!J8 -> 3486.4376 | L10: =Harvest!J8 -> 50966.213 | M10: =CPUE!J8 -> 14.618421 | N10: =Effort!L8 -> 1887.5809 | O10: =Harvest!L8 -> 27088.795 | P10: =CPUE!L8 -> 14.351064 | Q10: CLOSED | R10: CLOSED | S10: CLOSED | T10: =+E10+H10+K10+N10 -> 11812.219 | U10: =+F10+I10+L10+O10 -> 164024.31
A11: 40873 | B11: 40873 | C11: -1.8 | D11: 0.80138889 | E11: =Effort!F9 -> 2800.7584 | F11: =Harvest!F9 -> 42119.098 | G11: =CPUE!F9 -> 15.038462 | H11: =Effort!H9 -> 880.58636 | I11: =Harvest!H9 -> 12697.487 | J11: =CPUE!H9 -> 14.419355 | K11: =Effort!J9 -> CLOSED | L11: =Harvest!J9 -> CLOSED | M11: =CPUE!J9 -> CLOSED | N11: =Effort!L9 -> 2108.9404 | O11: =Harvest!L9 -> 31634.106 | P11: =CPUE!L9 -> 15 | Q11: CLOSED | R11: CLOSED | S11: CLOSED | T11: =+E11+H11+N11 -> 5790.2852 | U11: =+F11+I11+O11 -> 86450.692
A12: Tide Series Totals | E12: =SUM(E10:E11) -> 7539.1777 | F12: =SUM(F10:F11) -> 106552.74 | G12: =F12/E12 -> 14.133205 | H12: =SUM(H10:H11) -> 2580.3672 | I12: =SUM(I10:I11) -> 34233.143 | J12: =I12/H12 -> 13.266772 | K12: =SUM(K10:K11) -> 3486.4376 | L12: =SUM(L10:L11) -> 50966.213 | M12: =L12/K12 -> 14.618421 | N12: =SUM(N10:N11) -> 3996.5214 | O12: =SUM(O10:O11) -> 58722.901 | P12: =O12/N12 -> 14.693504 | T12: =SUM(T10:T11) -> 17602.504 | U12: =SUM(U10:U11) -> 250475
A13: 40887 | B13: 40873 | C13: -0.5 | D13: 0.77083333 | E13: =Effort!F11 -> 2272.0249 | F13: =Harvest!F11 -> 16446.747 | G13: =CPUE!F11 -> 7.238806 | H13: =Effort!H11 -> 1095.1615 | I13: =Harvest!H11 -> 12244.923 | J13: =CPUE!H11 -> 11.180928 | K13: =Effort!J11 -> 1995.6361 | L13: =Harvest!J11 -> 26597.012 | M13: =CPUE!J11 -> 13.327586 | N13: =Effort!L11 -> 1375.0022 | O13: =Harvest!L11 -> 20682.325 | P13: =CPUE!L11 -> 15.041667 | Q13: CLOSED | R13: CLOSED | S13: CLOSED | T13: =+E13+H13+K13+N13 -> 6737.8247 | U13: =+F13+I13+L13+O13 -> 75971.007
A14: Tide Series Totals | E14: =+E13 -> 2272.0249 | F14: =+F13 -> 16446.747 | G14: =F14/E14 -> 7.238806 | H14: =+H13 -> 1095.1615 | I14: =+I13 -> 12244.923 | J14: =I14/H14 -> 11.180928 | K14: =+K13 -> 1995.6361 | L14: =+L13 -> 26597.012 | M14: =L14/K14 -> 13.327586 | N14: =+N13 -> 1375.0022 | O14: =+O13 -> 20682.325 | P14: =O14/N14 -> 15.041667 | T14: =+E14+H14+K14+N14 -> 6737.8247 | U14: =+F14+I14+L14+O14 -> 75971.007
A15: 40899 | B15: 40899 | C15: -0.9 | D15: 0.69444444 | E15: =Effort!F13 -> 1878.0267 | F15: =Harvest!F13 -> 28321.855 | G15: =CPUE!F13 -> 15.080645 | H15: =Effort!H13 -> 1291.5473 | I15: =Harvest!H13 -> 19334.071 | J15: =CPUE!H13 -> 14.969697 | K15: =Effort!J13 -> 1958.6515 | L15: =Harvest!J13 -> 28993.197 | M15: =CPUE!J13 -> 14.802632 | N15: =Effort!L13 -> 2321.1555 | O15: =Harvest!L13 -> 20682.325 | P15: =CPUE!L13 -> 8.9103576 | Q15: CLOSED | R15: CLOSED | S15: CLOSED | T15: =+E15+H15+K15+N15 -> 7449.381 | U15: =+F15+I15+L15+O15 -> 97331.448
A16: 40900 | B16: 40900 | C16: -1.4 | D16: 0.72847222 | E16: =Effort!F14 -> 2276.949 | F16: =Harvest!F14 -> 19103.921 | G16: =CPUE!F14 -> 8.3901398 | H16: =Effort!H14 -> 1585.2602 | I16: =Harvest!H14 -> 12800.976 | J16: =CPUE!H14 -> 8.075 | K16: =Effort!J14 -> 3056.6523 | L16: =Harvest!J14 -> 13065.69 | M16: =CPUE!J14 -> 4.2745098 | N16: =Effort!L14 -> 2112.8846 | O16: =Harvest!L14 -> 20682.325 | P16: =CPUE!L14 -> 9.7886677 | Q16: CLOSED | R16: CLOSED | S16: CLOSED | T16: =+E16+H16+K16+N16 -> 9031.7462 | U16: =+F16+I16+L16+O16 -> 65652.912
A17: Tide Series Totals | E17: =SUM(E15:E16) -> 4154.9758 | F17: =SUM(F15:F16) -> 47425.776 | G17: =F17/E17 -> 11.414212 | H17: =SUM(H15:H16) -> 2876.8074 | I17: =SUM(I15:I16) -> 32135.047 | J17: =I17/H17 -> 11.170385 | K17: =SUM(K15:K16) -> 5015.3039 | L17: =SUM(L15:L16) -> 42058.887 | M17: =L17/K17 -> 8.3861095 | N17: =SUM(N15:N16) -> 4434.0401 | O17: =SUM(O15:O16) -> 41364.65 | P17: =O17/N17 -> 9.3288852 | T17: =SUM(T15:T16) -> 16481.127 | U17: =SUM(U15:U16) -> 162984.36
A18: 40928 | B18: 40928 | C18: -0.5 | D18: 0.68611111 | E18: =Effort!F16 -> 1104.0844 | F18: =Harvest!F16 -> 7917.0931 | G18: =CPUE!F16 -> 7.1707317 | H18: =Effort!H16 -> 103.15589 | I18: =Harvest!H16 -> 815.86929 | J18: =CPUE!H16 -> 7.9090909 | K18: =Effort!J16 -> 538.66818 | L18: =Harvest!J16 -> 3740.7513 | M18: =CPUE!J16 -> 6.9444444 | N18: =Effort!L16 -> 139.61256 | O18: =Harvest!L16 -> 1861.5008 | P18: =CPUE!L16 -> 13.333333 | Q18: CLOSED | R18: CLOSED | S18: CLOSED | T18: =+E18+H18+K18+N18 -> 1885.521 | U18: =+F18+I18+L18+O18 -> 14335.214
A19: 40929 | B19: 40929 | C19: -0.8 | D19: 0.72013889 | E19: =Effort!F17 -> 1996.7487 | F19: =Harvest!F17 -> 22932.084 | G19: =CPUE!F17 -> 11.484712 | H19: =Effort!H17 -> 933.8591 | I19: =Harvest!H17 -> 12750.925 | J19: =CPUE!H17 -> 13.654014 | K19: =Effort!J17 -> 1672.1442 | L19: =Harvest!J17 -> 20714.112 | M19: =CPUE!J17 -> 12.387755 | N19: =Effort!L17 -> 1696.9818 | O19: =Harvest!L17 -> 30077.178 | P19: =CPUE!L17 -> 17.723925 | Q19: CLOSED | R19: CLOSED | S19: CLOSED | T19: =+E19+H19+K19+N19 -> 6299.7337 | U19: =+F19+I19+L19+O19 -> 86474.3
A20: Tide Series Totals | E20: =SUM(E18:E19) -> 3100.8331 | F20: =SUM(F18:F19) -> 30849.177 | G20: =F20/E20 -> 9.9486739 | H20: =SUM(H18:H19) -> 1037.015 | I20: =SUM(I18:I19) -> 13566.795 | J20: =I20/H20 -> 13.082544 | K20: =SUM(K18:K19) -> 2210.8123 | L20: =SUM(L18:L19) -> 24454.864 | M20: =L20/K20 -> 11.061483 | N20: =SUM(N18:N19) -> 1836.5944 | O20: =SUM(O18:O19) -> 31938.679 | P20: =O20/N20 -> 17.390165 | T20: =SUM(T18:T19) -> 8185.2548 | U20: =SUM(U18:U19) -> 100809.51
A21: 40957 | B21: 40957 | C21: 0 | D21: 0.67569444 | E21: =Effort!F19 -> 6838.8807 | F21: =Harvest!F19 -> 57532.084 | G21: =CPUE!F19 -> 8.4125 | H21: =Effort!H19 -> 1858.2378 | I21: =Harvest!H19 -> 11362.667 | J21: =CPUE!H19 -> 6.1147541 | K21: =Effort!J19 -> CLOSED | L21: =Harvest!J19 -> CLOSED | M21: =CPUE!J19 -> CLOSED | N21: =Effort!L19 -> 6276.7171 | O21: =Harvest!L19 -> 51488.695 | P21: =CPUE!L19 -> 8.203125 | Q21: CLOSED | R21: CLOSED | S21: CLOSED | T21: =+E21+H21+N21 -> 14973.836 | U21: =+F21+I21+O21 -> 120383.45
A22: 40958 | B22: 40958 | C22: -0.2 | D22: 0.70833333 | E22: =Effort!F20 -> 10016.606 | F22: =Harvest!F20 -> 149317.31 | G22: =CPUE!F20 -> 14.906977 | H22: =Effort!H20 -> 4572.3606 | I22: =Harvest!H20 -> 44173.654 | J22: =CPUE!H20 -> 9.6610169 | K22: CLOSED | L22: CLOSED | M22: CLOSED | N22: =Effort!L20 -> 7752.8048 | O22: =Harvest!L20 -> 109323.26 | P22: =CPUE!L20 -> 14.101124 | Q22: CLOSED | R22: CLOSED | S22: CLOSED | T22: =+E22+H22+N22 -> 22341.772 | U22: =+F22+I22+O22 -> 302814.23
A23: Tide Series Totals | E23: =SUM(E21:E22) -> 16855.487 | F23: =SUM(F21:F22) -> 206849.4 | G23: =F23/E23 -> 12.271933 | H23: =SUM(H21:H22) -> 6430.5984 | I23: =SUM(I21:I22) -> 55536.321 | J23: =I23/H23 -> 8.6362601 | N23: =SUM(N21:N22) -> 14029.522 | O23: =SUM(O21:O22) -> 160811.95 | P23: =O23/N23 -> 11.462397 | T23: =SUM(T21:T22) -> 37315.607 | U23: =SUM(U21:U22) -> 423197.67
A24: 40978 | B24: 40978 | C24: -0.3 | D24: 0.31875 | E24: =Effort!F22 -> 5360.6629 | F24: =Harvest!F22 -> 61966.711 | G24: =CPUE!F22 -> 11.559524 | H24: =Effort!H22 -> 1595.7792 | I24: =Harvest!H22 -> 22781.124 | J24: =CPUE!H22 -> 14.275862 | K24: =Effort!J22 -> 3766.1675 | L24: =Harvest!J22 -> 48063.471 | M24: =CPUE!J22 -> 12.761905 | N24: =Effort!L22 -> 1997.7925 | O24: =Harvest!L22 -> 24036.932 | P24: =CPUE!L22 -> 12.031746 | Q24: CLOSED | R24: CLOSED | S24: CLOSED | T24: =+E24+H24+K24+N24 -> 12720.402 | U24: =+F24+I24+L24+O24 -> 156848.24
A25: 40979 | B25: 40979 | C25: -0.4 | D25: 0.39444444 | E25: =Effort!F23 -> 6486.3442 | F25: =Harvest!F23 -> 72871.274 | G25: =CPUE!F23 -> 11.234568 | H25: =Effort!H23 -> 1716.2694 | I25: =Harvest!H23 -> 25083.937 | J25: =CPUE!H23 -> 14.615385 | K25: =Effort!J23 -> 3272.7311 | L25: =Harvest!J23 -> 47474.802 | M25: =CPUE!J23 -> 14.506173 | N25: =Effort!L23 -> 1959.798 | O25: =Harvest!L23 -> 24319.311 | P25: =CPUE!L23 -> 12.409091 | Q25: CLOSED | R25: CLOSED | S25: CLOSED | T25: =+E25+H25+K25+N25 -> 13435.143 | U25: =+F25+I25+L25+O25 -> 169749.33
A26: Tide Series Totals | E26: =SUM(E24:E25) -> 11847.007 | F26: =SUM(F24:F25) -> 134837.99 | G26: =F26/E26 -> 11.381607 | H26: =SUM(H24:H25) -> 3312.0486 | I26: =SUM(I24:I25) -> 47865.061 | J26: =I26/H26 -> 14.451799 | K26: =SUM(K24:K25) -> 7038.8986 | L26: =SUM(L24:L25) -> 95538.273 | M26: =L26/K26 -> 13.572901 | N26: =SUM(N24:N25) -> 3957.5905 | O26: =SUM(O24:O25) -> 48356.243 | P26: =O26/N26 -> 12.218607 | T26: =SUM(T24:T25) -> 26155.545 | U26: =SUM(U24:U25) -> 326597.56
A27: 40992 | B27: 40992 | C27: 0.3 | D27: 0.35069444 | E27: =Effort!F25 -> 5584.755 | F27: =Harvest!F25 -> 81215.59 | G27: =CPUE!F25 -> 14.542373 | H27: =Effort!H25 -> 1928.3926 | I27: =Harvest!H25 -> 26562.929 | J27: =CPUE!H25 -> 13.774648 | K27: =Effort!J25 -> 4043.0809 | L27: =Harvest!J25 -> 59039.348 | M27: =CPUE!J25 -> 14.602564 | N27: =Effort!L25 -> 2819.0842 | O27: =Harvest!L25 -> 42122.044 | P27: =CPUE!L25 -> 14.941748 | Q27: CLOSED | R27: CLOSED | S27: CLOSED | T27: =+E27+H27+K27+N27 -> 14375.313 | U27: =+F27+I27+L27+O27 -> 208939.91
A28: 40993 | B28: 40993 | C28: 0.3 | D28: 0.37430556 | E28: =Effort!F26 -> 5766.0008 | F28: =Harvest!F26 -> 49011.007 | G28: =CPUE!F26 -> 8.5 | H28: =Effort!H26 -> 2214.3078 | I28: =Harvest!H26 -> 32734.85 | J28: =CPUE!H26 -> 14.783333 | K28: =Effort!J26 -> CLOSED | L28: =Harvest!J26 -> CLOSED | M28: =CPUE!J26 -> CLOSED | N28: =Effort!L26 -> 3677.6779 | O28: =Harvest!L26 -> 54519.961 | P28: =CPUE!L26 -> 14.824561 | Q28: CLOSED | R28: CLOSED | S28: CLOSED | T28: =+E28+H28+N28 -> 11657.986 | U28: =+F28+I28+O28 -> 136265.82
A29: Tide Series Totals | E29: =SUM(E27:E28) -> 11350.756 | F29: =SUM(F27:F28) -> 130226.6 | G29: =F29/E29 -> 11.472945 | H29: =SUM(H27:H28) -> 4142.7003 | I29: =SUM(I27:I28) -> 59297.779 | J29: =I29/H29 -> 14.313799 | K29: =SUM(K27:K28) -> 4043.0809 | L29: =SUM(L27:L28) -> 59039.348 | M29: =L29/K29 -> 14.602564 | N29: =SUM(N27:N28) -> 6496.762 | O29: =SUM(O27:O28) -> 96642.005 | P29: =O29/N29 -> 14.875411 | T29: =SUM(T27:T28) -> 26033.299 | U29: =SUM(U27:U28) -> 345205.73
A30: 41006 | B30: 41006 | C30: -1.2 | D30: 0.31666667 | E30: =Effort!F28 -> 14020.804 | F30: =Harvest!F28 -> 210312.07 | G30: =CPUE!F28 -> 15 | H30: =Effort!H28 -> 5785.3129 | I30: =Harvest!H28 -> 86779.693 | J30: =CPUE!H28 -> 15 | K30: =Effort!J28 -> 4040.125 | L30: =Harvest!J28 -> 60601.874 | M30: =CPUE!J28 -> 15 | N30: =Effort!L28 -> 4530.8005 | O30: =Harvest!L28 -> 67693.737 | P30: =CPUE!L28 -> 14.940789 | Q30: =+Effort!N28 -> 3872.2597 | R30: =+Harvest!N28 -> 3872.2597 | S30: =+CPUE!N28 -> 1 | T30: =+E30+H30+K30+N30+Q30 -> 32249.302 | U30: =+F30+I30+L30+O30+R30 -> 429259.63
A31: 41007 | B31: 41007 | C31: -1.5 | D31: 0.34930556 | E31: =Effort!F29 -> 10042.051 | F31: =Harvest!F29 -> 137285.41 | G31: =CPUE!F29 -> 13.671053 | H31: =Effort!H29 -> 2386.62 | I31: =Harvest!H29 -> 35799.299 | J31: =CPUE!H29 -> 15 | K31: =Effort!J29 -> CLOSED | L31: =Harvest!J29 -> CLOSED | M31: =CPUE!J29 -> CLOSED | N31: =Effort!L29 -> 8013.0084 | O31: =Harvest!L29 -> 114608.07 | P31: =CPUE!L29 -> 14.302752 | Q31: =+Effort!N29 -> 312.04958 | R31: =+Harvest!N29 -> 312.04958 | S31: =+CPUE!N29 -> 1 | T31: =+E31+H31+N31+Q31 -> 20753.729 | U31: =+F31+I31+O31+R31 -> 288004.84
A32: 41008 | B32: 41008 | C32: -1.5 | D32: 0.38263889 | E32: =Effort!F30 -> 5594.3697 | F32: =Harvest!F30 -> 78053.182 | G32: =CPUE!F30 -> 13.952096 | H32: =Effort!H30 -> 2354.8447 | I32: =Harvest!H30 -> 35461.19 | J32: =CPUE!H30 -> 15.058824 | K32: =Effort!J30 -> CLOSED | L32: =Harvest!J30 -> CLOSED | M32: =CPUE!J30 -> CLOSED | N32: =Effort!L30 -> CLOSED | O32: =Harvest!L30 -> CLOSED | P32: =CPUE!L30 -> CLOSED | Q32: =+Effort!N30 -> 698.15319 | R32: =+Harvest!N30 -> 698.15319 | S32: =+CPUE!N30 -> 1 | T32: =+E32+H32+Q32 -> 8647.3675 | U32: =+F32+I32+R32 -> 114212.52
A33: Tide Series Totals | E33: =SUM(E30:E32) -> 29657.225 | F33: =SUM(F30:F32) -> 425650.66 | G33: =F33/E33 -> 14.352343 | H33: =SUM(H30:H32) -> 10526.778 | I33: =SUM(I30:I32) -> 158040.18 | J33: =I33/H33 -> 15.013159 | K33: =SUM(K30:K32) -> 4040.125 | L33: =SUM(L30:L32) -> 60601.874 | M33: =L33/K33 -> 15 | N33: =SUM(N30:N32) -> 12543.809 | O33: =SUM(O30:O32) -> 182301.81 | P33: =O33/N33 -> 14.53321 | Q33: =SUM(Q30:Q32) -> 4882.4624 | R33: =SUM(R30:R32) -> 4882.4624 | S33: =R33/Q33 -> 1 | T33: =SUM(T30:T32) -> 61650.399 | U33: =SUM(U30:U32) -> 831476.99
A34: 41020 | B34: 41020 | C34: -0.3 | D34: 0.31111111 | E34: =Effort!F32 -> 6010.9723 | F34: =Harvest!F32 -> 90164.585 | G34: =CPUE!F32 -> 15 | H34: =Effort!H32 -> 3487.894 | I34: =Harvest!H32 -> 52318.41 | J34: =CPUE!H32 -> 15 | K34: =Effort!J32 -> CLOSED | L34: =Harvest!J32 -> CLOSED | M34: =CPUE!J32 -> CLOSED | N34: =Effort!L32 -> CLOSED | O34: =Harvest!L32 -> CLOSED | P34: =CPUE!L32 -> CLOSED | Q34: =+Effort!N32 -> CLOSED | R34: =+Harvest!N32 -> CLOSED | S34: =+CPUE!N32 -> CLOSED | T34: =+E34+H34 -> 9498.8663 | U34: =+F34+I34 -> 142482.99
A35: 41021 | B35: 41021 | C35: -0.4 | D35: 0.33402778 | E35: =Effort!F33 -> 5904.4158 | F35: =Harvest!F33 -> 88566.237 | G35: =CPUE!F33 -> 15 | H35: =Effort!H33 -> 2704.6992 | I35: =Harvest!H33 -> 40570.487 | J35: =CPUE!H33 -> 15 | K35: =Effort!J33 -> CLOSED | L35: =Harvest!J33 -> CLOSED | M35: =CPUE!J33 -> CLOSED | N35: =Effort!L33 -> CLOSED | O35: =Harvest!L33 -> CLOSED | P35: =CPUE!L33 -> CLOSED | Q35: =+Effort!N33 -> CLOSED | R35: =+Harvest!N33 -> CLOSED | S35: =+CPUE!N33 -> CLOSED | T35: =+E35+H35 -> 8609.1149 | U35: =+F35+I35 -> 129136.72
A36: 41022 | B36: 41021 | C36: -0.4 | D36: 0.35763889 | E36: =Effort!F34 -> 3272.837 | F36: =Harvest!F34 -> 49092.556 | G36: =CPUE!F34 -> 15 | H36: =Effort!H34 -> 1700.939 | I36: =Harvest!H34 -> 25514.085 | J36: =CPUE!H34 -> 15 | K36: =Effort!J34 -> 1618.5332 | L36: =Harvest!J34 -> 24277.997 | M36: =CPUE!J34 -> 15 | N36: =Effort!L34 -> 1256.4545 | O36: =Harvest!L34 -> 18846.817 | P36: =CPUE!L34 -> 15 | Q36: =+Effort!N34 -> CLOSED | R36: =+Harvest!N34 -> CLOSED | S36: =+CPUE!N34 -> CLOSED | T36: =+E36+H36+K36+N36 -> 7848.7636 | U36: =+F36+I36+L36+O36 -> 117731.45
A37: Tide Series Totals | E37: =SUM(E34:E36) -> 15188.225 | F37: =SUM(F34:F36) -> 227823.38 | G37: =F37/E37 -> 15 | H37: =SUM(H34:H36) -> 7893.5321 | I37: =SUM(I34:I36) -> 118402.98 | J37: =I37/H37 -> 15 | K37: =SUM(K34:K36) -> 1618.5332 | L37: =SUM(L34:L36) -> 24277.997 | M37: =L37/K37 -> 15 | N37: =SUM(N34:N36) -> 1256.4545 | O37: =SUM(O34:O36) -> 18846.817 | P37: =O37/N37 -> 15 | T37: =+E37+H37+K37+N37 -> 25956.745 | U37: =+F37+I37+L37+O37 -> 389351.17
A38: 41034 | B38: 41034 | C38: -1.5 | D38: 0.27152778 | E38: =Effort!F36 -> CLOSED | F38: =Harvest!F36 -> CLOSED | G38: =CPUE!F36 -> CLOSED | H38: =Effort!H36 -> 3902.6236 | I38: =Harvest!H36 -> 58539.354 | J38: =CPUE!H36 -> 15 | K38: =Effort!J36 -> CLOSED | L38: =Harvest!J36 -> CLOSED | M38: =CPUE!J36 -> CLOSED | N38: =Effort!L36 -> CLOSED | O38: =Harvest!L36 -> CLOSED | P38: =CPUE!L36 -> CLOSED | Q38: =+Effort!N36 -> CLOSED | R38: =+Harvest!N36 -> CLOSED | S38: =+CPUE!N36 -> CLOSED | T38: =+H38 -> 3902.6236 | U38: =+I38 -> 58539.354
A39: 41035 | B39: 41035 | C39: -2.1 | D39: 0.30486111 | E39: =Effort!F37 -> CLOSED | F39: =Harvest!F37 -> CLOSED | G39: =CPUE!F37 -> CLOSED | H39: =Effort!H37 -> 3594.8535 | I39: =Harvest!H37 -> 53922.802 | J39: =CPUE!H37 -> 15 | K39: =Effort!J37 -> CLOSED | L39: =Harvest!J37 -> CLOSED | M39: =CPUE!J37 -> CLOSED | N39: =Effort!L37 -> CLOSED | O39: =Harvest!L37 -> CLOSED | P39: =CPUE!L37 -> CLOSED | Q39: =+Effort!N37 -> CLOSED | R39: =+Harvest!N37 -> CLOSED | S39: =+CPUE!N37 -> CLOSED | T39: =+H39 -> 3594.8535 | U39: =+I39 -> 53922.802
A40: 41036 | B40: 41036 | C40: -2.3 | D40: 0.33819444 | E40: =Effort!F38 -> CLOSED | F40: =Harvest!F38 -> CLOSED | G40: =CPUE!F38 -> CLOSED | H40: =Effort!H38 -> 2389.4747 | I40: =Harvest!H38 -> 35842.121 | J40: =CPUE!H38 -> 15 | K40: =Effort!J38 -> CLOSED | L40: =Harvest!J38 -> CLOSED | M40: =CPUE!J38 -> CLOSED | N40: =Effort!L38 -> CLOSED | O40: =Harvest!L38 -> CLOSED | P40: =CPUE!L38 -> CLOSED | Q40: =+Effort!N38 -> CLOSED | R40: =+Harvest!N38 -> CLOSED | S40: =+CPUE!N38 -> CLOSED | T40: =+H40 -> 2389.4747 | U40: =+I40 -> 35842.121
...

Sheet Tribal Update
A1: 2011-2012 State (non-Indian) Recreational Razor Clam Effort, Harvest and CPUE totals - PRELIMINARY
E2: COPALIS | I2: MOCROCKS | M2: KALALOCH | Q2: DAILY TOTALS
A3: DATE | B3: DAY | C3: TIDE | D3: TIME | E3: Effort | F3: Harvest | G3: CPUE | H3: Size (mm) | I3: Effort | J3: Harvest | K3: CPUE | L3: Size (mm) | M3: Effort | N3: Harvest | O3: CPUE | P3: Size (mm) | Q3: Effort | R3: Harvest
A4: 40844 | B4: 40844 | C4: -1.8 | D4: 0.85277778 | E4: 2125.5961 | F4: 27840.125 | G4: =+F4/E4 -> 13.097561 | I4: 866.87382 | J4: 12452.976 | K4: =+J4/I4 -> 14.365385 | M4: =+'Summary Table'!Q5 -> CLOSED | N4: =+'Summary Table'!R5 -> CLOSED | O4: =+'Summary Table'!S5 -> CLOSED | Q4: =+E4+I4 -> 2992.4699 | R4: =+F4+J4 -> 40293.101
A5: 40845 | B5: 40845 | C5: -1.5 | D5: 0.88680556 | E5: 1919.1157 | F5: 28786.736 | G5: =+F5/E5 -> 15 | I5: 1174.4697 | J5: 15085.861 | K5: =+J5/I5 -> 12.844828 | M5: CLOSED | N5: CLOSED | O5: CLOSED | Q5: =+E5+I5 -> 3093.5854 | R5: =+F5+J5 -> 43872.596
A6: Tide Series Totals | E6: =SUM(E4:E5) -> 4044.7118 | F6: =SUM(F4:F5) -> 56626.86 | G6: =+F6/E6 -> 14.000221 | H6: 105 | I6: =SUM(I4:I5) -> 2041.3435 | J6: =SUM(J4:J5) -> 27538.837 | K6: =+J6/I6 -> 13.490545 | L6: 109.58 | Q6: =+E6+I6 -> 6086.0553 | R6: =+F6+J6 -> 84165.697
A7: 40858 | B7: =+A7 -> 40858 | C7: -0.4 | D7: 0.78333333 | E7: CLOSED | F7: CLOSED | G7: CLOSED | I7: 1300.9052 | J7: 18227.455 | K7: 14.011364 | M7: CLOSED | N7: CLOSED | O7: CLOSED | Q7: =+I7 -> 1300.9052 | R7: =+J7 -> 18227.455
A8: 40859 | B8: =+A8 -> 40859 | C8: -0.4 | D8: 0.80763889 | E8: CLOSED | F8: CLOSED | G8: CLOSED | I8: 1349.4658 | J8: 14583.986 | K8: 10.807229 | M8: CLOSED | N8: CLOSED | O8: CLOSED | Q8: =+I8 -> 1349.4658 | R8: =+J8 -> 14583.986
A9: Tide Series Totals | I9: 2650.371 | J9: 32811.441 | K9: 12.379943 | L9: 108.54 | Q9: =I9 -> 2650.371 | R9: =J9 -> 32811.441
A10: 40872 | B10: 40872 | C10: -1.9 | D10: 0.76875 | E10: 2591.1949 | F10: 37879.179 | G10: 14.618421 | I10: 1522.754 | J10: 21853.14 | K10: 14.351064 | M10: CLOSED | N10: CLOSED | O10: CLOSED | Q10: =+E10+I10 -> 4113.949 | R10: =+F10+J10 -> 59732.319
A11: 40873 | B11: 40873 | C11: -1.8 | D11: 0.80138889 | E11: CLOSED | F11: CLOSED | G11: CLOSED | I11: 1731.5184 | J11: 25972.776 | K11: 15 | M11: CLOSED | N11: CLOSED | O11: CLOSED | Q11: =+I11 -> 1731.5184 | R11: =+J11 -> 25972.776
A12: Tide Series Totals | E12: =SUM(E10:E11) -> 2591.1949 | F12: =SUM(F10:F11) -> 37879.179 | G12: =+F12/E12 -> 14.618421 | H12: 110.27 | I12: =SUM(I10:I11) -> 3254.2724 | J12: =SUM(J10:J11) -> 47825.916 | K12: =+J12/I12 -> 14.696347 | L12: 116.29 | Q12: =SUM(Q10:Q11) -> 5845.4673 | R12: =SUM(R10:R11) -> 85705.094
A13: 40887 | B13: 40873 | C13: -0.5 | D13: 0.77083333 | E13: 1489.7179 | F13: 19854.344 | G13: 13.327586 | I13: 1149.3003 | J13: 17287.393 | K13: 15.041667 | M13: CLOSED | N13: CLOSED | O13: CLOSED | Q13: =+E13+I13 -> 2639.0182 | R13: =+F13+J13 -> 37141.736
A14: Tide Series Totals | E14: =SUM(E13) -> 1489.7179 | F14: =SUM(F13) -> 19854.344 | G14: =+F14/E14 -> 13.327586 | H14: 108.23 | I14: =SUM(I13) -> 1149.3003 | J14: =SUM(J13) -> 17287.393 | K14: =+J14/I14 -> 15.041667 | L14: 116.44 | Q14: =SUM(Q13) -> 2639.0182 | R14: =SUM(R13) -> 37141.736
A15: 40899 | B15: 40899 | C15: -0.9 | D15: 0.69444444 | E15: =+'Summary Table'!K15 -> 1958.6515 | F15: =+'Summary Table'!L15 -> 28993.197 | G15: =+'Summary Table'!M15 -> 14.802632 | I15: =+'Summary Table'!N15 -> 2321.1555 | J15: =+'Summary Table'!O15 -> 20682.325 | K15: =+'Summary Table'!P15 -> 8.9103576 | M15: CLOSED | N15: CLOSED | O15: CLOSED | Q15: =+E15+I15 -> 4279.807 | R15: =+F15+J15 -> 49675.522
A16: 40900 | B16: 40900 | C16: -1.4 | D16: 0.72847222 | E16: =+'Summary Table'!K16 -> 3056.6523 | F16: =+'Summary Table'!L16 -> 13065.69 | G16: =+'Summary Table'!M16 -> 4.2745098 | I16: =+'Summary Table'!N16 -> 2112.8846 | J16: =+'Summary Table'!O16 -> 20682.325 | K16: =+'Summary Table'!P16 -> 9.7886677 | M16: CLOSED | N16: CLOSED | O16: CLOSED | Q16: =+E16+I16 -> 5169.5369 | R16: =+F16+J16 -> 33748.016
A17: Tide Series Totals | E17: =SUM(E15:E16) -> 5015.3039 | F17: =SUM(F15:F16) -> 42058.887 | G17: =+F17/E17 -> 8.3861095 | H17: 116.56 | I17: =SUM(I15:I16) -> 4434.0401 | J17: =SUM(J15:J16) -> 41364.65 | K17: =+J17/I17 -> 9.3288852 | L17: 117.43 | Q17: =SUM(Q15:Q16) -> 9449.3439 | R17: =SUM(R15:R16) -> 83423.538
A18: 40928 | B18: 40928 | C18: -0.5 | D18: 0.68611111 | E18: 348.01619 | F18: 1615.7895 | G18: 4.6428571 | I18: 312.79636 | J18: 4170.6181 | K18: 13.333333 | M18: CLOSED | N18: CLOSED | O18: CLOSED | Q18: =+E18+I18 -> 660.81255 | R18: =+F18+J18 -> 5786.4076
A19: 40929 | B19: 40929 | C19: -0.8 | D19: 0.72013889 | E19: 1249.0207 | F19: 15472.562 | G19: 12.387755 | I19: 1062.2267 | J19: 12088.889 | K19: 11.380706 | M19: CLOSED | N19: CLOSED | O19: CLOSED | Q19: =+E19+I19 -> 2311.2474 | R19: =+F19+J19 -> 27561.451
A20: Tide Series Totals | E20: 1597.0368 | F20: 17088.351 | G20: 10.700036 | I20: 1375.0231 | J20: 16259.507 | K20: 11.824898 | Q20: =SUM(Q18:Q19) -> 2972.0599 | R20: =SUM(R18:R19) -> 33347.859
A21: 40957 | B21: 40957 | C21: 0 | D21: 0.67569444 | E21: CLOSED | F21: CLOSED | G21: CLOSED | I21: 4153.3205 | J21: 34070.207 | K21: 8.203125 | M21: CLOSED | N21: CLOSED | O21: CLOSED | Q21: =+I21 -> 4153.3205 | R21: =+J21 -> 34070.207
A22: 40958 | B22: 40958 | C22: -0.2 | D22: 0.70833333 | E22: CLOSED | F22: CLOSED | G22: CLOSED | I22: 5840.6429 | J22: 82359.627 | K22: 14.101124 | M22: CLOSED | N22: CLOSED | O22: CLOSED | Q22: =+I22 -> 5840.6429 | R22: =+J22 -> 82359.627
A23: Tide Series Totals | I23: 9993.9633 | J23: 116429.83 | K23: 11.650016 | L23: 112.99 | Q23: =SUM(Q21:Q22) -> 9993.9633 | R23: =SUM(R21:R22) -> 116429.83
A24: 40978 | B24: 40978 | C24: -0.3 | D24: 0.31875 | E24: 2590.0133 | F24: 33053.503 | G24: 12.761905 | I24: 1615.8831 | J24: 19441.895 | K24: 12.031746 | M24: CLOSED | N24: CLOSED | O24: CLOSED | Q24: =+E24+I24 -> 4205.8964 | R24: =+F24+J24 -> 52495.398
A25: 40979 | B25: 40979 | C25: -0.4 | D25: 0.39444444 | E25: 2492.0717 | F25: 36150.422 | G25: 14.506173 | I25: 1622.5429 | J25: 20134.282 | K25: 12.409091 | M25: CLOSED | N25: CLOSED | O25: CLOSED | Q25: =+E25+I25 -> 4114.6145 | R25: =+F25+J25 -> 56284.704
A26: Tide Series Totals | E26: 5082.0849 | F26: 69203.925 | G26: 13.617231 | H26: 115.32 | I26: 3238.426 | J26: 39576.177 | K26: 12.220806 | L26: 116.55 | Q26: =SUM(Q24:Q25) -> 8320.5109 | R26: =SUM(R24:R25) -> 108780.1
A27: 40992 | B27: 40992 | C27: 0.3 | D27: 0.35069444 | E27: 3354.6807 | F27: 48986.94 | G27: 14.602564 | I27: 2340.7165 | J27: 34974.395 | K27: 14.941748 | M27: CLOSED | N27: CLOSED | O27: CLOSED | Q27: =+E27+I27 -> 5695.3972 | R27: =+F27+J27 -> 83961.335
A28: 40993 | B28: 40993 | C28: 0.3 | D28: 0.37430556 | E28: CLOSED | F28: CLOSED | G28: CLOSED | I28: 3200.0793 | J28: 47439.772 | K28: 14.824561 | M28: CLOSED | N28: CLOSED | O28: CLOSED | Q28: =+I28 -> 3200.0793 | R28: =+J28 -> 47439.772
A29: Tide Series Totals | E29: 3354.6807 | F29: 48986.94 | G29: 14.602564 | H29: 110.45 | I29: 5540.7958 | J29: 82414.167 | K29: 14.874067 | L29: 116.94 | Q29: =SUM(Q27:Q28) -> 8895.4765 | R29: =SUM(R27:R28) -> 131401.11
A30: 41006 | B30: 41006 | C30: -1.2 | D30: 0.31666667 | E30: 3211.9089 | F30: 48178.633 | G30: 15 | I30: 3761.9733 | J30: 56206.851 | K30: 14.940789 | M30: 780.71472 | N30: 2187.5472 | O30: 2.8019802 | Q30: =+E30+I30+M30 -> 7754.5969 | R30: =+F30+J30+N30 -> 106573.03
A31: 41007 | B31: 41007 | C31: -1.5 | D31: 0.34930556 | E31: CLOSED | F31: CLOSED | G31: CLOSED | I31: 6468.2644 | J31: 92513.984 | K31: 14.302752 | M31: 305.36799 | N31: 214.88859 | O31: 0.7037037 | Q31: =+I31+M31 -> 6773.6324 | R31: =+J31+N31 -> 92728.873
A32: 41008 | B32: 41008 | C32: -1.5 | D32: 0.38263889 | E32: CLOSED | F32: CLOSED | G32: CLOSED | I32: CLOSED | J32: CLOSED | K32: CLOSED | M32: 197.06543 | N32: 549.39454 | O32: 2.7878788 | Q32: =+M32 -> 197.06543 | R32: =+N32 -> 549.39454
A33: Tide Series Totals | E33: 3211.9089 | F33: 48178.633 | G33: 15 | H33: 121.5 | I33: 10230.238 | J33: 148720.84 | K33: 14.537378 | L33: 119.59004 | M33: 1283.1481 | N33: 2951.8303 | O33: 2.3004595 | P33: 98.97 | Q33: =SUM(Q30:Q32) -> 14725.295 | R33: =SUM(R30:R32) -> 199851.3
A34: SEASON TOTALS: | E34: =+E6+E9+E12+E14+E17+E20+E23+E26+E29+E33 -> 26386.64 | F34: =+F6+F9+F12+F14+F17+F20+F23+F26+F29+F33 -> 339877.12 | G34: =F34/E34 -> 12.880652 | I34: =+I6+I9+I12+I14+I17+I20+I23+I26+I29+I33 -> 43907.773 | J34: =+J6+J9+J12+J14+J17+J20+J23+J26+J29+J33 -> 570228.76 | K34: =J34/I34 -> 12.986966 | M34: =+M6+M9+M12+M14+M17+M20+M23+M26+M29+M33 -> 1283.1481 | N34: =+N6+N9+N12+N14+N17+N20+N23+N26+N29+N33 -> 2951.8303 | Q34: =+Q6+Q9+Q12+Q14+Q17+Q20+Q23+Q26+Q29+Q33 -> 71577.561 | R34: =+R6+R9+R12+R14+R17+R20+R23+R26+R29+R33 -> 913057.71
A35: Wastage: | F35: =+Harvest!J42 -> 3076 | J35: =+Harvest!L42 -> 8518 | R35: =F35+J35+N35 -> 11594
A36: Season total, including Wastage | F36: =F34+F35 -> 342953.12 | J36: =J34+J35 -> 578746.76 | N36: =N34+N35 -> 2951.8303 | R36: =F36+J36+N36 -> 924651.71
A37: % of TAC Harvested: | F37: =Harvest!J45 -> 1.2555804 | J37: =Harvest!L45 -> 1.2261117 | N37: =Harvest!N45 -> 0.033774524
A38: Clams left in TAC: | F38: =Harvest!J46 -> -94915.678 | J38: =Harvest!L46 -> -136985.42 | N38: =Harvest!N46 -> 139678.05

Sheet TAC
A1: 2009 FALL - 2010 SPRING NON-TRIBAL TOTAL ALLOWABLE CATCH (TAC)
B3: 2011 - 2012 | C3: 2010 - 2011
A4: LONG BEACH | B4: 1094641.4 | C4: 1276247.7
A5: TWIN HARBORS | B5: 616314.31 | C5: 845427.67
A6: COPALIS | B6: 371373.04 | C6: 683167.41
A7: MOCROCKS | B7: 605830.7 | C7: 545586.69
A8: KALALOCH | B8: 144560.51 | C8: 258924.12
A9: COASTWIDE TAC | B9: =SUM(B4:B8) -> 2832720 | C9: =SUM(C4:C8) -> 3609353.6

Sheet Twin Harbors Data
A1: Date | B1: LocationID | C1: CPUE | D1: CorrectionFactor | E1: Calc People | F1: EstCorEffort | G1: TotHarvest
A2: 40458 | B2: 21100 | C2: 14.648148 | D2: 1.3793 | E2: 3 | F2: 4 | G2: 59
A3: 40458 | B3: 21200 | C3: 14.8 | D3: 1.3793 | E3: 755 | F3: 1041 | G3: 15249
A4: 40458 | B4: 22307 | C4: 14.545455 | D4: 1.3793 | E4: 653 | F4: 901 | G4: 13198
A5: 40458 | B5: 22309 | C5: 14.647059 | D5: 1.3793 | E5: 607 | F5: 837 | G5: 12260
A6: 40459 | B6: 21100 | C6: 14.666667 | D6: 1.3793 | E6: 12 | F6: 15 | G6: 220
A7: 40459 | B7: 21200 | C7: 15 | D7: 1.3793 | E7: 547 | F7: 687 | G7: 10076
A8: 40459 | B8: 22307 | C8: 13.857143 | D8: 1.3793 | E8: 443 | F8: 556 | G8: 8155
A9: 40459 | B9: 22309 | C9: 14.956522 | D9: 1.3793 | E9: 447 | F9: 561 | G9: 8391
A10: 40461 | B10: 21100 | C10: 10.16 | D10: 1.3793 | E10: 0 | F10: 0 | G10: 0
A11: 40461 | B11: 21200 | C11: 9.7142857 | D11: 1.3793 | E11: 254 | F11: 337 | G11: 3424
A12: 40461 | B12: 22307 | C12: 10.142857 | D12: 1.3793 | E12: 326 | F12: 432 | G12: 4389
A13: 40461 | B13: 22309 | C13: 11 | D13: 1.3793 | E13: 216 | F13: 286 | G13: 2906
... A53: 40563 | B53: 22309 | C53: 0.28571429 | D53: 1.5346667 | E53: 110 | F53: 169 | G53: 48
A54: 40564 | B54: 21100 | C54: 3.0338983 | D54: 1.534667 | E54: 0 | F54: =+E54*D54 -> 0 | G54: =+F54*C54 -> 0
A55: 40564 | B55: 21200 | C55: 3.0338983 | D55: 1.534667 | E55: 158.5625 | F55: =+E55*D55 -> 243.34064 | G55: =+F55*C55 -> 738.27074
A56: 40564 | B56: 22307 | C56: 3.0338983 | D56: 1.534667 | E56: 199.125 | F56: =+E56*D56 -> 305.59057 | G56: =+F56*C56 -> 927.1307
A57: 40564 | B57: 22309 | C57: 3.0338983 | D57: 1.534667 | E57: 55.3125 | F57: =+E57*D57 -> 84.886268 | G57: =+F57*C57 -> 257.53631
A58: 40565 | B58: 21100 | C58: 7.66 | D58: 1.46735 | E58: 0 | F58: 0 | G58: 0
A59: 40565 | B59: 21200 | C59: 4.7777778 | D59: 1.46735 | E59: 327 | F59: 428 | G59: 2045
A60: 40565 | B60: 22307 | C60: 12.090909 | D60: 1.46735 | E60: 653 | F60: 856 | G60: 6557
A61: 40565 | B61: 22309 | C61: 3.1 | D61: 1.46735 | E61: 493 | F61: 646 | G61: 4948
A62: 40591 | B62: 21100 | C62: 13.84507 | D62: 1.4254667 | E62: 0 | F62: 0 | G62: 0
A63: 40591 | B63: 21200 | C63: 13.916667 | D63: 1.4254667 | E63: 437 | F63: 606 | G63: 8434
A64: 40591 | B64: 22307 | C64: 12.823529 | D64: 1.4254667 | E64: 461 | F64: 639 | G64: 8847
A65: 40591 | B65: 22309 | C65: 14.666667 | D65: 1.4254667 | E65: 317 | F65: 439 | G65: 6439
A66: 40621 | B66: 21100 | C66: 5.4328358 | D66: 1.46735 | E66: 37 | F66: 47 | G66: 255
A67: 40621 | B67: 21200 | C67: 3.8333333 | D67: 1.46735 | E67: 776 | F67: 978 | G67: 5313
A68: 40621 | B68: 22307 | C68: 8.1333333 | D68: 1.46735 | E68: 865 | F68: 1090 | G68: 5922
A69: 40621 | B69: 22309 | C69: 6.5 | D69: 1.46735 | E69: 88 | F69: 111 | G69: 722
... A81: 40624 | B81: 22309 | C81: 13 | D81: 1.551 | E81: 51 | F81: 79 | G81: 1027

Sheet TH Wastage
A1: EventID | B1: BeachName | C1: Date | D1: SumOfWastage | E1: SumOfTotHarvest | I1: EventID | J1: BeachName | K1: Date | L1: SumOfWastage | M1: SumOfTotHarvest
A2: 416 | B2: Twin Harbors | C2: 40899 | D2: 773 | E2: 19334.071 | I2: 416 | J2: Twin Harbors | K2: 40899 | L2: 773 | M2: 19334.071
A3: 531 | B3: Twin Harbors | C3: 40979 | D3: 2007 | E3: 25083.937 | I3: 531 | J3: Twin Harbors | K3: 40979 | L3: 2007 | M3: 25083.937
A4: 543 | B4: Twin Harbors | C4: 40992 | D4: 797 | E4: 26562.929 | I4: 543 | J4: Twin Harbors | K4: 40992 | L4: 797 | M4: 26562.929
A5: 544 | B5: Twin Harbors | C5: 40993 | D5: 163 | E5: 32734.85 | I5: 544 | J5: Twin Harbors | K5: 40993 | L5: 163 | M5: 32734.85
A6: 553 | B6: Twin Harbors | C6: 41006 | D6: 3471 | E6: 86779.693 | I6: 553 | J6: Twin Harbors | K6: 41006 | L6: 3471 | M6: 86779.693
A7: 554 | B7: Twin Harbors | C7: 41007 | D7: 715 | E7: 35799.299 | I7: 554 | J7: Twin Harbors | K7: 41007 | L7: 715 | M7: 35799.299
A8: 555 | B8: Twin Harbors | C8: 41008 | D8: 3120 | E8: 35461.19 | I8: 555 | J8: Twin Harbors | K8: 41008 | L8: 3120 | M8: 35461.19
A9: 563 | B9: Twin Harbors | C9: 41021 | D9: 1352 | E9: 40570.487 | I9: 563 | J9: Twin Harbors | K9: 41021 | L9: 1352 | M9: 40570.487
A10: 571 | B10: Twin Harbors | C10: 41035 | D10: 5123 | E10: 53922.802 | I10: 571 | J10: Twin Harbors | K10: 41035 | L10: 5123 | M10: 53922.802
D22: =SUM(D2:D21) -> 17521 | E22: =SUM(E2:E21) -> 356249.26 | F22: =+D22/E22 -> 0.049181857

Sheet LB Wastage
A1: EventID | B1: BeachName | C1: Date | D1: SumOfWastage | E1: SumOfTotHarvest | I1: EventID | J1: BeachName | K1: Date | L1: SumOfWastage | M1: SumOfTotHarvest
A2: 415 | B2: LongBeach | C2: 40899 | D2: 96 | E2: 28321.855 | I2: 415 | J2: LongBeach | K2: 40899 | L2: 96 | M2: 28321.855
A3: 545 | B3: LongBeach | C3: 40992 | D3: 406 | E3: 81215.59 | I3: 545 | J3: LongBeach | K3: 40992 | L3: 406 | M3: 81215.59
A4: 558 | B4: LongBeach | C4: 41008 | D4: 2732 | E4: 78053.182 | I4: 558 | J4: LongBeach | K4: 41008 | L4: 2732 | M4: 78053.182
A5: 565 | B5: LongBeach | C5: 41021 | D5: 1181 | E5: 88566.237 | I5: 565 | J5: LongBeach | K5: 41021 | L5: 1181 | M5: 88566.237
D22: =SUM(D2:D21) -> 4415 | E22: =SUM(E2:E21) -> 276156.86 | F22: =+D22/E22 -> 0.015987291

Sheet Cop Wastage
A1: EventID | B1: BeachName | C1: Date | D1: SumOfWastage | E1: SumOfTotHarvest
A2: 417 | B2: Copalis | C2: 40899 | D2: 580 | E2: 28993.197
A3: 525 | B3: Copalis | C3: 40978 | D3: 481 | E3: 48063.471
A4: 542 | B4: Copalis | C4: 40992 | D4: 1772 | E4: 59039.348
A5: 568 | B5: Copalis | C5: 41022 | D5: 243 | E5: 24277.997
D22: =SUM(D2:D21) -> 3076 | E22: =SUM(E2:E21) -> 160374.01 | F22: =+D22/E22 -> 0.019180165

Sheet Moc Wastage
D1: EventID | E1: BeachName | F1: Date | G1: SumOfWastage | H1: SumOfTotHarvest
D2: 418 | E2: Mocrocks | F2: 40899 | G2: 655 | H2: 32728.292
D3: 540 | E3: Mocrocks | F3: 40992 | G3: 1263 | H3: 42122.044
D4: 541 | E4: Mocrocks | F4: 40993 | G4: 544 | H4: 54519.961
D5: 551 | E5: Mocrocks | F5: 41006 | G5: 3386 | H5: 67693.737
D6: 552 | E6: Mocrocks | F6: 41007 | G6: 2293 | H6: 114608.07
D7: 567 | E7: Mocrocks | F7: 41022 | G7: 377 | H7: 18846.817
G22: =SUM(G2:G21) -> 8518 | H22: =SUM(H2:H21) -> 330518.92 | I22: =+G22/H22 -> 0.025771595
