Workbook

Sheet Harvest
A1: Date | B1: Day | C1: Tide | D1: Time | E1: Longbeach | G1: Twin Harbors | I1: Copalis | K1: Mocrocks | M1: Kalaloch | O1: Daily Totals
A2: 41536 | B2: =+A2 -> 41536 | C2: -0.3 | D2: 0.80069444 | F2: CLOSED | H2: 45401.518 | J2: CLOSED | L2: CLOSED | N2: CLOSED | O2: =+H2 -> 45401.518 | Q2: =SUM(O2:O19) -> 929737.78
A3: 41537 | B3: =+A3 -> 41537 | C3: -0.5 | D3: 0.83125 | F3: CLOSED | H3: 21157.228 | J3: CLOSED | L3: CLOSED | N3: CLOSED | O3: =+H3 -> 21157.228
A4: 41538 | B4: =+A4 -> 41538 | C4: -0.5 | D4: 0.86041667 | F4: CLOSED | H4: 49505.04 | J4: CLOSED | L4: CLOSED | N4: CLOSED | O4: =+H4 -> 49505.04
A5: 41539 | B5: =+A5 -> 41539 | C5: -0.3 | D5: 0.88958333 | F5: CLOSED | H5: 9128.1002 | J5: CLOSED | L5: CLOSED | N5: CLOSED | O5: =+H5 -> 9128.1002
A6: 41540 | B6: =+A6 -> 41540 | C6: 0 | D6: 0.91944444 | F6: CLOSED | H6: 2336.5561 | J6: CLOSED | L6: CLOSED | N6: CLOSED | O6: =+H6 -> 2336.5561
A8: 41551 | B8: =+A8 -> 41551 | C8: 0 | D8: 0.78888889 | F8: 19426.826 | G8: * | H8: =(+J8+L8)*H9/(J9+L9) -> 19957.164 | J8: 29369.724 | L8: 18271.325 | N8: CLOSED | O8: =+F8+H8+J8+L8 -> 87025.04
A9: 41552 | B9: =+A9 -> 41552 | C9: -0.4 | D9: 0.81666667 | F9: 40797.213 | H9: 34217.806 | J9: 58529.485 | L9: 23154.074 | N9: CLOSED | O9: =+F9+H9+J9+L9 -> 156698.58
A10: 41553 | B10: =+A10 -> 41553 | C10: -0.7 | D10: 0.84513889 | F10: 28329.233 | H10: 21782.8 | J10: CLOSED | L10: 19208.907 | N10: CLOSED | O10: =+F10+H10+L10 -> 69320.94
A11: 41554 | B11: =+A11 -> 41554 | C11: -0.8 | D11: 0.875 | F11: 5751.9941 | H11: 6306.0817 | J11: CLOSED | L11: 2052.5059 | N11: CLOSED | O11: =+F11+H11+L11 -> 14110.582
A12: 41555 | B12: =+A12 -> 41555 | C12: -0.7 | D12: 0.90833333 | F12: CLOSED | H12: 2165.8989 | J12: CLOSED | L12: CLOSED | N12: CLOSED | O12: =+H12 -> 2165.8989
A14: 41564 | B14: =+A14 -> 41564 | C14: -0.2 | D14: 0.76041667 | F14: CLOSED | H14: 21850.647 | J14: CLOSED | L14: CLOSED | N14: CLOSED | O14: =+H14 -> 21850.647
A15: 41565 | B15: =+A15 -> 41565 | C15: -0.6 | D15: 0.78958333 | F15: 37337.46 | H15: 26190.469 | J15: 46909.494 | L15: 15520.121 | N15: CLOSED | O15: =+F15+H15+J15+L15 -> 125957.55
A16: 41566 | B16: =+A16 -> 41566 | C16: -0.7 | D16: 0.81805556 | F16: 53827.758 | H16: 42292.095 | J16: 84754.093 | L16: 44871.925 | N16: CLOSED | O16: =+F16+H16+J16+L16 -> 225745.87
A17: 41567 | B17: =+A17 -> 41567 | C17: -0.7 | D17: 0.84444444 | F17: 41320.949 | H17: 26515.767 | J17: CLOSED | L17: 22650.381 | N17: CLOSED | O17: =+F17+H17+L17 -> 90487.097
A18: 41568 | B18: =+A18 -> 41568 | C18: -0.4 | D18: 0.87152778 | F18: CLOSED | H18: 4911.222 | J18: CLOSED | L18: 2275.8268 | N18: CLOSED | O18: =+H18+L18 -> 7187.0488
A19: 41569 | B19: =+A19 -> 41569 | C19: -0.1 | D19: 0.89861111 | F19: CLOSED | H19: 1660.0928 | J19: CLOSED | L19: CLOSED | N19: CLOSED | O19: =+H19 -> 1660.0928
A21: 41579 | B21: =+A21 -> 41579 | C21: 0.1 | D21: 0.74444444 | F21: CLOSED | H21: 18996.688 | J21: CLOSED | L21: 20179.355 | N21: CLOSED | O21: =+H21+L21 -> 39176.043
A22: 41580 | B22: =+A22 -> 41580 | C22: -0.6 | D22: 0.77361111 | F22: 32798.556 | H22: 8249.2315 | J22: 14627.824 | L22: 12612.285 | N22: CLOSED | O22: =+F22+H22+J22+L22 -> 68287.897
A23: 41581 | B23: =+A23 -> 41581 | C23: -1.1 | D23: 0.76111111 | F23: 17037.942 | H23: 7802.6348 | J23: CLOSED | L23: 16187.953 | N23: CLOSED | O23: =+F23+H23+L23 -> 41028.53
A24: 41582 | B24: =+A24 -> 41582 | C24: -1.3 | D24: 0.79097222 | F24: 9867.2455 | H24: 5569.266 | J24: CLOSED | L24: 4982.5484 | N24: CLOSED | O24: =+F24+H24+L24 -> 20419.06
A25: 41583 | B25: =+A25 -> 41583 | C25: -1.4 | D25: 0.82916667 | F25: 4987.1395 | H25: 8167.6207 | J25: CLOSED | L25: CLOSED | N25: CLOSED | O25: =+F25+H25 -> 13154.76
A26: 41584 | B26: =+A26 -> 41584 | C26: -1.2 | D26: 0.85555556 | F26: CLOSED | H26: 4491.4045 | J26: CLOSED | L26: CLOSED | N26: CLOSED | O26: =+H26 -> 4491.4045
A27: 41585 | B27: =+A27 -> 41585 | C27: -0.8 | D27: 0.89166667 | F27: CLOSED | G27: * | H27: 4491.4045 | J27: CLOSED | L27: CLOSED | N27: CLOSED | O27: =+H27 -> 4491.4045
A28: 41586 | B28: =+A28 -> 41586 | C28: -0.3 | D28: 0.92986111 | F28: CLOSED | H28: 5412.6658 | J28: CLOSED | L28: CLOSED | N28: CLOSED | O28: =+H28 -> 5412.6658
A30: 41593 | B30: =+A30 -> 41593 | C30: -0.3 | D30: 0.70902778 | F30: 20804.439 | H30: 9897.1771 | J30: 20057.086 | L30: 7723.7193 | N30: CLOSED | O30: =+F30+H30+J30+L30 -> 58482.421
A31: 41594 | B31: =+A31 -> 41594 | C31: -0.6 | D31: 0.7375 | F31: 54007.024 | H31: 29058.088 | J31: 43395.924 | L31: 38836.262 | N31: CLOSED | O31: =+F31+H31+J31+L31 -> 165297.3
A32: 41595 | B32: =+A32 -> 41595 | C32: -0.7 | D32: 0.76388889 | F32: 11104.231 | G32: * | H32: =+L32*(H31+H30)/(L30+L31) -> 11648.043 | J32: CLOSED | L32: 13921.935 | N32: CLOSED | O32: =+F32+H32+L32 -> 36674.209
A33: 41596 | B33: =+A33 -> 41596 | C33: -0.6 | D33: 0.78958333 | F33: CLOSED | H33: 34.760948 | J33: CLOSED | L33: CLOSED | N33: CLOSED | O33: =+H33 -> 34.760948
A34: 41597 | B34: =+A34 -> 41597 | C34: -0.4 | D34: 0.81458333 | F34: CLOSED | H34: 2066.3745 | J34: CLOSED | L34: CLOSED | N34: CLOSED | O34: =+H34 -> 2066.3745
A35: 41598 | B35: =+A35 -> 41598 | C35: -0.2 | D35: 0.83958333 | F35: CLOSED | H35: 1065.1748 | J35: CLOSED | L35: CLOSED | N35: CLOSED | O35: =+H35 -> 1065.1748
A37: 41608 | B37: =+A37 -> 41608 | C37: -0.1 | D37: 0.68611111 | F37: 49286.818 | G37: * | H37: =+(J37+L37)*(H9+H16+H22+H31)/(J9+L9+J16+L16+J22+L22+J31+L31) -> 20397.551 | J37: 40803.254 | L37: 16685.1 | N37: CLOSED | O37: =+F37+H37+J37+L37 -> 127172.72
A38: 41609 | B38: =+A38 -> 41609 | C38: -0.9 | D38: 0.71736111 | F38: 9914.2017 | H38: 4240.4598 | J38: CLOSED | L38: 7884.1679 | N38: CLOSED | O38: =+F38+H38+L38 -> 22038.829
A39: 41610 | B39: =+A39 -> 41610 | C39: -1.4 | D39: 0.74930556 | F39: 6703.6526 | H39: 4304.1705 | J39: CLOSED | L39: 2709.9105 | N39: CLOSED | O39: =+F39+H39+L39 -> 13717.734
A40: 41611 | B40: =+A40 -> 41611 | C40: -1.7 | D40: 0.78055556 | F40: 5283.7976 | H40: 7173.7906 | J40: CLOSED | L40: 3184.0816 | N40: CLOSED | O40: =+F40+H40+L40 -> 15641.67
A41: 41612 | B41: =+A41 -> 41612 | C41: -1.7 | D41: 0.8125 | E41: * | F41: =+H41*F40/H40 -> 2558.6894 | H41: 3473.9222 | J41: CLOSED | L41: CLOSED | N41: CLOSED | O41: =+F41+H41 -> 6032.6116
A42: 41613 | B42: =+A42 -> 41613 | C42: -1.4 | D42: 0.84513889 | F42: CLOSED | H42: 1463.8814 | J42: CLOSED | L42: CLOSED | N42: CLOSED | O42: =+H42 -> 1463.8814
A43: 41614 | B43: =+A43 -> 41614 | C43: -1 | D43: 0.87847222 | F43: CLOSED | H43: 1007.0256 | J43: CLOSED | L43: CLOSED | N43: CLOSED | O43: =+H43 -> 1007.0256
A44: 41615 | B44: =+A44 -> 41615 | C44: -0.3 | D44: 0.91388889 | F44: CLOSED | H44: 598.5552 | J44: CLOSED | L44: CLOSED | N44: CLOSED | O44: =+H44 -> 598.5552
A46: 41622 | B46: =+A46 -> 41622 | C46: -0.1 | D46: 0.69791667 | F46: 24770.219 | H46: 13603.707 | J46: 19002.987 | L46: 8678.7984 | N46: CLOSED | O46: =+F46+H46+J46+L46 -> 66055.712
...

Sheet Effort
A1: Date | B1: Day | C1: Tide | D1: Time | E1: Longbeach | G1: Twin Harbors | I1: Copalis | K1: Mocrocks | M1: Kalaloch | O1: Daily Totals
A2: 41536 | B2: =+A2 -> 41536 | C2: -0.3 | D2: 0.80069444 | F2: CLOSED | H2: 3023.0358 | J2: CLOSED | L2: CLOSED | N2: CLOSED | O2: =+H2 -> 3023.0358 | Q2: =SUM(O2:O19) -> 63159.869
A3: 41537 | B3: =+A3 -> 41537 | C3: -0.5 | D3: 0.83125 | F3: CLOSED | H3: 1669.621 | J3: CLOSED | L3: CLOSED | N3: CLOSED | O3: =+H3 -> 1669.621
A4: 41538 | B4: =+A4 -> 41538 | C4: -0.5 | D4: 0.86041667 | F4: CLOSED | H4: 3341.8734 | J4: CLOSED | L4: CLOSED | N4: CLOSED | O4: =+H4 -> 3341.8734
A5: 41539 | B5: =+A5 -> 41539 | C5: -0.3 | D5: 0.88958333 | F5: CLOSED | H5: 673.80127 | J5: CLOSED | L5: CLOSED | N5: CLOSED | O5: =+H5 -> 673.80127
A6: 41540 | B6: =+A6 -> 41540 | C6: 0 | D6: 0.91944444 | F6: CLOSED | H6: 194.71301 | J6: CLOSED | L6: CLOSED | N6: CLOSED | O6: =+H6 -> 194.71301
A8: 41551 | B8: =+A8 -> 41551 | C8: 0 | D8: 0.78888889 | F8: 1295.1217 | G8: * | H8: =(+J8+L8)*H9/(J9+L9) -> 1333.5092 | J8: 1984.4408 | L8: 1198.866 | N8: CLOSED | O8: =+F8+H8+J8+L8 -> 5811.9378
A9: 41552 | B9: =+A9 -> 41552 | C9: -0.4 | D9: 0.81666667 | F9: 2719.8142 | H9: 2281.1871 | J9: 3901.9657 | L9: 1543.6049 | N9: CLOSED | O9: =+F9+H9+J9+L9 -> 10446.572
A10: 41553 | B10: =+A10 -> 41553 | C10: -0.7 | D10: 0.84513889 | F10: 2021.225 | H10: 1647.2 | J10: CLOSED | L10: 1304.756 | N10: CLOSED | O10: =+F10+H10+L10 -> 4973.181
A11: 41554 | B11: =+A11 -> 41554 | C11: -0.8 | D11: 0.875 | F11: 456.73402 | H11: 429.96012 | J11: CLOSED | L11: 175.01989 | N11: CLOSED | O11: =+F11+H11+L11 -> 1061.714
A12: 41555 | B12: =+A12 -> 41555 | C12: -0.7 | D12: 0.90833333 | F12: CLOSED | H12: 144.39326 | J12: CLOSED | L12: CLOSED | N12: CLOSED | O12: =+H12 -> 144.39326
A14: 41564 | B14: =+A14 -> 41564 | C14: -0.2 | D14: 0.76041667 | F14: CLOSED | H14: 1456.7098 | J14: CLOSED | L14: CLOSED | N14: CLOSED | O14: =+H14 -> 1456.7098
A15: 41565 | B15: =+A15 -> 41565 | C15: -0.6 | D15: 0.78958333 | F15: 2489.164 | H15: 1746.0312 | J15: 3251.1531 | L15: 1026.4303 | N15: CLOSED | O15: =+F15+H15+J15+L15 -> 8512.7787
A16: 41566 | B16: =+A16 -> 41566 | C16: -0.7 | D16: 0.81805556 | F16: 3646.6981 | H16: 2819.473 | J16: 5650.2729 | L16: 3004.0914 | N16: CLOSED | O16: =+F16+H16+J16+L16 -> 15120.535
A17: 41567 | B17: =+A17 -> 41567 | C17: -0.7 | D17: 0.84444444 | F17: 2754.7299 | H17: 1792.52 | J17: CLOSED | L17: 1510.0254 | N17: CLOSED | O17: =+F17+H17+L17 -> 6057.2753
A18: 41568 | B18: =+A18 -> 41568 | C18: -0.4 | D18: 0.87152778 | F18: CLOSED | H18: 379.05405 | J18: CLOSED | L18: 151.72179 | N18: CLOSED | O18: =+H18+L18 -> 530.77584
A19: 41569 | B19: =+A19 -> 41569 | C19: -0.1 | D19: 0.89861111 | F19: CLOSED | H19: 140.95128 | J19: CLOSED | L19: CLOSED | N19: CLOSED | O19: =+H19 -> 140.95128
A21: 41579 | B21: =+A21 -> 41579 | C21: 0.1 | D21: 0.74444444 | F21: CLOSED | H21: 1266.4459 | J21: CLOSED | L21: 1345.2904 | N21: CLOSED | O21: =+H21+L21 -> 2611.7362
A22: 41580 | B22: =+A22 -> 41580 | C22: -0.6 | D22: 0.77361111 | F22: 2656.3195 | H22: 984.07622 | J22: 1766.8439 | L22: 871.06432 | N22: CLOSED | O22: =+F22+H22+J22+L22 -> 6278.3039
A23: 41581 | B23: =+A23 -> 41581 | C23: -1.1 | D23: 0.76111111 | F23: 1126.1308 | H23: 540.34867 | J23: CLOSED | L23: 1079.1969 | N23: CLOSED | O23: =+F23+H23+L23 -> 2745.6763
A24: 41582 | B24: =+A24 -> 41582 | C24: -1.3 | D24: 0.79097222 | F24: 945.61103 | H24: 636.48755 | J24: CLOSED | L24: 384.53165 | N24: CLOSED | O24: =+F24+H24+L24 -> 1966.6302
A25: 41583 | B25: =+A25 -> 41583 | C25: -1.4 | D25: 0.82916667 | F25: 347.93996 | H25: 544.50805 | J25: CLOSED | L25: CLOSED | N25: CLOSED | O25: =+F25+H25 -> 892.44801
A26: 41584 | B26: =+A26 -> 41584 | C26: -1.2 | D26: 0.85555556 | F26: CLOSED | H26: 339.55635 | J26: CLOSED | L26: CLOSED | N26: CLOSED | O26: =+H26 -> 339.55635
A27: 41585 | B27: =+A27 -> 41585 | C27: -0.8 | D27: 0.89166667 | F27: CLOSED | G27: * | H27: 339.55635 | J27: CLOSED | L27: CLOSED | N27: CLOSED | O27: =+H27 -> 339.55635
A28: 41586 | B28: =+A28 -> 41586 | C28: -0.3 | D28: 0.92986111 | F28: CLOSED | H28: 374.90326 | J28: CLOSED | L28: CLOSED | N28: CLOSED | O28: =+H28 -> 374.90326
A30: 41593 | B30: 41593 | C30: -0.3 | D30: 0.70902778 | F30: 2311.6044 | H30: 668.29813 | J30: 1440.414 | L30: 524.29221 | N30: CLOSED | O30: =+F30+H30+J30+L30 -> 4944.6087
A31: 41594 | B31: 41594 | C31: -0.6 | D31: 0.7375 | F31: 4692.918 | H31: 1951.9937 | J31: 3896.465 | L31: 2660.018 | N31: CLOSED | O31: =+F31+H31+J31+L31 -> 13201.395
A32: 41595 | B32: 41595 | C32: -0.7 | D32: 0.76388889 | F32: 740.28206 | G32: * | H32: =+L32*(H31+H30)/(L30+L31) -> 815.51353 | J32: CLOSED | L32: 991.05299 | N32: CLOSED | O32: =+F32+H32+L32 -> 2546.8486
A33: 41596 | B33: 41596 | C33: -0.6 | D33: 0.78958333 | F33: CLOSED | H33: 45.189232 | J33: CLOSED | L33: CLOSED | N33: CLOSED | O33: =+H33 -> 45.189232
A34: 41597 | B34: 41597 | C34: -0.4 | D34: 0.81458333 | F34: CLOSED | H34: 137.7583 | J34: CLOSED | L34: CLOSED | N34: CLOSED | O34: =+H34 -> 137.7583
A35: 41598 | B35: 41598 | C35: -0.2 | D35: 0.83958333 | F35: CLOSED | H35: 71.01165 | J35: CLOSED | L35: CLOSED | N35: CLOSED | O35: =+H35 -> 71.01165
A37: 41608 | B37: =+A37 -> 41608 | C37: -0.1 | D37: 0.68611111 | F37: 3285.7879 | H37: =+(J37+L37)*(H9+H16+H22+H31)/(J9+L9+J16+L16+J22+L22+J31+L31) -> 1322.263 | J37: 2720.2169 | L37: 1112.34 | N37: CLOSED | O37: =+F37+H37+J37+L37 -> 8440.6078
A38: 41609 | B38: =+A38 -> 41609 | C38: -0.9 | D38: 0.71736111 | F38: 1295.15 | H38: 331.28592 | J38: CLOSED | L38: 525.6112 | N38: CLOSED | O38: =+F38+H38+L38 -> 2152.0472
A39: 41610 | B39: =+A39 -> 41610 | C39: -1.4 | D39: 0.74930556 | F39: 462.32087 | H39: 286.45503 | J39: CLOSED | L39: 180.6607 | N39: CLOSED | O39: =+F39+H39+L39 -> 929.4366
A40: 41611 | B40: =+A40 -> 41611 | C40: -1.7 | D40: 0.78055556 | F40: 352.25317 | H40: 478.25271 | J40: CLOSED | L40: 223.67515 | N40: CLOSED | O40: =+F40+H40+L40 -> 1054.181
A41: 41612 | B41: =+A41 -> 41612 | C41: -1.7 | D41: 0.8125 | F41: 220.15823 | H41: 231.59481 | J41: CLOSED | L41: CLOSED | N41: CLOSED | O41: =+F41+H41 -> 451.75305
A42: 41613 | B42: =+A42 -> 41613 | C42: -1.4 | D42: 0.84513889 | F42: CLOSED | H42: 103.78264 | J42: CLOSED | L42: CLOSED | N42: CLOSED | O42: =+H42 -> 103.78264
A43: 41614 | B43: =+A43 -> 41614 | C43: -1 | D43: 0.87847222 | F43: CLOSED | H43: 67.135038 | J43: CLOSED | L43: CLOSED | N43: CLOSED | O43: =+H43 -> 67.135038
A44: 41615 | B44: =+A44 -> 41615 | C44: -0.3 | D44: 0.91388889 | F44: CLOSED | H44: 39.90368 | J44: CLOSED | L44: CLOSED | N44: CLOSED | O44: =+H44 -> 39.90368
A46: 41622 | B46: =+A46 -> 41622 | C46: -0.1 | D46: 0.69791667 | F46: 1651.3479 | H46: 906.91382 | J46: 1266.8658 | L46: 578.58656 | N46: CLOSED | O46: =+F46+H46+J46+L46 -> 4403.7141
...

Sheet CPUE
A1: Date | B1: Day | C1: Tide | D1: Time | E1: Longbeach | G1: Twin Harbors | I1: Copalis | K1: Mocrocks | M1: Kalaloch | O1: Daily Totals
A2: 41536 | B2: =+A2 -> 41536 | C2: -0.3 | D2: 0.80069444 | F2: CLOSED | H2: =+Harvest!H2/Effort!H2 -> 15.018519 | J2: CLOSED | L2: CLOSED | N2: CLOSED | O2: =+Harvest!O2/Effort!O2 -> 15.018519 | Q2: =AVERAGE(O2:O19) -> 14.077313
A3: 41537 | B3: =+A3 -> 41537 | C3: -0.5 | D3: 0.83125 | F3: CLOSED | H3: =+Harvest!H3/Effort!H3 -> 12.671875 | J3: CLOSED | L3: CLOSED | N3: CLOSED | O3: =+Harvest!O3/Effort!O3 -> 12.671875
A4: 41538 | B4: =+A4 -> 41538 | C4: -0.5 | D4: 0.86041667 | F4: CLOSED | H4: =+Harvest!H4/Effort!H4 -> 14.813559 | J4: CLOSED | L4: CLOSED | N4: CLOSED | O4: =+Harvest!O4/Effort!O4 -> 14.813559
A5: 41539 | B5: =+A5 -> 41539 | C5: -0.3 | D5: 0.88958333 | F5: CLOSED | H5: =+Harvest!H5/Effort!H5 -> 13.54717 | J5: CLOSED | L5: CLOSED | N5: CLOSED | O5: =+Harvest!O5/Effort!O5 -> 13.54717
A6: 41540 | B6: =+A6 -> 41540 | C6: 0 | D6: 0.91944444 | F6: CLOSED | H6: =+Harvest!H6/Effort!H6 -> 12 | J6: CLOSED | L6: CLOSED | N6: CLOSED | O6: =+Harvest!O6/Effort!O6 -> 12
A8: 41551 | B8: =+A8 -> 41551 | C8: 0 | D8: 0.78888889 | F8: =+Harvest!F8/Effort!F8 -> 15 | H8: =+Harvest!H8/Effort!H8 -> 14.965899 | J8: =+Harvest!J8/Effort!J8 -> 14.8 | L8: =+Harvest!L8/Effort!L8 -> 15.240506 | N8: CLOSED | O8: =+Harvest!O8/Effort!O8 -> 14.973498
A9: 41552 | B9: =+A9 -> 41552 | C9: -0.4 | D9: 0.81666667 | F9: =+Harvest!F9/Effort!F9 -> 15 | H9: =+Harvest!H9/Effort!H9 -> 15 | J9: =+Harvest!J9/Effort!J9 -> 15 | L9: =+Harvest!L9/Effort!L9 -> 15 | N9: CLOSED | O9: =+Harvest!O9/Effort!O9 -> 15
A10: 41553 | B10: =+A10 -> 41553 | C10: -0.7 | D10: 0.84513889 | F10: =+Harvest!F10/Effort!F10 -> 14.015873 | H10: =+Harvest!H10/Effort!H10 -> 13.224138 | J10: CLOSED | L10: =+Harvest!L10/Effort!L10 -> 14.722222 | N10: CLOSED | O10: =+Harvest!O10/Effort!O10 -> 13.938954
A11: 41554 | B11: =+A11 -> 41554 | C11: -0.8 | D11: 0.875 | F11: =+Harvest!F11/Effort!F11 -> 12.59375 | H11: =+Harvest!H11/Effort!H11 -> 14.666667 | J11: CLOSED | L11: =+Harvest!L11/Effort!L11 -> 11.727273 | N11: CLOSED | O11: =+Harvest!O11/Effort!O11 -> 13.290379
A12: 41555 | B12: =+A12 -> 41555 | C12: -0.7 | D12: 0.90833333 | F12: CLOSED | H12: =+Harvest!H12/Effort!H12 -> 15 | J12: CLOSED | L12: CLOSED | N12: CLOSED | O12: =+Harvest!O12/Effort!O12 -> 15
A14: 41564 | B14: =+A14 -> 41564 | C14: -0.2 | D14: 0.76041667 | F14: CLOSED | H14: =+Harvest!H14/Effort!H14 -> 15 | J14: CLOSED | L14: CLOSED | N14: CLOSED | O14: =+Harvest!O14/Effort!O14 -> 15
A15: 41565 | B15: =+A15 -> 41565 | C15: -0.6 | D15: 0.78958333 | F15: =+Harvest!F15/Effort!F15 -> 15 | H15: =+Harvest!H15/Effort!H15 -> 15 | J15: =+Harvest!J15/Effort!J15 -> 14.428571 | L15: =+Harvest!L15/Effort!L15 -> 15.120482 | N15: CLOSED | O15: =+Harvest!O15/Effort!O15 -> 14.79629
A16: 41566 | B16: =+A16 -> 41566 | C16: -0.7 | D16: 0.81805556 | F16: =+Harvest!F16/Effort!F16 -> 14.760684 | H16: =+Harvest!H16/Effort!H16 -> 15 | J16: =+Harvest!J16/Effort!J16 -> 15 | L16: =+Harvest!L16/Effort!L16 -> 14.936937 | N16: CLOSED | O16: =+Harvest!O16/Effort!O16 -> 14.929754
A17: 41567 | B17: =+A17 -> 41567 | C17: -0.7 | D17: 0.84444444 | F17: =+Harvest!F17/Effort!F17 -> 15 | H17: =+Harvest!H17/Effort!H17 -> 14.792453 | J17: CLOSED | L17: =+Harvest!L17/Effort!L17 -> 15 | N17: CLOSED | O17: =+Harvest!O17/Effort!O17 -> 14.938581
A18: 41568 | B18: =+A18 -> 41568 | C18: -0.4 | D18: 0.87152778 | F18: CLOSED | H18: =+Harvest!H18/Effort!H18 -> 12.956522 | J18: CLOSED | L18: =+Harvest!L18/Effort!L18 -> 15 | N18: CLOSED | O18: =+Harvest!O18/Effort!O18 -> 13.540648
A19: 41569 | B19: =+A19 -> 41569 | C19: -0.1 | D19: 0.89861111 | F19: CLOSED | H19: =+Harvest!H19/Effort!H19 -> 11.777778 | J19: CLOSED | L19: CLOSED | N19: CLOSED | O19: =+Harvest!O19/Effort!O19 -> 11.777778
A21: 41579 | B21: =+A21 -> 41579 | C21: 0.1 | D21: 0.74444444 | F21: CLOSED | H21: =+Harvest!H21/Effort!H21 -> 15 | J21: CLOSED | L21: =+Harvest!L21/Effort!L21 -> 15 | N21: CLOSED | O21: =+Harvest!O21/Effort!O21 -> 15
A22: 41580 | B22: =+A22 -> 41580 | C22: -0.6 | D22: 0.77361111 | F22: =+Harvest!F22/Effort!F22 -> 12.347368 | H22: =+Harvest!H22/Effort!H22 -> 8.382716 | J22: =+Harvest!J22/Effort!J22 -> 8.2790698 | L22: =+Harvest!L22/Effort!L22 -> 14.479167 | N22: CLOSED | O22: =+Harvest!O22/Effort!O22 -> 10.876806
A23: 41581 | B23: =+A23 -> 41581 | C23: -1.1 | D23: 0.76111111 | F23: =+Harvest!F23/Effort!F23 -> 15.12963 | H23: =+Harvest!H23/Effort!H23 -> 14.44 | J23: CLOSED | L23: =+Harvest!L23/Effort!L23 -> 15 | N23: CLOSED | O23: =+Harvest!O23/Effort!O23 -> 14.942959
A24: 41582 | B24: =+A24 -> 41582 | C24: -1.3 | D24: 0.79097222 | F24: =+Harvest!F24/Effort!F24 -> 10.434783 | H24: =+Harvest!H24/Effort!H24 -> 8.75 | J24: CLOSED | L24: =+Harvest!L24/Effort!L24 -> 12.957447 | N24: CLOSED | O24: =+Harvest!O24/Effort!O24 -> 10.382765
A25: 41583 | B25: =+A25 -> 41583 | C25: -1.4 | D25: 0.82916667 | F25: =+Harvest!F25/Effort!F25 -> 14.333333 | H25: =+Harvest!H25/Effort!H25 -> 15 | J25: CLOSED | L25: CLOSED | N25: CLOSED | O25: =+Harvest!O25/Effort!O25 -> 14.740086
A26: 41584 | B26: =+A26 -> 41584 | C26: -1.2 | D26: 0.85555556 | F26: CLOSED | H26: =+Harvest!H26/Effort!H26 -> 13.227273 | J26: CLOSED | L26: CLOSED | N26: CLOSED | O26: =+Harvest!O26/Effort!O26 -> 13.227273
A27: 41585 | B27: =+A27 -> 41585 | C27: -0.8 | D27: 0.89166667 | F27: CLOSED | H27: =+Harvest!H27/Effort!H27 -> 13.227273 | J27: CLOSED | L27: CLOSED | N27: CLOSED | O27: =+Harvest!O27/Effort!O27 -> 13.227273
A28: 41586 | B28: =+A28 -> 41586 | C28: -0.3 | D28: 0.92986111 | F28: CLOSED | H28: =+Harvest!H28/Effort!H28 -> 14.4375 | J28: CLOSED | L28: CLOSED | N28: CLOSED | O28: =+Harvest!O28/Effort!O28 -> 14.4375
A30: 41593 | B30: 41593 | C30: -0.3 | D30: 0.70902778 | F30: =+Harvest!F30/Effort!F30 -> 9 | H30: =+Harvest!H30/Effort!H30 -> 14.809524 | J30: =+Harvest!J30/Effort!J30 -> 13.924528 | L30: =+Harvest!L30/Effort!L30 -> 14.731707 | N30: CLOSED | O30: =+Harvest!O30/Effort!O30 -> 11.827513
A31: 41594 | B31: 41594 | C31: -0.6 | D31: 0.7375 | F31: =+Harvest!F31/Effort!F31 -> 11.508197 | H31: =+Harvest!H31/Effort!H31 -> 14.886364 | J31: =+Harvest!J31/Effort!J31 -> 11.137255 | L31: =+Harvest!L31/Effort!L31 -> 14.6 | N31: CLOSED | O31: =+Harvest!O31/Effort!O31 -> 12.5212
A32: 41595 | B32: 41595 | C32: -0.7 | D32: 0.76388889 | F32: =+Harvest!F32/Effort!F32 -> 15 | G32: * | H32: =+Harvest!H32/Effort!H32 -> 14.283077 | J32: CLOSED | L32: =+Harvest!L32/Effort!L32 -> 14.047619 | N32: CLOSED | O32: =+Harvest!O32/Effort!O32 -> 14.399839
A33: 41596 | B33: 41596 | C33: -0.6 | D33: 0.78958333 | F33: CLOSED | H33: =+Harvest!H33/Effort!H33 -> 0.76923077 | J33: CLOSED | L33: CLOSED | N33: CLOSED | O33: =+Harvest!O33/Effort!O33 -> 0.76923077
A34: 41597 | B34: 41597 | C34: -0.4 | D34: 0.81458333 | F34: CLOSED | H34: =+Harvest!H34/Effort!H34 -> 15 | J34: CLOSED | L34: CLOSED | N34: CLOSED | O34: =+Harvest!O34/Effort!O34 -> 15
A35: 41598 | B35: 41598 | C35: -0.2 | D35: 0.83958333 | F35: CLOSED | H35: =+Harvest!H35/Effort!H35 -> 15 | J35: CLOSED | L35: CLOSED | N35: CLOSED | O35: =+Harvest!O35/Effort!O35 -> 15
A37: 41608 | B37: =+A37 -> 41608 | C37: -0.1 | D37: 0.68611111 | F37: =+Harvest!F37/Effort!F37 -> 15 | H37: =+Harvest!H37/Effort!H37 -> 15.426244 | J37: =+Harvest!J37/Effort!J37 -> 15 | L37: =+Harvest!L37/Effort!L37 -> 15 | N37: CLOSED | O37: =+Harvest!O37/Effort!O37 -> 15.066773
A38: 41609 | B38: =+A38 -> 41609 | C38: -0.9 | D38: 0.71736111 | F38: =+Harvest!F38/Effort!F38 -> 7.6548673 | H38: =+Harvest!H38/Effort!H38 -> 12.8 | J38: CLOSED | L38: =+Harvest!L38/Effort!L38 -> 15 | N38: CLOSED | O38: =+Harvest!O38/Effort!O38 -> 10.240867
A39: 41610 | B39: =+A39 -> 41610 | C39: -1.4 | D39: 0.74930556 | F39: =+Harvest!F39/Effort!F39 -> 14.5 | H39: =+Harvest!H39/Effort!H39 -> 15.025641 | J39: CLOSED | L39: =+Harvest!L39/Effort!L39 -> 15 | N39: CLOSED | O39: =+Harvest!O39/Effort!O39 -> 14.759192
A40: 41611 | B40: =+A40 -> 41611 | C40: -1.7 | D40: 0.78055556 | F40: =+Harvest!F40/Effort!F40 -> 15 | H40: =+Harvest!H40/Effort!H40 -> 15 | J40: CLOSED | L40: =+Harvest!L40/Effort!L40 -> 14.235294 | N40: CLOSED | O40: =+Harvest!O40/Effort!O40 -> 14.837745
A41: 41612 | B41: =+A41 -> 41612 | C41: -1.7 | D41: 0.8125 | F41: =+Harvest!F41/Effort!F41 -> 11.622047 | H41: =+Harvest!H41/Effort!H41 -> 15 | J41: CLOSED | L41: CLOSED | N41: CLOSED | O41: =+Harvest!O41/Effort!O41 -> 13.353782
A42: 41613 | B42: =+A42 -> 41613 | C42: -1.4 | D42: 0.84513889 | F42: CLOSED | H42: =+Harvest!H42/Effort!H42 -> 14.105263 | J42: CLOSED | L42: CLOSED | N42: CLOSED | O42: =+Harvest!O42/Effort!O42 -> 14.105263
A43: 41614 | B43: =+A43 -> 41614 | C43: -1 | D43: 0.87847222 | F43: CLOSED | H43: =+Harvest!H43/Effort!H43 -> 15 | J43: CLOSED | L43: CLOSED | N43: CLOSED | O43: =+Harvest!O43/Effort!O43 -> 15
A44: 41615 | B44: =+A44 -> 41615 | C44: -0.3 | D44: 0.91388889 | F44: CLOSED | H44: =+Harvest!H44/Effort!H44 -> 15 | J44: CLOSED | L44: CLOSED | N44: CLOSED | O44: =+Harvest!O44/Effort!O44 -> 15
A46: 41622 | B46: =+A46 -> 41622 | C46: -0.1 | D46: 0.69791667 | F46: =+Harvest!F46/Effort!F46 -> 15 | H46: =+Harvest!H46/Effort!H46 -> 15 | J46: =+Harvest!J46/Effort!J46 -> 15 | L46: =+Harvest!L46/Effort!L46 -> 15 | N46: CLOSED | O46: =+Harvest!O46/Effort!O46 -> 15
...

Sheet Summary Table
A1: 2013-2014 State (non-Indian) Recreational Razor Clam Effort, Harvest and CPUE totals.
E2: LONG BEACH | H2: TWIN HARBORS | K2: COPALIS | N2: MOCROCKS | Q2: KALALOCH | T2: DAILY TOTALS
A3: DATE | B3: DAY | C3: TIDE | D3: TIME | E3: Effort | F3: Harvest | G3: CPUE | H3: Effort | I3: Harvest | J3: CPUE | K3: Effort | L3: Harvest | M3: CPUE | N3: Effort | O3: Harvest | P3: CPUE | Q3: Effort | R3: Harvest | S3: CPUE | T3: Effort | U3: Harvest
A4: 41536 | B4: =+A4 -> 41536 | C4: -0.3 | D4: 0.80069444 | E4: =Effort!F2 -> CLOSED | F4: =Harvest!F2 -> CLOSED | G4: =CPUE!F2 -> CLOSED | H4: =Effort!H2 -> 3023.0358 | I4: =Harvest!H2 -> 45401.518 | J4: =CPUE!H2 -> 15.018519 | K4: =Effort!J2 -> CLOSED | L4: =Harvest!J2 -> CLOSED | M4: =CPUE!J2 -> CLOSED | N4: =Effort!L2 -> CLOSED | O4: =Harvest!L2 -> CLOSED | P4: =CPUE!L2 -> CLOSED | Q4: =Effort!N2 -> CLOSED | R4: =Harvest!N2 -> CLOSED | S4: =CPUE!N2 -> CLOSED | T4: =+H4 -> 3023.0358 | U4: =+I4 -> 45401.518
A5: 41537 | B5: =+A5 -> 41537 | C5: -0.5 | D5: 0.83125 | E5: =Effort!F3 -> CLOSED | F5: =Harvest!F3 -> CLOSED | G5: =CPUE!F3 -> CLOSED | H5: =Effort!H3 -> 1669.621 | I5: =Harvest!H3 -> 21157.228 | J5: =CPUE!H3 -> 12.671875 | K5: =Effort!J3 -> CLOSED | L5: =Harvest!J3 -> CLOSED | M5: =CPUE!J3 -> CLOSED | N5: =Effort!L3 -> CLOSED | O5: =Harvest!L3 -> CLOSED | P5: =CPUE!L3 -> CLOSED | Q5: =Effort!N3 -> CLOSED | R5: =Harvest!N3 -> CLOSED | S5: =CPUE!N3 -> CLOSED | T5: =+H5 -> 1669.621 | U5: =+I5 -> 21157.228
A6: 41538 | B6: =+A6 -> 41538 | C6: -0.5 | D6: 0.86041667 | E6: =Effort!F4 -> CLOSED | F6: =Harvest!F4 -> CLOSED | G6: =CPUE!F4 -> CLOSED | H6: =Effort!H4 -> 3341.8734 | I6: =Harvest!H4 -> 49505.04 | J6: =CPUE!H4 -> 14.813559 | K6: =Effort!J4 -> CLOSED | L6: =Harvest!J4 -> CLOSED | M6: =CPUE!J4 -> CLOSED | N6: =Effort!L4 -> CLOSED | O6: =Harvest!L4 -> CLOSED | P6: =CPUE!L4 -> CLOSED | Q6: =Effort!N4 -> CLOSED | R6: =Harvest!N4 -> CLOSED | S6: =CPUE!N4 -> CLOSED | T6: =+H6 -> 3341.8734 | U6: =+I6 -> 49505.04
A7: 41539 | B7: =+A7 -> 41539 | C7: -0.3 | D7: 0.88958333 | E7: =Effort!F5 -> CLOSED | F7: =Harvest!F5 -> CLOSED | G7: =CPUE!F5 -> CLOSED | H7: =Effort!H5 -> 673.80127 | I7: =Harvest!H5 -> 9128.1002 | J7: =CPUE!H5 -> 13.54717 | K7: =Effort!J5 -> CLOSED | L7: =Harvest!J5 -> CLOSED | M7: =CPUE!J5 -> CLOSED | N7: =Effort!L5 -> CLOSED | O7: =Harvest!L5 -> CLOSED | P7: =CPUE!L5 -> CLOSED | Q7: =Effort!N5 -> CLOSED | R7: =Harvest!N5 -> CLOSED | S7: =CPUE!N5 -> CLOSED | T7: =+H7 -> 673.80127 | U7: =+I7 -> 9128.1002
A8: 41540 | B8: =+A8 -> 41540 | C8: 0 | D8: 0.91944444 | E8: =Effort!F6 -> CLOSED | F8: =Harvest!F6 -> CLOSED | G8: =CPUE!F6 -> CLOSED | H8: =Effort!H6 -> 194.71301 | I8: =Harvest!H6 -> 2336.5561 | J8: =CPUE!H6 -> 12 | K8: =Effort!J6 -> CLOSED | L8: =Harvest!J6 -> CLOSED | M8: =CPUE!J6 -> CLOSED | N8: =Effort!L6 -> CLOSED | O8: =Harvest!L6 -> CLOSED | P8: =CPUE!L6 -> CLOSED | Q8: =Effort!N6 -> CLOSED | R8: =Harvest!N6 -> CLOSED | S8: =CPUE!N6 -> CLOSED | T8: =+H8 -> 194.71301 | U8: =+I8 -> 2336.5561
A9: Tide Series Totals | E9: =SUM(E4:E8) -> 0 | F9: =SUM(F4:F8) -> 0 | G9: =+F9/E9 -> #DIV/0! | H9: =SUM(H4:H8) -> 8903.0444 | I9: =SUM(I4:I8) -> 127528.44 | J9: =+I9/H9 -> 14.324139 | K9: =SUM(K4:K8) -> 0 | L9: =SUM(L4:L8) -> 0 | M9: =+L9/K9 -> #DIV/0! | N9: =SUM(N4:N8) -> 0 | O9: =SUM(O4:O8) -> 0 | P9: =+O9/N9 -> #DIV/0! | T9: =SUM(T4:T8) -> 8903.0444 | U9: =SUM(U4:U8) -> 127528.44
A10: 41551 | B10: =+A10 -> 41551 | C10: 0 | D10: 0.78888889 | E10: =Effort!F8 -> 1295.1217 | F10: =Harvest!F8 -> 19426.826 | G10: =CPUE!F8 -> 15 | H10: =Effort!H8 -> 1333.5092 | I10: =Harvest!H8 -> 19957.164 | J10: =CPUE!H8 -> 14.965899 | K10: =Effort!J8 -> 1984.4408 | L10: =Harvest!J8 -> 29369.724 | M10: =CPUE!J8 -> 14.8 | N10: =Effort!L8 -> 1198.866 | O10: =Harvest!L8 -> 18271.325 | P10: =CPUE!L8 -> 15.240506 | Q10: =Effort!N8 -> CLOSED | R10: =Harvest!N8 -> CLOSED | S10: =CPUE!N8 -> CLOSED | T10: =+E10+H10+K10+N10 -> 5811.9378 | U10: =+F10+I10+L10+O10 -> 87025.04
A11: 41552 | B11: =+A11 -> 41552 | C11: -0.4 | D11: 0.81666667 | E11: =Effort!F9 -> 2719.8142 | F11: =Harvest!F9 -> 40797.213 | G11: =CPUE!F9 -> 15 | H11: =Effort!H9 -> 2281.1871 | I11: =Harvest!H9 -> 34217.806 | J11: =CPUE!H9 -> 15 | K11: =Effort!J9 -> 3901.9657 | L11: =Harvest!J9 -> 58529.485 | M11: =CPUE!J9 -> 15 | N11: =Effort!L9 -> 1543.6049 | O11: =Harvest!L9 -> 23154.074 | P11: =CPUE!L9 -> 15 | Q11: =Effort!N9 -> CLOSED | R11: =Harvest!N9 -> CLOSED | S11: =CPUE!N9 -> CLOSED | T11: =+E11+H11+K11+N11 -> 10446.572 | U11: =+F11+I11+L11+O11 -> 156698.58
A12: 41553 | B12: =+A12 -> 41553 | C12: -0.7 | D12: 0.84513889 | E12: =Effort!F10 -> 2021.225 | F12: =Harvest!F10 -> 28329.233 | G12: =CPUE!F10 -> 14.015873 | H12: =Effort!H10 -> 1647.2 | I12: =Harvest!H10 -> 21782.8 | J12: =CPUE!H10 -> 13.224138 | K12: =Effort!J10 -> CLOSED | L12: =Harvest!J10 -> CLOSED | M12: =CPUE!J10 -> CLOSED | N12: =Effort!L10 -> 1304.756 | O12: =Harvest!L10 -> 19208.907 | P12: =CPUE!L10 -> 14.722222 | Q12: =Effort!N10 -> CLOSED | R12: =Harvest!N10 -> CLOSED | S12: =CPUE!N10 -> CLOSED | T12: =+E12+H12+N12 -> 4973.181 | U12: =+F12+I12+O12 -> 69320.94
A13: 41554 | B13: =+A13 -> 41554 | C13: -0.8 | D13: 0.875 | E13: =Effort!F11 -> 456.73402 | F13: =Harvest!F11 -> 5751.9941 | G13: =CPUE!F11 -> 12.59375 | H13: =Effort!H11 -> 429.96012 | I13: =Harvest!H11 -> 6306.0817 | J13: =CPUE!H11 -> 14.666667 | K13: =Effort!J11 -> CLOSED | L13: =Harvest!J11 -> CLOSED | M13: =CPUE!J11 -> CLOSED | N13: =Effort!L11 -> 175.01989 | O13: =Harvest!L11 -> 2052.5059 | P13: =CPUE!L11 -> 11.727273 | Q13: =Effort!N11 -> CLOSED | R13: =Harvest!N11 -> CLOSED | S13: =CPUE!N11 -> CLOSED | T13: =+E13+H13+N13 -> 1061.714 | U13: =+F13+I13+O13 -> 14110.582
A14: 41555 | B14: =+A14 -> 41555 | C14: -0.7 | D14: 0.90833333 | E14: =Effort!F12 -> CLOSED | F14: =Harvest!F12 -> CLOSED | G14: =CPUE!F12 -> CLOSED | H14: =Effort!H12 -> 144.39326 | I14: =Harvest!H12 -> 2165.8989 | J14: =CPUE!H12 -> 15 | K14: =Effort!J12 -> CLOSED | L14: =Harvest!J12 -> CLOSED | M14: =CPUE!J12 -> CLOSED | N14: =Effort!L12 -> CLOSED | O14: =Harvest!L12 -> CLOSED | P14: =CPUE!L12 -> CLOSED | Q14: =Effort!N12 -> CLOSED | R14: =Harvest!N12 -> CLOSED | S14: =CPUE!N12 -> CLOSED | T14: =+H14 -> 144.39326 | U14: =+I14 -> 2165.8989
A15: Tide Series Totals | E15: =SUM(E10:E14) -> 6492.8949 | F15: =SUM(F10:F14) -> 94305.265 | G15: =+F15/E15 -> 14.524379 | H15: =SUM(H10:H14) -> 5836.2497 | I15: =SUM(I10:I14) -> 84429.751 | J15: =+I15/H15 -> 14.466439 | K15: =SUM(K10:K14) -> 5886.4065 | L15: =SUM(L10:L14) -> 87899.21 | M15: =+L15/K15 -> 14.932575 | N15: =SUM(N10:N14) -> 4222.2468 | O15: =SUM(O10:O14) -> 62686.812 | P15: =+O15/N15 -> 14.84679 | T15: =SUM(T10:T14) -> 22437.798 | U15: =SUM(U10:U14) -> 329321.04
A16: 41564 | B16: 41564 | C16: -0.2 | D16: 0.76041667 | E16: =Effort!F14 -> CLOSED | F16: =Harvest!F14 -> CLOSED | G16: =CPUE!F14 -> CLOSED | H16: =Effort!H14 -> 1456.7098 | I16: =Harvest!H14 -> 21850.647 | J16: =CPUE!H14 -> 15 | K16: =Effort!J14 -> CLOSED | L16: =Harvest!J14 -> CLOSED | M16: =CPUE!J14 -> CLOSED | N16: =Effort!L14 -> CLOSED | O16: =Harvest!L14 -> CLOSED | P16: =CPUE!L14 -> CLOSED | Q16: =Effort!N14 -> CLOSED | R16: =Harvest!N14 -> CLOSED | S16: =CPUE!N14 -> CLOSED | T16: =+H16 -> 1456.7098 | U16: =+I16 -> 21850.647
A17: 41565 | B17: 41565 | C17: -0.6 | D17: 0.78958333 | E17: =Effort!F15 -> 2489.164 | F17: =Harvest!F15 -> 37337.46 | G17: =CPUE!F15 -> 15 | H17: =Effort!H15 -> 1746.0312 | I17: =Harvest!H15 -> 26190.469 | J17: =CPUE!H15 -> 15 | K17: =Effort!J15 -> 3251.1531 | L17: =Harvest!J15 -> 46909.494 | M17: =CPUE!J15 -> 14.428571 | N17: =Effort!L15 -> 1026.4303 | O17: =Harvest!L15 -> 15520.121 | P17: =CPUE!L15 -> 15.120482 | Q17: =Effort!N15 -> CLOSED | R17: =Harvest!N15 -> CLOSED | S17: =CPUE!N15 -> CLOSED | T17: =+E17+H17+K17+N17 -> 8512.7787 | U17: =+F17+I17+L17+O17 -> 125957.55
A18: 41566 | B18: 41566 | C18: -0.7 | D18: 0.81805556 | E18: =Effort!F16 -> 3646.6981 | F18: =Harvest!F16 -> 53827.758 | G18: =CPUE!F16 -> 14.760684 | H18: =Effort!H16 -> 2819.473 | I18: =Harvest!H16 -> 42292.095 | J18: =CPUE!H16 -> 15 | K18: =Effort!J16 -> 5650.2729 | L18: =Harvest!J16 -> 84754.093 | M18: =CPUE!J16 -> 15 | N18: =Effort!L16 -> 3004.0914 | O18: =Harvest!L16 -> 44871.925 | P18: =CPUE!L16 -> 14.936937 | Q18: =Effort!N16 -> CLOSED | R18: =Harvest!N16 -> CLOSED | S18: =CPUE!N16 -> CLOSED | T18: =+E18+H18+K18+N18 -> 15120.535 | U18: =+F18+I18+L18+O18 -> 225745.87
A19: 41567 | B19: 41567 | C19: -0.7 | D19: 0.84444444 | E19: =Effort!F17 -> 2754.7299 | F19: =Harvest!F17 -> 41320.949 | G19: =CPUE!F17 -> 15 | H19: =Effort!H17 -> 1792.52 | I19: =Harvest!H17 -> 26515.767 | J19: =CPUE!H17 -> 14.792453 | K19: =Effort!J17 -> CLOSED | L19: =Harvest!J17 -> CLOSED | M19: =CPUE!J17 -> CLOSED | N19: =Effort!L17 -> 1510.0254 | O19: =Harvest!L17 -> 22650.381 | P19: =CPUE!L17 -> 15 | Q19: =Effort!N17 -> CLOSED | R19: =Harvest!N17 -> CLOSED | S19: =CPUE!N17 -> CLOSED | T19: =+E19+H19+N19 -> 6057.2753 | U19: =+F19+I19+O19 -> 90487.097
A20: 41568 | B20: 41568 | C20: -0.4 | D20: 0.87152778 | E20: =Effort!F18 -> CLOSED | F20: =Harvest!F18 -> CLOSED | G20: =CPUE!F18 -> CLOSED | H20: =Effort!H18 -> 379.05405 | I20: =Harvest!H18 -> 4911.222 | J20: =CPUE!H18 -> 12.956522 | K20: =Effort!J18 -> CLOSED | L20: =Harvest!J18 -> CLOSED | M20: =CPUE!J18 -> CLOSED | N20: =Effort!L18 -> 151.72179 | O20: =Harvest!L18 -> 2275.8268 | P20: =CPUE!L18 -> 15 | Q20: =Effort!N18 -> CLOSED | R20: =Harvest!N18 -> CLOSED | S20: =CPUE!N18 -> CLOSED | T20: =+H20+N20 -> 530.77584 | U20: =+I20+O20 -> 7187.0488
A21: 41569 | B21: 41569 | C21: -0.1 | D21: 0.89861111 | E21: =Effort!F19 -> CLOSED | F21: =Harvest!F19 -> CLOSED | G21: =CPUE!F19 -> CLOSED | H21: =Effort!H19 -> 140.95128 | I21: =Harvest!H19 -> 1660.0928 | J21: =CPUE!H19 -> 11.777778 | K21: =Effort!J19 -> CLOSED | L21: =Harvest!J19 -> CLOSED | M21: =CPUE!J19 -> CLOSED | N21: =Effort!L19 -> CLOSED | O21: =Harvest!L19 -> CLOSED | P21: =CPUE!L19 -> CLOSED | Q21: =Effort!N19 -> CLOSED | R21: =Harvest!N19 -> CLOSED | S21: =CPUE!N19 -> CLOSED | T21: =+H21 -> 140.95128 | U21: =+I21 -> 1660.0928
A22: Tide Series Totals | E22: =SUM(E16:E21) -> 8890.5921 | F22: =SUM(F16:F21) -> 132486.17 | G22: =+F22/E22 -> 14.901838 | H22: =SUM(H16:H21) -> 8334.7393 | I22: =SUM(I16:I21) -> 123420.29 | J22: =+I22/H22 -> 14.807937 | K22: =SUM(K16:K21) -> 8901.4259 | L22: =SUM(L16:L21) -> 131663.59 | M22: =+L22/K22 -> 14.791292 | N22: =SUM(N16:N21) -> 5692.269 | O22: =SUM(O16:O21) -> 85318.254 | P22: =+O22/N22 -> 14.988444 | T22: =SUM(T16:T21) -> 31819.026 | U22: =SUM(U16:U21) -> 472888.3
A23: 41579 | B23: =+A23 -> 41579 | C23: 0.1 | D23: 0.74444444 | E23: =Effort!F21 -> CLOSED | F23: =Harvest!F21 -> CLOSED | G23: =CPUE!F21 -> CLOSED | H23: =Effort!H21 -> 1266.4459 | I23: =Harvest!H21 -> 18996.688 | J23: =CPUE!H21 -> 15 | K23: =Effort!J21 -> CLOSED | L23: =Harvest!J21 -> CLOSED | M23: =CPUE!J21 -> CLOSED | N23: =Effort!L21 -> 1345.2904 | O23: =Harvest!L21 -> 20179.355 | P23: =CPUE!L21 -> 15 | Q23: =Effort!N21 -> CLOSED | R23: =Harvest!N21 -> CLOSED | S23: =CPUE!N21 -> CLOSED | T23: =+H23+N23 -> 2611.7362 | U23: =+I23+O23 -> 39176.043
A24: 41580 | B24: =+A24 -> 41580 | C24: -0.6 | D24: 0.77361111 | E24: =Effort!F22 -> 2656.3195 | F24: =Harvest!F22 -> 32798.556 | G24: =CPUE!F22 -> 12.347368 | H24: =Effort!H22 -> 984.07622 | I24: =Harvest!H22 -> 8249.2315 | J24: =CPUE!H22 -> 8.382716 | K24: =Effort!J22 -> 1766.8439 | L24: =Harvest!J22 -> 14627.824 | M24: =CPUE!J22 -> 8.2790698 | N24: =Effort!L22 -> 871.06432 | O24: =Harvest!L22 -> 12612.285 | P24: =CPUE!L22 -> 14.479167 | Q24: =Effort!N22 -> CLOSED | R24: =Harvest!N22 -> CLOSED | S24: =CPUE!N22 -> CLOSED | T24: =+E24+H24+K24+N24 -> 6278.3039 | U24: =+F24+I24+L24+O24 -> 68287.897
A25: 41581 | B25: =+A25 -> 41581 | C25: -1.1 | D25: 0.76111111 | E25: =Effort!F23 -> 1126.1308 | F25: =Harvest!F23 -> 17037.942 | G25: =CPUE!F23 -> 15.12963 | H25: =Effort!H23 -> 540.34867 | I25: =Harvest!H23 -> 7802.6348 | J25: =CPUE!H23 -> 14.44 | K25: =Effort!J23 -> CLOSED | L25: =Harvest!J23 -> CLOSED | M25: =CPUE!J23 -> CLOSED | N25: =Effort!L23 -> 1079.1969 | O25: =Harvest!L23 -> 16187.953 | P25: =CPUE!L23 -> 15 | Q25: =Effort!N23 -> CLOSED | R25: =Harvest!N23 -> CLOSED | S25: =CPUE!N23 -> CLOSED | T25: =+E25+H25+N25 -> 2745.6763 | U25: =+F25+I25+O25 -> 41028.53
A26: 41582 | B26: =+A26 -> 41582 | C26: -1.3 | D26: 0.2965162 | E26: =Effort!F24 -> 945.61103 | F26: =Harvest!F24 -> 9867.2455 | G26: =CPUE!F24 -> 10.434783 | H26: =Effort!H24 -> 636.48755 | I26: =Harvest!H24 -> 5569.266 | J26: =CPUE!H24 -> 8.75 | K26: =Effort!J24 -> CLOSED | L26: =Harvest!J24 -> CLOSED | M26: =CPUE!J24 -> CLOSED | N26: =Effort!L24 -> 384.53165 | O26: =Harvest!L24 -> 4982.5484 | P26: =CPUE!L24 -> 12.957447 | Q26: =Effort!N24 -> CLOSED | R26: =Harvest!N24 -> CLOSED | S26: =CPUE!N24 -> CLOSED | T26: =+E26+H26+N26 -> 1966.6302 | U26: =+F26+I26+O26 -> 20419.06
A27: 41583 | B27: =+A27 -> 41583 | C27: -1.4 | D27: 0.82291667 | E27: =Effort!F25 -> 347.93996 | F27: =Harvest!F25 -> 4987.1395 | G27: =CPUE!F25 -> 14.333333 | H27: =Effort!H25 -> 544.50805 | I27: =Harvest!H25 -> 8167.6207 | J27: =CPUE!H25 -> 15 | K27: =Effort!J25 -> CLOSED | L27: =Harvest!J25 -> CLOSED | M27: =CPUE!J25 -> CLOSED | N27: =Effort!L25 -> CLOSED | O27: =Harvest!L25 -> CLOSED | P27: =CPUE!L25 -> CLOSED | Q27: =Effort!N25 -> CLOSED | R27: =Harvest!N25 -> CLOSED | S27: =CPUE!N25 -> CLOSED | T27: =+E27+H27 -> 892.44801 | U27: =+F27+I27 -> 13154.76
A28: 41584 | B28: =+A28 -> 41584 | C28: -1.2 | D28: 0.85555556 | E28: =Effort!F26 -> CLOSED | F28: =Harvest!F26 -> CLOSED | G28: =CPUE!F26 -> CLOSED | H28: =Effort!H26 -> 339.55635 | I28: =Harvest!H26 -> 4491.4045 | J28: =CPUE!H26 -> 13.227273 | K28: =Effort!J26 -> CLOSED | L28: =Harvest!J26 -> CLOSED | M28: =CPUE!J26 -> CLOSED | N28: =Effort!L26 -> CLOSED | O28: =Harvest!L26 -> CLOSED | P28: =CPUE!L26 -> CLOSED | Q28: =Effort!N26 -> CLOSED | R28: =Harvest!N26 -> CLOSED | S28: =CPUE!N26 -> CLOSED | T28: =+H28 -> 339.55635 | U28: =+I28 -> 4491.4045
A29: 41585 | B29: =+A29 -> 41585 | C29: -0.8 | D29: 0.89166667 | E29: =Effort!F27 -> CLOSED | F29: =Harvest!F27 -> CLOSED | G29: =CPUE!F27 -> CLOSED | H29: =Effort!H27 -> 339.55635 | I29: =Harvest!H27 -> 4491.4045 | J29: =CPUE!H27 -> 13.227273 | K29: =Effort!J27 -> CLOSED | L29: =Harvest!J27 -> CLOSED | M29: =CPUE!J27 -> CLOSED | N29: =Effort!L27 -> CLOSED | O29: =Harvest!L27 -> CLOSED | P29: =CPUE!L27 -> CLOSED | Q29: =Effort!N27 -> CLOSED | R29: =Harvest!N27 -> CLOSED | S29: =CPUE!N27 -> CLOSED | T29: =+H29 -> 339.55635 | U29: =+I29 -> 4491.4045
A30: 41586 | B30: =+A30 -> 41586 | C30: -0.3 | D30: 0.92986111 | E30: =Effort!F28 -> CLOSED | F30: =Harvest!F28 -> CLOSED | G30: =CPUE!F28 -> CLOSED | H30: =Effort!H28 -> 374.90326 | I30: =Harvest!H28 -> 5412.6658 | J30: =CPUE!H28 -> 14.4375 | K30: =Effort!J28 -> CLOSED | L30: =Harvest!J28 -> CLOSED | M30: =CPUE!J28 -> CLOSED | N30: =Effort!L28 -> CLOSED | O30: =Harvest!L28 -> CLOSED | P30: =CPUE!L28 -> CLOSED | Q30: =Effort!N28 -> CLOSED | R30: =Harvest!N28 -> CLOSED | S30: =CPUE!N28 -> CLOSED | T30: =+H30 -> 374.90326 | U30: =+I30 -> 5412.6658
A31: Tide Series Totals | E31: =SUM(E24:E30) -> 5076.0013 | F31: =SUM(F24:F30) -> 64690.883 | G31: =+F31/E31 -> 12.744457 | H31: =SUM(H23:H30) -> 5025.8823 | I31: =SUM(I23:I30) -> 63180.916 | J31: =+I31/H31 -> 12.571109 | K31: =SUM(K24:K30) -> 1766.8439 | L31: =SUM(L24:L30) -> 14627.824 | M31: =+L31/K31 -> 8.2790698 | N31: =SUM(N23:N30) -> 3680.0832 | O31: =SUM(O23:O30) -> 53962.142 | P31: =+O31/N31 -> 14.663294 | T31: =SUM(T23:T30) -> 15548.811 | U31: =SUM(U23:U30) -> 196461.76
A32: 41593 | B32: 41593 | C32: -0.3 | D32: 0.70902778 | E32: =Effort!F30 -> 2311.6044 | F32: =Harvest!F30 -> 20804.439 | G32: =CPUE!F30 -> 9 | H32: =Effort!H30 -> 668.29813 | I32: =Harvest!H30 -> 9897.1771 | J32: =CPUE!H30 -> 14.809524 | K32: =Effort!J30 -> 1440.414 | L32: =Harvest!J30 -> 20057.086 | M32: =CPUE!J30 -> 13.924528 | N32: =Effort!L30 -> 524.29221 | O32: =Harvest!L30 -> 7723.7193 | P32: =CPUE!L30 -> 14.731707 | Q32: =Effort!N30 -> CLOSED | R32: =Harvest!N30 -> CLOSED | S32: =CPUE!N30 -> CLOSED | T32: =+E32+H32+K32+N32 -> 4944.6087 | U32: =+F32+I32+L32+O32 -> 58482.421
A33: 41594 | B33: 41594 | C33: -0.6 | D33: 0.7375 | E33: =Effort!F31 -> 4692.918 | F33: =Harvest!F31 -> 54007.024 | G33: =CPUE!F31 -> 11.508197 | H33: =Effort!H31 -> 1951.9937 | I33: =Harvest!H31 -> 29058.088 | J33: =CPUE!H31 -> 14.886364 | K33: =Effort!J31 -> 3896.465 | L33: =Harvest!J31 -> 43395.924 | M33: =CPUE!J31 -> 11.137255 | N33: =Effort!L31 -> 2660.018 | O33: =Harvest!L31 -> 38836.262 | P33: =CPUE!L31 -> 14.6 | Q33: =Effort!N31 -> CLOSED | R33: =Harvest!N31 -> CLOSED | S33: =CPUE!N31 -> CLOSED | T33: =+E33+H33+K33+N33 -> 13201.395 | U33: =+F33+I33+L33+O33 -> 165297.3
A34: 41595 | B34: 41595 | C34: -0.7 | D34: 0.76388889 | E34: =Effort!F32 -> 740.28206 | F34: =Harvest!F32 -> 11104.231 | G34: =CPUE!F32 -> 15 | H34: =Effort!H32 -> 815.51353 | I34: =Harvest!H32 -> 11648.043 | J34: =CPUE!H32 -> 14.283077 | K34: =Effort!J32 -> CLOSED | L34: =Harvest!J32 -> CLOSED | M34: =CPUE!J32 -> CLOSED | N34: =Effort!L32 -> 991.05299 | O34: =Harvest!L32 -> 13921.935 | P34: =CPUE!L32 -> 14.047619 | Q34: =Effort!N32 -> CLOSED | R34: =Harvest!N32 -> CLOSED | S34: =CPUE!N32 -> CLOSED | T34: =+E34+H34+N34 -> 2546.8486 | U34: =+F34+I34+O34 -> 36674.209
A35: 41596 | B35: 41596 | C35: -0.6 | D35: 0.78958333 | E35: =Effort!F33 -> CLOSED | F35: =Harvest!F33 -> CLOSED | G35: =CPUE!F33 -> CLOSED | H35: =Effort!H33 -> 45.189232 | I35: =Harvest!H33 -> 34.760948 | J35: =CPUE!H33 -> 0.76923077 | K35: =Effort!J33 -> CLOSED | L35: =Harvest!J33 -> CLOSED | M35: =CPUE!J33 -> CLOSED | N35: =Effort!L33 -> CLOSED | O35: =Harvest!L33 -> CLOSED | P35: =CPUE!L33 -> CLOSED | Q35: =Effort!N33 -> CLOSED | R35: =Harvest!N33 -> CLOSED | S35: =CPUE!N33 -> CLOSED | T35: =+H35 -> 45.189232 | U35: =+I35 -> 34.760948
A36: 41597 | B36: 41597 | C36: -0.4 | D36: 0.81458333 | E36: =Effort!F34 -> CLOSED | F36: =Harvest!F34 -> CLOSED | G36: =CPUE!F34 -> CLOSED | H36: =Effort!H34 -> 137.7583 | I36: =Harvest!H34 -> 2066.3745 | J36: =CPUE!H34 -> 15 | K36: =Effort!J34 -> CLOSED | L36: =Harvest!J34 -> CLOSED | M36: =CPUE!J34 -> CLOSED | N36: =Effort!L34 -> CLOSED | O36: =Harvest!L34 -> CLOSED | P36: =CPUE!L34 -> CLOSED | Q36: =Effort!N34 -> CLOSED | R36: =Harvest!N34 -> CLOSED | S36: =CPUE!N34 -> CLOSED | T36: =+H36 -> 137.7583 | U36: =+I36 -> 2066.3745
A37: 41598 | B37: 41598 | C37: -0.2 | D37: 0.83958333 | E37: =Effort!F35 -> CLOSED | F37: =Harvest!F35 -> CLOSED | G37: =CPUE!F35 -> CLOSED | H37: =Effort!H35 -> 71.01165 | I37: =Harvest!H35 -> 1065.1748 | J37: =CPUE!H35 -> 15 | K37: =Effort!J35 -> CLOSED | L37: =Harvest!J35 -> CLOSED | M37: =CPUE!J35 -> CLOSED | N37: =Effort!L35 -> CLOSED | O37: =Harvest!L35 -> CLOSED | P37: =CPUE!L35 -> CLOSED | Q37: =Effort!N35 -> CLOSED | R37: =Harvest!N35 -> CLOSED | S37: =CPUE!N35 -> CLOSED | T37: =+H37 -> 71.01165 | U37: =+I37 -> 1065.1748
E38: =SUM(E32:E37) -> 7744.8044 | F38: =SUM(F32:F37) -> 85915.694 | G38: =+F38/E38 -> 11.093333 | H38: =SUM(H32:H37) -> 3689.7645 | I38: =SUM(I32:I37) -> 53769.618 | J38: =+I38/H38 -> 14.572642 | K38: =SUM(K32:K37) -> 5336.879 | L38: =SUM(L32:L37) -> 63453.01 | M38: =+L38/K38 -> 11.889535 | N38: =SUM(N32:N37) -> 4175.3632 | O38: =SUM(O32:O37) -> 60481.917 | P38: =+O38/N38 -> 14.485427 | T38: =SUM(T32:T37) -> 20946.811 | U38: =SUM(U32:U37) -> 263620.24
A39: 41608 | B39: 41608 | C39: -0.1 | D39: 0.68611111 | E39: =Effort!F37 -> 3285.7879 | F39: =Harvest!F37 -> 49286.818 | G39: =CPUE!F37 -> 15 | H39: =Effort!H37 -> 1322.263 | I39: =Harvest!H37 -> 20397.551 | J39: =CPUE!H37 -> 15.426244 | K39: =Effort!J37 -> 2720.2169 | L39: =Harvest!J37 -> 40803.254 | M39: =CPUE!J37 -> 15 | N39: =Effort!L37 -> 1112.34 | O39: =Harvest!L37 -> 16685.1 | P39: =CPUE!L37 -> 15 | Q39: =Effort!N37 -> CLOSED | R39: =Harvest!N37 -> CLOSED | S39: =CPUE!N37 -> CLOSED | T39: =+E39+H39+K39+N39 -> 8440.6078 | U39: =+F39+I39+L39+O39 -> 127172.72
A40: 41609 | B40: 41609 | C40: -0.9 | D40: 0.71736111 | E40: =Effort!F38 -> 1295.15 | F40: =Harvest!F38 -> 9914.2017 | G40: =CPUE!F38 -> 7.6548673 | H40: =Effort!H38 -> 331.28592 | I40: =Harvest!H38 -> 4240.4598 | J40: =CPUE!H38 -> 12.8 | K40: =Effort!J38 -> CLOSED | L40: =Harvest!J38 -> CLOSED | M40: =CPUE!J38 -> CLOSED | N40: =Effort!L38 -> 525.6112 | O40: =Harvest!L38 -> 7884.1679 | P40: =CPUE!L38 -> 15 | Q40: =Effort!N38 -> CLOSED | R40: =Harvest!N38 -> CLOSED | S40: =CPUE!N38 -> CLOSED | T40: =+E40+H40+N40 -> 2152.0472 | U40: =+F40+I40+O40 -> 22038.829
...

Sheet Tribal update
A1: 2013-2014 State (non-Indian) Recreational Razor Clam Effort, Harvest and CPUE totals.
E2: COPALIS | I2: MOCROCKS | M2: KALALOCH | Q2: DAILY TOTALS
A3: DATE | B3: DAY | C3: TIDE | D3: TIME | E3: Effort | F3: Harvest | G3: CPUE | H3: Size (mm) | I3: Effort | J3: Harvest | K3: CPUE | L3: Size (mm) | M3: Effort | N3: Harvest | O3: CPUE | P3: Size (mm) | Q3: Effort | R3: Harvest
A4: 41551 | B4: =+A4 -> 41551 | C4: 0 | D4: 0.78888889 | E4: =+Effort!J8 -> 1984.4408 | F4: =+Harvest!J8 -> 29369.724 | G4: =+F4/E4 -> 14.8 | I4: =+Effort!L8 -> 1198.866 | J4: =+Harvest!L8 -> 18271.325 | K4: =+J4/I4 -> 15.240506 | M4: =+Effort!N8 -> CLOSED | N4: =+Harvest!N8 -> CLOSED | Q4: =+E4+I4 -> 3183.3069 | R4: =+F4+J4 -> 47641.05
A5: 41552 | B5: =+A5 -> 41552 | C5: -0.4 | D5: 0.81666667 | E5: =+Effort!J9 -> 3901.9657 | F5: =+Harvest!J9 -> 58529.485 | G5: =+F5/E5 -> 15 | I5: =+Effort!L9 -> 1543.6049 | J5: =+Harvest!L9 -> 23154.074 | K5: =+J5/I5 -> 15 | M5: =+Effort!N9 -> CLOSED | N5: =+Harvest!N9 -> CLOSED | Q5: =+E5+I5 -> 5445.5706 | R5: =+F5+J5 -> 81683.559
A6: 41553 | B6: =+A6 -> 41553 | C6: -0.7 | D6: 0.84513889 | E6: =+Effort!J10 -> CLOSED | F6: =+Harvest!J10 -> CLOSED | I6: =+Effort!L10 -> 1304.756 | J6: =+Harvest!L10 -> 19208.907 | K6: =+J6/I6 -> 14.722222 | M6: =+Effort!N10 -> CLOSED | N6: =+Harvest!N10 -> CLOSED | Q6: =+I6 -> 1304.756 | R6: =+J6 -> 19208.907
A7: 41554 | B7: =+A7 -> 41554 | C7: -0.8 | D7: 0.875 | E7: =+Effort!J11 -> CLOSED | F7: =+Harvest!J11 -> CLOSED | I7: =+Effort!L11 -> 175.01989 | J7: =+Harvest!L11 -> 2052.5059 | K7: =+J7/I7 -> 11.727273 | M7: =+Effort!N11 -> CLOSED | N7: =+Harvest!N11 -> CLOSED | Q7: =+I7 -> 175.01989 | R7: =+J7 -> 2052.5059
E8: =SUM(E4:E7) -> 5886.4065 | F8: =SUM(F4:F7) -> 87899.21 | G8: =+F8/E8 -> 14.932575 | H8: 120.16 | I8: =SUM(I4:I7) -> 4222.2468 | J8: =SUM(J4:J7) -> 62686.812 | K8: =+J8/I8 -> 14.84679 | L8: 107.12 | Q8: =SUM(Q4:Q7) -> 10108.653 | R8: =SUM(R4:R7) -> 150586.02
A9: 41565 | B9: 41565 | C9: -0.6 | D9: 0.78958333 | E9: =+'Summary Table'!K17 -> 3251.1531 | F9: =+'Summary Table'!L17 -> 46909.494 | G9: =+F9/E9 -> 14.428571 | I9: =+'Summary Table'!N17 -> 1026.4303 | J9: =+'Summary Table'!O17 -> 15520.121 | K9: =+J9/I9 -> 15.120482 | M9: =+'Summary Table'!Q17 -> CLOSED | N9: =+'Summary Table'!R17 -> CLOSED | Q9: =+E9+I9 -> 4277.5834 | R9: =+F9+J9 -> 62429.616
A10: 41566 | B10: 41566 | C10: -0.7 | D10: 0.81805556 | E10: =+'Summary Table'!K18 -> 5650.2729 | F10: =+'Summary Table'!L18 -> 84754.093 | G10: =+F10/E10 -> 15 | I10: =+'Summary Table'!N18 -> 3004.0914 | J10: =+'Summary Table'!O18 -> 44871.925 | K10: =+J10/I10 -> 14.936937 | M10: =+'Summary Table'!Q18 -> CLOSED | N10: =+'Summary Table'!R18 -> CLOSED | Q10: =+E10+I10 -> 8654.3643 | R10: =+F10+J10 -> 129626.02
A11: 41567 | B11: 41567 | C11: -0.7 | D11: 0.84444444 | E11: =+'Summary Table'!K19 -> CLOSED | F11: =+'Summary Table'!L19 -> CLOSED | I11: =+'Summary Table'!N19 -> 1510.0254 | J11: =+'Summary Table'!O19 -> 22650.381 | K11: =+J11/I11 -> 15 | M11: =+'Summary Table'!Q19 -> CLOSED | N11: =+'Summary Table'!R19 -> CLOSED | Q11: =+I11 -> 1510.0254 | R11: =+J11 -> 22650.381
A12: 41568 | B12: 41568 | C12: -0.4 | D12: 0.87152778 | E12: =+'Summary Table'!K20 -> CLOSED | F12: =+'Summary Table'!L20 -> CLOSED | I12: =+'Summary Table'!N20 -> 151.72179 | J12: =+'Summary Table'!O20 -> 2275.8268 | K12: =+J12/I12 -> 15 | M12: =+'Summary Table'!Q20 -> CLOSED | N12: =+'Summary Table'!R20 -> CLOSED | Q12: =+I12 -> 151.72179 | R12: =+J12 -> 2275.8268
E13: =SUM(E9:E12) -> 8901.4259 | F13: =SUM(F9:F12) -> 131663.59 | G13: =+F13/E13 -> 14.791292 | H13: 119.96 | I13: =SUM(I9:I12) -> 5692.269 | J13: =SUM(J9:J12) -> 85318.254 | K13: =+J13/I13 -> 14.988444 | L13: 116.95 | Q13: =SUM(Q9:Q12) -> 14593.695 | R13: =SUM(R9:R12) -> 216981.84
A14: 41579 | B14: 41579 | C14: 0.1 | D14: 0.74444444 | E14: =+'Summary Table'!K23 -> CLOSED | F14: =+'Summary Table'!L23 -> CLOSED | I14: =+'Summary Table'!N23 -> 1345.2904 | J14: =+'Summary Table'!O23 -> 20179.355 | K14: =+J14/I14 -> 15 | M14: =+'Summary Table'!R23 -> CLOSED | N14: =+'Summary Table'!S23 -> CLOSED | Q14: =+I14 -> 1345.2904 | R14: =+J14 -> 20179.355
A15: 41580 | B15: 41580 | C15: -0.6 | D15: 0.77361111 | E15: =+'Summary Table'!K24 -> 1766.8439 | F15: =+'Summary Table'!L24 -> 14627.824 | G15: =+F15/E15 -> 8.2790698 | I15: =+'Summary Table'!N24 -> 871.06432 | J15: =+'Summary Table'!O24 -> 12612.285 | K15: =+J15/I15 -> 14.479167 | M15: =+'Summary Table'!R24 -> CLOSED | N15: =+'Summary Table'!S24 -> CLOSED | Q15: =+E15+I15 -> 2637.9082 | R15: =+F15+J15 -> 27240.109
A16: 41581 | B16: 41581 | C16: -1.1 | D16: 0.76111111 | E16: =+'Summary Table'!K25 -> CLOSED | F16: =+'Summary Table'!L25 -> CLOSED | I16: =+'Summary Table'!N25 -> 1079.1969 | J16: =+'Summary Table'!O25 -> 16187.953 | K16: =+J16/I16 -> 15 | M16: =+'Summary Table'!R25 -> CLOSED | N16: =+'Summary Table'!S25 -> CLOSED | Q16: =+I16 -> 1079.1969 | R16: =+J16 -> 16187.953
A17: 41582 | B17: 41582 | C17: -1.3 | D17: 0.2965162 | E17: =+'Summary Table'!K26 -> CLOSED | F17: =+'Summary Table'!L26 -> CLOSED | I17: =+'Summary Table'!N26 -> 384.53165 | J17: =+'Summary Table'!O26 -> 4982.5484 | K17: =+J17/I17 -> 12.957447 | M17: =+'Summary Table'!R26 -> CLOSED | N17: =+'Summary Table'!S26 -> CLOSED | Q17: =+I17 -> 384.53165 | R17: =+J17 -> 4982.5484
E18: =SUM(E15:E17) -> 1766.8439 | F18: =SUM(F15:F17) -> 14627.824 | G18: =+F18/E18 -> 8.2790698 | I18: =SUM(I14:I17) -> 3680.0832 | J18: =SUM(J14:J17) -> 53962.142 | K18: =+J18/I18 -> 14.663294 | L18: 118.51 | Q18: =SUM(Q14:Q17) -> 5446.927 | R18: =SUM(R14:R17) -> 68589.966
A19: 41593 | B19: 41593 | C19: -0.3 | D19: 0.70902778 | E19: =+'Summary Table'!K32 -> 1440.414 | F19: =+'Summary Table'!L32 -> 20057.086 | G19: =+F19/E19 -> 13.924528 | I19: =+'Summary Table'!N32 -> 524.29221 | J19: =+'Summary Table'!O32 -> 7723.7193 | K19: =+J19/I19 -> 14.731707 | M19: =+'Summary Table'!Q32 -> CLOSED | N19: =+'Summary Table'!R32 -> CLOSED | Q19: =+E19+I19 -> 1964.7062 | R19: =+F19+J19 -> 27780.805
A20: 41594 | B20: 41594 | C20: -0.6 | D20: 0.7375 | E20: =+'Summary Table'!K33 -> 3896.465 | F20: =+'Summary Table'!L33 -> 43395.924 | G20: =+F20/E20 -> 11.137255 | I20: =+'Summary Table'!N33 -> 2660.018 | J20: =+'Summary Table'!O33 -> 38836.262 | K20: =+J20/I20 -> 14.6 | M20: =+'Summary Table'!Q33 -> CLOSED | N20: =+'Summary Table'!R33 -> CLOSED | Q20: =+E20+I20 -> 6556.483 | R20: =+F20+J20 -> 82232.187
A21: 41595 | B21: 41595 | C21: -0.7 | D21: 0.76388889 | E21: =+'Summary Table'!K34 -> CLOSED | F21: =+'Summary Table'!L34 -> CLOSED | I21: =+'Summary Table'!N34 -> 991.05299 | J21: =+'Summary Table'!O34 -> 13921.935 | K21: =+J21/I21 -> 14.047619 | M21: =+'Summary Table'!Q34 -> CLOSED | N21: =+'Summary Table'!R34 -> CLOSED | Q21: =+I21 -> 991.05299 | R21: =+J21 -> 13921.935
E22: =SUM(E19:E21) -> 5336.879 | F22: =SUM(F19:F21) -> 63453.01 | G22: =+F22/E22 -> 11.889535 | H22: 119.34 | I22: =SUM(I19:I21) -> 4175.3632 | J22: =SUM(J19:J21) -> 60481.917 | K22: =+J22/I22 -> 14.485427 | L22: 127.44 | Q22: =SUM(Q19:Q21) -> 9512.2422 | R22: =SUM(R19:R21) -> 123934.93
A23: 41608 | B23: 41608 | C23: -0.1 | D23: 0.68611111 | E23: 2720.2169 | F23: 40803.254 | G23: 15 | I23: 1112.34 | J23: 16685.1 | K23: 15 | M23: =+'Summary Table'!R32 -> CLOSED | N23: =+'Summary Table'!S32 -> CLOSED | Q23: =+E23+I23 -> 3832.5569 | R23: =+F23+J23 -> 57488.354
A24: 41609 | B24: 41609 | C24: -0.9 | D24: 0.71736111 | E24: CLOSED | F24: CLOSED | I24: 525.6112 | J24: 7884.1679 | K24: 15 | M24: =+'Summary Table'!R33 -> CLOSED | N24: =+'Summary Table'!S33 -> CLOSED | Q24: =+I24 -> 525.6112 | R24: =+J24 -> 7884.1679
A25: 41610 | B25: 41610 | C25: -1.4 | D25: 0.74930556 | E25: CLOSED | F25: CLOSED | I25: 180.6607 | J25: 2709.9105 | K25: 15 | M25: =+'Summary Table'!R34 -> CLOSED | N25: =+'Summary Table'!S34 -> CLOSED | Q25: =+I25 -> 180.6607 | R25: =+J25 -> 2709.9105
A26: 41611 | B26: 41611 | C26: -1.7 | D26: 0.78055556 | E26: CLOSED | F26: CLOSED | I26: 223.67515 | J26: 3184.0816 | K26: 14.235294 | M26: =+'Summary Table'!R35 -> CLOSED | N26: =+'Summary Table'!S35 -> CLOSED | Q26: =+I26 -> 223.67515 | R26: =+J26 -> 3184.0816
E27: =SUM(E23:E26) -> 2720.2169 | F27: =SUM(F23:F26) -> 40803.254 | G27: =+F27/E27 -> 15 | I27: =SUM(I23:I26) -> 2042.287 | J27: =SUM(J23:J26) -> 30463.26 | K27: =+J27/I27 -> 14.916248 | Q27: =SUM(Q23:Q26) -> 4762.504 | R27: =SUM(R23:R26) -> 71266.514
A28: 41622 | B28: 41622 | C28: -0.1 | D28: 0.69791667 | E28: 1266.8658 | F28: 19002.987 | G28: 15 | I28: 578.58656 | J28: 8678.7984 | K28: 15 | M28: =+'Summary Table'!Q41 -> CLOSED | N28: =+'Summary Table'!R41 -> CLOSED | Q28: =+E28+I28 -> 1845.4524 | R28: =+F28+J28 -> 27681.785
A29: 41623 | B29: 41623 | C29: -0.3 | D29: 0.72638889 | E29: CLOSED | F29: CLOSED | I29: 821.63649 | J29: 12284.467 | K29: 14.95122 | M29: =+'Summary Table'!Q42 -> CLOSED | N29: =+'Summary Table'!R42 -> CLOSED | Q29: =+I29 -> 821.63649 | R29: =+J29 -> 12284.467
A30: 41624 | B30: 41624 | C30: -0.4 | D30: 0.75208333 | E30: CLOSED | F30: CLOSED | I30: 295.93943 | J30: 4439.0915 | K30: 15 | M30: =+'Summary Table'!Q43 -> CLOSED | N30: =+'Summary Table'!R43 -> CLOSED | Q30: =+I30 -> 295.93943 | R30: =+J30 -> 4439.0915
E31: =SUM(E28:E30) -> 1266.8658 | F31: =SUM(F28:F30) -> 19002.987 | G31: =+F31/E31 -> 15 | I31: =SUM(I28:I30) -> 1696.1625 | J31: =SUM(J28:J30) -> 25402.357 | K31: =+J31/I31 -> 14.97637 | L31: 102.74 | Q31: =SUM(Q28:Q30) -> 2963.0283 | R31: =SUM(R28:R30) -> 44405.344
A32: 41637 | B32: 41637 | C32: -0.2 | D32: 0.67013889 | E32: 3259.2887 | F32: 47376.09 | G32: 14.535714 | I32: 1216.8901 | J32: 18253.352 | K32: 15 | M32: CLOSED | N32: CLOSED | Q32: =+E32+I32 -> 4476.1789 | R32: =+F32+J32 -> 65629.442
A33: 41638 | B33: 41638 | C33: -0.9 | D33: 0.70486111 | E33: 5014.0908 | F33: 74353.688 | G33: 14.828947 | I33: 2510.9249 | J33: 36727.596 | K33: 14.627119 | M33: CLOSED | N33: CLOSED | Q33: =+E33+I33 -> 7525.0156 | R33: =+F33+J33 -> 111081.28
A34: 41639 | B34: 41639 | C34: -1.4 | D34: 0.7375 | E34: 2969.1741 | F34: 44565.623 | G34: 15.009434 | I34: 1993.9448 | J34: 29909.172 | K34: 15 | M34: CLOSED | N34: CLOSED | Q34: =+E34+I34 -> 4963.1189 | R34: =+F34+J34 -> 74474.795
A35: 41640 | B35: 41640 | C35: -1.7 | D35: 0.77013889 | E35: CLOSED | F35: CLOSED | G35: CLOSED | I35: 2305.0059 | J35: 34784.635 | K35: 15.090909 | M35: CLOSED | N35: CLOSED | Q35: =+I35 -> 2305.0059 | R35: =+J35 -> 34784.635
A36: 41641 | B36: 41641 | C36: -1.7 | D36: 0.80208333 | E36: CLOSED | F36: CLOSED | G36: CLOSED | I36: 254.96262 | J36: 2448.827 | K36: 9.6046512 | M36: CLOSED | N36: CLOSED | Q36: =+I36 -> 254.96262 | R36: =+J36 -> 2448.827
A37: 41642 | B37: 41642 | C37: -1.4 | D37: 0.83333333 | E37: CLOSED | F37: CLOSED | G37: CLOSED | I37: 886.41281 | J37: 13296.192 | K37: 15 | M37: CLOSED | N37: CLOSED | Q37: =+I37 -> 886.41281 | R37: =+J37 -> 13296.192
A38: 41643 | B38: 41643 | C38: -0.9 | D38: 0.86458333 | E38: 1269.4116 | F38: 19063.842 | G38: 15.017857 | I38: 666.95773 | J38: 10004.366 | K38: 15 | M38: CLOSED | N38: CLOSED | Q38: =+E38+I38 -> 1936.3693 | R38: =+F38+J38 -> 29068.208
E39: =SUM(E32:E38) -> 12511.965 | F39: =SUM(F32:F38) -> 185359.24 | G39: =+F39/E39 -> 14.814559 | H39: 120.47 | I39: =SUM(I32:I38) -> 9835.0988 | J39: =SUM(J32:J38) -> 145424.14 | K39: =+J39/I39 -> 14.786241 | L39: 119.74 | Q39: =SUM(Q32:Q38) -> 22347.064 | R39: =SUM(R32:R38) -> 330783.38
A40: 41656 | B40: 41656 | C40: 0 | D40: 0.80694444 | E40: CLOSED | F40: CLOSED | G40: CLOSED | I40: 419.11389 | J40: 4009.5228 | K40: 9.5666667 | M40: CLOSED | N40: CLOSED | Q40: =+I40 -> 419.11389 | R40: =+J40 -> 4009.5228
...

Sheet Copy Sheet
A1: BeachName | B1: Date | C1: Effort | D1: Harvest | E1: CPUE | F1: EventID | G1: CorrectionFactor
A2: Twin Harbors | B2: 41536 | C2: 3023.0358 | D2: 45401.518 | E2: 15.018519 | F2: 781 | G2: 0.33563334
A3: Twin Harbors | B3: 41537 | C3: 1669.621 | D3: 21157.228 | E3: 12.671875 | F3: 782 | G3: 0.59235001
A4: Twin Harbors | B4: 41538 | C4: 3341.8734 | D4: 49505.04 | E4: 14.813559 | F4: 783 | G4: 0.51243335
A5: Twin Harbors | B5: 41539 | C5: 673.80127 | D5: 9128.1002 | E5: 13.54717 | F5: 784 | G5: 0.47909999
A6: Twin Harbors | B6: 41540 | C6: 194.71301 | D6: 2336.5561 | E6: 12 | F6: 785 | G6: 0.52824998
A8: BeachName | B8: Date | C8: Effort | D8: Harvest | E8: CPUE | F8: EventID | G8: CorrectionFactor
A9: Copalis | B9: 41551 | C9: 1984.4408 | D9: 29369.724 | E9: 14.8 | F9: 786 | G9: 0.50836664
A10: Copalis | B10: 41552 | C10: 3901.9657 | D10: 58529.485 | E10: 15 | F10: 787 | G10: 0.49360001
A11: LongBeach | B11: 41551 | C11: 1295.1217 | D11: 19426.826 | E11: 15 | F11: 793 | G11: 0.72675002
A12: LongBeach | B12: 41552 | C12: 2719.8142 | D12: 40797.213 | E12: 15 | F12: 794 | G12: 0.72675002
A13: LongBeach | B13: 41553 | C13: 2021.225 | D13: 28329.233 | E13: 14.015873 | F13: 795 | G13: 0.71276665
A14: LongBeach | B14: 41554 | C14: 456.73402 | D14: 5751.9941 | E14: 12.59375 | F14: 799 | G14: 0.53109998
A15: Mocrocks | B15: 41551 | C15: 1198.866 | D15: 18271.325 | E15: 15.240506 | F15: 788 | G15: 0.54243332
A16: Mocrocks | B16: 41552 | C16: 1543.6049 | D16: 23154.074 | E16: 15 | F16: 789 | G16: 0.58923334
A17: Mocrocks | B17: 41553 | C17: 1304.756 | D17: 19208.907 | E17: 14.722222 | F17: 790 | G17: 0.58660001
A18: Mocrocks | B18: 41554 | C18: 175.01989 | D18: 2052.5059 | E18: 11.727273 | F18: 796 | G18: 0.58660001
A19: Twin Harbors | B19: 41552 | C19: 2281.1871 | D19: 34217.806 | E19: 15 | F19: 791 | G19: 0.52824998
A20: Twin Harbors | B20: 41553 | C20: 1647.2 | D20: 21782.8 | E20: 13.224138 | F20: 792 | G20: 0.5
... A22: Twin Harbors | B22: 41555 | C22: 144.39326 | D22: 2165.8989 | E22: 15 | F22: 798 | G22: 0.50367498
A24: BeachName | B24: Date | C24: Effort | D24: Harvest | E24: CPUE | F24: EventID | G24: CorrectionFactor
A25: Copalis | B25: 41565 | C25: 3251.1531 | D25: 46909.494 | E25: 14.428571 | F25: 803 | G25: 0.50836664
A26: Copalis | B26: 41566 | C26: 5650.2729 | D26: 84754.093 | E26: 15 | F26: 805 | G26: 0.50836664
A27: LongBeach | B27: 41565 | C27: 2489.164 | D27: 37337.46 | E27: 15 | F27: 811 | G27: 0.72675002
A28: LongBeach | B28: 41566 | C28: 3646.6981 | D28: 53827.758 | E28: 14.760684 | F28: 812 | G28: 0.71276665
A29: LongBeach | B29: 41567 | C29: 2754.7299 | D29: 41320.949 | E29: 15 | F29: 813 | G29: 0.72675002
A30: Mocrocks | B30: 41565 | C30: 1026.4303 | D30: 15520.121 | E30: 15.120482 | F30: 802 | G30: 0.60364997
A31: Mocrocks | B31: 41566 | C31: 3004.0914 | D31: 44871.925 | E31: 14.936937 | F31: 806 | G31: 0.58399999
A32: Mocrocks | B32: 41567 | C32: 1510.0254 | D32: 22650.381 | E32: 15 | F32: 808 | G32: 0.55293334
A33: Mocrocks | B33: 41568 | C33: 151.72179 | D33: 2275.8268 | E33: 15 | F33: 809 | G33: 0.58660001
A34: Twin Harbors | B34: 41564 | C34: 1456.7098 | D34: 21850.647 | E34: 15 | F34: 800 | G34: 0.53109998
A35: Twin Harbors | B35: 41565 | C35: 1746.0312 | D35: 26190.469 | E35: 15 | F35: 801 | G35: 0.5
A36: Twin Harbors | B36: 41566 | C36: 2819.473 | D36: 42292.095 | E36: 15 | F36: 804 | G36: 0.49849999
... A39: Twin Harbors | B39: 41569 | C39: 140.95128 | D39: 1660.0928 | E39: 11.777778 | F39: 814 | G39: 0.43099999
A41: BeachName | B41: Date | C41: Effort | D41: Harvest | E41: CPUE | F41: EventID | G41: CorrectionFactor
A42: Copalis | B42: 41580 | C42: 1766.8439 | D42: 14627.824 | E42: 8.2790698 | F42: 815 | G42: 0.44510001
A43: LongBeach | B43: 41580 | C43: 2656.3195 | D43: 32798.556 | E43: 12.347368 | F43: 822 | G43: 0.70696664
A44: LongBeach | B44: 41581 | C44: 1126.1308 | D44: 17037.942 | E44: 15.12963 | F44: 823 | G44: 0.72675002
A45: LongBeach | B45: 41582 | C45: 945.61103 | D45: 9867.2455 | E45: 10.434783 | F45: 828 | G45: 0.71276665
A46: LongBeach | B46: 41583 | C46: 347.93996 | D46: 4987.1395 | E46: 14.333333 | F46: 829 | G46: 0.71276665
...

Sheet TAC
A1: 2009 FALL - 2010 SPRING NON-TRIBAL TOTAL ALLOWABLE CATCH (TAC)
B3: 2013 - 2014 | C3: 2012 - 2013 | D3: 2011 - 2012 | E3: 2010 - 2011
A4: LONG BEACH | B4: 2881223.3 | C4: 1847952.1 | D4: 1094641.4 | E4: 1276247.7
A5: TWIN HARBORS | B5: =5744410.73323314*0.4 -> 2297764.3 | C5: 1881783.2 | D5: 616314.31 | E5: 845427.67
A6: COPALIS | B6: =(2615522*0.5)-(161153)+250000 -> 1396608 | C6: 1072689.6 | D6: 371373.04 | E6: 683167.41
A7: MOCROCKS | B7: 2088668.5 | C7: 909667.35 | D7: 605830.7 | E7: 545586.69
A8: KALALOCH | B8: =1033285.9456848*0.254*0.5 -> 131227.32 | C8: 113543.21 | D8: 144560.51 | E8: 258924.12
