Workbook

Sheet Harvest
A1: Date | B1: Day | C1: Tide | D1: Time | E1: Longbeach | G1: Twin Harbors | I1: Copalis | K1: Mocrocks | M1: Kalaloch | O1: Daily Totals
A2: 41919 | B2: =+A2 -> 41919 | C2: -0.5 | D2: 0.76805556 | F2: 24500.023 | H2: 22288.859 | J2: CLOSED | L2: CLOSED | N2: CLOSED | O2: =+F2+H2 -> 46788.882 | Q2: =SUM(O2:O15) -> 367485.58
A3: 41920 | B3: =+A3 -> 41920 | C3: -0.9 | D3: 0.80069444 | F3: 24526.935 | H3: 26450.194 | J3: CLOSED | L3: CLOSED | N3: CLOSED | O3: =+F3+H3 -> 50977.129
A4: 41921 | B4: =+A4 -> 41921 | C4: -1.1 | D4: 0.83194444 | F4: 25889.969 | H4: 17842.448 | J4: CLOSED | L4: CLOSED | N4: CLOSED | O4: =+F4+H4 -> 43732.417
A5: 41922 | B5: =+A5 -> 41922 | C5: -1.1 | D5: 0.86319444 | F5: 37783.571 | H5: 29946.516 | J5: CLOSED | L5: 16040.535 | N5: CLOSED | O5: =+F5+H5+L5 -> 83770.622
A6: 41923 | B6: =+A6 -> 41923 | C6: -0.8 | D6: 0.89444444 | F6: 9249.1406 | H6: 4169.3616 | J6: 8634.5273 | L6: 24229.882 | N6: CLOSED | O6: =+F6+H6+J6+L6 -> 46282.911
A7: 41924 | B7: =+A7 -> 41924 | C7: =-0.3 -> -0.3 | D7: 0.92708333 | F7: =+L7*F5/L5 -> 8871.8219 | H7: =+L7*H5/L5 -> 7031.6316 | J7: CLOSED | L7: 3766.4192 | N7: CLOSED | O7: =+F7+H7+L7 -> 19669.873
A9: 41934 | B9: =+A9 -> 41934 | C9: 0.3 | D9: 0.77152778 | F9: 0 | H9: 265.34297 | J9: CLOSED | L9: CLOSED | N9: CLOSED | O9: =+F9+H9 -> 265.34297
A10: 41935 | B10: =+A10 -> 41935 | C10: -0.1 | D10: 0.79652778 | F10: 7861.4357 | H10: 10873.984 | J10: CLOSED | L10: CLOSED | N10: CLOSED | O10: =+F10+H10 -> 18735.419
A11: 41936 | B11: =+A11 -> 41936 | C11: -0.4 | D11: 0.82222222 | F11: 12716.286 | H11: 11569.649 | J11: CLOSED | L11: 20419.757 | N11: CLOSED | O11: =+F11+H11+L11 -> 44705.691
A12: 41937 | B12: =+A12 -> 41937 | C12: -0.6 | D12: 0.84861111 | E12: * | F12: =+J12*F6/J6 -> 0 | G12: * | H12: =+J12*H6/J6 -> 0 | J12: 0 | K12: * | L12: =+J12*J6/L6 -> 0 | N12: CLOSED | O12: =+F12+H12+J12+L12 -> 0
A13: 41938 | B13: =+A13 -> 41938 | C13: -0.6 | D13: 0.87708333 | F13: 1509.7407 | H13: 3180.3125 | J13: CLOSED | L13: 5700.2073 | N13: CLOSED | O13: =+F13+H13+L13 -> 10390.26
A14: 41939 | B14: =+A14 -> 41939 | C14: -0.4 | D14: 0.90763889 | E14: * | F14: =+H14*(F10+F9)/(H10+H9) -> 896.59494 | H14: 1270.4377 | J14: CLOSED | L14: CLOSED | N14: CLOSED | O14: =+F14+H14 -> 2167.0326
A15: 41940 | B15: =+A15 -> 41940 | C15: -0.2 | D15: 0.94166667 | F15: 0 | G15: * | H15: =+F15*(H10+H9)/(F10+F9) -> 0 | J15: CLOSED | L15: CLOSED | N15: CLOSED | O15: =+F15+H15 -> 0
A17: 41947 | B17: =+A17 -> 41947 | C17: 1.2 | D17: 0.15 | F17: 11971.104 | H17: 16438.646 | J17: CLOSED | L17: CLOSED | N17: CLOSED | O17: =+F17+H17 -> 28409.75
A18: 41948 | B18: =+A18 -> 41948 | C18: -0.7 | D18: 0.71805556 | F18: 7161.623 | H18: 13416.527 | J18: CLOSED | L18: CLOSED | N18: CLOSED | O18: =+F18+H18 -> 20578.15
A19: 41949 | B19: =+A19 -> 41949 | C19: -1.1 | D19: 0.74930556 | F19: 10435.898 | H19: 13304.393 | J19: CLOSED | L19: CLOSED | N19: CLOSED | O19: =+F19+H19 -> 23740.291
A20: 41950 | B20: =+A20 -> 41950 | C20: -1.2 | D20: 0.77916667 | F20: 39767.513 | H20: 22312.183 | J20: CLOSED | L20: 15959.749 | N20: CLOSED | O20: =+F20+H20+L20 -> 78039.446
A21: 41951 | B21: =+A21 -> 41951 | C21: -1.1 | D21: 0.80833333 | E21: * | F21: =+H21*(F20+F19+F18+F17)/(H20+H19+H18+H17) -> 35242.116 | H21: 33277.927 | J21: 42243.129 | L21: 27588.032 | N21: CLOSED | O21: =+F21+H21+J21+L21 -> 138351.2
A22: 41952 | B22: =+A22 -> 41952 | C22: -0.7 | D22: 0.83680556 | E22: * | F22: =+Effort!F22*CPUE!F22 -> 2571.2572 | H22: 2522.6344 | J22: CLOSED | L22: 7838.027 | N22: CLOSED | O22: =+F22+H22+L22 -> 12931.919
A23: 41953 | B23: =+A23 -> 41953 | C23: -0.3 | D23: 0.86597222 | E23: * | F23: =+Effort!F23*CPUE!H23 -> 2571.2572 | G23: * | H23: =+Effort!H23*CPUE!H23 -> 2383.5915 | J23: CLOSED | L23: CLOSED | N23: CLOSED | O23: =+F23+H23 -> 4954.8488
A24: 41954 | B24: =+A24 -> 41954 | C24: 0.2 | D24: 0.89652778 | E24: * | F24: =+H24*(F20+F19+F18+F17)/(H17+H18+H19+H20) -> 897.30882 | H24: 847.2981 | J24: CLOSED | L24: CLOSED | N24: CLOSED | O24: =+F24+H24 -> 1744.6069
A26: 41963 | B26: =+A26 -> 41963 | C26: 0 | D26: 0.7125 | F26: 6375.1289 | H26: 15197.644 | J26: CLOSED | L26: CLOSED | N26: CLOSED | O26: =+F26+H26 -> 21572.772
A27: 41964 | B27: =+A27 -> 41964 | C27: -0.5 | D27: 0.73958333 | F27: 1755.8388 | H27: 908.66071 | J27: CLOSED | L27: 4579.216 | N27: CLOSED | O27: =+F27+H27+L27 -> 7243.7155
A28: 41965 | B28: =+A28 -> 41965 | C28: -0.8 | D28: 0.76666667 | E28: * | F28: =+H28*(F27+F26)/(H26+H27) -> 6404.8876 | H28: 12687.182 | J28: 20605.139 | L28: 19249.966 | N28: CLOSED | O28: =+F28+H28+J28+L28 -> 58947.175
A29: 41966 | B29: =+A29 -> 41966 | C29: -1 | D29: 0.79513889 | F29: 5551.2334 | H29: 3603.9795 | J29: CLOSED | L29: 6389.9843 | N29: CLOSED | O29: =+F29+H29+L29 -> 15545.197
A30: 41967 | B30: =+A30 -> 41967 | C30: -1.1 | D30: 0.82430556 | F30: 196.76642 | H30: 0 | J30: CLOSED | L30: CLOSED | N30: CLOSED | O30: =+F30+H30 -> 196.76642
A31: 41968 | B31: =+A31 -> 41968 | C31: -0.9 | D31: 0.85555556 | E31: * | F31: 1834.6186 | G31: * | H31: 3634.1216 | J31: CLOSED | L31: CLOSED | N31: CLOSED | O31: =+F31+H31 -> 5468.7401
A32: 41969 | B32: =+A32 -> 41969 | C32: -0.5 | D32: 0.88819444 | E32: * | F32: =+H32*(F27+F26)/(H26+H27) -> 1834.6186 | H32: 3634.1216 | J32: CLOSED | L32: CLOSED | N32: CLOSED | O32: =+F32+H32 -> 5468.7401
A34: 41976 | B34: =+A34 -> 41976 | C34: -0.1 | D34: 0.67638889 | F34: 12364.244 | H34: 10111.091 | J34: CLOSED | L34: CLOSED | N34: CLOSED | O34: =+F34+H34 -> 22475.335
A35: 41977 | B35: =+A35 -> 41977 | C35: -0.6 | D35: 0.70972222 | F35: 12452.767 | H35: 9075.6695 | J35: CLOSED | L35: CLOSED | N35: CLOSED | O35: =+F35+H35 -> 21528.436
A36: 41978 | B36: =+A36 -> 41978 | C36: -0.9 | D36: 0.73958333 | F36: 12690.708 | H36: 11410.791 | J36: CLOSED | L36: 14418.036 | N36: CLOSED | O36: =+F36+H36+L36 -> 38519.534
A37: 41979 | B37: =+A37 -> 41979 | C37: -1 | D37: 0.76805556 | F37: 15925.352 | G37: * | H37: =+(H34+H35+H36)*F37/(F34+F35+F36) -> 12991.373 | J37: 15362.334 | L37: 20966.366 | N37: CLOSED | O37: =+F37+H37+J37+L37 -> 65245.425
A38: 41980 | B38: =+A38 -> 41980 | C38: -0.9 | D38: 0.79583333 | F38: 1052.6316 | H38: 3113.8633 | J38: CLOSED | L38: 5210.1071 | M38: 15 | N38: CLOSED | O38: =+F38+H38+L38 -> 9376.6019
A39: 41981 | B39: =+A39 -> 41981 | C39: -0.6 | D39: 0.82222222 | F39: 1052.6316 | H39: 3113.8633 | J39: CLOSED | L39: CLOSED | N39: CLOSED | O39: =+F39+H39 -> 4166.4948
A40: 41982 | B40: =+A40 -> 41982 | C40: -0.2 | D40: 0.84791667 | E40: + | F40: 0 | G40: + | H40: 0 | J40: CLOSED | L40: CLOSED | N40: CLOSED | O40: =+F40+H40 -> 0
A41: 41983 | B41: =+A41 -> 41983 | C41: 0.2 | D41: 0.87361111 | E41: + | F41: 0 | G41: + | H41: 0 | J41: CLOSED | L41: CLOSED | N41: CLOSED | O41: =+F41+H41 -> 0
A43: 41992 | B43: =+A43 -> 41992 | C43: 0 | D43: 0.69513889 | E43: * | F43: =+H43*F46/H46 -> 13707.333 | H43: 3878.2693 | J43: CLOSED | L43: 5939.9198 | N43: CLOSED | O43: =+F43+H43+L43 -> 23525.522
A44: 41993 | B44: =+A44 -> 41993 | C44: -0.6 | D44: 0.72430556 | E44: * | F44: 0 | G44: * | H44: =+L44*H43/L43 -> 0 | J44: 68.986479 | L44: 0 | N44: CLOSED | O44: =+F44+H44+J44+L44 -> 68.986479
A45: 41994 | B45: =+A45 -> 41994 | C45: -1.1 | D45: 0.75416667 | E45: * | F45: =+Effort!F45*CPUE!F45 -> 11149.078 | H45: 9386.4796 | J45: CLOSED | K45: * | L45: =+Effort!L45*CPUE!L45 -> 13086.902 | N45: CLOSED | O45: =+F45+H45+L45 -> 33622.46
...

Sheet Effort
A1: Date | B1: Day | C1: Tide | D1: Time | E1: Longbeach | G1: Twin Harbors | I1: Copalis | K1: Mocrocks | M1: Kalaloch | O1: Daily Totals
A2: 41919 | B2: =+A2 -> 41919 | C2: -0.5 | D2: 0.76805556 | F2: 1633.3349 | H2: 1485.9239 | J2: CLOSED | L2: CLOSED | N2: CLOSED | O2: =+F2+H2 -> 3119.2588 | Q2: =SUM(O2:O15) -> 24068.842
A3: 41920 | B3: =+A3 -> 41920 | C3: -0.9 | D3: 0.80069444 | F3: 1665.0139 | H3: 1763.3463 | J3: CLOSED | L3: CLOSED | N3: CLOSED | O3: =+F3+H3 -> 3428.3601
A4: 41921 | B4: =+A4 -> 41921 | C4: -1.1 | D4: 0.83194444 | F4: 1725.9979 | H4: 1310.4623 | J4: CLOSED | L4: CLOSED | N4: CLOSED | O4: =+F4+H4 -> 3036.4602
A5: 41922 | B5: =+A5 -> 41922 | C5: -1.1 | D5: 0.86319444 | F5: 2633.4004 | H5: 2090.2266 | J5: CLOSED | L5: 1222.3151 | N5: CLOSED | O5: =+F5+H5 -> 4723.627
A6: 41923 | B6: =+A6 -> 41923 | C6: -0.8 | D6: 0.89444444 | F6: 1397.0056 | H6: 484.01957 | J6: 2205.5586 | L6: 2126.2957 | N6: CLOSED | O6: =+F6+H6 -> 1881.0252
A7: 41924 | B7: =+A7 -> 41924 | C7: =-0.3 -> -0.3 | D7: 0.92708333 | F7: =+L7*F5/L5 -> 635.04874 | H7: =+L7*H5/L5 -> 504.06149 | J7: CLOSED | L7: 294.76325 | N7: CLOSED | O7: =+F7+H7 -> 1139.1102
A9: 41934 | B9: =+A9 -> 41934 | C9: 0.3 | D9: 0.77152778 | F9: 218.83188 | H9: 380.70948 | J9: CLOSED | L9: CLOSED | N9: CLOSED | O9: =+F9+H9 -> 599.54136
A10: 41935 | B10: =+A10 -> 41935 | C10: -0.1 | D10: 0.79652778 | F10: 524.09571 | H10: 770.81403 | J10: CLOSED | L10: CLOSED | N10: CLOSED | O10: =+F10+H10 -> 1294.9097
A11: 41936 | B11: =+A11 -> 41936 | C11: -0.4 | D11: 0.82222222 | F11: 892.37092 | H11: 1019.0882 | J11: CLOSED | L11: 1499.4481 | N11: CLOSED | O11: =+F11+H11+L11 -> 3410.9072
A12: 41937 | B12: =+A12 -> 41937 | C12: -0.6 | D12: 0.84861111 | E12: * | F12: =+J12*F6/J6 -> 124.18038 | G12: * | H12: =+J12*H6/J6 -> 43.024691 | J12: 196.05298 | K12: * | L12: =+J12*J6/L6 -> 203.36133 | N12: CLOSED | O12: =+F12+H12+J12+L12 -> 566.61938
A13: 41938 | B13: =+A13 -> 41938 | C13: -0.6 | D13: 0.87708333 | F13: 100.64938 | H13: 212.02083 | J13: CLOSED | L13: 380.01382 | N13: CLOSED | O13: =+F13+H13+L13 -> 692.68403
A14: 41939 | B14: =+A14 -> 41939 | C14: -0.4 | D14: 0.90763889 | E14: * | F14: =+H14*(F10+F9)/(H10+H9) -> 59.251615 | H14: 91.838867 | J14: CLOSED | L14: CLOSED | N14: CLOSED | O14: =+F14+H14 -> 151.09048
A15: 41940 | B15: =+A15 -> 41940 | C15: -0.2 | D15: 0.94166667 | F15: 9.9014573 | G15: * | H15: =+F15*(H10+H9)/(F10+F9) -> 15.347069 | J15: CLOSED | L15: CLOSED | N15: CLOSED | O15: =+F15+H15 -> 25.248526
A17: 41947 | B17: =+A17 -> 41947 | C17: 1.2 | D17: 0.15 | F17: 798.0736 | H17: 1095.9097 | J17: CLOSED | L17: CLOSED | N17: CLOSED | O17: =+F17+H17 -> 1893.9833
A18: 41948 | B18: =+A18 -> 41948 | C18: -0.7 | D18: 0.71805556 | F18: 476.76527 | H18: 894.43514 | J18: CLOSED | L18: CLOSED | N18: CLOSED | O18: =+F18+H18 -> 1371.2004
A19: 41949 | B19: =+A19 -> 41949 | C19: -1.1 | D19: 0.74930556 | F19: 695.72654 | H19: 904.89438 | J19: CLOSED | L19: CLOSED | N19: CLOSED | O19: =+F19+H19 -> 1600.6209
A20: 41950 | B20: =+A20 -> 41950 | C20: -1.2 | D20: 0.77916667 | F20: 2757.2142 | H20: 1487.4789 | J20: CLOSED | L20: 1063.9833 | N20: CLOSED | O20: =+F20+H20+L20 -> 5308.6764
A21: 41951 | B21: =+A21 -> 41951 | C21: -1.1 | D21: 0.80833333 | E21: * | F21: =+H21*(F20+F19+F18+F17)/(H20+H19+H18+H17) -> 2524.6928 | H21: 2340.4256 | J21: 3127.5339 | L21: 1948.1299 | N21: CLOSED | O21: =+F21+H21+J21+L21 -> 9940.7822
A22: 41952 | B22: =+A22 -> 41952 | C22: -0.7 | D22: 0.83680556 | E22: * | F22: =+H22*(F20+F19+F18+F17)/(H17+H18+H19+H20) -> 171.41715 | H22: 158.9061 | J22: CLOSED | L22: 728.74218 | N22: CLOSED | O22: =+F22+H22+L22 -> 1059.0654
A23: 41953 | B23: =+A23 -> 41953 | C23: -0.3 | D23: 0.86597222 | E23: * | F23: 171.41715 | G23: * | H23: 158.9061 | J23: CLOSED | L23: CLOSED | N23: CLOSED | O23: =+F23+H23 -> 330.32325
A24: 41954 | B24: =+A24 -> 41954 | C24: 0.2 | D24: 0.89652778 | E24: * | F24: =+H24*(F20+F19+F18+F17)/(H17+H18+H19+H20) -> 60.933856 | H24: 56.48654 | J24: CLOSED | L24: CLOSED | N24: CLOSED | O24: =+F24+H24 -> 117.4204
A26: 41963 | B26: =+A26 -> 41963 | C26: 0 | D26: 0.7125 | F26: 433.43652 | H26: 1033.7037 | J26: CLOSED | L26: CLOSED | N26: CLOSED | O26: =+F26+H26 -> 1467.1402
A27: 41964 | B27: =+A27 -> 41964 | C27: -0.5 | D27: 0.73958333 | F27: 250.83411 | H27: 302.8869 | J27: CLOSED | L27: 640.25513 | N27: CLOSED | O27: =+F27+H27+L27 -> 1193.9761
A28: 41965 | B28: =+A28 -> 41965 | C28: -0.8 | D28: 0.76666667 | E28: * | F28: =+H28*(F27+F26)/(H26+H27) -> 682.78721 | H28: 1333.693 | J28: 2124.6544 | L28: 1283.331 | N28: CLOSED | O28: =+F28+H28+J28+L28 -> 5424.4657
A29: 41966 | B29: =+A29 -> 41966 | C29: -1 | D29: 0.79513889 | F29: 370.08223 | H29: 367.39597 | J29: CLOSED | L29: 428.76518 | N29: CLOSED | O29: =+F29+H29+L29 -> 1166.2434
A30: 41967 | B30: =+A30 -> 41967 | C30: -1.1 | D30: 0.82430556 | F30: 121.08703 | H30: 94.700896 | J30: CLOSED | L30: CLOSED | N30: CLOSED | O30: =+F30+H30 -> 215.78792
A31: 41968 | B31: =+A31 -> 41968 | C31: -0.9 | D31: 0.85555556 | E31: * | F31: 173.06948 | G31: * | H31: 338.05782 | J31: CLOSED | L31: CLOSED | N31: CLOSED | O31: =+F31+H31 -> 511.1273
A32: 41969 | B32: =+A32 -> 41969 | C32: -0.5 | D32: 0.88819444 | E32: * | F32: =+H32*(F27+F26)/(H26+H27) -> 173.06948 | H32: 338.05782 | J32: CLOSED | L32: CLOSED | N32: CLOSED | O32: =+F32+H32 -> 511.1273
A34: 41976 | B34: =+A34 -> 41976 | C34: -0.1 | D34: 0.67638889 | F34: 824.28295 | H34: 674.07271 | J34: CLOSED | L34: CLOSED | N34: CLOSED | O34: =+F34+H34 -> 1498.3557
A35: 41977 | B35: =+A35 -> 41977 | C35: -0.6 | D35: 0.70972222 | F35: 830.18446 | H35: 609.55989 | J35: CLOSED | L35: CLOSED | N35: CLOSED | O35: =+F35+H35 -> 1439.7443
A36: 41978 | B36: =+A36 -> 41978 | C36: -0.9 | D36: 0.73958333 | F36: 846.04719 | H36: 760.71939 | J36: CLOSED | L36: 961.20238 | N36: CLOSED | O36: =+F36+H36 -> 1606.7666
A37: 41979 | B37: =+A37 -> 41979 | C37: -1 | D37: 0.76805556 | F37: 1083.2473 | G37: * | H37: =+(H34+H35+H36)*F37/(F34+F35+F36) -> 885.63322 | J37: 1191.6819 | L37: 1410.4646 | N37: CLOSED | O37: =+F37+H37 -> 1968.8805
A38: 41980 | B38: =+A38 -> 41980 | C38: -0.9 | D38: 0.79583333 | F38: 70.175437 | H38: 293.76068 | J38: CLOSED | L38: 347.34048 | N38: CLOSED | O38: =+F38+H38 -> 363.93612
A39: 41981 | B39: =+A39 -> 41981 | C39: -0.6 | D39: 0.82222222 | F39: 70.175437 | H39: 293.76068 | J39: CLOSED | L39: CLOSED | N39: CLOSED | O39: =+F39+H39 -> 363.93612
A40: 41982 | B40: =+A40 -> 41982 | C40: -0.2 | D40: 0.84791667 | E40: + | F40: 0 | G40: + | H40: 0 | J40: CLOSED | L40: CLOSED | N40: CLOSED | O40: =+F40+H40 -> 0
A41: 41983 | B41: =+A41 -> 41983 | C41: 0.2 | D41: 0.87361111 | E41: + | F41: 0 | G41: + | H41: 0 | J41: CLOSED | L41: CLOSED | N41: CLOSED | O41: =+F41+H41 -> 0
A43: 41992 | B43: =+A43 -> 41992 | C43: 0 | D43: 0.69513889 | E43: * | F43: =+H43*F46/H46 -> 1267.172 | H43: 550.46402 | J43: CLOSED | L43: 909.71745 | N43: CLOSED | O43: =+F43+H43 -> 1817.636
A44: 41993 | B44: =+A44 -> 41993 | C44: -0.6 | D44: 0.72430556 | E44: * | F44: 1267.172 | G44: * | H44: =+L44*H43/L43 -> 274.97499 | J44: 781.84676 | L44: 454.43396 | N44: CLOSED | O44: =+F44+H44 -> 1542.147
A45: 41994 | B45: =+A45 -> 41994 | C45: -1.1 | D45: 0.75416667 | E45: * | F45: =+H45*F29/H29 -> 743.2719 | H45: 737.87683 | J45: CLOSED | K45: * | L45: =+H45*L38/H38 -> 872.46014 | N45: CLOSED | O45: =+F45+H45 -> 1481.1487
...

Sheet CPUE
A1: Date | B1: Day | C1: Tide | D1: Time | E1: Longbeach | G1: Twin Harbors | I1: Copalis | K1: Mocrocks | M1: Kalaloch
A2: 41919 | B2: =+A2 -> 41919 | C2: -0.5 | D2: 0.76805556 | F2: =+Harvest!F2/Effort!F2 -> 15 | H2: =+Harvest!H2/Effort!H2 -> 15 | J2: CLOSED | L2: CLOSED | N2: CLOSED | P2: =AVERAGE(F2:N15) -> 10.128751
A3: 41920 | B3: =+A3 -> 41920 | C3: -0.9 | D3: 0.80069444 | F3: =+Harvest!F3/Effort!F3 -> 14.730769 | H3: =+Harvest!H3/Effort!H3 -> 15 | J3: CLOSED | L3: CLOSED | N3: CLOSED
A4: 41921 | B4: =+A4 -> 41921 | C4: -1.1 | D4: 0.83194444 | F4: =+Harvest!F4/Effort!F4 -> 15 | H4: =+Harvest!H4/Effort!H4 -> 13.615385 | J4: CLOSED | L4: CLOSED | N4: CLOSED
A5: 41922 | B5: =+A5 -> 41922 | C5: -1.1 | D5: 0.86319444 | F5: =+Harvest!F5/Effort!F5 -> 14.347826 | H5: =+Harvest!H5/Effort!H5 -> 14.326923 | J5: CLOSED | L5: =+Harvest!L5/Effort!L5 -> 13.123077 | N5: CLOSED
A6: 41923 | B6: =+A6 -> 41923 | C6: -0.8 | D6: 0.89444444 | F6: =+Harvest!F6/Effort!F6 -> 6.6206897 | H6: =+Harvest!H6/Effort!H6 -> 8.6140351 | J6: =+Harvest!J6/Effort!J6 -> 3.9148936 | L6: =+Harvest!L6/Effort!L6 -> 11.395349 | N6: CLOSED
A7: 41924 | B7: =+A7 -> 41924 | C7: =-0.3 -> -0.3 | D7: 0.92708333 | F7: =+Harvest!F7/Effort!F7 -> 13.970301 | H7: =+Harvest!H7/Effort!H7 -> 13.949948 | J7: CLOSED | L7: =+Harvest!L7/Effort!L7 -> 12.777778 | N7: CLOSED
A9: 41934 | B9: =+A9 -> 41934 | C9: 0.3 | D9: 0.77152778 | F9: =+Harvest!F9/Effort!F9 -> 0 | H9: =+Harvest!H9/Effort!H9 -> 0.6969697 | J9: CLOSED | L9: CLOSED | N9: CLOSED
A10: 41935 | B10: =+A10 -> 41935 | C10: -0.1 | D10: 0.79652778 | F10: =+Harvest!F10/Effort!F10 -> 15 | H10: =+Harvest!H10/Effort!H10 -> 14.107143 | J10: CLOSED | L10: CLOSED | N10: CLOSED
A11: 41936 | B11: =+A11 -> 41936 | C11: -0.4 | D11: 0.82222222 | F11: =+Harvest!F11/Effort!F11 -> 14.25 | H11: =+Harvest!H11/Effort!H11 -> 11.352941 | J11: CLOSED | L11: =+Harvest!L11/Effort!L11 -> 13.618182 | N11: CLOSED
A12: 41937 | B12: =+A12 -> 41937 | C12: -0.6 | D12: 0.84861111 | E12: * | F12: =+Harvest!F12/Effort!F12 -> 0 | G12: * | H12: =+Harvest!H12/Effort!H12 -> 0 | J12: =+Harvest!J12/Effort!J12 -> 0 | L12: =+Harvest!L12/Effort!L12 -> 0 | N12: CLOSED
A13: 41938 | B13: =+A13 -> 41938 | C13: -0.6 | D13: 0.87708333 | F13: =+Harvest!F13/Effort!F13 -> 15 | H13: =+Harvest!H13/Effort!H13 -> 15 | J13: CLOSED | L13: =+Harvest!L13/Effort!L13 -> 15 | N13: CLOSED
A14: 41939 | B14: =+A14 -> 41939 | C14: -0.4 | D14: 0.90763889 | E14: * | F14: =+Harvest!F14/Effort!F14 -> 15.131992 | H14: =+Harvest!H14/Effort!H14 -> 13.833333 | J14: CLOSED | L14: CLOSED | N14: CLOSED
A15: 41940 | B15: =+A15 -> 41940 | C15: -0.2 | D15: 0.94166667 | F15: =+Harvest!F15/Effort!F15 -> 0 | G15: * | H15: =+Harvest!H15/Effort!H15 -> 0 | J15: CLOSED | L15: CLOSED | N15: CLOSED
A17: 41947 | B17: =+A17 -> 41947 | C17: 1.2 | D17: 0.15 | F17: =+Harvest!F17/Effort!F17 -> 15 | H17: =+Harvest!H17/Effort!H17 -> 15 | J17: CLOSED | L17: CLOSED | N17: CLOSED
A18: 41948 | B18: =+A18 -> 41948 | C18: -0.7 | D18: 0.71805556 | F18: =+Harvest!F18/Effort!F18 -> 15.021277 | H18: =+Harvest!H18/Effort!H18 -> 15 | J18: CLOSED | L18: CLOSED | N18: CLOSED
A19: 41949 | B19: =+A19 -> 41949 | C19: -1.1 | D19: 0.74930556 | F19: =+Harvest!F19/Effort!F19 -> 15 | H19: =+Harvest!H19/Effort!H19 -> 14.702703 | J19: CLOSED | L19: CLOSED | N19: CLOSED
A20: 41950 | B20: =+A20 -> 41950 | C20: -1.2 | D20: 0.77916667 | F20: =+Harvest!F20/Effort!F20 -> 14.423077 | H20: =+Harvest!H20/Effort!H20 -> 15 | J20: CLOSED | L20: =+Harvest!L20/Effort!L20 -> 15 | N20: CLOSED
A21: 41951 | B21: =+A21 -> 41951 | C21: -1.1 | D21: 0.80833333 | E21: * | F21: =+Harvest!F21/Effort!F21 -> 13.958972 | H21: =+Harvest!H21/Effort!H21 -> 14.21875 | J21: =+Harvest!J21/Effort!J21 -> 13.506849 | L21: =+Harvest!L21/Effort!L21 -> 14.16129 | N21: CLOSED
A22: 41952 | B22: =+A22 -> 41952 | C22: -0.7 | D22: 0.83680556 | E22: * | F22: 15 | H22: =+Harvest!H22/Effort!H22 -> 15.875 | J22: CLOSED | L22: =+Harvest!L22/Effort!L22 -> 10.755556 | N22: CLOSED
A23: 41953 | B23: =+A23 -> 41953 | C23: -0.3 | D23: 0.86597222 | E23: * | F23: =+Harvest!F23/Effort!F23 -> 15 | G23: * | H23: 15 | J23: CLOSED | L23: CLOSED | N23: CLOSED
A24: 41954 | B24: =+A24 -> 41954 | C24: 0.2 | D24: 0.89652778 | E24: * | F24: =+Harvest!F24/Effort!F24 -> 14.725948 | H24: =+Harvest!H24/Effort!H24 -> 15 | J24: CLOSED | L24: CLOSED | N24: CLOSED
A26: 41963 | B26: =+A26 -> 41963 | C26: 0 | D26: 0.7125 | F26: =+Harvest!F26/Effort!F26 -> 14.708333 | H26: =+Harvest!H26/Effort!H26 -> 14.702128 | J26: CLOSED | L26: CLOSED | N26: CLOSED
A27: 41964 | B27: =+A27 -> 41964 | C27: -0.5 | D27: 0.73958333 | F27: =+Harvest!F27/Effort!F27 -> 7 | H27: =+Harvest!H27/Effort!H27 -> 3 | J27: CLOSED | L27: =+Harvest!L27/Effort!L27 -> 7.1521739 | N27: CLOSED
A28: 41965 | B28: =+A28 -> 41965 | C28: -0.8 | D28: 0.76666667 | E28: * | F28: =+Harvest!F28/Effort!F28 -> 9.3805031 | H28: =+Harvest!H28/Effort!H28 -> 9.5128205 | J28: =+Harvest!J28/Effort!J28 -> 9.6981132 | L28: =+Harvest!L28/Effort!L28 -> 15 | N28: CLOSED
A29: 41966 | B29: =+A29 -> 41966 | C29: -1 | D29: 0.79513889 | F29: =+Harvest!F29/Effort!F29 -> 15 | H29: =+Harvest!H29/Effort!H29 -> 9.8095238 | J29: CLOSED | L29: =+Harvest!L29/Effort!L29 -> 14.903226 | N29: CLOSED
A30: 41967 | B30: =+A30 -> 41967 | C30: -1.1 | D30: 0.82430556 | F30: =+Harvest!F30/Effort!F30 -> 1.625 | H30: =+Harvest!H30/Effort!H30 -> 0 | J30: CLOSED | L30: CLOSED | N30: CLOSED
A31: 41968 | B31: =+A31 -> 41968 | C31: -0.9 | D31: 0.85555556 | E31: * | F31: =+Harvest!F31/Effort!F31 -> 10.600474 | G31: * | H31: =+Harvest!H31/Effort!H31 -> 10.75 | J31: CLOSED | L31: CLOSED | N31: CLOSED
A32: 41969 | B32: =+A32 -> 41969 | C32: -0.5 | D32: 0.88819444 | E32: * | F32: =+Harvest!F32/Effort!F32 -> 10.600474 | H32: =+Harvest!H32/Effort!H32 -> 10.75 | J32: CLOSED | L32: CLOSED | N32: CLOSED
A34: 41976 | B34: =+A34 -> 41976 | C34: -0.1 | D34: 0.67638889 | F34: =+Harvest!F34/Effort!F34 -> 15 | H34: =+Harvest!H34/Effort!H34 -> 15 | J34: CLOSED | L34: CLOSED | N34: CLOSED
A35: 41977 | B35: =+A35 -> 41977 | C35: -0.6 | D35: 0.70972222 | F35: =+Harvest!F35/Effort!F35 -> 15 | H35: =+Harvest!H35/Effort!H35 -> 14.888889 | J35: CLOSED | L35: CLOSED | N35: CLOSED
A36: 41978 | B36: =+A36 -> 41978 | C36: -0.9 | D36: 0.73958333 | F36: =+Harvest!F36/Effort!F36 -> 15 | H36: =+Harvest!H36/Effort!H36 -> 15 | J36: CLOSED | L36: =+Harvest!L36/Effort!L36 -> 15 | N36: CLOSED
A37: 41979 | B37: =+A37 -> 41979 | C37: -1 | D37: 0.76805556 | F37: =+Harvest!F37/Effort!F37 -> 14.701493 | G37: * | H37: =+Harvest!H37/Effort!H37 -> 14.669022 | J37: =+Harvest!J37/Effort!J37 -> 12.891304 | L37: =+Harvest!L37/Effort!L37 -> 14.864865 | N37: CLOSED
A38: 41980 | B38: =+A38 -> 41980 | C38: -0.9 | D38: 0.79583333 | F38: =+Harvest!F38/Effort!F38 -> 15 | H38: =+Harvest!H38/Effort!H38 -> 10.6 | J38: CLOSED | L38: =+Harvest!L38/Effort!L38 -> 15 | N38: CLOSED
A39: 41981 | B39: =+A39 -> 41981 | C39: -0.6 | D39: 0.82222222 | F39: =+Harvest!F39/Effort!F39 -> 15 | H39: =+Harvest!H39/Effort!H39 -> 10.6 | J39: CLOSED | L39: CLOSED | N39: CLOSED
A40: 41982 | B40: =+A40 -> 41982 | C40: -0.2 | D40: 0.84791667 | E40: + | F40: 0 | G40: + | H40: 0 | J40: CLOSED | L40: CLOSED | N40: CLOSED
A41: 41983 | B41: =+A41 -> 41983 | C41: 0.2 | D41: 0.87361111 | E41: + | F41: 0 | G41: + | H41: 0 | J41: CLOSED | L41: CLOSED | N41: CLOSED
A43: 41992 | B43: =+A43 -> 41992 | C43: 0 | D43: 0.69513889 | E43: * | F43: =+Harvest!F43/Effort!F43 -> 10.817264 | H43: =+Harvest!H43/Effort!H43 -> 7.0454545 | J43: CLOSED | L43: =+Harvest!L43/Effort!L43 -> 6.5294118 | N43: CLOSED
A44: 41993 | B44: =+A44 -> 41993 | C44: -0.6 | D44: 0.72430556 | E44: * | F44: =+Harvest!F44/Effort!F44 -> 0 | G44: * | H44: =+Harvest!H44/Effort!H44 -> 0 | J44: =+Harvest!J44/Effort!J44 -> 0.088235294 | L44: =+Harvest!L44/Effort!L44 -> 0 | N44: CLOSED
A45: 41994 | B45: =+A45 -> 41994 | C45: -1.1 | D45: 0.75416667 | E45: * | F45: 15 | H45: =+Harvest!H45/Effort!H45 -> 12.72093 | J45: CLOSED | L45: 15 | N45: CLOSED
...

Sheet Summary Table
A1: 2014-2015 State (non-Indian) Recreational Razor Clam Effort, Harvest and CPUE totals.
E2: LONG BEACH | H2: TWIN HARBORS | K2: COPALIS | N2: MOCROCKS | Q2: KALALOCH | T2: DAILY TOTALS
A3: DATE | B3: DAY | C3: TIDE | D3: TIME | E3: Effort | F3: Harvest | G3: CPUE | H3: Effort | I3: Harvest | J3: CPUE | K3: Effort | L3: Harvest | M3: CPUE | N3: Effort | O3: Harvest | P3: CPUE | Q3: Effort | R3: Harvest | S3: CPUE | T3: Effort | U3: Harvest
A4: 41919 | B4: =+A4 -> 41919 | C4: -0.5 | D4: 0.76805556 | E4: =Effort!F2 -> 1633.3349 | F4: =Harvest!F2 -> 24500.023 | G4: =CPUE!F2 -> 15 | H4: =Effort!H2 -> 1485.9239 | I4: =Harvest!H2 -> 22288.859 | J4: =CPUE!H2 -> 15 | K4: =Effort!J2 -> CLOSED | L4: =Harvest!J2 -> CLOSED | M4: =CPUE!J2 -> CLOSED | N4: =Effort!L2 -> CLOSED | O4: =Harvest!L2 -> CLOSED | P4: =CPUE!L2 -> CLOSED | Q4: =Effort!N2 -> CLOSED | R4: =Harvest!N2 -> CLOSED | S4: =CPUE!N2 -> CLOSED | T4: =+E4+H4 -> 3119.2588 | U4: =+F4+I4 -> 46788.882
A5: 41920 | B5: =+A5 -> 41920 | C5: -0.9 | D5: 0.80069444 | E5: =Effort!F3 -> 1665.0139 | F5: =Harvest!F3 -> 24526.935 | G5: =CPUE!F3 -> 14.730769 | H5: =Effort!H3 -> 1763.3463 | I5: =Harvest!H3 -> 26450.194 | J5: =CPUE!H3 -> 15 | K5: =Effort!J3 -> CLOSED | L5: =Harvest!J3 -> CLOSED | M5: =CPUE!J3 -> CLOSED | N5: =Effort!L3 -> CLOSED | O5: =Harvest!L3 -> CLOSED | P5: =CPUE!L3 -> CLOSED | Q5: =Effort!N3 -> CLOSED | R5: =Harvest!N3 -> CLOSED | S5: =CPUE!N3 -> CLOSED | T5: =+E5+H5 -> 3428.3601 | U5: =+F5+I5 -> 50977.129
A6: 41921 | B6: =+A6 -> 41921 | C6: -1.1 | D6: 0.83194444 | E6: =Effort!F4 -> 1725.9979 | F6: =Harvest!F4 -> 25889.969 | G6: =CPUE!F4 -> 15 | H6: =Effort!H4 -> 1310.4623 | I6: =Harvest!H4 -> 17842.448 | J6: =CPUE!H4 -> 13.615385 | K6: =Effort!J4 -> CLOSED | L6: =Harvest!J4 -> CLOSED | M6: =CPUE!J4 -> CLOSED | N6: =Effort!L4 -> CLOSED | O6: =Harvest!L4 -> CLOSED | P6: =CPUE!L4 -> CLOSED | Q6: =Effort!N4 -> CLOSED | R6: =Harvest!N4 -> CLOSED | S6: =CPUE!N4 -> CLOSED | T6: =+E6+H6 -> 3036.4602 | U6: =+F6+I6 -> 43732.417
A7: 41922 | B7: =+A7 -> 41922 | C7: -1.1 | D7: 0.86319444 | E7: =Effort!F5 -> 2633.4004 | F7: =Harvest!F5 -> 37783.571 | G7: =CPUE!F5 -> 14.347826 | H7: =Effort!H5 -> 2090.2266 | I7: =Harvest!H5 -> 29946.516 | J7: =CPUE!H5 -> 14.326923 | K7: =Effort!J5 -> CLOSED | L7: =Harvest!J5 -> CLOSED | M7: =CPUE!J5 -> CLOSED | N7: =Effort!L5 -> 1222.3151 | O7: =Harvest!L5 -> 16040.535 | P7: =CPUE!L5 -> 13.123077 | Q7: =Effort!N5 -> CLOSED | R7: =Harvest!N5 -> CLOSED | S7: =CPUE!N5 -> CLOSED | T7: =+E7+H7+N7 -> 5945.9421 | U7: =+F7+I7+O7 -> 83770.622
A8: 41923 | B8: =+A8 -> 41923 | C8: -0.8 | D8: 0.89444444 | E8: =Effort!F6 -> 1397.0056 | F8: =Harvest!F6 -> 9249.1406 | G8: =CPUE!F6 -> 6.6206897 | H8: =Effort!H6 -> 484.01957 | I8: =Harvest!H6 -> 4169.3616 | J8: =CPUE!H6 -> 8.6140351 | K8: =Effort!J6 -> 2205.5586 | L8: =Harvest!J6 -> 8634.5273 | M8: =CPUE!J6 -> 3.9148936 | N8: =Effort!L6 -> 2126.2957 | O8: =Harvest!L6 -> 24229.882 | P8: =CPUE!L6 -> 11.395349 | Q8: =Effort!N6 -> CLOSED | R8: =Harvest!N6 -> CLOSED | S8: =CPUE!N6 -> CLOSED | T8: =+E8+H8+K8+N8 -> 6212.8795 | U8: =+F8+I8+L8+O8 -> 46282.911
A9: 41924 | B9: =+A9 -> 41924 | C9: -0.3 | D9: 0.92708333 | E9: =Effort!F7 -> 635.04874 | F9: =Harvest!F7 -> 8871.8219 | G9: =CPUE!F7 -> 13.970301 | H9: =Effort!H7 -> 504.06149 | I9: =Harvest!H7 -> 7031.6316 | J9: =CPUE!H7 -> 13.949948 | K9: =Effort!J7 -> CLOSED | L9: =Harvest!J7 -> CLOSED | M9: =CPUE!J7 -> CLOSED | N9: =Effort!L7 -> 294.76325 | O9: =Harvest!L7 -> 3766.4192 | P9: =CPUE!L7 -> 12.777778 | Q9: =Effort!N7 -> CLOSED | R9: =Harvest!N7 -> CLOSED | S9: =CPUE!N7 -> CLOSED | T9: =+E9+H9+N9 -> 1433.8735 | U9: =+F9+I9+O9 -> 19669.873
A10: Tide Series Totals | E10: =SUM(E4:E9) -> 9689.8015 | F10: =SUM(F4:F9) -> 130821.46 | G10: =+F10/E10 -> 13.500943 | H10: =SUM(H4:H9) -> 7638.0401 | I10: =SUM(I4:I9) -> 107729.01 | J10: =+I10/H10 -> 14.104274 | K10: =SUM(K8:K9) -> 2205.5586 | L10: =SUM(L8:L9) -> 8634.5273 | M10: =+L10/K10 -> 3.9148936 | N10: =SUM(N7:N9) -> 3643.3741 | O10: =SUM(O7:O9) -> 44036.836 | P10: =+O10/N10 -> 12.086828 | T10: =SUM(T4:T9) -> 23176.774 | U10: =SUM(U4:U9) -> 291221.83
A11: 41934 | B11: 41934 | C11: 0.3 | D11: 0.77152778 | E11: =Effort!F9 -> 218.83188 | F11: =Harvest!F9 -> 0 | G11: =CPUE!F9 -> 0 | H11: =Effort!H9 -> 380.70948 | I11: =Harvest!H9 -> 265.34297 | J11: =CPUE!H9 -> 0.6969697 | K11: =Effort!J9 -> CLOSED | L11: =Harvest!J9 -> CLOSED | M11: =CPUE!J9 -> CLOSED | N11: =Effort!L9 -> CLOSED | O11: =Harvest!L9 -> CLOSED | P11: =CPUE!L9 -> CLOSED | Q11: =Effort!N9 -> CLOSED | R11: =Harvest!N9 -> CLOSED | S11: =CPUE!N9 -> CLOSED | T11: =+E11+H11 -> 599.54136 | U11: =+F11+I11 -> 265.34297
A12: 41935 | B12: 41935 | C12: -0.1 | D12: 0.79652778 | E12: =Effort!F10 -> 524.09571 | F12: =Harvest!F10 -> 7861.4357 | G12: =CPUE!F10 -> 15 | H12: =Effort!H10 -> 770.81403 | I12: =Harvest!H10 -> 10873.984 | J12: =CPUE!H10 -> 14.107143 | K12: =Effort!J10 -> CLOSED | L12: =Harvest!J10 -> CLOSED | M12: =CPUE!J10 -> CLOSED | N12: =Effort!L10 -> CLOSED | O12: =Harvest!L10 -> CLOSED | P12: =CPUE!L10 -> CLOSED | Q12: =Effort!N10 -> CLOSED | R12: =Harvest!N10 -> CLOSED | S12: =CPUE!N10 -> CLOSED | T12: =+E12+H12 -> 1294.9097 | U12: =+F12+I12 -> 18735.419
A13: 41936 | B13: 41936 | C13: -0.4 | D13: 0.82222222 | E13: =Effort!F11 -> 892.37092 | F13: =Harvest!F11 -> 12716.286 | G13: =CPUE!F11 -> 14.25 | H13: =Effort!H11 -> 1019.0882 | I13: =Harvest!H11 -> 11569.649 | J13: =CPUE!H11 -> 11.352941 | K13: =Effort!J11 -> CLOSED | L13: =Harvest!J11 -> CLOSED | M13: =CPUE!J11 -> CLOSED | N13: =Effort!L11 -> 1499.4481 | O13: =Harvest!L11 -> 20419.757 | P13: =CPUE!L11 -> 13.618182 | Q13: =Effort!N11 -> CLOSED | R13: =Harvest!N11 -> CLOSED | S13: =CPUE!N11 -> CLOSED | T13: =+E13+H13+N13 -> 3410.9072 | U13: =+F13+I13+O13 -> 44705.691
A14: 41937 | B14: 41937 | C14: -0.6 | D14: 0.84861111 | E14: =Effort!F12 -> 124.18038 | F14: =Harvest!F12 -> 0 | G14: =CPUE!F12 -> 0 | H14: =Effort!H12 -> 43.024691 | I14: =Harvest!H12 -> 0 | J14: =CPUE!H12 -> 0 | K14: =Effort!J12 -> 196.05298 | L14: =Harvest!J12 -> 0 | M14: =CPUE!J12 -> 0 | N14: =Effort!L12 -> 203.36133 | O14: =Harvest!L12 -> 0 | P14: =CPUE!L12 -> 0 | Q14: =Effort!N12 -> CLOSED | R14: =Harvest!N12 -> CLOSED | S14: =CPUE!N12 -> CLOSED | T14: =+E14+H14+K14+N14 -> 566.61938 | U14: =+F14+I14+L14+O14 -> 0
A15: 41938 | B15: 41938 | C15: -0.6 | D15: 0.87708333 | E15: =Effort!F13 -> 100.64938 | F15: =Harvest!F13 -> 1509.7407 | G15: =CPUE!F13 -> 15 | H15: =Effort!H13 -> 212.02083 | I15: =Harvest!H13 -> 3180.3125 | J15: =CPUE!H13 -> 15 | K15: =Effort!J13 -> CLOSED | L15: =Harvest!J13 -> CLOSED | M15: =CPUE!J13 -> CLOSED | N15: =Effort!L13 -> 380.01382 | O15: =Harvest!L13 -> 5700.2073 | P15: =CPUE!L13 -> 15 | Q15: =Effort!N13 -> CLOSED | R15: =Harvest!N13 -> CLOSED | S15: =CPUE!N13 -> CLOSED | T15: =+E15+H15+N15 -> 692.68403 | U15: =+F15+I15+O15 -> 10390.26
A16: 41939 | B16: 41939 | C16: -0.4 | D16: 0.90763889 | E16: =Effort!F14 -> 59.251615 | F16: =Harvest!F14 -> 896.59494 | G16: =CPUE!F14 -> 15.131992 | H16: =Effort!H14 -> 91.838867 | I16: =Harvest!H14 -> 1270.4377 | J16: =CPUE!H14 -> 13.833333 | K16: =Effort!J14 -> CLOSED | L16: =Harvest!J14 -> CLOSED | M16: =CPUE!J14 -> CLOSED | N16: =Effort!L14 -> CLOSED | O16: =Harvest!L14 -> CLOSED | P16: =CPUE!L14 -> CLOSED | Q16: =Effort!N14 -> CLOSED | R16: =Harvest!N14 -> CLOSED | S16: =CPUE!N14 -> CLOSED | T16: =+E16+H16 -> 151.09048 | U16: =+F16+I16 -> 2167.0326
A17: 41940 | B17: 41940 | C17: -0.2 | D17: 0.94166667 | E17: =Effort!F15 -> 9.9014573 | F17: =Harvest!F15 -> 0 | G17: =CPUE!F15 -> 0 | H17: =Effort!H15 -> 15.347069 | I17: =Harvest!H15 -> 0 | J17: =CPUE!H15 -> 0 | K17: =Effort!J15 -> CLOSED | L17: =Harvest!J15 -> CLOSED | M17: =CPUE!J15 -> CLOSED | N17: =Effort!L15 -> CLOSED | O17: =Harvest!L15 -> CLOSED | P17: =CPUE!L15 -> CLOSED | Q17: =Effort!N15 -> CLOSED | R17: =Harvest!N15 -> CLOSED | S17: =CPUE!N15 -> CLOSED | T17: =+E17+H17 -> 25.248526 | U17: =+F17+I17 -> 0
A18: Tide Series Totals | E18: =SUM(E11:E17) -> 1929.2813 | F18: =SUM(F11:F17) -> 22984.057 | G18: =+F18/E18 -> 11.913274 | H18: =SUM(H11:H17) -> 2532.8432 | I18: =SUM(I11:I17) -> 27159.725 | J18: =+I18/H18 -> 10.723019 | K18: =SUM(K14:K17) -> 196.05298 | L18: =SUM(L14:L17) -> 0 | M18: =+L18/K18 -> 0 | N18: =SUM(N13:N17) -> 2082.8232 | O18: =SUM(O13:O17) -> 26119.964 | P18: =+O18/N18 -> 12.540653 | T18: =SUM(T11:T17) -> 6741.0007 | U18: =SUM(U11:U17) -> 76263.746
A19: 41947 | B19: 41947 | C19: 1.2 | D19: 0.15 | E19: =Effort!F17 -> 798.0736 | F19: =Harvest!F17 -> 11971.104 | G19: =CPUE!F17 -> 15 | H19: =Effort!H17 -> 1095.9097 | I19: =Harvest!H17 -> 16438.646 | J19: =CPUE!H17 -> 15 | K19: =Effort!J17 -> CLOSED | L19: =Harvest!J17 -> CLOSED | M19: =CPUE!J17 -> CLOSED | N19: =Effort!L17 -> CLOSED | O19: =Harvest!L17 -> CLOSED | P19: =CPUE!L17 -> CLOSED | Q19: =Effort!N17 -> CLOSED | R19: =Harvest!N17 -> CLOSED | S19: =CPUE!N17 -> CLOSED | T19: =+E19+H19 -> 1893.9833 | U19: =+F19+I19 -> 28409.75
A20: 41948 | B20: 41948 | C20: -0.7 | D20: 0.71805556 | E20: =Effort!F18 -> 476.76527 | F20: =Harvest!F18 -> 7161.623 | G20: =CPUE!F18 -> 15.021277 | H20: =Effort!H18 -> 894.43514 | I20: =Harvest!H18 -> 13416.527 | J20: =CPUE!H18 -> 15 | K20: =Effort!J18 -> CLOSED | L20: =Harvest!J18 -> CLOSED | M20: =CPUE!J18 -> CLOSED | N20: =Effort!L18 -> CLOSED | O20: =Harvest!L18 -> CLOSED | P20: =CPUE!L18 -> CLOSED | Q20: =Effort!N18 -> CLOSED | R20: =Harvest!N18 -> CLOSED | S20: =CPUE!N18 -> CLOSED | T20: =+E20+H20 -> 1371.2004 | U20: =+F20+I20 -> 20578.15
A21: 41949 | B21: 41949 | C21: -1.1 | D21: 0.74930556 | E21: =Effort!F19 -> 695.72654 | F21: =Harvest!F19 -> 10435.898 | G21: =CPUE!F19 -> 15 | H21: =Effort!H19 -> 904.89438 | I21: =Harvest!H19 -> 13304.393 | J21: =CPUE!H19 -> 14.702703 | K21: =Effort!J19 -> CLOSED | L21: =Harvest!J19 -> CLOSED | M21: =CPUE!J19 -> CLOSED | N21: =Effort!L19 -> CLOSED | O21: =Harvest!L19 -> CLOSED | P21: =CPUE!L19 -> CLOSED | Q21: =Effort!N19 -> CLOSED | R21: =Harvest!N19 -> CLOSED | S21: =CPUE!N19 -> CLOSED | T21: =+E21+H21 -> 1600.6209 | U21: =+F21+I21 -> 23740.291
A22: 41950 | B22: 41950 | C22: -1.2 | D22: 0.77916667 | E22: =Effort!F20 -> 2757.2142 | F22: =Harvest!F20 -> 39767.513 | G22: =CPUE!F20 -> 14.423077 | H22: =Effort!H20 -> 1487.4789 | I22: =Harvest!H20 -> 22312.183 | J22: =CPUE!H20 -> 15 | K22: =Effort!J20 -> CLOSED | L22: =Harvest!J20 -> CLOSED | M22: =CPUE!J20 -> CLOSED | N22: =Effort!L20 -> 1063.9833 | O22: =Harvest!L20 -> 15959.749 | P22: =CPUE!L20 -> 15 | Q22: =Effort!N20 -> CLOSED | R22: =Harvest!N20 -> CLOSED | S22: =CPUE!N20 -> CLOSED | T22: =+E22+H22+N22 -> 5308.6764 | U22: =+F22+I22+O22 -> 78039.446
A23: 41951 | B23: 41951 | C23: -1.1 | D23: 0.80833333 | E23: =Effort!F21 -> 2524.6928 | F23: =Harvest!F21 -> 35242.116 | G23: =CPUE!F21 -> 13.958972 | H23: =Effort!H21 -> 2340.4256 | I23: =Harvest!H21 -> 33277.927 | J23: =CPUE!H21 -> 14.21875 | K23: =Effort!J21 -> 3127.5339 | L23: =Harvest!J21 -> 42243.129 | M23: =CPUE!J21 -> 13.506849 | N23: =Effort!L21 -> 1948.1299 | O23: =Harvest!L21 -> 27588.032 | P23: =CPUE!L21 -> 14.16129 | Q23: =Effort!N21 -> CLOSED | R23: =Harvest!N21 -> CLOSED | S23: =CPUE!N21 -> CLOSED | T23: =+E23+H23+K23+N23 -> 9940.7822 | U23: =+F23+I23+L23+O23 -> 138351.2
A24: 41952 | B24: 41952 | C24: -0.7 | D24: 0.83680556 | E24: =Effort!F22 -> 171.41715 | F24: =Harvest!F22 -> 2571.2572 | G24: =CPUE!F22 -> 15 | H24: =Effort!H22 -> 158.9061 | I24: =Harvest!H22 -> 2522.6344 | J24: =CPUE!H22 -> 15.875 | K24: =Effort!J22 -> CLOSED | L24: =Harvest!J22 -> CLOSED | M24: =CPUE!J22 -> CLOSED | N24: =Effort!L22 -> 728.74218 | O24: =Harvest!L22 -> 7838.027 | P24: =CPUE!L22 -> 10.755556 | Q24: =Effort!N22 -> CLOSED | R24: =Harvest!N22 -> CLOSED | S24: =CPUE!N22 -> CLOSED | T24: =+E24+H24+N24 -> 1059.0654 | U24: =+F24+I24+O24 -> 12931.919
A25: 41953 | B25: 41953 | C25: -0.3 | D25: 0.86597222 | E25: =Effort!F23 -> 171.41715 | F25: =Harvest!F23 -> 2571.2572 | G25: =CPUE!F23 -> 15 | H25: =Effort!H23 -> 158.9061 | I25: =Harvest!H23 -> 2383.5915 | J25: =CPUE!H23 -> 15 | K25: =Effort!J23 -> CLOSED | L25: =Harvest!J23 -> CLOSED | M25: =CPUE!J23 -> CLOSED | N25: =Effort!L23 -> CLOSED | O25: =Harvest!L23 -> CLOSED | P25: =CPUE!L23 -> CLOSED | Q25: =Effort!N23 -> CLOSED | R25: =Harvest!N23 -> CLOSED | S25: =CPUE!N23 -> CLOSED | T25: =+E25+H25 -> 330.32325 | U25: =+F25+I25 -> 4954.8488
A26: 41954 | B26: 41954 | C26: 0.2 | D26: 0.89652778 | E26: =Effort!F24 -> 60.933856 | F26: =Harvest!F24 -> 897.30882 | G26: =CPUE!F24 -> 14.725948 | H26: =Effort!H24 -> 56.48654 | I26: =Harvest!H24 -> 847.2981 | J26: =CPUE!H24 -> 15 | K26: =Effort!J24 -> CLOSED | L26: =Harvest!J24 -> CLOSED | M26: =CPUE!J24 -> CLOSED | N26: =Effort!L24 -> CLOSED | O26: =Harvest!L24 -> CLOSED | P26: =CPUE!L24 -> CLOSED | Q26: =Effort!N24 -> CLOSED | R26: =Harvest!N24 -> CLOSED | S26: =CPUE!N24 -> CLOSED | T26: =+E26+H26 -> 117.4204 | U26: =+F26+I26 -> 1744.6069
A27: Tide Series Totals | E27: =SUM(E19:E26) -> 7656.2406 | F27: =SUM(F19:F26) -> 110618.08 | G27: =+F27/E27 -> 14.448093 | H27: =SUM(H19:H26) -> 7097.4425 | I27: =SUM(I19:I26) -> 104503.2 | J27: =+I27/H27 -> 14.724064 | K27: =SUM(K19:K26) -> 3127.5339 | L27: =SUM(L19:L26) -> 42243.129 | M27: =+L27/K27 -> 13.506849 | N27: =SUM(N19:N26) -> 3740.8553 | O27: =SUM(O19:O26) -> 51385.809 | P27: =+O27/N27 -> 13.73638 | T27: =SUM(T19:T26) -> 21622.072 | U27: =SUM(U19:U26) -> 308750.22
A28: 41963 | B28: 41963 | C28: 0 | D28: 0.7125 | E28: =Effort!F26 -> 433.43652 | F28: =Harvest!F26 -> 6375.1289 | G28: =CPUE!F26 -> 14.708333 | H28: =Effort!H26 -> 1033.7037 | I28: =Harvest!H26 -> 15197.644 | J28: =CPUE!H26 -> 14.702128 | K28: =Effort!J26 -> CLOSED | L28: =Harvest!J26 -> CLOSED | M28: =CPUE!J26 -> CLOSED | N28: =Effort!L26 -> CLOSED | O28: =Harvest!L26 -> CLOSED | P28: =CPUE!L26 -> CLOSED | Q28: =Effort!N26 -> CLOSED | R28: =Harvest!N26 -> CLOSED | S28: =CPUE!N26 -> CLOSED | T28: =+E28+H28 -> 1467.1402 | U28: =+F28+I28 -> 21572.772
A29: 41964 | B29: 41964 | C29: -0.5 | D29: 0.73958333 | E29: =Effort!F27 -> 250.83411 | F29: =Harvest!F27 -> 1755.8388 | G29: =CPUE!F27 -> 7 | H29: =Effort!H27 -> 302.8869 | I29: =Harvest!H27 -> 908.66071 | J29: =CPUE!H27 -> 3 | K29: =Effort!J27 -> CLOSED | L29: =Harvest!J27 -> CLOSED | M29: =CPUE!J27 -> CLOSED | N29: =Effort!L27 -> 640.25513 | O29: =Harvest!L27 -> 4579.216 | P29: =CPUE!L27 -> 7.1521739 | Q29: =Effort!N27 -> CLOSED | R29: =Harvest!N27 -> CLOSED | S29: =CPUE!N27 -> CLOSED | T29: =+E29+H29+N29 -> 1193.9761 | U29: =+F29+I29+O29 -> 7243.7155
A30: 41965 | B30: 41965 | C30: -0.8 | D30: 0.76666667 | E30: =Effort!F28 -> 682.78721 | F30: =Harvest!F28 -> 6404.8876 | G30: =CPUE!F28 -> 9.3805031 | H30: =Effort!H28 -> 1333.693 | I30: =Harvest!H28 -> 12687.182 | J30: =CPUE!H28 -> 9.5128205 | K30: =Effort!J28 -> 2124.6544 | L30: =Harvest!J28 -> 20605.139 | M30: =CPUE!J28 -> 9.6981132 | N30: =Effort!L28 -> 1283.331 | O30: =Harvest!L28 -> 19249.966 | P30: =CPUE!L28 -> 15 | Q30: =Effort!N28 -> CLOSED | R30: =Harvest!N28 -> CLOSED | S30: =CPUE!N28 -> CLOSED | T30: =+E30+H30+K30+N30 -> 5424.4657 | U30: =+F30+I30+L30+O30 -> 58947.175
A31: 41966 | B31: 41966 | C31: -1 | D31: 0.79513889 | E31: =Effort!F29 -> 370.08223 | F31: =Harvest!F29 -> 5551.2334 | G31: =CPUE!F29 -> 15 | H31: =Effort!H29 -> 367.39597 | I31: =Harvest!H29 -> 3603.9795 | J31: =CPUE!H29 -> 9.8095238 | K31: =Effort!J29 -> CLOSED | L31: =Harvest!J29 -> CLOSED | M31: =CPUE!J29 -> CLOSED | N31: =Effort!L29 -> 428.76518 | O31: =Harvest!L29 -> 6389.9843 | P31: =CPUE!L29 -> 14.903226 | Q31: =Effort!N29 -> CLOSED | R31: =Harvest!N29 -> CLOSED | S31: =CPUE!N29 -> CLOSED | T31: =+E31+H31+N31 -> 1166.2434 | U31: =+F31+I31+O31 -> 15545.197
A32: 41967 | B32: 41967 | C32: -1.1 | D32: 0.82430556 | E32: =Effort!F30 -> 121.08703 | F32: =Harvest!F30 -> 196.76642 | G32: =CPUE!F30 -> 1.625 | H32: =Effort!H30 -> 94.700896 | I32: =Harvest!H30 -> 0 | J32: =CPUE!H30 -> 0 | K32: =Effort!J30 -> CLOSED | L32: =Harvest!J30 -> CLOSED | M32: =CPUE!J30 -> CLOSED | N32: =Effort!L30 -> CLOSED | O32: =Harvest!L30 -> CLOSED | P32: =CPUE!L30 -> CLOSED | Q32: =Effort!N30 -> CLOSED | R32: =Harvest!N30 -> CLOSED | S32: =CPUE!N30 -> CLOSED | T32: =+E32+H32 -> 215.78792 | U32: =+F32+I32 -> 196.76642
A33: 41968 | B33: 41968 | C33: -0.9 | D33: 0.85555556 | E33: =Effort!F31 -> 173.06948 | F33: =Harvest!F31 -> 1834.6186 | G33: =CPUE!F31 -> 10.600474 | H33: =Effort!H31 -> 338.05782 | I33: =Harvest!H31 -> 3634.1216 | J33: =CPUE!H31 -> 10.75 | K33: =Effort!J31 -> CLOSED | L33: =Harvest!J31 -> CLOSED | M33: =CPUE!J31 -> CLOSED | N33: =Effort!L31 -> CLOSED | O33: =Harvest!L31 -> CLOSED | P33: =CPUE!L31 -> CLOSED | Q33: =Effort!N31 -> CLOSED | R33: =Harvest!N31 -> CLOSED | S33: =CPUE!N31 -> CLOSED | T33: =+E33+H33 -> 511.1273 | U33: =+F33+I33 -> 5468.7401
A34: 41969 | B34: 41969 | C34: -0.5 | D34: 0.88819444 | E34: =Effort!F32 -> 173.06948 | F34: =Harvest!F32 -> 1834.6186 | G34: =CPUE!F32 -> 10.600474 | H34: =Effort!H32 -> 338.05782 | I34: =Harvest!H32 -> 3634.1216 | J34: =CPUE!H32 -> 10.75 | K34: =Effort!J32 -> CLOSED | L34: =Harvest!J32 -> CLOSED | M34: =CPUE!J32 -> CLOSED | N34: =Effort!L32 -> CLOSED | O34: =Harvest!L32 -> CLOSED | P34: =CPUE!L32 -> CLOSED | Q34: =Effort!N32 -> CLOSED | R34: =Harvest!N32 -> CLOSED | S34: =CPUE!N32 -> CLOSED | T34: =+E34+H34 -> 511.1273 | U34: =+F34+I34 -> 5468.7401
A35: Tide Series Totals | E35: =SUM(E28:E34) -> 2204.3661 | F35: =SUM(F28:F34) -> 23953.092 | G35: =+F35/E35 -> 10.866204 | H35: =SUM(H28:H34) -> 3808.4961 | I35: =SUM(I28:I34) -> 39665.709 | J35: =+I35/H35 -> 10.415058 | K35: =SUM(K29:K34) -> 2124.6544 | L35: =SUM(L29:L34) -> 20605.139 | M35: =+L35/K35 -> 9.6981132 | N35: =SUM(N28:N34) -> 2352.3513 | O35: =SUM(O28:O34) -> 30219.166 | P35: =+O35/N35 -> 12.846366 | T35: =SUM(T28:T34) -> 10489.868 | U35: =SUM(U28:U34) -> 114443.11
A36: 41976 | B36: 41976 | C36: -0.1 | D36: 0.67638889 | E36: =Effort!F34 -> 824.28295 | F36: =Harvest!F34 -> 12364.244 | G36: =CPUE!F34 -> 15 | H36: =Effort!H34 -> 674.07271 | I36: =Harvest!H34 -> 10111.091 | J36: =CPUE!H34 -> 15 | K36: =Effort!J34 -> CLOSED | L36: =Harvest!J34 -> CLOSED | M36: =CPUE!J34 -> CLOSED | N36: =Effort!L34 -> CLOSED | O36: =Harvest!L34 -> CLOSED | P36: =CPUE!L34 -> CLOSED | Q36: =Effort!N34 -> CLOSED | R36: =Harvest!N34 -> CLOSED | S36: =CPUE!N34 -> CLOSED | T36: =+E36+H36 -> 1498.3557 | U36: =+F36+I36 -> 22475.335
A37: 41977 | B37: 41977 | C37: -0.6 | D37: 0.70972222 | E37: =Effort!F35 -> 830.18446 | F37: =Harvest!F35 -> 12452.767 | G37: =CPUE!F35 -> 15 | H37: =Effort!H35 -> 609.55989 | I37: =Harvest!H35 -> 9075.6695 | J37: =CPUE!H35 -> 14.888889 | K37: =Effort!J35 -> CLOSED | L37: =Harvest!J35 -> CLOSED | M37: =CPUE!J35 -> CLOSED | N37: =Effort!L35 -> CLOSED | O37: =Harvest!L35 -> CLOSED | P37: =CPUE!L35 -> CLOSED | Q37: =Effort!N35 -> CLOSED | R37: =Harvest!N35 -> CLOSED | S37: =CPUE!N35 -> CLOSED | T37: =+E37+H37 -> 1439.7443 | U37: =+F37+I37 -> 21528.436
A38: 41978 | B38: 41978 | C38: -0.9 | D38: 0.73958333 | E38: =Effort!F36 -> 846.04719 | F38: =Harvest!F36 -> 12690.708 | G38: =CPUE!F36 -> 15 | H38: =Effort!H36 -> 760.71939 | I38: =Harvest!H36 -> 11410.791 | J38: =CPUE!H36 -> 15 | K38: =Effort!J36 -> CLOSED | L38: =Harvest!J36 -> CLOSED | M38: =CPUE!J36 -> CLOSED | N38: =Effort!L36 -> 961.20238 | O38: =Harvest!L36 -> 14418.036 | P38: =CPUE!L36 -> 15 | Q38: =Effort!N36 -> CLOSED | R38: =Harvest!N36 -> CLOSED | S38: =CPUE!N36 -> CLOSED | T38: =+E38+H38+N38 -> 2567.969 | U38: =+F38+I38+O38 -> 38519.534
A39: 41979 | B39: 41979 | C39: -1 | D39: 0.76805556 | E39: =Effort!F37 -> 1083.2473 | F39: =Harvest!F37 -> 15925.352 | G39: =CPUE!F37 -> 14.701493 | H39: =Effort!H37 -> 885.63322 | I39: =Harvest!H37 -> 12991.373 | J39: =CPUE!H37 -> 14.669022 | K39: =Effort!J37 -> 1191.6819 | L39: =Harvest!J37 -> 15362.334 | M39: =CPUE!J37 -> 12.891304 | N39: =Effort!L37 -> 1410.4646 | O39: =Harvest!L37 -> 20966.366 | P39: =CPUE!L37 -> 14.864865 | Q39: =Effort!N37 -> CLOSED | R39: =Harvest!N37 -> CLOSED | S39: =CPUE!N37 -> CLOSED | T39: =+E39+H39+K39+N39 -> 4571.027 | U39: =+F39+I39+L39+O39 -> 65245.425
A40: 41980 | B40: 41980 | C40: -0.9 | D40: 0.79583333 | E40: =Effort!F38 -> 70.175437 | F40: =Harvest!F38 -> 1052.6316 | G40: =CPUE!F38 -> 15 | H40: =Effort!H38 -> 293.76068 | I40: =Harvest!H38 -> 3113.8633 | J40: =CPUE!H38 -> 10.6 | K40: =Effort!J38 -> CLOSED | L40: =Harvest!J38 -> CLOSED | M40: =CPUE!J38 -> CLOSED | N40: =Effort!L38 -> 347.34048 | O40: =Harvest!L38 -> 5210.1071 | P40: =CPUE!L38 -> 15 | Q40: =Effort!N38 -> CLOSED | R40: =Harvest!N38 -> CLOSED | S40: =CPUE!N38 -> CLOSED | T40: =+E40+H40+N40 -> 711.2766 | U40: =+F40+I40+O40 -> 9376.6019
...

Sheet Copy Sheet
A1: BeachName | B1: Date | C1: Effort | D1: Harvest | E1: CPUE | F1: EventID | G1: CorrectionFactor
A2: Copalis | B2: 41923 | C2: 2205.5586 | D2: 8634.5273 | E2: 3.9148936 | F2: 1028 | G2: 0.50836664
A3: LongBeach | B3: 41919 | C3: 1633.3349 | D3: 24500.023 | E3: 15 | F3: 1022 | G3: 0.64889997
A4: LongBeach | B4: 41920 | C4: 1665.0139 | D4: 24526.935 | E4: 14.730769 | F4: 1023 | G4: 0.71276665
A5: LongBeach | B5: 41921 | C5: 1725.9979 | D5: 25889.969 | E5: 15 | F5: 1034 | G5: 0.64889997
A6: LongBeach | B6: 41922 | C6: 2633.4004 | D6: 37783.571 | E6: 14.347826 | F6: 1033 | G6: 0.71276665
A7: LongBeach | B7: 41923 | C7: 1397.0056 | D7: 9249.1406 | E7: 6.6206897 | F7: 1032 | G7: 0.70696664
A8: Mocrocks | B8: 41922 | C8: 1222.3151 | D8: 16040.535 | E8: 13.123077 | F8: 1027 | G8: 0.4786
A9: Mocrocks | B9: 41923 | C9: 2126.2957 | D9: 24229.882 | E9: 11.395349 | F9: 1030 | G9: 0.54353333
A10: Mocrocks | B10: 41924 | C10: 294.76325 | D10: 3766.4192 | E10: 12.777778 | F10: 1031 | G10: 0.56029999
A11: Twin Harbors | B11: 41919 | C11: 1485.9239 | D11: 22288.859 | E11: 15 | F11: 1021 | G11: 0.51243335
A12: Twin Harbors | B12: 41920 | C12: 1763.3463 | D12: 26450.194 | E12: 15 | F12: 1024 | G12: 0.53109998
A13: Twin Harbors | B13: 41921 | C13: 1310.4623 | D13: 17842.448 | E13: 13.615385 | F13: 1025 | G13: 0.52713335
... A15: Twin Harbors | B15: 41923 | C15: 484.01957 | D15: 4169.3616 | E15: 8.6140351 | F15: 1029 | G15: 0.52713335
A17: BeachName | B17: Date | C17: Effort | D17: Harvest | E17: CPUE | F17: EventID | G17: CorrectionFactor
A18: Copalis | B18: 41937 | C18: 196.05298 | D18: 0 | E18: 0 | F18: 1044 | G18: 0.4939
A19: LongBeach | B19: 41934 | C19: 218.83188 | D19: 0 | E19: 0 | F19: 1036 | G19: 0.64889997
A20: LongBeach | B20: 41935 | C20: 524.09571 | D20: 7861.4357 | E20: 15 | F20: 1037 | G20: 0.669725
A21: LongBeach | B21: 41936 | C21: 892.37092 | D21: 12716.286 | E21: 14.25 | F21: 1039 | G21: 0.64883333
A22: LongBeach | B22: 41938 | C22: 100.64938 | D22: 1509.7407 | E22: 15 | F22: 1038 | G22: 0.669725
A23: LongBeach | B23: 41940 | C23: 9.9014573 | D23: 0 | E23: 0 | F23: 1040 | G23: 0.70696664
A24: Mocrocks | B24: 41936 | C24: 1499.4481 | D24: 20419.757 | E24: 13.618182 | F24: 1043 | G24: 0.54353333
A25: Mocrocks | B25: 41938 | C25: 380.01382 | D25: 5700.2073 | E25: 15 | F25: 1045 | G25: 0.56029999
A26: Twin Harbors | B26: 41934 | C26: 380.70948 | D26: 265.34297 | E26: 0.6969697 | F26: 1035 | G26: 0.51243335
A27: Twin Harbors | B27: 41935 | C27: 770.81403 | D27: 10873.984 | E27: 14.107143 | F27: 1041 | G27: 0.53109998
A28: Twin Harbors | B28: 41936 | C28: 1019.0882 | D28: 11569.649 | E28: 11.352941 | F28: 1042 | G28: 0.52824998
A29: Twin Harbors | B29: 41938 | C29: 212.02083 | D29: 3180.3125 | E29: 15 | F29: 1046 | G29: 0.52824998
A30: Twin Harbors | B30: 41939 | C30: 91.838867 | D30: 1270.4377 | E30: 13.833333 | F30: 1047 | G30: 0.47909999
A32: BeachName | B32: Date | C32: Effort | D32: Harvest | E32: CPUE | F32: EventID | G32: CorrectionFactor
A33: Copalis | B33: 41951 | C33: 3127.5339 | D33: 42243.129 | E33: 13.506849 | F33: 1056 | G33: 0.45344999
A34: LongBeach | B34: 41947 | C34: 798.0736 | D34: 11971.104 | E34: 15 | F34: 1048 | G34: 0.72675002
A35: LongBeach | B35: 41948 | C35: 476.76527 | D35: 7161.623 | E35: 15.021277 | F35: 1062 | G35: 0.70696664
A36: LongBeach | B36: 41949 | C36: 695.72654 | D36: 10435.898 | E36: 15 | F36: 1061 | G36: 0.70142502
A37: LongBeach | B37: 41950 | C37: 2757.2142 | D37: 39767.513 | E37: 14.423077 | F37: 1060 | G37: 0.45583335
A38: Mocrocks | B38: 41950 | C38: 1063.9833 | D38: 15959.749 | E38: 15 | F38: 1053 | G38: 0.5812
A39: Mocrocks | B39: 41951 | C39: 1948.1299 | D39: 27588.032 | E39: 14.16129 | F39: 1054 | G39: 0.57266665
A40: Mocrocks | B40: 41952 | C40: 728.74218 | D40: 7838.027 | E40: 10.755556 | F40: 1059 | G40: 0.56029999
A41: Twin Harbors | B41: 41947 | C41: 1095.9097 | D41: 16438.646 | E41: 15 | F41: 1049 | G41: 0.52824998
A42: Twin Harbors | B42: 41948 | C42: 894.43514 | D42: 13416.527 | E42: 15 | F42: 1050 | G42: 0.53109998
A43: Twin Harbors | B43: 41949 | C43: 904.89438 | D43: 13304.393 | E43: 14.702703 | F43: 1051 | G43: 0.52713335
...

Sheet Tide Info
A1: TideDate | B1: TideHeight | C1: TideTime | D1: Sunrise | E1: Sunset
A2: 41893 | B2: -0.1 | C2: 0.35347222 | D2: 0.28402778 | E2: 0.81736111
A3: 41893 | B3: -0.7 | C3: 0.87847222 | D3: 0.28402778 | E3: 0.81736111
A4: 41894 | B4: 0.5 | C4: 0.38333333 | D4: 0.28541667 | E4: 0.81597222
A5: 41894 | B5: -0.5 | C5: 0.9125 | D5: 0.28541667 | E5: 0.81597222
A6: 41895 | B6: 1.3 | C6: 0.41388889 | D6: 0.28611111 | E6: 0.81458333
A7: 41895 | B7: -0.2 | C7: 0.94861111 | D7: 0.28611111 | E7: 0.81458333
A8: 41896 | B8: 2 | C8: 0.44652778 | D8: 0.28680556 | E8: 0.81319444
A9: 41896 | B9: 0.3 | C9: 0.9875 | D9: 0.28680556 | E9: 0.81319444
A10: 41897 | B10: 2.6 | C10: 0.48472222 | D10: 0.28819444 | E10: 0.81180556
A11: 41898 | B11: 0.7 | C11: 0.030555556 | D11: 0.28888889 | E11: 0.81041667
A12: 41898 | B12: 3.1 | C12: 0.52916667 | D12: 0.28888889 | E12: 0.81041667
A13: 41899 | B13: 0.9 | C13: 0.077083333 | D13: 0.28958333 | E13: 0.80902778
... A1677: 42766 | B1677: 0.2 | C1677: 0.86805556 | D1677: 0.32222222 | E1677: 0.72083333

Sheet Tribal update
A1: 2014-2015 State (non-Indian) Recreational Razor Clam Effort, Harvest and CPUE totals.
E2: COPALIS | I2: MOCROCKS | M2: KALALOCH | Q2: DAILY TOTALS
A3: DATE | B3: DAY | C3: TIDE | D3: TIME | E3: Effort | F3: Harvest | G3: CPUE | H3: Size (mm) | I3: Effort | J3: Harvest | K3: CPUE | L3: Size (mm) | M3: Effort | N3: Harvest | O3: CPUE | P3: Size (mm) | Q3: Effort | R3: Harvest
A4: 41922 | B4: =+A4 -> 41922 | C4: -1.1 | D4: 0.86319444 | E4: CLOSED | F4: CLOSED | G4: CLOSED | I4: 1222.3151 | J4: 16040.535 | K4: 13.123077 | M4: CLOSED | N4: CLOSED | O4: CLOSED | Q4: =+I4 -> 1222.3151 | R4: =+J4 -> 16040.535
A5: 41923 | B5: =+A5 -> 41923 | C5: -0.8 | D5: 0.89444444 | E5: 2205.5586 | F5: 8634.5273 | G5: 3.9148936 | I5: 2126.2957 | J5: 24229.882 | K5: 11.395349 | M5: CLOSED | N5: CLOSED | O5: CLOSED | Q5: =+E5+I5 -> 4331.8543 | R5: =+F5+J5 -> 32864.409
A6: 41924 | B6: =+A6 -> 41924 | C6: =-0.3 -> -0.3 | D6: 0.92708333 | E6: CLOSED | F6: CLOSED | G6: CLOSED | I6: 294.76325 | J6: 3766.4192 | K6: 12.777778 | M6: CLOSED | N6: CLOSED | O6: CLOSED | Q6: =+I6 -> 294.76325 | R6: =+J6 -> 3766.4192
E7: =SUM(E4:E6) -> 2205.5586 | F7: =SUM(F4:F6) -> 8634.5273 | G7: =+F7/E7 -> 3.9148936 | I7: =SUM(I4:I6) -> 3643.3741 | J7: =SUM(J4:J6) -> 44036.836 | K7: =+J7/I7 -> 12.086828 | L7: 120.68 | Q7: =SUM(Q4:Q6) -> 5848.9327 | R7: =SUM(R4:R6) -> 52671.363
A8: 41936 | B8: 41936 | C8: -0.4 | D8: 0.82222222 | E8: CLOSED | F8: CLOSED | G8: CLOSED | I8: 1499.4481 | J8: 20419.757 | K8: 13.618182 | M8: CLOSED | N8: CLOSED | O8: CLOSED | Q8: =+I8 -> 1499.4481 | R8: =+J8 -> 20419.757
A9: 41937 | B9: 41937 | C9: -0.6 | D9: 0.84861111 | E9: 196.05298 | F9: 0 | G9: 0 | I9: 203.36133 | J9: 0 | K9: 0 | M9: CLOSED | N9: CLOSED | O9: CLOSED | Q9: =+E9+I9 -> 399.4143 | R9: =+F9+J9 -> 0
A10: 41938 | B10: 41938 | C10: -0.6 | D10: 0.87708333 | E10: CLOSED | F10: CLOSED | G10: CLOSED | I10: 380.01382 | J10: 5700.2073 | K10: 15 | M10: CLOSED | N10: CLOSED | O10: CLOSED | Q10: =+I10 -> 380.01382 | R10: =+J10 -> 5700.2073
E11: =SUM(E9:E10) -> 196.05298 | F11: =SUM(F9:F10) -> 0 | G11: =+F11/E11 -> 0 | I11: =SUM(I8:I10) -> 2082.8232 | J11: =SUM(J8:J10) -> 26119.964 | K11: =+J11/I11 -> 12.540653 | L11: 115.39 | Q11: =SUM(Q8:Q10) -> 2278.8762 | R11: =SUM(R8:R10) -> 26119.964
A12: 41950 | B12: 41950 | C12: -1.2 | D12: 0.77916667 | E12: CLOSED | F12: CLOSED | G12: CLOSED | I12: 1063.9833 | J12: 15959.749 | K12: 15 | M12: CLOSED | N12: CLOSED | O12: CLOSED | Q12: =+I12 -> 1063.9833 | R12: =+J12 -> 15959.749
A13: 41951 | B13: 41951 | C13: -1.1 | D13: 0.80833333 | E13: 3127.5339 | F13: 42243.129 | G13: 13.506849 | I13: 1948.1299 | J13: 27588.032 | K13: 14.16129 | M13: CLOSED | N13: CLOSED | O13: CLOSED | Q13: =+E13+I13 -> 5075.6638 | R13: =+F13+J13 -> 69831.162
A14: 41952 | B14: 41952 | C14: -0.7 | D14: 0.83680556 | E14: CLOSED | F14: CLOSED | G14: CLOSED | I14: 728.74218 | J14: 7838.027 | K14: 10.755556 | M14: CLOSED | N14: CLOSED | O14: CLOSED | Q14: =+I14 -> 728.74218 | R14: =+J14 -> 7838.027
E15: =SUM(E13:E14) -> 3127.5339 | F15: =SUM(F13:F14) -> 42243.129 | G15: =+F15/E15 -> 13.506849 | I15: =SUM(I12:I14) -> 3740.8553 | J15: =SUM(J12:J14) -> 51385.809 | K15: =+J15/I15 -> 13.73638 | Q15: =SUM(Q12:Q14) -> 6868.3892 | R15: =SUM(R12:R14) -> 93628.938
A16: 41964 | B16: 41964 | C16: -0.5 | D16: 0.73958333 | E16: CLOSED | F16: CLOSED | G16: CLOSED | I16: 640.25513 | J16: 4579.216 | K16: 7.1521739 | M16: CLOSED | N16: CLOSED | O16: CLOSED | Q16: =+I16 -> 640.25513 | R16: =+J16 -> 4579.216
A17: 41965 | B17: 41965 | C17: -0.8 | D17: 0.76666667 | E17: 2124.6544 | F17: 20605.139 | G17: 9.6981132 | I17: 1283.331 | J17: 19249.966 | K17: 15 | M17: CLOSED | N17: CLOSED | O17: CLOSED | Q17: =+E17+I17 -> 3407.9855 | R17: =+F17+J17 -> 39855.105
A18: 41966 | B18: 41966 | C18: -1 | D18: 0.79513889 | E18: CLOSED | F18: CLOSED | G18: CLOSED | I18: 428.76518 | J18: 6389.9843 | K18: 14.903226 | M18: CLOSED | N18: CLOSED | O18: CLOSED | Q18: =+I18 -> 428.76518 | R18: =+J18 -> 6389.9843
E19: =SUM(E17:E18) -> 2124.6544 | F19: =SUM(F17:F18) -> 20605.139 | G19: =+F19/E19 -> 9.6981132 | I19: =SUM(I16:I18) -> 2352.3513 | J19: =SUM(J16:J18) -> 30219.166 | K19: =+J19/I19 -> 12.846366 | Q19: =SUM(Q16:Q18) -> 4477.0058 | R19: =SUM(R16:R18) -> 50824.305
A20: 41978 | B20: 41964 | C20: -0.9 | D20: 0.70972222 | E20: CLOSED | F20: CLOSED | G20: CLOSED | I20: 961.20238 | J20: 14418.036 | K20: 15 | M20: CLOSED | N20: CLOSED | O20: CLOSED | Q20: =+I20 -> 961.20238 | R20: =+J20 -> 14418.036
A21: 41979 | B21: 41965 | C21: -1 | D21: 0.73958333 | E21: 1191.6819 | F21: 15362.334 | G21: 12.891304 | I21: 1410.4646 | J21: 20966.366 | K21: 14.864865 | M21: CLOSED | N21: CLOSED | O21: CLOSED | Q21: =+E21+I21 -> 2602.1465 | R21: =+F21+J21 -> 36328.699
A22: 41980 | B22: 41966 | C22: -0.9 | D22: 0.76805556 | E22: CLOSED | F22: CLOSED | G22: CLOSED | I22: 347.34048 | J22: 5210.1071 | K22: 15 | M22: CLOSED | N22: CLOSED | O22: CLOSED | Q22: =+I22 -> 347.34048 | R22: =+J22 -> 5210.1071
E23: =SUM(E21:E22) -> 1191.6819 | F23: =SUM(F21:F22) -> 15362.334 | G23: =+F23/E23 -> 12.891304 | I23: =SUM(I20:I22) -> 2719.0074 | J23: =SUM(J20:J22) -> 40594.508 | K23: =+J23/I23 -> 14.9299 | Q23: =SUM(Q20:Q22) -> 3910.6893 | R23: =SUM(R20:R22) -> 55956.842
A24: 41992 | B24: 41964 | C24: 0 | D24: 0.69513889 | E24: CLOSED | F24: CLOSED | G24: CLOSED | I24: 909.71745 | J24: 5939.9198 | K24: 6.5294118 | M24: CLOSED | N24: CLOSED | O24: CLOSED | Q24: =+I24 -> 909.71745 | R24: =+J24 -> 5939.9198
A25: 41993 | B25: 41965 | C25: -0.6 | D25: 0.72430556 | E25: 781.84676 | F25: 68.986479 | G25: 0.088235294 | I25: 454.43396 | J25: 0 | K25: 0 | M25: CLOSED | N25: CLOSED | O25: CLOSED | Q25: =+E25+I25 -> 1236.2807 | R25: =+F25+J25 -> 68.986479
A26: 41994 | B26: 41966 | C26: -1.1 | D26: 0.75416667 | E26: CLOSED | F26: CLOSED | G26: CLOSED | I26: 872.46014 | J26: 13086.902 | K26: 15 | M26: CLOSED | N26: CLOSED | O26: CLOSED | Q26: =+I26 -> 872.46014 | R26: =+J26 -> 13086.902
E27: =SUM(E25:E26) -> 781.84676 | F27: =SUM(F25:F26) -> 68.986479 | G27: =+F27/E27 -> 0.088235294 | I27: =SUM(I24:I26) -> 2236.6115 | J27: =SUM(J24:J26) -> 19026.822 | K27: =+J27/I27 -> 8.5069855 | Q27: =SUM(Q24:Q26) -> 3018.4583 | R27: =SUM(R24:R26) -> 19095.808
A28: 42004 | B28: Wed | C28: 0.6 | D28: 0.62847222 | E28: 2956.2948 | F28: 44344.421 | G28: 15 | I28: 1992.3104 | J28: 29884.656 | K28: 15 | M28: CLOSED | N28: CLOSED | O28: CLOSED | Q28: =+E28+I28 -> 4948.6051 | R28: =+F28+J28 -> 74229.077
A29: 42005 | B29: Thu | C29: 0.2 | D29: 0.66736111 | E29: 3455.8474 | F29: 51837.711 | G29: 15 | I29: 2947.4411 | J29: 44211.617 | K29: 15 | M29: CLOSED | N29: CLOSED | O29: CLOSED | Q29: =+E29+I29 -> 6403.2886 | R29: =+F29+J29 -> 96049.328
A30: 42006 | B30: Fri | C30: -0.2 | D30: 0.70069444 | E30: 2410.8541 | F30: 33253.161 | G30: 13.793103 | I30: 1198.2598 | J30: 17958.534 | K30: 14.987179 | M30: CLOSED | N30: CLOSED | O30: CLOSED | Q30: =+E30+I30 -> 3609.1139 | R30: =+F30+J30 -> 51211.695
A31: 41642 | B31: Sat | C31: -0.5 | D31: 0.73055556 | E31: 3146.0924 | F31: 47280.008 | G31: 15.028169 | I31: 1581.326 | J31: 23688.884 | K31: 14.980392 | M31: CLOSED | N31: CLOSED | O31: CLOSED | Q31: =+E31+I31 -> 4727.4184 | R31: =+F31+J31 -> 70968.892
A32: 41643 | B32: Sun | C32: -0.05 | D32: 0.75833333 | E32: CLOSED | F32: CLOSED | G32: CLOSED | I32: 97.88867 | J32: 391.55468 | K32: 4 | M32: CLOSED | N32: CLOSED | O32: CLOSED | Q32: =+I32 -> 97.88867 | R32: =+J32 -> 391.55468
E33: =SUM(E28:E32) -> 11969.089 | F33: =SUM(F28:F32) -> 176715.3 | G33: =+F33/E33 -> 14.764307 | I33: =SUM(I28:I32) -> 7817.226 | J33: =SUM(J28:J32) -> 116135.25 | K33: =+J33/I33 -> 14.856324 | Q33: =SUM(Q28:Q32) -> 19786.315 | R33: =SUM(R28:R32) -> 292850.55
A34: 42021 | B34: 42021 | C34: 0.1 | D34: 0.67708333 | E34: 1990.4827 | F34: 23136.13 | G34: 11.623377 | I34: 1277.5845 | J34: 17233.196 | K34: 13.488889 | M34: CLOSED | N34: CLOSED | O34: CLOSED | Q34: =+E34+I34 -> 3268.0672 | R34: =+F34+J34 -> 40369.326
A35: 42022 | B35: 42022 | C35: -0.6 | D35: 0.70972222 | E35: CLOSED | F35: CLOSED | G35: CLOSED | I35: 2382.1223 | J35: 29732.415 | K35: 12.481481 | M35: CLOSED | N35: CLOSED | O35: CLOSED | Q35: =+I35 -> 2382.1223 | R35: =+J35 -> 29732.415
A36: 42027 | B36: 42027 | C36: -0.6 | D36: 0.86111111 | E36: CLOSED | F36: CLOSED | G36: CLOSED | I36: 188.7509 | J36: 578.04963 | K36: 3.0625 | M36: CLOSED | N36: CLOSED | O36: CLOSED | Q36: =+I36 -> 188.7509 | R36: =+J36 -> 578.04963
A37: 42028 | B37: 42028 | C37: 0.1 | D37: 0.89236111 | E37: 413.86003 | F37: 6207.9005 | G37: 15 | I37: 398.46208 | J37: 5976.9311 | K37: 15 | M37: CLOSED | N37: CLOSED | O37: CLOSED | Q37: =+E37+I37 -> 812.32211 | R37: =+F37+J37 -> 12184.832
E38: =SUM(E34:E37) -> 2404.3427 | F38: =SUM(F34:F37) -> 29344.03 | G38: =+F38/E38 -> 12.204596 | I38: =SUM(I34:I37) -> 4246.9198 | J38: =SUM(J34:J37) -> 53520.592 | K38: =+J38/I38 -> 12.602214 | Q38: =SUM(Q34:Q37) -> 6651.2625 | R38: =SUM(R34:R37) -> 82864.622
A39: 42034 | B39: 42034 | C39: 0.5 | D39: 0.65486111 | E39: CLOSED | F39: CLOSED | G39: CLOSED | I39: 2439.2317 | J39: 36714.643 | K39: 15.051724 | M39: CLOSED | N39: CLOSED | O39: CLOSED | Q39: =+I39 -> 2439.2317 | R39: =+J39 -> 36714.643
A40: 42035 | B40: 42035 | C40: 0.2 | D40: 0.68888889 | E40: 3379.9945 | F40: 50699.918 | G40: 15 | I40: 2745.0019 | J40: 41175.028 | K40: 15 | M40: CLOSED | N40: CLOSED | O40: CLOSED | Q40: =+E40+I40 -> 6124.9964 | R40: =+F40+J40 -> 91874.946
...

Sheet TAC
A1: NON-TRIBAL TOTAL ALLOWABLE CATCH (TAC)
B3: 2014 - 2015 | C3: 2013 - 2014 | D3: 2012 - 2013 | E3: 2011 - 2012 | F3: 2010 - 2011
A4: LONG BEACH | B4: 3885491.5 | C4: 2881223.3 | D4: 1847952.1 | E4: 1094641.4 | F4: 1276247.7
A5: TWIN HARBORS | B5: 2662860.8 | C5: =5744410.73323314*0.4 -> 2297764.3 | D5: 1881783.2 | E5: 616314.31 | F5: 845427.67
A6: COPALIS | B6: 889827.43 | C6: =(2615522*0.5)-(161153)+250000 -> 1396608 | D6: 1072689.6 | E6: 371373.04 | F6: 683167.41
A7: MOCROCKS | B7: 2240308.7 | C7: 2088668.5 | D7: 909667.35 | E7: 605830.7 | F7: 545586.69
A8: KALALOCH | B8: 125735.13 | C8: =1033285.9456848*0.254*0.5 -> 131227.32 | D8: 113543.21 | E8: 144560.51 | F8: 258924.12
A9: COASTWIDE TAC | B9: =SUM(B4:B8) -> 9804223.7 | C9: =SUM(C4:C8) -> 8795491.4 | D9: =SUM(D4:D8) -> 5825635.5 | E9: =SUM(E4:E8) -> 2832720 | F9: =SUM(F4:F8) -> 3609353.6
B14: =161784/B4 -> 0.041637975

Sheet TH Wastage
A1: EventID | B1: BeachName | C1: Date | D1: SumOfWastage | E1: SumOfTotHarvest
A2: 1021 | B2: Twin Harbors | C2: 41919 | D2: 891 | E2: 22288.859
A3: 1024 | B3: Twin Harbors | C3: 41920 | D3: 1587 | E3: 26450.194
A4: 1029 | B4: Twin Harbors | C4: 41923 | D4: 0 | E4: 4169.3616
A5: 1050 | B5: Twin Harbors | C5: 41948 | D5: 134 | E5: 13416.527
A6: 1070 | B6: Twin Harbors | C6: 41965 | D6: 253 | E6: 12687.182
A7: 1086 | B7: Twin Harbors | C7: 41976 | D7: 539 | E7: 10111.091
A8: 1089 | B8: Twin Harbors | C8: 41978 | D8: 342 | E8: 11410.791
A9: 1118 | B9: Twin Harbors | C9: 42004 | D9: 1819 | E9: 30310.543
A10: 1119 | B10: Twin Harbors | C10: 42005 | D10: 165 | E10: 32968.356
A11: 1146 | B11: Twin Harbors | C11: 42034 | D11: 334 | E11: 16725.036
A12: 1141 | B12: Twin Harbors | C12: 42035 | D12: 261 | E12: 15664.494
A13: 1143 | B13: Twin Harbors | C13: 42037 | D13: 793 | E13: 8813.3856
... A25: 1204 | B25: Twin Harbors | C25: 42115 | D25: 789 | E25: 39476.094
