Workbook

Sheet Harvest
A1: Date | B1: Day | C1: Tide | D1: Time | E1: Longbeach | G1: Twin Harbors | I1: Copalis | K1: Mocrocks | M1: Kalaloch | O1: Daily Totals
A2: 42362 | B2: =+A2 -> 42362 | C2: -1.2 | D2: 0.74097222 | F2: CLOSED | H2: CLOSED | J2: 42035.027 | L2: CLOSED | N2: CLOSED | O2: =+J2 -> 42035.027
A3: 42363 | B3: =+A3 -> 42363 | C3: -1.3 | D3: 0.77083333 | F3: CLOSED | H3: CLOSED | J3: 45110.099 | L3: CLOSED | N3: CLOSED | O3: =+J3 -> 45110.099
A4: 42364 | B4: =+A4 -> 42364 | C4: -1.1 | D4: 0.8 | F4: CLOSED | H4: CLOSED | J4: 78186.261 | L4: CLOSED | N4: CLOSED | O4: =+J4 -> 78186.261
A6: 42376 | B6: =+A6 -> 42376 | C6: 0.1 | D6: 0.70625 | F6: 31029.546 | H6: CLOSED | J6: CLOSED | L6: CLOSED | N6: CLOSED | O6: =+F6 -> 31029.546
A7: 42377 | B7: =+A7 -> 42377 | C7: -0.4 | D7: 0.73402778 | F7: 32644.271 | H7: CLOSED | J7: 68780.604 | L7: CLOSED | N7: CLOSED | O7: =+F7+J7 -> 101424.87
A8: 42378 | B8: =+A8 -> 42378 | C8: -0.8 | D8: 0.76111111 | F8: 87418.73 | H8: CLOSED | J8: 114652.1 | L8: CLOSED | N8: CLOSED | O8: =+F8+J8 -> 202070.83
A9: 42379 | B9: =+A9 -> 42379 | C9: -1 | D9: 0.78819444 | F9: 34039.751 | H9: CLOSED | J9: CLOSED | L9: CLOSED | N9: CLOSED | O9: =+F9 -> 34039.751
A10: 42380 | B10: =+A10 -> 42380 | C10: -1 | D10: 0.81527778 | F10: 7121.6395 | H10: CLOSED | J10: CLOSED | L10: CLOSED | N10: CLOSED | O10: =+F10 -> 7121.6395
A11: 42381 | B11: =+A11 -> 42381 | C11: -0.8 | D11: 0.84305556 | F11: 1887.2871 | H11: CLOSED | J11: CLOSED | L11: CLOSED | N11: CLOSED | O11: =+F11 -> 1887.2871
A12: 42382 | B12: =+A12 -> 42382 | C12: -0.4 | D12: 0.87222222 | F12: 8868.7553 | H12: CLOSED | J12: CLOSED | L12: CLOSED | N12: CLOSED | O12: =+F12 -> 8868.7553
A13: 42383 | B13: =+A13 -> 42383 | C13: 0.2 | D13: 0.90277778 | E13: * | F13: 8900 | H13: CLOSED | J13: CLOSED | L13: CLOSED | N13: CLOSED | O13: =+F13 -> 8900
A15: 42390 | B15: =+A15 -> 42390 | C15: -0.4 | D15: 0.70069444 | F15: 4230.7215 | H15: CLOSED | J15: CLOSED | L15: CLOSED | N15: CLOSED | O15: =+F15 -> 4230.7215
A16: 42391 | B16: =+A16 -> 42391 | C16: -0.7 | D16: 0.73263889 | F16: 42697.617 | H16: CLOSED | J16: 49770.571 | L16: CLOSED | N16: CLOSED | O16: =+F16+J16 -> 92468.189
A17: 42392 | B17: =+A17 -> 42392 | C17: -0.8 | D17: 0.76111111 | F17: 96068.744 | H17: CLOSED | J17: CLOSED | L17: CLOSED | N17: CLOSED | O17: =+F17 -> 96068.744
A18: 42393 | B18: =+A18 -> 42393 | C18: -0.7 | D18: 0.7875 | E18: ** | F18: 34000 | H18: CLOSED | J18: CLOSED | L18: CLOSED | N18: CLOSED | O18: =+F18 -> 34000
A19: 42394 | B19: =+A19 -> 42394 | C19: -0.4 | D19: 0.81319444 | E19: ** | F19: 7500 | H19: CLOSED | J19: CLOSED | L19: CLOSED | N19: CLOSED | O19: =+F19 -> 7500
A20: 42395 | B20: =+A20 -> 42395 | C20: 0 | D20: 0.83680556 | E20: ** | F20: 1900 | H20: CLOSED | J20: CLOSED | L20: CLOSED | N20: CLOSED | O20: =+F20 -> 1900
A21: 42396 | B21: =+A21 -> 42396 | C21: 0.5 | D21: 0.86041667 | E21: + | F21: 0 | H21: CLOSED | J21: CLOSED | L21: CLOSED | N21: CLOSED | O21: =+F21 -> 0
A23: 42404 | B23: =+A23 -> 42404 | C23: 0.8 | D23: 0.65347222 | F23: 10622.333 | H23: CLOSED | J23: CLOSED | L23: CLOSED | N23: CLOSED | O23: =+F23 -> 10622.333
A24: 42405 | B24: =+A24 -> 42405 | C24: 0.2 | D24: 0.68611111 | F24: 2905.4137 | H24: CLOSED | J24: CLOSED | L24: CLOSED | N24: CLOSED | O24: =+F24 -> 2905.4137
A25: 42406 | B25: =+A25 -> 42406 | C25: -0.3 | D25: 0.71597222 | F25: 121224.39 | H25: CLOSED | J25: CLOSED | L25: CLOSED | N25: CLOSED | O25: =+F25 -> 121224.39
A26: 42407 | B26: =+A26 -> 42407 | C26: -0.7 | D26: 0.74444444 | F26: 25403.936 | H26: CLOSED | J26: CLOSED | L26: CLOSED | N26: CLOSED | O26: =+F26 -> 25403.936
A27: 42408 | B27: =+A27 -> 42408 | C27: -1 | D27: 0.77222222 | F27: 50370.948 | H27: CLOSED | J27: CLOSED | L27: CLOSED | N27: CLOSED | O27: =+F27 -> 50370.948
A28: 42409 | B28: =+A28 -> 42409 | C28: -0.9 | D28: 0.8 | E28: ** | F28: 8000 | H28: CLOSED | J28: CLOSED | L28: CLOSED | N28: CLOSED | O28: =+F28 -> 8000
A29: 42410 | B29: =+A29 -> 42410 | C29: -0.7 | D29: 0.82777778 | F29: 5815.2032 | H29: CLOSED | J29: CLOSED | L29: CLOSED | N29: CLOSED | O29: =+F29 -> 5815.2032
A30: 42411 | B30: =+A30 -> 42411 | C30: -0.1 | D30: 0.85694444 | E30: ** | F30: 5850 | H30: CLOSED | J30: CLOSED | L30: CLOSED | N30: CLOSED | O30: =+F30 -> 5850
A31: 42412 | B31: =+A31 -> 42412 | C31: 0.6 | D31: 0.88680556 | E31: ** | F31: 11000 | H31: CLOSED | J31: CLOSED | L31: CLOSED | N31: CLOSED | O31: =+F31 -> 11000
A32: 42413 | B32: =+A32 -> 42413 | C32: 1.4 | D32: 0.91944444 | E32: ** | F32: 15000 | H32: CLOSED | J32: CLOSED | L32: CLOSED | N32: CLOSED | O32: =+F32 -> 15000
A33: 42414 | B33: =+A33 -> 42414 | C33: 2.2 | D33: 0.95694444 | E33: ** | F33: 1000 | H33: CLOSED | J33: CLOSED | L33: CLOSED | N33: CLOSED | O33: =+F33 -> 1000
A35: 42415 | B35: =+A35 -> 42415 | C35: 1.1 | D35: 0.51111111 | E35: ** | F35: 8000 | H35: CLOSED | J35: CLOSED | L35: CLOSED | N35: CLOSED | O35: =+F35 -> 8000
A36: 42416 | B36: =+A36 -> 42416 | C36: 1 | D36: 0.5625 | E36: ** | F36: 8000 | H36: CLOSED | J36: CLOSED | L36: CLOSED | N36: CLOSED | O36: =+F36 -> 8000
A37: 42417 | B37: =+A37 -> 42417 | C37: 0.7 | D37: 0.61111111 | F37: 7673.8625 | H37: CLOSED | J37: CLOSED | L37: CLOSED | N37: CLOSED | O37: =+F37 -> 7673.8625
A38: 42418 | B38: =+A38 -> 42418 | C38: 0.3 | D38: 0.65347222 | F38: 8977.8398 | H38: CLOSED | J38: CLOSED | L38: CLOSED | N38: CLOSED | O38: =+F38 -> 8977.8398
A39: 42419 | B39: =+A39 -> 42419 | C39: 0 | D39: 0.68958333 | F39: 22831.619 | H39: CLOSED | J39: 42899.999 | L39: 14975.819 | N39: CLOSED | O39: =+F39+J39+L39 -> 80707.437
A40: 42420 | B40: =+A40 -> 42420 | C40: -0.1 | D40: 0.72013889 | F40: 201114.35 | H40: CLOSED | J40: 128329.73 | L40: 117314.81 | N40: CLOSED | O40: =+F40+J40+L40 -> 446758.89
A41: 42421 | B41: =+A41 -> 42421 | C41: -0.2 | D41: 0.74722222 | F41: 32313.047 | H41: CLOSED | J41: CLOSED | L41: 37155.497 | N41: CLOSED | O41: =+F41+L41 -> 69468.544
A42: 42422 | B42: =+A42 -> 42422 | C42: -0.1 | D42: 0.77152778 | F42: 18961.597 | H42: CLOSED | J42: CLOSED | L42: CLOSED | N42: CLOSED | O42: =+F42 -> 18961.597
A43: 42423 | B43: =+A43 -> 42423 | C43: 0.1 | D43: 0.79444444 | E43: ** | F43: 16050 | H43: CLOSED | J43: CLOSED | L43: CLOSED | N43: CLOSED | O43: =+F43 -> 16050
A44: 42424 | B44: =+A44 -> 42424 | C44: 0.5 | D44: 0.81597222 | F44: 3372.4205 | H44: CLOSED | J44: CLOSED | L44: CLOSED | N44: CLOSED | O44: =+F44 -> 3372.4205
...

Sheet Effort
A1: Date | B1: Day | C1: Tide | D1: Time | E1: Longbeach | G1: Twin Harbors | I1: Copalis | K1: Mocrocks | M1: Kalaloch | O1: Daily Totals
A2: 42362 | B2: =+A2 -> 42362 | C2: -1.2 | D2: 0.74097222 | F2: CLOSED | H2: CLOSED | J2: 2988.2721 | L2: CLOSED | N2: CLOSED | O2: =+J2 -> 2988.2721
A3: 42363 | B3: =+A3 -> 42363 | C3: -1.3 | D3: 0.77083333 | F3: CLOSED | H3: CLOSED | J3: 3038.5041 | L3: CLOSED | N3: CLOSED | O3: =+J3 -> 3038.5041
A4: 42364 | B4: =+A4 -> 42364 | C4: -1.1 | D4: 0.8 | F4: CLOSED | H4: CLOSED | J4: 5373.483 | L4: CLOSED | N4: CLOSED | O4: =+J4 -> 5373.483
A6: 42376 | B6: =+A6 -> 42376 | C6: 0.1 | D6: 0.70625 | F6: 2173.2756 | H6: CLOSED | J6: CLOSED | L6: CLOSED | N6: CLOSED | O6: =+F6 -> 2173.2756
A7: 42377 | B7: =+A7 -> 42377 | C7: -0.4 | D7: 0.73402778 | F7: 2178.502 | H7: CLOSED | J7: 4608.3005 | L7: CLOSED | N7: CLOSED | O7: =+F7+J7 -> 6786.8025
A8: 42378 | B8: =+A8 -> 42378 | C8: -0.8 | D8: 0.76111111 | F8: 6868.6145 | H8: CLOSED | J8: 8906.2352 | L8: CLOSED | N8: CLOSED | O8: =+F8+J8 -> 15774.85
A9: 42379 | B9: =+A9 -> 42379 | C9: -1 | D9: 0.78819444 | F9: 2284.2464 | H9: CLOSED | J9: CLOSED | L9: CLOSED | N9: CLOSED | O9: =+F9 -> 2284.2464
A10: 42380 | B10: =+A10 -> 42380 | C10: -1 | D10: 0.81527778 | F10: 508.68853 | H10: CLOSED | J10: CLOSED | L10: CLOSED | N10: CLOSED | O10: =+F10 -> 508.68853
A11: 42381 | B11: =+A11 -> 42381 | C11: -0.8 | D11: 0.84305556 | F11: 125.81914 | H11: CLOSED | J11: CLOSED | L11: CLOSED | N11: CLOSED | O11: =+F11 -> 125.81914
A12: 42382 | B12: =+A12 -> 42382 | C12: -0.4 | D12: 0.87222222 | F12: 591.25035 | H12: CLOSED | J12: CLOSED | L12: CLOSED | N12: CLOSED | O12: =+F12 -> 591.25035
A13: 42383 | B13: =+A13 -> 42383 | C13: 0.2 | D13: 0.90277778 | E13: ** | F13: 600 | H13: CLOSED | J13: CLOSED | L13: CLOSED | N13: CLOSED | O13: =+F13 -> 600
A15: 42390 | B15: =+A15 -> 42390 | C15: -0.4 | D15: 0.70069444 | F15: 488.61854 | H15: CLOSED | J15: CLOSED | L15: CLOSED | N15: CLOSED | O15: =+F15 -> 488.61854
A16: 42391 | B16: =+A16 -> 42391 | C16: -0.7 | D16: 0.73263889 | F16: 2846.5078 | H16: CLOSED | J16: 4454.509 | L16: CLOSED | N16: CLOSED | O16: =+F16+J16 -> 7301.0168
A17: 42392 | B17: =+A17 -> 42392 | C17: -0.8 | D17: 0.76111111 | F17: 6367.2656 | H17: CLOSED | J17: CLOSED | L17: CLOSED | N17: CLOSED | O17: =+F17 -> 6367.2656
A18: 42393 | B18: =+A18 -> 42393 | C18: -0.7 | D18: 0.7875 | E18: ** | F18: 2300 | H18: CLOSED | J18: CLOSED | L18: CLOSED | N18: CLOSED | O18: =+F18 -> 2300
A19: 42394 | B19: =+A19 -> 42394 | C19: -0.4 | D19: 0.81319444 | E19: ** | F19: 510 | H19: CLOSED | J19: CLOSED | L19: CLOSED | N19: CLOSED | O19: =+F19 -> 510
A20: 42395 | B20: =+A20 -> 42395 | C20: 0 | D20: 0.83680556 | E20: ** | F20: 150 | H20: CLOSED | J20: CLOSED | L20: CLOSED | N20: CLOSED | O20: =+F20 -> 150
A21: 42396 | B21: =+A21 -> 42396 | C21: 0.5 | D21: 0.86041667 | E21: + | F21: 100 | H21: CLOSED | J21: CLOSED | L21: CLOSED | N21: CLOSED | O21: =+F21 -> 100
A23: 42404 | B23: =+A23 -> 42404 | C23: 0.8 | D23: 0.65347222 | F23: 774.80547 | H23: CLOSED | J23: CLOSED | L23: CLOSED | N23: CLOSED | O23: =+F23 -> 774.80547
A24: 42405 | B24: =+A24 -> 42405 | C24: 0.2 | D24: 0.68611111 | F24: 451.95325 | H24: CLOSED | J24: CLOSED | L24: CLOSED | N24: CLOSED | O24: =+F24 -> 451.95325
A25: 42406 | B25: =+A25 -> 42406 | C25: -0.3 | D25: 0.71597222 | F25: 8081.6261 | H25: CLOSED | J25: CLOSED | L25: CLOSED | N25: CLOSED | O25: =+F25 -> 8081.6261
A26: 42407 | B26: =+A26 -> 42407 | C26: -0.7 | D26: 0.74444444 | F26: 1693.5957 | H26: CLOSED | J26: CLOSED | L26: CLOSED | N26: CLOSED | O26: =+F26 -> 1693.5957
A27: 42408 | B27: =+A27 -> 42408 | C27: -1 | D27: 0.77222222 | F27: 3408.5604 | H27: CLOSED | J27: CLOSED | L27: CLOSED | N27: CLOSED | O27: =+F27 -> 3408.5604
A28: 42409 | B28: =+A28 -> 42409 | C28: -0.9 | D28: 0.8 | E28: ** | F28: 550 | H28: CLOSED | J28: CLOSED | L28: CLOSED | N28: CLOSED | O28: =+F28 -> 550
A29: 42410 | B29: =+A29 -> 42410 | C29: -0.7 | D29: 0.82777778 | F29: 387.68022 | H29: CLOSED | J29: CLOSED | L29: CLOSED | N29: CLOSED | O29: =+F29 -> 387.68022
A30: 42411 | B30: =+A30 -> 42411 | C30: -0.1 | D30: 0.85694444 | E30: ** | F30: 400 | H30: CLOSED | J30: CLOSED | L30: CLOSED | N30: CLOSED | O30: =+F30 -> 400
A31: 42412 | B31: =+A31 -> 42412 | C31: 0.6 | D31: 0.88680556 | E31: ** | F31: 800 | H31: CLOSED | J31: CLOSED | L31: CLOSED | N31: CLOSED | O31: =+F31 -> 800
A32: 42413 | B32: =+A32 -> 42413 | C32: 1.4 | D32: 0.91944444 | E32: ** | F32: 1000 | H32: CLOSED | J32: CLOSED | L32: CLOSED | N32: CLOSED | O32: =+F32 -> 1000
A33: 42414 | B33: =+A33 -> 42414 | C33: 2.2 | D33: 0.95694444 | E33: ** | F33: 100 | H33: CLOSED | J33: CLOSED | L33: CLOSED | N33: CLOSED | O33: =+F33 -> 100
A35: 42415 | B35: =+A35 -> 42415 | C35: 1.1 | D35: 0.51111111 | E35: ** | F35: 800 | H35: CLOSED | J35: CLOSED | L35: CLOSED | N35: CLOSED | O35: =+F35 -> 800
A36: 42416 | B36: =+A36 -> 42416 | C36: 1 | D36: 0.5625 | E36: ** | F36: 800 | H36: CLOSED | J36: CLOSED | L36: CLOSED | N36: CLOSED | O36: =+F36 -> 800
A37: 42417 | B37: =+A37 -> 42417 | C37: 0.7 | D37: 0.61111111 | F37: 791.11985 | H37: CLOSED | J37: CLOSED | L37: CLOSED | N37: CLOSED | O37: =+F37 -> 791.11985
A38: 42418 | B38: =+A38 -> 42418 | C38: 0.3 | D38: 0.65347222 | F38: 873.949 | H38: CLOSED | J38: CLOSED | L38: CLOSED | N38: CLOSED | O38: =+F38 -> 873.949
A39: 42419 | B39: =+A39 -> 42419 | C39: 0 | D39: 0.68958333 | F39: 1990.7679 | H39: CLOSED | J39: 3391.3042 | L39: 1766.6574 | N39: CLOSED | O39: =+F39+J39+L39 -> 7148.7296
A40: 42420 | B40: =+A40 -> 42420 | C40: -0.1 | D40: 0.72013889 | F40: 13050.087 | H40: CLOSED | J40: 9950.4269 | L40: 7972.8508 | N40: CLOSED | O40: =+F40+J40+L40 -> 30973.364
A41: 42421 | B41: =+A41 -> 42421 | C41: -0.2 | D41: 0.74722222 | F41: 2154.2031 | H41: CLOSED | J41: CLOSED | L41: 2511.1991 | N41: CLOSED | O41: =+F41+L41 -> 4665.4023
A42: 42422 | B42: =+A42 -> 42422 | C42: -0.1 | D42: 0.77152778 | F42: 1270.6225 | H42: CLOSED | J42: CLOSED | L42: CLOSED | N42: CLOSED | O42: =+F42 -> 1270.6225
A43: 42423 | B43: =+A43 -> 42423 | C43: 0.1 | D43: 0.79444444 | E43: ** | F43: 1100 | H43: CLOSED | J43: CLOSED | L43: CLOSED | N43: CLOSED | O43: =+F43 -> 1100
A44: 42424 | B44: =+A44 -> 42424 | C44: 0.5 | D44: 0.81597222 | F44: 358.76814 | H44: CLOSED | J44: CLOSED | L44: CLOSED | N44: CLOSED | O44: =+F44 -> 358.76814
...

Sheet CPUE
A1: Date | B1: Day | C1: Tide | D1: Time | E1: Longbeach | G1: Twin Harbors | I1: Copalis | K1: Mocrocks | M1: Kalaloch
A2: 42362 | B2: =+A2 -> 42362 | C2: -1.2 | D2: 0.74097222 | F2: CLOSED | H2: CLOSED | J2: =+Harvest!J2/Effort!J2 -> 14.066667 | L2: CLOSED | N2: CLOSED
A3: 42363 | B3: =+A3 -> 42363 | C3: -1.3 | D3: 0.77083333 | F3: CLOSED | H3: CLOSED | J3: =+Harvest!J3/Effort!J3 -> 14.846154 | L3: CLOSED | N3: CLOSED
A4: 42364 | B4: =+A4 -> 42364 | C4: -1.1 | D4: 0.8 | F4: CLOSED | H4: CLOSED | J4: =+Harvest!J4/Effort!J4 -> 14.550388 | L4: CLOSED | N4: CLOSED
A6: 42376 | B6: =+A6 -> 42376 | C6: 0.1 | D6: 0.70625 | F6: =+Harvest!F6/Effort!F6 -> 14.277778 | H6: CLOSED | J6: CLOSED | L6: CLOSED | N6: CLOSED
A7: 42377 | B7: =+A7 -> 42377 | C7: -0.4 | D7: 0.73402778 | F7: =+Harvest!F7/Effort!F7 -> 14.984733 | H7: CLOSED | J7: =+Harvest!J7/Effort!J7 -> 14.925373 | L7: CLOSED | N7: CLOSED
A8: 42378 | B8: =+A8 -> 42378 | C8: -0.8 | D8: 0.76111111 | F8: =+Harvest!F8/Effort!F8 -> 12.727273 | H8: CLOSED | J8: =+Harvest!J8/Effort!J8 -> 12.873239 | L8: CLOSED | N8: CLOSED
A9: 42379 | B9: =+A9 -> 42379 | C9: -1 | D9: 0.78819444 | F9: =+Harvest!F9/Effort!F9 -> 14.901961 | H9: CLOSED | J9: CLOSED | L9: CLOSED | N9: CLOSED
A10: 42380 | B10: =+A10 -> 42380 | C10: -1 | D10: 0.81527778 | F10: =+Harvest!F10/Effort!F10 -> 14 | H10: CLOSED | J10: CLOSED | L10: CLOSED | N10: CLOSED
A11: 42381 | B11: =+A11 -> 42381 | C11: -0.8 | D11: 0.84305556 | F11: =+Harvest!F11/Effort!F11 -> 15 | H11: CLOSED | J11: CLOSED | L11: CLOSED | N11: CLOSED
A12: 42382 | B12: =+A12 -> 42382 | C12: -0.4 | D12: 0.87222222 | F12: =+Harvest!F12/Effort!F12 -> 15 | H12: CLOSED | J12: CLOSED | L12: CLOSED | N12: CLOSED
A13: 42383 | B13: =+A13 -> 42383 | C13: 0.2 | D13: 0.90277778 | F13: =+Harvest!F13/Effort!F13 -> 14.833333 | H13: CLOSED | J13: CLOSED | L13: CLOSED | N13: CLOSED
A15: 42390 | B15: =+A15 -> 42390 | C15: -0.4 | D15: 0.70069444 | F15: =+Harvest!F15/Effort!F15 -> 8.6585366 | H15: CLOSED | J15: CLOSED | L15: CLOSED | N15: CLOSED
A16: 42391 | B16: =+A16 -> 42391 | C16: -0.7 | D16: 0.73263889 | F16: =+Harvest!F16/Effort!F16 -> 15 | H16: CLOSED | J16: =+Harvest!J16/Effort!J16 -> 11.173077 | L16: CLOSED | N16: CLOSED
A17: 42392 | B17: =+A17 -> 42392 | C17: -0.8 | D17: 0.76111111 | F17: =+Harvest!F17/Effort!F17 -> 15.087912 | H17: CLOSED | J17: CLOSED | L17: CLOSED | N17: CLOSED
A18: 42393 | B18: =+A18 -> 42393 | C18: -0.7 | D18: 0.7875 | F18: =+Harvest!F18/Effort!F18 -> 14.782609 | H18: CLOSED | J18: CLOSED | L18: CLOSED | N18: CLOSED
A19: 42394 | B19: =+A19 -> 42394 | C19: -0.4 | D19: 0.81319444 | F19: =+Harvest!F19/Effort!F19 -> 14.705882 | H19: CLOSED | J19: CLOSED | L19: CLOSED | N19: CLOSED
A20: 42395 | B20: =+A20 -> 42395 | C20: 0 | D20: 0.83680556 | F20: =+Harvest!F20/Effort!F20 -> 12.666667 | H20: CLOSED | J20: CLOSED | L20: CLOSED | N20: CLOSED
A21: 42396 | B21: =+A21 -> 42396 | C21: 0.5 | D21: 0.86041667 | F21: =+Harvest!F21/Effort!F21 -> 0 | H21: CLOSED | J21: CLOSED | L21: CLOSED | N21: CLOSED
A23: 42404 | B23: =+A23 -> 42404 | C23: 0.8 | D23: 0.65347222 | F23: =+Harvest!F23/Effort!F23 -> 13.709677 | H23: CLOSED | J23: CLOSED | L23: CLOSED | N23: CLOSED
A24: 42405 | B24: =+A24 -> 42405 | C24: 0.2 | D24: 0.68611111 | F24: =+Harvest!F24/Effort!F24 -> 6.4285714 | H24: CLOSED | J24: CLOSED | L24: CLOSED | N24: CLOSED
A25: 42406 | B25: =+A25 -> 42406 | C25: -0.3 | D25: 0.71597222 | F25: =+Harvest!F25/Effort!F25 -> 15 | H25: CLOSED | J25: CLOSED | L25: CLOSED | N25: CLOSED
A26: 42407 | B26: =+A26 -> 42407 | C26: -0.7 | D26: 0.74444444 | F26: =+Harvest!F26/Effort!F26 -> 15 | H26: CLOSED | J26: CLOSED | L26: CLOSED | N26: CLOSED
A27: 42408 | B27: =+A27 -> 42408 | C27: -1 | D27: 0.77222222 | F27: =+Harvest!F27/Effort!F27 -> 14.777778 | H27: CLOSED | J27: CLOSED | L27: CLOSED | N27: CLOSED
A28: 42409 | B28: =+A28 -> 42409 | C28: -0.9 | D28: 0.8 | F28: =+Harvest!F28/Effort!F28 -> 14.545455 | H28: CLOSED | J28: CLOSED | L28: CLOSED | N28: CLOSED
A29: 42410 | B29: =+A29 -> 42410 | C29: -0.7 | D29: 0.82777778 | F29: =+Harvest!F29/Effort!F29 -> 15 | H29: CLOSED | J29: CLOSED | L29: CLOSED | N29: CLOSED
... A38: 42418 | B38: =+A38 -> 42418 | C38: 0.3 | D38: 0.65347222 | F38: =+Harvest!F38/Effort!F38 -> 10.272727 | H38: CLOSED | J38: CLOSED | L38: CLOSED | N38: CLOSED
A39: 42419 | B39: =+A39 -> 42419 | C39: 0 | D39: 0.68958333 | F39: =+Harvest!F39/Effort!F39 -> 11.46875 | H39: CLOSED | J39: =+Harvest!J39/Effort!J39 -> 12.65 | L39: =+Harvest!L39/Effort!L39 -> 8.4769231 | N39: CLOSED
A40: 42420 | B40: =+A40 -> 42420 | C40: -0.1 | D40: 0.72013889 | F40: =+Harvest!F40/Effort!F40 -> 15.410959 | H40: CLOSED | J40: =+Harvest!J40/Effort!J40 -> 12.896907 | L40: =+Harvest!L40/Effort!L40 -> 14.714286 | N40: CLOSED
A41: 42421 | B41: =+A41 -> 42421 | C41: -0.2 | D41: 0.74722222 | F41: =+Harvest!F41/Effort!F41 -> 15 | H41: CLOSED | J41: CLOSED | L41: =+Harvest!L41/Effort!L41 -> 14.795918 | N41: CLOSED
A42: 42422 | B42: =+A42 -> 42422 | C42: -0.1 | D42: 0.77152778 | F42: =+Harvest!F42/Effort!F42 -> 14.923077 | H42: CLOSED | J42: CLOSED | L42: CLOSED | N42: CLOSED
A43: 42423 | B43: =+A43 -> 42423 | C43: 0.1 | D43: 0.79444444 | E43: ** | F43: =+Harvest!F43/Effort!F43 -> 14.590909 | H43: CLOSED | J43: CLOSED | L43: CLOSED | N43: CLOSED
A44: 42424 | B44: =+A44 -> 42424 | C44: 0.5 | D44: 0.81597222 | F44: =+Harvest!F44/Effort!F44 -> 9.4 | H44: CLOSED | J44: CLOSED | L44: CLOSED | N44: CLOSED
A45: 42425 | B45: =+A45 -> 42425 | C45: 0.9 | D45: 0.8375 | E45: ** | F45: =+Harvest!F45/Effort!F45 -> 10.344828 | H45: CLOSED | J45: CLOSED | L45: CLOSED | N45: CLOSED
A46: 42426 | B46: =+A46 -> 42426 | C46: 1.4 | D46: 0.85902778 | F46: =+Harvest!F46/Effort!F46 -> 11.7 | H46: CLOSED | J46: CLOSED | L46: CLOSED | N46: CLOSED
A47: 42427 | B47: =+A47 -> 42427 | C47: 2 | D47: 0.88125 | F47: =+Harvest!F47/Effort!F47 -> 12 | H47: CLOSED | J47: CLOSED | L47: CLOSED | N47: CLOSED
A48: 42428 | B48: =+A48 -> 42428 | C48: 2.5 | D48: 0.90555556 | E48: # | F48: 0 | H48: CLOSED | J48: CLOSED | L48: CLOSED | N48: CLOSED
A49: 42429 | B49: =+A49 -> 42429 | C49: 3.1 | D49: 0.93472222 | E49: # | F49: 0 | H49: CLOSED | J49: CLOSED | L49: CLOSED | N49: CLOSED
A51: 42430 | B51: =+A51 -> 42430 | C51: 1.9 | D51: 0.48888889 | E51: ** | F51: =+Harvest!F51/Effort!F51 -> 11.6875 | H51: CLOSED | J51: CLOSED | L51: CLOSED | N51: CLOSED
A52: 42431 | B52: =+A52 -> 42431 | C52: 1.8 | D52: 0.53541667 | F52: =+Harvest!F52/Effort!F52 -> 11.666667 | H52: CLOSED | J52: CLOSED | L52: CLOSED | N52: CLOSED
...

Sheet Summary Table
A1: 2015-2016 State (non-Indian) Recreational Razor Clam Effort, Harvest and CPUE totals.
E2: LONG BEACH | H2: TWIN HARBORS | K2: COPALIS | N2: MOCROCKS | Q2: KALALOCH | T2: DAILY TOTALS
A3: DATE | B3: DAY | C3: TIDE | D3: TIME | E3: Effort | F3: Harvest | G3: CPUE | H3: Effort | I3: Harvest | J3: CPUE | K3: Effort | L3: Harvest | M3: CPUE | N3: Effort | O3: Harvest | P3: CPUE | Q3: Effort | R3: Harvest | S3: CPUE | T3: Effort | U3: Harvest
A4: 42362 | B4: 42362 | C4: -1.2 | D4: 0.74097222 | E4: =Effort!F2 -> CLOSED | F4: =Harvest!F2 -> CLOSED | G4: =CPUE!F2 -> CLOSED | H4: =Effort!H2 -> CLOSED | I4: =Harvest!H2 -> CLOSED | J4: =CPUE!H2 -> CLOSED | K4: =Effort!J2 -> 2988.2721 | L4: =Harvest!J2 -> 42035.027 | M4: =CPUE!J2 -> 14.066667 | N4: =Effort!L2 -> CLOSED | O4: =Harvest!L2 -> CLOSED | P4: =CPUE!L2 -> CLOSED | Q4: =Effort!N2 -> CLOSED | R4: =Harvest!N2 -> CLOSED | S4: =CPUE!N2 -> CLOSED | T4: =+K4 -> 2988.2721 | U4: =+L4 -> 42035.027
A5: 42363 | B5: 42363 | C5: -1.3 | D5: 0.77083333 | E5: =Effort!F3 -> CLOSED | F5: =Harvest!F3 -> CLOSED | G5: =CPUE!F3 -> CLOSED | H5: =Effort!H3 -> CLOSED | I5: =Harvest!H3 -> CLOSED | J5: =CPUE!H3 -> CLOSED | K5: =Effort!J3 -> 3038.5041 | L5: =Harvest!J3 -> 45110.099 | M5: =CPUE!J3 -> 14.846154 | N5: =Effort!L3 -> CLOSED | O5: =Harvest!L3 -> CLOSED | P5: =CPUE!L3 -> CLOSED | Q5: =Effort!N3 -> CLOSED | R5: =Harvest!N3 -> CLOSED | S5: =CPUE!N3 -> CLOSED | T5: =+K5 -> 3038.5041 | U5: =+L5 -> 45110.099
A6: 42364 | B6: 42364 | C6: -1.1 | D6: 0.8 | E6: =Effort!F4 -> CLOSED | F6: =Harvest!F4 -> CLOSED | G6: =CPUE!F4 -> CLOSED | H6: =Effort!H4 -> CLOSED | I6: =Harvest!H4 -> CLOSED | J6: =CPUE!H4 -> CLOSED | K6: =Effort!J4 -> 5373.483 | L6: =Harvest!J4 -> 78186.261 | M6: =CPUE!J4 -> 14.550388 | N6: =Effort!L4 -> CLOSED | O6: =Harvest!L4 -> CLOSED | P6: =CPUE!L4 -> CLOSED | Q6: =Effort!N4 -> CLOSED | R6: =Harvest!N4 -> CLOSED | S6: =CPUE!N4 -> CLOSED | T6: =+K6 -> 5373.483 | U6: =+L6 -> 78186.261
A7: Tide Series Totals | K7: =SUM(K4:K6) -> 11400.259 | L7: =SUM(L4:L6) -> 165331.39 | M7: =+L7/K7 -> 14.502424 | T7: =SUM(T4:T6) -> 11400.259 | U7: =SUM(U4:U6) -> 165331.39
A8: 42376 | B8: =+A8 -> 42376 | C8: 0.1 | D8: 0.70625 | E8: =Effort!F6 -> 2173.2756 | F8: =Harvest!F6 -> 31029.546 | G8: =CPUE!F6 -> 14.277778 | H8: =Effort!H6 -> CLOSED | I8: =Harvest!H6 -> CLOSED | J8: =CPUE!H6 -> CLOSED | K8: =Effort!J6 -> CLOSED | L8: =Harvest!J6 -> CLOSED | M8: =CPUE!J6 -> CLOSED | N8: =Effort!L6 -> CLOSED | O8: =Harvest!L6 -> CLOSED | P8: =CPUE!L6 -> CLOSED | Q8: =Effort!N6 -> CLOSED | R8: =Harvest!N6 -> CLOSED | S8: =CPUE!N6 -> CLOSED | T8: =+E8 -> 2173.2756 | U8: =+F8 -> 31029.546
A9: 42377 | B9: =+A9 -> 42377 | C9: -0.4 | D9: 0.73402778 | E9: =Effort!F7 -> 2178.502 | F9: =Harvest!F7 -> 32644.271 | G9: =CPUE!F7 -> 14.984733 | H9: =Effort!H7 -> CLOSED | I9: =Harvest!H7 -> CLOSED | J9: =CPUE!H7 -> CLOSED | K9: =Effort!J7 -> 4608.3005 | L9: =Harvest!J7 -> 68780.604 | M9: =CPUE!J7 -> 14.925373 | N9: =Effort!L7 -> CLOSED | O9: =Harvest!L7 -> CLOSED | P9: =CPUE!L7 -> CLOSED | Q9: =Effort!N7 -> CLOSED | R9: =Harvest!N7 -> CLOSED | S9: =CPUE!N7 -> CLOSED | T9: =+E9+K9 -> 6786.8025 | U9: =+F9+L9 -> 101424.87
A10: 42378 | B10: =+A10 -> 42378 | C10: -0.8 | D10: 0.76111111 | E10: =Effort!F8 -> 6868.6145 | F10: =Harvest!F8 -> 87418.73 | G10: =CPUE!F8 -> 12.727273 | H10: =Effort!H8 -> CLOSED | I10: =Harvest!H8 -> CLOSED | J10: =CPUE!H8 -> CLOSED | K10: =Effort!J8 -> 8906.2352 | L10: =Harvest!J8 -> 114652.1 | M10: =CPUE!J8 -> 12.873239 | N10: =Effort!L8 -> CLOSED | O10: =Harvest!L8 -> CLOSED | P10: =CPUE!L8 -> CLOSED | Q10: =Effort!N8 -> CLOSED | R10: =Harvest!N8 -> CLOSED | S10: =CPUE!N8 -> CLOSED | T10: =+E10+K10 -> 15774.85 | U10: =+F10+L10 -> 202070.83
A11: 42379 | B11: =+A11 -> 42379 | C11: -1 | D11: 0.78819444 | E11: =Effort!F9 -> 2284.2464 | F11: =Harvest!F9 -> 34039.751 | G11: =CPUE!F9 -> 14.901961 | H11: =Effort!H9 -> CLOSED | I11: =Harvest!H9 -> CLOSED | J11: =CPUE!H9 -> CLOSED | K11: =Effort!J9 -> CLOSED | L11: =Harvest!J9 -> CLOSED | M11: =CPUE!J9 -> CLOSED | N11: =Effort!L9 -> CLOSED | O11: =Harvest!L9 -> CLOSED | P11: =CPUE!L9 -> CLOSED | Q11: =Effort!N9 -> CLOSED | R11: =Harvest!N9 -> CLOSED | S11: =CPUE!N9 -> CLOSED | T11: =+E11 -> 2284.2464 | U11: =+F11 -> 34039.751
A12: 42380 | B12: =+A12 -> 42380 | C12: -1 | D12: 0.81527778 | E12: =Effort!F10 -> 508.68853 | F12: =Harvest!F10 -> 7121.6395 | G12: =CPUE!F10 -> 14 | H12: =Effort!H10 -> CLOSED | I12: =Harvest!H10 -> CLOSED | J12: =CPUE!H10 -> CLOSED | K12: =Effort!J10 -> CLOSED | L12: =Harvest!J10 -> CLOSED | M12: =CPUE!J10 -> CLOSED | N12: =Effort!L10 -> CLOSED | O12: =Harvest!L10 -> CLOSED | P12: =CPUE!L10 -> CLOSED | Q12: =Effort!N10 -> CLOSED | R12: =Harvest!N10 -> CLOSED | S12: =CPUE!N10 -> CLOSED | T12: =+E12 -> 508.68853 | U12: =+F12 -> 7121.6395
A13: 42381 | B13: =+A13 -> 42381 | C13: -0.8 | D13: 0.84305556 | E13: =Effort!F11 -> 125.81914 | F13: =Harvest!F11 -> 1887.2871 | G13: =CPUE!F11 -> 15 | H13: =Effort!H11 -> CLOSED | I13: =Harvest!H11 -> CLOSED | J13: =CPUE!H11 -> CLOSED | K13: =Effort!J11 -> CLOSED | L13: =Harvest!J11 -> CLOSED | M13: =CPUE!J11 -> CLOSED | N13: =Effort!L11 -> CLOSED | O13: =Harvest!L11 -> CLOSED | P13: =CPUE!L11 -> CLOSED | Q13: =Effort!N11 -> CLOSED | R13: =Harvest!N11 -> CLOSED | S13: =CPUE!N11 -> CLOSED | T13: =+E13 -> 125.81914 | U13: =+F13 -> 1887.2871
A14: 42382 | B14: =+A14 -> 42382 | C14: -0.4 | D14: 0.87222222 | E14: =Effort!F12 -> 591.25035 | F14: =Harvest!F12 -> 8868.7553 | G14: =CPUE!F12 -> 15 | H14: =Effort!H12 -> CLOSED | I14: =Harvest!H12 -> CLOSED | J14: =CPUE!H12 -> CLOSED | K14: =Effort!J12 -> CLOSED | L14: =Harvest!J12 -> CLOSED | M14: =CPUE!J12 -> CLOSED | N14: =Effort!L12 -> CLOSED | O14: =Harvest!L12 -> CLOSED | P14: =CPUE!L12 -> CLOSED | Q14: =Effort!N12 -> CLOSED | R14: =Harvest!N12 -> CLOSED | S14: =CPUE!N12 -> CLOSED | T14: =+E14 -> 591.25035 | U14: =+F14 -> 8868.7553
A15: 42383 | B15: =+A15 -> 42383 | C15: 0.2 | D15: 0.90277778 | E15: =Effort!F13 -> 600 | F15: =Harvest!F13 -> 8900 | G15: =CPUE!F13 -> 14.833333 | H15: =Effort!H13 -> CLOSED | I15: =Harvest!H13 -> CLOSED | J15: =CPUE!H13 -> CLOSED | K15: =Effort!J13 -> CLOSED | L15: =Harvest!J13 -> CLOSED | M15: =CPUE!J13 -> CLOSED | N15: =Effort!L13 -> CLOSED | O15: =Harvest!L13 -> CLOSED | P15: =CPUE!L13 -> CLOSED | Q15: =Effort!N13 -> CLOSED | R15: =Harvest!N13 -> CLOSED | S15: =CPUE!N13 -> CLOSED | T15: =+E15 -> 600 | U15: =+F15 -> 8900
A16: Tide Series Totals | E16: =SUM(E8:E15) -> 15330.397 | F16: =SUM(F8:F15) -> 211909.98 | G16: =+F16/E16 -> 13.822864 | K16: =SUM(K9:K15) -> 13514.536 | L16: =SUM(L9:L15) -> 183432.7 | M16: =+L16/K16 -> 13.572993 | T16: =SUM(T8:T15) -> 28844.932 | U16: =SUM(U8:U15) -> 395342.68
A17: 42390 | B17: 42390 | C17: -0.4 | D17: 0.70069444 | E17: =Effort!F15 -> 488.61854 | F17: =Harvest!F15 -> 4230.7215 | G17: =CPUE!F15 -> 8.6585366 | H17: =Effort!H15 -> CLOSED | I17: =Harvest!H15 -> CLOSED | J17: =CPUE!H15 -> CLOSED | K17: =Effort!J15 -> CLOSED | L17: =Harvest!J15 -> CLOSED | M17: =CPUE!J15 -> CLOSED | N17: =Effort!L15 -> CLOSED | O17: =Harvest!L15 -> CLOSED | P17: =CPUE!L15 -> CLOSED | Q17: =Effort!N15 -> CLOSED | R17: =Harvest!N15 -> CLOSED | S17: =CPUE!N15 -> CLOSED | T17: =+E17 -> 488.61854 | U17: =+F17 -> 4230.7215
A18: 42391 | B18: 42391 | C18: -0.7 | D18: 0.73263889 | E18: =Effort!F16 -> 2846.5078 | F18: =Harvest!F16 -> 42697.617 | G18: =CPUE!F16 -> 15 | H18: =Effort!H16 -> CLOSED | I18: =Harvest!H16 -> CLOSED | J18: =CPUE!H16 -> CLOSED | K18: =Effort!J16 -> 4454.509 | L18: =Harvest!J16 -> 49770.571 | M18: =CPUE!J16 -> 11.173077 | N18: =Effort!L16 -> CLOSED | O18: =Harvest!L16 -> CLOSED | P18: =CPUE!L16 -> CLOSED | Q18: =Effort!N16 -> CLOSED | R18: =Harvest!N16 -> CLOSED | S18: =CPUE!N16 -> CLOSED | T18: =+E18+K18 -> 7301.0168 | U18: =+F18+L18 -> 92468.189
A19: 42392 | B19: 42392 | C19: -0.8 | D19: 0.76111111 | E19: =Effort!F17 -> 6367.2656 | F19: =Harvest!F17 -> 96068.744 | G19: =CPUE!F17 -> 15.087912 | H19: =Effort!H17 -> CLOSED | I19: =Harvest!H17 -> CLOSED | J19: =CPUE!H17 -> CLOSED | K19: =Effort!J17 -> CLOSED | L19: =Harvest!J17 -> CLOSED | M19: =CPUE!J17 -> CLOSED | N19: =Effort!L17 -> CLOSED | O19: =Harvest!L17 -> CLOSED | P19: =CPUE!L17 -> CLOSED | Q19: =Effort!N17 -> CLOSED | R19: =Harvest!N17 -> CLOSED | S19: =CPUE!N17 -> CLOSED | T19: =+E19 -> 6367.2656 | U19: =+F19 -> 96068.744
A20: 42393 | B20: 42393 | C20: -0.7 | D20: 0.7875 | E20: =Effort!F18 -> 2300 | F20: =Harvest!F18 -> 34000 | G20: =CPUE!F18 -> 14.782609 | H20: =Effort!H18 -> CLOSED | I20: =Harvest!H18 -> CLOSED | J20: =CPUE!H18 -> CLOSED | K20: =Effort!J18 -> CLOSED | L20: =Harvest!J18 -> CLOSED | M20: =CPUE!J18 -> CLOSED | N20: =Effort!L18 -> CLOSED | O20: =Harvest!L18 -> CLOSED | P20: =CPUE!L18 -> CLOSED | Q20: =Effort!N18 -> CLOSED | R20: =Harvest!N18 -> CLOSED | S20: =CPUE!N18 -> CLOSED | T20: =+E20 -> 2300 | U20: =+F20 -> 34000
A21: 42394 | B21: 42394 | C21: -0.4 | D21: 0.81319444 | E21: =Effort!F19 -> 510 | F21: =Harvest!F19 -> 7500 | G21: =CPUE!F19 -> 14.705882 | H21: =Effort!H19 -> CLOSED | I21: =Harvest!H19 -> CLOSED | J21: =CPUE!H19 -> CLOSED | K21: =Effort!J19 -> CLOSED | L21: =Harvest!J19 -> CLOSED | M21: =CPUE!J19 -> CLOSED | N21: =Effort!L19 -> CLOSED | O21: =Harvest!L19 -> CLOSED | P21: =CPUE!L19 -> CLOSED | Q21: =Effort!N19 -> CLOSED | R21: =Harvest!N19 -> CLOSED | S21: =CPUE!N19 -> CLOSED | T21: =+E21 -> 510 | U21: =+F21 -> 7500
A22: 42395 | B22: 42395 | C22: 0 | D22: 0.83680556 | E22: =Effort!F20 -> 150 | F22: =Harvest!F20 -> 1900 | G22: =CPUE!F20 -> 12.666667 | H22: =Effort!H20 -> CLOSED | I22: =Harvest!H20 -> CLOSED | J22: =CPUE!H20 -> CLOSED | K22: =Effort!J20 -> CLOSED | L22: =Harvest!J20 -> CLOSED | M22: =CPUE!J20 -> CLOSED | N22: =Effort!L20 -> CLOSED | O22: =Harvest!L20 -> CLOSED | P22: =CPUE!L20 -> CLOSED | Q22: =Effort!N20 -> CLOSED | R22: =Harvest!N20 -> CLOSED | S22: =CPUE!N20 -> CLOSED | T22: =+E22 -> 150 | U22: =+F22 -> 1900
A23: 42396 | B23: 42396 | C23: 0.5 | D23: 0.86041667 | E23: =Effort!F21 -> 100 | F23: =Harvest!F21 -> 0 | G23: =CPUE!F21 -> 0 | H23: =Effort!H21 -> CLOSED | I23: =Harvest!H21 -> CLOSED | J23: =CPUE!H21 -> CLOSED | K23: =Effort!J21 -> CLOSED | L23: =Harvest!J21 -> CLOSED | M23: =CPUE!J21 -> CLOSED | N23: =Effort!L21 -> CLOSED | O23: =Harvest!L21 -> CLOSED | P23: =CPUE!L21 -> CLOSED | Q23: =Effort!N21 -> CLOSED | R23: =Harvest!N21 -> CLOSED | S23: =CPUE!N21 -> CLOSED | T23: =+E23 -> 100 | U23: =+F23 -> 0
A24: Tide Series Totals | E24: =SUM(E17:E23) -> 12762.392 | F24: =SUM(F17:F23) -> 186397.08 | G24: =+F24/E24 -> 14.605184 | K24: =SUM(K18:K23) -> 4454.509 | L24: =SUM(L18:L23) -> 49770.571 | M24: =+L24/K24 -> 11.173077 | T24: =SUM(T17:T23) -> 17216.901 | U24: =SUM(U17:U23) -> 236167.65
A25: 42404 | B25: 42404 | C25: 0.8 | D25: 0.65347222 | E25: =Effort!F23 -> 774.80547 | F25: =Harvest!F23 -> 10622.333 | G25: =CPUE!F23 -> 13.709677 | H25: =Effort!H23 -> CLOSED | I25: =Harvest!H23 -> CLOSED | J25: =CPUE!H23 -> CLOSED | K25: =Effort!J23 -> CLOSED | L25: =Harvest!J23 -> CLOSED | M25: =CPUE!J23 -> CLOSED | N25: =Effort!L23 -> CLOSED | O25: =Harvest!L23 -> CLOSED | P25: =CPUE!L23 -> CLOSED | Q25: =Effort!N23 -> CLOSED | R25: =Harvest!N23 -> CLOSED | S25: =CPUE!N23 -> CLOSED | T25: =+E25 -> 774.80547 | U25: =+F25 -> 10622.333
A26: 42405 | B26: 42405 | C26: 0.2 | D26: 0.68611111 | E26: =Effort!F24 -> 451.95325 | F26: =Harvest!F24 -> 2905.4137 | G26: =CPUE!F24 -> 6.4285714 | H26: =Effort!H24 -> CLOSED | I26: =Harvest!H24 -> CLOSED | J26: =CPUE!H24 -> CLOSED | K26: =Effort!J24 -> CLOSED | L26: =Harvest!J24 -> CLOSED | M26: =CPUE!J24 -> CLOSED | N26: =Effort!L24 -> CLOSED | O26: =Harvest!L24 -> CLOSED | P26: =CPUE!L24 -> CLOSED | Q26: =Effort!N24 -> CLOSED | R26: =Harvest!N24 -> CLOSED | S26: =CPUE!N24 -> CLOSED | T26: =+E26 -> 451.95325 | U26: =+F26 -> 2905.4137
A27: 42406 | B27: 42406 | C27: -0.3 | D27: 0.71597222 | E27: =Effort!F25 -> 8081.6261 | F27: =Harvest!F25 -> 121224.39 | G27: =CPUE!F25 -> 15 | H27: =Effort!H25 -> CLOSED | I27: =Harvest!H25 -> CLOSED | J27: =CPUE!H25 -> CLOSED | K27: =Effort!J25 -> CLOSED | L27: =Harvest!J25 -> CLOSED | M27: =CPUE!J25 -> CLOSED | N27: =Effort!L25 -> CLOSED | O27: =Harvest!L25 -> CLOSED | P27: =CPUE!L25 -> CLOSED | Q27: =Effort!N25 -> CLOSED | R27: =Harvest!N25 -> CLOSED | S27: =CPUE!N25 -> CLOSED | T27: =+E27 -> 8081.6261 | U27: =+F27 -> 121224.39
A28: 42407 | B28: 42407 | C28: -0.7 | D28: 0.74444444 | E28: =Effort!F26 -> 1693.5957 | F28: =Harvest!F26 -> 25403.936 | G28: =CPUE!F26 -> 15 | H28: =Effort!H26 -> CLOSED | I28: =Harvest!H26 -> CLOSED | J28: =CPUE!H26 -> CLOSED | K28: =Effort!J26 -> CLOSED | L28: =Harvest!J26 -> CLOSED | M28: =CPUE!J26 -> CLOSED | N28: =Effort!L26 -> CLOSED | O28: =Harvest!L26 -> CLOSED | P28: =CPUE!L26 -> CLOSED | Q28: =Effort!N26 -> CLOSED | R28: =Harvest!N26 -> CLOSED | S28: =CPUE!N26 -> CLOSED | T28: =+E28 -> 1693.5957 | U28: =+F28 -> 25403.936
A29: 42408 | B29: =+A29 -> 42408 | C29: -1 | D29: 0.77222222 | E29: =Effort!F27 -> 3408.5604 | F29: =Harvest!F27 -> 50370.948 | G29: =CPUE!F27 -> 14.777778 | H29: =Effort!H27 -> CLOSED | I29: =Harvest!H27 -> CLOSED | J29: =CPUE!H27 -> CLOSED | K29: =Effort!J27 -> CLOSED | L29: =Harvest!J27 -> CLOSED | M29: =CPUE!J27 -> CLOSED | N29: =Effort!L27 -> CLOSED | O29: =Harvest!L27 -> CLOSED | P29: =CPUE!L27 -> CLOSED | Q29: =Effort!N27 -> CLOSED | R29: =Harvest!N27 -> CLOSED | S29: =CPUE!N27 -> CLOSED | T29: =+E29 -> 3408.5604 | U29: =+F29 -> 50370.948
A30: 42409 | B30: =+A30 -> 42409 | C30: -0.9 | D30: 0.8 | E30: =Effort!F28 -> 550 | F30: =Harvest!F28 -> 8000 | G30: =CPUE!F28 -> 14.545455 | H30: =Effort!H28 -> CLOSED | I30: =Harvest!H28 -> CLOSED | J30: =CPUE!H28 -> CLOSED | K30: =Effort!J28 -> CLOSED | L30: =Harvest!J28 -> CLOSED | M30: =CPUE!J28 -> CLOSED | N30: =Effort!L28 -> CLOSED | O30: =Harvest!L28 -> CLOSED | P30: =CPUE!L28 -> CLOSED | Q30: =Effort!N28 -> CLOSED | R30: =Harvest!N28 -> CLOSED | S30: =CPUE!N28 -> CLOSED | T30: =+E30 -> 550 | U30: =+F30 -> 8000
A31: 42410 | B31: =+A31 -> 42410 | C31: -0.7 | D31: 0.82777778 | E31: =Effort!F29 -> 387.68022 | F31: =Harvest!F29 -> 5815.2032 | G31: =CPUE!F29 -> 15 | H31: =Effort!H29 -> CLOSED | I31: =Harvest!H29 -> CLOSED | J31: =CPUE!H29 -> CLOSED | K31: =Effort!J29 -> CLOSED | L31: =Harvest!J29 -> CLOSED | M31: =CPUE!J29 -> CLOSED | N31: =Effort!L29 -> CLOSED | O31: =Harvest!L29 -> CLOSED | P31: =CPUE!L29 -> CLOSED | Q31: =Effort!N29 -> CLOSED | R31: =Harvest!N29 -> CLOSED | S31: =CPUE!N29 -> CLOSED | T31: =+E31 -> 387.68022 | U31: =+F31 -> 5815.2032
A32: 42411 | B32: =+A32 -> 42411 | C32: -0.1 | D32: 0.85694444 | E32: =Effort!F30 -> 400 | F32: =Harvest!F30 -> 5850 | G32: =CPUE!F30 -> 14.625 | H32: =Effort!H30 -> CLOSED | I32: =Harvest!H30 -> CLOSED | J32: =CPUE!H30 -> CLOSED | K32: =Effort!J30 -> CLOSED | L32: =Harvest!J30 -> CLOSED | M32: =CPUE!J30 -> CLOSED | N32: =Effort!L30 -> CLOSED | O32: =Harvest!L30 -> CLOSED | P32: =CPUE!L30 -> CLOSED | Q32: =Effort!N30 -> CLOSED | R32: =Harvest!N30 -> CLOSED | S32: =CPUE!N30 -> CLOSED | T32: =+E32 -> 400 | U32: =+F32 -> 5850
A33: 42412 | B33: =+A33 -> 42412 | C33: 0.6 | D33: 0.88680556 | E33: =Effort!F31 -> 800 | F33: =Harvest!F31 -> 11000 | G33: =CPUE!F31 -> 13.75 | H33: =Effort!H31 -> CLOSED | I33: =Harvest!H31 -> CLOSED | J33: =CPUE!H31 -> CLOSED | K33: =Effort!J31 -> CLOSED | L33: =Harvest!J31 -> CLOSED | M33: =CPUE!J31 -> CLOSED | N33: =Effort!L31 -> CLOSED | O33: =Harvest!L31 -> CLOSED | P33: =CPUE!L31 -> CLOSED | Q33: =Effort!N31 -> CLOSED | R33: =Harvest!N31 -> CLOSED | S33: =CPUE!N31 -> CLOSED | T33: =+E33 -> 800 | U33: =+F33 -> 11000
A34: 42413 | B34: =+A34 -> 42413 | C34: 1.4 | D34: 0.91944444 | E34: =Effort!F32 -> 1000 | F34: =Harvest!F32 -> 15000 | G34: =CPUE!F32 -> 15 | H34: =Effort!H32 -> CLOSED | I34: =Harvest!H32 -> CLOSED | J34: =CPUE!H32 -> CLOSED | K34: =Effort!J32 -> CLOSED | L34: =Harvest!J32 -> CLOSED | M34: =CPUE!J32 -> CLOSED | N34: =Effort!L32 -> CLOSED | O34: =Harvest!L32 -> CLOSED | P34: =CPUE!L32 -> CLOSED | Q34: =Effort!N32 -> CLOSED | R34: =Harvest!N32 -> CLOSED | S34: =CPUE!N32 -> CLOSED | T34: =+E34 -> 1000 | U34: =+F34 -> 15000
A35: 42414 | B35: =+A35 -> 42414 | C35: 2.2 | D35: 0.95694444 | E35: =Effort!F33 -> 100 | F35: =Harvest!F33 -> 1000 | G35: =CPUE!F33 -> 10 | H35: =Effort!H33 -> CLOSED | I35: =Harvest!H33 -> CLOSED | J35: =CPUE!H33 -> CLOSED | K35: =Effort!J33 -> CLOSED | L35: =Harvest!J33 -> CLOSED | M35: =CPUE!J33 -> CLOSED | N35: =Effort!L33 -> CLOSED | O35: =Harvest!L33 -> CLOSED | P35: =CPUE!L33 -> CLOSED | Q35: =Effort!N33 -> CLOSED | R35: =Harvest!N33 -> CLOSED | S35: =CPUE!N33 -> CLOSED | T35: =+E35 -> 100 | U35: =+F35 -> 1000
A36: Tide Series Totals | E36: =SUM(E25:E35) -> 17648.221 | F36: =SUM(F25:F35) -> 257192.23 | G36: =+F36/E36 -> 14.573266 | T36: =SUM(T25:T35) -> 17648.221 | U36: =SUM(U25:U35) -> 257192.23
A37: 42415 | B37: =+A37 -> 42415 | C37: 1.1 | D37: 0.51111111 | E37: =Effort!F35 -> 800 | F37: =Harvest!F35 -> 8000 | G37: =CPUE!F35 -> 10 | H37: =Effort!H35 -> CLOSED | I37: =Harvest!H35 -> CLOSED | J37: =CPUE!H35 -> CLOSED | K37: =Effort!J35 -> CLOSED | L37: =Harvest!J35 -> CLOSED | M37: =CPUE!J35 -> CLOSED | N37: =Effort!L35 -> CLOSED | O37: =Harvest!L35 -> CLOSED | P37: =CPUE!L35 -> CLOSED | Q37: =Effort!N35 -> CLOSED | R37: =Harvest!N35 -> CLOSED | S37: =CPUE!N35 -> CLOSED | T37: =+E37 -> 800 | U37: =+F37 -> 8000
A38: 42416 | B38: =+A38 -> 42416 | C38: 1 | D38: 0.5625 | E38: =Effort!F36 -> 800 | F38: =Harvest!F36 -> 8000 | G38: =CPUE!F36 -> 10 | H38: =Effort!H36 -> CLOSED | I38: =Harvest!H36 -> CLOSED | J38: =CPUE!H36 -> CLOSED | K38: =Effort!J36 -> CLOSED | L38: =Harvest!J36 -> CLOSED | M38: =CPUE!J36 -> CLOSED | N38: =Effort!L36 -> CLOSED | O38: =Harvest!L36 -> CLOSED | P38: =CPUE!L36 -> CLOSED | Q38: =Effort!N36 -> CLOSED | R38: =Harvest!N36 -> CLOSED | S38: =CPUE!N36 -> CLOSED | T38: =+E38 -> 800 | U38: =+F38 -> 8000
A39: 42417 | B39: =+A39 -> 42417 | C39: 0.7 | D39: 0.61111111 | E39: =Effort!F37 -> 791.11985 | F39: =Harvest!F37 -> 7673.8625 | G39: =CPUE!F37 -> 9.7 | H39: =Effort!H37 -> CLOSED | I39: =Harvest!H37 -> CLOSED | J39: =CPUE!H37 -> CLOSED | K39: =Effort!J37 -> CLOSED | L39: =Harvest!J37 -> CLOSED | M39: =CPUE!J37 -> CLOSED | N39: =Effort!L37 -> CLOSED | O39: =Harvest!L37 -> CLOSED | P39: =CPUE!L37 -> CLOSED | Q39: =Effort!N37 -> CLOSED | R39: =Harvest!N37 -> CLOSED | S39: =CPUE!N37 -> CLOSED | T39: =+E39 -> 791.11985 | U39: =+F39 -> 7673.8625
A40: 42418 | B40: =+A40 -> 42418 | C40: 0.3 | D40: 0.65347222 | E40: =Effort!F38 -> 873.949 | F40: =Harvest!F38 -> 8977.8398 | G40: =CPUE!F38 -> 10.272727 | H40: =Effort!H38 -> CLOSED | I40: =Harvest!H38 -> CLOSED | J40: =CPUE!H38 -> CLOSED | K40: =Effort!J38 -> CLOSED | L40: =Harvest!J38 -> CLOSED | M40: =CPUE!J38 -> CLOSED | N40: =Effort!L38 -> CLOSED | O40: =Harvest!L38 -> CLOSED | P40: =CPUE!L38 -> CLOSED | Q40: =Effort!N38 -> CLOSED | R40: =Harvest!N38 -> CLOSED | S40: =CPUE!N38 -> CLOSED | T40: =+E40 -> 873.949 | U40: =+F40 -> 8977.8398
...

Sheet Copy Sheet
A1: BeachName | B1: Date | C1: Effort | D1: Harvest | E1: CPUE | F1: EventID | G1: CorrectionFactor
A2: Copalis | B2: 42362 | C2: 3418.4839 | D2: 48086.674 | E2: 14.066667 | F2: 1224 | G2: 0.4815
A3: Copalis | B3: 42363 | C3: 3097.8534 | D3: 45991.208 | E3: 14.846154 | F3: 1225 | G3: 0.45906666
A4: Copalis | B4: 42364 | C4: 5364.5965 | D4: 78056.958 | E4: 14.550388 | F4: 1226 | G4: 0.49884999
A6: BeachName | B6: Date | C6: Effort | D6: Harvest | E6: CPUE | F6: EventID | G6: CorrectionFactor
A7: Copalis | B7: 42377 | C7: 4608.3005 | D7: 68780.604 | E7: 14.925373 | F7: 1227 | G7: 0.36967501
A8: Copalis | B8: 42378 | C8: 8906.2352 | D8: 114652.1 | E8: 12.873239 | F8: 1228 | G8: 0.498025
A10: BeachName | B10: Date | C10: Effort | D10: Harvest | E10: CPUE | F10: EventID | G10: CorrectionFactor
A11: Copalis | B11: 42362 | C11: 2988.2721 | D11: 42035.027 | E11: 14.066667 | F11: 1224 | G11: 0.55081999
A12: Copalis | B12: 42363 | C12: 3038.5041 | D12: 45110.099 | E12: 14.846154 | F12: 1225 | G12: 0.46803334
A13: Copalis | B13: 42364 | C13: 5373.483 | D13: 78186.261 | E13: 14.550388 | F13: 1226 | G13: 0.498025
A14: Copalis | B14: 42377 | C14: 4608.3005 | D14: 68780.604 | E14: 14.925373 | F14: 1227 | G14: 0.36967501
A15: Copalis | B15: 42378 | C15: 8906.2352 | D15: 114652.1 | E15: 12.873239 | F15: 1228 | G15: 0.498025
A16: LongBeach | B16: 42376 | C16: 2173.2756 | D16: 31029.546 | E16: 14.277778 | F16: 1229 | G16: 0.68533331
A17: LongBeach | B17: 42377 | C17: 2178.502 | D17: 32644.271 | E17: 14.984733 | F17: 1230 | G17: 0.68533331
A18: LongBeach | B18: 42378 | C18: 6868.6145 | D18: 87418.73 | E18: 12.727273 | F18: 1231 | G18: 0.68533331
A19: LongBeach | B19: 42379 | C19: 2284.2464 | D19: 34039.751 | E19: 14.901961 | F19: 1232 | G19: 0.63583332
A20: LongBeach | B20: 42380 | C20: 508.68853 | D20: 7121.6395 | E20: 14 | F20: 1233 | G20: 0.59417498
A21: LongBeach | B21: 42381 | C21: 125.81914 | D21: 1887.2871 | E21: 15 | F21: 1234 | G21: 0.63583332
A22: LongBeach | B22: 42382 | C22: 591.25035 | D22: 8868.7553 | E22: 15 | F22: 1235 | G22: 0.46173334
A24: BeachName | B24: Date | C24: Effort | D24: Harvest | E24: CPUE | F24: EventID | G24: CorrectionFactor
A25: Copalis | B25: 42391 | C25: 4454.509 | D25: 49770.571 | E25: 11.173077 | F25: 1236 | G25: 0.42597499
A26: LongBeach | B26: 42390 | C26: 488.61854 | D26: 4230.7215 | E26: 8.6585366 | F26: 1239 | G26: 0.50959998
A27: LongBeach | B27: 42391 | C27: 2846.5078 | D27: 42697.617 | E27: 15 | F27: 1237 | G27: 0.70139998
A28: LongBeach | B28: 42392 | C28: 6367.2656 | D28: 96068.744 | E28: 15.087912 | F28: 1238 | G28: 0.70139998
A30: BeachName | B30: Date | C30: Effort | D30: Harvest | E30: CPUE | F30: EventID | G30: CorrectionFactor
A31: LongBeach | B31: 42404 | C31: 774.80547 | D31: 10622.333 | E31: 13.709677 | F31: 1240 | G31: 0.68533331
A32: LongBeach | B32: 42405 | C32: 451.95325 | D32: 2905.4137 | E32: 6.4285714 | F32: 1241 | G32: 0.70139998
A33: LongBeach | B33: 42406 | C33: 8081.6261 | D33: 121224.39 | E33: 15 | F33: 1242 | G33: 0.68533331
A34: LongBeach | B34: 42407 | C34: 1693.5957 | D34: 25403.936 | E34: 15 | F34: 1243 | G34: 0.36070001
A35: LongBeach | B35: 42408 | C35: 3408.5604 | D35: 50370.948 | E35: 14.777778 | F35: 1244 | G35: 0.68533331
A36: LongBeach | B36: 42410 | C36: 387.68022 | D36: 5815.2032 | E36: 15 | F36: 1245 | G36: 0.63583332
A38: BeachName | B38: Date | C38: Effort | D38: Harvest | E38: CPUE | F38: EventID | G38: CorrectionFactor
A39: Copalis | B39: 42419 | C39: 3391.3042 | D39: 42899.999 | E39: 12.65 | F39: 1246 | G39: 0.39866668
A40: Copalis | B40: 42420 | C40: 9950.4269 | D40: 128329.73 | E40: 12.896907 | F40: 1247 | G40: 0.42597499
A41: LongBeach | B41: 42417 | C41: 791.11985 | D41: 7673.8625 | E41: 9.7 | F41: 1251 | G41: 0.54353333
A42: LongBeach | B42: 42418 | C42: 873.949 | D42: 8977.8398 | E42: 10.272727 | F42: 1252 | G42: 0.54353333
A43: LongBeach | B43: 42419 | C43: 1990.7679 | D43: 22831.619 | E43: 11.46875 | F43: 1253 | G43: 0.54605001
A44: LongBeach | B44: 42420 | C44: 13050.087 | D44: 201114.35 | E44: 15.410959 | F44: 1254 | G44: 0.54605001
A45: LongBeach | B45: 42421 | C45: 2154.2031 | D45: 32313.047 | E45: 15 | F45: 1255 | G45: 0.56029999
...

Sheet Sheet1
A1: TideDate | B1: TideHeight | C1: TideTime | D1: Sunrise | E1: Sunset
A2: 42429 | B2: 1.9 | C2: 0.44791667 | D2: 0.29027778 | E2: 0.75138889
A3: 42430 | B3: 1.9 | C3: 0.48888889 | D3: 0.28888889 | E3: 0.75208333
A4: 42431 | B4: 1.8 | C4: 0.53541667 | D4: 0.2875 | E4: 0.75347222
A5: 42432 | B5: 1.4 | C5: 0.58263889 | D5: 0.28611111 | E5: 0.75416667
A6: 42433 | B6: 0.9 | C6: 0.625 | D6: 0.28472222 | E6: 0.75555556
A7: 42434 | B7: 0.3 | C7: 0.66180556 | D7: 0.28333333 | E7: 0.75625
A8: 42435 | B8: -0.2 | C8: 0.69444444 | D8: 0.28263889 | E8: 0.75763889
A9: 42436 | B9: -0.5 | C9: 0.72430556 | D9: 0.28125 | E9: 0.75833333
A10: 42437 | B10: -0.6 | C10: 0.75347222 | D10: 0.27986111 | E10: 0.75972222
A11: 42438 | B11: -0.5 | C11: 0.78263889 | D11: 0.27847222 | E11: 0.76041667
A12: 42439 | B12: -0.2 | C12: 0.81111111 | D12: 0.27708333 | E12: 0.76111111
A13: 42440 | B13: -0.1 | C13: 0.33263889 | D13: 0.27569444 | E13: 0.7625
... A33: 42460 | B33: 1.2 | C33: 0.54305556 | D33: 0.28958333 | E33: 0.82361111

Sheet Tide Info
A1: TideDate | B1: TideHeight | C1: TideTime | D1: Sunrise | E1: Sunset
A2: 42362 | B2: 2.8 | C2: 0.20138889 | D2: 0.33541667 | E2: 0.68819444
A3: 42362 | B3: -1.2 | C3: 0.74097222 | D3: 0.33541667 | E3: 0.68819444
A4: 42363 | B4: 2.7 | C4: 0.23611111 | D4: 0.33541667 | E4: 0.68888889
A5: 42363 | B5: -1.3 | C5: 0.77083333 | D5: 0.33541667 | E5: 0.68888889
A6: 42364 | B6: 2.7 | C6: 0.26944444 | D6: 0.33541667 | E6: 0.68888889
A7: 42364 | B7: -1.1 | C7: 0.8 | D7: 0.33541667 | E7: 0.68888889
A8: 42365 | B8: 2.8 | C8: 0.30138889 | D8: 0.33541667 | E8: 0.68958333
A9: 42365 | B9: -0.8 | C9: 0.82777778 | D9: 0.33541667 | E9: 0.68958333
A10: 42366 | B10: 2.9 | C10: 0.33333333 | D10: 0.33611111 | E10: 0.69027778
A11: 42366 | B11: -0.3 | C11: 0.85486111 | D11: 0.33611111 | E11: 0.69027778
A12: 42367 | B12: 2.9 | C12: 0.36527778 | D12: 0.33611111 | E12: 0.69097222
A13: 42367 | B13: 0.2 | C13: 0.88194444 | D13: 0.33611111 | E13: 0.69097222
... A784: 42766 | B784: 0.2 | C784: 0.86805556 | D784: 0.32222222 | E784: 0.72083333

Sheet Tribal update
A1: 2015-2016 State (non-Indian) Recreational Razor Clam Effort, Harvest and CPUE totals.
E2: COPALIS | I2: MOCROCKS | M2: KALALOCH | Q2: DAILY TOTALS
A3: DATE | B3: DAY | C3: TIDE | D3: TIME | E3: Effort | F3: Harvest | G3: CPUE | H3: Size (mm) | I3: Effort | J3: Harvest | K3: CPUE | L3: Size (mm) | M3: Effort | N3: Harvest | O3: CPUE | P3: Size (mm) | Q3: Effort | R3: Harvest
A4: 42362 | B4: 42362 | C4: -1.2 | D4: 0.74097222 | E4: 2988.2721 | F4: 42035.027 | G4: 14.066667 | I4: CLOSED | J4: CLOSED | K4: CLOSED | M4: CLOSED | N4: CLOSED | O4: CLOSED | Q4: =+E4 -> 2988.2721 | R4: =+F4 -> 42035.027
A5: 42363 | B5: 42363 | C5: -1.3 | D5: 0.77083333 | E5: 3038.5041 | F5: 45110.099 | G5: 14.846154 | I5: CLOSED | J5: CLOSED | K5: CLOSED | M5: CLOSED | N5: CLOSED | O5: CLOSED | Q5: =+E5 -> 3038.5041 | R5: =+F5 -> 45110.099
A6: 42364 | B6: 42364 | C6: -1.1 | D6: 0.8 | E6: 5373.483 | F6: 78186.261 | G6: 14.550388 | I6: CLOSED | J6: CLOSED | K6: CLOSED | M6: CLOSED | N6: CLOSED | O6: CLOSED | Q6: =+E6 -> 5373.483 | R6: =+F6 -> 78186.261
A7: Tide Series Totals | E7: =SUM(E4:E6) -> 11400.259 | F7: =SUM(F4:F6) -> 165331.39 | G7: =+F7/E7 -> 14.502424 | H7: 111.5 | Q7: =SUM(Q4:Q6) -> 11400.259 | R7: =SUM(R4:R6) -> 165331.39
A8: 42377 | B8: 42377 | C8: -0.4 | D8: 0.73402778 | E8: 4608.3005 | F8: 68780.604 | G8: 14.925373 | I8: CLOSED | J8: CLOSED | K8: CLOSED | M8: CLOSED | N8: CLOSED | O8: CLOSED | Q8: =+E8 -> 4608.3005 | R8: =+F8 -> 68780.604
A9: 42378 | B9: 42378 | C9: -0.8 | D9: 0.76111111 | E9: 8906.2352 | F9: 114652.1 | G9: 12.873239 | I9: CLOSED | J9: CLOSED | K9: CLOSED | M9: CLOSED | N9: CLOSED | O9: CLOSED | Q9: =+E9 -> 8906.2352 | R9: =+F9 -> 114652.1
A10: Tide Series Totals | E10: =SUM(E8:E9) -> 13514.536 | F10: =SUM(F8:F9) -> 183432.7 | G10: =+F10/E10 -> 13.572993 | H10: 114.29 | Q10: =SUM(Q8:Q9) -> 13514.536 | R10: =SUM(R8:R9) -> 183432.7
A11: 42391 | B11: 42391 | C11: -0.7 | D11: 0.73263889 | E11: 4454.509 | F11: 49770.571 | G11: 11.173077 | I11: CLOSED | J11: CLOSED | K11: CLOSED | M11: CLOSED | N11: CLOSED | O11: CLOSED | Q11: =+E11 -> 4454.509 | R11: =+F11 -> 49770.571
A12: Tide Series Totals | E12: =SUM(E11) -> 4454.509 | F12: =SUM(F11) -> 49770.571 | G12: =+F12/E12 -> 11.173077 | Q12: =SUM(Q11) -> 4454.509 | R12: =SUM(R11) -> 49770.571
A13: 42419 | B13: 42419 | C13: 0 | D13: 0.68958333 | E13: 3391.3042 | F13: 42899.999 | G13: 12.65 | I13: 1766.6574 | J13: 14975.819 | K13: 8.4769231 | M13: CLOSED | N13: CLOSED | O13: CLOSED | Q13: =+E13+I13 -> 5157.9617 | R13: =+F13+J13 -> 57875.818
A14: 42420 | B14: 42420 | C14: -0.1 | D14: 0.72013889 | E14: 9950.4269 | F14: 128329.73 | G14: 12.896907 | I14: 7972.8508 | J14: 117314.81 | K14: 14.714286 | M14: CLOSED | N14: CLOSED | O14: CLOSED | Q14: =+E14+I14 -> 17923.278 | R14: =+F14+J14 -> 245644.54
A15: 42421 | B15: 42421 | C15: -0.2 | D15: 0.74722222 | E15: CLOSED | F15: CLOSED | G15: CLOSED | I15: 2511.1991 | J15: 37155.497 | K15: 14.795918 | M15: CLOSED | N15: CLOSED | O15: CLOSED | Q15: =+I15 -> 2511.1991 | R15: =+J15 -> 37155.497
A16: Tide Series Totals | E16: =SUM(E13:E15) -> 13341.731 | F16: =SUM(F13:F15) -> 171229.73 | G16: =+F16/E16 -> 12.834146 | I16: =SUM(I13:I15) -> 12250.707 | J16: =SUM(J13:J15) -> 169446.12 | K16: =+J16/I16 -> 13.831538 | Q16: =SUM(Q13:Q15) -> 25592.438 | R16: =SUM(R13:R15) -> 340675.85
A17: 42434 | B17: 42434 | C17: 0.3 | D17: 0.66180556 | E17: CLOSED | F17: CLOSED | G17: CLOSED | I17: 4831.4403 | J17: 16190.465 | K17: 3.3510638 | M17: CLOSED | N17: CLOSED | O17: CLOSED | Q17: =+I17 -> 4831.4403 | R17: =+J17 -> 16190.465
A18: 42435 | B18: 42435 | C18: -0.2 | D18: 0.69444444 | E18: CLOSED | F18: CLOSED | G18: CLOSED | I18: 3365.1189 | J18: 46672.736 | K18: 13.869565 | M18: CLOSED | N18: CLOSED | O18: CLOSED | Q18: =+I18 -> 3365.1189 | R18: =+J18 -> 46672.736
A19: 42436 | B19: 42436 | C19: -0.5 | D19: 0.72430556 | E19: CLOSED | F19: CLOSED | G19: CLOSED | I19: 1534.2714 | J19: 23014.071 | K19: 15 | M19: CLOSED | N19: CLOSED | O19: CLOSED | Q19: =+I19 -> 1534.2714 | R19: =+J19 -> 23014.071
A20: 42437 | B20: 42437 | C20: -0.6 | D20: 0.75347222 | E20: CLOSED | F20: CLOSED | G20: CLOSED | I20: 1104.0364 | J20: 15814.576 | K20: 14.324324 | M20: CLOSED | N20: CLOSED | O20: CLOSED | Q20: =+I20 -> 1104.0364 | R20: =+J20 -> 15814.576
A21: Tide Series Totals | I21: =SUM(I17:I20) -> 10834.867 | J21: =SUM(J17:J20) -> 101691.85 | K21: =+J21/I21 -> 9.385611 | Q21: =SUM(Q17:Q20) -> 10834.867 | R21: =SUM(R17:R20) -> 101691.85
A22: 42447 | B22: 42447 | C22: 0.7 | D22: 0.67708333 | E22: 3152.6803 | F22: 45488.673 | G22: 14.428571 | I22: 1390.7223 | J22: 20860.834 | K22: 15 | M22: CLOSED | N22: CLOSED | O22: CLOSED | Q22: =+E22+I22 -> 4543.4025 | R22: =+F22+J22 -> 66349.506
A23: 42448 | B23: 42448 | C23: 0.5 | D23: 0.71319444 | E23: 3556.6749 | F23: 45113.613 | G23: 12.684211 | I23: 3124.4271 | J23: 41740.394 | K23: 13.359375 | M23: CLOSED | N23: CLOSED | O23: CLOSED | Q23: =+E23+I23 -> 6681.102 | R23: =+F23+J23 -> 86854.007
A24: 42449 | B24: 42449 | C24: 0.4 | D24: 0.74305556 | E24: 2388.5618 | F24: 26990.748 | G24: 11.3 | I24: 1243.0343 | J24: 15811.396 | K24: 12.72 | M24: CLOSED | N24: CLOSED | O24: CLOSED | Q24: =+E24+I24 -> 3631.5961 | R24: =+F24+J24 -> 42802.144
A25: Tide Series Totals | E25: =SUM(E22:E24) -> 9097.917 | F25: =SUM(F22:F24) -> 117593.03 | G25: =+F25/E25 -> 12.92527 | I25: =SUM(I22:I24) -> 5758.1837 | J25: =SUM(J22:J24) -> 78412.624 | K25: =+J25/I25 -> 13.617597 | Q25: =SUM(Q22:Q24) -> 14856.101 | R25: =SUM(R22:R24) -> 196005.66
A26: 42454 | B26: 42454 | C26: 0.7 | D26: 0.35486111 | E26: CLOSED | F26: CLOSED | G26: CLOSED | I26: 1292.8784 | J26: 14939.928 | K26: 11.555556 | M26: CLOSED | N26: CLOSED | O26: CLOSED | Q26: =+I26 -> 1292.8784 | R26: =+J26 -> 14939.928
A27: 42455 | B27: 42455 | C27: 0.6 | D27: 0.37916667 | E27: CLOSED | F27: CLOSED | G27: CLOSED | I27: 4968.0354 | J27: 74520.532 | K27: 15 | M27: CLOSED | N27: CLOSED | O27: CLOSED | Q27: =+I27 -> 4968.0354 | R27: =+J27 -> 74520.532
A28: 42456 | B28: 42456 | C28: 0.7 | D28: 0.40416667 | E28: CLOSED | F28: CLOSED | G28: CLOSED | I28: 3481.0953 | J28: 44183.133 | K28: 12.692308 | M28: CLOSED | N28: CLOSED | O28: CLOSED | Q28: =+I28 -> 3481.0953 | R28: =+J28 -> 44183.133
A29: Tide Series Totals | I29: =SUM(I26:I28) -> 9742.0091 | J29: =SUM(J26:J28) -> 133643.59 | K29: =+J29/I29 -> 13.718278 | Q29: =SUM(Q26:Q28) -> 9742.0091 | R29: =SUM(R26:R28) -> 133643.59
A30: 42467 | B30: 42467 | C30: -0.6 | D30: 0.29652778 | E30: 1222.4801 | F30: 18362.15 | G30: 15.020408 | I30: 871.30697 | J30: 13069.605 | K30: 15 | M30: CLOSED | N30: CLOSED | O30: CLOSED | Q30: =+E30+I30 -> 2093.7871 | R30: =+F30+J30 -> 31431.755
A31: 42468 | B31: 42468 | C31: -1.1 | D31: 0.32916667 | E31: 2975.1365 | F31: 44627.048 | G31: 15 | I31: 1517.8988 | J31: 22768.481 | K31: 15 | M31: CLOSED | N31: CLOSED | O31: CLOSED | Q31: =+E31+I31 -> 4493.0353 | R31: =+F31+J31 -> 67395.529
A32: 42469 | B32: 42469 | C32: -1.3 | D32: 0.3625 | E32: 6892.9022 | F32: 102732.57 | G32: 14.90411 | I32: CLOSED | J32: CLOSED | K32: CLOSED | M32: CLOSED | N32: CLOSED | O32: CLOSED | Q32: =+E32 -> 6892.9022 | R32: =+F32 -> 102732.57
A33: 42470 | B33: 42470 | C33: -1.2 | D33: 0.39722222 | E33: CLOSED | F33: CLOSED | G33: CLOSED | I33: 6262.1848 | J33: 93932.772 | K33: 15 | M33: CLOSED | N33: CLOSED | O33: CLOSED | Q33: =+I33 -> 6262.1848 | R33: =+J33 -> 93932.772
A34: Tide Series Totals | E34: =SUM(E30:E33) -> 11090.519 | F34: =SUM(F30:F33) -> 165721.77 | G34: =+F34/E34 -> 14.942652 | I34: =SUM(I30:I33) -> 8651.3905 | J34: =SUM(J30:J33) -> 129770.86 | K34: =+J34/I34 -> 15 | Q34: =SUM(Q30:Q33) -> 19741.909 | R34: =SUM(R30:R33) -> 295492.63
A35: 42483 | B35: 42483 | C35: -0.2 | D35: 0.33888889 | E35: CLOSED | F35: CLOSED | G35: CLOSED | I35: 4007.8539 | J35: 60334.45 | K35: 15.054054 | M35: CLOSED | N35: CLOSED | O35: CLOSED | Q35: =+I35 -> 4007.8539 | R35: =+J35 -> 60334.45
A36: 42485 | B36: 42485 | C36: -0.2 | D36: 0.3875 | E36: 1346.5156 | F36: 19650.712 | G36: 14.59375 | I36: 1555.6668 | J36: 23335.003 | K36: 15 | M36: CLOSED | N36: CLOSED | O36: CLOSED | Q36: =+E36+I36 -> 2902.1824 | R36: =+F36+J36 -> 42985.715
A37: 42486 | B37: 42486 | C37: -0.1 | D37: 0.41388889 | E37: 1060.9701 | F37: 15914.551 | G37: 15 | I37: 1407.1107 | J37: 21106.66 | K37: 15 | M37: CLOSED | N37: CLOSED | O37: CLOSED | Q37: =+E37+I37 -> 2468.0808 | R37: =+F37+J37 -> 37021.212
A38: Tide Series Totals | E38: =SUM(E36:E37) -> 2407.4857 | F38: =SUM(F36:F37) -> 35565.263 | G38: =+F38/E38 -> 14.772783 | I38: =SUM(I35:I37) -> 6970.6315 | J38: =SUM(J35:J37) -> 104776.11 | K38: =+J38/I38 -> 15.031079 | Q38: =SUM(Q35:Q37) -> 9378.1171 | R38: =SUM(R35:R37) -> 140341.38
A39: 42499 | B39: 42499 | C39: -1.9 | D39: 0.38472222 | E39: CLOSED | F39: CLOSED | G39: CLOSED | I39: 2774.1613 | J39: 41409.432 | K39: 14.926829 | M39: CLOSED | N39: CLOSED | O39: CLOSED | Q39: =+I39 -> 2774.1613 | R39: =+J39 -> 41409.432
A40: 42500 | B40: 42500 | C40: -1.5 | D40: 0.41875 | E40: CLOSED | F40: CLOSED | G40: CLOSED | I40: 2903.3889 | J40: 43550.834 | K40: 15 | M40: CLOSED | N40: CLOSED | O40: CLOSED | Q40: =+I40 -> 2903.3889 | R40: =+J40 -> 43550.834
...

Sheet TAC
A1: NON-TRIBAL TOTAL ALLOWABLE CATCH (TAC)
B3: 2015 - 2016 | C3: 2014 - 2015 | D3: 2013 - 2014 | E3: 2012 - 2013 | F3: 2011 - 2012 | G3: 2010 - 2011
A4: LONG BEACH | B4: 4768605 | C4: 3885491.5 | D4: 2881223.3 | E4: 1847952.1 | F4: 1094641.4 | G4: 1276247.7
A5: TWIN HARBORS | B5: 1198600 | C5: 2662860.8 | D5: =5744410.73323314*0.4 -> 2297764.3 | E5: 1881783.2 | F5: 616314.31 | G5: 845427.67
A6: COPALIS | B6: 1094781 | C6: 889827.43 | D6: =(2615522*0.5)-(161153)+250000 -> 1396608 | E6: 1072689.6 | F6: 371373.04 | G6: 683167.41
A7: MOCROCKS | B7: 1695074 | C7: 2240308.7 | D7: 2088668.5 | E7: 909667.35 | F7: 605830.7 | G7: 545586.69
A8: KALALOCH | B8: 63740 | C8: 125735.13 | D8: =1033285.9456848*0.254*0.5 -> 131227.32 | E8: 113543.21 | F8: 144560.51 | G8: 258924.12
A9: COASTWIDE TAC | B9: =SUM(B4:B8) -> 8820800 | C9: =SUM(C4:C8) -> 9804223.7 | D9: =SUM(D4:D8) -> 8795491.4 | E9: =SUM(E4:E8) -> 5825635.5 | F9: =SUM(F4:F8) -> 2832720 | G9: =SUM(G4:G8) -> 3609353.6

Sheet TH Wastage
D100: =SUM(D2:D99) -> 0 | E100: =SUM(E2:E99) -> 0 | F100: =+D100/E100 -> #DIV/0!

Sheet LB Wastage
A1: EventID | B1: BeachName | C1: Date | D1: LocationID | E1: NHoles | F1: NClams | G1: NMorts
A2: 1295 | B2: LongBeach | C2: 42466 | D2: 12600 | E2: 100 | F2: 2 | G2: 2
A3: 1296 | B3: LongBeach | C3: 42467 | D3: 12600 | E3: 50 | F3: 4 | G3: 4
A4: 1296 | B4: LongBeach | C4: 42467 | D4: 12500 | E4: 50 | F4: 1 | G4: 1
A5: 1296 | B5: LongBeach | C5: 42467 | D5: 12400 | E5: 50 | F5: 0 | G5: 0
A6: 1297 | B6: LongBeach | C6: 42468 | D6: 12400 | E6: 50 | F6: 0 | G6: 0
A7: 1297 | B7: LongBeach | C7: 42468 | D7: 12500 | E7: 50 | F7: 2 | G7: 2
A8: 1299 | B8: LongBeach | C8: 42471 | D8: 12600 | E8: 50 | F8: 2 | G8: 2
A9: 1299 | B9: LongBeach | C9: 42471 | D9: 12500 | E9: 50 | F9: 2 | G9: 2
E100: =SUM(E2:E99) -> 450 | F100: =SUM(F2:F99) -> 13 | G100: =SUM(G2:G99) -> 13 | H100: =+G100/E100 -> 0.028888889

Sheet Cop Wastage
A1: EventID | B1: BeachName | C1: Date | D1: LocationID | E1: NHoles | F1: NClams | G1: NMorts | M1: EventID | N1: BeachName | O1: Date | P1: LocationID | Q1: NHoles | R1: NClams | S1: NMorts
A2: 1272 | B2: Copalis | C2: 42447 | D2: 31005 | E2: 100 | F2: 2 | G2: 2 | M2: 1272 | N2: Copalis | O2: 42447 | P2: 31005 | Q2: 100 | R2: 2 | S2: 2
A3: 1272 | B3: Copalis | C3: 42447 | D3: 32007 | E3: 100 | F3: 1 | G3: 1 | M3: 1272 | N3: Copalis | O3: 42447 | P3: 32007 | Q3: 100 | R3: 1 | S3: 1
A4: 1272 | B4: Copalis | C4: 42447 | D4: 33012 | E4: 100 | F4: 3 | G4: 2 | M4: 1272 | N4: Copalis | O4: 42447 | P4: 33012 | Q4: 100 | R4: 3 | S4: 2
A5: 1290 | B5: Copalis | C5: 42468 | D5: 31005 | E5: 100 | F5: 14 | G5: 14 | M5: 1290 | N5: Copalis | O5: 42468 | P5: 31005 | Q5: 100 | R5: 14 | S5: 14
A6: 1290 | B6: Copalis | C6: 42468 | D6: 32007 | E6: 100 | F6: 0 | G6: 0 | M6: 1290 | N6: Copalis | O6: 42468 | P6: 32007 | Q6: 100 | R6: 0 | S6: 0
A7: 1290 | B7: Copalis | C7: 42468 | D7: 31002 | E7: 100 | F7: 1 | G7: 1 | M7: 1290 | N7: Copalis | O7: 42468 | P7: 31002 | Q7: 100 | R7: 1 | S7: 1
A8: 1291 | B8: Copalis | C8: 42469 | D8: 33012 | E8: 100 | F8: 2 | G8: 2 | M8: 1291 | N8: Copalis | O8: 42469 | P8: 33012 | Q8: 100 | R8: 2 | S8: 2
A9: 1291 | B9: Copalis | C9: 42469 | D9: 32009 | E9: 100 | F9: 6 | G9: 5 | M9: 1291 | N9: Copalis | O9: 42469 | P9: 32009 | Q9: 100 | R9: 6 | S9: 5
A10: 1309 | B10: Copalis | C10: 42485 | D10: 31005 | E10: 100 | F10: 1 | G10: 1 | Q10: =SUM(Q2:Q9) -> 800 | S10: =SUM(S2:S9) -> 27 | T10: =+S10/Q10 -> 0.03375
A11: 1309 | B11: Copalis | C11: 42485 | D11: 33012 | E11: 100 | F11: 3 | G11: 3
A12: 1324 | B12: Copalis | C12: 42511 | D12: 33012 | E12: 100 | F12: 5 | G12: 5
E100: =SUM(E2:E99) -> 1100 | F100: =SUM(F2:F99) -> 38 | G100: =SUM(G2:G99) -> 36 | H100: =+G100/E100 -> 0.032727273

Sheet Moc Wastage
A1: EventID | B1: BeachName | C1: Date | D1: LocationID | E1: NHoles | F1: NClams | G1: NMorts
A2: 1287 | B2: Mocrocks | C2: 42468 | D2: 42600 | E2: 100 | F2: 2 | G2: 2
A3: 1287 | B3: Mocrocks | C3: 42468 | D3: 41400 | E3: 100 | F3: 4 | G3: 4
A4: 1288 | B4: Mocrocks | C4: 42470 | D4: 41300 | E4: 100 | F4: 2 | G4: 2
A5: 1288 | B5: Mocrocks | C5: 42470 | D5: 41400 | E5: 100 | F5: 4 | G5: 4
A6: 1288 | B6: Mocrocks | C6: 42470 | D6: 42500 | E6: 100 | F6: 2 | G6: 2
A7: 1288 | B7: Mocrocks | C7: 42470 | D7: 42600 | E7: 100 | F7: 1 | G7: 1
A8: 1305 | B8: Mocrocks | C8: 42483 | D8: 41400 | E8: 100 | F8: 2 | G8: 2
A9: 1311 | B9: Mocrocks | C9: 42485 | D9: 42500 | E9: 100 | F9: 3 | G9: 3
A10: 1314 | B10: Mocrocks | C10: 42499 | D10: 41400 | E10: 100 | F10: 3 | G10: 3
A11: 1314 | B11: Mocrocks | C11: 42499 | D11: 42600 | E11: 100 | F11: 2 | G11: 2
A12: 1314 | B12: Mocrocks | C12: 42499 | D12: 42500 | E12: 100 | F12: 4 | G12: 4
A13: 1315 | B13: Mocrocks | C13: 42500 | D13: 42600 | E13: 110 | F13: 2 | G13: 2
... A19: 1325 | B19: Mocrocks | C19: 42512 | D19: 41300 | E19: 100 | F19: 5 | G19: 5
E100: =SUM(E2:E99) -> 1810 | F100: =SUM(F2:F99) -> 51 | G100: =SUM(G2:G99) -> 51 | H100: =+G100/E100 -> 0.028176796
