Workbook

Sheet Harvest
A1: Date | B1: Day | C1: Tide | D1: Time | E1: Longbeach | G1: Twin Harbors | I1: Copalis | K1: Mocrocks | M1: Kalaloch | O1: Daily Totals
A2: 42657 | B2: 42657 | C2: 0.2 | D2: 0.74652778 | F2: Closed | G2: + | H2: 0 | I2: + | J2: 0 | K2: + | L2: 0 | N2: Closed | O2: =+H2+J2+L2 -> 0 | Q2: =SUM(O2:O7) -> 38959.263
A3: 42658 | B3: 42658 | C3: -0.6 | D3: 0.77916667 | F3: Closed | G3: + | H3: 0 | I3: + | J3: 0 | K3: + | L3: 0 | N3: Closed | O3: =+H3+J3+L3 -> 0
A4: 42659 | B4: 42659 | C4: -1.1 | D4: 0.81111111 | F4: Closed | H4: 5239.273 | J4: 3931.0174 | L4: 3976.3841 | N4: Closed | O4: =+H4+J4+L4 -> 13146.675
A5: 42660 | B5: 42660 | C5: -1.4 | D5: 0.84444444 | F5: Closed | H5: 14382.965 | J5: Closed | L5: Closed | N5: Closed | O5: =+H5 -> 14382.965
A6: 42661 | B6: 42661 | C6: -1.4 | D6: 0.87777778 | F6: Closed | H6: 9038.1747 | J6: Closed | L6: Closed | N6: Closed | O6: =+H6 -> 9038.1747
A7: 42662 | B7: 42662 | C7: -1.1 | D7: 0.91319444 | F7: Closed | H7: 2391.4485 | J7: Closed | L7: Closed | N7: Closed | O7: =+H7 -> 2391.4485
A9: 42691 | B9: 42691 | C9: -1.3 | D9: 0.85902778 | F9: Closed | H9: 10852.816 | J9: 10315.008 | L9: 7736.059 | N9: Closed | O9: =+H9+J9+L9 -> 28903.883
A10: 42692 | B10: 42692 | C10: -0.8 | D10: 0.89444444 | F10: Closed | H10: 12110.146 | J10: 10774.46 | L10: 6406.8845 | N10: Closed | O10: =+H10+J10+L10 -> 29291.491
A11: 42693 | B11: 42693 | C11: -0.1 | D11: 0.93194444 | F11: Closed | H11: 252.86589 | J11: 261.92821 | L11: 159.50036 | N11: Closed | O11: =+H11+J11+L11 -> 674.29446
A13: 42700 | B13: 42700 | C13: 0.5 | D13: 0.69930556 | F13: Closed | H13: 34508.144 | J13: Closed | L13: Closed | N13: Closed | O13: =+H13 -> 34508.144
A14: 42701 | B14: 42701 | C14: 0.2 | D14: 0.725 | F14: Closed | H14: 3289.6565 | J14: Closed | L14: Closed | N14: Closed | O14: =+H14 -> 3289.6565
A15: 42702 | B15: 42702 | C15: -0.1 | D15: 0.74930556 | F15: Closed | G15: * | H15: 3300 | J15: Closed | L15: Closed | N15: Closed | O15: =+H15 -> 3300
A17: 42714 | B17: 42714 | C17: 0.5 | D17: 0.64444444 | F17: Closed | H17: Closed | J17: 16813.56 | L17: 22186.181 | N17: Closed | O17: =+J17+L17 -> 38999.741
A18: 42715 | B18: 42715 | C18: -0.5 | D18: 0.68125 | F18: Closed | H18: Closed | J18: 14427.834 | L18: 13865.988 | N18: Closed | O18: =+J18+L18 -> 28293.822
A20: 42734 | B20: 42734 | C20: -0.4 | D20: 0.80694444 | F20: Closed | H20: Closed | J20: 33206.837 | L20: 19052.495 | N20: Closed | O20: =+J20+L20 -> 52259.332
A21: 42735 | B21: 42735 | C21: -0.4 | D21: 0.83125 | F21: Closed | H21: Closed | J21: 16361.611 | L21: 7057.4573 | N21: Closed | O21: =+J21+L21 -> 23419.068
A23: 42743 | B23: 42743 | C23: 0.4 | D23: 0.63263889 | F23: Closed | H23: Closed | J23: Closed | L23: Closed | N23: 55.977518 | O23: =+N23 -> 55.977518
A24: 42744 | B24: 42744 | C24: -0.4 | D24: 0.67222222 | F24: Closed | H24: Closed | J24: Closed | L24: Closed | N24: 1354.0909 | O24: =+N24 -> 1354.0909
A26: 42748 | B26: 42748 | C26: -1.4 | D26: 0.80347222 | F26: Closed | H26: Closed | J26: 19953.336 | L26: 7541.2774 | N26: Closed | O26: =+J26+L26 -> 27494.613
A27: 42749 | B27: 42749 | C27: -1 | D27: 0.83263889 | F27: Closed | H27: Closed | J27: 29519.205 | L27: 11707.679 | N27: Closed | O27: =+J27+L27 -> 41226.884
A28: 42750 | B28: 42750 | C28: -0.4 | D28: 0.86111111 | F28: Closed | H28: Closed | J28: 10379.858 | L28: 6457.2727 | N28: Closed | O28: =+J28+L28 -> 16837.131
A30: 42762 | B30: =+A30 -> 42762 | C30: -0.5 | D30: 0.76805556 | F30: Closed | H30: Closed | J30: 41084.52 | L30: Closed | N30: Closed | O30: =+J30 -> 41084.52
A31: 42763 | B31: =+A31 -> 42763 | C31: -0.6 | D31: 0.79236111 | F31: Closed | H31: Closed | J31: 60122.957 | L31: Closed | N31: Closed | O31: =+J31 -> 60122.957
A32: 42764 | B32: =+A32 -> 42764 | C32: -0.5 | D32: 0.81736111 | F32: Closed | H32: Closed | J32: 7517.0823 | L32: 7038.8012 | N32: Closed | O32: =+J32+L32 -> 14555.883
A33: 42765 | B33: =+A33 -> 42765 | C33: -0.3 | D33: 0.84236111 | F33: Closed | H33: Closed | J33: 6733.1876 | L33: 3902.1458 | N33: Closed | O33: =+J33+L33 -> 10635.333
A34: 42766 | B34: =+A34 -> 42766 | C34: 0.2 | D34: 0.86805556 | F34: Closed | H34: Closed | J34: 3819.7609 | L34: 1201.5436 | N34: Closed | O34: =+J34+L34 -> 5021.3045
A36: 42773 | B36: =+A36 -> 42773 | C36: -0.1 | D36: 0.66180556 | F36: Closed | H36: 10833.886 | J36: 11402.082 | L36: 7811.4949 | N36: Closed | O36: =+H36+J36+L36 -> 30047.463
A37: 42774 | B37: =+A37 -> 42774 | C37: -0.6 | D37: 0.69861111 | F37: Closed | H37: 8621.2794 | J37: 7546.1728 | L37: 6552.5503 | N37: Closed | O37: =+H37+J37+L37 -> 22720.002
A38: 42775 | B38: =+A38 -> 42775 | C38: -0.9 | D38: 0.73125 | F38: Closed | H38: 5333.4717 | J38: 4994.2372 | L38: 978.87929 | N38: Closed | O38: =+H38+J38+L38 -> 11306.588
A39: 42776 | B39: =+A39 -> 42776 | C39: -1 | D39: 0.76111111 | F39: Closed | H39: 13987.284 | J39: Closed | L39: 11802.752 | N39: Closed | O39: =+H39+L39 -> 25790.036
A40: 42777 | B40: =+A40 -> 42777 | C40: -0.8 | D40: 0.78958333 | F40: Closed | H40: 45902.945 | J40: Closed | L40: 49446.36 | N40: Closed | O40: =+H40+L40 -> 95349.305
A41: 42778 | B41: =+A41 -> 42778 | C41: -0.5 | D41: 0.81527778 | F41: Closed | H41: 18791.496 | J41: Closed | L41: 6302.3529 | N41: Closed | O41: =+H41+L41 -> 25093.849
A43: 42789 | B43: =+A43 -> 42789 | C43: 0.3 | D43: 0.69583333 | F43: Closed | H43: 30768.198 | J43: Closed | L43: Closed | N43: Closed | O43: =+H43 -> 30768.198
A44: 42790 | B44: =+A44 -> 42790 | C44: -0.1 | D44: 0.72291667 | F44: Closed | H44: 30879.446 | J44: 36368.681 | L44: 21031.351 | N44: Closed | O44: =+H44+J44+L44 -> 88279.478
A45: 42791 | B45: =+A45 -> 42791 | C45: -0.3 | D45: 0.74861111 | F45: Closed | H45: 70266.78 | J45: 108102.1 | L45: 66871.304 | N45: Closed | O45: =+H45+J45+L45 -> 245240.19
A46: 42792 | B46: =+A46 -> 42792 | C46: -0.4 | D46: 0.77361111 | F46: Closed | H46: 23539.1 | J46: 18158.717 | L46: 10016.961 | N46: Closed | O46: =+H46+J46+L46 -> 51714.778
A47: 42793 | B47: =+A47 -> 42793 | C47: -0.3 | D47: 0.79930556 | F47: Closed | H47: 4876.5299 | J47: Closed | L47: Closed | N47: Closed | O47: =+H47 -> 4876.5299
A48: 42794 | B48: =+A48 -> 42794 | C48: 0 | D48: 0.825 | F48: Closed | H48: 5388.9177 | J48: Closed | L48: Closed | N48: Closed | O48: =+H48 -> 5388.9177
A50: 42801 | B50: =+A50 -> 42801 | C50: 0.5 | D50: 0.60625 | F50: Closed | H50: 5883.692 | J50: Closed | L50: Closed | N50: Closed | O50: =+H50 -> 5883.692
...

Sheet Effort
A1: Date | B1: Day | C1: Tide | D1: Time | E1: Longbeach | G1: Twin Harbors | I1: Copalis | K1: Mocrocks | M1: Kalaloch | O1: Daily Totals
A2: 42657 | B2: 42657 | C2: 0.2 | D2: 0.74652778 | F2: Closed | G2: + | H2: 0 | I2: + | J2: 0 | K2: + | L2: 0 | N2: Closed
A3: 42658 | B3: 42658 | C3: -0.6 | D3: 0.77916667 | F3: Closed | G3: + | H3: 0 | I3: + | J3: 0 | K3: + | L3: 0 | N3: Closed
A4: 42659 | B4: 42659 | C4: -1.1 | D4: 0.81111111 | F4: Closed | H4: 554.15388 | J4: 307.45388 | L4: 296.48478 | N4: Closed | O4: =+H4+J4+L4 -> 1158.0925
A5: 42660 | B5: 42660 | C5: -1.4 | D5: 0.84444444 | F5: Closed | H5: 1012.021 | J5: Closed | L5: Closed | N5: Closed | O5: =+H5 -> 1012.021
A6: 42661 | B6: 42661 | C6: -1.4 | D6: 0.87777778 | F6: Closed | H6: 677.8631 | J6: Closed | L6: Closed | N6: Closed | O6: =+H6 -> 677.8631
A7: 42662 | B7: 42662 | C7: -1.1 | D7: 0.91319444 | F7: Closed | H7: 159.4299 | J7: Closed | L7: Closed | N7: Closed | O7: =+H7 -> 159.4299 | Q7: =SUM(O4:O7) -> 3007.4065
A9: 42691 | B9: 42691 | C9: -1.3 | D9: 0.85902778 | F9: Closed | H9: 809.65455 | J9: 698.17739 | L9: 546.07475 | N9: Closed | O9: =+H9+J9+L9 -> 2053.9067
A10: 42692 | B10: 42692 | C10: -0.8 | D10: 0.89444444 | F10: Closed | H10: 895.90365 | J10: 908.09801 | L10: 842.59275 | N10: Closed | O10: =+H10+J10+L10 -> 2646.5944
A11: 42693 | B11: 42693 | C11: -0.1 | D11: 0.93194444 | F11: Closed | H11: 416.48499 | J11: 654.82053 | L11: 595.46802 | N11: Closed | O11: =+H11+J11+L11 -> 1666.7735
A13: 42700 | B13: 42700 | C13: 0.5 | D13: 0.69930556 | F13: Closed | H13: 4386.0819 | J13: Closed | L13: Closed | N13: Closed | O13: =+H13 -> 4386.0819
A14: 42701 | B14: 42701 | C14: 0.2 | D14: 0.725 | F14: Closed | H14: 455.99199 | J14: Closed | L14: Closed | N14: Closed | O14: =+H14 -> 455.99199
A15: 42702 | B15: 42702 | C15: -0.1 | D15: 0.74930556 | F15: Closed | G15: * | H15: 460 | J15: Closed | L15: Closed | N15: Closed | O15: =+H15 -> 460 | Q15: =SUM(O9:O15) -> 11669.349
A17: 42714 | B17: 42714 | C17: 0.5 | D17: 0.64444444 | F17: Closed | H17: Closed | J17: 1730.2545 | L17: 1897.7294 | N17: Closed | O17: =+J17+L17 -> 3627.9838
A18: 42715 | B18: 42715 | C18: -0.5 | D18: 0.68125 | F18: Closed | H18: Closed | J18: 961.85558 | L18: 924.39921 | N18: Closed | O18: =+J18+L18 -> 1886.2548
A20: 42734 | B20: 42734 | C20: -0.4 | D20: 0.80694444 | F20: Closed | H20: Closed | J20: 2584.6269 | L20: 1621.0631 | N20: Closed | O20: =+J20+L20 -> 4205.69
A21: 42735 | B21: 42735 | C21: -0.4 | D21: 0.83125 | F21: Closed | H21: Closed | J21: 1417.8172 | L21: 849.15931 | N21: Closed | O21: =+J21+L21 -> 2266.9765 | Q21: =SUM(O17:O21) -> 11986.905
A23: 42743 | B23: 42743 | C23: 0.4 | D23: 0.63263889 | F23: Closed | H23: Closed | J23: Closed | L23: Closed | N23: 424.70811 | O23: =+N23 -> 424.70811
A24: 42744 | B24: 42744 | C24: -0.4 | D24: 0.67222222 | F24: Closed | H24: Closed | J24: Closed | L24: Closed | N24: 212.72727 | O24: =+N24 -> 212.72727
A26: 42748 | B26: 42748 | C26: -1.4 | D26: 0.80347222 | F26: Closed | H26: Closed | J26: 1360.4547 | L26: 528.84133 | N26: Closed | O26: =+J26+L26 -> 1889.296
A27: 42749 | B27: 42749 | C27: -1 | D27: 0.83263889 | F27: Closed | H27: Closed | J27: 2076.159 | L27: 1249.2064 | N27: Closed | O27: =+J27+L27 -> 3325.3654
A28: 42750 | B28: 42750 | C28: -0.4 | D28: 0.86111111 | F28: Closed | H28: Closed | J28: 827.08032 | L28: 789.73839 | N28: Closed | O28: =+J28+L28 -> 1616.8187
A30: 42762 | B30: =+A30 -> 42762 | C30: -0.5 | D30: 0.76805556 | F30: Closed | H30: Closed | J30: 3378.4057 | L30: Closed | N30: Closed | O30: =+J30 -> 3378.4057
A31: 42763 | B31: =+A31 -> 42763 | C31: -0.6 | D31: 0.79236111 | F31: Closed | H31: Closed | J31: 5779.776 | L31: Closed | N31: Closed | O31: =+J31 -> 5779.776
A32: 42764 | B32: =+A32 -> 42764 | C32: -0.5 | D32: 0.81736111 | F32: Closed | H32: Closed | J32: 528.97987 | L32: 476.5855 | N32: Closed | O32: =+J32+L32 -> 1005.5654
A33: 42765 | B33: =+A33 -> 42765 | C33: -0.3 | D33: 0.84236111 | F33: Closed | H33: Closed | J33: 448.87918 | L33: 271.73718 | N33: Closed | O33: =+J33+L33 -> 720.61635
A34: 42766 | B34: =+A34 -> 42766 | C34: 0.2 | D34: 0.86805556 | F34: Closed | H34: Closed | J34: 254.65073 | L34: 80.102905 | N34: Closed | O34: =+J34+L34 -> 334.75363 | Q34: =SUM(O23:O34) -> 18688.033
A36: 42773 | B36: =+A36 -> 42773 | C36: -0.1 | D36: 0.66180556 | F36: Closed | H36: 734.50074 | J36: 760.1388 | L36: 537.04028 | N36: Closed | O36: =+H36+J36+L36 -> 2031.6798
A37: 42774 | B37: =+A37 -> 42774 | C37: -0.6 | D37: 0.69861111 | F37: Closed | H37: 581.59425 | J37: 552.54403 | L37: 458.04235 | N37: Closed | O37: =+H37+J37+L37 -> 1592.1806
A38: 42775 | B38: =+A38 -> 42775 | C38: -0.9 | D38: 0.73125 | F38: Closed | H38: 599.1023 | J38: 688.09491 | L38: 549.78152 | N38: Closed | O38: =+H38+J38+L38 -> 1836.9787
A39: 42776 | B39: =+A39 -> 42776 | C39: -1 | D39: 0.76111111 | F39: Closed | H39: 973.02848 | J39: Closed | L39: 1468.6682 | N39: Closed | O39: =+H39+L39 -> 2441.6967
A40: 42777 | B40: =+A40 -> 42777 | C40: -0.8 | D40: 0.78958333 | F40: Closed | H40: 3616.08 | J40: Closed | L40: 4451.6084 | N40: Closed | O40: =+H40+L40 -> 8067.6884
A41: 42778 | B41: =+A41 -> 42778 | C41: -0.5 | D41: 0.81527778 | F41: Closed | H41: 1320.6322 | J41: Closed | L41: 716.17647 | N41: Closed | O41: =+H41+L41 -> 2036.8087
A43: 42789 | B43: =+A43 -> 42789 | C43: 0.3 | D43: 0.69583333 | F43: Closed | H43: 2118.2925 | J43: Closed | L43: Closed | N43: Closed | O43: =+H43 -> 2118.2925
A44: 42790 | B44: =+A44 -> 42790 | C44: -0.1 | D44: 0.72291667 | F44: Closed | H44: 2110.9955 | J44: 2424.5787 | L44: 1438.6266 | N44: Closed | O44: =+H44+J44+L44 -> 5974.2009
A45: 42791 | B45: =+A45 -> 42791 | C45: -0.3 | D45: 0.74861111 | F45: Closed | H45: 4832.7589 | J45: 8177.9369 | L45: 4819.975 | N45: Closed | O45: =+H45+J45+L45 -> 17830.671
A46: 42792 | B46: =+A46 -> 42792 | C46: -0.4 | D46: 0.77361111 | F46: Closed | H46: 1906 | J46: 1607.6658 | L46: 783.21915 | N46: Closed | O46: =+H46+J46+L46 -> 4296.885
A47: 42793 | B47: =+A47 -> 42793 | C47: -0.3 | D47: 0.79930556 | F47: Closed | H47: 714.23923 | J47: Closed | L47: Closed | N47: Closed | O47: =+H47 -> 714.23923
A48: 42794 | B48: =+A48 -> 42794 | C48: 0 | D48: 0.825 | F48: Closed | H48: 447.007 | J48: Closed | L48: Closed | N48: Closed | O48: =+H48 -> 447.007 | Q48: =SUM(O36:O48) -> 49388.328
A50: 42801 | B50: =+A50 -> 42801 | C50: 0.5 | D50: 0.60625 | F50: Closed | H50: 392.24613 | J50: Closed | L50: Closed | N50: Closed | O50: =+H50 -> 392.24613
...

Sheet CPUE
A1: Date | B1: Day | C1: Tide | D1: Time | E1: Longbeach | G1: Twin Harbors | I1: Copalis | K1: Mocrocks | M1: Kalaloch
A2: 42657 | B2: 42657 | C2: 0.2 | D2: 0.74652778 | F2: Closed | G2: + | H2: 0 | I2: + | J2: 0 | K2: + | L2: 0 | N2: Closed
A3: 42658 | B3: 42658 | C3: -0.6 | D3: 0.77916667 | F3: Closed | G3: + | H3: 0 | I3: + | J3: 0 | K3: + | L3: 0 | N3: Closed
A4: 42659 | B4: 42659 | C4: -1.1 | D4: 0.81111111 | F4: Closed | H4: =+Harvest!H4/Effort!H4 -> 9.4545455 | J4: =+Harvest!J4/Effort!J4 -> 12.785714 | L4: =+Harvest!L4/Effort!L4 -> 13.411765 | N4: Closed
A5: 42660 | B5: 42660 | C5: -1.4 | D5: 0.84444444 | F5: Closed | H5: =+Harvest!H5/Effort!H5 -> 14.212121 | J5: Closed | L5: Closed | N5: Closed
A6: 42661 | B6: 42661 | C6: -1.4 | D6: 0.87777778 | F6: Closed | H6: =+Harvest!H6/Effort!H6 -> 13.333333 | J6: Closed | L6: Closed | N6: Closed
A7: 42662 | B7: 42662 | C7: -1.1 | D7: 0.91319444 | F7: Closed | H7: =+Harvest!H7/Effort!H7 -> 15 | J7: Closed | L7: Closed | N7: Closed
A9: 42691 | B9: 42691 | C9: -1.3 | D9: 0.85902778 | F9: Closed | H9: =+Harvest!H9/Effort!H9 -> 13.404255 | J9: =+Harvest!J9/Effort!J9 -> 14.774194 | L9: =+Harvest!L9/Effort!L9 -> 14.166667 | N9: Closed
A10: 42692 | B10: 42692 | C10: -0.8 | D10: 0.89444444 | F10: Closed | H10: =+Harvest!H10/Effort!H10 -> 13.517241 | J10: =+Harvest!J10/Effort!J10 -> 11.864865 | L10: =+Harvest!L10/Effort!L10 -> 7.6037736 | N10: Closed
A11: 42693 | B11: 42693 | C11: -0.1 | D11: 0.93194444 | F11: Closed | H11: =+Harvest!H11/Effort!H11 -> 0.60714286 | J11: =+Harvest!J11/Effort!J11 -> 0.4 | L11: =+Harvest!L11/Effort!L11 -> 0.26785714 | N11: Closed
A13: 42700 | B13: 42700 | C13: 0.5 | D13: 0.69930556 | F13: Closed | H13: =+Harvest!H13/Effort!H13 -> 7.8676471 | J13: Closed | L13: Closed | N13: Closed
A14: 42701 | B14: 42701 | C14: 0.2 | D14: 0.725 | F14: Closed | H14: =+Harvest!H14/Effort!H14 -> 7.2142857 | J14: Closed | L14: Closed | N14: Closed
A15: 42702 | B15: 42702 | C15: -0.1 | D15: 0.74930556 | F15: Closed | H15: =+Harvest!H15/Effort!H15 -> 7.173913 | J15: Closed | L15: Closed | N15: Closed
A17: 42714 | B17: 42714 | C17: 0.5 | D17: 0.64444444 | F17: Closed | H17: Closed | J17: =+Harvest!J17/Effort!J17 -> 9.7173913 | L17: =+Harvest!L17/Effort!L17 -> 11.690909 | N17: Closed
A18: 42715 | B18: 42715 | C18: -0.5 | D18: 0.68125 | F18: Closed | H18: Closed | J18: =+Harvest!J18/Effort!J18 -> 15 | L18: =+Harvest!L18/Effort!L18 -> 15 | N18: Closed
A20: 42734 | B20: 42734 | C20: -0.4 | D20: 0.80694444 | F20: Closed | H20: Closed | J20: =+Harvest!J20/Effort!J20 -> 12.847826 | L20: =+Harvest!L20/Effort!L20 -> 11.753086 | N20: Closed
A21: 42735 | B21: 42735 | C21: -0.4 | D21: 0.83125 | F21: Closed | H21: Closed | J21: =+Harvest!J21/Effort!J21 -> 11.54 | L21: =+Harvest!L21/Effort!L21 -> 8.3111111 | N21: Closed
A23: 42743 | B23: 42743 | C23: 0.4 | D23: 0.63263889 | F23: Closed | H23: Closed | J23: Closed | L23: Closed | N23: 0.13180233
A24: 42744 | B24: 42744 | C24: -0.4 | D24: 0.67222222 | F24: Closed | H24: Closed | J24: Closed | L24: Closed | N24: =+Harvest!N24/Effort!N24 -> 6.3653846
A26: 42748 | B26: 42748 | C26: -1.4 | D26: 0.80347222 | F26: Closed | H26: Closed | J26: =+Harvest!J26/Effort!J26 -> 14.666667 | L26: =+Harvest!L26/Effort!L26 -> 14.26 | N26: Closed
A27: 42749 | B27: 42749 | C27: -1 | D27: 0.83263889 | F27: Closed | H27: Closed | J27: =+Harvest!J27/Effort!J27 -> 14.218182 | L27: =+Harvest!L27/Effort!L27 -> 9.372093 | N27: Closed
A28: 42750 | B28: 42750 | C28: -0.4 | D28: 0.86111111 | F28: Closed | H28: Closed | J28: =+Harvest!J28/Effort!J28 -> 12.55 | L28: =+Harvest!L28/Effort!L28 -> 8.1764706 | N28: Closed
A30: 42762 | B30: =+A30 -> 42762 | C30: -0.5 | D30: 0.76805556 | F30: Closed | H30: Closed | J30: =+Harvest!J30/Effort!J30 -> 12.16092 | L30: Closed | N30: Closed
A31: 42763 | B31: =+A31 -> 42763 | C31: -0.6 | D31: 0.79236111 | F31: Closed | H31: Closed | J31: =+Harvest!J31/Effort!J31 -> 10.402299 | L31: Closed | N31: Closed
A32: 42764 | B32: =+A32 -> 42764 | C32: -0.5 | D32: 0.81736111 | F32: Closed | H32: Closed | J32: =+Harvest!J32/Effort!J32 -> 14.210526 | L32: =+Harvest!L32/Effort!L32 -> 14.769231 | N32: Closed
A33: 42765 | B33: =+A33 -> 42765 | C33: -0.3 | D33: 0.84236111 | F33: Closed | H33: Closed | J33: =+Harvest!J33/Effort!J33 -> 15 | L33: =+Harvest!L33/Effort!L33 -> 14.36 | N33: Closed
A34: 42766 | B34: =+A34 -> 42766 | C34: 0.2 | D34: 0.86805556 | F34: Closed | H34: Closed | J34: =+Harvest!J34/Effort!J34 -> 15 | L34: =+Harvest!L34/Effort!L34 -> 15 | N34: Closed
A36: 42773 | B36: =+A36 -> 42773 | C36: -0.1 | D36: 0.66180556 | F36: Closed | H36: =+Harvest!H36/Effort!H36 -> 14.75 | J36: =+Harvest!J36/Effort!J36 -> 15 | L36: =+Harvest!L36/Effort!L36 -> 14.545455 | N36: Closed
A37: 42774 | B37: =+A37 -> 42774 | C37: -0.6 | D37: 0.69861111 | F37: Closed | H37: =+Harvest!H37/Effort!H37 -> 14.823529 | J37: =+Harvest!J37/Effort!J37 -> 13.657143 | L37: =+Harvest!L37/Effort!L37 -> 14.305556 | N37: Closed
A38: 42775 | B38: =+A38 -> 42775 | C38: -0.9 | D38: 0.73125 | F38: Closed | H38: =+Harvest!H38/Effort!H38 -> 8.902439 | J38: =+Harvest!J38/Effort!J38 -> 7.2580645 | L38: =+Harvest!L38/Effort!L38 -> 1.7804878 | N38: Closed
A39: 42776 | B39: =+A39 -> 42776 | C39: -1 | D39: 0.76111111 | F39: Closed | H39: =+Harvest!H39/Effort!H39 -> 14.375 | J39: Closed | L39: =+Harvest!L39/Effort!L39 -> 8.0363636 | N39: Closed
A40: 42777 | B40: =+A40 -> 42777 | C40: -0.8 | D40: 0.78958333 | F40: Closed | H40: =+Harvest!H40/Effort!H40 -> 12.694118 | J40: Closed | L40: =+Harvest!L40/Effort!L40 -> 11.107527 | N40: Closed
A41: 42778 | B41: =+A41 -> 42778 | C41: -0.5 | D41: 0.81527778 | F41: Closed | H41: =+Harvest!H41/Effort!H41 -> 14.229167 | J41: Closed | L41: =+Harvest!L41/Effort!L41 -> 8.8 | N41: Closed
A43: 42789 | B43: =+A43 -> 42789 | C43: 0.3 | D43: 0.69583333 | F43: Closed | H43: =+Harvest!H43/Effort!H43 -> 14.525 | J43: Closed | L43: Closed | N43: Closed
A44: 42790 | B44: =+A44 -> 42790 | C44: -0.1 | D44: 0.72291667 | F44: Closed | H44: =+Harvest!H44/Effort!H44 -> 14.627907 | J44: =+Harvest!J44/Effort!J44 -> 15 | L44: =+Harvest!L44/Effort!L44 -> 14.619048 | N44: Closed
A45: 42791 | B45: =+A45 -> 42791 | C45: -0.3 | D45: 0.74861111 | F45: Closed | H45: =+Harvest!H45/Effort!H45 -> 14.539683 | J45: =+Harvest!J45/Effort!J45 -> 13.21875 | L45: =+Harvest!L45/Effort!L45 -> 13.873786 | N45: Closed
A46: 42792 | B46: =+A46 -> 42792 | C46: -0.4 | D46: 0.77361111 | F46: Closed | H46: =+Harvest!H46/Effort!H46 -> 12.35 | J46: =+Harvest!J46/Effort!J46 -> 11.295082 | L46: =+Harvest!L46/Effort!L46 -> 12.789474 | N46: Closed
A47: 42793 | B47: =+A47 -> 42793 | C47: -0.3 | D47: 0.79930556 | F47: Closed | H47: =+Harvest!H47/Effort!H47 -> 6.8275862 | J47: Closed | L47: Closed | N47: Closed
A48: 42794 | B48: =+A48 -> 42794 | C48: 0 | D48: 0.825 | F48: Closed | H48: =+Harvest!H48/Effort!H48 -> 12.055556 | J48: Closed | L48: Closed | N48: Closed
A50: 42801 | B50: =+A50 -> 42801 | C50: 0.5 | D50: 0.60625 | F50: Closed | H50: =+Harvest!H50/Effort!H50 -> 15 | J50: Closed | L50: Closed | N50: Closed
...

Sheet Summary Table
A1: 2016-2017 State (non-Indian) Recreational Razor Clam Effort, Harvest and CPUE totals.FINAL
E2: LONG BEACH | H2: TWIN HARBORS | K2: COPALIS | N2: MOCROCKS | Q2: KALALOCH | T2: DAILY TOTALS
A3: DATE | B3: DAY | C3: TIDE | D3: TIME | E3: Effort | F3: Harvest | G3: CPUE | H3: Effort | I3: Harvest | J3: CPUE | K3: Effort | L3: Harvest | M3: CPUE | N3: Effort | O3: Harvest | P3: CPUE | Q3: Effort | R3: Harvest | S3: CPUE | T3: Effort | U3: Harvest
A4: 42657 | B4: 42657 | C4: 0.2 | D4: 0.74652778 | E4: =Effort!F2 -> Closed | F4: =Harvest!F2 -> Closed | G4: =CPUE!F2 -> Closed | H4: =Effort!H2 -> 0 | I4: =Harvest!H2 -> 0 | J4: =CPUE!H2 -> 0 | K4: =Effort!J2 -> 0 | L4: =Harvest!J2 -> 0 | M4: =CPUE!J2 -> 0 | N4: =Effort!L2 -> 0 | O4: =Harvest!L2 -> 0 | P4: =CPUE!L2 -> 0 | Q4: =Effort!N2 -> Closed | R4: =Harvest!N2 -> Closed | S4: =CPUE!N2 -> Closed | T4: =+H4+K4+N4 -> 0 | U4: =+I4+L4+O4 -> 0
A5: 42658 | B5: 42658 | C5: -0.6 | D5: 0.77916667 | E5: =Effort!F3 -> Closed | F5: =Harvest!F3 -> Closed | G5: =CPUE!F3 -> Closed | H5: =Effort!H3 -> 0 | I5: =Harvest!H3 -> 0 | J5: =CPUE!H3 -> 0 | K5: =Effort!J3 -> 0 | L5: =Harvest!J3 -> 0 | M5: =CPUE!J3 -> 0 | N5: =Effort!L3 -> 0 | O5: =Harvest!L3 -> 0 | P5: =CPUE!L3 -> 0 | Q5: =Effort!N3 -> Closed | R5: =Harvest!N3 -> Closed | S5: =CPUE!N3 -> Closed | T5: =+H5+K5+N5 -> 0 | U5: =+I5+L5+O5 -> 0
A6: 42659 | B6: 42659 | C6: -1.1 | D6: 0.81111111 | E6: =Effort!F4 -> Closed | F6: =Harvest!F4 -> Closed | G6: =CPUE!F4 -> Closed | H6: =Effort!H4 -> 554.15388 | I6: =Harvest!H4 -> 5239.273 | J6: =CPUE!H4 -> 9.4545455 | K6: =Effort!J4 -> 307.45388 | L6: =Harvest!J4 -> 3931.0174 | M6: =CPUE!J4 -> 12.785714 | N6: =Effort!L4 -> 296.48478 | O6: =Harvest!L4 -> 3976.3841 | P6: =CPUE!L4 -> 13.411765 | Q6: =Effort!N4 -> Closed | R6: =Harvest!N4 -> Closed | S6: =CPUE!N4 -> Closed | T6: =+H6+K6+N6 -> 1158.0925 | U6: =+I6+L6+O6 -> 13146.675
A7: 42660 | B7: 42660 | C7: -1.4 | D7: 0.84444444 | E7: =Effort!F5 -> Closed | F7: =Harvest!F5 -> Closed | G7: =CPUE!F5 -> Closed | H7: =Effort!H5 -> 1012.021 | I7: =Harvest!H5 -> 14382.965 | J7: =CPUE!H5 -> 14.212121 | K7: =Effort!J5 -> Closed | L7: =Harvest!J5 -> Closed | M7: =CPUE!J5 -> Closed | N7: =Effort!L5 -> Closed | O7: =Harvest!L5 -> Closed | P7: =CPUE!L5 -> Closed | Q7: =Effort!N5 -> Closed | R7: =Harvest!N5 -> Closed | S7: =CPUE!N5 -> Closed | T7: =+H7 -> 1012.021 | U7: =+I7 -> 14382.965
A8: 42661 | B8: 42661 | C8: -1.4 | D8: 0.87777778 | E8: =Effort!F6 -> Closed | F8: =Harvest!F6 -> Closed | G8: =CPUE!F6 -> Closed | H8: =Effort!H6 -> 677.8631 | I8: =Harvest!H6 -> 9038.1747 | J8: =CPUE!H6 -> 13.333333 | K8: =Effort!J6 -> Closed | L8: =Harvest!J6 -> Closed | M8: =CPUE!J6 -> Closed | N8: =Effort!L6 -> Closed | O8: =Harvest!L6 -> Closed | P8: =CPUE!L6 -> Closed | Q8: =Effort!N6 -> Closed | R8: =Harvest!N6 -> Closed | S8: =CPUE!N6 -> Closed | T8: =+H8 -> 677.8631 | U8: =+I8 -> 9038.1747
A9: 42662 | B9: 42662 | C9: -1.1 | D9: 0.91319444 | E9: =Effort!F7 -> Closed | F9: =Harvest!F7 -> Closed | G9: =CPUE!F7 -> Closed | H9: =Effort!H7 -> 159.4299 | I9: =Harvest!H7 -> 2391.4485 | J9: =CPUE!H7 -> 15 | K9: =Effort!J7 -> Closed | L9: =Harvest!J7 -> Closed | M9: =CPUE!J7 -> Closed | N9: =Effort!L7 -> Closed | O9: =Harvest!L7 -> Closed | P9: =CPUE!L7 -> Closed | Q9: =Effort!N7 -> Closed | R9: =Harvest!N7 -> Closed | S9: =CPUE!N7 -> Closed | T9: =+H9 -> 159.4299 | U9: =+I9 -> 2391.4485
A10: Tide Series Totals | H10: =SUM(H4:H9) -> 2403.4679 | I10: =SUM(I4:I9) -> 31051.861 | J10: =+I10/H10 -> 12.919607 | K10: =SUM(K4:K9) -> 307.45388 | L10: =SUM(L4:L9) -> 3931.0174 | M10: =+L10/K10 -> 12.785714 | N10: =SUM(N4:N9) -> 296.48478 | O10: =SUM(O4:O9) -> 3976.3841 | P10: =+O10/N10 -> 13.411765 | T10: =SUM(T4:T9) -> 3007.4065 | U10: =SUM(U4:U9) -> 38959.263
A11: 42691 | B11: 42691 | C11: -1.3 | D11: 0.85902778 | E11: =Effort!F9 -> Closed | F11: =Harvest!F9 -> Closed | G11: =CPUE!F9 -> Closed | H11: =Effort!H9 -> 809.65455 | I11: =Harvest!H9 -> 10852.816 | J11: =CPUE!H9 -> 13.404255 | K11: =Effort!J9 -> 698.17739 | L11: =Harvest!J9 -> 10315.008 | M11: =CPUE!J9 -> 14.774194 | N11: =Effort!L9 -> 546.07475 | O11: =Harvest!L9 -> 7736.059 | P11: =CPUE!L9 -> 14.166667 | Q11: =Effort!N9 -> Closed | R11: =Harvest!N9 -> Closed | S11: =CPUE!N9 -> Closed | T11: =+H11+K11+N11 -> 2053.9067 | U11: =+I11+L11+O11 -> 28903.883
A12: 42692 | B12: 42692 | C12: -0.8 | D12: 0.89444444 | E12: =Effort!F10 -> Closed | F12: =Harvest!F10 -> Closed | G12: =CPUE!F10 -> Closed | H12: =Effort!H10 -> 895.90365 | I12: =Harvest!H10 -> 12110.146 | J12: =CPUE!H10 -> 13.517241 | K12: =Effort!J10 -> 908.09801 | L12: =Harvest!J10 -> 10774.46 | M12: =CPUE!J10 -> 11.864865 | N12: =Effort!L10 -> 842.59275 | O12: =Harvest!L10 -> 6406.8845 | P12: =CPUE!L10 -> 7.6037736 | Q12: =Effort!N10 -> Closed | R12: =Harvest!N10 -> Closed | S12: =CPUE!N10 -> Closed | T12: =+H12+K12+N12 -> 2646.5944 | U12: =+I12+L12+O12 -> 29291.491
A13: 42693 | B13: 42693 | C13: -0.1 | D13: 0.93194444 | E13: =Effort!F11 -> Closed | F13: =Harvest!F11 -> Closed | G13: =CPUE!F11 -> Closed | H13: =Effort!H11 -> 416.48499 | I13: =Harvest!H11 -> 252.86589 | J13: =CPUE!H11 -> 0.60714286 | K13: =Effort!J11 -> 654.82053 | L13: =Harvest!J11 -> 261.92821 | M13: =CPUE!J11 -> 0.4 | N13: =Effort!L11 -> 595.46802 | O13: =Harvest!L11 -> 159.50036 | P13: =CPUE!L11 -> 0.26785714 | Q13: =Effort!N11 -> Closed | R13: =Harvest!N11 -> Closed | S13: =CPUE!N11 -> Closed | T13: =+H13+K13+N13 -> 1666.7735 | U13: =+I13+L13+O13 -> 674.29446
A14: Tide Series Totals | H14: =SUM(H11:H13) -> 2122.0432 | I14: =SUM(I11:I13) -> 23215.828 | J14: =+I14/H14 -> 10.940318 | K14: =SUM(K11:K13) -> 2261.0959 | L14: =SUM(L11:L13) -> 21351.396 | M14: =+L14/K14 -> 9.4429413 | N14: =SUM(N11:N13) -> 1984.1355 | O14: =SUM(O11:O13) -> 14302.444 | P14: =+O14/N14 -> 7.2084007 | T14: =SUM(T11:T13) -> 6367.2747 | U14: =SUM(U11:U13) -> 58869.668
A15: 42700 | B15: 42700 | C15: 0.5 | D15: 0.69930556 | E15: =Effort!F13 -> Closed | F15: =Harvest!F13 -> Closed | G15: =CPUE!F13 -> Closed | H15: =Effort!H13 -> 4386.0819 | I15: =Harvest!H13 -> 34508.144 | J15: =CPUE!H13 -> 7.8676471 | K15: =Effort!J13 -> Closed | L15: =Harvest!J13 -> Closed | M15: =CPUE!J13 -> Closed | N15: =Effort!L13 -> Closed | O15: =Harvest!L13 -> Closed | P15: =CPUE!L13 -> Closed | Q15: =Effort!N13 -> Closed | R15: =Harvest!N13 -> Closed | S15: =CPUE!N13 -> Closed | T15: =+H15 -> 4386.0819 | U15: =+I15 -> 34508.144
A16: 42701 | B16: 42701 | C16: 0.2 | D16: 0.725 | E16: =Effort!F14 -> Closed | F16: =Harvest!F14 -> Closed | G16: =CPUE!F14 -> Closed | H16: =Effort!H14 -> 455.99199 | I16: =Harvest!H14 -> 3289.6565 | J16: =CPUE!H14 -> 7.2142857 | K16: =Effort!J14 -> Closed | L16: =Harvest!J14 -> Closed | M16: =CPUE!J14 -> Closed | N16: =Effort!L14 -> Closed | O16: =Harvest!L14 -> Closed | P16: =CPUE!L14 -> Closed | Q16: =Effort!N14 -> Closed | R16: =Harvest!N14 -> Closed | S16: =CPUE!N14 -> Closed | T16: =+H16 -> 455.99199 | U16: =+I16 -> 3289.6565
A17: 42702 | B17: 42702 | C17: -0.1 | D17: 0.74930556 | E17: =Effort!F15 -> Closed | F17: =Harvest!F15 -> Closed | G17: =CPUE!F15 -> Closed | H17: =Effort!H15 -> 460 | I17: =Harvest!H15 -> 3300 | J17: =CPUE!H15 -> 7.173913 | K17: =Effort!J15 -> Closed | L17: =Harvest!J15 -> Closed | M17: =CPUE!J15 -> Closed | N17: =Effort!L15 -> Closed | O17: =Harvest!L15 -> Closed | P17: =CPUE!L15 -> Closed | Q17: =Effort!N15 -> Closed | R17: =Harvest!N15 -> Closed | S17: =CPUE!N15 -> Closed | T17: =+H17 -> 460 | U17: =+I17 -> 3300
A18: Tide Series Totals | H18: =SUM(H15:H17) -> 5302.0739 | I18: =SUM(I15:I17) -> 41097.801 | J18: =+I18/H18 -> 7.751269 | T18: =SUM(T15:T17) -> 5302.0739 | U18: =SUM(U15:U17) -> 41097.801
A19: 42714 | B19: 42714 | C19: 0.5 | D19: 0.64444444 | E19: =Effort!F17 -> Closed | F19: =Harvest!F17 -> Closed | G19: =CPUE!F17 -> Closed | H19: =Effort!H17 -> Closed | I19: =Harvest!H17 -> Closed | J19: =CPUE!H17 -> Closed | K19: =Effort!J17 -> 1730.2545 | L19: =Harvest!J17 -> 16813.56 | M19: =CPUE!J17 -> 9.7173913 | N19: =Effort!L17 -> 1897.7294 | O19: =Harvest!L17 -> 22186.181 | P19: =CPUE!L17 -> 11.690909 | Q19: =Effort!N17 -> Closed | R19: =Harvest!N17 -> Closed | S19: =CPUE!N17 -> Closed | T19: =+K19+N19 -> 3627.9838 | U19: =+L19+O19 -> 38999.741
A20: 42715 | B20: 42715 | C20: -0.5 | D20: 0.68125 | E20: =Effort!F18 -> Closed | F20: =Harvest!F18 -> Closed | G20: =CPUE!F18 -> Closed | H20: =Effort!H18 -> Closed | I20: =Harvest!H18 -> Closed | J20: =CPUE!H18 -> Closed | K20: =Effort!J18 -> 961.85558 | L20: =Harvest!J18 -> 14427.834 | M20: =CPUE!J18 -> 15 | N20: =Effort!L18 -> 924.39921 | O20: =Harvest!L18 -> 13865.988 | P20: =CPUE!L18 -> 15 | Q20: =Effort!N18 -> Closed | R20: =Harvest!N18 -> Closed | S20: =CPUE!N18 -> Closed | T20: =+K20+N20 -> 1886.2548 | U20: =+L20+O20 -> 28293.822
A21: Tide Series Totals | K21: =SUM(K19:K20) -> 2692.1101 | L21: =SUM(L19:L20) -> 31241.393 | M21: =+L21/K21 -> 11.604798 | N21: =SUM(N19:N20) -> 2822.1286 | O21: =SUM(O19:O20) -> 36052.17 | P21: =+O21/N21 -> 12.774815 | T21: =SUM(T19:T20) -> 5514.2386 | U21: =SUM(U19:U20) -> 67293.563
A22: 42734 | B22: 42734 | C22: -0.4 | D22: 0.80694444 | E22: =Effort!F20 -> Closed | F22: =Harvest!F20 -> Closed | G22: =CPUE!F20 -> Closed | H22: =Effort!H20 -> Closed | I22: =Harvest!H20 -> Closed | J22: =CPUE!H20 -> Closed | K22: =Effort!J20 -> 2584.6269 | L22: =Harvest!J20 -> 33206.837 | M22: =CPUE!J20 -> 12.847826 | N22: =Effort!L20 -> 1621.0631 | O22: =Harvest!L20 -> 19052.495 | P22: =CPUE!L20 -> 11.753086 | Q22: =Effort!N20 -> Closed | R22: =Harvest!N20 -> Closed | S22: =CPUE!N20 -> Closed | T22: =+K22+N22 -> 4205.69 | U22: =+L22+O22 -> 52259.332
A23: 42735 | B23: 42735 | C23: -0.4 | D23: 0.83125 | E23: =Effort!F21 -> Closed | F23: =Harvest!F21 -> Closed | G23: =CPUE!F21 -> Closed | H23: =Effort!H21 -> Closed | I23: =Harvest!H21 -> Closed | J23: =CPUE!H21 -> Closed | K23: =Effort!J21 -> 1417.8172 | L23: =Harvest!J21 -> 16361.611 | M23: =CPUE!J21 -> 11.54 | N23: =Effort!L21 -> 849.15931 | O23: =Harvest!L21 -> 7057.4573 | P23: =CPUE!L21 -> 8.3111111 | Q23: =Effort!N21 -> Closed | R23: =Harvest!N21 -> Closed | S23: =CPUE!N21 -> Closed | T23: =+K23+N23 -> 2266.9765 | U23: =+L23+O23 -> 23419.068
A24: Tide Series Totals | K24: =SUM(K22:K23) -> 4002.4441 | L24: =SUM(L22:L23) -> 49568.448 | M24: =+L24/K24 -> 12.384545 | N24: =SUM(N22:N23) -> 2470.2224 | O24: =SUM(O22:O23) -> 26109.952 | P24: =+O24/N24 -> 10.569879 | T24: =SUM(T22:T23) -> 6472.6665 | U24: =SUM(U22:U23) -> 75678.4
A25: 42743 | B25: 42743 | C25: 0.4 | D25: 0.63263889 | E25: =Effort!F23 -> Closed | F25: =Harvest!F23 -> Closed | G25: =CPUE!F23 -> Closed | H25: =Effort!H23 -> Closed | I25: =Harvest!H23 -> Closed | J25: =CPUE!H23 -> Closed | K25: =Effort!J23 -> Closed | L25: =Harvest!J23 -> Closed | M25: =CPUE!J23 -> Closed | N25: =Effort!L23 -> Closed | O25: =Harvest!L23 -> Closed | P25: =CPUE!L23 -> Closed | Q25: =Effort!N23 -> 424.70811 | R25: =Harvest!N23 -> 55.977518 | S25: =CPUE!N23 -> 0.13180233 | T25: =+Q25 -> 424.70811 | U25: =+R25 -> 55.977518
A26: 42744 | B26: 42744 | C26: -0.4 | D26: 0.67222222 | E26: =Effort!F24 -> Closed | F26: =Harvest!F24 -> Closed | G26: =CPUE!F24 -> Closed | H26: =Effort!H24 -> Closed | I26: =Harvest!H24 -> Closed | J26: =CPUE!H24 -> Closed | K26: =Effort!J24 -> Closed | L26: =Harvest!J24 -> Closed | M26: =CPUE!J24 -> Closed | N26: =Effort!L24 -> Closed | O26: =Harvest!L24 -> Closed | P26: =CPUE!L24 -> Closed | Q26: =Effort!N24 -> 212.72727 | R26: =Harvest!N24 -> 1354.0909 | S26: =CPUE!N24 -> 6.3653846 | T26: =+Q26 -> 212.72727 | U26: =+R26 -> 1354.0909
A27: Tide Series Totals | Q27: =SUM(Q25:Q26) -> 637.43538 | R27: =SUM(R25:R26) -> 1410.0684 | S27: =+R27/Q27 -> 2.2120963 | T27: =SUM(T25:T26) -> 637.43538 | U27: =SUM(U25:U26) -> 1410.0684
A28: 42748 | B28: 42748 | C28: -1.4 | D28: 0.80347222 | E28: =Effort!F26 -> Closed | F28: =Harvest!F26 -> Closed | G28: =CPUE!F26 -> Closed | H28: =Effort!H26 -> Closed | I28: =Harvest!H26 -> Closed | J28: =CPUE!H26 -> Closed | K28: =Effort!J26 -> 1360.4547 | L28: =Harvest!J26 -> 19953.336 | M28: =CPUE!J26 -> 14.666667 | N28: =Effort!L26 -> 528.84133 | O28: =Harvest!L26 -> 7541.2774 | P28: =CPUE!L26 -> 14.26 | Q28: =Effort!N26 -> Closed | R28: =Harvest!N26 -> Closed | S28: =CPUE!N26 -> Closed | T28: =+K28+N28 -> 1889.296 | U28: =+L28+O28 -> 27494.613
A29: 42749 | B29: 42749 | C29: -1 | D29: 0.83263889 | E29: =Effort!F27 -> Closed | F29: =Harvest!F27 -> Closed | G29: =CPUE!F27 -> Closed | H29: =Effort!H27 -> Closed | I29: =Harvest!H27 -> Closed | J29: =CPUE!H27 -> Closed | K29: =Effort!J27 -> 2076.159 | L29: =Harvest!J27 -> 29519.205 | M29: =CPUE!J27 -> 14.218182 | N29: =Effort!L27 -> 1249.2064 | O29: =Harvest!L27 -> 11707.679 | P29: =CPUE!L27 -> 9.372093 | Q29: =Effort!N27 -> Closed | R29: =Harvest!N27 -> Closed | S29: =CPUE!N27 -> Closed | T29: =+K29+N29 -> 3325.3654 | U29: =+L29+O29 -> 41226.884 | TJ29: +
A30: 42750 | B30: 42750 | C30: -0.4 | D30: 0.86111111 | E30: =Effort!F28 -> Closed | F30: =Harvest!F28 -> Closed | G30: =CPUE!F28 -> Closed | H30: =Effort!H28 -> Closed | I30: =Harvest!H28 -> Closed | J30: =CPUE!H28 -> Closed | K30: =Effort!J28 -> 827.08032 | L30: =Harvest!J28 -> 10379.858 | M30: =CPUE!J28 -> 12.55 | N30: =Effort!L28 -> 789.73839 | O30: =Harvest!L28 -> 6457.2727 | P30: =CPUE!L28 -> 8.1764706 | Q30: =Effort!N28 -> Closed | R30: =Harvest!N28 -> Closed | S30: =CPUE!N28 -> Closed | T30: =+K30+N30 -> 1616.8187 | U30: =+L30+O30 -> 16837.131
A31: Tide Series Totals | K31: =SUM(K28:K30) -> 4263.694 | L31: =SUM(L28:L30) -> 59852.399 | M31: =+L31/K31 -> 14.037686 | N31: =SUM(N28:N30) -> 2567.7861 | O31: =SUM(O28:O30) -> 25706.229 | P31: =+O31/N31 -> 10.011047 | T31: =SUM(T28:T30) -> 6831.4801 | U31: =SUM(U28:U30) -> 85558.628
A32: 42762 | B32: 42762 | C32: -0.5 | D32: 0.76805556 | E32: =Effort!F30 -> Closed | F32: =Harvest!F30 -> Closed | G32: =CPUE!F30 -> Closed | H32: =Effort!H30 -> Closed | I32: =Harvest!H30 -> Closed | J32: =CPUE!H30 -> Closed | K32: =Effort!J30 -> 3378.4057 | L32: =Harvest!J30 -> 41084.52 | M32: =CPUE!J30 -> 12.16092 | N32: =Effort!L30 -> Closed | O32: =Harvest!L30 -> Closed | P32: =CPUE!L30 -> Closed | Q32: =Effort!N30 -> Closed | R32: =Harvest!N30 -> Closed | S32: =CPUE!N30 -> Closed | T32: =+K32 -> 3378.4057 | U32: =+L32 -> 41084.52
A33: 42763 | B33: 42763 | C33: -0.6 | D33: 0.79236111 | E33: =Effort!F31 -> Closed | F33: =Harvest!F31 -> Closed | G33: =CPUE!F31 -> Closed | H33: =Effort!H31 -> Closed | I33: =Harvest!H31 -> Closed | J33: =CPUE!H31 -> Closed | K33: =Effort!J31 -> 5779.776 | L33: =Harvest!J31 -> 60122.957 | M33: =CPUE!J31 -> 10.402299 | N33: =Effort!L31 -> Closed | O33: =Harvest!L31 -> Closed | P33: =CPUE!L31 -> Closed | Q33: =Effort!N31 -> Closed | R33: =Harvest!N31 -> Closed | S33: =CPUE!N31 -> Closed | T33: =+K33 -> 5779.776 | U33: =+L33 -> 60122.957
A34: 42764 | B34: 42764 | C34: -0.5 | D34: 0.81736111 | E34: =Effort!F32 -> Closed | F34: =Harvest!F32 -> Closed | G34: =CPUE!F32 -> Closed | H34: =Effort!H32 -> Closed | I34: =Harvest!H32 -> Closed | J34: =CPUE!H32 -> Closed | K34: =Effort!J32 -> 528.97987 | L34: =Harvest!J32 -> 7517.0823 | M34: =CPUE!J32 -> 14.210526 | N34: =Effort!L32 -> 476.5855 | O34: =Harvest!L32 -> 7038.8012 | P34: =CPUE!L32 -> 14.769231 | Q34: =Effort!N32 -> Closed | R34: =Harvest!N32 -> Closed | S34: =CPUE!N32 -> Closed | T34: =+K34+N34 -> 1005.5654 | U34: =+L34+O34 -> 14555.883
A35: 42765 | B35: 42765 | C35: -0.3 | D35: 0.84236111 | E35: =Effort!F33 -> Closed | F35: =Harvest!F33 -> Closed | G35: =CPUE!F33 -> Closed | H35: =Effort!H33 -> Closed | I35: =Harvest!H33 -> Closed | J35: =CPUE!H33 -> Closed | K35: =Effort!J33 -> 448.87918 | L35: =Harvest!J33 -> 6733.1876 | M35: =CPUE!J33 -> 15 | N35: =Effort!L33 -> 271.73718 | O35: =Harvest!L33 -> 3902.1458 | P35: =CPUE!L33 -> 14.36 | Q35: =Effort!N33 -> Closed | R35: =Harvest!N33 -> Closed | S35: =CPUE!N33 -> Closed | T35: =+K35+N35 -> 720.61635 | U35: =+L35+O35 -> 10635.333
A36: 42766 | B36: =+A36 -> 42766 | C36: 0.2 | D36: 0.86805556 | E36: =Effort!F34 -> Closed | F36: =Harvest!F34 -> Closed | G36: =CPUE!F34 -> Closed | H36: =Effort!H34 -> Closed | I36: =Harvest!H34 -> Closed | J36: =CPUE!H34 -> Closed | K36: =Effort!J34 -> 254.65073 | L36: =Harvest!J34 -> 3819.7609 | M36: =CPUE!J34 -> 15 | N36: =Effort!L34 -> 80.102905 | O36: =Harvest!L34 -> 1201.5436 | P36: =CPUE!L34 -> 15 | Q36: =Effort!N34 -> Closed | R36: =Harvest!N34 -> Closed | S36: =CPUE!N34 -> Closed | T36: =+K36+N36 -> 334.75363 | U36: =+L36+O36 -> 5021.3045
A37: Tide Series Totals | K37: =SUM(K32:K36) -> 10390.691 | L37: =SUM(L32:L36) -> 119277.51 | M37: =+L37/K37 -> 11.479266 | N37: =SUM(N34:N36) -> 828.42558 | O37: =SUM(O34:O36) -> 12142.491 | P37: =+O37/N37 -> 14.65731 | T37: =SUM(T32:T36) -> 11219.117 | U37: =SUM(U32:U36) -> 131420
A38: 42773 | B38: 42773 | C38: -0.1 | D38: 0.66180556 | E38: =Effort!F36 -> Closed | F38: =Harvest!F36 -> Closed | G38: =CPUE!F36 -> Closed | H38: =Effort!H36 -> 734.50074 | I38: =Harvest!H36 -> 10833.886 | J38: =CPUE!H36 -> 14.75 | K38: =Effort!J36 -> 760.1388 | L38: =Harvest!J36 -> 11402.082 | M38: =CPUE!J36 -> 15 | N38: =Effort!L36 -> 537.04028 | O38: =Harvest!L36 -> 7811.4949 | P38: =CPUE!L36 -> 14.545455 | Q38: =Effort!N36 -> Closed | R38: =Harvest!N36 -> Closed | S38: =CPUE!N36 -> Closed | T38: =+H38+K38+N38 -> 2031.6798 | U38: =+I38+L38+O38 -> 30047.463
A39: 42774 | B39: 42774 | C39: -0.6 | D39: 0.69861111 | E39: =Effort!F37 -> Closed | F39: =Harvest!F37 -> Closed | G39: =CPUE!F37 -> Closed | H39: =Effort!H37 -> 581.59425 | I39: =Harvest!H37 -> 8621.2794 | J39: =CPUE!H37 -> 14.823529 | K39: =Effort!J37 -> 552.54403 | L39: =Harvest!J37 -> 7546.1728 | M39: =CPUE!J37 -> 13.657143 | N39: =Effort!L37 -> 458.04235 | O39: =Harvest!L37 -> 6552.5503 | P39: =CPUE!L37 -> 14.305556 | Q39: =Effort!N37 -> Closed | R39: =Harvest!N37 -> Closed | S39: =CPUE!N37 -> Closed | T39: =+H39+K39+N39 -> 1592.1806 | U39: =+I39+L39+O39 -> 22720.002
A40: 42775 | B40: 42775 | C40: -0.9 | D40: 0.73125 | E40: =Effort!F38 -> Closed | F40: =Harvest!F38 -> Closed | G40: =CPUE!F38 -> Closed | H40: =Effort!H38 -> 599.1023 | I40: =Harvest!H38 -> 5333.4717 | J40: =CPUE!H38 -> 8.902439 | K40: =Effort!J38 -> 688.09491 | L40: =Harvest!J38 -> 4994.2372 | M40: =CPUE!J38 -> 7.2580645 | N40: =Effort!L38 -> 549.78152 | O40: =Harvest!L38 -> 978.87929 | P40: =CPUE!L38 -> 1.7804878 | Q40: =Effort!N38 -> Closed | R40: =Harvest!N38 -> Closed | S40: =CPUE!N38 -> Closed | T40: =+H40+K40+N40 -> 1836.9787 | U40: =+I40+L40+O40 -> 11306.588
...

Sheet Copy Sheet
A1: BeachName | B1: Date | C1: Effort | D1: Harvest | E1: CPUE | F1: EventID | G1: CorrectionFactor
A2: Copalis | B2: 42659 | C2: 307.45388 | D2: 3931.0174 | E2: 12.785714 | F2: 1329 | G2: 0.50356668
A3: Mocrocks | B3: 42659 | C3: 296.48478 | D3: 3976.3841 | E3: 13.411765 | F3: 1328 | G3: 0.56326669
A4: Twin Harbors | B4: 42659 | C4: 554.15388 | D4: 5239.273 | E4: 9.4545455 | F4: 1330 | G4: 0.53109998
A5: Twin Harbors | B5: 42660 | C5: 1012.021 | D5: 14382.965 | E5: 14.212121 | F5: 1331 | G5: 0.38405001
A6: Twin Harbors | B6: 42661 | C6: 677.8631 | D6: 9038.1747 | E6: 13.333333 | F6: 1332 | G6: 0.38405001
A7: Twin Harbors | B7: 42662 | C7: 159.4299 | D7: 2391.4485 | E7: 15 | F7: 1333 | G7: 0.43099999
A9: BeachName | B9: Date | C9: Effort | D9: Harvest | E9: CPUE | F9: EventID | G9: CorrectionFactor
A10: Copalis | B10: 42691 | C10: 698.17739 | D10: 10315.008 | E10: 14.774194 | F10: 1334 | G10: 0.47889999
A11: Copalis | B11: 42692 | C11: 908.09801 | D11: 10774.46 | E11: 11.864865 | F11: 1339 | G11: 0.46496665
A12: Copalis | B12: 42693 | C12: 654.82053 | D12: 261.92821 | E12: 0.4 | F12: 1340 | G12: 0.51429999
A13: Mocrocks | B13: 42691 | C13: 546.07475 | D13: 7736.059 | E13: 14.166667 | F13: 1335 | G13: 0.55113333
A14: Mocrocks | B14: 42692 | C14: 842.59275 | D14: 6406.8845 | E14: 7.6037736 | F14: 1337 | G14: 0.55113333
A15: Mocrocks | B15: 42693 | C15: 595.46802 | D15: 159.50036 | E15: 0.26785714 | F15: 1342 | G15: 0.55075002
A16: Twin Harbors | B16: 42691 | C16: 809.65455 | D16: 10852.816 | E16: 13.404255 | F16: 1336 | G16: 0.52824998
A17: Twin Harbors | B17: 42692 | C17: 895.90365 | D17: 12110.146 | E17: 13.517241 | F17: 1338 | G17: 0.51243335
A18: Twin Harbors | B18: 42693 | C18: 416.48499 | D18: 252.86589 | E18: 0.60714286 | F18: 1341 | G18: 0.47396666
A20: BeachName | B20: Date | C20: Effort | D20: Harvest | E20: CPUE | F20: EventID | G20: CorrectionFactor
A21: Twin Harbors | B21: 42700 | C21: 4386.0819 | D21: 34508.144 | E21: 7.8676471 | F21: 1343 | G21: 0.439475
A22: Twin Harbors | B22: 42701 | C22: 455.99199 | D22: 3289.6565 | E22: 7.2142857 | F22: 1344 | G22: 0.47396666
A24: BeachName | B24: Date | C24: Effort | D24: Harvest | E24: CPUE | F24: EventID | G24: CorrectionFactor
A25: Copalis | B25: 42714 | C25: 1730.2545 | D25: 16813.56 | E25: 9.7173913 | F25: 1345 | G25: 0.46496665
A26: Copalis | B26: 42715 | C26: 961.85558 | D26: 14427.834 | E26: 15 | F26: 1347 | G26: 0.46496665
A27: Mocrocks | B27: 42714 | C27: 1897.7294 | D27: 22186.181 | E27: 11.690909 | F27: 1346 | G27: 0.56365001
A28: Mocrocks | B28: 42715 | C28: 924.39921 | D28: 13865.988 | E28: 15 | F28: 1348 | G28: 0.57010001
A30: BeachName | B30: Date | C30: Effort | D30: Harvest | E30: CPUE | F30: EventID | G30: CorrectionFactor
A31: Copalis | B31: 42734 | C31: 2584.6269 | D31: 33206.837 | E31: 12.847826 | F31: 1349 | G31: 0.47889999
A32: Copalis | B32: 42735 | C32: 1417.8172 | D32: 16361.611 | E32: 11.54 | F32: 1350 | G32: 0.50356668
A33: Mocrocks | B33: 42734 | C33: 1621.0631 | D33: 19052.495 | E33: 11.753086 | F33: 1351 | G33: 0.55113333
A34: Mocrocks | B34: 42735 | C34: 849.15931 | D34: 7057.4573 | E34: 8.3111111 | F34: 1352 | G34: 0.55113333
A36: BeachName | B36: Date | C36: Effort | D36: Harvest | E36: CPUE | F36: EventID | G36: CorrectionFactor
A37: Kalaloch | B37: 42743 | C37: 419.41622 | D37: 43.545946 | E37: 0.10382514 | F37: 1353 | G37: 1
A38: Kalaloch | B38: 42743 | C38: 430 | D38: 68.409091 | E38: 0.15909091 | F38: 1355 | G38: 1
C39: =AVERAGE(C37:C38) -> 424.70811 | D39: =AVERAGE(D37:D38) -> 55.977518 | E39: =+D39/C39 -> 0.13180233
A40: Kalaloch | B40: 42744 | C40: 212.72727 | D40: 1354.0909 | E40: 6.3653846 | F40: 1354 | G40: 1
A42: BeachName | B42: Date | C42: Effort | D42: Harvest | E42: CPUE | F42: EventID | G42: CorrectionFactor
A43: Copalis | B43: 42748 | C43: 1360.4547 | D43: 19953.336 | E43: 14.666667 | F43: 1356 | G43: 0.47889999
A44: Copalis | B44: 42749 | C44: 2076.159 | D44: 29519.205 | E44: 14.218182 | F44: 1357 | G44: 0.50333333
A45: Copalis | B45: 42750 | C45: 827.08032 | D45: 10379.858 | E45: 12.55 | F45: 1358 | G45: 0.495
A46: Mocrocks | B46: 42748 | C46: 528.84133 | D46: 7541.2774 | E46: 14.26 | F46: 1359 | G46: 0.53785002
...

Sheet Tide Info
A1: TideDate | B1: TideDate | C1: TideHeight | D1: TideTime | E1: Sunrise | F1: Sunset

Sheet Tribal update
A1: 2016-2017 State (non-Indian) Recreational Razor Clam Effort, Harvest and CPUE totals.
E2: COPALIS | I2: MOCROCKS | M2: KALALOCH | Q2: DAILY TOTALS
A3: DATE | B3: DAY | C3: TIDE | D3: TIME | E3: Effort | F3: Harvest | G3: CPUE | H3: Size (mm) | I3: Effort | J3: Harvest | K3: CPUE | L3: Size (mm) | M3: Effort | N3: Harvest | O3: CPUE | P3: Size (mm) | Q3: Effort | R3: Harvest
A4: 42659 | B4: 42659 | C4: -1.1 | D4: 0.81111111 | E4: 307.45388 | F4: 3931.0174 | G4: 12.785714 | I4: 296.48478 | J4: 3976.3841 | K4: 13.411765 | M4: CLOSED | N4: CLOSED | O4: CLOSED | Q4: =+E4+I4 -> 603.93865 | R4: =+F4+J4 -> 7907.4015
A5: Tide Series Totals | E5: =SUM(E4) -> 307.45388 | F5: =SUM(F4) -> 3931.0174 | G5: =+F5/E5 -> 12.785714 | I5: =SUM(I4) -> 296.48478 | J5: =SUM(J4) -> 3976.3841 | K5: =+J5/I5 -> 13.411765 | Q5: =SUM(Q4) -> 603.93865 | R5: =SUM(R4) -> 7907.4015
A6: 42691 | B6: 42691 | C6: -1.3 | D6: 0.85902778 | E6: 698.17739 | F6: 10315.008 | G6: 14.774194 | I6: 546.07475 | J6: 7736.059 | K6: 14.166667 | M6: CLOSED | N6: CLOSED | O6: CLOSED | Q6: =+E6+I6 -> 1244.2521 | R6: =+F6+J6 -> 18051.067
A7: 42692 | B7: 42692 | C7: -0.8 | D7: 0.89444444 | E7: 908.09801 | F7: 10774.46 | G7: 11.864865 | I7: 842.59275 | J7: 6406.8845 | K7: 7.6037736 | M7: CLOSED | N7: CLOSED | O7: CLOSED | Q7: =+E7+I7 -> 1750.6908 | R7: =+F7+J7 -> 17181.345
A8: 42693 | B8: 42693 | C8: -0.1 | D8: 0.93194444 | E8: 654.82053 | F8: 261.92821 | G8: 0.4 | I8: 595.46802 | J8: 159.50036 | K8: 0.26785714 | M8: CLOSED | N8: CLOSED | O8: CLOSED | Q8: =+E8+I8 -> 1250.2886 | R8: =+F8+J8 -> 421.42858
A9: Tide Series Totals | E9: =SUM(E6:E8) -> 2261.0959 | F9: =SUM(F6:F8) -> 21351.396 | G9: =+F9/E9 -> 9.4429413 | I9: =SUM(I6:I8) -> 1984.1355 | J9: =SUM(J6:J8) -> 14302.444 | K9: =+J9/I9 -> 7.2084007 | Q9: =SUM(Q6:Q8) -> 4245.2315 | R9: =SUM(R6:R8) -> 35653.84
A10: 42714 | B10: 42714 | C10: 0.5 | D10: 0.64444444 | E10: 1730.2545 | F10: 16813.56 | G10: 9.7173913 | I10: 1897.7294 | J10: 22186.181 | K10: 11.690909 | M10: CLOSED | N10: CLOSED | O10: CLOSED | Q10: =+E10+I10 -> 3627.9838 | R10: =+F10+J10 -> 38999.741
A11: 42715 | B11: 42715 | C11: -0.5 | D11: 0.68125 | E11: 961.85558 | F11: 14427.834 | G11: 15 | I11: 924.39921 | J11: 13865.988 | K11: 15 | M11: CLOSED | N11: CLOSED | O11: CLOSED | Q11: =+E11+I11 -> 1886.2548 | R11: =+F11+J11 -> 28293.822
A12: Tide Series Totals | E12: =SUM(E10:E11) -> 2692.1101 | F12: =SUM(F10:F11) -> 31241.393 | G12: =+F12/E12 -> 11.604798 | I12: =SUM(I10:I11) -> 2822.1286 | J12: =SUM(J10:J11) -> 36052.17 | K12: =+J12/I12 -> 12.774815 | Q12: =SUM(Q10:Q11) -> 5514.2386 | R12: =SUM(R10:R11) -> 67293.563
A13: 42734 | B13: 42734 | C13: -0.4 | D13: 0.80694444 | E13: 2584.6269 | F13: 33206.837 | G13: 12.847826 | I13: 1621.0631 | J13: 19052.495 | K13: 11.753086 | M13: CLOSED | N13: CLOSED | O13: CLOSED | Q13: =+E13+I13 -> 4205.69 | R13: =+F13+J13 -> 52259.332
A14: 42735 | B14: 42735 | C14: -0.4 | D14: 0.83125 | E14: 1417.8172 | F14: 16361.611 | G14: 11.54 | I14: 849.15931 | J14: 7057.4573 | K14: 8.3111111 | M14: CLOSED | N14: CLOSED | O14: CLOSED | Q14: =+E14+I14 -> 2266.9765 | R14: =+F14+J14 -> 23419.068
A15: Tide Series Totals | E15: =SUM(E13:E14) -> 4002.4441 | F15: =SUM(F13:F14) -> 49568.448 | G15: =+F15/E15 -> 12.384545 | I15: =SUM(I13:I14) -> 2470.2224 | J15: =SUM(J13:J14) -> 26109.952 | K15: =+J15/I15 -> 10.569879 | Q15: =SUM(Q13:Q14) -> 6472.6665 | R15: =SUM(R13:R14) -> 75678.4
A16: 42743 | B16: 42743 | C16: 0.4 | D16: 0.63263889 | E16: CLOSED | F16: CLOSED | G16: CLOSED | I16: CLOSED | J16: CLOSED | K16: CLOSED | M16: 424.70811 | N16: 55.977518 | O16: 0.13180233 | Q16: =+M16 -> 424.70811 | R16: =+N16 -> 55.977518
A17: 42744 | B17: 42744 | C17: -0.4 | D17: 0.67222222 | E17: CLOSED | F17: CLOSED | G17: CLOSED | I17: CLOSED | J17: CLOSED | K17: CLOSED | M17: 212.72727 | N17: 1354.0909 | O17: 6.3653846 | Q17: =+M17 -> 212.72727 | R17: =+N17 -> 1354.0909
A18: Tide Series Totals | M18: =SUM(M16:M17) -> 637.43538 | N18: =SUM(N16:N17) -> 1410.0684 | O18: =+N18/M18 -> 2.2120963 | Q18: =SUM(Q16:Q17) -> 637.43538 | R18: =SUM(R16:R17) -> 1410.0684
A19: 42748 | B19: 42748 | C19: -1.4 | D19: 0.80347222 | E19: 1360.4547 | F19: 19953.336 | G19: 14.666667 | I19: 528.84133 | J19: 7541.2774 | K19: 14.26 | M19: CLOSED | N19: CLOSED | O19: CLOSED | Q19: =+E19+I19 -> 1889.296 | R19: =+F19+J19 -> 27494.613
A20: 42749 | B20: 42749 | C20: -1 | D20: 0.83263889 | E20: 2076.159 | F20: 29519.205 | G20: 14.218182 | I20: 1249.2064 | J20: 11707.679 | K20: 9.372093 | M20: CLOSED | N20: CLOSED | O20: CLOSED | Q20: =+E20+I20 -> 3325.3654 | R20: =+F20+J20 -> 41226.884
A21: 42750 | B21: 42750 | C21: -0.4 | D21: 0.86111111 | E21: 827.08032 | F21: 10379.858 | G21: 12.55 | I21: 789.73839 | J21: 6457.2727 | K21: 8.1764706 | M21: CLOSED | N21: CLOSED | O21: CLOSED | Q21: =+E21+I21 -> 1616.8187 | R21: =+F21+J21 -> 16837.131
A22: Tide Series Totals | E22: =SUM(E19:E21) -> 4263.694 | F22: =SUM(F19:F21) -> 59852.399 | G22: =+F22/E22 -> 14.037686 | I22: =SUM(I19:I21) -> 2567.7861 | J22: =SUM(J19:J21) -> 25706.229 | K22: =+J22/I22 -> 10.011047 | Q22: =SUM(Q19:Q21) -> 6831.4801 | R22: =SUM(R19:R21) -> 85558.628
A23: 42762 | B23: 42762 | C23: -0.5 | D23: 0.76805556 | E23: 3378.4057 | F23: 41084.52 | G23: 12.16092 | I23: Closed | J23: Closed | K23: Closed | M23: CLOSED | N23: CLOSED | O23: CLOSED | Q23: =+E23 -> 3378.4057 | R23: =+F23 -> 41084.52
A24: 42763 | B24: 42763 | C24: -0.6 | D24: 0.79236111 | E24: 5779.776 | F24: 60122.957 | G24: 10.402299 | I24: Closed | J24: Closed | K24: Closed | M24: CLOSED | N24: CLOSED | O24: CLOSED | Q24: =+E24 -> 5779.776 | R24: =+F24 -> 60122.957
A25: 42764 | B25: 42764 | C25: -0.5 | D25: 0.81736111 | E25: 528.97987 | F25: 7517.0823 | G25: 14.210526 | I25: 476.5855 | J25: 7038.8012 | K25: 14.769231 | M25: CLOSED | N25: CLOSED | O25: CLOSED | Q25: =+E25+I25 -> 1005.5654 | R25: =+F25+J25 -> 14555.883
A26: 42765 | B26: 42765 | C26: -0.3 | D26: 0.84236111 | E26: 448.87918 | F26: 6733.1876 | G26: 15 | I26: 271.73718 | J26: 3902.1458 | K26: 14.36 | M26: CLOSED | N26: CLOSED | O26: CLOSED | Q26: =+E26+I26 -> 720.61635 | R26: =+F26+J26 -> 10635.333
A27: 42766 | B27: =+A27 -> 42766 | C27: 0.2 | D27: 0.86805556 | E27: 254.65073 | F27: 3819.7609 | G27: 15 | I27: 80.102905 | J27: 1201.5436 | K27: 15 | M27: CLOSED | N27: CLOSED | O27: CLOSED | Q27: =+E27+I27 -> 334.75363 | R27: =+F27+J27 -> 5021.3045
A28: Tide Series Totals | E28: =SUM(E23:E27) -> 10390.691 | F28: =SUM(F23:F27) -> 119277.51 | G28: =+F28/E28 -> 11.479266 | I28: =SUM(I25:I27) -> 828.42558 | J28: =SUM(J25:J27) -> 12142.491 | K28: =+J28/I28 -> 14.65731 | Q28: =SUM(Q23:Q27) -> 11219.117 | R28: =SUM(R23:R27) -> 131420
A29: 42773 | B29: 42773 | C29: -0.1 | D29: 0.66180556 | E29: 760.1388 | F29: 11402.082 | G29: 15 | I29: 537.04028 | J29: 7811.4949 | K29: 14.545455 | M29: Closed | N29: Closed | O29: Closed | Q29: =+E29+I29 -> 1297.1791 | R29: =+F29+J29 -> 19213.577
A30: 42774 | B30: 42774 | C30: -0.6 | D30: 0.69861111 | E30: 552.54403 | F30: 7546.1728 | G30: 13.657143 | I30: 458.04235 | J30: 6552.5503 | K30: 14.305556 | M30: Closed | N30: Closed | O30: Closed | Q30: =+E30+I30 -> 1010.5864 | R30: =+F30+J30 -> 14098.723
A31: 42775 | B31: 42775 | C31: -0.9 | D31: 0.73125 | E31: 688.09491 | F31: 4994.2372 | G31: 7.2580645 | I31: 549.78152 | J31: 978.87929 | K31: 1.7804878 | M31: Closed | N31: Closed | O31: Closed | Q31: =+E31+I31 -> 1237.8764 | R31: =+F31+J31 -> 5973.1165
A32: 42776 | B32: 42776 | C32: -1 | D32: 0.76111111 | E32: Closed | F32: Closed | G32: Closed | I32: 1468.6682 | J32: 11802.752 | K32: 8.0363636 | M32: Closed | N32: Closed | O32: Closed | Q32: =+I32 -> 1468.6682 | R32: =+J32 -> 11802.752
A33: 42777 | B33: 42777 | C33: -0.8 | D33: 0.78958333 | E33: Closed | F33: Closed | G33: Closed | I33: 4451.6084 | J33: 49446.36 | K33: 11.107527 | M33: Closed | N33: Closed | O33: Closed | Q33: =+I33 -> 4451.6084 | R33: =+J33 -> 49446.36
A34: 42778 | B34: 42778 | C34: -0.5 | D34: 0.81527778 | E34: Closed | F34: Closed | G34: Closed | I34: 716.17647 | J34: 6302.3529 | K34: 8.8 | M34: Closed | N34: Closed | O34: Closed | Q34: =+I34 -> 716.17647 | R34: =+J34 -> 6302.3529
A35: Tide Series Totals | E35: =SUM(E29:E34) -> 2000.7777 | F35: =SUM(F29:F34) -> 23942.492 | G35: =+F35/E35 -> 11.966593 | I35: =SUM(I29:I34) -> 8181.3172 | J35: =SUM(J29:J34) -> 82894.389 | K35: =+J35/I35 -> 10.132157 | Q35: =SUM(Q29:Q34) -> 10182.095 | R35: =SUM(R29:R34) -> 106836.88
A36: 42790 | B36: 42790 | C36: -0.1 | D36: 0.72291667 | E36: 2424.5787 | F36: 36368.681 | G36: 15 | I36: 1438.6266 | J36: 21031.351 | K36: 14.619048 | M36: Closed | N36: Closed | O36: Closed | Q36: =+E36+I36 -> 3863.2053 | R36: =+F36+J36 -> 57400.032
A37: 42791 | B37: 42791 | C37: -0.3 | D37: 0.74861111 | E37: 8177.9369 | F37: 108102.1 | G37: 13.21875 | I37: 4819.975 | J37: 66871.304 | K37: 13.873786 | M37: Closed | N37: Closed | O37: Closed | Q37: =+E37+I37 -> 12997.912 | R37: =+F37+J37 -> 174973.41
A38: 42792 | B38: 42792 | C38: -0.4 | D38: 0.77361111 | E38: 1607.6658 | F38: 18158.717 | G38: 11.295082 | I38: 783.21915 | J38: 10016.961 | K38: 12.789474 | M38: Closed | N38: Closed | O38: Closed | Q38: =+E38+I38 -> 2390.885 | R38: =+F38+J38 -> 28175.678
A39: Tide Series Totals | E39: =SUM(E36:E38) -> 12210.181 | F39: =SUM(F36:F38) -> 162629.5 | G39: =+F39/E39 -> 13.319172 | I39: =SUM(I36:I38) -> 7041.8208 | J39: =SUM(J36:J38) -> 97919.615 | K39: =+J39/I39 -> 13.90544 | Q39: =SUM(Q36:Q38) -> 19252.002 | R39: =SUM(R36:R38) -> 260549.12
A40: 42803 | B40: 42803 | C40: -0.1 | D40: 0.68611111 | E40: Closed | F40: Closed | G40: Closed | I40: 571.30106 | J40: 7426.9137 | K40: 13 | M40: Closed | N40: Closed | O40: Closed | Q40: =+I40 -> 571.30106 | R40: =+J40 -> 7426.9137
...

Sheet TAC
A1: NON-TRIBAL TOTAL ALLOWABLE CATCH (TAC)
B3: 2016 - 2017 | C3: 2015 - 2016 | D3: 2014 - 2015 | E3: 2013 - 2014 | F3: 2012 - 2013 | G3: 2011 - 2012 | H3: 2010 - 2011
A4: LONG BEACH | B4: 4895623.6 | C4: 4768605 | D4: 3885491.5 | E4: 2881223.3 | F4: 1847952.1 | G4: 1094641.4 | H4: 1276247.7
A5: TWIN HARBORS | B5: 1896630.9 | C5: 1198600 | D5: 2662860.8 | E5: =5744410.73323314*0.4 -> 2297764.3 | F5: 1881783.2 | G5: 616314.31 | H5: 845427.67
A6: COPALIS | B6: 880571.45 | C6: 1094781 | D6: 889827.43 | E6: =(2615522*0.5)-(161153)+250000 -> 1396608 | F6: 1072689.6 | G6: 371373.04 | H6: 683167.41
A7: MOCROCKS | B7: 941919.24 | C7: 1695074 | D7: 2240308.7 | E7: 2088668.5 | F7: 909667.35 | G7: 605830.7 | H7: 545586.69
A8: KALALOCH | B8: 725888.21 | C8: 63740 | D8: 125735.13 | E8: =1033285.9456848*0.254*0.5 -> 131227.32 | F8: 113543.21 | G8: 144560.51 | H8: 258924.12
A9: COASTWIDE TAC | B9: =SUM(B4:B8) -> 9340633.4 | C9: =SUM(C4:C8) -> 8820800 | D9: =SUM(D4:D8) -> 9804223.7 | E9: =SUM(E4:E8) -> 8795491.4 | F9: =SUM(F4:F8) -> 5825635.5 | G9: =SUM(G4:G8) -> 2832720 | H9: =SUM(H4:H8) -> 3609353.6

Sheet TH Wastage
A1: EventID | B1: BeachName | C1: Date | D1: LocationID | E1: NHoles | F1: NClams | G1: NMorts
A2: 1391 | B2: Twin Harbors | C2: 42789 | D2: 21200 | E2: 100 | F2: 2 | G2: 2
A3: 1392 | B3: Twin Harbors | C3: 42790 | D3: 21200 | E3: 100 | F3: 6 | G3: 6
A4: 1408 | B4: Twin Harbors | C4: 42807 | D4: 21200 | E4: 100 | F4: 5 | G4: 5
A5: 1426 | B5: Twin Harbors | C5: 42838 | D5: 21200 | E5: 100 | F5: 3 | G5: 3
A6: 1428 | B6: Twin Harbors | C6: 42840 | D6: 21200 | E6: 100 | F6: 2 | G6: 2
A7: 1442 | B7: Twin Harbors | C7: 42851 | D7: 21200 | E7: 100 | F7: 5 | G7: 5
A8: 1442 | B8: Twin Harbors | C8: 42851 | D8: 22309 | E8: 100 | F8: 2 | G8: 2
A9: 1443 | B9: Twin Harbors | C9: 42852 | D9: 22309 | E9: 100 | F9: 2 | G9: 2
A10: 1444 | B10: Twin Harbors | C10: 42853 | D10: 21200 | E10: 100 | F10: 11 | G10: 11
A11: 1444 | B11: Twin Harbors | C11: 42853 | D11: 22307 | E11: 100 | F11: 2 | G11: 2
E40: =SUM(E2:E39) -> 1000 | F40: =SUM(F2:F39) -> 40 | G40: =SUM(G2:G39) -> 40 | H40: =+G40/E40 -> 0.04

Sheet LB Wastage
A1: EventID | B1: BeachName | C1: Date | D1: LocationID | E1: NHoles | F1: NClams | G1: NMorts
A2: 1439 | B2: LongBeach | C2: 42853 | D2: 12500 | E2: 100 | F2: 3 | G2: 3
E100: =SUM(E2:E99) -> 100 | F100: =SUM(F2:F99) -> 3 | G100: =SUM(G2:G99) -> 3 | H100: =+G100/E100 -> 0.03

Sheet Cop Wastage
A1: EventID | B1: BeachName | C1: Date | D1: LocationID | E1: NHoles | F1: NClams | G1: NMorts
A2: 1386 | B2: Copalis | C2: 42791 | D2: 32009 | E2: 93 | F2: 1 | G2: 1
A3: 1413 | B3: Copalis | C3: 42825 | D3: 32009 | E3: 100 | F3: 5 | G3: 5
A4: 1424 | B4: Copalis | C4: 42840 | D4: 31005 | E4: 100 | F4: 3 | G4: 3
A5: 1435 | B5: Copalis | C5: 42853 | D5: 33012 | E5: 100 | F5: 6 | G5: 6
A6: 1435 | B6: Copalis | C6: 42853 | D6: 32009 | E6: 100 | F6: 13 | G6: 13
A7: 1437 | B7: Copalis | C7: 42855 | D7: 31005 | E7: 100 | F7: 3 | G7: 3
E40: =SUM(E2:E39) -> 593 | F40: =SUM(F2:F39) -> 31 | G40: =SUM(G2:G39) -> 31 | H40: =+G40/E40 -> 0.05227656
E100: =SUM(E2:E99) -> 1186 | F100: =SUM(F2:F99) -> 62 | G100: =SUM(G2:G99) -> 62 | H100: =+G100/E100 -> 0.05227656

Sheet Moc Wastage
A1: EventID | B1: BeachName | C1: Date | D1: LocationID | E1: NHoles | F1: NClams | G1: NMorts
A2: 1372 | B2: Mocrocks | C2: 42773 | D2: 41400 | E2: 100 | F2: 0 | G2: 0
A3: 1388 | B3: Mocrocks | C3: 42790 | D3: 42600 | E3: 100 | F3: 4 | G3: 4
A4: 1434 | B4: Mocrocks | C4: 42852 | D4: 42600 | E4: 100 | F4: 2 | G4: 2
A5: 1434 | B5: Mocrocks | C5: 42852 | D5: 41400 | E5: 100 | F5: 5 | G5: 5
A6: 1436 | B6: Mocrocks | C6: 42854 | D6: 41300 | E6: 100 | F6: 4 | G6: 4
A7: 1436 | B7: Mocrocks | C7: 42854 | D7: 41400 | E7: 100 | F7: 2 | G7: 2
E40: =SUM(E2:E39) -> 600 | F40: =SUM(F2:F39) -> 17 | G40: =SUM(G2:G39) -> 17 | H40: =+G40/E40 -> 0.028333333
E100: =SUM(E2:E99) -> 1200 | F100: =SUM(F2:F99) -> 34 | G100: =SUM(G2:G99) -> 34 | H100: =+G100/E100 -> 0.028333333

Sheet Summary By Month
A1: 2016-2017 State (non-Indian) Recreational Razor Clam Effort, Harvest and CPUE totals by month.
B2: LONG BEACH | F2: TWIN HARBORS | J2: COPALIS | N2: MOCROCKS | R2: KALALOCH | V2: DAILY TOTALS
A3: MONTH | B3: Effort | C3: Harvest | D3: CPUE | E3: DAYS | F3: Effort | G3: Harvest | H3: CPUE | I3: DAYS | J3: Effort | K3: Harvest | L3: CPUE | M3: DAYS | N3: Effort | O3: Harvest | P3: CPUE | Q3: DAYS | R3: Effort | S3: Harvest | T3: CPUE | U3: DAYS | V3: Effort | W3: Harvest
A4: OCTOBER | B4: Closed | E4: 0 | F4: 2403.4679 | G4: 31051.861 | H4: 12.919607 | I4: 6 | J4: 307.45388 | K4: 3931.0174 | L4: 12.785714 | M4: 3 | N4: 296.48478 | O4: 3976.3841 | P4: 13.411765 | Q4: 3 | R4: Closed | U4: 0 | V4: =F4+J4+N4 -> 3007.4065 | W4: =G4+K4+O4 -> 38959.263
A5: NOVEMBER | B5: Closed | E5: 0 | F5: 7424.1171 | G5: 64313.629 | H5: 8.6627983 | I5: 6 | J5: 2261.0959 | K5: 21351.396 | L5: 9.4429413 | M5: 3 | N5: 1984.1355 | O5: 14302.444 | P5: 7.2084007 | Q5: 3 | R5: Closed | U5: 0 | V5: =F5+J5+N5 -> 11669.349 | W5: 99967.469
A6: DECEMBER | B6: Closed | E6: 0 | F6: Closed | I6: 0 | J6: 6694.5542 | K6: 80809.841 | L6: 12.070982 | M6: 4 | N6: 5292.351 | O6: 62162.122 | P6: 11.745654 | Q6: 4 | R6: Closed | U6: 0 | V6: =J6+N6 -> 11986.905 | W6: =K6+O6 -> 142971.96
A7: JANUARY | B7: Closed | E7: 0 | F7: Closed | I7: 0 | J7: 14654.385 | K7: 179129.91 | L7: 12.223638 | M7: 8 | N7: 3396.2117 | O7: 37848.719 | P7: 11.144393 | Q7: 6 | R7: 637.43538 | S7: 1410.0684 | T7: 2.2120963 | U7: 2 | V7: =J7+N7+R7 -> 18688.033 | W7: =K7+O7+S7 -> 218388.7
A8: FEBRUARY | B8: Closed | E8: 0 | F8: 19954.231 | G8: 269189.33 | H8: 13.490339 | I8: 12 | J8: 14210.959 | K8: 186571.99 | L8: 13.12874 | M8: 6 | N8: 15223.138 | O8: 180814 | P8: 11.877578 | Q8: 9 | R8: Closed | U8: 0 | V8: =F8+J8+N8 -> 49388.328 | W8: =G8+K8+O8 -> 636575.33
A9: MARCH | B9: Closed | E9: 0 | F9: 10075.572 | G9: 144024.18 | H9: 14.294393 | I9: 7 | J9: 16698.813 | K9: 194492.97 | L9: 11.647113 | M9: 4 | N9: 7428.8473 | O9: 46012.958 | P9: 6.1938221 | Q9: 5 | R9: Closed | U9: 0 | V9: =F9+J9+N9 -> 34203.232 | W9: =G9+K9+O9 -> 384530.11
A10: APRIL | B10: 71278.286 | C10: 1392613.4 | D10: 19.537695 | E10: 10 | F10: 23036 | G10: 325507.35 | H10: 14.130572 | I10: 15 | J10: 27280.71 | K10: 373906.05 | L10: 14.496805 | M10: 5 | N10: 24336.452 | O10: 341511.45 | P10: 13.89891 | Q10: 5 | R10: Closed | V10: 145931.13 | W10: =C10+G10+K10+O10 -> 2433538.3
A11: MAY | B11: 6500 | C11: 162500 | D11: 25 | E11: 1 | I11: 0 | M11: 0 | Q11: 0 | R11: Closed | U11: 0 | V11: =B11 -> 6500 | W11: =C11 -> 162500
A12: SEASON SUBTOTALS: | B12: =SUM(B4:B11) -> 77778.286 | C12: =SUM(C10:C11) -> 1555113.4 | D12: =C12/B12 -> 19.994185 | E12: =SUM(E4:E11) -> 11 | F12: =SUM(F4:F11) -> 62893.388 | G12: =SUM(G4:G11) -> 834086.36 | H12: =G12/F12 -> 13.261909 | I12: =SUM(I4:I11) -> 46 | J12: =SUM(J4:J11) -> 82107.971 | K12: =SUM(K4:K11) -> 1040193.2 | L12: =K12/J12 -> 12.668602 | M12: =SUM(M4:M11) -> 33 | N12: =SUM(N4:N11) -> 57957.62 | O12: =SUM(O4:O11) -> 686628.09 | P12: =O12/N12 -> 11.847072 | Q12: =SUM(Q4:Q11) -> 35 | R12: =SUM(R4:R11) -> 637.43538 | S12: =S7 -> 1410.0684 | T12: =S12/R12 -> 2.2120963 | U12: =SUM(U4:U11) -> 2 | V12: =B12+F12+J12+N12+R12 -> 281374.7 | W12: =C12+G12+K12+O12+S12 -> 4117431.1 | X12: -60990.197
A13: WASTAGE | C13: 46653.403 | G13: 33363.454 | K13: 54377.721 | O13: 19454.462 | W13: 153849.04
