Workbook

Sheet Harvest
A1: Date | B1: Day | C1: Tide | D1: Time | E1: Longbeach | G1: Twin Harbors | I1: Copalis | K1: Mocrocks | M1: Kalaloch | O1: Daily Totals
A2: 43384 | B2: =+A2 -> 43384 | C2: -0.6 | D2: 0.87361111 | F2: CLOSED | H2: 25850.305 | J2: CLOSED | L2: 18599.554 | N2: CLOSED | O2: =+H2+L2 -> 44449.859 | Q2: =SUM(O2:O9) -> 231563.65
A3: 43385 | B3: =+A3 -> 43385 | C3: -0.3 | D3: 0.90347222 | F3: CLOSED | H3: 16131.648 | J3: 29090.25 | L3: CLOSED | N3: CLOSED | O3: =+H3+J3 -> 45221.898
A4: 43386 | B4: =+A4 -> 43386 | C4: 0.1 | D4: 0.93472222 | F4: CLOSED | H4: 26016.664 | J4: CLOSED | L4: 23316.105 | N4: CLOSED | O4: =+H4+L4 -> 49332.769
A6: 43398 | B6: =+A6 -> 43398 | C6: -0.5 | D6: 0.82986111 | F6: CLOSED | H6: 2060.629 | J6: 10682.551 | L6: CLOSED | N6: CLOSED | O6: =+H6+J6 -> 12743.18
A7: 43399 | B7: =+A7 -> 43399 | C7: -0.7 | D7: 0.85833333 | F7: CLOSED | H7: 22219.796 | J7: CLOSED | L7: 33762.125 | N7: CLOSED | O7: =+H7+L7 -> 55981.921
A8: 43400 | B8: =+A8 -> 43400 | C8: -0.7 | D8: 0.88819444 | F8: CLOSED | H8: 7589.9774 | J8: 10258.666 | L8: CLOSED | N8: CLOSED | O8: =+H8+J8 -> 17848.643
A9: 43401 | B9: =+A9 -> 43401 | C9: -0.6 | D9: 0.92222222 | F9: CLOSED | H9: 2770.0689 | J9: CLOSED | L9: 3215.3112 | N9: CLOSED | O9: =+H9+L9 -> 5985.3801
A11: 43412 | B11: =+A11 -> 43412 | C11: -0.8 | D11: 0.78958333 | F11: CLOSED | H11: 18520.615 | J11: CLOSED | L11: 20767.153 | N11: CLOSED | O11: =+H11+L11 -> 39287.767
A12: 43413 | B12: =+A12 -> 43413 | C12: -0.7 | D12: 0.81666667 | F12: CLOSED | H12: 13082.881 | J12: 28854.588 | L12: CLOSED | N12: CLOSED | O12: =+H12+J12 -> 41937.469
A13: 43414 | B13: =+A13 -> 43414 | C13: -0.4 | D13: 0.84375 | F13: CLOSED | H13: 31626.737 | J13: CLOSED | L13: 31724.956 | N13: CLOSED | O13: =+H13+L13 -> 63351.693
A14: 43415 | B14: =+A14 -> 43415 | C14: 0 | D14: 0.87222222 | F14: CLOSED | G14: * | H14: =+J14*(H12+H8+H6+H3)/(J3+J6+J8+J12) -> 12189.853 | J14: 24742.213 | L14: CLOSED | N14: CLOSED | O14: =+H14+J14 -> 36932.066
A16: 43426 | B16: =+A16 -> 43426 | C16: -0.7 | D16: 0.74652778 | F16: CLOSED | G16: * | H16: =+J16*(H12+H8+H6+H3)/(J3+J6+J8+J12) -> 11448.849 | J16: 23238.168 | L16: CLOSED | N16: CLOSED | O16: =+H16+J16 -> 34687.017
A17: 43427 | B17: =+A17 -> 43427 | C17: -1.1 | D17: 0.775 | F17: CLOSED | H17: 26782.21 | J17: CLOSED | L17: 59634.625 | N17: CLOSED | O17: =+H17+L17 -> 86416.836
A18: 43428 | B18: =+A18 -> 43428 | C18: -1.3 | D18: 0.80555556 | F18: CLOSED | G18: * | H18: =+(J18+L18)*H12/J12 -> 30267.771 | J18: 47122.802 | L18: 19633.448 | N18: CLOSED | O18: =+H18+J18+L18 -> 97024.021
A19: 43429 | B19: =+A19 -> 43429 | C19: -1.3 | D19: 0.83680556 | F19: CLOSED | H19: 4513.5407 | J19: CLOSED | L19: 7321.8112 | N19: CLOSED | O19: =+H19+L19 -> 11835.352
A21: 43440 | B21: =+A21 -> 43440 | C21: -0.7 | D21: 0.75069444 | F21: CLOSED | H21: 9809.2362 | J21: 12790.317 | L21: CLOSED | N21: CLOSED | O21: =+H21+J21 -> 22599.553
A22: 43441 | B22: =+A22 -> 43441 | C22: -0.7 | D22: 0.77777778 | F22: CLOSED | H22: 9522.0081 | J22: CLOSED | L22: 4694.4845 | N22: CLOSED | O22: =+H22+L22 -> 14216.493
A23: 43442 | B23: =+A23 -> 43442 | C23: -0.6 | D23: 0.80277778 | F23: CLOSED | H23: 12936.849 | J23: 21330.225 | L23: CLOSED | N23: CLOSED | O23: =+H23+J23 -> 34267.074
A24: 43443 | B24: =+A24 -> 43443 | C24: -0.4 | D24: 0.82847222 | F24: CLOSED | H24: 762.29931 | J24: CLOSED | L24: 2003.8623 | N24: CLOSED | O24: =+H24+L24 -> 2766.1616
A26: 43454 | B26: =+A26 -> 43454 | C26: -0.3 | D26: 0.70208333 | F26: CLOSED | H26: 1892.803 | J26: CLOSED | L26: 1142.9609 | N26: CLOSED | O26: =+H26+L26 -> 3035.7639
A27: 43455 | B27: =+A27 -> 43455 | C27: -1 | D27: 0.73263889 | F27: CLOSED | H27: 17388.105 | J27: 25219.716 | L27: CLOSED | N27: CLOSED | O27: =+H27+J27 -> 42607.821
A28: 43456 | B28: =+A28 -> 43456 | C28: -1.4 | D28: 0.76388889 | F28: 3998.6841 | H28: 363.89578 | J28: CLOSED | L28: 4055.9884 | N28: CLOSED | O28: =+F28+H28+L28 -> 8418.5682
A29: 43457 | B29: =+A29 -> 43457 | C29: -1.6 | D29: 0.79513889 | F29: CLOSED | H29: 1872.6821 | J29: 7628.5395 | L29: CLOSED | N29: CLOSED | O29: =+H29+J29 -> 9501.2216
A31: 43467 | B31: =+A31 -> 43467 | C31: 0.2 | D31: 0.68194444 | F31: CLOSED | H31: 15541.821 | J31: CLOSED | L31: CLOSED | N31: CLOSED | O31: =+H31 -> 15541.821
A32: 43468 | B32: =+A32 -> 43468 | C32: -0.2 | D32: 0.7125 | F32: CLOSED | H32: 210.56008 | J32: CLOSED | L32: CLOSED | N32: CLOSED | O32: =+H32 -> 210.56008
A33: 43469 | B33: =+A33 -> 43469 | C33: -0.4 | D33: 0.74027778 | F33: CLOSED | H33: 2071.917 | J33: CLOSED | L33: 9123.1457 | N33: CLOSED | O33: =+H33+L33 -> 11195.063
A34: 43470 | B34: =+A34 -> 43470 | C34: -0.4 | D34: 0.76597222 | F34: CLOSED | H34: 445.28936 | J34: 11861.458 | L34: CLOSED | N34: CLOSED | O34: =+H34+J34 -> 12306.748
A35: 43471 | B35: =+A35 -> 43471 | C35: -0.4 | D35: 0.79097222 | F35: CLOSED | H35: 1220.1537 | J35: CLOSED | L35: 1407.4803 | N35: CLOSED | O35: =+H35+L35 -> 2627.634
A37: 43482 | B37: =+A37 -> 43482 | C37: 0.4 | D37: 0.65208333 | F37: CLOSED | H37: 1628.9953 | J37: CLOSED | L37: CLOSED | N37: CLOSED | O37: =+H37 -> 1628.9953
A38: 43483 | B38: =+A38 -> 43483 | C38: -0.4 | D38: 0.6875 | F38: CLOSED | H38: 5347.0335 | J38: CLOSED | L38: CLOSED | N38: CLOSED | O38: =+H38 -> 5347.0335
A39: 43484 | B39: =+A39 -> 43484 | C39: -1.1 | D39: 0.72083333 | F39: CLOSED | H39: 29704.381 | J39: CLOSED | L39: 92345.796 | N39: CLOSED | O39: =+H39+L39 -> 122050.18
A40: 43485 | B40: =+A40 -> 43485 | C40: -1.6 | D40: 0.75347222 | F40: CLOSED | H40: 34202.388 | J40: 77918.622 | L40: CLOSED | N40: CLOSED | O40: =+H40+J40 -> 112121.01
A41: 43486 | B41: =+A41 -> 43486 | C41: -1.8 | D41: 0.78541667 | F41: CLOSED | H41: 19877.82 | J41: CLOSED | L41: 20145.444 | N41: CLOSED | O41: =+H41+L41 -> 40023.264
A43: 43497 | B43: =+A43 -> 43497 | C43: 0.2 | D43: 0.7 | F43: CLOSED | H43: 11808.168 | J43: 17945.537 | L43: CLOSED | N43: CLOSED | O43: =+H43+J43 -> 29753.705
A44: 43498 | B44: =+A44 -> 43498 | C44: 0 | D44: 0.72777778 | F44: CLOSED | H44: 49839.255 | J44: CLOSED | L44: 42861.716 | N44: CLOSED | O44: =+H44+L44 -> 92700.972
A45: 43499 | B45: =+A45 -> 43499 | C45: -0.1 | D45: 0.75277778 | F45: CLOSED | G45: * | H45: =+J45*(H43+H40)/(J43+J40) -> 5037.982 | J45: 10496.763 | L45: CLOSED | N45: CLOSED | O45: =+H45+J45 -> 15534.745
A47: 43511 | B47: =+A47 -> 43511 | C47: 0.4 | D47: 0.63263889 | F47: CLOSED | H47: 4050.8198 | J47: CLOSED | L47: 9445.6821 | N47: CLOSED | O47: =+H47+L47 -> 13496.502
A48: 43512 | B48: =+A48 -> 43512 | C48: -0.3 | D48: 0.67222222 | F48: CLOSED | H48: 20656.269 | J48: 50369.407 | L48: CLOSED | N48: 795.52172 | O48: =+H48+J48+N48 -> 71821.198
A49: 43513 | B49: =+A49 -> 43513 | C49: -1 | D49: 0.70763889 | F49: 110140.54 | G49: * | H49: =+J49*(H48+H43+H40)/(J40+J43+J48) -> 31032.29 | J49: 68069.275 | L49: 38176.283 | N49: 1268.0257 | O49: =+F49+H49+J49+L49+N49 -> 248686.42
...

Sheet Effort
A1: Date | B1: Day | C1: Tide | D1: Time | E1: Longbeach | G1: Twin Harbors | I1: Copalis | K1: Mocrocks | M1: Kalaloch | O1: Daily Totals
A2: 43384 | B2: =+A2 -> 43384 | C2: -0.6 | D2: 0.87361111 | F2: CLOSED | H2: 1852.5577 | J2: CLOSED | L2: 1283.6696 | N2: CLOSED | O2: =+H2+L2 -> 3136.2273 | Q2: =SUM(O2:O9) -> 18435.451
A3: 43385 | B3: =+A3 -> 43385 | C3: -0.3 | D3: 0.90347222 | F3: CLOSED | H3: 1085.784 | J3: 1983.4262 | L3: CLOSED | N3: CLOSED | O3: =+H3+J3 -> 3069.2101
A4: 43386 | B4: =+A4 -> 43386 | C4: 0.1 | D4: 0.93472222 | F4: CLOSED | H4: 1666.4268 | J4: CLOSED | L4: 1673.064 | N4: CLOSED | O4: =+H4+L4 -> 3339.4909
A6: 43398 | B6: =+A6 -> 43398 | C6: -0.5 | D6: 0.82986111 | F6: CLOSED | H6: 632.23844 | J6: 1056.2522 | L6: CLOSED | N6: CLOSED | O6: =+H6+J6 -> 1688.4907
A7: 43399 | B7: =+A7 -> 43399 | C7: -0.7 | D7: 0.85833333 | F7: CLOSED | H7: 2041.5625 | J7: CLOSED | L7: 2233.178 | N7: CLOSED | O7: =+H7+L7 -> 4274.7405
A8: 43400 | B8: =+A8 -> 43400 | C8: -0.7 | D8: 0.88819444 | F8: CLOSED | H8: 670.448 | J8: 1327.3992 | L8: CLOSED | N8: CLOSED | O8: =+H8+J8 -> 1997.8472
A9: 43401 | B9: =+A9 -> 43401 | C9: -0.6 | D9: 0.92222222 | F9: CLOSED | H9: 261.32726 | J9: CLOSED | L9: 668.1166 | N9: CLOSED | O9: =+H9+L9 -> 929.44386
A11: 43412 | B11: =+A11 -> 43412 | C11: -0.8 | D11: 0.78958333 | F11: CLOSED | H11: 1280.6808 | J11: CLOSED | L11: 1395.4213 | N11: CLOSED | O11: =+H11+L11 -> 2676.1021
A12: 43413 | B12: =+A12 -> 43413 | C12: -0.7 | D12: 0.81666667 | F12: CLOSED | H12: 901.32581 | J12: 1923.6392 | L12: CLOSED | N12: CLOSED | O12: =+H12+J12 -> 2824.965
A13: 43414 | B13: =+A13 -> 43414 | C13: -0.4 | D13: 0.84375 | F13: CLOSED | H13: 2386.1605 | J13: CLOSED | L13: 2162.2596 | N13: CLOSED | O13: =+H13+L13 -> 4548.4201
A14: 43415 | B14: =+A14 -> 43415 | C14: 0 | D14: 0.87222222 | F14: CLOSED | G14: * | H14: =+J14*(H12+H8+H6+H3)/(J3+J6+J8+J12) -> 867.23855 | J14: 1658.3253 | L14: CLOSED | N14: CLOSED | O14: =+H14+J14 -> 2525.5638
A16: 43426 | B16: =+A16 -> 43426 | C16: -0.7 | D16: 0.74652778 | F16: CLOSED | G16: * | H16: =+J16*(H12+H8+H6+H3)/(J3+J6+J8+J12) -> 830.57634 | J16: 1588.2201 | L16: CLOSED | N16: CLOSED | O16: =+H16+J16 -> 2418.7965
A17: 43427 | B17: =+A17 -> 43427 | C17: -1.1 | D17: 0.775 | F17: CLOSED | H17: 2423.2726 | J17: CLOSED | L17: 4038.186 | N17: CLOSED | O17: =+H17+L17 -> 6461.4585
A18: 43428 | B18: =+A18 -> 43428 | C18: -1.3 | D18: 0.80555556 | F18: CLOSED | G18: * | H18: =+(J18+L18)*H12/J12 -> 2161.5193 | J18: 3198.5485 | L18: 1414.6371 | N18: CLOSED | O18: =+H18+J18+L18 -> 6774.7049
A19: 43429 | B19: =+A19 -> 43429 | C19: -1.3 | D19: 0.83680556 | F19: CLOSED | H19: 300.90271 | J19: CLOSED | L19: 499.47239 | N19: CLOSED | O19: =+H19+L19 -> 800.3751
A21: 43440 | B21: =+A21 -> 43440 | C21: -0.7 | D21: 0.75069444 | F21: CLOSED | H21: 1538.7037 | J21: 1112.2015 | L21: CLOSED | N21: CLOSED | O21: =+H21+J21 -> 2650.9052
A22: 43441 | B22: =+A22 -> 43441 | C22: -0.7 | D22: 0.77777778 | F22: CLOSED | H22: 804.41326 | J22: CLOSED | L22: 576.30501 | N22: CLOSED | O22: =+H22+L22 -> 1380.7183
A23: 43442 | B23: =+A23 -> 43442 | C23: -0.6 | D23: 0.80277778 | F23: CLOSED | H23: 948.5266 | J23: 1667.892 | L23: CLOSED | N23: CLOSED | O23: =+H23+J23 -> 2616.4186
A24: 43443 | B24: =+A24 -> 43443 | C24: -0.4 | D24: 0.82847222 | F24: CLOSED | H24: 132.87786 | J24: CLOSED | L24: 226.07678 | N24: CLOSED | O24: =+H24+L24 -> 358.95464
A26: 43454 | B26: =+A26 -> 43454 | C26: -0.3 | D26: 0.70208333 | F26: CLOSED | H26: 397.64769 | J26: CLOSED | L26: 280.13747 | N26: CLOSED | O26: =+H26+L26 -> 677.78516
A27: 43455 | B27: =+A27 -> 43455 | C27: -1 | D27: 0.73263889 | F27: CLOSED | H27: 1183.6582 | J27: 1681.3144 | L27: CLOSED | N27: CLOSED | O27: =+H27+J27 -> 2864.9725
A28: 43456 | B28: =+A28 -> 43456 | C28: -1.4 | D28: 0.76388889 | F28: 1777.1929 | H28: 709.59678 | J28: CLOSED | L28: 881.01387 | N28: CLOSED | O28: =+F28+H28+L28 -> 3367.8036
A29: 43457 | B29: =+A29 -> 43457 | C29: -1.6 | D29: 0.79513889 | F29: CLOSED | H29: 587.93506 | J29: 1074.4422 | L29: CLOSED | N29: CLOSED | O29: =+H29+J29 -> 1662.3773
A31: 43467 | B31: =+A31 -> 43467 | C31: 0.2 | D31: 0.68194444 | F31: CLOSED | H31: 1358.3299 | J31: CLOSED | L31: CLOSED | N31: CLOSED | O31: =+H31 -> 1358.3299
A32: 43468 | B32: =+A32 -> 43468 | C32: -0.2 | D32: 0.7125 | F32: CLOSED | H32: 232.7243 | J32: CLOSED | L32: CLOSED | N32: CLOSED | O32: =+H32 -> 232.7243
A33: 43469 | B33: =+A33 -> 43469 | C33: -0.4 | D33: 0.74027778 | F33: CLOSED | H33: 723.21631 | J33: CLOSED | L33: 931.36522 | N33: CLOSED | O33: =+H33+L33 -> 1654.5815
A34: 43470 | B34: =+A34 -> 43470 | C34: -0.4 | D34: 0.76597222 | F34: CLOSED | H34: 667.93404 | J34: 1448.5191 | L34: CLOSED | N34: CLOSED | O34: =+H34+J34 -> 2116.4532
A35: 43471 | B35: =+A35 -> 43471 | C35: -0.4 | D35: 0.79097222 | F35: CLOSED | H35: 142.90088 | J35: CLOSED | L35: 95.964568 | N35: CLOSED | O35: =+H35+L35 -> 238.86545
A37: 43482 | B37: =+A37 -> 43482 | C37: 0.4 | D37: 0.65208333 | F37: CLOSED | H37: 760.19779 | J37: CLOSED | L37: CLOSED | N37: CLOSED | O37: =+H37 -> 760.19779
A38: 43483 | B38: =+A38 -> 43483 | C38: -0.4 | D38: 0.6875 | F38: CLOSED | H38: 751.23611 | J38: CLOSED | L38: CLOSED | N38: CLOSED | O38: =+H38 -> 751.23611
A39: 43484 | B39: =+A39 -> 43484 | C39: -1.1 | D39: 0.72083333 | F39: CLOSED | H39: 4752.7009 | J39: CLOSED | L39: 6352.8668 | N39: CLOSED | O39: =+H39+L39 -> 11105.568
A40: 43485 | B40: =+A40 -> 43485 | C40: -1.6 | D40: 0.75347222 | F40: CLOSED | H40: 2417.1299 | J40: 5194.5748 | L40: CLOSED | N40: CLOSED | O40: =+H40+J40 -> 7611.7047
A41: 43486 | B41: =+A41 -> 43486 | C41: -1.8 | D41: 0.78541667 | F41: CLOSED | H41: 1325.188 | J41: CLOSED | L41: 1471.4933 | N41: CLOSED | O41: =+H41+L41 -> 2796.6813
A43: 43497 | B43: =+A43 -> 43497 | C43: 0.2 | D43: 0.7 | F43: CLOSED | H43: 1060.3253 | J43: 1395.1561 | L43: CLOSED | N43: CLOSED | O43: =+H43+J43 -> 2455.4814
A44: 43498 | B44: =+A44 -> 43498 | C44: 0 | D44: 0.72777778 | F44: CLOSED | H44: 4068.5106 | J44: CLOSED | L44: 3324.7873 | N44: CLOSED | O44: =+H44+L44 -> 7393.298
A45: 43499 | B45: =+A45 -> 43499 | C45: -0.1 | D45: 0.75277778 | F45: CLOSED | G45: * | H45: =+J45*(H43+H40)/(J43+J40) -> 393.10652 | J45: 744.93159 | L45: CLOSED | N45: CLOSED | O45: =+H45+J45 -> 1138.0381
A47: 43511 | B47: =+A47 -> 43511 | C47: 0.4 | D47: 0.63263889 | F47: CLOSED | H47: 466.58657 | J47: CLOSED | L47: 794.78231 | N47: CLOSED | O47: =+H47+L47 -> 1261.3689
A48: 43512 | B48: =+A48 -> 43512 | C48: -0.3 | D48: 0.67222222 | F48: CLOSED | H48: 1607.1842 | J48: 4004.5243 | L48: CLOSED | N48: 282.29952 | O48: =+H48+J48+N48 -> 5894.008
A49: 43513 | B49: =+A49 -> 43513 | C49: -1 | D49: 0.70763889 | F49: 8343.9805 | G49: * | H49: =+J49*(H48+H43+H40)/(J40+J43+J48) -> 2177.9584 | J49: 4537.9516 | L49: 2715.4678 | N49: 309.65567 | O49: =+F49+H49+J49+L49+N49 -> 18085.014
...

Sheet CPUE
A1: Date | B1: Day | C1: Tide | D1: Time | E1: Longbeach | G1: Twin Harbors | I1: Copalis | K1: Mocrocks | M1: Kalaloch
A2: 43384 | B2: =+A2 -> 43384 | C2: -0.6 | D2: 0.87361111 | F2: CLOSED | H2: =+Harvest!H2/Effort!H2 -> 13.953846 | J2: CLOSED | L2: =+Harvest!L2/Effort!L2 -> 14.489362 | N2: CLOSED | O2: =+Harvest!O2/Effort!O2 -> 14.173035 | Q2: =AVERAGE(O2:O9) -> 11.385196
A3: 43385 | B3: =+A3 -> 43385 | C3: -0.3 | D3: 0.90347222 | F3: CLOSED | H3: =+Harvest!H3/Effort!H3 -> 14.857143 | J3: =+Harvest!J3/Effort!J3 -> 14.666667 | L3: CLOSED | N3: CLOSED | O3: =+Harvest!O3/Effort!O3 -> 14.734051
A4: 43386 | B4: =+A4 -> 43386 | C4: 0.1 | D4: 0.93472222 | F4: CLOSED | H4: =+Harvest!H4/Effort!H4 -> 15.612245 | J4: CLOSED | L4: =+Harvest!L4/Effort!L4 -> 13.93617 | N4: CLOSED | O4: =+Harvest!O4/Effort!O4 -> 14.772542
A6: 43398 | B6: =+A6 -> 43398 | C6: -0.5 | D6: 0.82986111 | F6: CLOSED | H6: =+Harvest!H6/Effort!H6 -> 3.2592593 | J6: =+Harvest!J6/Effort!J6 -> 10.113636 | L6: CLOSED | N6: CLOSED | O6: =+Harvest!O6/Effort!O6 -> 7.5470834
A7: 43399 | B7: =+A7 -> 43399 | C7: -0.7 | D7: 0.85833333 | F7: CLOSED | H7: =+Harvest!H7/Effort!H7 -> 10.883721 | J7: CLOSED | L7: =+Harvest!L7/Effort!L7 -> 15.118421 | N7: CLOSED | O7: =+Harvest!O7/Effort!O7 -> 13.095981
A8: 43400 | B8: =+A8 -> 43400 | C8: -0.7 | D8: 0.88819444 | F8: CLOSED | H8: =+Harvest!H8/Effort!H8 -> 11.320755 | J8: =+Harvest!J8/Effort!J8 -> 7.7283951 | L8: CLOSED | N8: CLOSED | O8: =+Harvest!O8/Effort!O8 -> 8.9339379
A9: 43401 | B9: =+A9 -> 43401 | C9: -0.6 | D9: 0.92222222 | F9: CLOSED | H9: =+Harvest!H9/Effort!H9 -> 10.6 | J9: CLOSED | L9: =+Harvest!L9/Effort!L9 -> 4.8125 | N9: CLOSED | O9: =+Harvest!O9/Effort!O9 -> 6.4397435
A11: 43412 | B11: =+A11 -> 43412 | C11: -0.8 | D11: 0.78958333 | F11: CLOSED | H11: =+Harvest!H11/Effort!H11 -> 14.461538 | J11: CLOSED | L11: =+Harvest!L11/Effort!L11 -> 14.882353 | N11: CLOSED | O11: =+Harvest!O11/Effort!O11 -> 14.680967
A12: 43413 | B12: =+A12 -> 43413 | C12: -0.7 | D12: 0.81666667 | F12: CLOSED | H12: =+Harvest!H12/Effort!H12 -> 14.515152 | J12: =+Harvest!J12/Effort!J12 -> 15 | L12: CLOSED | N12: CLOSED | O12: =+Harvest!O12/Effort!O12 -> 14.845306
A13: 43414 | B13: =+A13 -> 43414 | C13: -0.4 | D13: 0.84375 | F13: CLOSED | H13: =+Harvest!H13/Effort!H13 -> 13.254237 | J13: CLOSED | L13: =+Harvest!L13/Effort!L13 -> 14.672131 | N13: CLOSED | O13: =+Harvest!O13/Effort!O13 -> 13.928286
A14: 43415 | B14: =+A14 -> 43415 | C14: 0 | D14: 0.87222222 | F14: CLOSED | G14: * | H14: =+Harvest!H14/Effort!H14 -> 14.05594 | J14: =+Harvest!J14/Effort!J14 -> 14.92 | L14: CLOSED | N14: CLOSED | O14: =+Harvest!O14/Effort!O14 -> 14.623296
F15: CLOSED
A16: 43426 | B16: =+A16 -> 43426 | C16: -0.7 | D16: 0.74652778 | F16: CLOSED | G16: * | H16: =+Harvest!H16/Effort!H16 -> 13.784222 | J16: =+Harvest!J16/Effort!J16 -> 14.631579 | L16: CLOSED | N16: CLOSED | O16: =+Harvest!O16/Effort!O16 -> 14.34061
A17: 43427 | B17: =+A17 -> 43427 | C17: -1.1 | D17: 0.775 | F17: CLOSED | H17: =+Harvest!H17/Effort!H17 -> 11.052083 | J17: CLOSED | L17: =+Harvest!L17/Effort!L17 -> 14.767677 | N17: CLOSED | O17: =+Harvest!O17/Effort!O17 -> 13.374199
A18: 43428 | B18: =+A18 -> 43428 | C18: -1.3 | D18: 0.80555556 | F18: CLOSED | G18: * | H18: =+Harvest!H18/Effort!H18 -> 14.003007 | J18: =+Harvest!J18/Effort!J18 -> 14.732558 | L18: =+Harvest!L18/Effort!L18 -> 13.878788 | N18: CLOSED | O18: =+Harvest!O18/Effort!O18 -> 14.321512
A19: 43429 | B19: =+A19 -> 43429 | C19: -1.3 | D19: 0.83680556 | F19: CLOSED | H19: =+Harvest!H19/Effort!H19 -> 15 | J19: CLOSED | L19: =+Harvest!L19/Effort!L19 -> 14.659091 | N19: CLOSED | O19: =+Harvest!O19/Effort!O19 -> 14.787256
A21: 43440 | B21: =+A21 -> 43440 | C21: -0.7 | D21: 0.75069444 | F21: CLOSED | H21: =+Harvest!H21/Effort!H21 -> 6.375 | J21: =+Harvest!J21/Effort!J21 -> 11.5 | L21: CLOSED | N21: CLOSED | O21: =+Harvest!O21/Effort!O21 -> 8.5252212
A22: 43441 | B22: =+A22 -> 43441 | C22: -0.7 | D22: 0.77777778 | F22: CLOSED | H22: =+Harvest!H22/Effort!H22 -> 11.837209 | J22: CLOSED | L22: =+Harvest!L22/Effort!L22 -> 8.1458333 | N22: CLOSED | O22: =+Harvest!O22/Effort!O22 -> 10.296447
A23: 43442 | B23: =+A23 -> 43442 | C23: -0.6 | D23: 0.80277778 | F23: CLOSED | H23: =+Harvest!H23/Effort!H23 -> 13.638889 | J23: =+Harvest!J23/Effort!J23 -> 12.788732 | L23: CLOSED | N23: CLOSED | O23: =+Harvest!O23/Effort!O23 -> 13.096938
A24: 43443 | B24: =+A24 -> 43443 | C24: -0.4 | D24: 0.82847222 | F24: CLOSED | H24: =+Harvest!H24/Effort!H24 -> 5.7368421 | J24: CLOSED | L24: =+Harvest!L24/Effort!L24 -> 8.8636364 | N24: CLOSED | O24: =+Harvest!O24/Effort!O24 -> 7.7061594
A26: 43454 | B26: =+A26 -> 43454 | C26: -0.3 | D26: 0.70208333 | F26: CLOSED | H26: =+Harvest!H26/Effort!H26 -> 4.76 | J26: CLOSED | L26: =+Harvest!L26/Effort!L26 -> 4.08 | N26: CLOSED | O26: =+Harvest!O26/Effort!O26 -> 4.4789471
A27: 43455 | B27: =+A27 -> 43455 | C27: -1 | D27: 0.73263889 | F27: CLOSED | H27: =+Harvest!H27/Effort!H27 -> 14.690141 | J27: =+Harvest!J27/Effort!J27 -> 15 | L27: CLOSED | N27: CLOSED | O27: =+Harvest!O27/Effort!O27 -> 14.871982
A28: 43456 | B28: =+A28 -> 43456 | C28: -1.4 | D28: 0.76388889 | F28: =+Harvest!F28/Effort!F28 -> 2.25 | H28: =+Harvest!H28/Effort!H28 -> 0.51282051 | J28: CLOSED | L28: =+Harvest!L28/Effort!L28 -> 4.6037736 | N28: CLOSED | O28: =+Harvest!O28/Effort!O28 -> 2.4997207
A29: 43457 | B29: =+A29 -> 43457 | C29: -1.6 | D29: 0.79513889 | F29: CLOSED | H29: =+Harvest!H29/Effort!H29 -> 3.1851852 | J29: =+Harvest!J29/Effort!J29 -> 7.1 | L29: CLOSED | N29: CLOSED | O29: =+Harvest!O29/Effort!O29 -> 5.7154425
A31: 43467 | B31: =+A31 -> 43467 | C31: 0.2 | D31: 0.68194444 | F31: CLOSED | H31: =+Harvest!H31/Effort!H31 -> 11.44186 | J31: CLOSED | L31: CLOSED | N31: CLOSED
A32: 43468 | B32: =+A32 -> 43468 | C32: -0.2 | D32: 0.7125 | F32: CLOSED | H32: =+Harvest!H32/Effort!H32 -> 0.9047619 | J32: CLOSED | L32: CLOSED | N32: CLOSED
A33: 43469 | B33: =+A33 -> 43469 | C33: -0.4 | D33: 0.74027778 | F33: CLOSED | H33: =+Harvest!H33/Effort!H33 -> 2.8648649 | J33: CLOSED | L33: =+Harvest!L33/Effort!L33 -> 9.7954545 | N33: CLOSED
A34: 43470 | B34: =+A34 -> 43470 | C34: -0.4 | D34: 0.76597222 | F34: CLOSED | H34: =+Harvest!H34/Effort!H34 -> 0.66666667 | J34: =+Harvest!J34/Effort!J34 -> 8.1886792 | L34: CLOSED | N34: CLOSED
A35: 43471 | B35: =+A35 -> 43471 | C35: -0.4 | D35: 0.79097222 | F35: CLOSED | H35: =+Harvest!H35/Effort!H35 -> 8.5384615 | J35: CLOSED | L35: =+Harvest!L35/Effort!L35 -> 14.666667 | N35: CLOSED
A37: 43482 | B37: =+A37 -> 43482 | C37: 0.4 | D37: 0.65208333 | F37: CLOSED | H37: =+Harvest!H37/Effort!H37 -> 2.1428571 | J37: CLOSED | L37: CLOSED | N37: CLOSED
A38: 43483 | B38: =+A38 -> 43483 | C38: -0.4 | D38: 0.6875 | F38: CLOSED | H38: =+Harvest!H38/Effort!H38 -> 7.1176471 | J38: CLOSED | L38: CLOSED | N38: CLOSED
A39: 43484 | B39: =+A39 -> 43484 | C39: -1.1 | D39: 0.72083333 | F39: CLOSED | H39: =+Harvest!H39/Effort!H39 -> 6.25 | J39: CLOSED | L39: =+Harvest!L39/Effort!L39 -> 14.536082 | N39: CLOSED
A40: 43485 | B40: =+A40 -> 43485 | C40: -1.6 | D40: 0.75347222 | F40: CLOSED | H40: =+Harvest!H40/Effort!H40 -> 14.15 | J40: =+Harvest!J40/Effort!J40 -> 15 | L40: CLOSED | N40: CLOSED
A41: 43486 | B41: =+A41 -> 43486 | C41: -1.8 | D41: 0.78541667 | F41: CLOSED | H41: =+Harvest!H41/Effort!H41 -> 15 | J41: CLOSED | L41: =+Harvest!L41/Effort!L41 -> 13.690476 | N41: CLOSED
A43: 43497 | B43: =+A43 -> 43497 | C43: 0.2 | D43: 0.7 | F43: CLOSED | H43: =+Harvest!H43/Effort!H43 -> 11.136364 | J43: =+Harvest!J43/Effort!J43 -> 12.862745 | L43: CLOSED | N43: CLOSED
A44: 43498 | B44: =+A44 -> 43498 | C44: 0 | D44: 0.72777778 | F44: CLOSED | H44: =+Harvest!H44/Effort!H44 -> 12.25 | J44: CLOSED | L44: =+Harvest!L44/Effort!L44 -> 12.891566 | N44: CLOSED
A45: 43499 | B45: =+A45 -> 43499 | C45: -0.1 | D45: 0.75277778 | F45: CLOSED | H45: =+Harvest!H45/Effort!H45 -> 12.815819 | J45: =+Harvest!J45/Effort!J45 -> 14.090909 | L45: CLOSED | N45: CLOSED
A47: 43511 | B47: =+A47 -> 43511 | C47: 0.4 | D47: 0.63263889 | F47: CLOSED | H47: =+Harvest!H47/Effort!H47 -> 8.6818182 | J47: CLOSED | L47: =+Harvest!L47/Effort!L47 -> 11.884615 | N47: CLOSED
A48: 43512 | B48: =+A48 -> 43512 | C48: -0.3 | D48: 0.67222222 | F48: CLOSED | H48: =+Harvest!H48/Effort!H48 -> 12.852459 | J48: =+Harvest!J48/Effort!J48 -> 12.578125 | L48: CLOSED | N48: =+Harvest!N48/Effort!N48 -> 2.8180059
...

Sheet Summary Table
A1: 2018-2019 State (non-Indian) Recreational Razor Clam Effort, Harvest and CPUE totals.
E2: LONG BEACH | H2: TWIN HARBORS | K2: COPALIS | N2: MOCROCKS | Q2: KALALOCH | T2: DAILY TOTALS
A3: DATE | B3: DAY | C3: TIDE | D3: TIME | E3: Effort | F3: Harvest | G3: CPUE | H3: Effort | I3: Harvest | J3: CPUE | K3: Effort | L3: Harvest | M3: CPUE | N3: Effort | O3: Harvest | P3: CPUE | Q3: Effort | R3: Harvest | S3: CPUE | T3: Effort | U3: Harvest
A4: 43384 | B4: =+A4 -> 43384 | C4: -0.6 | D4: 0.87361111 | E4: =Effort!F2 -> CLOSED | F4: =Harvest!F2 -> CLOSED | G4: =CPUE!F2 -> CLOSED | H4: =Effort!H2 -> 1852.5577 | I4: =Harvest!H2 -> 25850.305 | J4: =CPUE!H2 -> 13.953846 | K4: =Effort!J2 -> CLOSED | L4: =Harvest!J2 -> CLOSED | M4: =CPUE!J2 -> CLOSED | N4: =Effort!L2 -> 1283.6696 | O4: =Harvest!L2 -> 18599.554 | P4: =CPUE!L2 -> 14.489362 | Q4: =Effort!N2 -> CLOSED | R4: =Harvest!N2 -> CLOSED | S4: =CPUE!N2 -> CLOSED | T4: =+H4+N4 -> 3136.2273 | U4: =+I4+O4 -> 44449.859
A5: 43385 | B5: =+A5 -> 43385 | C5: -0.3 | D5: 0.90347222 | E5: =Effort!F3 -> CLOSED | F5: =Harvest!F3 -> CLOSED | G5: =CPUE!F3 -> CLOSED | H5: =Effort!H3 -> 1085.784 | I5: =Harvest!H3 -> 16131.648 | J5: =CPUE!H3 -> 14.857143 | K5: =Effort!J3 -> 1983.4262 | L5: =Harvest!J3 -> 29090.25 | M5: =CPUE!J3 -> 14.666667 | N5: =Effort!L3 -> CLOSED | O5: =Harvest!L3 -> CLOSED | P5: =CPUE!L3 -> CLOSED | Q5: =Effort!N3 -> CLOSED | R5: =Harvest!N3 -> CLOSED | S5: =CPUE!N3 -> CLOSED | T5: =+H5+K5 -> 3069.2101 | U5: =+I5+L5 -> 45221.898
A6: 43386 | B6: =+A6 -> 43386 | C6: 0.1 | D6: 0.93472222 | E6: =Effort!F4 -> CLOSED | F6: =Harvest!F4 -> CLOSED | G6: =CPUE!F4 -> CLOSED | H6: =Effort!H4 -> 1666.4268 | I6: =Harvest!H4 -> 26016.664 | J6: =CPUE!H4 -> 15.612245 | K6: =Effort!J4 -> CLOSED | L6: =Harvest!J4 -> CLOSED | M6: =CPUE!J4 -> CLOSED | N6: =Effort!L4 -> 1673.064 | O6: =Harvest!L4 -> 23316.105 | P6: =CPUE!L4 -> 13.93617 | Q6: =Effort!N4 -> CLOSED | R6: =Harvest!N4 -> CLOSED | S6: =CPUE!N4 -> CLOSED | T6: =+H6+N6 -> 3339.4909 | U6: =+I6+O6 -> 49332.769
A7: Tide Series Totals | H7: =SUM(H4:H6) -> 4604.7685 | I7: =SUM(I4:I6) -> 67998.616 | J7: =+I7/H7 -> 14.767 | K7: =SUM(K4:K6) -> 1983.4262 | L7: =SUM(L4:L6) -> 29090.25 | M7: =+L7/K7 -> 14.666667 | N7: =SUM(N4:N6) -> 2956.7337 | O7: =SUM(O4:O6) -> 41915.659 | P7: =+O7/N7 -> 14.176339 | T7: =SUM(T4:T6) -> 9544.9283 | U7: =SUM(U4:U6) -> 139004.53
A8: 43398 | B8: =+A8 -> 43398 | C8: -0.5 | D8: 0.82986111 | E8: =Effort!F6 -> CLOSED | F8: =Harvest!F6 -> CLOSED | G8: =CPUE!F6 -> CLOSED | H8: =Effort!H6 -> 632.23844 | I8: =Harvest!H6 -> 2060.629 | J8: =CPUE!H6 -> 3.2592593 | K8: =Effort!J6 -> 1056.2522 | L8: =Harvest!J6 -> 10682.551 | M8: =CPUE!J6 -> 10.113636 | N8: =Effort!L6 -> CLOSED | O8: =Harvest!L6 -> CLOSED | P8: =CPUE!L6 -> CLOSED | Q8: =Effort!N6 -> CLOSED | R8: =Harvest!N6 -> CLOSED | S8: =CPUE!N6 -> CLOSED | T8: =+H8+K8 -> 1688.4907 | U8: =+I8+L8 -> 12743.18
A9: 43399 | B9: =+A9 -> 43399 | C9: -0.7 | D9: 0.85833333 | E9: =Effort!F7 -> CLOSED | F9: =Harvest!F7 -> CLOSED | G9: =CPUE!F7 -> CLOSED | H9: =Effort!H7 -> 2041.5625 | I9: =Harvest!H7 -> 22219.796 | J9: =CPUE!H7 -> 10.883721 | K9: =Effort!J7 -> CLOSED | L9: =Harvest!J7 -> CLOSED | M9: =CPUE!J7 -> CLOSED | N9: =Effort!L7 -> 2233.178 | O9: =Harvest!L7 -> 33762.125 | P9: =CPUE!L7 -> 15.118421 | Q9: =Effort!N7 -> CLOSED | R9: =Harvest!N7 -> CLOSED | S9: =CPUE!N7 -> CLOSED | T9: =+H9+N9 -> 4274.7405 | U9: =+I9+O9 -> 55981.921
A10: 43400 | B10: =+A10 -> 43400 | C10: -0.7 | D10: 0.88819444 | E10: =Effort!F8 -> CLOSED | F10: =Harvest!F8 -> CLOSED | G10: =CPUE!F8 -> CLOSED | H10: =Effort!H8 -> 670.448 | I10: =Harvest!H8 -> 7589.9774 | J10: =CPUE!H8 -> 11.320755 | K10: =Effort!J8 -> 1327.3992 | L10: =Harvest!J8 -> 10258.666 | M10: =CPUE!J8 -> 7.7283951 | N10: =Effort!L8 -> CLOSED | O10: =Harvest!L8 -> CLOSED | P10: =CPUE!L8 -> CLOSED | Q10: =Effort!N8 -> CLOSED | R10: =Harvest!N8 -> CLOSED | S10: =CPUE!N8 -> CLOSED | T10: =+H10+K10 -> 1997.8472 | U10: =+I10+L10 -> 17848.643
A11: 43401 | B11: =+A11 -> 43401 | C11: -0.6 | D11: 0.92222222 | E11: =Effort!F9 -> CLOSED | F11: =Harvest!F9 -> CLOSED | G11: =CPUE!F9 -> CLOSED | H11: =Effort!H9 -> 261.32726 | I11: =Harvest!H9 -> 2770.0689 | J11: =CPUE!H9 -> 10.6 | K11: =Effort!J9 -> CLOSED | L11: =Harvest!J9 -> CLOSED | M11: =CPUE!J9 -> CLOSED | N11: =Effort!L9 -> 668.1166 | O11: =Harvest!L9 -> 3215.3112 | P11: =CPUE!L9 -> 4.8125 | Q11: =Effort!N9 -> CLOSED | R11: =Harvest!N9 -> CLOSED | S11: =CPUE!N9 -> CLOSED | T11: =+H11+N11 -> 929.44386 | U11: =+I11+O11 -> 5985.3801
A12: Tide Series Totals | H12: =SUM(H8:H11) -> 3605.5762 | I12: =SUM(I8:I11) -> 34640.472 | J12: =+I12/H12 -> 9.6074718 | K12: =SUM(K8:K11) -> 2383.6515 | L12: =SUM(L8:L11) -> 20941.217 | M12: =+L12/K12 -> 8.7853518 | N12: =SUM(N9:N11) -> 2901.2946 | O12: =SUM(O9:O11) -> 36977.436 | P12: =+O12/N12 -> 12.74515 | T12: =SUM(T8:T11) -> 8890.5222 | U12: =SUM(U8:U11) -> 92559.124
A13: 43412 | B13: =+A13 -> 43412 | C13: -0.8 | D13: 0.78958333 | E13: =Effort!F11 -> CLOSED | F13: =Harvest!F11 -> CLOSED | G13: =CPUE!F11 -> CLOSED | H13: =Effort!H11 -> 1280.6808 | I13: =Harvest!H11 -> 18520.615 | J13: =CPUE!H11 -> 14.461538 | K13: =Effort!J11 -> CLOSED | L13: =Harvest!J11 -> CLOSED | M13: =CPUE!J11 -> CLOSED | N13: =Effort!L11 -> 1395.4213 | O13: =Harvest!L11 -> 20767.153 | P13: =CPUE!L11 -> 14.882353 | Q13: =Effort!N11 -> CLOSED | R13: =Harvest!N11 -> CLOSED | S13: =CPUE!N11 -> CLOSED | T13: =+H13+N13 -> 2676.1021 | U13: =+I13+O13 -> 39287.767
A14: 43413 | B14: =+A14 -> 43413 | C14: -0.7 | D14: 0.81666667 | E14: =Effort!F12 -> CLOSED | F14: =Harvest!F12 -> CLOSED | G14: =CPUE!F12 -> CLOSED | H14: =Effort!H12 -> 901.32581 | I14: =Harvest!H12 -> 13082.881 | J14: =CPUE!H12 -> 14.515152 | K14: =Effort!J12 -> 1923.6392 | L14: =Harvest!J12 -> 28854.588 | M14: =CPUE!J12 -> 15 | N14: =Effort!L12 -> CLOSED | O14: =Harvest!L12 -> CLOSED | P14: =CPUE!L12 -> CLOSED | Q14: =Effort!N12 -> CLOSED | R14: =Harvest!N12 -> CLOSED | S14: =CPUE!N12 -> CLOSED | T14: =+H14+K14 -> 2824.965 | U14: =+I14+L14 -> 41937.469
A15: 43414 | B15: =+A15 -> 43414 | C15: -0.4 | D15: 0.84375 | E15: =Effort!F13 -> CLOSED | F15: =Harvest!F13 -> CLOSED | G15: =CPUE!F13 -> CLOSED | H15: =Effort!H13 -> 2386.1605 | I15: =Harvest!H13 -> 31626.737 | J15: =CPUE!H13 -> 13.254237 | K15: =Effort!J13 -> CLOSED | L15: =Harvest!J13 -> CLOSED | M15: =CPUE!J13 -> CLOSED | N15: =Effort!L13 -> 2162.2596 | O15: =Harvest!L13 -> 31724.956 | P15: =CPUE!L13 -> 14.672131 | Q15: =Effort!N13 -> CLOSED | R15: =Harvest!N13 -> CLOSED | S15: =CPUE!N13 -> CLOSED | T15: =+H15+N15 -> 4548.4201 | U15: =+I15+O15 -> 63351.693
A16: 43415 | B16: =+A16 -> 43415 | C16: 0 | D16: 0.87222222 | E16: =Effort!F14 -> CLOSED | F16: =Harvest!F14 -> CLOSED | G16: =CPUE!F14 -> CLOSED | H16: =Effort!H14 -> 867.23855 | I16: =Harvest!H14 -> 12189.853 | J16: =CPUE!H14 -> 14.05594 | K16: =Effort!J14 -> 1658.3253 | L16: =Harvest!J14 -> 24742.213 | M16: =CPUE!J14 -> 14.92 | N16: =Effort!L14 -> CLOSED | O16: =Harvest!L14 -> CLOSED | P16: =CPUE!L14 -> CLOSED | Q16: =Effort!N14 -> CLOSED | R16: =Harvest!N14 -> CLOSED | S16: =CPUE!N14 -> CLOSED | T16: =+H16+K16 -> 2525.5638 | U16: =+I16+L16 -> 36932.066
A17: Tide Series Totals | H17: =SUM(H13:H16) -> 5435.4056 | I17: =SUM(I13:I16) -> 75420.086 | J17: =+I17/H17 -> 13.875705 | K17: =SUM(K13:K16) -> 3581.9645 | L17: =SUM(L13:L16) -> 53596.801 | M17: =+L17/K17 -> 14.962963 | N17: =SUM(N13:N16) -> 3557.6809 | O17: =SUM(O13:O16) -> 52492.109 | P17: =+O17/N17 -> 14.754586 | T17: =SUM(T13:T16) -> 12575.051 | U17: =SUM(U13:U16) -> 181509
A18: 43426 | B18: =+A18 -> 43426 | C18: -0.7 | D18: 0.74652778 | E18: =Effort!F16 -> CLOSED | F18: =Harvest!F16 -> CLOSED | G18: =CPUE!F16 -> CLOSED | H18: =Effort!H16 -> 830.57634 | I18: =Harvest!H16 -> 11448.849 | J18: =CPUE!H16 -> 13.784222 | K18: =Effort!J16 -> 1588.2201 | L18: =Harvest!J16 -> 23238.168 | M18: =CPUE!J16 -> 14.631579 | N18: =Effort!L16 -> CLOSED | O18: =Harvest!L16 -> CLOSED | P18: =CPUE!L16 -> CLOSED | Q18: =Effort!N16 -> CLOSED | R18: =Harvest!N16 -> CLOSED | S18: =CPUE!N16 -> CLOSED | T18: =+H18+K18 -> 2418.7965 | U18: =+I18+L18 -> 34687.017
A19: 43427 | B19: =+A19 -> 43427 | C19: -1.1 | D19: 0.775 | E19: =Effort!F17 -> CLOSED | F19: =Harvest!F17 -> CLOSED | G19: =CPUE!F17 -> CLOSED | H19: =Effort!H17 -> 2423.2726 | I19: =Harvest!H17 -> 26782.21 | J19: =CPUE!H17 -> 11.052083 | K19: =Effort!J17 -> CLOSED | L19: =Harvest!J17 -> CLOSED | M19: =CPUE!J17 -> CLOSED | N19: =Effort!L17 -> 4038.186 | O19: =Harvest!L17 -> 59634.625 | P19: =CPUE!L17 -> 14.767677 | Q19: =Effort!N17 -> CLOSED | R19: =Harvest!N17 -> CLOSED | S19: =CPUE!N17 -> CLOSED | T19: =+H19+N19 -> 6461.4585 | U19: =+I19+O19 -> 86416.836
A20: 43428 | B20: =+A20 -> 43428 | C20: -1.3 | D20: 0.80555556 | E20: =Effort!F18 -> CLOSED | F20: =Harvest!F18 -> CLOSED | G20: =CPUE!F18 -> CLOSED | H20: =Effort!H18 -> 2161.5193 | I20: =Harvest!H18 -> 30267.771 | J20: =CPUE!H18 -> 14.003007 | K20: =Effort!J18 -> 3198.5485 | L20: =Harvest!J18 -> 47122.802 | M20: =CPUE!J18 -> 14.732558 | N20: =Effort!L18 -> 1414.6371 | O20: =Harvest!L18 -> 19633.448 | P20: =CPUE!L18 -> 13.878788 | Q20: =Effort!N18 -> CLOSED | R20: =Harvest!N18 -> CLOSED | S20: =CPUE!N18 -> CLOSED | T20: =+H20+K20+N20 -> 6774.7049 | U20: =+I20+L20+O20 -> 97024.021
A21: 43429 | B21: =+A21 -> 43429 | C21: -1.3 | D21: 0.83680556 | E21: =Effort!F19 -> CLOSED | F21: =Harvest!F19 -> CLOSED | G21: =CPUE!F19 -> CLOSED | H21: =Effort!H19 -> 300.90271 | I21: =Harvest!H19 -> 4513.5407 | J21: =CPUE!H19 -> 15 | K21: =Effort!J19 -> CLOSED | L21: =Harvest!J19 -> CLOSED | M21: =CPUE!J19 -> CLOSED | N21: =Effort!L19 -> 499.47239 | O21: =Harvest!L19 -> 7321.8112 | P21: =CPUE!L19 -> 14.659091 | Q21: =Effort!N19 -> CLOSED | R21: =Harvest!N19 -> CLOSED | S21: =CPUE!N19 -> CLOSED | T21: =+H21+N21 -> 800.3751 | U21: =+I21+O21 -> 11835.352
A22: Tide Series Totals | H22: =SUM(H18:H21) -> 5716.2709 | I22: =SUM(I18:I21) -> 73012.371 | J22: =+I22/H22 -> 12.772728 | K22: =SUM(K18:K21) -> 4786.7686 | L22: =SUM(L18:L21) -> 70360.97 | M22: =+L22/K22 -> 14.699054 | N22: =SUM(N19:N21) -> 5952.2955 | O22: =SUM(O19:O21) -> 86589.885 | P22: =+O22/N22 -> 14.54731 | T22: =SUM(T18:T21) -> 16455.335 | U22: =SUM(U18:U21) -> 229963.23
A23: 43440 | B23: =+A23 -> 43440 | C23: -0.7 | D23: 0.75069444 | E23: =Effort!F21 -> CLOSED | F23: =Harvest!F21 -> CLOSED | G23: =CPUE!F21 -> CLOSED | H23: =Effort!H21 -> 1538.7037 | I23: =Harvest!H21 -> 9809.2362 | J23: =CPUE!H21 -> 6.375 | K23: =Effort!J21 -> 1112.2015 | L23: =Harvest!J21 -> 12790.317 | M23: =CPUE!J21 -> 11.5 | N23: =Effort!L21 -> CLOSED | O23: =Harvest!L21 -> CLOSED | P23: =CPUE!L21 -> CLOSED | Q23: =Effort!N21 -> CLOSED | R23: =Harvest!N21 -> CLOSED | S23: =CPUE!N21 -> CLOSED | T23: =+H23+K23 -> 2650.9052 | U23: =+I23+L23 -> 22599.553
A24: 43441 | B24: =+A24 -> 43441 | C24: -0.7 | D24: 0.77777778 | E24: =Effort!F22 -> CLOSED | F24: =Harvest!F22 -> CLOSED | G24: =CPUE!F22 -> CLOSED | H24: =Effort!H22 -> 804.41326 | I24: =Harvest!H22 -> 9522.0081 | J24: =CPUE!H22 -> 11.837209 | K24: =Effort!J22 -> CLOSED | L24: =Harvest!J22 -> CLOSED | M24: =CPUE!J22 -> CLOSED | N24: =Effort!L22 -> 576.30501 | O24: =Harvest!L22 -> 4694.4845 | P24: =CPUE!L22 -> 8.1458333 | Q24: =Effort!N22 -> CLOSED | R24: =Harvest!N22 -> CLOSED | S24: =CPUE!N22 -> CLOSED | T24: =+H24+N24 -> 1380.7183 | U24: =+I24+O24 -> 14216.493
A25: 43442 | B25: =+A25 -> 43442 | C25: -0.6 | D25: 0.80277778 | E25: =Effort!F23 -> CLOSED | F25: =Harvest!F23 -> CLOSED | G25: =CPUE!F23 -> CLOSED | H25: =Effort!H23 -> 948.5266 | I25: =Harvest!H23 -> 12936.849 | J25: =CPUE!H23 -> 13.638889 | K25: =Effort!J23 -> 1667.892 | L25: =Harvest!J23 -> 21330.225 | M25: =CPUE!J23 -> 12.788732 | N25: =Effort!L23 -> CLOSED | O25: =Harvest!L23 -> CLOSED | P25: =CPUE!L23 -> CLOSED | Q25: =Effort!N23 -> CLOSED | R25: =Harvest!N23 -> CLOSED | S25: =CPUE!N23 -> CLOSED | T25: =+H25+K25 -> 2616.4186 | U25: =+I25+L25 -> 34267.074
A26: 43443 | B26: =+A26 -> 43443 | C26: -0.4 | D26: 0.82847222 | E26: =Effort!F24 -> CLOSED | F26: =Harvest!F24 -> CLOSED | G26: =CPUE!F24 -> CLOSED | H26: =Effort!H24 -> 132.87786 | I26: =Harvest!H24 -> 762.29931 | J26: =CPUE!H24 -> 5.7368421 | K26: =Effort!J24 -> CLOSED | L26: =Harvest!J24 -> CLOSED | M26: =CPUE!J24 -> CLOSED | N26: =Effort!L24 -> 226.07678 | O26: =Harvest!L24 -> 2003.8623 | P26: =CPUE!L24 -> 8.8636364 | Q26: =Effort!N24 -> CLOSED | R26: =Harvest!N24 -> CLOSED | S26: =CPUE!N24 -> CLOSED | T26: =+H26+N26 -> 358.95464 | U26: =+I26+O26 -> 2766.1616
A27: Tide Series Totals | H27: =SUM(H23:H26) -> 3424.5214 | I27: =SUM(I23:I26) -> 33030.393 | J27: =+I27/H27 -> 9.6452579 | K27: =SUM(K23:K26) -> 2780.0935 | L27: =SUM(L23:L26) -> 34120.542 | M27: =+L27/K27 -> 12.273163 | N27: =SUM(N24:N26) -> 802.38178 | O27: =SUM(O24:O26) -> 6698.3469 | P27: =+O27/N27 -> 8.3480794 | T27: =SUM(T23:T26) -> 7006.9967 | U27: =SUM(U23:U26) -> 73849.281
A28: 43454 | B28: =+A28 -> 43454 | C28: -0.3 | D28: 0.70208333 | E28: =Effort!F26 -> CLOSED | F28: =Harvest!F26 -> CLOSED | G28: =CPUE!F26 -> CLOSED | H28: =Effort!H26 -> 397.64769 | I28: =Harvest!H26 -> 1892.803 | J28: =CPUE!H26 -> 4.76 | K28: =Effort!J26 -> CLOSED | L28: =Harvest!J26 -> CLOSED | M28: =CPUE!J26 -> CLOSED | N28: =Effort!L26 -> 280.13747 | O28: =Harvest!L26 -> 1142.9609 | P28: =CPUE!L26 -> 4.08 | Q28: =Effort!N26 -> CLOSED | R28: =Harvest!N26 -> CLOSED | S28: =CPUE!N26 -> CLOSED | T28: =+H28+N28 -> 677.78516 | U28: =+I28+O28 -> 3035.7639
A29: 43455 | B29: =+A29 -> 43455 | C29: -1 | D29: 0.73263889 | E29: =Effort!F27 -> CLOSED | F29: =Harvest!F27 -> CLOSED | G29: =CPUE!F27 -> CLOSED | H29: =Effort!H27 -> 1183.6582 | I29: =Harvest!H27 -> 17388.105 | J29: =CPUE!H27 -> 14.690141 | K29: =Effort!J27 -> 1681.3144 | L29: =Harvest!J27 -> 25219.716 | M29: =CPUE!J27 -> 15 | N29: =Effort!L27 -> CLOSED | O29: =Harvest!L27 -> CLOSED | P29: =CPUE!L27 -> CLOSED | Q29: =Effort!N27 -> CLOSED | R29: =Harvest!N27 -> CLOSED | S29: =CPUE!N27 -> CLOSED | T29: =+H29+K29 -> 2864.9725 | U29: =+I29+L29 -> 42607.821
A30: 43456 | B30: =+A30 -> 43456 | C30: -1.4 | D30: 0.76388889 | E30: =Effort!F28 -> 1777.1929 | F30: =Harvest!F28 -> 3998.6841 | G30: =CPUE!F28 -> 2.25 | H30: =Effort!H28 -> 709.59678 | I30: =Harvest!H28 -> 363.89578 | J30: =CPUE!H28 -> 0.51282051 | K30: =Effort!J28 -> CLOSED | L30: =Harvest!J28 -> CLOSED | M30: =CPUE!J28 -> CLOSED | N30: =Effort!L28 -> 881.01387 | O30: =Harvest!L28 -> 4055.9884 | P30: =CPUE!L28 -> 4.6037736 | Q30: =Effort!N28 -> CLOSED | R30: =Harvest!N28 -> CLOSED | S30: =CPUE!N28 -> CLOSED | T30: =+E30+H30+N30 -> 3367.8036 | U30: =+F30+I30+O30 -> 8418.5682
A31: 43457 | B31: =+A31 -> 43457 | C31: -1.6 | D31: 0.79513889 | E31: =Effort!F29 -> CLOSED | F31: =Harvest!F29 -> CLOSED | G31: =CPUE!F29 -> CLOSED | H31: =Effort!H29 -> 587.93506 | I31: =Harvest!H29 -> 1872.6821 | J31: =CPUE!H29 -> 3.1851852 | K31: =Effort!J29 -> 1074.4422 | L31: =Harvest!J29 -> 7628.5395 | M31: =CPUE!J29 -> 7.1 | N31: =Effort!L29 -> CLOSED | O31: =Harvest!L29 -> CLOSED | P31: =CPUE!L29 -> CLOSED | Q31: =Effort!N29 -> CLOSED | R31: =Harvest!N29 -> CLOSED | S31: =CPUE!N29 -> CLOSED | T31: =+H31+K31 -> 1662.3773 | U31: =+I31+L31 -> 9501.2216
A32: Tide Series Totals | E32: =SUM(E30:E31) -> 1777.1929 | F32: =SUM(F30:F31) -> 3998.6841 | G32: =+F32/E32 -> 2.25 | H32: =SUM(H28:H31) -> 2878.8377 | I32: =SUM(I28:I31) -> 21517.486 | J32: =+I32/H32 -> 7.4743658 | K32: =SUM(K29:K31) -> 2755.7566 | L32: =SUM(L29:L31) -> 32848.255 | M32: =+L32/K32 -> 11.919868 | N32: =SUM(N28:N31) -> 1161.1513 | O32: =SUM(O28:O31) -> 5198.9493 | P32: =+O32/N32 -> 4.4774088 | T32: =SUM(T28:T31) -> 8572.9385 | U32: =SUM(U28:U31) -> 63563.374
A33: 43467 | B33: =+A33 -> 43467 | C33: 0.2 | D33: 0.68194444 | E33: =Effort!F31 -> CLOSED | F33: =Harvest!F31 -> CLOSED | G33: =CPUE!F31 -> CLOSED | H33: =Effort!H31 -> 1358.3299 | I33: =Harvest!H31 -> 15541.821 | J33: =CPUE!H31 -> 11.44186 | K33: =Effort!J31 -> CLOSED | L33: =Harvest!J31 -> CLOSED | M33: =CPUE!J31 -> CLOSED | N33: =Effort!L31 -> CLOSED | O33: =Harvest!L31 -> CLOSED | P33: =CPUE!L31 -> CLOSED | Q33: =Effort!N31 -> CLOSED | R33: =Harvest!N31 -> CLOSED | S33: =CPUE!N31 -> CLOSED | T33: =+H33 -> 1358.3299 | U33: =+I33 -> 15541.821
A34: 43468 | B34: =+A34 -> 43468 | C34: -0.2 | D34: 0.7125 | E34: =Effort!F32 -> CLOSED | F34: =Harvest!F32 -> CLOSED | G34: =CPUE!F32 -> CLOSED | H34: =Effort!H32 -> 232.7243 | I34: =Harvest!H32 -> 210.56008 | J34: =CPUE!H32 -> 0.9047619 | K34: =Effort!J32 -> CLOSED | L34: =Harvest!J32 -> CLOSED | M34: =CPUE!J32 -> CLOSED | N34: =Effort!L32 -> CLOSED | O34: =Harvest!L32 -> CLOSED | P34: =CPUE!L32 -> CLOSED | Q34: =Effort!N32 -> CLOSED | R34: =Harvest!N32 -> CLOSED | S34: =CPUE!N32 -> CLOSED | T34: =+H34 -> 232.7243 | U34: =+I34 -> 210.56008
A35: 43469 | B35: =+A35 -> 43469 | C35: -0.4 | D35: 0.74027778 | E35: =Effort!F33 -> CLOSED | F35: =Harvest!F33 -> CLOSED | G35: =CPUE!F33 -> CLOSED | H35: =Effort!H33 -> 723.21631 | I35: =Harvest!H33 -> 2071.917 | J35: =CPUE!H33 -> 2.8648649 | K35: =Effort!J33 -> CLOSED | L35: =Harvest!J33 -> CLOSED | M35: =CPUE!J33 -> CLOSED | N35: =Effort!L33 -> 931.36522 | O35: =Harvest!L33 -> 9123.1457 | P35: =CPUE!L33 -> 9.7954545 | Q35: =Effort!N33 -> CLOSED | R35: =Harvest!N33 -> CLOSED | S35: =CPUE!N33 -> CLOSED | T35: =+H35+N35 -> 1654.5815 | U35: =+I35+O35 -> 11195.063
A36: 43470 | B36: =+A36 -> 43470 | C36: -0.4 | D36: 0.76597222 | E36: =Effort!F34 -> CLOSED | F36: =Harvest!F34 -> CLOSED | G36: =CPUE!F34 -> CLOSED | H36: =Effort!H34 -> 667.93404 | I36: =Harvest!H34 -> 445.28936 | J36: =CPUE!H34 -> 0.66666667 | K36: =Effort!J34 -> 1448.5191 | L36: =Harvest!J34 -> 11861.458 | M36: =CPUE!J34 -> 8.1886792 | N36: =Effort!L34 -> CLOSED | O36: =Harvest!L34 -> CLOSED | P36: =CPUE!L34 -> CLOSED | Q36: =Effort!N34 -> CLOSED | R36: =Harvest!N34 -> CLOSED | S36: =CPUE!N34 -> CLOSED | T36: =+H36+K36 -> 2116.4532 | U36: =+I36+L36 -> 12306.748
A37: 43471 | B37: =+A37 -> 43471 | C37: -0.4 | D37: 0.79097222 | E37: =Effort!F35 -> CLOSED | F37: =Harvest!F35 -> CLOSED | G37: =CPUE!F35 -> CLOSED | H37: =Effort!H35 -> 142.90088 | I37: =Harvest!H35 -> 1220.1537 | J37: =CPUE!H35 -> 8.5384615 | K37: =Effort!J35 -> CLOSED | L37: =Harvest!J35 -> CLOSED | M37: =CPUE!J35 -> CLOSED | N37: =Effort!L35 -> 95.964568 | O37: =Harvest!L35 -> 1407.4803 | P37: =CPUE!L35 -> 14.666667 | Q37: =Effort!N35 -> CLOSED | R37: =Harvest!N35 -> CLOSED | S37: =CPUE!N35 -> CLOSED | T37: =+H37+N37 -> 238.86545 | U37: =+I37+O37 -> 2627.634 | TI37: +
A38: Tide Series Totals | H38: =SUM(H33:H37) -> 3125.1055 | I38: =SUM(I33:I37) -> 19489.742 | J38: =+I38/H38 -> 6.2365069 | K38: =SUM(K36:K37) -> 1448.5191 | L38: =SUM(L36:L37) -> 11861.458 | M38: =+L38/K38 -> 8.1886792 | N38: =SUM(N35:N37) -> 1027.3298 | O38: =SUM(O35:O37) -> 10530.626 | P38: =+O38/N38 -> 10.250482 | T38: =SUM(T33:T37) -> 5600.9544 | U38: =SUM(U33:U37) -> 41881.826
A39: 43482 | B39: 43482 | C39: 0.4 | D39: 0.65208333 | E39: =Effort!F37 -> CLOSED | F39: =Harvest!F37 -> CLOSED | G39: =CPUE!F37 -> CLOSED | H39: =Effort!H37 -> 760.19779 | I39: =Harvest!H37 -> 1628.9953 | J39: =CPUE!H37 -> 2.1428571 | K39: =Effort!J37 -> CLOSED | L39: =Harvest!J37 -> CLOSED | M39: =CPUE!J37 -> CLOSED | N39: =Effort!L37 -> CLOSED | O39: =Harvest!L37 -> CLOSED | P39: =CPUE!L37 -> CLOSED | Q39: =Effort!N37 -> CLOSED | R39: =Harvest!N37 -> CLOSED | S39: =CPUE!N37 -> CLOSED | T39: =+H39 -> 760.19779 | U39: =+I39 -> 1628.9953
A40: 43483 | B40: 43483 | C40: -0.4 | D40: 0.6875 | E40: =Effort!F38 -> CLOSED | F40: =Harvest!F38 -> CLOSED | G40: =CPUE!F38 -> CLOSED | H40: =Effort!H38 -> 751.23611 | I40: =Harvest!H38 -> 5347.0335 | J40: =CPUE!H38 -> 7.1176471 | K40: =Effort!J38 -> CLOSED | L40: =Harvest!J38 -> CLOSED | M40: =CPUE!J38 -> CLOSED | N40: =Effort!L38 -> CLOSED | O40: =Harvest!L38 -> CLOSED | P40: =CPUE!L38 -> CLOSED | Q40: =Effort!N38 -> CLOSED | R40: =Harvest!N38 -> CLOSED | S40: =CPUE!N38 -> CLOSED | T40: =+H40 -> 751.23611 | U40: =+I40 -> 5347.0335
...

Sheet Tribal update
A1: 2018-2019 State (non-Indian) Recreational Razor Clam Effort, Harvest and CPUE totals.
E2: COPALIS | I2: MOCROCKS | M2: KALALOCH | Q2: DAILY TOTALS
A3: DATE | B3: DAY | C3: TIDE | D3: TIME | E3: Effort | F3: Harvest | G3: CPUE | H3: Size (mm) | I3: Effort | J3: Harvest | K3: CPUE | L3: Size (mm) | M3: Effort | N3: Harvest | O3: CPUE | P3: Size (mm) | Q3: Effort | R3: Harvest
A4: 43384 | B4: =+A4 -> 43384 | C4: -0.6 | D4: 0.87361111 | E4: CLOSED | F4: CLOSED | G4: CLOSED | I4: 1283.6696 | J4: 18599.554 | K4: 14.489362 | M4: CLOSED | N4: CLOSED | O4: CLOSED | Q4: =+I4 -> 1283.6696 | R4: =+J4 -> 18599.554
A5: 43385 | B5: =+A5 -> 43385 | C5: -0.3 | D5: 0.90347222 | E5: 1983.4262 | F5: 29090.25 | G5: 14.666667 | I5: CLOSED | J5: CLOSED | K5: CLOSED | M5: CLOSED | N5: CLOSED | O5: CLOSED | Q5: =+E5 -> 1983.4262 | R5: =+F5 -> 29090.25
A6: 43386 | B6: =+A6 -> 43386 | C6: 0.1 | D6: 0.93472222 | E6: CLOSED | F6: CLOSED | G6: CLOSED | I6: 1673.064 | J6: 23316.105 | K6: 13.93617 | M6: CLOSED | N6: CLOSED | O6: CLOSED | Q6: =+I6 -> 1673.064 | R6: =+J6 -> 23316.105
A7: Tide Series Totals | E7: =SUM(E5:E6) -> 1983.4262 | F7: =SUM(F5:F6) -> 29090.25 | G7: =+F7/E7 -> 14.666667 | I7: =SUM(I4:I6) -> 2956.7337 | J7: =SUM(J4:J6) -> 41915.659 | K7: =+J7/I7 -> 14.176339 | Q7: =SUM(Q4:Q6) -> 4940.1598 | R7: =SUM(R4:R6) -> 71005.909
A8: 43398 | B8: =+A8 -> 43398 | C8: -0.5 | D8: 0.82986111 | E8: 1056.2522 | F8: 10682.551 | G8: 10.113636 | I8: CLOSED | J8: CLOSED | K8: CLOSED | M8: CLOSED | N8: CLOSED | O8: CLOSED | Q8: =+E8 -> 1056.2522 | R8: =+F8 -> 10682.551
A9: 43399 | B9: =+A9 -> 43399 | C9: -0.7 | D9: 0.85833333 | E9: CLOSED | F9: CLOSED | G9: CLOSED | I9: 2233.178 | J9: 33762.125 | K9: 15.118421 | M9: CLOSED | N9: CLOSED | O9: CLOSED | Q9: =+I9 -> 2233.178 | R9: =+J9 -> 33762.125
A10: 43400 | B10: =+A10 -> 43400 | C10: -0.7 | D10: 0.88819444 | E10: 1327.3992 | F10: 10258.666 | G10: 7.7283951 | I10: CLOSED | J10: CLOSED | K10: CLOSED | M10: CLOSED | N10: CLOSED | O10: CLOSED | Q10: =+E10 -> 1327.3992 | R10: =+F10 -> 10258.666
A11: 43401 | B11: =+A11 -> 43401 | C11: -0.6 | D11: 0.92222222 | E11: CLOSED | F11: CLOSED | G11: CLOSED | I11: 668.1166 | J11: 3215.3112 | K11: 4.8125 | M11: CLOSED | N11: CLOSED | O11: CLOSED | Q11: =+I11 -> 668.1166 | R11: =+J11 -> 3215.3112
A12: Tide Series Totals | E12: =SUM(E8:E11) -> 2383.6515 | F12: =SUM(F8:F11) -> 20941.217 | G12: =+F12/E12 -> 8.7853518 | I12: =SUM(I9:I11) -> 2901.2946 | J12: =SUM(J9:J11) -> 36977.436 | K12: =+J12/I12 -> 12.74515 | Q12: =SUM(Q8:Q11) -> 5284.946 | R12: =SUM(R8:R11) -> 57918.652
A13: 43412 | B13: =+A13 -> 43412 | C13: -0.8 | D13: 0.78958333 | E13: CLOSED | F13: CLOSED | G13: CLOSED | I13: 1395.4213 | J13: 20767.153 | K13: 14.882353 | M13: CLOSED | N13: CLOSED | O13: CLOSED | Q13: =+I13 -> 1395.4213 | R13: =+J13 -> 20767.153
A14: 43413 | B14: =+A14 -> 43413 | C14: -0.7 | D14: 0.81666667 | E14: 1923.6392 | F14: 28854.588 | G14: 15 | I14: CLOSED | J14: CLOSED | K14: CLOSED | M14: CLOSED | N14: CLOSED | O14: CLOSED | Q14: =+E14 -> 1923.6392 | R14: =+F14 -> 28854.588
A15: 43414 | B15: =+A15 -> 43414 | C15: -0.4 | D15: 0.84375 | E15: CLOSED | F15: CLOSED | G15: CLOSED | I15: 2162.2596 | J15: 31724.956 | K15: 14.672131 | M15: CLOSED | N15: CLOSED | O15: CLOSED | Q15: =+I15 -> 2162.2596 | R15: =+J15 -> 31724.956
A16: 43415 | B16: =+A16 -> 43415 | C16: 0 | D16: 0.87222222 | E16: 1658.3253 | F16: 24742.213 | G16: 14.92 | I16: CLOSED | J16: CLOSED | K16: CLOSED | M16: CLOSED | N16: CLOSED | O16: CLOSED | Q16: =+E16 -> 1658.3253 | R16: =+F16 -> 24742.213
A17: Tide Series Totals | E17: =SUM(E14:E16) -> 3581.9645 | F17: =SUM(F14:F16) -> 53596.801 | G17: =+F17/E17 -> 14.962963 | I17: =SUM(I13:I16) -> 3557.6809 | J17: =SUM(J13:J16) -> 52492.109 | K17: =+J17/I17 -> 14.754586 | Q17: =SUM(Q13:Q16) -> 7139.6454 | R17: =SUM(R13:R16) -> 106088.91
A18: 43426 | B18: =+A18 -> 43426 | C18: -0.7 | D18: 0.74652778 | E18: 1588.2201 | F18: 23238.168 | G18: 14.631579 | I18: CLOSED | J18: CLOSED | K18: CLOSED | M18: CLOSED | N18: CLOSED | O18: CLOSED | Q18: =+E18 -> 1588.2201 | R18: =+F18 -> 23238.168
A19: 43427 | B19: =+A19 -> 43427 | C19: -1.1 | D19: 0.775 | E19: CLOSED | F19: CLOSED | G19: CLOSED | I19: 4038.186 | J19: 59634.625 | K19: 14.767677 | M19: CLOSED | N19: CLOSED | O19: CLOSED | Q19: =+I19 -> 4038.186 | R19: =+J19 -> 59634.625
A20: 43428 | B20: =+A20 -> 43428 | C20: -1.3 | D20: 0.80555556 | E20: 3198.5485 | F20: 47122.802 | G20: 14.732558 | I20: 1414.6371 | J20: 19633.448 | K20: 13.878788 | M20: CLOSED | N20: CLOSED | O20: CLOSED | Q20: =+E20+I20 -> 4613.1856 | R20: =+F20+J20 -> 66756.25
A21: 43429 | B21: =+A21 -> 43429 | C21: -1.3 | D21: 0.83680556 | E21: CLOSED | F21: CLOSED | G21: CLOSED | I21: 499.47239 | J21: 7321.8112 | K21: 14.659091 | M21: CLOSED | N21: CLOSED | O21: CLOSED | Q21: =+I21 -> 499.47239 | R21: =+J21 -> 7321.8112
A22: Tide Series Totals | E22: =SUM(E18:E21) -> 4786.7686 | F22: =SUM(F18:F21) -> 70360.97 | G22: =+F22/E22 -> 14.699054 | I22: =SUM(I19:I21) -> 5952.2955 | J22: =SUM(J19:J21) -> 86589.885 | K22: =+J22/I22 -> 14.54731 | Q22: =SUM(Q18:Q21) -> 10739.064 | R22: =SUM(R18:R21) -> 156950.85
A23: 43440 | B23: =+A23 -> 43440 | C23: -0.7 | D23: 0.75069444 | E23: 1112.2015 | F23: 12790.317 | G23: 11.5 | I23: CLOSED | J23: CLOSED | K23: CLOSED | M23: CLOSED | N23: CLOSED | O23: CLOSED | Q23: =+E23 -> 1112.2015 | R23: =+F23 -> 12790.317
A24: 43441 | B24: =+A24 -> 43441 | C24: -0.7 | D24: 0.77777778 | E24: CLOSED | F24: CLOSED | G24: CLOSED | I24: 576.30501 | J24: 4694.4845 | K24: 8.1458333 | M24: CLOSED | N24: CLOSED | O24: CLOSED | Q24: =+I24 -> 576.30501 | R24: =+J24 -> 4694.4845
A25: 43442 | B25: =+A25 -> 43442 | C25: -0.6 | D25: 0.80277778 | E25: 1667.892 | F25: 21330.225 | G25: 12.788732 | I25: CLOSED | J25: CLOSED | K25: CLOSED | M25: CLOSED | N25: CLOSED | O25: CLOSED | Q25: =+E25 -> 1667.892 | R25: =+F25 -> 21330.225
A26: 43443 | B26: =+A26 -> 43443 | C26: -0.4 | D26: 0.82847222 | E26: CLOSED | F26: CLOSED | G26: CLOSED | I26: 226.07678 | J26: 2003.8623 | K26: 8.8636364 | M26: CLOSED | N26: CLOSED | O26: CLOSED | Q26: =+I26 -> 226.07678 | R26: =+J26 -> 2003.8623
A27: Tide Series Totals | E27: =SUM(E23:E26) -> 2780.0935 | F27: =SUM(F23:F26) -> 34120.542 | G27: =+F27/E27 -> 12.273163 | I27: =SUM(I24:I26) -> 802.38178 | J27: =SUM(J24:J26) -> 6698.3469 | K27: =+J27/I27 -> 8.3480794 | Q27: =SUM(Q23:Q26) -> 3582.4753 | R27: =SUM(R23:R26) -> 40818.889
A28: 43454 | B28: =+A28 -> 43454 | C28: -0.3 | D28: 0.70208333 | E28: CLOSED | F28: CLOSED | G28: CLOSED | I28: 280.13747 | J28: 1142.9609 | K28: 4.08 | M28: CLOSED | N28: CLOSED | O28: CLOSED | Q28: =+I28 -> 280.13747 | R28: =+J28 -> 1142.9609
A29: 43455 | B29: =+A29 -> 43455 | C29: -1 | D29: 0.73263889 | E29: 1681.3144 | F29: 25219.716 | G29: 15 | I29: CLOSED | J29: CLOSED | K29: CLOSED | M29: CLOSED | N29: CLOSED | O29: CLOSED | Q29: =+E29 -> 1681.3144 | R29: =+F29 -> 25219.716
A30: 43456 | B30: =+A30 -> 43456 | C30: -1.4 | D30: 0.76388889 | E30: CLOSED | F30: CLOSED | G30: CLOSED | I30: 881.01387 | J30: 4055.9884 | K30: 4.6037736 | M30: CLOSED | N30: CLOSED | O30: CLOSED | Q30: =+I30 -> 881.01387 | R30: =+J30 -> 4055.9884
A31: 43457 | B31: =+A31 -> 43457 | C31: -1.6 | D31: 0.79513889 | E31: 1074.4422 | F31: 7628.5395 | G31: 7.1 | I31: CLOSED | J31: CLOSED | K31: CLOSED | M31: CLOSED | N31: CLOSED | O31: CLOSED | Q31: =+E31 -> 1074.4422 | R31: =+F31 -> 7628.5395
A32: Tide Series Totals | E32: =SUM(E29:E31) -> 2755.7566 | F32: =SUM(F29:F31) -> 32848.255 | G32: =+F32/E32 -> 11.919868 | I32: =SUM(I28:I31) -> 1161.1513 | J32: =SUM(J28:J31) -> 5198.9493 | K32: =+J32/I32 -> 4.4774088 | Q32: =SUM(Q28:Q31) -> 3916.9079 | R32: =SUM(R28:R31) -> 38047.204
A33: 43469 | B33: =+A33 -> 43469 | C33: -0.4 | D33: 0.74027778 | E33: CLOSED | F33: CLOSED | G33: CLOSED | I33: 931.36522 | J33: 9123.1457 | K33: 9.7954545 | M33: CLOSED | N33: CLOSED | O33: CLOSED | Q33: 931.36522 | R33: 9123.1457
A34: 43470 | B34: =+A34 -> 43470 | C34: -0.4 | D34: 0.76597222 | E34: 1448.5191 | F34: 11861.458 | G34: 8.1886792 | I34: CLOSED | J34: CLOSED | K34: CLOSED | M34: CLOSED | N34: CLOSED | O34: CLOSED | Q34: 1448.5191 | R34: 11861.458
A35: 43471 | B35: =+A35 -> 43471 | C35: -0.4 | D35: 0.79097222 | E35: CLOSED | F35: CLOSED | G35: CLOSED | I35: 95.964568 | J35: 1407.4803 | K35: 14.666667 | M35: CLOSED | N35: CLOSED | O35: CLOSED | Q35: 95.964568 | R35: 1407.4803
A36: Tide Series Totals | E36: =SUM(E34:E35) -> 1448.5191 | F36: =SUM(F34:F35) -> 11861.458 | G36: =+F36/E36 -> 8.1886792 | I36: =SUM(I33:I35) -> 1027.3298 | J36: =SUM(J33:J35) -> 10530.626 | K36: =+J36/I36 -> 10.250482 | Q36: =SUM(Q33:Q35) -> 2475.8489 | R36: =SUM(R33:R35) -> 22392.085
A37: 43484 | B37: =+A37 -> 43484 | C37: -1.1 | D37: 0.72083333 | E37: CLOSED | F37: CLOSED | G37: CLOSED | I37: 6352.8668 | J37: 92345.796 | K37: 14.536082 | M37: CLOSED | N37: CLOSED | O37: CLOSED | Q37: =+I37 -> 6352.8668 | R37: =+J37 -> 92345.796
A38: 43485 | B38: =+A38 -> 43485 | C38: -1.6 | D38: 0.75347222 | E38: 5194.5748 | F38: 77918.622 | G38: 15 | I38: CLOSED | J38: CLOSED | K38: CLOSED | M38: CLOSED | N38: CLOSED | O38: CLOSED | Q38: =+E38 -> 5194.5748 | R38: =+F38 -> 77918.622
A39: 43486 | B39: =+A39 -> 43486 | C39: -1.8 | D39: 0.78541667 | E39: CLOSED | F39: CLOSED | G39: CLOSED | I39: 1471.4933 | J39: 20145.444 | K39: 13.690476 | M39: CLOSED | N39: CLOSED | O39: CLOSED | Q39: =+I39 -> 1471.4933 | R39: =+J39 -> 20145.444
A40: Tide Series Totals | E40: =SUM(E38:E39) -> 5194.5748 | F40: =SUM(F38:F39) -> 77918.622 | G40: =+F40/E40 -> 15 | I40: =SUM(I37:I39) -> 7824.3601 | J40: =SUM(J37:J39) -> 112491.24 | K40: =+J40/I40 -> 14.377053 | Q40: =SUM(Q37:Q39) -> 13018.935 | R40: =SUM(R37:R39) -> 190409.86
...

Sheet Copy Sheet
A1: BeachName | B1: Date | C1: Effort | D1: Harvest | E1: CPUE | F1: EventID | G1: CorrectionFactor
A2: Copalis | B2: 43385 | C2: 1983.4262 | D2: 29090.25 | E2: 14.666667 | F2: 1521 | G2: 0.50492501
A3: Mocrocks | B3: 43384 | C3: 1283.6696 | D3: 18599.554 | E3: 14.489362 | F3: 1519 | G3: 0.58923334
A4: Mocrocks | B4: 43386 | C4: 1673.064 | D4: 23316.105 | E4: 13.93617 | F4: 1523 | G4: 0.54243332
A5: Twin Harbors | B5: 43384 | C5: 1852.5577 | D5: 25850.305 | E5: 13.953846 | F5: 1518 | G5: 0.52713335
A6: Twin Harbors | B6: 43385 | C6: 1085.784 | D6: 16131.648 | E6: 14.857143 | F6: 1520 | G6: 0.52713335
A7: Twin Harbors | B7: 43386 | C7: 1666.4268 | D7: 26016.664 | E7: 15.612245 | F7: 1522 | G7: 0.52713335
A9: BeachName | B9: Date | C9: Effort | D9: Harvest | E9: CPUE | F9: EventID | G9: CorrectionFactor
A10: Copalis | B10: 43398 | C10: 1056.2522 | D10: 10682.551 | E10: 10.113636 | F10: 1524 | G10: 0.5582
A11: Copalis | B11: 43400 | C11: 1327.3992 | D11: 10258.666 | E11: 7.7283951 | F11: 1529 | G11: 0.49880001
A12: Mocrocks | B12: 43399 | C12: 2233.178 | D12: 33762.125 | E12: 15.118421 | F12: 1527 | G12: 0.51174998
A13: Mocrocks | B13: 43401 | C13: 668.1166 | D13: 3215.3112 | E13: 4.8125 | F13: 1530 | G13: 0.51727498
A14: Twin Harbors | B14: 43398 | C14: 632.23844 | D14: 2060.629 | E14: 3.2592593 | F14: 1525 | G14: 0.53109998
A15: Twin Harbors | B15: 43399 | C15: 2041.5625 | D15: 22219.796 | E15: 10.883721 | F15: 1526 | G15: 0.51243335
A16: Twin Harbors | B16: 43400 | C16: 670.448 | D16: 7589.9774 | E16: 11.320755 | F16: 1528 | G16: 0.53109998
A17: Twin Harbors | B17: 43401 | C17: 261.32726 | D17: 2770.0689 | E17: 10.6 | F17: 1531 | G17: 0.51555002
A19: BeachName | B19: Date | C19: Effort | D19: Harvest | E19: CPUE | F19: EventID | G19: CorrectionFactor
A20: Copalis | B20: 43413 | C20: 1923.6392 | D20: 28854.588 | E20: 15 | F20: 1533 | G20: 0.490825
A21: Copalis | B21: 43415 | C21: 1658.3253 | D21: 24742.213 | E21: 14.92 | F21: 1535 | G21: 0.44668001
A22: Mocrocks | B22: 43412 | C22: 1395.4213 | D22: 20767.153 | E22: 14.882353 | F22: 1532 | G22: 0.32104999
A23: Mocrocks | B23: 43414 | C23: 2708.4908 | D23: 39739.332 | E23: 14.672131 | F23: 1534 | G23: 0.65113336
A24: Twin Harbors | B24: 43412 | C24: 1280.6808 | D24: 18520.615 | E24: 14.461538 | F24: 1536 | G24: 0.47396666
A25: Twin Harbors | B25: 43413 | C25: 901.32581 | D25: 13082.881 | E25: 14.515152 | F25: 1537 | G25: 0.53109998
A26: Twin Harbors | B26: 43414 | C26: 2386.1605 | D26: 31626.737 | E26: 13.254237 | F26: 1538 | G26: 0.52713335
A28: BeachName | B28: Date | C28: Effort | D28: Harvest | E28: CPUE | F28: EventID | G28: CorrectionFactor
A29: Copalis | B29: 43426 | C29: 1588.2201 | D29: 23238.168 | E29: 14.631579 | F29: 1539 | G29: 0.51840001
A30: Copalis | B30: 43428 | C30: 3198.5485 | D30: 47122.802 | E30: 14.732558 | F30: 1542 | G30: 0.52386665
A31: Mocrocks | B31: 43427 | C31: 4038.186 | D31: 59634.625 | E31: 14.767677 | F31: 1540 | G31: 0.57612503
A32: Mocrocks | B32: 43428 | C32: 1414.6371 | D32: 19633.448 | E32: 13.878788 | F32: 1543 | G32: 0.53653336
A33: Mocrocks | B33: 43429 | C33: 499.47239 | D33: 7321.8112 | E33: 14.659091 | F33: 1544 | G33: 0.5686
A34: Twin Harbors | B34: 43427 | C34: 2423.2726 | D34: 26782.21 | E34: 11.052083 | F34: 1541 | G34: 0.53109998
A35: Twin Harbors | B35: 43429 | C35: 300.90271 | D35: 4513.5407 | E35: 15 | F35: 1545 | G35: 0.49849999
A37: BeachName | B37: Date | C37: Effort | D37: Harvest | E37: CPUE | F37: EventID | G37: CorrectionFactor
A38: Copalis | B38: 43440 | C38: 1112.2015 | D38: 12790.317 | E38: 11.5 | F38: 1546 | G38: 0.61140001
A39: Copalis | B39: 43442 | C39: 1667.892 | D39: 21330.225 | E39: 12.788732 | F39: 1551 | G39: 0.52593333
A40: Mocrocks | B40: 43441 | C40: 576.30501 | D40: 4694.4845 | E40: 8.1458333 | F40: 1549 | G40: 0.58004999
A41: Mocrocks | B41: 43443 | C41: 226.07678 | D41: 2003.8623 | E41: 8.8636364 | F41: 1552 | G41: 0.51310003
A42: Twin Harbors | B42: 43440 | C42: 1538.7037 | D42: 9809.2362 | E42: 6.375 | F42: 1547 | G42: 0.52713335
A43: Twin Harbors | B43: 43441 | C43: 804.41326 | D43: 9522.0081 | E43: 11.837209 | F43: 1548 | G43: 0.49849999
A44: Twin Harbors | B44: 43442 | C44: 948.5266 | D44: 12936.849 | E44: 13.638889 | F44: 1550 | G44: 0.52713335
...

Sheet Sunset times
A1: Date | B1: Day | C1: Tide | D1: Time | E1: Sunset
A2: 43384 | B2: =+A2 -> 43384 | C2: -0.6 | D2: 0.87361111 | E2: 0.77569444
A3: 43385 | B3: =+A3 -> 43385 | C3: -0.3 | D3: 0.90347222 | E3: 0.77430556
A4: 43386 | B4: =+A4 -> 43386 | C4: 0.1 | D4: 0.93472222 | E4: 0.77291667
A6: 43398 | B6: =+A6 -> 43398 | C6: -0.5 | D6: 0.82986111 | E6: 0.75763889
A7: 43399 | B7: =+A7 -> 43399 | C7: -0.7 | D7: 0.85833333 | E7: 0.75694444
A8: 43400 | B8: =+A8 -> 43400 | C8: -0.7 | D8: 0.88819444 | E8: 0.75555556
A9: 43401 | B9: =+A9 -> 43401 | C9: -0.6 | D9: 0.92222222 | E9: 0.75416667
A11: 43412 | B11: =+A11 -> 43412 | C11: -0.8 | D11: 0.78958333 | E11: 0.70138889
A12: 43413 | B12: =+A12 -> 43413 | C12: -0.7 | D12: 0.81666667 | E12: 0.70069444
A13: 43414 | B13: =+A13 -> 43414 | C13: -0.4 | D13: 0.84375 | E13: 0.69930556
A14: 43415 | B14: =+A14 -> 43415 | C14: 0 | D14: 0.87222222 | E14: 0.69861111
A16: 43426 | B16: =+A16 -> 43426 | C16: -0.7 | D16: 0.74652778 | E16: 0.69097222
... A29: 43457 | B29: =+A29 -> 43457 | C29: -1.6 | D29: 0.79513889 | E29: 0.6875

Sheet Harvest Dates
A1: 2018-2019 State/QIN Razor Clam Low Tide Harvest Date Sharing | M1: total days calculation | T1: saturday calculation
E2: COPALIS | F2: MOCROCKS | M2: COPALIS | N2: MOCROCKS | P2: COPALIS | Q2: MOCROCKS | T2: COPALIS | U2: MOCROCKS | W2: COPALIS | X2: MOCROCKS
A3: DATE | B3: DAY | C3: TIDE | D3: TIME | M3: QIN | N3: QIN | P3: STATE | Q3: STATE | T3: QIN | U3: QIN | W3: STATE | X3: STATE
A4: 43348 | B4: =+A4 -> 43348 | F4: QIN | M4: =IF(E4="QIN",1,0) -> 0 | N4: =IF(F4="QIN",1,0) -> 1 | P4: =IF(E4="STATE",1,0) -> 0 | Q4: =IF(F4="STATE",1,0) -> 0
A5: =A4+1 -> 43349 | B5: =+A5 -> 43349 | F5: QIN | M5: =IF(E5="QIN",1,0) -> 0 | N5: =IF(F5="QIN",1,0) -> 1 | P5: =IF(E5="STATE",1,0) -> 0 | Q5: =IF(F5="STATE",1,0) -> 0
A6: =A5+1 -> 43350 | B6: =+A6 -> 43350 | F6: QIN | M6: =IF(E6="QIN",1,0) -> 0 | N6: =IF(F6="QIN",1,0) -> 1 | P6: =IF(E6="STATE",1,0) -> 0 | Q6: =IF(F6="STATE",1,0) -> 0
A7: =A6+1 -> 43351 | B7: =+A7 -> 43351 | F7: QIN | M7: =IF(E7="QIN",1,0) -> 0 | N7: =IF(F7="QIN",1,0) -> 1 | P7: =IF(E7="STATE",1,0) -> 0 | Q7: =IF(F7="STATE",1,0) -> 0
A8: 43352 | B8: =+A8 -> 43352 | C8: -0.6 | D8: 0.17638889 | F8: QIN | M8: =IF(E8="QIN",1,0) -> 0 | N8: =IF(F8="QIN",1,0) -> 1 | P8: =IF(E8="STATE",1,0) -> 0 | Q8: =IF(F8="STATE",1,0) -> 0
A9: =A8+1 -> 43353 | B9: =+A9 -> 43353 | F9: QIN | M9: =IF(E9="QIN",1,0) -> 0 | N9: =IF(F9="QIN",1,0) -> 1 | P9: =IF(E9="STATE",1,0) -> 0 | Q9: =IF(F9="STATE",1,0) -> 0
A10: =A9+1 -> 43354 | B10: =+A10 -> 43354 | F10: QIN | M10: =IF(E10="QIN",1,0) -> 0 | N10: =IF(F10="QIN",1,0) -> 1 | P10: =IF(E10="STATE",1,0) -> 0 | Q10: =IF(F10="STATE",1,0) -> 0
A11: =A10+1 -> 43355 | B11: =+A11 -> 43355 | F11: QIN | N11: =IF(F11="QIN",1,0) -> 1 | Q11: =IF(F11="STATE",1,0) -> 0
A13: 43366 | B13: =+A13 -> 43366 | C13: -0.6 | D13: 0.17638889 | E13: QIN | M13: =IF(E13="QIN",1,0) -> 1 | N13: =IF(F13="QIN",1,0) -> 0 | P13: =IF(E13="STATE",1,0) -> 0 | Q13: =IF(F13="STATE",1,0) -> 0
A14: =A13+1 -> 43367 | B14: =+A14 -> 43367 | C14: -0.1 | D14: 0.2 | E14: QIN | M14: =IF(E14="QIN",1,0) -> 1 | N14: =IF(F14="QIN",1,0) -> 0 | P14: =IF(E14="STATE",1,0) -> 0 | Q14: =IF(F14="STATE",1,0) -> 0
A15: =A14+1 -> 43368 | B15: =+A15 -> 43368 | C15: -0.1 | D15: 0.22222222 | E15: QIN | M15: =IF(E15="QIN",1,0) -> 1 | N15: =IF(F15="QIN",1,0) -> 0 | P15: =IF(E15="STATE",1,0) -> 0 | Q15: =IF(F15="STATE",1,0) -> 0
A16: =A15+1 -> 43369 | B16: =+A16 -> 43369 | C16: 0 | D16: 0.76458333 | E16: QIN | M16: =IF(E16="QIN",1,0) -> 1 | N16: =IF(F16="QIN",1,0) -> 0 | P16: =IF(E16="STATE",1,0) -> 0 | Q16: =IF(F16="STATE",1,0) -> 0
A17: =A16+1 -> 43370 | B17: =+A17 -> 43370 | C17: -0.2 | D17: 0.79027778 | E17: QIN | M17: =IF(E17="QIN",1,0) -> 1 | N17: =IF(F17="QIN",1,0) -> 0 | P17: =IF(E17="STATE",1,0) -> 0 | Q17: =IF(F17="STATE",1,0) -> 0
