Workbook

Sheet Harvest
A1: Date | B1: Day | C1: Tide | D1: Time | E1: Longbeach | G1: Twin Harbors | I1: Copalis | K1: Mocrocks | M1: Kalaloch | O1: Daily Totals
A2: 43735 | B2: Fri | C2: -0.9 | D2: 0.24444444 | F2: 31676.927 | H2: CLOSED | J2: CLOSED | L2: CLOSED | N2: CLOSED | O2: =SUM(F2:N2) -> 31676.927 | Q2: =SUM(O2:O11) -> 949774.57
A3: 43736 | B3: Sat | C3: -0.8 | D3: 0.275 | F3: 125073.23 | H3: CLOSED | J3: CLOSED | L3: CLOSED | N3: CLOSED | O3: =SUM(F3:N3) -> 125073.23
A4: 43737 | B4: Sun | C4: -0.6 | D4: 0.30486111 | E4: ** | F4: 120000 | H4: CLOSED | J4: CLOSED | L4: CLOSED | N4: CLOSED | O4: =SUM(F4:N4) -> 120000
A6: 43764 | B6: Sat | C6: 0 | D6: 0.74930556 | F6: 117815.18 | H6: 54176.192 | J6: 110223 | L6: CLOSED | N6: CLOSED | O6: =SUM(F6:N6) -> 282214.37
A7: 43765 | B7: Sun | C7: -0.8 | D7: 0.78263889 | E7: * | F7: 77972.215 | H7: 35854.845 | J7: CLOSED | L7: 73894.802 | N7: CLOSED | O7: =SUM(F7:N7) -> 187721.86
A8: 43766 | B8: Mon | C8: -1.2 | D8: 0.81458333 | E8: * | F8: =(F6*J8)/J6 -> 46580.995 | G8: * | H8: =(H6*J8)/J6 -> 21419.828 | J8: 43579.248 | L8: CLOSED | N8: CLOSED | O8: =SUM(F8:N8) -> 111580.07
A9: 43767 | B9: Tue | C9: -1.4 | D9: 0.84583333 | F9: 15327.075 | G9: * | H9: =(H7*L9)/L7 -> 12453.927 | J9: CLOSED | L9: 25666.837 | N9: CLOSED | O9: =SUM(F9:N9) -> 53447.838
A10: 43768 | B10: Wed | C10: -1.2 | D10: 0.87708333 | E10: * | F10: =(F6*J10)/J6 -> 12584.436 | H10: 5270.8922 | J10: 11773.477 | L10: CLOSED | N10: CLOSED | O10: =SUM(F10:N10) -> 29628.805
A11: 43769 | B11: Thu | C11: -0.8 | D11: 0.90972222 | E11: * | F11: =Effort!F11*CPUE!F11 -> 2408.0658 | G11: * | H11: =(H7*L11)/L7 -> 1967.825 | J11: CLOSED | L11: 4055.5758 | N11: CLOSED | O11: =SUM(F11:N11) -> 8431.4666
A12: 43770 | B12: Fri | C12: -0.2 | D12: 0.94305556 | E12: * | F12: =(H12*F6)/H6 -> 10806.553 | H12: 4969.291 | J12: 11172.494 | L12: CLOSED | N12: CLOSED | O12: =SUM(F12:N12) -> 26948.339
A14: 43780 | B14: Mon | C14: 0.1 | D14: 0.74375 | E14: * | F14: =Effort!F14*CPUE!F14 -> 15664.105 | G14: * | H14: =Effort!H14*CPUE!H14 -> 16506.91 | J14: 28212.409 | L14: CLOSED | N14: CLOSED | O14: =SUM(F14:N14) -> 60383.425
A15: 43781 | B15: Tue | C15: -0.3 | D15: 0.76875 | F15: 15998.247 | H15: 10742.858 | J15: CLOSED | L15: 13580.532 | N15: CLOSED | O15: =SUM(F15:N15) -> 40321.637
A16: 43782 | B16: Wed | C16: -0.5 | D16: 0.79375 | E16: * | F16: =Effort!F16*CPUE!F16 -> 7056.6744 | G16: * | H16: =(H18*J16)/J18 -> 7410.812 | J16: 12599.845 | L16: CLOSED | N16: CLOSED | O16: =SUM(F16:N16) -> 27067.331
A17: 43783 | B17: Thu | C17: -0.6 | D17: 0.82013889 | E17: * | F17: =(F15*L17)/L15 -> 9096.2589 | G17: * | H17: =(H15*L17)/L15 -> 6108.1576 | J17: CLOSED | L17: 7721.5981 | N17: CLOSED | O17: =SUM(F17:N17) -> 22926.015
A18: 43784 | B18: Fri | C18: -0.5 | D18: 0.84861111 | F18: 12170.04 | H18: 12091.996 | J18: 20558.782 | L18: CLOSED | N18: CLOSED | O18: =SUM(F18:N18) -> 44820.818
A19: 43785 | B19: Sat | C19: -0.3 | D19: 0.88055556 | F19: 32936.785 | G19: * | H19: =(H18*F19)/F18 -> 32725.568 | J19: CLOSED | L19: 28091.085 | N19: CLOSED | O19: =SUM(F19:N19) -> 93753.437
A20: 43786 | B20: Sun | C20: -0.1 | D20: 0.91597222 | E20: * | F20: =(F15*H20)/H15 -> 2952.3664 | H20: 1982.5204 | J20: 4030.638 | L20: CLOSED | N20: CLOSED | O20: =SUM(F20:N20) -> 8965.5248
A22: 43793 | B22: Sun | C22: -0.4 | D22: 0.69930556 | F22: 43477.914 | G22: * | H22: =(H28*J22)/J28 -> 15334.262 | J22: 47202.433 | L22: CLOSED | N22: CLOSED | O22: =SUM(F22:N22) -> 106014.61
A23: 43794 | B23: Mon | C23: -1 | D23: 0.73194444 | E23: * | F23: =Effort!F23*CPUE!F23 -> 23228.685 | H23: 13089.421 | J23: CLOSED | L23: 17468.045 | N23: CLOSED | O23: =SUM(F23:N23) -> 53786.151
A24: 43795 | B24: Tue | C24: -1.3 | D24: 0.7625 | E24: * | F24: =J24*F22/J22 -> 15759.551 | G24: * | H24: =J24*H28/J28 -> 5558.2494 | J24: 17109.587 | L24: CLOSED | N24: CLOSED | O24: =SUM(F24:N24) -> 38427.388
A25: 43796 | B25: Wed | C25: -1.4 | D25: 0.79305556 | F25: =Effort!F25*CPUE!F25 -> 18308.131 | G25: * | H25: =L25*H23/L23 -> 5959.2595 | J25: CLOSED | L25: 7952.7289 | N25: CLOSED | O25: =SUM(F25:N25) -> 32220.119
A26: 43797 | B26: Thu | C26: -1.2 | D26: 0.82222222 | E26: * | F26: =J26*F22/J22 -> 21810.001 | G26: * | H26: =J26*H28/J28 -> 7692.1877 | J26: 23678.347 | L26: CLOSED | N26: CLOSED | O26: =SUM(F26:N26) -> 53180.536
A27: 43798 | B27: Fri | C27: -0.7 | D27: 0.85347222 | E27: * | F27: =Effort!F27*CPUE!F27 -> 47767.47 | G27: * | H27: =L27*H23/L23 -> 22722.739 | J27: CLOSED | L27: 30323.865 | N27: CLOSED | O27: =SUM(F27:N27) -> 100814.07
A28: 43799 | B28: Sat | C28: -0.2 | D28: 0.88194444 | F28: =(20428.9763/23048.9375*7380.9665)+7380.9665 -> 13922.942 | H28: 6866.207 | J28: 21135.786 | L28: CLOSED | N28: CLOSED | O28: =SUM(F28:N28) -> 41924.935
A30: 43809 | B30: Tue | C30: -0.2 | D30: 0.72777778 | E30: * | F30: =F36*L30/L36 -> 5379.1866 | G30: * | H30: =H36*L30/L36 -> 3919.7424 | J30: CLOSED | L30: 5404.4749 | N30: CLOSED | O30: =SUM(F30:N30) -> 14703.404
A31: 43810 | B31: Wed | C31: -0.6 | D31: 0.75416667 | E31: * | F31: =F33*J31/J33 -> 634.71077 | H31: 456.95824 | J31: 2252.595 | L31: CLOSED | N31: CLOSED | O31: =SUM(F31:N31) -> 3344.264
A32: 43811 | B32: Thu | C32: -0.9 | D32: 0.78125 | E32: * | F32: =F36*L32/L36 -> 248.96994 | G32: * | H32: =H36*L32/L36 -> 181.42112 | J32: CLOSED | L32: 250.14038 | N32: CLOSED | O32: =SUM(F32:N32) -> 680.53144
A33: 43812 | B33: Fri | C33: -1 | D33: 0.80972222 | F33: 4325.4539 | G33: * | H33: =H31*J33/J31 -> 3114.0984 | J33: 15351.08 | L33: CLOSED | N33: CLOSED | O33: =SUM(F33:N33) -> 22790.633
A34: 43813 | B34: Sat | C34: -1 | D34: 0.83888889 | E34: * | F34: =F36*L34/L36 -> 24947.955 | G34: * | H34: =H36*L34/L36 -> 18179.246 | J34: CLOSED | L34: 25065.238 | N34: CLOSED | O34: =SUM(F34:N34) -> 68192.439
A35: 43814 | B35: Sun | C35: -0.8 | D35: 0.87013889 | E35: * | F35: =Effort!F35*CPUE!F35 -> 3270.7566 | G35: * | H35: =Effort!H35*CPUE!H35 -> 5017.5128 | J35: 5744.6807 | L35: CLOSED | N35: CLOSED | O35: =SUM(F35:N35) -> 14032.95
A36: 43815 | B36: Mon | C36: -0.4 | D36: 0.90347222 | F36: 1307.7209 | H36: 952.91899 | J36: CLOSED | L36: 1313.8687 | N36: CLOSED | O36: =SUM(F36:N36) -> 3574.5086
A38: 43822 | B38: Mon | C38: -0.4 | D38: 0.69097222 | F38: =Effort!F38*CPUE!F38 -> 24405.53 | G38: * | H38: =Effort!H38*CPUE!H38 -> 9587.9216 | J38: CLOSED | L38: 18533.41 | N38: CLOSED | O38: =SUM(F38:N38) -> 52526.862
A39: 43825 | B39: Thu | C39: -1.1 | D39: 0.78263889 | F39: =9329.00426382607+8745.41065728367 -> 18074.415 | G39: * | H39: =Effort!H39*CPUE!H39 -> 15869.084 | J39: 16165.561 | L39: CLOSED | N39: CLOSED | O39: =SUM(F39:N39) -> 50109.06
A40: 43826 | B40: Fri | C40: -0.9 | D40: 0.80972222 | E40: * | F40: =Effort!F40*CPUE!F40 -> 16679.377 | H40: 6581.1674 | J40: CLOSED | L40: 5893.7112 | N40: CLOSED | O40: =SUM(F40:N40) -> 29154.256
A41: 43827 | B41: Sat | C41: -0.6 | D41: 0.83680556 | F41: =Effort!F41*CPUE!F41 -> 14362.715 | H41: 17672.727 | J41: 13464.667 | L41: CLOSED | N41: CLOSED | O41: =SUM(F41:N41) -> 45500.109
A42: 43828 | B42: Sun | C42: -0.2 | D42: 0.86319444 | E42: * | F42: =Effort!F42*CPUE!F42 -> 9817.3993 | G42: * | H42: =Effort!H42*CPUE!H42 -> 3856.8494 | J42: CLOSED | L42: 7496.0189 | N42: CLOSED | O42: =SUM(F42:N42) -> 21170.268
A44: 43838 | B44: Wed | C44: -0.3 | D44: 0.71180556 | F44: =Effort!F44*CPUE!F44 -> 7459.6408 | G44: * | H44: =Effort!H44*CPUE!H44 -> 3276.686 | J44: CLOSED | L44: 3715.9922 | N44: CLOSED | O44: =SUM(F44:N44) -> 14452.319
A45: 43839 | B45: Thu | C45: -0.8 | D45: 0.74097222 | F45: =Effort!F45*CPUE!F45 -> 7588.9987 | H45: 7781.3224 | J45: 15414.365 | L45: CLOSED | N45: CLOSED | O45: =SUM(F45:N45) -> 30784.686
A46: 43840 | B46: Fri | C46: -1.2 | D46: 0.77013889 | E46: * | F46: =Effort!F46*CPUE!F46 -> 3763.448 | G46: * | H46: =Effort!H46*CPUE!H46 -> 1653.1141 | J46: CLOSED | L46: 880.74078 | N46: CLOSED | O46: =SUM(F46:N46) -> 6297.3029
...

Sheet Effort
A1: Date | B1: Day | C1: Tide | D1: Time | E1: Longbeach | G1: Twin Harbors | I1: Copalis | K1: Mocrocks | M1: Kalaloch | O1: Daily Totals
A2: 43735 | B2: Fri | C2: -0.9 | D2: 0.24444444 | F2: 2262.6377 | H2: CLOSED | J2: CLOSED | L2: CLOSED | N2: CLOSED | O2: =SUM(F2:N2) -> 2262.6377 | Q2: =SUM(O2:O11) -> 63675.566
A3: 43736 | B3: Sat | C3: -0.8 | D3: 0.275 | F3: 8338.2153 | H3: CLOSED | J3: CLOSED | L3: CLOSED | N3: CLOSED | O3: =SUM(F3:N3) -> 8338.2153
A4: 43737 | B4: Sun | C4: -0.6 | D4: 0.30486111 | E4: ** | F4: 8000 | H4: CLOSED | J4: CLOSED | L4: CLOSED | N4: CLOSED | O4: =SUM(F4:N4) -> 8000
A6: 43764 | B6: Sat | C6: 0 | D6: 0.74930556 | F6: 7854.35 | H6: 3611.7461 | J6: 7348.1701 | L6: CLOSED | N6: CLOSED | O6: =SUM(F6:N6) -> 18814.266
A7: 43765 | B7: Sun | C7: -0.8 | D7: 0.78263889 | E7: * | F7: 5198.148 | H7: 2390.323 | J7: CLOSED | L7: 4926.3202 | N7: CLOSED | O7: =SUM(F7:N7) -> 12514.791
A8: 43766 | B8: Mon | C8: -1.2 | D8: 0.81458333 | E8: * | F8: =(F6*J8)/J6 -> 3142.5845 | G8: * | H8: =(H6*J8)/J6 -> 1445.0868 | J8: 2940.0581 | L8: CLOSED | N8: CLOSED | O8: =SUM(F8:N8) -> 7527.7294
A9: 43767 | B9: Tue | C9: -1.4 | D9: 0.84583333 | F9: 1021.805 | G9: * | H9: =(H7*L9)/L7 -> 834.99935 | J9: CLOSED | L9: 1720.8863 | N9: CLOSED | O9: =SUM(F9:N9) -> 3577.6907
A10: 43768 | B10: Wed | C10: -1.2 | D10: 0.87708333 | E10: * | F10: =(F6*J10)/J6 -> 888.31726 | H10: 358.75183 | J10: 831.06894 | L10: CLOSED | N10: CLOSED | O10: =SUM(F10:N10) -> 2078.138
A11: 43769 | B11: Thu | C11: -0.8 | D11: 0.90972222 | E11: * | F11: =(F9*L11)/L9 -> 160.53772 | G11: * | H11: =(H7*L11)/L7 -> 131.18833 | J11: CLOSED | L11: 270.37172 | N11: CLOSED | O11: =SUM(F11:N11) -> 562.09777
A12: 43770 | B12: Fri | C12: -0.2 | D12: 0.94305556 | E12: * | F12: =(H12*F6)/H6 -> 752.81653 | H12: 346.17533 | J12: 744.83295 | L12: CLOSED | N12: CLOSED | O12: =SUM(F12:N12) -> 1843.8248
A14: 43780 | B14: Mon | C14: 0.1 | D14: 0.74375 | E14: * | F14: =(F18*J14)/J18 -> 1044.2737 | G14: * | H14: =(H18*J14)/J18 -> 1100.4607 | J14: 1880.8273 | L14: CLOSED | N14: CLOSED | O14: =SUM(F14:N14) -> 4025.5616
A15: 43781 | B15: Tue | C15: -0.3 | D15: 0.76875 | F15: 1066.5498 | H15: 716.19051 | J15: CLOSED | L15: 947.47897 | N15: CLOSED | O15: =SUM(F15:N15) -> 2730.2193
A16: 43782 | B16: Wed | C16: -0.5 | D16: 0.79375 | E16: * | F16: =(F18*J16)/J18 -> 470.44496 | G16: * | H16: =(H18*J16)/J18 -> 495.75719 | J16: 847.31208 | L16: CLOSED | N16: CLOSED | O16: =SUM(F16:N16) -> 1813.5142
A17: 43783 | B17: Thu | C17: -0.6 | D17: 0.82013889 | E17: * | F17: =(F15*L17)/L15 -> 684.82272 | G17: * | H17: =(H15*L17)/L15 -> 459.85994 | J17: CLOSED | L17: 608.36833 | N17: CLOSED | O17: =SUM(F17:N17) -> 1753.051
A18: 43784 | B18: Fri | C18: -0.5 | D18: 0.84861111 | F18: 811.3358 | H18: 854.98961 | J18: 1461.286 | L18: CLOSED | N18: CLOSED | O18: =SUM(F18:N18) -> 3127.6114
A19: 43785 | B19: Sat | C19: -0.3 | D19: 0.88055556 | F19: 2195.7856 | G19: * | H19: =(H18*F19)/F18 -> 2313.9295 | J19: CLOSED | L19: 1903.9513 | N19: CLOSED | O19: =SUM(F19:N19) -> 6413.6665
A20: 43786 | B20: Sun | C20: -0.1 | D20: 0.91597222 | E20: * | F20: =(F15*H20)/H15 -> 196.82442 | H20: 132.16803 | J20: 313.91262 | L20: CLOSED | N20: CLOSED | O20: =SUM(F20:N20) -> 642.90507
A22: 43793 | B22: Sun | C22: -0.4 | D22: 0.69930556 | F22: 3014.032 | G22: * | H22: =H28*J22/J28 -> 1264.2011 | J22: 3356.6175 | L22: CLOSED | N22: CLOSED | O22: =SUM(F22:N22) -> 7634.8506
A23: 43794 | B23: Mon | C23: -1 | D23: 0.73194444 | E23: * | F23: =H23*F28/H28 -> 1548.579 | H23: 942.04166 | J23: CLOSED | L23: 1216.1297 | N23: CLOSED | O23: =SUM(F23:N23) -> 3706.7504
A24: 43795 | B24: Tue | C24: -1.3 | D24: 0.7625 | E24: * | F24: =J24*F22/J22 -> 1059.5404 | G24: * | H24: =J24*H28/J28 -> 444.41207 | J24: 1179.9715 | L24: CLOSED | N24: CLOSED | O24: =SUM(F24:N24) -> 2683.9241
A25: 43796 | B25: Wed | C25: -1.4 | D25: 0.79305556 | F25: =(1367.75197577578/1646.2812570957*666.666662008917)+666.666662008917 -> 1220.542 | G25: * | H25: =L25*H23/L23 -> 603.11256 | J25: CLOSED | L25: 778.58884 | N25: CLOSED | O25: =SUM(F25:N25) -> 2602.2434
A26: 43797 | B26: Thu | C26: -1.2 | D26: 0.82222222 | E26: * | F26: =J26*F22/J22 -> 1458.1812 | G26: * | H26: =J26*H28/J28 -> 611.61736 | J26: 1623.9232 | L26: CLOSED | N26: CLOSED | O26: =SUM(F26:N26) -> 3693.7217
A27: 43798 | B27: Fri | C27: -0.7 | D27: 0.85347222 | E27: * | F27: =L27*F25/L25 -> 3184.498 | G27: * | H27: =L27*H23/L23 -> 1573.572 | J27: CLOSED | L27: 2031.4045 | N27: CLOSED | O27: =SUM(F27:N27) -> 6789.4745
A28: 43799 | B28: Sat | C28: -0.2 | D28: 0.88194444 | F28: =(1367.7519757757/1646.2812570957*512.567119073571)+512.567119073571 -> 938.41458 | H28: 570.86247 | J28: 1515.7137 | L28: CLOSED | N28: CLOSED | O28: =SUM(F28:N28) -> 3024.9908
A30: 43809 | B30: Tue | C30: -0.2 | D30: 0.72777778 | E30: * | F30: =F36*L30/L36 -> 462.8974 | G30: * | H30: =H36*L30/L36 -> 439.96593 | J30: CLOSED | L30: 465.0735 | N30: CLOSED | O30: =SUM(F30:N30) -> 1367.9368
A31: 43810 | B31: Wed | C31: -0.6 | D31: 0.75416667 | E31: * | F31: =F33*J31/J33 -> 165.48695 | H31: 253.86569 | J31: 290.65742 | L31: CLOSED | N31: CLOSED | O31: =SUM(F31:N31) -> 710.01006
A32: 43811 | B32: Thu | C32: -0.9 | D32: 0.78125 | E32: * | F32: =F36*L32/L36 -> 271.60359 | G32: * | H32: =H36*L32/L36 -> 258.14862 | J32: CLOSED | L32: 272.88042 | N32: CLOSED | O32: =SUM(F32:N32) -> 802.63263
A33: 43812 | B33: Fri | C33: -1 | D33: 0.80972222 | F33: 674.398 | G33: * | H33: =H31*J33/J31 -> 1034.562 | J33: 1184.4969 | L33: CLOSED | N33: CLOSED | O33: =SUM(F33:N33) -> 2893.457
A34: 43813 | B34: Sat | C34: -1 | D34: 0.83888889 | E34: * | F34: =F36*L34/L36 -> 1668.2524 | G34: * | H34: =H36*L34/L36 -> 1585.6089 | J34: CLOSED | L34: 1676.095 | N34: CLOSED | O34: =SUM(F34:N34) -> 4929.9562
A35: 43814 | B35: Sun | C35: -0.8 | D35: 0.87013889 | E35: * | F35: =F33*J35/J33 -> 218.05044 | G35: * | H35: =H31*J35/J31 -> 334.50085 | J35: 382.97872 | L35: CLOSED | N35: CLOSED | O35: =SUM(F35:N35) -> 935.53001
A36: 43815 | B36: Mon | C36: -0.4 | D36: 0.90347222 | F36: 87.1814 | H36: 82.862521 | J36: CLOSED | L36: 87.591244 | N36: CLOSED | O36: =SUM(F36:N36) -> 257.63517
A38: 43822 | B38: Mon | C38: -0.4 | D38: 0.69097222 | F38: =(645.854141341805/1002.43837573607*989.510443316819)+989.510443316819 -> 1627.0353 | G38: * | H38: =H40*L38/L40 -> 639.19477 | J38: CLOSED | L38: 1240.07 | N38: CLOSED | O38: =SUM(F38:N38) -> 3506.3001
A39: 43825 | B39: Thu | C39: -1.1 | D39: 0.78263889 | F39: =645.854141341805+1002.43837573607 -> 1648.2925 | G39: * | H39: =H41*J39/J41 -> 1586.9084 | J39: 1843.1761 | L39: CLOSED | N39: CLOSED | O39: =SUM(F39:N39) -> 5078.377
A40: 43826 | B40: Fri | C40: -0.9 | D40: 0.80972222 | E40: * | F40: =F38*L40/L38 -> 2566.0581 | H40: 1008.0979 | J40: CLOSED | L40: 1955.7607 | N40: CLOSED | O40: =SUM(F40:N40) -> 5529.9166
A41: 43827 | B41: Sat | C41: -0.6 | D41: 0.83680556 | F41: =(645.854141341805/1002.43837573607*637.789284700683)+637.789284700683 -> 1048.7062 | H41: 1335.2727 | J41: 1550.9041 | L41: CLOSED | N41: CLOSED | O41: =SUM(F41:N41) -> 3934.8829
A42: 43828 | B42: Sun | C42: -0.2 | D42: 0.86319444 | E42: * | F42: =F38*L42/L38 -> 732.64174 | G42: * | H42: =H40*L42/L40 -> 287.82458 | J42: CLOSED | L42: 558.39418 | N42: CLOSED | O42: =SUM(F42:N42) -> 1578.8605
A44: 43838 | B44: Wed | C44: -0.3 | D44: 0.71180556 | F44: =(645.854141341805/1002.43837573607*302.447538328286)+302.447538328286 -> 497.30939 | G44: * | H44: =(H50/L50*L44) -> 218.44573 | J44: CLOSED | L44: 255.47446 | N44: CLOSED | O44: =SUM(F44:N44) -> 971.22958
A45: 43839 | B45: Thu | C45: -0.8 | D45: 0.74097222 | F45: =(645.854141341805/1002.43837573607*307.692293328198)+307.692293328198 -> 505.93325 | H45: 519.77399 | J45: 1027.6243 | L45: CLOSED | N45: CLOSED | O45: =SUM(F45:N45) -> 2053.3316
A46: 43840 | B46: Fri | C46: -1.2 | D46: 0.77013889 | E46: * | F46: =(F44/L44*L46) -> 752.6896 | G46: * | H46: =(H50/L50*L46) -> 330.62282 | J46: CLOSED | L46: 386.66668 | N46: CLOSED | O46: =SUM(F46:N46) -> 1469.9791
...

Sheet CPUE
A1: Date | B1: Day | C1: Tide | D1: Time | E1: Longbeach | G1: Twin Harbors | I1: Copalis | K1: Mocrocks | M1: Kalaloch | O1: Daily Totals
A2: 43735 | B2: Fri | C2: -0.9 | D2: 0.24444444 | F2: =+Harvest!F2/Effort!F2 -> 14 | H2: CLOSED | J2: CLOSED | L2: CLOSED | N2: CLOSED | O2: =+Harvest!O2/Effort!O2 -> 14 | Q2: =AVERAGE(O2:O11) -> 14.779905
A3: 43736 | B3: Sat | C3: -0.8 | D3: 0.275 | F3: =+Harvest!F3/Effort!F3 -> 15 | H3: CLOSED | J3: CLOSED | L3: CLOSED | N3: CLOSED | O3: =+Harvest!O3/Effort!O3 -> 15
A4: 43737 | B4: Sun | C4: -0.6 | D4: 0.30486111 | E4: ** | F4: =+Harvest!F4/Effort!F4 -> 15 | H4: CLOSED | J4: CLOSED | L4: CLOSED | N4: CLOSED | O4: =+Harvest!O4/Effort!O4 -> 15
A6: 43764 | B6: Sat | C6: 0 | D6: 0.74930556 | F6: =+Harvest!F6/Effort!F6 -> 14.999991 | H6: =+Harvest!H6/Effort!H6 -> 15 | J6: =+Harvest!J6/Effort!J6 -> 15.000061 | L6: CLOSED | N6: CLOSED | O6: =+Harvest!O6/Effort!O6 -> 15.00002
A7: 43765 | B7: Sun | C7: -0.8 | D7: 0.78263889 | E7: * | F7: =+Harvest!F7/Effort!F7 -> 14.999999 | H7: =+Harvest!H7/Effort!H7 -> 15 | J7: CLOSED | L7: =+Harvest!L7/Effort!L7 -> 15 | N7: CLOSED | O7: =+Harvest!O7/Effort!O7 -> 15
A8: 43766 | B8: Mon | C8: -1.2 | D8: 0.81458333 | E8: * | F8: =+Harvest!F8/Effort!F8 -> 14.822511 | G8: * | H8: =+Harvest!H8/Effort!H8 -> 14.82252 | J8: =+Harvest!J8/Effort!J8 -> 14.822581 | L8: CLOSED | N8: CLOSED | O8: =+Harvest!O8/Effort!O8 -> 14.82254
A9: 43767 | B9: Tue | C9: -1.4 | D9: 0.84583333 | F9: =+Harvest!F9/Effort!F9 -> 15 | G9: * | H9: =+Harvest!H9/Effort!H9 -> 14.914894 | J9: CLOSED | L9: =+Harvest!L9/Effort!L9 -> 14.914894 | N9: CLOSED | O9: =+Harvest!O9/Effort!O9 -> 14.9392
A10: 43768 | B10: Wed | C10: -1.2 | D10: 0.87708333 | E10: * | F10: =+Harvest!F10/Effort!F10 -> 14.166601 | H10: =+Harvest!H10/Effort!H10 -> 14.692308 | J10: =+Harvest!J10/Effort!J10 -> 14.166667 | L10: CLOSED | N10: CLOSED | O10: =+Harvest!O10/Effort!O10 -> 14.257381
A11: 43769 | B11: Thu | C11: -0.8 | D11: 0.90972222 | E11: * | F11: 15 | G11: * | H11: =+Harvest!H11/Effort!H11 -> 15 | J11: CLOSED | L11: =+Harvest!L11/Effort!L11 -> 15 | N11: CLOSED | O11: =+Harvest!O11/Effort!O11 -> 15
A12: 43770 | B12: Fri | C12: -0.2 | D12: 0.94305556 | E12: * | F12: =+Harvest!F12/Effort!F12 -> 14.35483 | H12: =+Harvest!H12/Effort!H12 -> 14.354839 | J12: =+Harvest!J12/Effort!J12 -> 15 | L12: CLOSED | N12: CLOSED | O12: =+Harvest!O12/Effort!O12 -> 14.615455
A14: 43780 | B14: Mon | C14: 0.1 | D14: 0.74375 | E14: * | F14: 15 | G14: * | H14: 15 | J14: =+Harvest!J14/Effort!J14 -> 15 | L14: CLOSED | N14: CLOSED | O14: =+Harvest!O14/Effort!O14 -> 15
A15: 43781 | B15: Tue | C15: -0.3 | D15: 0.76875 | F15: =+Harvest!F15/Effort!F15 -> 15 | H15: =+Harvest!H15/Effort!H15 -> 15 | J15: CLOSED | L15: =+Harvest!L15/Effort!L15 -> 14.333333 | N15: CLOSED | O15: =+Harvest!O15/Effort!O15 -> 14.768644
A16: 43782 | B16: Wed | C16: -0.5 | D16: 0.79375 | E16: * | F16: 15 | G16: * | H16: =+Harvest!H16/Effort!H16 -> 14.948471 | J16: =+Harvest!J16/Effort!J16 -> 14.87037 | L16: CLOSED | N16: CLOSED | O16: =+Harvest!O16/Effort!O16 -> 14.925348
A17: 43783 | B17: Thu | C17: -0.6 | D17: 0.82013889 | E17: * | F17: =+Harvest!F17/Effort!F17 -> 13.282648 | G17: * | H17: =+Harvest!H17/Effort!H17 -> 13.282648 | J17: CLOSED | L17: =+Harvest!L17/Effort!L17 -> 12.692308 | N17: CLOSED | O17: =+Harvest!O17/Effort!O17 -> 13.07778
A18: 43784 | B18: Fri | C18: -0.5 | D18: 0.84861111 | F18: =+Harvest!F18/Effort!F18 -> 15.000004 | H18: =+Harvest!H18/Effort!H18 -> 14.142857 | J18: =+Harvest!J18/Effort!J18 -> 14.068966 | L18: CLOSED | N18: CLOSED | O18: =+Harvest!O18/Effort!O18 -> 14.330686
A19: 43785 | B19: Sat | C19: -0.3 | D19: 0.88055556 | F19: =+Harvest!F19/Effort!F19 -> 15 | G19: * | H19: =+Harvest!H19/Effort!H19 -> 14.142854 | J19: CLOSED | L19: =+Harvest!L19/Effort!L19 -> 14.754098 | N19: CLOSED | O19: =+Harvest!O19/Effort!O19 -> 14.61776
A20: 43786 | B20: Sun | C20: -0.1 | D20: 0.91597222 | E20: * | F20: =+Harvest!F20/Effort!F20 -> 15 | H20: =+Harvest!H20/Effort!H20 -> 15 | J20: =+Harvest!J20/Effort!J20 -> 12.84 | L20: CLOSED | N20: CLOSED | O20: =+Harvest!O20/Effort!O20 -> 13.945332
A22: 43793 | B22: Sun | C22: -0.4 | D22: 0.69930556 | F22: =+Harvest!F22/Effort!F22 -> 14.425167 | G22: * | H22: =+Harvest!H22/Effort!H22 -> 12.129607 | J22: =+Harvest!J22/Effort!J22 -> 14.0625 | L22: CLOSED | N22: CLOSED | O22: =+Harvest!O22/Effort!O22 -> 13.885617
A23: 43794 | B23: Mon | C23: -1 | D23: 0.73194444 | E23: * | F23: 15 | H23: =+Harvest!H23/Effort!H23 -> 13.894737 | J23: CLOSED | L23: =+Harvest!L23/Effort!L23 -> 14.363636 | N23: CLOSED | O23: =+Harvest!O23/Effort!O23 -> 14.510325
A24: 43795 | B24: Tue | C24: -1.3 | D24: 0.7625 | E24: * | F24: =+Harvest!F24/Effort!F24 -> 14.87395 | G24: * | H24: =+Harvest!H24/Effort!H24 -> 12.506972 | J24: =+Harvest!J24/Effort!J24 -> 14.5 | L24: CLOSED | N24: CLOSED | O24: =+Harvest!O24/Effort!O24 -> 14.317614
A25: 43796 | B25: Wed | C25: -1.4 | D25: 0.79305556 | F25: 15 | G25: * | H25: =+Harvest!H25/Effort!H25 -> 9.8808413 | J25: CLOSED | L25: =+Harvest!L25/Effort!L25 -> 10.214286 | N25: CLOSED | O25: =+Harvest!O25/Effort!O25 -> 12.38167
A26: 43797 | B26: Thu | C26: -1.2 | D26: 0.82222222 | E26: * | F26: =+Harvest!F26/Effort!F26 -> 14.95699 | G26: * | H26: =+Harvest!H26/Effort!H26 -> 12.576798 | J26: =+Harvest!J26/Effort!J26 -> 14.580952 | L26: CLOSED | N26: CLOSED | O26: =+Harvest!O26/Effort!O26 -> 14.397548
A27: 43798 | B27: Fri | C27: -0.7 | D27: 0.85347222 | E27: * | F27: 15 | G27: * | H27: =+Harvest!H27/Effort!H27 -> 14.440228 | J27: CLOSED | L27: =+Harvest!L27/Effort!L27 -> 14.927536 | N27: CLOSED | O27: =+Harvest!O27/Effort!O27 -> 14.848583
A28: 43799 | B28: Sat | C28: -0.2 | D28: 0.88194444 | F28: =+Harvest!F28/Effort!F28 -> 14.836664 | H28: =+Harvest!H28/Effort!H28 -> 12.027778 | J28: =+Harvest!J28/Effort!J28 -> 13.944444 | L28: CLOSED | N28: CLOSED | O28: =+Harvest!O28/Effort!O28 -> 13.859525
A30: 43809 | B30: Tue | C30: -0.2 | D30: 0.72777778 | E30: * | F30: =+Harvest!F30/Effort!F30 -> 11.620689 | G30: * | H30: =+Harvest!H30/Effort!H30 -> 8.9091954 | J30: CLOSED | L30: =+Harvest!L30/Effort!L30 -> 11.62069 | N30: CLOSED | O30: =+Harvest!O30/Effort!O30 -> 10.748599
A31: 43810 | B31: Wed | C31: -0.6 | D31: 0.75416667 | E31: * | F31: =+Harvest!F31/Effort!F31 -> 3.8354128 | H31: =+Harvest!H31/Effort!H31 -> 1.8 | J31: =+Harvest!J31/Effort!J31 -> 7.75 | L31: CLOSED | N31: CLOSED | O31: =+Harvest!O31/Effort!O31 -> 4.7101643
A32: 43811 | B32: Thu | C32: -0.9 | D32: 0.78125 | E32: * | F32: =+Harvest!F32/Effort!F32 -> 0.9166666 | G32: * | H32: =+Harvest!H32/Effort!H32 -> 0.70277778 | J32: CLOSED | L32: =+Harvest!L32/Effort!L32 -> 0.91666667 | N32: CLOSED | O32: =+Harvest!O32/Effort!O32 -> 0.84787412
A33: 43812 | B33: Fri | C33: -1 | D33: 0.80972222 | F33: =+Harvest!F33/Effort!F33 -> 6.4138 | G33: * | H33: =+Harvest!H33/Effort!H33 -> 3.0100645 | J33: =+Harvest!J33/Effort!J33 -> 12.96 | L33: CLOSED | N33: CLOSED | O33: =+Harvest!O33/Effort!O33 -> 7.8766102
A34: 43813 | B34: Sat | C34: -1 | D34: 0.83888889 | E34: * | F34: =+Harvest!F34/Effort!F34 -> 14.954544 | G34: * | H34: =+Harvest!H34/Effort!H34 -> 11.465152 | J34: CLOSED | L34: =+Harvest!L34/Effort!L34 -> 14.954545 | N34: CLOSED | O34: =+Harvest!O34/Effort!O34 -> 13.83226
A35: 43814 | B35: Sun | C35: -0.8 | D35: 0.87013889 | E35: * | F35: 15 | G35: * | H35: 15 | J35: =+Harvest!J35/Effort!J35 -> 15 | L35: CLOSED | N35: CLOSED | O35: =+Harvest!O35/Effort!O35 -> 15
A36: 43815 | B36: Mon | C36: -0.4 | D36: 0.90347222 | F36: =+Harvest!F36/Effort!F36 -> 14.999999 | H36: =+Harvest!H36/Effort!H36 -> 11.5 | J36: CLOSED | L36: =+Harvest!L36/Effort!L36 -> 15 | N36: CLOSED | O36: =+Harvest!O36/Effort!O36 -> 13.874304
A38: 43822 | B38: Mon | C38: -0.4 | D38: 0.69097222 | F38: 15 | G38: * | H38: 15 | J38: CLOSED | L38: =+Harvest!L38/Effort!L38 -> 14.945455 | N38: CLOSED | O38: =+Harvest!O38/Effort!O38 -> 14.980709
A39: 43825 | B39: Thu | C39: -1.1 | D39: 0.78263889 | F39: =+Harvest!F39/Effort!F39 -> 10.965538 | G39: * | H39: 10 | J39: =+Harvest!J39/Effort!J39 -> 8.7704918 | L39: CLOSED | N39: CLOSED | O39: =+Harvest!O39/Effort!O39 -> 9.8671406
A40: 43826 | B40: Fri | C40: -0.9 | D40: 0.80972222 | E40: * | F40: 6.5 | H40: =+Harvest!H40/Effort!H40 -> 6.5283019 | J40: CLOSED | L40: =+Harvest!L40/Effort!L40 -> 3.0135135 | N40: CLOSED | O40: =+Harvest!O40/Effort!O40 -> 5.2720968
A41: 43827 | B41: Sat | C41: -0.6 | D41: 0.83680556 | F41: 13.695652 | H41: =+Harvest!H41/Effort!H41 -> 13.235294 | J41: =+Harvest!J41/Effort!J41 -> 8.6818182 | L41: CLOSED | N41: CLOSED | O41: =+Harvest!O41/Effort!O41 -> 11.563269
A42: 43828 | B42: Sun | C42: -0.2 | D42: 0.86319444 | E42: * | F42: 13.4 | G42: * | H42: 13.4 | J42: CLOSED | L42: =+Harvest!L42/Effort!L42 -> 13.424242 | N42: CLOSED | O42: =+Harvest!O42/Effort!O42 -> 13.408574
A44: 43838 | B44: Wed | C44: -0.3 | D44: 0.71180556 | F44: 15 | G44: * | H44: 15 | J44: CLOSED | L44: =+Harvest!L44/Effort!L44 -> 14.545455 | N44: CLOSED | O44: =+Harvest!O44/Effort!O44 -> 14.880435
A45: 43839 | B45: Thu | C45: -0.8 | D45: 0.74097222 | F45: 15 | H45: =+Harvest!H45/Effort!H45 -> 14.970588 | J45: =+Harvest!J45/Effort!J45 -> 15 | L45: CLOSED | N45: CLOSED | O45: =+Harvest!O45/Effort!O45 -> 14.992555
A46: 43840 | B46: Fri | C46: -1.2 | D46: 0.77013889 | E46: * | F46: 5 | G46: * | H46: 5 | J46: CLOSED | L46: =+Harvest!L46/Effort!L46 -> 2.2777778 | N46: CLOSED | O46: =+Harvest!O46/Effort!O46 -> 4.2839404
...

Sheet Summary Table
A1: 2019-2020 State (non-Indian) Recreational Razor Clam Effort, Harvest and CPUE totals.
E2: LONG BEACH | H2: TWIN HARBORS | K2: COPALIS | N2: MOCROCKS | Q2: KALALOCH | T2: DAILY TOTALS
A3: DATE | B3: DAY | C3: TIDE | D3: TIME | E3: Effort | F3: Harvest | G3: CPUE | H3: Effort | I3: Harvest | J3: CPUE | K3: Effort | L3: Harvest | M3: CPUE | N3: Effort | O3: Harvest | P3: CPUE | Q3: Effort | R3: Harvest | S3: CPUE | T3: Effort | U3: Harvest
A4: 43735 | B4: =+A4 -> 43735 | C4: -0.6 | D4: 0.87361111 | E4: =Effort!F2 -> 2262.6377 | F4: =Harvest!F2 -> 31676.927 | G4: =+CPUE!F2 -> 14 | H4: =Effort!H2 -> CLOSED | I4: =Harvest!H2 -> CLOSED | J4: =CPUE!H2 -> CLOSED | K4: =Effort!J2 -> CLOSED | L4: =Harvest!J2 -> CLOSED | M4: =CPUE!J2 -> CLOSED | N4: =Effort!L2 -> CLOSED | O4: =Harvest!L2 -> CLOSED | P4: =CPUE!L2 -> CLOSED | Q4: =Effort!N2 -> CLOSED | R4: =Harvest!N2 -> CLOSED | S4: =CPUE!N2 -> CLOSED | T4: =+E4 -> 2262.6377 | U4: =F4 -> 31676.927
A5: 43736 | B5: =+A5 -> 43736 | C5: -0.3 | D5: 0.90347222 | E5: =Effort!F3 -> 8338.2153 | F5: =Harvest!F3 -> 125073.23 | G5: =+CPUE!F3 -> 15 | H5: =Effort!H3 -> CLOSED | I5: =Harvest!H3 -> CLOSED | J5: =CPUE!H3 -> CLOSED | K5: =Effort!J3 -> CLOSED | L5: =Harvest!J3 -> CLOSED | M5: =CPUE!J3 -> CLOSED | N5: =Effort!L3 -> CLOSED | O5: =Harvest!L3 -> CLOSED | P5: =CPUE!L3 -> CLOSED | Q5: =Effort!N3 -> CLOSED | R5: =Harvest!N3 -> CLOSED | S5: =CPUE!N3 -> CLOSED | T5: =+E5 -> 8338.2153 | U5: =F5 -> 125073.23
A6: 43737 | B6: =+A6 -> 43737 | C6: 0.1 | D6: 0.93472222 | E6: =Effort!F4 -> 8000 | F6: =Harvest!F4 -> 120000 | G6: =+CPUE!F4 -> 15 | H6: =Effort!H4 -> CLOSED | I6: =Harvest!H4 -> CLOSED | J6: =CPUE!H4 -> CLOSED | K6: =Effort!J4 -> CLOSED | L6: =Harvest!J4 -> CLOSED | M6: =CPUE!J4 -> CLOSED | N6: =Effort!L4 -> CLOSED | O6: =Harvest!L4 -> CLOSED | P6: =CPUE!L4 -> CLOSED | Q6: =Effort!N4 -> CLOSED | R6: =Harvest!N4 -> CLOSED | S6: =CPUE!N4 -> CLOSED | T6: =+E6 -> 8000 | U6: =F6 -> 120000
A7: Tide Series Totals | E7: =SUM(E4:E6) -> 18600.853 | F7: =SUM(F4:F6) -> 276750.16 | G7: =+F7/E7 -> 14.878358 | T7: =SUM(T4:T6) -> 18600.853 | U7: =SUM(U4:U6) -> 276750.16
A8: 43764 | B8: Sat | C8: 0 | D8: 0.74930556 | E8: =Effort!F6 -> 7854.35 | F8: =Harvest!F6 -> 117815.18 | G8: =+CPUE!F6 -> 14.999991 | H8: =Effort!H6 -> 3611.7461 | I8: =Harvest!H6 -> 54176.192 | J8: =CPUE!H6 -> 15 | K8: =Effort!J6 -> 7348.1701 | L8: =Harvest!J6 -> 110223 | M8: =CPUE!J6 -> 15.000061 | N8: =Effort!L6 -> CLOSED | O8: =Harvest!L6 -> CLOSED | P8: =CPUE!L6 -> CLOSED | Q8: CLOSED | R8: CLOSED | S8: CLOSED | T8: =SUM(E8+H8+K8) -> 18814.266 | U8: =SUM(F8+I8+L8) -> 282214.37
A9: 43765 | B9: Sun | C9: -0.8 | D9: 0.78263889 | E9: =Effort!F7 -> 5198.148 | F9: =Harvest!F7 -> 77972.215 | G9: =+CPUE!F7 -> 14.999999 | H9: =Effort!H7 -> 2390.323 | I9: =Harvest!H7 -> 35854.845 | J9: =CPUE!H7 -> 15 | K9: =Effort!J7 -> CLOSED | L9: =Harvest!J7 -> CLOSED | M9: =CPUE!J7 -> CLOSED | N9: =Effort!L7 -> 4926.3202 | O9: =Harvest!L7 -> 73894.802 | P9: =CPUE!L7 -> 15 | Q9: CLOSED | R9: CLOSED | S9: CLOSED | T9: =SUM(E9+H9+N9) -> 12514.791 | U9: =SUM(F9+I9+O9) -> 187721.86
A10: 43766 | B10: Mon | C10: -1.2 | D10: 0.81458333 | E10: =Effort!F8 -> 3142.5845 | F10: =Harvest!F8 -> 46580.995 | G10: =+CPUE!F8 -> 14.822511 | H10: =Effort!H8 -> 1445.0868 | I10: =Harvest!H8 -> 21419.828 | J10: =CPUE!H8 -> 14.82252 | K10: =Effort!J8 -> 2940.0581 | L10: =Harvest!J8 -> 43579.248 | M10: =CPUE!J8 -> 14.822581 | N10: =Effort!L8 -> CLOSED | O10: =Harvest!L8 -> CLOSED | P10: =CPUE!L8 -> CLOSED | Q10: CLOSED | R10: CLOSED | S10: CLOSED | T10: =SUM(E10+H10+K10) -> 7527.7294 | U10: =SUM(F10+I10+L10) -> 111580.07
A11: 43767 | B11: Tue | C11: -1.4 | D11: 0.84583333 | E11: =Effort!F9 -> 1021.805 | F11: =Harvest!F9 -> 15327.075 | G11: =+CPUE!F9 -> 15 | H11: =Effort!H9 -> 834.99935 | I11: =Harvest!H9 -> 12453.927 | J11: =CPUE!H9 -> 14.914894 | K11: =Effort!J9 -> CLOSED | L11: =Harvest!J9 -> CLOSED | M11: =CPUE!J9 -> CLOSED | N11: =Effort!L9 -> 1720.8863 | O11: =Harvest!L9 -> 25666.837 | P11: =CPUE!L9 -> 14.914894 | Q11: CLOSED | R11: CLOSED | S11: CLOSED | T11: =SUM(E11+H11+N11) -> 3577.6907 | U11: =SUM(F11+I11+O11) -> 53447.838
A12: 43768 | B12: Wed | C12: -1.2 | D12: 0.87708333 | E12: =Effort!F10 -> 888.31726 | F12: =Harvest!F10 -> 12584.436 | G12: =+CPUE!F10 -> 14.166601 | H12: =Effort!H10 -> 358.75183 | I12: =Harvest!H10 -> 5270.8922 | J12: =CPUE!H10 -> 14.692308 | K12: =Effort!J10 -> 831.06894 | L12: =Harvest!J10 -> 11773.477 | M12: =CPUE!J10 -> 14.166667 | N12: =Effort!L10 -> CLOSED | O12: =Harvest!L10 -> CLOSED | P12: =CPUE!L10 -> CLOSED | Q12: CLOSED | R12: CLOSED | S12: CLOSED | T12: =SUM(E12+H12+K12) -> 2078.138 | U12: =SUM(F12+I12+L12) -> 29628.805
A13: 43769 | B13: Thu | C13: -0.8 | D13: 0.90972222 | E13: =Effort!F11 -> 160.53772 | F13: =Harvest!F11 -> 2408.0658 | G13: =+CPUE!F11 -> 15 | H13: =Effort!H11 -> 131.18833 | I13: =Harvest!H11 -> 1967.825 | J13: =CPUE!H11 -> 15 | K13: =Effort!J11 -> CLOSED | L13: =Harvest!J11 -> CLOSED | M13: =CPUE!J11 -> CLOSED | N13: =Effort!L11 -> 270.37172 | O13: =Harvest!L11 -> 4055.5758 | P13: =CPUE!L11 -> 15 | Q13: CLOSED | R13: CLOSED | S13: CLOSED | T13: =SUM(E13+H13+N13) -> 562.09777 | U13: =SUM(F13+I13+O13) -> 8431.4666
A14: 43770 | B14: Fri | C14: -0.2 | D14: 0.94305556 | E14: =Effort!F12 -> 752.81653 | F14: =Harvest!F12 -> 10806.553 | G14: =+CPUE!F12 -> 14.35483 | H14: =Effort!H12 -> 346.17533 | I14: =Harvest!H12 -> 4969.291 | J14: =CPUE!H12 -> 14.354839 | K14: =Effort!J12 -> 744.83295 | L14: =Harvest!J12 -> 11172.494 | M14: =CPUE!J12 -> 15 | N14: =Effort!L12 -> CLOSED | O14: =Harvest!L12 -> CLOSED | P14: =CPUE!L12 -> CLOSED | Q14: CLOSED | R14: CLOSED | S14: CLOSED | T14: =SUM(E14+H14+K14) -> 1843.8248 | U14: =SUM(F14+I14+L14) -> 26948.339
A15: Tide Series Totals | E15: =SUM(E8:E14) -> 19018.559 | F15: =SUM(F8:F14) -> 283494.52 | G15: =+F15/E15 -> 14.906204 | H15: =SUM(H8:H14) -> 9118.2707 | I15: =SUM(I8:I14) -> 136112.8 | J15: =+I15/H15 -> 14.92748 | K15: =SUM(K8:K14) -> 11864.13 | L15: =SUM(L8:L14) -> 176748.22 | M15: =+L15/K15 -> 14.897697 | N15: =SUM(N8:N14) -> 6917.5782 | O15: =SUM(O8:O14) -> 103617.21 | P15: =+O15/N15 -> 14.978828 | T15: =SUM(T8:T14) -> 46918.538 | U15: =SUM(U8:U14) -> 699972.75
A16: 43780 | B16: Mon | C16: 0.1 | D16: 0.74375 | E16: =Effort!F14 -> 1044.2737 | F16: =Harvest!F14 -> 15664.105 | G16: =+CPUE!F14 -> 15 | H16: =Effort!H14 -> 1100.4607 | I16: =Harvest!H14 -> 16506.91 | J16: =CPUE!H14 -> 15 | K16: =Effort!J14 -> 1880.8273 | L16: =Harvest!J14 -> 28212.409 | M16: =CPUE!J14 -> 15 | N16: =Effort!L14 -> CLOSED | O16: =Harvest!L14 -> CLOSED | P16: =CPUE!L14 -> CLOSED | Q16: CLOSED | R16: CLOSED | S16: CLOSED | T16: =SUM(E16+H16+K16) -> 4025.5616 | U16: =SUM(F16+I16+L16) -> 60383.425
A17: 43781 | B17: Tue | C17: -0.3 | D17: 0.76875 | E17: =Effort!F15 -> 1066.5498 | F17: =Harvest!F15 -> 15998.247 | G17: =+CPUE!F15 -> 15 | H17: =Effort!H15 -> 716.19051 | I17: =Harvest!H15 -> 10742.858 | J17: =CPUE!H15 -> 15 | K17: =Effort!J15 -> CLOSED | L17: =Harvest!J15 -> CLOSED | M17: =CPUE!J15 -> CLOSED | N17: =Effort!L15 -> 947.47897 | O17: =Harvest!L15 -> 13580.532 | P17: =CPUE!L15 -> 14.333333 | Q17: CLOSED | R17: CLOSED | S17: CLOSED | T17: =SUM(E17+H17+N17) -> 2730.2193 | U17: =SUM(F17+I17+O17) -> 40321.637
A18: 43782 | B18: Wed | C18: -0.5 | D18: 0.79375 | E18: =Effort!F16 -> 470.44496 | F18: =Harvest!F16 -> 7056.6744 | G18: =+CPUE!F16 -> 15 | H18: =Effort!H16 -> 495.75719 | I18: =Harvest!H16 -> 7410.812 | J18: =CPUE!H16 -> 14.948471 | K18: =Effort!J16 -> 847.31208 | L18: =Harvest!J16 -> 12599.845 | M18: =CPUE!J16 -> 14.87037 | N18: =Effort!L16 -> CLOSED | O18: =Harvest!L16 -> CLOSED | P18: =CPUE!L16 -> CLOSED | Q18: CLOSED | R18: CLOSED | S18: CLOSED | T18: =SUM(E18+H18+K18) -> 1813.5142 | U18: =SUM(F18+I18+L18) -> 27067.331
A19: 43783 | B19: Thu | C19: -0.6 | D19: 0.82013889 | E19: =Effort!F17 -> 684.82272 | F19: =Harvest!F17 -> 9096.2589 | G19: =+CPUE!F17 -> 13.282648 | H19: =Effort!H17 -> 459.85994 | I19: =Harvest!H17 -> 6108.1576 | J19: =CPUE!H17 -> 13.282648 | K19: =Effort!J17 -> CLOSED | L19: =Harvest!J17 -> CLOSED | M19: =CPUE!J17 -> CLOSED | N19: =Effort!L17 -> 608.36833 | O19: =Harvest!L17 -> 7721.5981 | P19: =CPUE!L17 -> 12.692308 | Q19: CLOSED | R19: CLOSED | S19: CLOSED | T19: =SUM(E19+H19+N19) -> 1753.051 | U19: =SUM(F19+I19+O19) -> 22926.015
A20: 43784 | B20: Fri | C20: -0.5 | D20: 0.84861111 | E20: =Effort!F18 -> 811.3358 | F20: =Harvest!F18 -> 12170.04 | G20: =+CPUE!F18 -> 15.000004 | H20: =Effort!H18 -> 854.98961 | I20: =Harvest!H18 -> 12091.996 | J20: =CPUE!H18 -> 14.142857 | K20: =Effort!J18 -> 1461.286 | L20: =Harvest!J18 -> 20558.782 | M20: =CPUE!J18 -> 14.068966 | N20: =Effort!L18 -> CLOSED | O20: =Harvest!L18 -> CLOSED | P20: =CPUE!L18 -> CLOSED | Q20: CLOSED | R20: CLOSED | S20: CLOSED | T20: =SUM(E20+H20+K20) -> 3127.6114 | U20: =SUM(F20+I20+L20) -> 44820.818
A21: 43785 | B21: Sat | C21: -0.3 | D21: 0.88055556 | E21: =Effort!F19 -> 2195.7856 | F21: =Harvest!F19 -> 32936.785 | G21: =+CPUE!F19 -> 15 | H21: =Effort!H19 -> 2313.9295 | I21: =Harvest!H19 -> 32725.568 | J21: =CPUE!H19 -> 14.142854 | K21: =Effort!J19 -> CLOSED | L21: =Harvest!J19 -> CLOSED | M21: =CPUE!J19 -> CLOSED | N21: =Effort!L19 -> 1903.9513 | O21: =Harvest!L19 -> 28091.085 | P21: =CPUE!L19 -> 14.754098 | Q21: CLOSED | R21: CLOSED | S21: CLOSED | T21: =SUM(E21+H21+N21) -> 6413.6665 | U21: =SUM(F21+I21+O21) -> 93753.437
A22: 43786 | B22: Sun | C22: -0.1 | D22: 0.91597222 | E22: =Effort!F20 -> 196.82442 | F22: =Harvest!F20 -> 2952.3664 | G22: =+CPUE!F20 -> 15 | H22: =Effort!H20 -> 132.16803 | I22: =Harvest!H20 -> 1982.5204 | J22: =CPUE!H20 -> 15 | K22: =Effort!J20 -> 313.91262 | L22: =Harvest!J20 -> 4030.638 | M22: =CPUE!J20 -> 12.84 | N22: =Effort!L20 -> CLOSED | O22: =Harvest!L20 -> CLOSED | P22: =CPUE!L20 -> CLOSED | Q22: CLOSED | R22: CLOSED | S22: CLOSED | T22: =SUM(E22+H22+K22) -> 642.90507 | U22: =SUM(F22+I22+L22) -> 8965.5248
A23: Tide Series Totals | E23: =SUM(E16:E22) -> 6470.037 | F23: =SUM(F16:F22) -> 95874.477 | G23: =+F23/E23 -> 14.818227 | H23: =SUM(H16:H22) -> 6073.3555 | I23: =SUM(I16:I22) -> 87568.821 | J23: =+I23/H23 -> 14.418524 | K23: =SUM(K16:K22) -> 4503.3379 | L23: =SUM(L16:L22) -> 65401.674 | M23: =+L23/K23 -> 14.522933 | N23: =SUM(N16:N22) -> 3459.7986 | O23: =SUM(O16:O22) -> 49393.215 | P23: =+O23/N23 -> 14.276327 | T23: =SUM(T16:T22) -> 20506.529 | U23: =SUM(U16:U22) -> 298238.19
A24: 43793 | B24: Sun | C24: -0.4 | D24: 0.69930556 | E24: =Effort!F22 -> 3014.032 | F24: =Harvest!F22 -> 43477.914 | G24: =+CPUE!F22 -> 14.425167 | H24: =Effort!H22 -> 1264.2011 | I24: =Harvest!H22 -> 15334.262 | J24: =CPUE!H22 -> 12.129607 | K24: =Effort!J22 -> 3356.6175 | L24: =Harvest!J22 -> 47202.433 | M24: =CPUE!J22 -> 14.0625 | N24: =Effort!L22 -> CLOSED | O24: =Harvest!L22 -> CLOSED | P24: =CPUE!L22 -> CLOSED | Q24: CLOSED | R24: CLOSED | S24: CLOSED | T24: =SUM(E24+H24+K24) -> 7634.8506 | U24: =SUM(F24+I24+L24) -> 106014.61
A25: 43794 | B25: Mon | C25: -1 | D25: 0.73194444 | E25: =Effort!F23 -> 1548.579 | F25: =Harvest!F23 -> 23228.685 | G25: =+CPUE!F23 -> 15 | H25: =Effort!H23 -> 942.04166 | I25: =Harvest!H23 -> 13089.421 | J25: =CPUE!H23 -> 13.894737 | K25: =Effort!J23 -> CLOSED | L25: =Harvest!J23 -> CLOSED | M25: =CPUE!J23 -> CLOSED | N25: =Effort!L23 -> 1216.1297 | O25: =Harvest!L23 -> 17468.045 | P25: =CPUE!L23 -> 14.363636 | Q25: CLOSED | R25: CLOSED | S25: CLOSED | T25: =SUM(E25+H25+N25) -> 3706.7504 | U25: =SUM(F25+I25+O25) -> 53786.151
A26: 43795 | B26: Tue | C26: -1.3 | D26: 0.7625 | E26: =Effort!F24 -> 1059.5404 | F26: =Harvest!F24 -> 15759.551 | G26: =+CPUE!F24 -> 14.87395 | H26: =Effort!H24 -> 444.41207 | I26: =Harvest!H24 -> 5558.2494 | J26: =CPUE!H24 -> 12.506972 | K26: =Effort!J24 -> 1179.9715 | L26: =Harvest!J24 -> 17109.587 | M26: =CPUE!J24 -> 14.5 | N26: =Effort!L24 -> CLOSED | O26: =Harvest!L24 -> CLOSED | P26: =CPUE!L24 -> CLOSED | Q26: CLOSED | R26: CLOSED | S26: CLOSED | T26: =SUM(E26+H26+K26) -> 2683.9241 | U26: =SUM(F26+I26+L26) -> 38427.388
A27: 43796 | B27: Wed | C27: -1.4 | D27: 0.79305556 | E27: =Effort!F25 -> 1220.542 | F27: =Harvest!F25 -> 18308.131 | G27: =+CPUE!F25 -> 15 | H27: =Effort!H25 -> 603.11256 | I27: =Harvest!H25 -> 5959.2595 | J27: =CPUE!H25 -> 9.8808413 | K27: =Effort!J25 -> CLOSED | L27: =Harvest!J25 -> CLOSED | M27: =CPUE!J25 -> CLOSED | N27: =Effort!L25 -> 778.58884 | O27: =Harvest!L25 -> 7952.7289 | P27: =CPUE!L25 -> 10.214286 | Q27: CLOSED | R27: CLOSED | S27: CLOSED | T27: =SUM(E27+H27+N27) -> 2602.2434 | U27: =SUM(F27+I27+O27) -> 32220.119
A28: 43797 | B28: Thu | C28: -1.2 | D28: 0.82222222 | E28: =Effort!F26 -> 1458.1812 | F28: =Harvest!F26 -> 21810.001 | G28: =+CPUE!F26 -> 14.95699 | H28: =Effort!H26 -> 611.61736 | I28: =Harvest!H26 -> 7692.1877 | J28: =CPUE!H26 -> 12.576798 | K28: =Effort!J26 -> 1623.9232 | L28: =Harvest!J26 -> 23678.347 | M28: =CPUE!J26 -> 14.580952 | N28: =Effort!L26 -> CLOSED | O28: =Harvest!L26 -> CLOSED | P28: =CPUE!L26 -> CLOSED | Q28: CLOSED | R28: CLOSED | S28: CLOSED | T28: =SUM(E28+H28+K28) -> 3693.7217 | U28: =SUM(F28+I28+L28) -> 53180.536
A29: 43798 | B29: Fri | C29: -0.7 | D29: 0.85208333 | E29: =Effort!F27 -> 3184.498 | F29: =Harvest!F27 -> 47767.47 | G29: =+CPUE!F27 -> 15 | H29: =Effort!H27 -> 1573.572 | I29: =Harvest!H27 -> 22722.739 | J29: =CPUE!H27 -> 14.440228 | K29: =Effort!J27 -> CLOSED | L29: =Harvest!J27 -> CLOSED | M29: =CPUE!J27 -> CLOSED | N29: =Effort!L27 -> 2031.4045 | O29: =Harvest!L27 -> 30323.865 | P29: =CPUE!L27 -> 14.927536 | Q29: CLOSED | R29: CLOSED | S29: CLOSED | T29: =SUM(E29+H29+N29) -> 6789.4745 | U29: =SUM(F29+I29+O29) -> 100814.07
A30: 43799 | B30: Sat | C30: -0.2 | D30: 0.88194444 | E30: =Effort!F28 -> 938.41458 | F30: =Harvest!F28 -> 13922.942 | G30: =+CPUE!F28 -> 14.836664 | H30: =Effort!H28 -> 570.86247 | I30: =Harvest!H28 -> 6866.207 | J30: =CPUE!H28 -> 12.027778 | K30: =Effort!J28 -> 1515.7137 | L30: =Harvest!J28 -> 21135.786 | M30: =CPUE!J28 -> 13.944444 | N30: =Effort!L28 -> CLOSED | O30: =Harvest!L28 -> CLOSED | P30: =CPUE!L28 -> CLOSED | Q30: CLOSED | R30: CLOSED | S30: CLOSED | T30: =SUM(E30+H30+K30) -> 3024.9908 | U30: =SUM(F30+I30+L30) -> 41924.935
A31: Tide Series Totals | E31: =SUM(E24:E30) -> 12423.787 | F31: =SUM(F24:F30) -> 184274.69 | G31: =+F31/E31 -> 14.832409 | H31: =SUM(H24:H30) -> 6009.8192 | I31: =SUM(I24:I30) -> 77222.325 | J31: =+I31/H31 -> 12.849359 | K31: =SUM(K24:K30) -> 7676.2259 | L31: =SUM(L24:L30) -> 109126.15 | M31: =+L31/K31 -> 14.216121 | N31: =SUM(N24:N30) -> 4026.1231 | O31: =SUM(O24:O30) -> 55744.639 | P31: =+O31/N31 -> 13.845736 | T31: =SUM(T24:T30) -> 30135.955 | U31: =SUM(U24:U30) -> 426367.81
A32: 43809 | B32: Tue | C32: -0.2 | D32: 0.72777778 | E32: =Effort!F30 -> 462.8974 | F32: =Harvest!F30 -> 5379.1866 | G32: =+CPUE!F30 -> 11.620689 | H32: =Effort!H30 -> 439.96593 | I32: =Harvest!H30 -> 3919.7424 | J32: =CPUE!H30 -> 8.9091954 | K32: =Effort!J30 -> CLOSED | L32: =Harvest!J30 -> CLOSED | M32: =CPUE!J30 -> CLOSED | N32: =Effort!L30 -> 465.0735 | O32: =Harvest!L30 -> 5404.4749 | P32: =CPUE!L30 -> 11.62069 | Q32: CLOSED | R32: CLOSED | S32: CLOSED | T32: =SUM(E32+H32+N32) -> 1367.9368 | U32: =SUM(F32+I32+O32) -> 14703.404
A33: 43810 | B33: Wed | C33: -0.6 | D33: 0.75416667 | E33: =Effort!F31 -> 165.48695 | F33: =Harvest!F31 -> 634.71077 | G33: =+CPUE!F31 -> 3.8354128 | H33: =Effort!H31 -> 253.86569 | I33: =Harvest!H31 -> 456.95824 | J33: =CPUE!H31 -> 1.8 | K33: =Effort!J31 -> 290.65742 | L33: =Harvest!J31 -> 2252.595 | M33: =CPUE!J31 -> 7.75 | N33: =Effort!L31 -> CLOSED | O33: =Harvest!L31 -> CLOSED | P33: =CPUE!L31 -> CLOSED | Q33: CLOSED | R33: CLOSED | S33: CLOSED | T33: =SUM(E33+H33+K33) -> 710.01006 | U33: =SUM(F33+I33+L33) -> 3344.264
A34: 43811 | B34: Thu | C34: -0.9 | D34: 0.78125 | E34: =Effort!F32 -> 271.60359 | F34: =Harvest!F32 -> 248.96994 | G34: =+CPUE!F32 -> 0.9166666 | H34: =Effort!H32 -> 258.14862 | I34: =Harvest!H32 -> 181.42112 | J34: =CPUE!H32 -> 0.70277778 | K34: =Effort!J32 -> CLOSED | L34: =Harvest!J32 -> CLOSED | M34: =CPUE!J32 -> CLOSED | N34: =Effort!L32 -> 272.88042 | O34: =Harvest!L32 -> 250.14038 | P34: =CPUE!L32 -> 0.91666667 | Q34: CLOSED | R34: CLOSED | S34: CLOSED | T34: =SUM(E34+H34+N34) -> 802.63263 | U34: =SUM(F34+I34+O34) -> 680.53144
A35: 43812 | B35: Fri | C35: -1 | D35: 0.80972222 | E35: =Effort!F33 -> 674.398 | F35: =Harvest!F33 -> 4325.4539 | G35: =+CPUE!F33 -> 6.4138 | H35: =Effort!H33 -> 1034.562 | I35: =Harvest!H33 -> 3114.0984 | J35: =CPUE!H33 -> 3.0100645 | K35: =Effort!J33 -> 1184.4969 | L35: =Harvest!J33 -> 15351.08 | M35: =CPUE!J33 -> 12.96 | N35: =Effort!L33 -> CLOSED | O35: =Harvest!L33 -> CLOSED | P35: =CPUE!L33 -> CLOSED | Q35: CLOSED | R35: CLOSED | S35: CLOSED | T35: =SUM(E35+H35+K35) -> 2893.457 | U35: =SUM(F35+I35+L35) -> 22790.633
A36: 43813 | B36: Sat | C36: -1 | D36: 0.83888889 | E36: =Effort!F34 -> 1668.2524 | F36: =Harvest!F34 -> 24947.955 | G36: =+CPUE!F34 -> 14.954544 | H36: =Effort!H34 -> 1585.6089 | I36: =Harvest!H34 -> 18179.246 | J36: =CPUE!H34 -> 11.465152 | K36: =Effort!J34 -> CLOSED | L36: =Harvest!J34 -> CLOSED | M36: =CPUE!J34 -> CLOSED | N36: =Effort!L34 -> 1676.095 | O36: =Harvest!L34 -> 25065.238 | P36: =CPUE!L34 -> 14.954545 | Q36: CLOSED | R36: CLOSED | S36: CLOSED | T36: =SUM(E36+H36+N36) -> 4929.9562 | U36: =SUM(F36+I36+O36) -> 68192.439
A37: 43814 | B37: Sun | C37: -0.8 | D37: 0.87013889 | E37: =Effort!F35 -> 218.05044 | F37: =Harvest!F35 -> 3270.7566 | G37: =+CPUE!F35 -> 15 | H37: =Effort!H35 -> 334.50085 | I37: =Harvest!H35 -> 5017.5128 | J37: =CPUE!H35 -> 15 | K37: =Effort!J35 -> 382.97872 | L37: =Harvest!J35 -> 5744.6807 | M37: =CPUE!J35 -> 15 | N37: =Effort!L35 -> CLOSED | O37: =Harvest!L35 -> CLOSED | P37: =CPUE!L35 -> CLOSED | Q37: CLOSED | R37: CLOSED | S37: CLOSED | T37: =SUM(E37+H37+K37) -> 935.53001 | U37: =SUM(F37+I37+L37) -> 14032.95
A38: 43815 | B38: Mon | C38: -0.4 | D38: 0.90347222 | E38: =Effort!F36 -> 87.1814 | F38: =Harvest!F36 -> 1307.7209 | G38: =+CPUE!F36 -> 14.999999 | H38: =Effort!H36 -> 82.862521 | I38: =Harvest!H36 -> 952.91899 | J38: =CPUE!H36 -> 11.5 | K38: =Effort!J36 -> CLOSED | L38: =Harvest!J36 -> CLOSED | M38: =CPUE!J36 -> CLOSED | N38: =Effort!L36 -> 87.591244 | O38: =Harvest!L36 -> 1313.8687 | P38: =CPUE!L36 -> 15 | Q38: CLOSED | R38: CLOSED | S38: CLOSED | T38: =SUM(E38+H38+N38) -> 257.63517 | U38: =SUM(F38+I38+O38) -> 3574.5086
A39: Tide Series Totals | E39: =SUM(E32:E38) -> 3547.8702 | F39: =SUM(F32:F38) -> 40114.753 | G39: =+F39/E39 -> 11.306714 | H39: =SUM(H32:H38) -> 3989.5145 | I39: =SUM(I32:I38) -> 31821.898 | J39: =+I39/H39 -> 7.9763836 | K39: =SUM(K32:K38) -> 1858.1331 | L39: =SUM(L32:L38) -> 23348.356 | M39: =+L39/K39 -> 12.565492 | N39: =SUM(N32:N38) -> 2501.6401 | O39: =SUM(O32:O38) -> 32033.722 | P39: =+O39/N39 -> 12.805088 | T39: =SUM(T32:T38) -> 11897.158 | U39: =SUM(U32:U38) -> 127318.73
A40: 43822 | B40: Mon | C40: -0.4 | D40: 0.69097222 | E40: =Effort!F38 -> 1627.0353 | F40: =Harvest!F38 -> 24405.53 | G40: =+CPUE!F38 -> 15 | H40: =Effort!H38 -> 639.19477 | I40: =Harvest!H38 -> 9587.9216 | J40: =CPUE!H38 -> 15 | K40: =Effort!J38 -> CLOSED | L40: =Harvest!J38 -> CLOSED | M40: =CPUE!J38 -> CLOSED | N40: =Effort!L38 -> 1240.07 | O40: =Harvest!L38 -> 18533.41 | P40: =CPUE!L38 -> 14.945455 | Q40: CLOSED | R40: CLOSED | S40: CLOSED | T40: =SUM(E40+H40+N40) -> 3506.3001 | U40: =SUM(F40+I40+O40) -> 52526.862
...

Sheet Tribal Update
A1: 2019-2020 State (non-Indian) Recreational Razor Clam Effort, Harvest and CPUE totals.
E2: COPALIS | I2: MOCROCKS | M2: KALALOCH | Q2: DAILY TOTALS
A3: DATE | B3: DAY | C3: TIDE | D3: TIME | E3: Effort | F3: Harvest | G3: CPUE | H3: Size (mm) | I3: Effort | J3: Harvest | K3: CPUE | L3: Size (mm) | M3: Effort | N3: Harvest | O3: CPUE | P3: Size (mm) | Q3: Effort | R3: Harvest
A4: 43764 | B4: Sat | C4: 0 | D4: 0.74930556 | E4: =Effort!J6 -> 7348.1701 | F4: =Harvest!J6 -> 110223 | G4: =CPUE!J6 -> 15.000061 | I4: =Effort!L6 -> CLOSED | J4: =Harvest!L6 -> CLOSED | K4: =CPUE!L6 -> CLOSED | M4: CLOSED | N4: CLOSED | O4: CLOSED | Q4: =E4 -> 7348.1701 | R4: =F4 -> 110223
A5: 43765 | B5: Sun | C5: -0.8 | D5: 0.78263889 | E5: =Effort!J7 -> CLOSED | F5: =Harvest!J7 -> CLOSED | G5: =CPUE!J7 -> CLOSED | I5: =Effort!L7 -> 4926.3202 | J5: =Harvest!L7 -> 73894.802 | K5: =CPUE!L7 -> 15 | M5: CLOSED | N5: CLOSED | O5: CLOSED | Q5: =SUM(E5,I5) -> 4926.3202 | R5: =SUM(F5,J5) -> 73894.802
A6: 43766 | B6: Mon | C6: -1.2 | D6: 0.81458333 | E6: =Effort!J8 -> 2940.0581 | F6: =Harvest!J8 -> 43579.248 | G6: =CPUE!J8 -> 14.822581 | I6: =Effort!L8 -> CLOSED | J6: =Harvest!L8 -> CLOSED | K6: =CPUE!L8 -> CLOSED | M6: CLOSED | N6: CLOSED | O6: CLOSED | Q6: =SUM(E6,I6) -> 2940.0581 | R6: =SUM(F6,J6) -> 43579.248
A7: 43767 | B7: Tue | C7: -1.4 | D7: 0.84583333 | E7: =Effort!J9 -> CLOSED | F7: =Harvest!J9 -> CLOSED | G7: =CPUE!J9 -> CLOSED | I7: =Effort!L9 -> 1720.8863 | J7: =Harvest!L9 -> 25666.837 | K7: =CPUE!L9 -> 14.914894 | M7: CLOSED | N7: CLOSED | O7: CLOSED | Q7: =SUM(E7,I7) -> 1720.8863 | R7: =SUM(F7,J7) -> 25666.837
A8: 43768 | B8: Wed | C8: -1.2 | D8: 0.87708333 | E8: =Effort!J10 -> 831.06894 | F8: =Harvest!J10 -> 11773.477 | G8: =CPUE!J10 -> 14.166667 | I8: =Effort!L10 -> CLOSED | J8: =Harvest!L10 -> CLOSED | K8: =CPUE!L10 -> CLOSED | M8: CLOSED | N8: CLOSED | O8: CLOSED | Q8: =SUM(E8,I8) -> 831.06894 | R8: =SUM(F8,J8) -> 11773.477
A9: 43769 | B9: Thu | C9: -0.8 | D9: 0.90972222 | E9: =Effort!J11 -> CLOSED | F9: =Harvest!J11 -> CLOSED | G9: =CPUE!J11 -> CLOSED | I9: =Effort!L11 -> 270.37172 | J9: =Harvest!L11 -> 4055.5758 | K9: =CPUE!L11 -> 15 | M9: CLOSED | N9: CLOSED | O9: CLOSED | Q9: =SUM(E9,I9) -> 270.37172 | R9: =SUM(F9,J9) -> 4055.5758
A10: 43770 | B10: Fri | C10: -0.2 | D10: 0.94305556 | E10: =Effort!J12 -> 744.83295 | F10: =Harvest!J12 -> 11172.494 | G10: =CPUE!J12 -> 15 | I10: =Effort!L12 -> CLOSED | J10: =Harvest!L12 -> CLOSED | K10: =CPUE!L12 -> CLOSED | M10: CLOSED | N10: CLOSED | O10: CLOSED | Q10: =SUM(E10,I10) -> 744.83295 | R10: =SUM(F10,J10) -> 11172.494
A11: Tide Series Totals | E11: =SUM(E4:E10) -> 11864.13 | F11: =SUM(F4:F10) -> 176748.22 | G11: =+F11/E11 -> 14.897697 | H11: 116.1 | I11: =SUM(I4:I10) -> 6917.5782 | J11: =SUM(J4:J10) -> 103617.21 | K11: =+J11/I11 -> 14.978828 | L11: 116.3 | Q11: =SUM(Q4:Q10) -> 18781.708 | R11: =SUM(R4:R10) -> 280365.43
A12: 43780 | B12: Mon | C12: 0.1 | D12: 0.74375 | E12: =Effort!J14 -> 1880.8273 | F12: =Harvest!J14 -> 28212.409 | G12: =CPUE!J14 -> 15 | I12: =Effort!L14 -> CLOSED | J12: =Harvest!L14 -> CLOSED | K12: =CPUE!L14 -> CLOSED | M12: CLOSED | N12: CLOSED | O12: CLOSED | Q12: =SUM(E12,I12) -> 1880.8273 | R12: =SUM(F12,J12) -> 28212.409
A13: 43781 | B13: Tue | C13: -0.3 | D13: 0.76875 | E13: =Effort!J15 -> CLOSED | F13: =Harvest!J15 -> CLOSED | G13: =CPUE!J15 -> CLOSED | I13: =Effort!L15 -> 947.47897 | J13: =Harvest!L15 -> 13580.532 | K13: =CPUE!L15 -> 14.333333 | M13: CLOSED | N13: CLOSED | O13: CLOSED | Q13: =SUM(E13,I13) -> 947.47897 | R13: =SUM(F13,J13) -> 13580.532
A14: 43782 | B14: Wed | C14: -0.5 | D14: 0.79375 | E14: =Effort!J16 -> 847.31208 | F14: =Harvest!J16 -> 12599.845 | G14: =CPUE!J16 -> 14.87037 | I14: =Effort!L16 -> CLOSED | J14: =Harvest!L16 -> CLOSED | K14: =CPUE!L16 -> CLOSED | M14: CLOSED | N14: CLOSED | O14: CLOSED | Q14: =SUM(E14,I14) -> 847.31208 | R14: =SUM(F14,J14) -> 12599.845
A15: 43783 | B15: Thu | C15: -0.6 | D15: 0.82013889 | E15: =Effort!J17 -> CLOSED | F15: =Harvest!J17 -> CLOSED | G15: =CPUE!J17 -> CLOSED | I15: =Effort!L17 -> 608.36833 | J15: =Harvest!L17 -> 7721.5981 | K15: =CPUE!L17 -> 12.692308 | M15: CLOSED | N15: CLOSED | O15: CLOSED | Q15: =SUM(E15,I15) -> 608.36833 | R15: =SUM(F15,J15) -> 7721.5981
A16: 43784 | B16: Fri | C16: -0.5 | D16: 0.84861111 | E16: =Effort!J18 -> 1461.286 | F16: =Harvest!J18 -> 20558.782 | G16: =CPUE!J18 -> 14.068966 | I16: =Effort!L18 -> CLOSED | J16: =Harvest!L18 -> CLOSED | K16: =CPUE!L18 -> CLOSED | M16: CLOSED | N16: CLOSED | O16: CLOSED | Q16: =SUM(E16,I16) -> 1461.286 | R16: =SUM(F16,J16) -> 20558.782
A17: 43785 | B17: Sat | C17: -0.3 | D17: 0.88055556 | E17: =Effort!J19 -> CLOSED | F17: =Harvest!J19 -> CLOSED | G17: =CPUE!J19 -> CLOSED | I17: =Effort!L19 -> 1903.9513 | J17: =Harvest!L19 -> 28091.085 | K17: =CPUE!L19 -> 14.754098 | M17: CLOSED | N17: CLOSED | O17: CLOSED | Q17: =SUM(E17,I17) -> 1903.9513 | R17: =SUM(F17,J17) -> 28091.085
A18: 43786 | B18: Sun | C18: -0.1 | D18: 0.91597222 | E18: =Effort!J20 -> 313.91262 | F18: =Harvest!J20 -> 4030.638 | G18: =CPUE!J20 -> 12.84 | I18: =Effort!L20 -> CLOSED | J18: =Harvest!L20 -> CLOSED | K18: =CPUE!L20 -> CLOSED | M18: CLOSED | N18: CLOSED | O18: CLOSED | Q18: =SUM(E18,I18) -> 313.91262 | R18: =SUM(F18,J18) -> 4030.638
A19: Tide Series Totals | E19: =SUM(E12:E18) -> 4503.3379 | F19: =SUM(F12:F18) -> 65401.674 | G19: =+F19/E19 -> 14.522933 | H19: 104.76 | I19: =SUM(I12:I18) -> 3459.7986 | J19: =SUM(J12:J18) -> 49393.215 | K19: =+J19/I19 -> 14.276327 | L19: 108.9 | Q19: =SUM(Q12:Q18) -> 7963.1366 | R19: =SUM(R12:R18) -> 114794.89
A20: 43793 | B20: Sun | C20: -0.4 | D20: 0.69930556 | E20: =Effort!J22 -> 3356.6175 | F20: =Harvest!J22 -> 47202.433 | G20: =CPUE!J22 -> 14.0625 | I20: =Effort!L22 -> CLOSED | J20: =Harvest!L22 -> CLOSED | K20: =CPUE!L22 -> CLOSED | M20: CLOSED | N20: CLOSED | O20: CLOSED | Q20: =SUM(E20,I20) -> 3356.6175 | R20: =SUM(F20,J20) -> 47202.433
A21: 43794 | B21: Mon | C21: -1 | D21: 0.73194444 | E21: =Effort!J23 -> CLOSED | F21: =Harvest!J23 -> CLOSED | G21: =CPUE!J23 -> CLOSED | I21: =Effort!L23 -> 1216.1297 | J21: =Harvest!L23 -> 17468.045 | K21: =CPUE!L23 -> 14.363636 | M21: CLOSED | N21: CLOSED | O21: CLOSED | Q21: =SUM(E21,I21) -> 1216.1297 | R21: =SUM(F21,J21) -> 17468.045
A22: 43795 | B22: Tue | C22: -1.3 | D22: 0.7625 | E22: =Effort!J24 -> 1179.9715 | F22: =Harvest!J24 -> 17109.587 | G22: =CPUE!J24 -> 14.5 | I22: =Effort!L24 -> CLOSED | J22: =Harvest!L24 -> CLOSED | K22: =CPUE!L24 -> CLOSED | M22: CLOSED | N22: CLOSED | O22: CLOSED | Q22: =SUM(E22,I22) -> 1179.9715 | R22: =SUM(F22,J22) -> 17109.587
A23: 43796 | B23: Wed | C23: -1.4 | D23: 0.79305556 | E23: =Effort!J25 -> CLOSED | F23: =Harvest!J25 -> CLOSED | G23: =CPUE!J25 -> CLOSED | I23: =Effort!L25 -> 778.58884 | J23: =Harvest!L25 -> 7952.7289 | K23: =CPUE!L25 -> 10.214286 | M23: CLOSED | N23: CLOSED | O23: CLOSED | Q23: =SUM(E23,I23) -> 778.58884 | R23: =SUM(F23,J23) -> 7952.7289
A24: 43797 | B24: Thu | C24: -1.2 | D24: 0.82222222 | E24: =Effort!J26 -> 1623.9232 | F24: =Harvest!J26 -> 23678.347 | G24: =CPUE!J26 -> 14.580952 | I24: =Effort!L26 -> CLOSED | J24: =Harvest!L26 -> CLOSED | K24: =CPUE!L26 -> CLOSED | M24: CLOSED | N24: CLOSED | O24: CLOSED | Q24: =SUM(E24,I24) -> 1623.9232 | R24: =SUM(F24,J24) -> 23678.347
A25: 43798 | B25: Fri | C25: -0.7 | D25: 0.85208333 | E25: =Effort!J27 -> CLOSED | F25: =Harvest!J27 -> CLOSED | G25: =CPUE!J27 -> CLOSED | I25: =Effort!L27 -> 2031.4045 | J25: =Harvest!L27 -> 30323.865 | K25: =CPUE!L27 -> 14.927536 | M25: CLOSED | N25: CLOSED | O25: CLOSED | Q25: =SUM(E25,I25) -> 2031.4045 | R25: =SUM(F25,J25) -> 30323.865
A26: 43799 | B26: Sat | C26: -0.2 | D26: 0.88194444 | E26: =Effort!J28 -> 1515.7137 | F26: =Harvest!J28 -> 21135.786 | G26: =CPUE!J28 -> 13.944444 | I26: =Effort!L28 -> CLOSED | J26: =Harvest!L28 -> CLOSED | K26: =CPUE!L28 -> CLOSED | M26: CLOSED | N26: CLOSED | O26: CLOSED | Q26: =SUM(E26,I26) -> 1515.7137 | R26: =SUM(F26,J26) -> 21135.786
A27: Tide Series Totals | E27: =SUM(E20:E26) -> 7676.2259 | F27: =SUM(F20:F26) -> 109126.15 | G27: =+F27/E27 -> 14.216121 | H27: 115.5 | I27: =SUM(I20:I26) -> 4026.1231 | J27: =SUM(J20:J26) -> 55744.639 | K27: =+J27/I27 -> 13.845736 | L27: 117.02 | Q27: =SUM(Q20:Q26) -> 11702.349 | R27: =SUM(R20:R26) -> 164870.79
A28: 43809 | B28: Tue | C28: -0.2 | D28: 0.72777778 | E28: =Effort!J30 -> CLOSED | F28: =Harvest!J30 -> CLOSED | G28: =CPUE!J30 -> CLOSED | I28: =Effort!L30 -> 465.0735 | J28: =Harvest!L30 -> 5404.4749 | K28: =CPUE!L30 -> 11.62069 | M28: CLOSED | N28: CLOSED | O28: CLOSED | Q28: =SUM(E28,I28) -> 465.0735 | R28: =SUM(F28,J28) -> 5404.4749
A29: 43810 | B29: Wed | C29: -0.6 | D29: 0.75416667 | E29: =Effort!J31 -> 290.65742 | F29: =Harvest!J31 -> 2252.595 | G29: =CPUE!J31 -> 7.75 | I29: =Effort!L31 -> CLOSED | J29: =Harvest!L31 -> CLOSED | K29: =CPUE!L31 -> CLOSED | M29: CLOSED | N29: CLOSED | O29: CLOSED | Q29: =SUM(E29,I29) -> 290.65742 | R29: =SUM(F29,J29) -> 2252.595
A30: 43811 | B30: Thu | C30: -0.9 | D30: 0.78125 | E30: =Effort!J32 -> CLOSED | F30: =Harvest!J32 -> CLOSED | G30: =CPUE!J32 -> CLOSED | I30: =Effort!L32 -> 272.88042 | J30: =Harvest!L32 -> 250.14038 | K30: =CPUE!L32 -> 0.91666667 | M30: CLOSED | N30: CLOSED | O30: CLOSED | Q30: =SUM(E30,I30) -> 272.88042 | R30: =SUM(F30,J30) -> 250.14038
A31: 43812 | B31: Fri | C31: -1 | D31: 0.80972222 | E31: =Effort!J33 -> 1184.4969 | F31: =Harvest!J33 -> 15351.08 | G31: =CPUE!J33 -> 12.96 | I31: =Effort!L33 -> CLOSED | J31: =Harvest!L33 -> CLOSED | K31: =CPUE!L33 -> CLOSED | M31: CLOSED | N31: CLOSED | O31: CLOSED | Q31: =SUM(E31,I31) -> 1184.4969 | R31: =SUM(F31,J31) -> 15351.08
A32: 43813 | B32: Sat | C32: -1 | D32: 0.83888889 | E32: =Effort!J34 -> CLOSED | F32: =Harvest!J34 -> CLOSED | G32: =CPUE!J34 -> CLOSED | I32: =Effort!L34 -> 1676.095 | J32: =Harvest!L34 -> 25065.238 | K32: =CPUE!L34 -> 14.954545 | M32: CLOSED | N32: CLOSED | O32: CLOSED | Q32: =SUM(E32,I32) -> 1676.095 | R32: =SUM(F32,J32) -> 25065.238
A33: 43814 | B33: Sun | C33: -0.8 | D33: 0.87013889 | E33: =Effort!J35 -> 382.97872 | F33: =Harvest!J35 -> 5744.6807 | G33: =CPUE!J35 -> 15 | I33: =Effort!L35 -> CLOSED | J33: =Harvest!L35 -> CLOSED | K33: =CPUE!L35 -> CLOSED | M33: CLOSED | N33: CLOSED | O33: CLOSED | Q33: =SUM(E33,I33) -> 382.97872 | R33: =SUM(F33,J33) -> 5744.6807
A34: 43815 | B34: Mon | C34: -0.4 | D34: 0.90347222 | E34: =Effort!J36 -> CLOSED | F34: =Harvest!J36 -> CLOSED | G34: =CPUE!J36 -> CLOSED | I34: =Effort!L36 -> 87.591244 | J34: =Harvest!L36 -> 1313.8687 | K34: =CPUE!L36 -> 15 | M34: CLOSED | N34: CLOSED | O34: CLOSED | Q34: =SUM(E34,I34) -> 87.591244 | R34: =SUM(F34,J34) -> 1313.8687
A35: Tide Series Totals | E35: =SUM(E28:E34) -> 1858.1331 | F35: =SUM(F28:F34) -> 23348.356 | G35: =+F35/E35 -> 12.565492 | I35: =SUM(I28:I34) -> 2501.6401 | J35: =SUM(J28:J34) -> 32033.722 | K35: =+J35/I35 -> 12.805088 | L35: 117.5 | Q35: =SUM(Q28:Q34) -> 4359.7732 | R35: =SUM(R28:R34) -> 55382.078
A36: 43822 | B36: Mon | C36: -0.4 | D36: 0.69097222 | E36: =Effort!J38 -> CLOSED | F36: =Harvest!J38 -> CLOSED | G36: =CPUE!J38 -> CLOSED | I36: =Effort!L38 -> 1240.07 | J36: =Harvest!L38 -> 18533.41 | K36: =CPUE!L38 -> 14.945455 | M36: CLOSED | N36: CLOSED | O36: CLOSED | Q36: =SUM(E36,I36) -> 1240.07 | R36: =SUM(F36,J36) -> 18533.41
A37: 43825 | B37: Thu | C37: -1.1 | D37: 0.78263889 | E37: =Effort!J39 -> 1843.1761 | F37: =Harvest!J39 -> 16165.561 | G37: =CPUE!J39 -> 8.7704918 | I37: =Effort!L39 -> CLOSED | J37: =Harvest!L39 -> CLOSED | K37: =CPUE!L39 -> CLOSED | M37: CLOSED | N37: CLOSED | O37: CLOSED | Q37: =SUM(E37,I37) -> 1843.1761 | R37: =SUM(F37,J37) -> 16165.561
A38: 43826 | B38: Fri | C38: -0.9 | D38: 0.80972222 | E38: =Effort!J40 -> CLOSED | F38: =Harvest!J40 -> CLOSED | G38: =CPUE!J40 -> CLOSED | I38: =Effort!L40 -> 1955.7607 | J38: =Harvest!L40 -> 5893.7112 | K38: =CPUE!L40 -> 3.0135135 | M38: CLOSED | N38: CLOSED | O38: CLOSED | Q38: =SUM(E38,I38) -> 1955.7607 | R38: =SUM(F38,J38) -> 5893.7112
A39: 43827 | B39: Sat | C39: -0.6 | D39: 0.83680556 | E39: =Effort!J41 -> 1550.9041 | F39: =Harvest!J41 -> 13464.667 | G39: =CPUE!J41 -> 8.6818182 | I39: =Effort!L41 -> CLOSED | J39: =Harvest!L41 -> CLOSED | K39: =CPUE!L41 -> CLOSED | M39: CLOSED | N39: CLOSED | O39: CLOSED | Q39: =SUM(E39,I39) -> 1550.9041 | R39: =SUM(F39,J39) -> 13464.667
A40: 43828 | B40: Sun | C40: -0.2 | D40: 0.86319444 | E40: =Effort!J42 -> CLOSED | F40: =Harvest!J42 -> CLOSED | G40: =CPUE!J42 -> CLOSED | I40: =Effort!L42 -> 558.39418 | J40: =Harvest!L42 -> 7496.0189 | K40: =CPUE!L42 -> 13.424242 | M40: CLOSED | N40: CLOSED | O40: CLOSED | Q40: =SUM(E40,I40) -> 558.39418 | R40: =SUM(F40,J40) -> 7496.0189
...

Sheet TAC
A1: NON-TRIBAL TOTAL ALLOWABLE CATCH (TAC)
B3: 2019-2020 | C3: 2018-2019 | D3: 2017 - 2018 | E3: 2016 - 2017 | F3: 2015 - 2016 | G3: 2014 - 2015 | H3: 2013 - 2014 | I3: 2012 - 2013 | J3: 2011 - 2012 | K3: 2010 - 2011
A4: LONG BEACH | B4: 5205466.8 | C4: 333557 | D4: 872679.52 | E4: 4895623.6 | F4: 4768605 | G4: 3885491.5 | H4: 2881223.3 | I4: 1847952.1 | J4: 1094641.4 | K4: 1276247.7
A5: TWIN HARBORS | B5: 1843227.2 | C5: 1377125 | D5: 506698.76 | E5: 1896630.9 | F5: 1198600 | G5: 2662860.8 | H5: =5744410.73323314*0.4 -> 2297764.3 | I5: 1881783.2 | J5: 616314.31 | K5: 845427.67
A6: COPALIS | B6: 2036078.6 | C6: 860768 | D6: 591366.12 | E6: 880571.45 | F6: 1094781 | G6: 889827.43 | H6: =(2615522*0.5)-(161153)+250000 -> 1396608 | I6: 1072689.6 | J6: 371373.04 | K6: 683167.41
A7: MOCROCKS | B7: 1649890.4 | C7: 1508774 | D7: 778354.53 | E7: 941919.24 | F7: 1695074 | G7: 2240308.7 | H7: 2088668.5 | I7: 909667.35 | J7: 605830.7 | K7: 545586.69
A8: KALALOCH | B8: 219560.65 | C8: 777386 | D8: 24444.43 | E8: 725888.21 | F8: 63740 | G8: 125735.13 | H8: =1033285.9456848*0.254*0.5 -> 131227.32 | I8: 113543.21 | J8: 144560.51 | K8: 258924.12
A9: COASTWIDE TAC | B9: =SUM(B4:B8) -> 10954224 | C9: =SUM(C4:C8) -> 4857610 | D9: =SUM(D4:D8) -> 2773543.4 | E9: =SUM(E4:E8) -> 9340633.4 | F9: =SUM(F4:F8) -> 8820800 | G9: =SUM(G4:G8) -> 9804223.7 | H9: =SUM(H4:H8) -> 8795491.4 | I9: =SUM(I4:I8) -> 5825635.5 | ... K9: =SUM(K4:K8) -> 3609353.6

Sheet TH Wastage
A1: EventID | B1: LocationID | C1: NHoles | D1: NClams | E1: NMorts
A2: 1623 | B2: 22309 | C2: 100 | D2: 8 | E2: 8
A3: 1623 | B3: 21200 | C3: 100 | D3: 1 | E3: 1
C100: =SUM(C2:C99) -> 200 | D100: =SUM(D2:D99) -> 9 | E100: =SUM(E2:E99) -> 9 | F100: =E100/C100 -> 0.045

Sheet LB Wastage
A1: EventID | B1: LocationID | C1: NHoles | D1: NClams | E1: NMorts
A2: 1621 | B2: 11200 | C2: 25 | D2: 3 | E2: 3
A3: 1621 | B3: 11200 | C3: 25 | D3: 2 | E3: 2
A4: 1621 | B4: 11200 | C4: 25 | D4: 0 | E4: 0
A5: 1621 | B5: 11200 | C5: 25 | D5: 2 | E5: 2
A6: 1621 | B6: 12400 | C6: 100 | D6: 7 | E6: 7
A7: 1622 | B7: 12500 | C7: 100 | D7: 1 | E7: 1
A8: 1622 | B8: 12400 | C8: 100 | D8: 8 | E8: 8
A9: 1722 | B9: 12600 | C9: 50 | D9: 6 | E9: 6
C100: =SUM(C2:C99) -> 450 | D100: =SUM(D2:D99) -> 29 | E100: =SUM(E2:E99) -> 29 | F100: =E100/C100 -> 0.064444444

Sheet Cop Wastage
A1: EventID | B1: LocationID | C1: NHoles | D1: NClams | E1: NMorts
A2: 1624 | B2: 32007 | C2: 100 | D2: 4 | E2: 4
C100: =SUM(C2:C99) -> 100 | D100: =SUM(D2:D99) -> 4 | E100: =SUM(E2:E99) -> 4 | F100: =E100/C100 -> 0.04

