Workbook

Sheet Harvest
A1: Date | B1: Day | C1: Tide | D1: Time | E1: Longbeach | G1: Twin Harbors | I1: Copalis | K1: Mocrocks | M1: Kalaloch | O1: Daily Totals
A2: 44456 | B2: Fri | C2: -0.4 | D2: 0.1875 | E2: * | F2: =CPUE!F2*Effort!F2 -> 12593.952 | G2: * | H2: =CPUE!H2*Effort!H2 -> 6075.4191 | J2: CLOSED | L2: 9619.6814 | N2: CLOSED | O2: =SUM(F2:N2) -> 28289.052 | Q2: =SUM(O2:O28) -> 2239984.5
A3: 44457 | B3: Sat | C3: -0.5 | D3: 0.22361111 | F3: =CPUE!F3*Effort!F3 -> 25491.192 | G3: * | H3: =CPUE!H3*Effort!H3 -> 19987.424 | J3: 26711.365 | L3: CLOSED | N3: CLOSED | O3: =SUM(F3:N3) -> 72189.982
A4: 44458 | B4: Sun | C4: -0.6 | D4: 0.25416667 | E4: * | F4: =CPUE!F4*Effort!F4 -> 111059.76 | H4: 47195.999 | J4: CLOSED | L4: 69378.065 | N4: CLOSED | O4: =SUM(F4:N4) -> 227633.82
A5: 44459 | B5: Mon | C5: -0.5 | D5: 0.28125 | E5: * | F5: =CPUE!F5*Effort!F5 -> 40965.493 | H5: 29905.028 | J5: 41409.558 | L5: CLOSED | N5: CLOSED | O5: =SUM(F5:N5) -> 112280.08
A6: 44460 | B6: Tue | C6: -0.2 | D6: 0.30625 | F6: =31578.948084252+22614.6015313031 -> 54193.55 | H6: 24836.215 | J6: CLOSED | L6: 41859.955 | N6: CLOSED | O6: =SUM(F6:N6) -> 120889.72
A7: 44461 | B7: Wed | C7: 0.3 | D7: 0.32916667 | F7: =CPUE!F7*Effort!F7 -> 57115.306 | H7: 29693.237 | J7: 52765.8 | L7: CLOSED | N7: CLOSED | O7: =SUM(F7:N7) -> 139574.34
A8: 44462 | B8: Thu | C8: 0.3 | D8: 0.87361111 | E8: * | F8: =CPUE!F8*Effort!F8 -> 30265.655 | H8: 28236.43 | J8: CLOSED | L8: 21116.388 | N8: CLOSED | O8: =SUM(F8:N8) -> 79618.474
A9: 44463 | B9: Fri | C9: 0.4 | D9: 0.9 | E9: * | F9: =CPUE!F9*Effort!F9 -> 39992.114 | G9: * | H9: =CPUE!H9*Effort!H9 -> 29745.294 | J9: 40269.544 | L9: CLOSED | N9: CLOSED | O9: =SUM(F9:N9) -> 110006.95
A10: 44464 | B10: Sat | C10: 0.5 | D10: 0.92708333 | F10: =CPUE!F10*Effort!F10 -> 57184.066 | H10: 47702.402 | J10: 32170.787 | L10: 18922.142 | N10: CLOSED | O10: =SUM(F10:N10) -> 155979.4
A12: 44472 | B12: Sun | C12: 0.2 | D12: 0.20277778 | E12: * | F12: =CPUE!F12*Effort!F12 -> 18306.539 | G12: * | H12: =CPUE!H12*Effort!H12 -> 13157.571 | J12: 13628.599 | L12: CLOSED | N12: CLOSED | O12: =SUM(F12:N12) -> 45092.709
A13: 44473 | B13: Mon | C13: 0 | D13: 0.23125 | E13: * | F13: =CPUE!F13*Effort!F13 -> 7925.8171 | G13: * | H13: =CPUE!H13*Effort!H13 -> 4750.9748 | J13: CLOSED | L13: 5923.3311 | N13: CLOSED | O13: =SUM(F13:N13) -> 18600.123
A14: 44474 | B14: Tue | C14: -0.1 | D14: 0.25833333 | F14: =CPUE!F14*Effort!F14 -> 5682.6542 | H14: 6365.5094 | J14: 5618.3511 | L14: CLOSED | N14: CLOSED | O14: =SUM(F14:N14) -> 17666.515
A15: 44475 | B15: Wed | C15: -0.3 | D15: 0.80555556 | E15: * | F15: =CPUE!F15*Effort!F15 -> 77176.407 | H15: 44090.265 | J15: CLOSED | L15: 60261.808 | N15: CLOSED | O15: =SUM(F15:N15) -> 181528.48
A16: 44476 | B16: Thu | C16: -0.8 | D16: 0.83611111 | F16: =CPUE!F16*Effort!F16 -> 60762.177 | H16: 46960.367 | J16: 43947.379 | L16: CLOSED | N16: CLOSED | O16: =SUM(F16:N16) -> 151669.92
A17: 44477 | B17: Fri | C17: -1.1 | D17: 0.86805556 | F17: =(43384.314536755+70470.5895530587) -> 113854.9 | H17: 73352.368 | J17: CLOSED | L17: 82315.7 | N17: CLOSED | O17: =SUM(F17:N17) -> 269522.97
A18: 44478 | B18: Sat | C18: -1.1 | D18: 0.90138889 | F18: =CPUE!F18*Effort!F18 -> 48636.07 | G18: * | H18: =CPUE!H18*Effort!H18 -> 49665.759 | J18: 46151.109 | L18: CLOSED | N18: CLOSED | O18: =SUM(F18:N18) -> 144452.94
A19: 44479 | B19: Sun | C19: -0.8 | D19: 0.93888889 | F19: =CPUE!F19*Effort!F19 -> 10026.922 | H19: 17719.972 | J19: CLOSED | L19: 16536.6 | N19: CLOSED | O19: =SUM(F19:N19) -> 44283.494
A20: 44480 | B20: Mon | C20: -0.4 | D20: 0.98055556 | E20: * | F20: =CPUE!F20*Effort!F20 -> 8800.0559 | G20: * | H20: =CPUE!H20*Effort!H20 -> 9226.0008 | J20: 9469.5654 | L20: CLOSED | N20: CLOSED | O20: =SUM(F20:N20) -> 27495.622
A22: 44488 | B22: Tue | C22: 0.3 | D22: 0.78263889 | F22: =23042.4116706904+24300.4219816668 -> 47342.834 | H22: 41285.715 | J22: 31412.039 | L22: CLOSED | N22: CLOSED | O22: =SUM(F22:N22) -> 120040.59
A23: 44489 | B23: Wed | C23: 0 | D23: 0.80763889 | E23: * | F23: =CPUE!F23*Effort!F23 -> 16327.335 | H23: 15822.708 | J23: CLOSED | L23: 14729.022 | N23: CLOSED | O23: =SUM(F23:N23) -> 46879.065
A24: 44490 | B24: Thu | C24: -0.1 | D24: 0.83194444 | E24: * | F24: =CPUE!F24*Effort!F24 -> 7861.0349 | H24: 4067.0556 | J24: 9307.3618 | L24: CLOSED | N24: CLOSED | O24: =SUM(F24:N24) -> 21235.452
A25: 44491 | B25: Fri | C25: -0.1 | D25: 0.85555556 | F25: =CPUE!F25*Effort!F25 -> 12447.058 | H25: 5961.9384 | J25: CLOSED | L25: 15071.747 | N25: CLOSED | O25: =SUM(F25:N25) -> 33480.744
A26: 44492 | B26: Sat | C26: 0 | D26: 0.87986111 | F26: =CPUE!F26*Effort!F26 -> 23983.333 | H26: 19474.753 | J26: 27757.918 | L26: CLOSED | N26: CLOSED | O26: =SUM(F26:N26) -> 71216.005
A27: 44493 | B27: Sun | C27: 0.2 | D27: 0.90486111 | E27: + | F27: 0 | G27: + | H27: 0 | J27: CLOSED | K27: + | L27: 0 | N27: CLOSED | O27: =SUM(F27:N27) -> 0
A28: 44494 | B28: Mon | C28: 0.5 | D28: 0.93402778 | E28: * | F28: 86 | H28: 72 | I28: * | J28: 200 | L28: CLOSED | N28: CLOSED | O28: =SUM(F28:N28) -> 358
A30: 44503 | B30: Wed | C30: -0.3 | D30: 0.76111111 | F30: =23670.9714666302+19247.5139517877 -> 42918.485 | G30: * | H30: =CPUE!H30*Effort!H30 -> 23559.068 | J30: CLOSED | L30: 25530.097 | N30: CLOSED | O30: =SUM(F30:N30) -> 92007.65
A31: 44504 | B31: Thu | C31: -1.1 | D31: 0.79236111 | E31: * | F31: =CPUE!F31*Effort!F31 -> 35823.172 | H31: 20879.51 | J31: 35700.369 | L31: CLOSED | N31: CLOSED | O31: =SUM(F31:N31) -> 92403.052
A32: 44505 | B32: Fri | C32: -1.6 | D32: 0.82361111 | F32: =CPUE!F32*Effort!F32 -> 60836.017 | H32: 29574.582 | J32: CLOSED | L32: 38528.11 | N32: CLOSED | O32: =SUM(F32:N32) -> 128938.71
A33: 44506 | B33: Sat | C33: -1.8 | D33: 0.85625 | F33: =CPUE!F33*Effort!F33 -> 58875.968 | H33: 40526.861 | J33: 52338.756 | L33: CLOSED | N33: CLOSED | O33: =SUM(F33:N33) -> 151741.58
A34: 44507 | B34: Sun | C34: -1.6 | D34: 0.84930556 | E34: * | F34: =CPUE!F34*Effort!F34 -> 21249.624 | H34: 14604.711 | J34: CLOSED | L34: 14303.156 | N34: CLOSED | O34: =SUM(F34:N34) -> 50157.491
A35: 44508 | B35: Mon | C35: -1.2 | D35: 0.88611111 | F35: =CPUE!F35*Effort!F35 -> 9753.3431 | H35: 11486.445 | J35: 15299.302 | L35: CLOSED | N35: CLOSED | O35: =SUM(F35:N35) -> 36539.09
A36: 44509 | B36: Tue | C36: -0.6 | D36: 0.92569444 | E36: * | F36: =CPUE!F36*Effort!F36 -> 1770.7459 | G36: * | H36: =CPUE!H36*Effort!H36 -> 1197.3118 | J36: CLOSED | L36: =CPUE!L36*Effort!L36 -> 1246.1539 | N36: CLOSED | O36: =SUM(F36:N36) -> 4214.2116
A37: 44510 | B37: Wed | C37: 0 | D37: 0.96944444 | E37: * | F37: =CPUE!F37*Effort!F37 -> 828.59378 | H37: =CPUE!H37*Effort!H37 -> 797.33333 | J37: 1269.2256 | L37: CLOSED | N37: CLOSED | O37: =SUM(F37:N37) -> 2895.1527
A39: 44516 | B39: Tue | C39: 0.5 | D39: 0.70138889 | E39: * | F39: =CPUE!F39*Effort!F39 -> 30419.848 | H39: 24996.243 | J39: 28810.359 | L39: CLOSED | N39: CLOSED | O39: =SUM(F39:N39) -> 84226.449
A40: 44517 | B40: Wed | C40: 0.1 | D40: 0.72777778 | F40: =12004.7612024583+9615.38454820553 -> 21620.146 | G40: * | H40: =CPUE!H40*Effort!H40 -> 15293.853 | J40: CLOSED | L40: 16467.514 | N40: CLOSED | O40: =SUM(F40:N40) -> 53381.513
A41: 44518 | B41: Thu | C41: -0.2 | D41: 0.75208333 | E41: * | F41: =CPUE!F41*Effort!F41 -> 11672.04 | G41: * | H41: =CPUE!H41*Effort!H41 -> 9719.3963 | J41: 16672.382 | L41: CLOSED | N41: CLOSED | O41: =SUM(F41:N41) -> 38063.818
A42: 44519 | B42: Fri | C42: -0.3 | D42: 0.77569444 | F42: =CPUE!F42*Effort!F42 -> 27005.439 | H42: 18661.955 | J42: CLOSED | L42: 19836.834 | N42: CLOSED | O42: =SUM(F42:N42) -> 65504.228
A43: 44520 | B43: Sat | C43: -0.3 | D43: 0.79861111 | F43: =17692.2212191512+21210.4070297193 -> 38902.628 | H43: 32371.381 | J43: 51165.129 | L43: CLOSED | N43: CLOSED | O43: =SUM(F43:N43) -> 122439.14
A44: 44521 | B44: Sun | C44: -0.2 | D44: 0.82222222 | F44: =CPUE!F44*Effort!F44 -> 7988.5015 | H44: 10982.236 | J44: CLOSED | L44: 13294.588 | N44: CLOSED | O44: =SUM(F44:N44) -> 32265.326
...

Sheet Effort
A1: Date | B1: Day | C1: Tide | D1: Time | E1: Longbeach | G1: Twin Harbors | I1: Copalis | K1: Mocrocks | M1: Kalaloch | O1: Daily Totals
A2: 44456 | B2: Fri | C2: -0.4 | D2: 0.1875 | E2: * | F2: =F6/L6*L2 -> 629.6976 | G2: * | H2: =H6/L6*L2 -> 303.77096 | J2: CLOSED | L2: 486.38839 | N2: CLOSED | O2: =SUM(F2:N2) -> 1419.8569 | Q2: =SUM(O2:O28) -> 126278.1
A3: 44457 | B3: Sat | C3: -0.5 | D3: 0.22361111 | F3: =(1130.73007656515/1578.9474042126)*781.783698935879+781.783698935879 -> 1341.6417 | G3: * | H3: =H5/J5*J3 -> 999.37121 | J3: 1358.205 | L3: CLOSED | N3: CLOSED | O3: =SUM(F3:N3) -> 3699.2179
A4: 44458 | B4: Sun | C4: -0.6 | D4: 0.25416667 | E4: * | F4: =F6/L6*L4 -> 5552.988 | H4: 2499.709 | J4: CLOSED | L4: 4289.2158 | N4: CLOSED | O4: =SUM(F4:N4) -> 12341.913
A5: 44459 | B5: Mon | C5: -0.5 | D5: 0.28125 | E5: * | F5: =F7/J7*J5 -> 2048.2747 | H5: 1523.4637 | J5: 2070.4779 | L5: CLOSED | N5: CLOSED | O5: =SUM(F5:N5) -> 5642.2163
A6: 44460 | B6: Tue | C6: -0.2 | D6: 0.30625 | F6: =1130.73007656515+1578.9474042126 -> 2709.6775 | H6: 1307.1692 | J6: CLOSED | L6: 2092.9978 | N6: CLOSED | O6: =SUM(F6:N6) -> 6109.8445
A7: 44461 | B7: Wed | C7: 0.3 | D7: 0.32916667 | F7: =(1130.73007656515/1578.9474042126)*1712.23023344867+1712.23023344867 -> 2938.408 | H7: 1560.3865 | J7: 2970.2603 | L7: CLOSED | N7: CLOSED | O7: =SUM(F7:N7) -> 7469.0548
A8: 44462 | B8: Thu | C8: 0.3 | D8: 0.87361111 | E8: * | F8: =F6/L6*L8 -> 1635.9814 | H8: 1534.5886 | J8: CLOSED | L8: 1263.6579 | N8: CLOSED | O8: =SUM(F8:N8) -> 4434.2278
A9: 44463 | B9: Fri | C9: 0.4 | D9: 0.9 | E9: * | F9: =F7/J7*J9 -> 2161.7359 | G9: * | H9: =H5/J5*J9 -> 1607.8537 | J9: 2185.169 | L9: CLOSED | N9: CLOSED | O9: =SUM(F9:N9) -> 5954.7587
A10: 44464 | B10: Sat | C10: 0.5 | D10: 0.92708333 | F10: =(1130.73007656515/1578.9474042126)*1763.04456535519+1763.04456535519 -> 3025.612 | H10: 2889.6192 | J10: 1608.5394 | L10: 1124.0876 | N10: CLOSED | O10: =SUM(F10:N10) -> 8647.8582
A12: 44472 | B12: Sun | C12: 0.2 | D12: 0.20277778 | E12: * | F12: =F14/J14*J12 -> 1307.6099 | G12: * | H12: =H14/J14*J12 -> 939.82647 | J12: 964.6377 | L12: CLOSED | N12: CLOSED | O12: =SUM(F12:N12) -> 3212.0741
A13: 44473 | B13: Mon | C13: 0 | D13: 0.23125 | E13: * | F13: =F17/L17*L13 -> 609.67824 | G13: * | H13: =H15/L15*L13 -> 365.4596 | J13: CLOSED | L13: 459.00352 | N13: CLOSED | O13: =SUM(F13:N13) -> 1434.1414
A14: 44474 | B14: Tue | C14: -0.1 | D14: 0.25833333 | F14: =(2285.29416038091/3523.52947765293)*355.360551467962+355.360551467962 -> 585.84064 | H14: 421.06482 | J14: 432.18085 | L14: CLOSED | N14: CLOSED | O14: =SUM(F14:N14) -> 1439.0863
A15: 44475 | B15: Wed | C15: -0.3 | D15: 0.80555556 | E15: * | F15: =F17/L17*L15 -> 4061.9161 | H15: 2434.8355 | J15: CLOSED | L15: 3058.0619 | N15: CLOSED | O15: =SUM(F15:N15) -> 9554.8135
A16: 44476 | B16: Thu | C16: -0.8 | D16: 0.83611111 | F16: =(2285.29416038091/3523.52947765293)*1842.86300107912+1842.86300107912 -> 3038.1089 | H16: 2380.183 | J16: 2197.3689 | L16: CLOSED | N16: CLOSED | O16: =SUM(F16:N16) -> 7615.6608
A17: 44477 | B17: Fri | C17: -1.1 | D17: 0.86805556 | F17: =3523.52947765293+2285.29416038091 -> 5808.8236 | H17: 3703.6259 | J17: CLOSED | L17: 4373.242 | N17: CLOSED | O17: =SUM(F17:N17) -> 13885.691
A18: 44478 | B18: Sat | C18: -1.1 | D18: 0.90138889 | F18: =(2285.29416038091/3523.52947765293*1915.69989952869)+1915.69989952869 -> 3158.1864 | G18: * | H18: =H14/J14*J18 -> 3311.0506 | J18: 3398.4617 | L18: CLOSED | N18: CLOSED | O18: =SUM(F18:N18) -> 9867.6986
A19: 44479 | B19: Sun | C19: -0.8 | D19: 0.93888889 | F19: =(2285.29416038091/3523.52947765293*304.107654036494)+304.107654036494 -> 501.34609 | H19: 897.81192 | J19: CLOSED | L19: 859.04416 | N19: CLOSED | O19: =SUM(F19:N19) -> 2258.2022
A20: 44480 | B20: Mon | C20: -0.4 | D20: 0.98055556 | E20: * | F20: =F18/J18*J20 -> 440.0028 | G20: * | H20: =H18/J18*J20 -> 461.30004 | J20: 473.47827 | L20: CLOSED | N20: CLOSED | O20: =SUM(F20:N20) -> 1374.7811
A22: 44488 | B22: Tue | C22: 0.3 | D22: 0.78263889 | F22: =1567.51099800615+1232.01440116842 -> 2799.5254 | H22: 2333.5404 | J22: 2476.1742 | L22: CLOSED | N22: CLOSED | O22: =SUM(F22:N22) -> 7609.24
A23: 44489 | B23: Wed | C23: 0 | D23: 0.80763889 | E23: * | F23: =F25/L25*L23 -> 907.07414 | H23: 1084.6211 | J23: CLOSED | L23: 823.09239 | N23: CLOSED | O23: =SUM(F23:N23) -> 2814.7877
A24: 44490 | B24: Thu | C24: -0.1 | D24: 0.83194444 | E24: * | F24: =F26/J26*J24 -> 561.50249 | H24: 359.28053 | J24: 655.9474 | L24: CLOSED | N24: CLOSED | O24: =SUM(F24:N24) -> 1576.7304
A25: 44491 | B25: Fri | C25: -0.1 | D25: 0.85555556 | F25: =(1567.51099800615/1232.01440116842*622.465670238644)+622.465670238644 -> 1414.4384 | H25: 743.55241 | J25: CLOSED | L25: 1283.4821 | N25: CLOSED | O25: =SUM(F25:N25) -> 3441.4729
A26: 44492 | B26: Sat | C26: 0 | D26: 0.87986111 | F26: =(1567.51099800615/1232.01440116842*659.661187886277)+659.661187886277 -> 1498.9583 | H26: 1195.3813 | J26: 1751.0836 | L26: CLOSED | N26: CLOSED | O26: =SUM(F26:N26) -> 4445.4232
A27: 44493 | B27: Sun | C27: 0.2 | D27: 0.90486111 | E27: + | F27: 0 | G27: + | H27: 0 | J27: CLOSED | K27: + | L27: 0 | N27: CLOSED | O27: =SUM(F27:N27) -> 0
A28: 44494 | B28: Mon | C28: 0.5 | D28: 0.93402778 | E28: * | F28: =F22/H22*H28 -> 10.797211 | H28: 9 | I28: * | J28: =J22/H22*H28 -> 9.5501101 | L28: CLOSED | N28: CLOSED | O28: =SUM(F28:N28) -> 29.347321
A30: 44503 | B30: Wed | C30: -0.3 | D30: 0.76111111 | F30: =1403.41728063025+969.953458987728 -> 2373.3707 | G30: * | H30: =H34/L34*L30 -> 1239.9509 | J30: CLOSED | L30: 1290.5324 | N30: CLOSED | O30: =SUM(F30:N30) -> 4903.854
A31: 44504 | B31: Thu | C31: -1.1 | D31: 0.79236111 | E31: * | F31: =F33/J33*J31 -> 1990.1762 | H31: 1162.844 | J31: 1998.155 | L31: CLOSED | N31: CLOSED | O31: =SUM(F31:N31) -> 5151.1752
A32: 44505 | B32: Fri | C32: -1.6 | D32: 0.82361111 | F32: =(1403.41728063025/969.953458987728*1373.62285714286)+1373.62285714286 -> 3361.1059 | H32: 1528.9666 | J32: CLOSED | L32: 2365.3621 | N32: CLOSED | O32: =SUM(F32:N32) -> 7255.4346
A33: 44506 | B33: Sat | C33: -1.8 | D33: 0.85625 | F33: =(1403.41728063025/969.953458987728*1253.20507840723)+1253.20507840723 -> 3066.4567 | H33: 2199.132 | J33: 3078.7503 | L33: CLOSED | N33: CLOSED | O33: =SUM(F33:N33) -> 8344.339
A34: 44507 | B34: Sun | C34: -1.6 | D34: 0.84930556 | E34: * | F34: =F32/L32*L34 -> 1180.5347 | H34: 798.23319 | J34: CLOSED | L34: 830.79559 | N34: CLOSED | O34: =SUM(F34:N34) -> 2809.5634
A35: 44508 | B35: Mon | C35: -1.2 | D35: 0.88611111 | F35: =(1403.41728063025/969.953458987728*209.790207712132)+209.790207712132 -> 513.33385 | H35: 574.32224 | J35: 783.14526 | L35: CLOSED | N35: CLOSED | O35: =SUM(F35:N35) -> 1870.8013
A36: 44509 | B36: Tue | C36: -0.6 | D36: 0.92569444 | E36: * | F36: =F32/L32*L36 -> 118.04973 | G36: * | H36: =H34/L34*L36 -> 79.82079 | J36: CLOSED | L36: 83.076926 | N36: CLOSED | O36: =SUM(F36:N36) -> 280.94744
A37: 44510 | B37: Wed | C37: 0 | D37: 0.96944444 | E37: * | F37: =F35/J35*J37 -> 63.737983 | H37: 61.333333 | J37: 97.239057 | L37: CLOSED | N37: CLOSED | O37: =SUM(F37:N37) -> 222.31037
A39: 44516 | B39: Tue | C39: 0.5 | D39: 0.70138889 | E39: * | F39: =F43/H43*H39 -> 1559.9922 | H39: 1299.0173 | J39: 1466.0893 | L39: CLOSED | N39: CLOSED | O39: =SUM(F39:N39) -> 4325.0988
A40: 44517 | B40: Wed | C40: 0.1 | D40: 0.72777778 | F40: =480.769227410277+622.653589339125 -> 1103.4228 | G40: * | H40: =H42/F42*F40 -> 784.30016 | J40: CLOSED | L40: 846.46098 | N40: CLOSED | O40: =SUM(F40:N40) -> 2734.184
A41: 44518 | B41: Thu | C41: -0.2 | D41: 0.75208333 | E41: * | F41: =F43/J43*J41 -> 598.56616 | G41: * | H41: =H43/J43*J41 -> 498.43058 | J41: 844.17122 | L41: CLOSED | N41: CLOSED | O41: =SUM(F41:N41) -> 1941.168
A42: 44519 | B42: Fri | C42: -0.3 | D42: 0.77569444 | F42: =(1080.971157162/884.611060957561*675.211588669605)+675.211588669605 -> 1500.3022 | H42: 1066.3974 | J42: CLOSED | L42: 1368.0575 | N42: CLOSED | O42: =SUM(F42:N42) -> 3934.7571
A43: 44520 | B43: Sat | C43: -0.3 | D43: 0.79861111 | F43: =1080.971157162+884.611060957561 -> 1965.5822 | H43: 1636.7552 | J43: 2772.1045 | L43: CLOSED | N43: CLOSED | O43: =SUM(F43:N43) -> 6374.4419
A44: 44521 | B44: Sun | C44: -0.2 | D44: 0.82222222 | F44: =(1080.971157162/884.611060957561*189.222540289374)+189.222540289374 -> 420.44745 | H44: 595.52796 | J44: CLOSED | L44: 726.48021 | N44: CLOSED | O44: =SUM(F44:N44) -> 1742.4556
...

Sheet CPUE
A1: Date | B1: Day | C1: Tide | D1: Time | E1: Longbeach | G1: Twin Harbors | I1: Copalis | K1: Mocrocks | M1: Kalaloch | O1: Daily Totals
A2: 44456 | B2: Fri | C2: -0.4 | D2: 0.1875 | E2: * | F2: 20 | G2: * | H2: 20 | J2: CLOSED | L2: =+Harvest!L2/Effort!L2 -> 19.777778 | N2: CLOSED | O2: =+Harvest!O2/Effort!O2 -> 19.923875 | Q2: =AVERAGE(O2:O28) -> 16.257001
A3: 44457 | B3: Sat | C3: -0.5 | D3: 0.22361111 | F3: 19 | G3: * | H3: 20 | J3: =+Harvest!J3/Effort!J3 -> 19.666667 | L3: CLOSED | N3: CLOSED | O3: =+Harvest!O3/Effort!O3 -> 19.514931
A4: 44458 | B4: Sun | C4: -0.6 | D4: 0.25416667 | E4: * | F4: 20 | H4: =+Harvest!H4/Effort!H4 -> 18.880597 | J4: CLOSED | L4: =+Harvest!L4/Effort!L4 -> 16.175 | N4: CLOSED | O4: =+Harvest!O4/Effort!O4 -> 18.443966
A5: 44459 | B5: Mon | C5: -0.5 | D5: 0.28125 | E5: * | F5: 20 | H5: =+Harvest!H5/Effort!H5 -> 19.62963 | J5: =+Harvest!J5/Effort!J5 -> 20 | L5: CLOSED | N5: CLOSED | O5: =+Harvest!O5/Effort!O5 -> 19.899996
A6: 44460 | B6: Tue | C6: -0.2 | D6: 0.30625 | F6: =+Harvest!F6/Effort!F6 -> 20 | H6: =+Harvest!H6/Effort!H6 -> 19 | J6: CLOSED | L6: =+Harvest!L6/Effort!L6 -> 20 | N6: CLOSED | O6: =+Harvest!O6/Effort!O6 -> 19.786055
A7: 44461 | B7: Wed | C7: 0.3 | D7: 0.32916667 | F7: 19.4375 | H7: =+Harvest!H7/Effort!H7 -> 19.029412 | J7: =+Harvest!J7/Effort!J7 -> 17.764706 | L7: CLOSED | N7: CLOSED | O7: =+Harvest!O7/Effort!O7 -> 18.687016
A8: 44462 | B8: Thu | C8: 0.3 | D8: 0.87361111 | E8: * | F8: 18.5 | H8: =+Harvest!H8/Effort!H8 -> 18.4 | J8: CLOSED | L8: =+Harvest!L8/Effort!L8 -> 16.710526 | N8: CLOSED | O8: =+Harvest!O8/Effort!O8 -> 17.955431
A9: 44463 | B9: Fri | C9: 0.4 | D9: 0.9 | E9: * | F9: 18.5 | G9: * | H9: 18.5 | J9: =+Harvest!J9/Effort!J9 -> 18.428571 | L9: CLOSED | N9: CLOSED | O9: =+Harvest!O9/Effort!O9 -> 18.473788
A10: 44464 | B10: Sat | C10: 0.5 | D10: 0.92708333 | F10: 18.9 | H10: =+Harvest!H10/Effort!H10 -> 16.508197 | J10: =+Harvest!J10/Effort!J10 -> 20 | L10: =+Harvest!L10/Effort!L10 -> 16.833333 | N10: CLOSED | O10: =+Harvest!O10/Effort!O10 -> 18.036766
A12: 44472 | B12: Sun | C12: 0.2 | D12: 0.20277778 | E12: * | F12: 14 | G12: * | H12: 14 | J12: =+Harvest!J12/Effort!J12 -> 14.128205 | L12: CLOSED | N12: CLOSED | O12: =+Harvest!O12/Effort!O12 -> 14.038502
A13: 44473 | B13: Mon | C13: 0 | D13: 0.23125 | E13: * | F13: 13 | G13: * | H13: 13 | J13: CLOSED | L13: =+Harvest!L13/Effort!L13 -> 12.904762 | N13: CLOSED | O13: =+Harvest!O13/Effort!O13 -> 12.969519
A14: 44474 | B14: Tue | C14: -0.1 | D14: 0.25833333 | F14: 9.7 | H14: =+Harvest!H14/Effort!H14 -> 15.117647 | J14: =+Harvest!J14/Effort!J14 -> 13 | L14: CLOSED | N14: CLOSED | O14: =+Harvest!O14/Effort!O14 -> 12.276202
A15: 44475 | B15: Wed | C15: -0.3 | D15: 0.80555556 | E15: * | F15: 19 | H15: =+Harvest!H15/Effort!H15 -> 18.108108 | J15: CLOSED | L15: =+Harvest!L15/Effort!L15 -> 19.705882 | N15: CLOSED | O15: =+Harvest!O15/Effort!O15 -> 18.998642
A16: 44476 | B16: Thu | C16: -0.8 | D16: 0.83611111 | F16: 20 | H16: =+Harvest!H16/Effort!H16 -> 19.72973 | J16: =+Harvest!J16/Effort!J16 -> 20 | L16: CLOSED | N16: CLOSED | O16: =+Harvest!O16/Effort!O16 -> 19.91553
A17: 44477 | B17: Fri | C17: -1.1 | D17: 0.86805556 | F17: =+Harvest!F17/Effort!F17 -> 19.600338 | H17: =+Harvest!H17/Effort!H17 -> 19.805556 | J17: CLOSED | L17: =+Harvest!L17/Effort!L17 -> 18.822581 | N17: CLOSED | O17: =+Harvest!O17/Effort!O17 -> 19.410122
A18: 44478 | B18: Sat | C18: -1.1 | D18: 0.90138889 | F18: 15.4 | G18: * | H18: 15 | J18: =+Harvest!J18/Effort!J18 -> 13.58 | L18: CLOSED | N18: CLOSED | O18: =+Harvest!O18/Effort!O18 -> 14.638969
A19: 44479 | B19: Sun | C19: -0.8 | D19: 0.93888889 | F19: 20 | H19: =+Harvest!H19/Effort!H19 -> 19.736842 | J19: CLOSED | L19: =+Harvest!L19/Effort!L19 -> 19.25 | N19: CLOSED | O19: =+Harvest!O19/Effort!O19 -> 19.610066
A20: 44480 | B20: Mon | C20: -0.4 | D20: 0.98055556 | E20: * | F20: 20 | G20: * | H20: 20 | J20: =+Harvest!J20/Effort!J20 -> 20 | L20: CLOSED | N20: CLOSED | O20: =+Harvest!O20/Effort!O20 -> 20
A22: 44488 | B22: Tue | C22: 0.3 | D22: 0.78263889 | F22: =+Harvest!F22/Effort!F22 -> 16.911021 | H22: =+Harvest!H22/Effort!H22 -> 17.692308 | J22: =+Harvest!J22/Effort!J22 -> 12.685714 | L22: CLOSED | N22: CLOSED | O22: =+Harvest!O22/Effort!O22 -> 15.775634
A23: 44489 | B23: Wed | C23: 0 | D23: 0.80763889 | E23: * | F23: 18 | H23: =+Harvest!H23/Effort!H23 -> 14.588235 | J23: CLOSED | L23: =+Harvest!L23/Effort!L23 -> 17.894737 | N23: CLOSED | O23: =+Harvest!O23/Effort!O23 -> 16.654565
A24: 44490 | B24: Thu | C24: -0.1 | D24: 0.83194444 | E24: * | F24: 14 | H24: =+Harvest!H24/Effort!H24 -> 11.32 | J24: =+Harvest!J24/Effort!J24 -> 14.189189 | L24: CLOSED | N24: CLOSED | O24: =+Harvest!O24/Effort!O24 -> 13.46803
A25: 44491 | B25: Fri | C25: -0.1 | D25: 0.85555556 | F25: 8.8 | H25: =+Harvest!H25/Effort!H25 -> 8.0181818 | J25: CLOSED | L25: =+Harvest!L25/Effort!L25 -> 11.742857 | N25: CLOSED | O25: =+Harvest!O25/Effort!O25 -> 9.7286087
A26: 44492 | B26: Sat | C26: 0 | D26: 0.87986111 | F26: 16 | H26: =+Harvest!H26/Effort!H26 -> 16.291667 | J26: =+Harvest!J26/Effort!J26 -> 15.851852 | L26: CLOSED | N26: CLOSED | O26: =+Harvest!O26/Effort!O26 -> 16.020073
A27: 44493 | B27: Sun | C27: 0.2 | D27: 0.90486111 | E27: * | F27: 0 | G27: * | H27: 0 | J27: CLOSED | L27: 0 | N27: CLOSED | O27: 0
A28: 44494 | B28: Mon | C28: 0.5 | D28: 0.93402778 | E28: * | F28: 8 | G28: * | H28: 8 | J28: 11 | L28: CLOSED | N28: CLOSED | O28: =+Harvest!O28/Effort!O28 -> 12.198728
A30: 44503 | B30: Wed | C30: -0.3 | D30: 0.76111111 | F30: =+Harvest!F30/Effort!F30 -> 18.083346 | G30: * | H30: 19 | J30: CLOSED | L30: =+Harvest!L30/Effort!L30 -> 19.782609 | N30: CLOSED | O30: =+Harvest!O30/Effort!O30 -> 18.762314
A31: 44504 | B31: Thu | C31: -1.1 | D31: 0.79236111 | E31: * | F31: 18 | H31: =+Harvest!H31/Effort!H31 -> 17.955556 | J31: =+Harvest!J31/Effort!J31 -> 17.866667 | L31: CLOSED | N31: CLOSED | O31: =+Harvest!O31/Effort!O31 -> 17.938247
A32: 44505 | B32: Fri | C32: -1.6 | D32: 0.82361111 | F32: 18.1 | H32: =+Harvest!H32/Effort!H32 -> 19.342857 | J32: CLOSED | L32: =+Harvest!L32/Effort!L32 -> 16.288462 | N32: CLOSED | O32: =+Harvest!O32/Effort!O32 -> 17.771328
A33: 44506 | B33: Sat | C33: -1.8 | D33: 0.85625 | F33: 19.2 | H33: =+Harvest!H33/Effort!H33 -> 18.428571 | J33: =+Harvest!J33/Effort!J33 -> 17 | L33: CLOSED | N33: CLOSED | O33: =+Harvest!O33/Effort!O33 -> 18.184974
A34: 44507 | B34: Sun | C34: -1.6 | D34: 0.84930556 | E34: * | F34: 18 | H34: =+Harvest!H34/Effort!H34 -> 18.296296 | J34: CLOSED | L34: =+Harvest!L34/Effort!L34 -> 17.216216 | N34: CLOSED | O34: =+Harvest!O34/Effort!O34 -> 17.852415
A35: 44508 | B35: Mon | C35: -1.2 | D35: 0.88611111 | F35: 19 | H35: =+Harvest!H35/Effort!H35 -> 20 | J35: =+Harvest!J35/Effort!J35 -> 19.535714 | L35: CLOSED | N35: CLOSED | O35: =+Harvest!O35/Effort!O35 -> 19.531251
A36: 44509 | B36: Tue | C36: -0.6 | D36: 0.92569444 | E36: * | F36: 15 | G36: * | H36: 15 | J36: CLOSED | L36: 15 | N36: CLOSED | O36: =+Harvest!O36/Effort!O36 -> 15
A37: 44510 | B37: Wed | C37: 0 | D37: 0.96944444 | E37: * | F37: 13 | H37: 13 | J37: =+Harvest!J37/Effort!J37 -> 13.052632 | L37: CLOSED | N37: CLOSED | O37: =+Harvest!O37/Effort!O37 -> 13.023021
A39: 44516 | B39: Tue | C39: 0.5 | D39: 0.70138889 | E39: * | F39: 19.5 | H39: =+Harvest!H39/Effort!H39 -> 19.242424 | J39: =+Harvest!J39/Effort!J39 -> 19.651163 | L39: CLOSED | N39: CLOSED | O39: =+Harvest!O39/Effort!O39 -> 19.473879
A40: 44517 | B40: Wed | C40: 0.1 | D40: 0.72777778 | F40: =+Harvest!F40/Effort!F40 -> 19.593709 | G40: * | H40: 19.5 | J40: CLOSED | L40: =+Harvest!L40/Effort!L40 -> 19.454545 | N40: CLOSED | O40: =+Harvest!O40/Effort!O40 -> 19.523746
A41: 44518 | B41: Thu | C41: -0.2 | D41: 0.75208333 | E41: * | F41: 19.5 | G41: * | H41: 19.5 | J41: =+Harvest!J41/Effort!J41 -> 19.75 | L41: CLOSED | N41: CLOSED | O41: =+Harvest!O41/Effort!O41 -> 19.608719
A42: 44519 | B42: Fri | C42: -0.3 | D42: 0.77569444 | F42: 18 | H42: =+Harvest!H42/Effort!H42 -> 17.5 | J42: CLOSED | L42: =+Harvest!L42/Effort!L42 -> 14.5 | N42: CLOSED | O42: =+Harvest!O42/Effort!O42 -> 16.647591
A43: 44520 | B43: Sat | C43: -0.3 | D43: 0.79861111 | F43: =+Harvest!F43/Effort!F43 -> 19.791911 | H43: =+Harvest!H43/Effort!H43 -> 19.777778 | J43: =+Harvest!J43/Effort!J43 -> 18.457143 | L43: CLOSED | N43: CLOSED | O43: =+Harvest!O43/Effort!O43 -> 19.207821
A44: 44521 | B44: Sun | C44: -0.2 | D44: 0.82222222 | F44: 19 | H44: =+Harvest!H44/Effort!H44 -> 18.441176 | J44: CLOSED | L44: =+Harvest!L44/Effort!L44 -> 18.3 | N44: CLOSED | O44: =+Harvest!O44/Effort!O44 -> 18.517158
...

Sheet Summary Table
A1: 2021-2022 State (non-Tribal) Recreational Razor Clam Effort, Harvest and CPUE totals.
E2: LONG BEACH | H2: TWIN HARBORS | K2: COPALIS | N2: MOCROCKS | Q2: KALALOCH | T2: DAILY TOTALS | W2: CROSS | X2: CHECK
A3: DATE | B3: DAY | C3: TIDE | D3: TIME | E3: Effort | F3: Harvest | G3: CPUE | H3: Effort | I3: Harvest | J3: CPUE | K3: Effort | L3: Harvest | M3: CPUE | N3: Effort | O3: Harvest | P3: CPUE | Q3: Effort | R3: Harvest | S3: CPUE | T3: Effort | U3: Harvest
A4: 44456 | B4: Fri | C4: -0.4 | D4: 0.1875 | E4: =Effort!F2 -> 629.6976 | F4: =Harvest!F2 -> 12593.952 | G4: =+CPUE!F2 -> 20 | H4: =Effort!H2 -> 303.77096 | I4: =Harvest!H2 -> 6075.4191 | J4: =CPUE!H2 -> 20 | K4: =Effort!J2 -> CLOSED | L4: =Harvest!J2 -> CLOSED | M4: =CPUE!J2 -> CLOSED | N4: =Effort!L2 -> 486.38839 | O4: =Harvest!L2 -> 9619.6814 | P4: =CPUE!L2 -> 19.777778 | Q4: CLOSED | R4: CLOSED | S4: CLOSED | T4: =SUM(E4+H4+N4) -> 1419.8569 | U4: =SUM(F4+I4+O4) -> 28289.052
A5: 44457 | B5: Sat | C5: -0.5 | D5: 0.22361111 | E5: =Effort!F3 -> 1341.6417 | F5: =Harvest!F3 -> 25491.192 | G5: =+CPUE!F3 -> 19 | H5: =Effort!H3 -> 999.37121 | I5: =Harvest!H3 -> 19987.424 | J5: =CPUE!H3 -> 20 | K5: =Effort!J3 -> 1358.205 | L5: =Harvest!J3 -> 26711.365 | M5: =CPUE!J3 -> 19.666667 | N5: =Effort!L3 -> CLOSED | O5: =Harvest!L3 -> CLOSED | P5: =CPUE!L3 -> CLOSED | Q5: CLOSED | R5: CLOSED | S5: CLOSED | T5: =SUM(E5+H5+K5) -> 3699.2179 | U5: =SUM(F5+I5+L5) -> 72189.982
A6: 44458 | B6: Sun | C6: -0.6 | D6: 0.25416667 | E6: =Effort!F4 -> 5552.988 | F6: =Harvest!F4 -> 111059.76 | G6: =+CPUE!F4 -> 20 | H6: =Effort!H4 -> 2499.709 | I6: =Harvest!H4 -> 47195.999 | J6: =CPUE!H4 -> 18.880597 | K6: =Effort!J4 -> CLOSED | L6: =Harvest!J4 -> CLOSED | M6: =CPUE!J4 -> CLOSED | N6: =Effort!L4 -> 4289.2158 | O6: =Harvest!L4 -> 69378.065 | P6: =CPUE!L4 -> 16.175 | Q6: CLOSED | R6: CLOSED | S6: CLOSED | T6: =SUM(E6+H6+N6) -> 12341.913 | U6: =SUM(F6+I6+O6) -> 227633.82
A7: 44459 | B7: Mon | C7: -0.5 | D7: 0.28125 | E7: =Effort!F5 -> 2048.2747 | F7: =Harvest!F5 -> 40965.493 | G7: =+CPUE!F5 -> 20 | H7: =Effort!H5 -> 1523.4637 | I7: =Harvest!H5 -> 29905.028 | J7: =CPUE!H5 -> 19.62963 | K7: =Effort!J5 -> 2070.4779 | L7: =Harvest!J5 -> 41409.558 | M7: =CPUE!J5 -> 20 | N7: =Effort!L5 -> CLOSED | O7: =Harvest!L5 -> CLOSED | P7: =CPUE!L5 -> CLOSED | Q7: CLOSED | R7: CLOSED | S7: CLOSED | T7: =SUM(E7+H7+K7) -> 5642.2163 | U7: =SUM(F7+I7+L7) -> 112280.08
A8: 44460 | B8: Tue | C8: -0.2 | D8: 0.30625 | E8: =Effort!F6 -> 2709.6775 | F8: =Harvest!F6 -> 54193.55 | G8: =+CPUE!F6 -> 20 | H8: =Effort!H6 -> 1307.1692 | I8: =Harvest!H6 -> 24836.215 | J8: =CPUE!H6 -> 19 | K8: =Effort!J6 -> CLOSED | L8: =Harvest!J6 -> CLOSED | M8: =CPUE!J6 -> CLOSED | N8: =Effort!L6 -> 2092.9978 | O8: =Harvest!L6 -> 41859.955 | P8: =CPUE!L6 -> 20 | Q8: CLOSED | R8: CLOSED | S8: CLOSED | T8: =SUM(E8+H8+N8) -> 6109.8445 | U8: =SUM(F8+I8+O8) -> 120889.72
A9: 44461 | B9: Wed | C9: 0.3 | D9: 0.32916667 | E9: =Effort!F7 -> 2938.408 | F9: =Harvest!F7 -> 57115.306 | G9: =+CPUE!F7 -> 19.4375 | H9: =Effort!H7 -> 1560.3865 | I9: =Harvest!H7 -> 29693.237 | J9: =CPUE!H7 -> 19.029412 | K9: =Effort!J7 -> 2970.2603 | L9: =Harvest!J7 -> 52765.8 | M9: =CPUE!J7 -> 17.764706 | N9: =Effort!L7 -> CLOSED | O9: =Harvest!L7 -> CLOSED | P9: =CPUE!L7 -> CLOSED | Q9: CLOSED | R9: CLOSED | S9: CLOSED | T9: =SUM(E9+H9+K9) -> 7469.0548 | U9: =SUM(F9+I9+L9) -> 139574.34
A10: 44462 | B10: Thu | C10: 0.3 | D10: 0.87361111 | E10: =Effort!F8 -> 1635.9814 | F10: =Harvest!F8 -> 30265.655 | G10: =+CPUE!F8 -> 18.5 | H10: =Effort!H8 -> 1534.5886 | I10: =Harvest!H8 -> 28236.43 | J10: =CPUE!H8 -> 18.4 | K10: =Effort!J8 -> CLOSED | L10: =Harvest!J8 -> CLOSED | M10: =CPUE!J8 -> CLOSED | N10: =Effort!L8 -> 1263.6579 | O10: =Harvest!L8 -> 21116.388 | P10: =CPUE!L8 -> 16.710526 | Q10: CLOSED | R10: CLOSED | S10: CLOSED | T10: =SUM(E10+H10+N10) -> 4434.2278 | U10: =SUM(F10+I10+O10) -> 79618.474
A11: 44463 | B11: Fri | C11: 0.4 | D11: 0.9 | E11: =Effort!F9 -> 2161.7359 | F11: =Harvest!F9 -> 39992.114 | G11: =+CPUE!F9 -> 18.5 | H11: =Effort!H9 -> 1607.8537 | I11: =Harvest!H9 -> 29745.294 | J11: =CPUE!H9 -> 18.5 | K11: =Effort!J9 -> 2185.169 | L11: =Harvest!J9 -> 40269.544 | M11: =CPUE!J9 -> 18.428571 | N11: =Effort!L9 -> CLOSED | O11: =Harvest!L9 -> CLOSED | P11: =CPUE!L9 -> CLOSED | Q11: CLOSED | R11: CLOSED | S11: CLOSED | T11: =SUM(E11+H11+K11) -> 5954.7587 | U11: =SUM(F11+I11+L11) -> 110006.95
A12: 44464 | B12: Sat | C12: 0.5 | D12: 0.92708333 | E12: =Effort!F10 -> 3025.612 | F12: =Harvest!F10 -> 57184.066 | G12: =+CPUE!F10 -> 18.9 | H12: =Effort!H10 -> 2889.6192 | I12: =Harvest!H10 -> 47702.402 | J12: =CPUE!H10 -> 16.508197 | K12: =Effort!J10 -> 1608.5394 | L12: =Harvest!J10 -> 32170.787 | M12: =CPUE!J10 -> 20 | N12: =Effort!L10 -> 1124.0876 | O12: =Harvest!L10 -> 18922.142 | P12: =CPUE!L10 -> 16.833333 | Q12: CLOSED | R12: CLOSED | S12: CLOSED | T12: =SUM(E12+H12+N12+K12) -> 8647.8582 | U12: =SUM(F12+I12+O12+L12) -> 155979.4
A13: Tide Series Totals | E13: =SUM(E4:E12) -> 22044.017 | F13: =SUM(F4:F12) -> 428861.09 | G13: =+F13/E13 -> 19.454762 | H13: =SUM(H4:H12) -> 14225.932 | I13: =SUM(I4:I12) -> 263377.45 | J13: =+I13/H13 -> 18.513897 | K13: =SUM(K4:K12) -> 10192.652 | L13: =SUM(L4:L12) -> 193327.06 | M13: =+L13/K13 -> 18.967297 | N13: =SUM(N4:N12) -> 9256.3474 | O13: =SUM(O4:O12) -> 160896.23 | P13: =+O13/N13 -> 17.382259 | T13: =SUM(T4:T12) -> 55718.948 | U13: =SUM(U4:U12) -> 1046461.8 | W13: =SUM(H13,K13,N13,Q13,E13) -> 55718.948 | X13: =SUM(R13,O13,L13,I13,F13) -> 1046461.8
A14: 44472 | B14: Sun | C14: 0.2 | D14: 0.20277778 | E14: =Effort!F12 -> 1307.6099 | F14: =Harvest!F12 -> 18306.539 | G14: =+CPUE!F12 -> 14 | H14: =Effort!H12 -> 939.82647 | I14: =Harvest!H12 -> 13157.571 | J14: =CPUE!H12 -> 14 | K14: =Effort!J12 -> 964.6377 | L14: =Harvest!J12 -> 13628.599 | M14: =CPUE!J12 -> 14.128205 | N14: =Effort!L12 -> CLOSED | O14: =Harvest!L12 -> CLOSED | P14: =CPUE!L12 -> CLOSED | Q14: CLOSED | R14: CLOSED | S14: CLOSED | T14: =SUM(E14+H14+K14) -> 3212.0741 | U14: =SUM(F14+I14+L14) -> 45092.709
A15: 44473 | B15: Mon | C15: 0 | D15: 0.23125 | E15: =Effort!F13 -> 609.67824 | F15: =Harvest!F13 -> 7925.8171 | G15: =+CPUE!F13 -> 13 | H15: =Effort!H13 -> 365.4596 | I15: =Harvest!H13 -> 4750.9748 | J15: =CPUE!H13 -> 13 | K15: =Effort!J13 -> CLOSED | L15: =Harvest!J13 -> CLOSED | M15: =CPUE!J13 -> CLOSED | N15: =Effort!L13 -> 459.00352 | O15: =Harvest!L13 -> 5923.3311 | P15: =CPUE!L13 -> 12.904762 | Q15: CLOSED | R15: CLOSED | S15: CLOSED | T15: =SUM(E15+H15+N15) -> 1434.1414 | U15: =SUM(F15+I15+O15) -> 18600.123
A16: 44474 | B16: Tue | C16: -0.1 | D16: 0.25833333 | E16: =Effort!F14 -> 585.84064 | F16: =Harvest!F14 -> 5682.6542 | G16: =+CPUE!F14 -> 9.7 | H16: =Effort!H14 -> 421.06482 | I16: =Harvest!H14 -> 6365.5094 | J16: =CPUE!H14 -> 15.117647 | K16: =Effort!J14 -> 432.18085 | L16: =Harvest!J14 -> 5618.3511 | M16: =CPUE!J14 -> 13 | N16: =Effort!L14 -> CLOSED | O16: =Harvest!L14 -> CLOSED | P16: =CPUE!L14 -> CLOSED | Q16: CLOSED | R16: CLOSED | S16: CLOSED | T16: =SUM(E16+H16+K16) -> 1439.0863 | U16: =SUM(F16+I16+L16) -> 17666.515
A17: 44475 | B17: Wed | C17: -0.3 | D17: 0.80555556 | E17: =Effort!F15 -> 4061.9161 | F17: =Harvest!F15 -> 77176.407 | G17: =+CPUE!F15 -> 19 | H17: =Effort!H15 -> 2434.8355 | I17: =Harvest!H15 -> 44090.265 | J17: =CPUE!H15 -> 18.108108 | K17: =Effort!J15 -> CLOSED | L17: =Harvest!J15 -> CLOSED | M17: =CPUE!J15 -> CLOSED | N17: =Effort!L15 -> 3058.0619 | O17: =Harvest!L15 -> 60261.808 | P17: =CPUE!L15 -> 19.705882 | Q17: CLOSED | R17: CLOSED | S17: CLOSED | T17: =SUM(E17+H17+N17) -> 9554.8135 | U17: =SUM(F17+I17+O17) -> 181528.48
A18: 44476 | B18: Thu | C18: -0.8 | D18: 0.83611111 | E18: =Effort!F16 -> 3038.1089 | F18: =Harvest!F16 -> 60762.177 | G18: =+CPUE!F16 -> 20 | H18: =Effort!H16 -> 2380.183 | I18: =Harvest!H16 -> 46960.367 | J18: =CPUE!H16 -> 19.72973 | K18: =Effort!J16 -> 2197.3689 | L18: =Harvest!J16 -> 43947.379 | M18: =CPUE!J16 -> 20 | N18: =Effort!L16 -> CLOSED | O18: =Harvest!L16 -> CLOSED | P18: =CPUE!L16 -> CLOSED | Q18: CLOSED | R18: CLOSED | S18: CLOSED | T18: =SUM(E18+H18+K18) -> 7615.6608 | U18: =SUM(F18+I18+L18) -> 151669.92
A19: 44477 | B19: Fri | C19: -1.1 | D19: 0.86805556 | E19: =Effort!F17 -> 5808.8236 | F19: =Harvest!F17 -> 113854.9 | G19: =+CPUE!F17 -> 19.600338 | H19: =Effort!H17 -> 3703.6259 | I19: =Harvest!H17 -> 73352.368 | J19: =CPUE!H17 -> 19.805556 | K19: =Effort!J17 -> CLOSED | L19: =Harvest!J17 -> CLOSED | M19: =CPUE!J17 -> CLOSED | N19: =Effort!L17 -> 4373.242 | O19: =Harvest!L17 -> 82315.7 | P19: =CPUE!L17 -> 18.822581 | Q19: CLOSED | R19: CLOSED | S19: CLOSED | T19: =SUM(E19+H19+N19) -> 13885.691 | U19: =SUM(F19+I19+O19) -> 269522.97
A20: 44478 | B20: Sat | C20: -1.1 | D20: 0.90138889 | E20: =Effort!F18 -> 3158.1864 | F20: =Harvest!F18 -> 48636.07 | G20: =+CPUE!F18 -> 15.4 | H20: =Effort!H18 -> 3311.0506 | I20: =Harvest!H18 -> 49665.759 | J20: =CPUE!H18 -> 15 | K20: =Effort!J18 -> 3398.4617 | L20: =Harvest!J18 -> 46151.109 | M20: =CPUE!J18 -> 13.58 | N20: =Effort!L18 -> CLOSED | O20: =Harvest!L18 -> CLOSED | P20: =CPUE!L18 -> CLOSED | Q20: CLOSED | R20: CLOSED | S20: CLOSED | T20: =SUM(E20+H20+K20) -> 9867.6986 | U20: =SUM(F20+I20+L20) -> 144452.94
A21: 44479 | B21: Sun | C21: -0.8 | D21: 0.93888889 | E21: =Effort!F19 -> 501.34609 | F21: =Harvest!F19 -> 10026.922 | G21: =+CPUE!F19 -> 20 | H21: =Effort!H19 -> 897.81192 | I21: =Harvest!H19 -> 17719.972 | J21: =CPUE!H19 -> 19.736842 | K21: =Effort!J19 -> CLOSED | L21: =Harvest!J19 -> CLOSED | M21: =CPUE!J19 -> CLOSED | N21: =Effort!L19 -> 859.04416 | O21: =Harvest!L19 -> 16536.6 | P21: =CPUE!L19 -> 19.25 | Q21: CLOSED | R21: CLOSED | S21: CLOSED | T21: =SUM(E21+H21+N21) -> 2258.2022 | U21: =SUM(F21+I21+O21) -> 44283.494
A22: 44480 | B22: Mon | C22: -0.4 | D22: 0.98055556 | E22: =Effort!F20 -> 440.0028 | F22: =Harvest!F20 -> 8800.0559 | G22: =+CPUE!F20 -> 20 | H22: =Effort!H20 -> 461.30004 | I22: =Harvest!H20 -> 9226.0008 | J22: =CPUE!H20 -> 20 | K22: =Effort!J20 -> 473.47827 | L22: =Harvest!J20 -> 9469.5654 | M22: =CPUE!J20 -> 20 | N22: =Effort!L20 -> CLOSED | O22: =Harvest!L20 -> CLOSED | P22: =CPUE!L20 -> CLOSED | Q22: CLOSED | R22: CLOSED | S22: CLOSED | T22: =SUM(E22+H22+K22) -> 1374.7811 | U22: =SUM(F22+I22+L22) -> 27495.622
A23: Tide Series Totals | E23: =SUM(E14:E22) -> 19511.513 | F23: =SUM(F14:F22) -> 351171.55 | G23: =+F23/E23 -> 17.998171 | H23: =SUM(H14:H22) -> 14915.158 | I23: =SUM(I14:I22) -> 265288.79 | J23: =+I23/H23 -> 17.786522 | K23: =SUM(K14:K22) -> 7466.1274 | L23: =SUM(L14:L22) -> 118815 | M23: =+L23/K23 -> 15.913873 | N23: =SUM(N14:N22) -> 8749.3515 | O23: =SUM(O14:O22) -> 165037.44 | P23: =+O23/N23 -> 18.862819 | T23: =SUM(T14:T22) -> 50642.149 | U23: =SUM(U14:U22) -> 900312.77 | W23: =SUM(H23,K23,N23,Q23,E23) -> 50642.149 | X23: =SUM(R23,O23,L23,I23,F23) -> 900312.77
A24: 44488 | B24: Tue | C24: 0.3 | D24: 0.78263889 | E24: =Effort!F22 -> 2799.5254 | F24: =Harvest!F22 -> 47342.834 | G24: =+CPUE!F22 -> 16.911021 | H24: =Effort!H22 -> 2333.5404 | I24: =Harvest!H22 -> 41285.715 | J24: =CPUE!H22 -> 17.692308 | K24: =Effort!J22 -> 2476.1742 | L24: =Harvest!J22 -> 31412.039 | M24: =CPUE!J22 -> 12.685714 | N24: =Effort!L22 -> CLOSED | O24: =Harvest!L22 -> CLOSED | P24: =CPUE!L22 -> CLOSED | Q24: CLOSED | R24: CLOSED | S24: CLOSED | T24: =SUM(E24+H24+K24) -> 7609.24 | U24: =SUM(F24+I24+L24) -> 120040.59
A25: 44489 | B25: Wed | C25: 0 | D25: 0.80763889 | E25: =Effort!F23 -> 907.07414 | F25: =Harvest!F23 -> 16327.335 | G25: =+CPUE!F23 -> 18 | H25: =Effort!H23 -> 1084.6211 | I25: =Harvest!H23 -> 15822.708 | J25: =CPUE!H23 -> 14.588235 | K25: =Effort!J23 -> CLOSED | L25: =Harvest!J23 -> CLOSED | M25: =CPUE!J23 -> CLOSED | N25: =Effort!L23 -> 823.09239 | O25: =Harvest!L23 -> 14729.022 | P25: =CPUE!L23 -> 17.894737 | Q25: CLOSED | R25: CLOSED | S25: CLOSED | T25: =SUM(E25+H25+N25) -> 2814.7877 | U25: =SUM(F25+I25+O25) -> 46879.065
A26: 44490 | B26: Thu | C26: -0.1 | D26: 0.83194444 | E26: =Effort!F24 -> 561.50249 | F26: =Harvest!F24 -> 7861.0349 | G26: =+CPUE!F24 -> 14 | H26: =Effort!H24 -> 359.28053 | I26: =Harvest!H24 -> 4067.0556 | J26: =CPUE!H24 -> 11.32 | K26: =Effort!J24 -> 655.9474 | L26: =Harvest!J24 -> 9307.3618 | M26: =CPUE!J24 -> 14.189189 | N26: =Effort!L24 -> CLOSED | O26: =Harvest!L24 -> CLOSED | P26: =CPUE!L24 -> CLOSED | Q26: CLOSED | R26: CLOSED | S26: CLOSED | T26: =SUM(E26+H26+K26) -> 1576.7304 | U26: =SUM(F26+I26+L26) -> 21235.452
A27: 44491 | B27: Fri | C27: -0.1 | D27: 0.85555556 | E27: =Effort!F25 -> 1414.4384 | F27: =Harvest!F25 -> 12447.058 | G27: =+CPUE!F25 -> 8.8 | H27: =Effort!H25 -> 743.55241 | I27: =Harvest!H25 -> 5961.9384 | J27: =CPUE!H25 -> 8.0181818 | K27: =Effort!J25 -> CLOSED | L27: =Harvest!J25 -> CLOSED | M27: =CPUE!J25 -> CLOSED | N27: =Effort!L25 -> 1283.4821 | O27: =Harvest!L25 -> 15071.747 | P27: =CPUE!L25 -> 11.742857 | Q27: CLOSED | R27: CLOSED | S27: CLOSED | T27: =SUM(E27+H27+N27) -> 3441.4729 | U27: =SUM(F27+I27+O27) -> 33480.744
A28: 44492 | B28: Sat | C28: 0 | D28: 0.87986111 | E28: =Effort!F26 -> 1498.9583 | F28: =Harvest!F26 -> 23983.333 | G28: =+CPUE!F26 -> 16 | H28: =Effort!H26 -> 1195.3813 | I28: =Harvest!H26 -> 19474.753 | J28: =CPUE!H26 -> 16.291667 | K28: =Effort!J26 -> 1751.0836 | L28: =Harvest!J26 -> 27757.918 | M28: =CPUE!J26 -> 15.851852 | N28: =Effort!L26 -> CLOSED | O28: =Harvest!L26 -> CLOSED | P28: =CPUE!L26 -> CLOSED | Q28: CLOSED | R28: CLOSED | S28: CLOSED | T28: =SUM(E28+H28+K28) -> 4445.4232 | U28: =SUM(F28+I28+L28) -> 71216.005
A29: 44493 | B29: Sun | C29: 0.2 | D29: 0.90486111 | E29: =Effort!F27 -> 0 | F29: =Harvest!F27 -> 0 | G29: =+CPUE!F27 -> 0 | H29: =Effort!H27 -> 0 | I29: =Harvest!H27 -> 0 | J29: =CPUE!H27 -> 0 | K29: =Effort!J27 -> CLOSED | L29: =Harvest!J27 -> CLOSED | M29: =CPUE!J27 -> CLOSED | N29: =Effort!L27 -> 0 | O29: =Harvest!L27 -> 0 | P29: =CPUE!L27 -> 0 | Q29: CLOSED | R29: CLOSED | S29: CLOSED | T29: =SUM(E29+H29+N29) -> 0 | U29: =SUM(F29+I29+O29) -> 0
A30: 44494 | B30: Mon | C30: 0.5 | D30: 0.93402778 | E30: =Effort!F28 -> 10.797211 | F30: =Harvest!F28 -> 86 | G30: =+CPUE!F28 -> 8 | H30: =Effort!H28 -> 9 | I30: =Harvest!H28 -> 72 | J30: =CPUE!H28 -> 8 | K30: =Effort!J28 -> 9.5501101 | L30: =Harvest!J28 -> 200 | M30: =CPUE!J28 -> 11 | N30: =Effort!L28 -> CLOSED | O30: =Harvest!L28 -> CLOSED | P30: =CPUE!L28 -> CLOSED | Q30: CLOSED | R30: CLOSED | S30: CLOSED | T30: =SUM(E30+H30+K30) -> 29.347321 | U30: =SUM(F30+I30+L30) -> 358
A31: Tide Series Totals | E31: =SUM(E24:E30) -> 7192.296 | F31: =SUM(F24:F30) -> 108047.59 | G31: =+F31/E31 -> 15.022685 | H31: =SUM(H24:H30) -> 5725.3758 | I31: =SUM(I24:I30) -> 86684.171 | J31: =+I31/H31 -> 15.140346 | K31: =SUM(K24:K30) -> 4892.7554 | L31: =SUM(L24:L30) -> 68677.319 | M31: =+L31/K31 -> 14.036532 | N31: =SUM(N24:N30) -> 2106.5745 | O31: =SUM(O24:O30) -> 29800.769 | P31: =+O31/N31 -> 14.146553 | T31: =SUM(T24:T30) -> 19917.002 | U31: =SUM(U24:U30) -> 293209.85 | W31: =SUM(H31,K31,N31,Q31,E31) -> 19917.002 | X31: =SUM(R31,O31,L31,I31,F31) -> 293209.85
A32: 44503 | B32: Wed | C32: -0.3 | D32: 0.76111111 | E32: =Effort!F30 -> 2373.3707 | F32: =Harvest!F30 -> 42918.485 | G32: =+CPUE!F30 -> 18.083346 | H32: =Effort!H30 -> 1239.9509 | I32: =Harvest!H30 -> 23559.068 | J32: =CPUE!H30 -> 19 | K32: =Effort!J30 -> CLOSED | L32: =Harvest!J30 -> CLOSED | M32: =CPUE!J30 -> CLOSED | N32: =Effort!L30 -> 1290.5324 | O32: =Harvest!L30 -> 25530.097 | P32: =CPUE!L30 -> 19.782609 | Q32: CLOSED | R32: CLOSED | S32: CLOSED | T32: =SUM(E32+H32+N32) -> 4903.854 | U32: =SUM(F32+I32+O32) -> 92007.65
A33: 44504 | B33: Thu | C33: -1.1 | D33: 0.79236111 | E33: =Effort!F31 -> 1990.1762 | F33: =Harvest!F31 -> 35823.172 | G33: =+CPUE!F31 -> 18 | H33: =Effort!H31 -> 1162.844 | I33: =Harvest!H31 -> 20879.51 | J33: =CPUE!H31 -> 17.955556 | K33: =Effort!J31 -> 1998.155 | L33: =Harvest!J31 -> 35700.369 | M33: =CPUE!J31 -> 17.866667 | N33: =Effort!L31 -> CLOSED | O33: =Harvest!L31 -> CLOSED | P33: =CPUE!L31 -> CLOSED | Q33: CLOSED | R33: CLOSED | S33: CLOSED | T33: =SUM(E33+H33+K33) -> 5151.1752 | U33: =SUM(F33+I33+L33) -> 92403.052
A34: 44505 | B34: Fri | C34: -1.6 | D34: 0.82361111 | E34: =Effort!F32 -> 3361.1059 | F34: =Harvest!F32 -> 60836.017 | G34: =+CPUE!F32 -> 18.1 | H34: =Effort!H32 -> 1528.9666 | I34: =Harvest!H32 -> 29574.582 | J34: =CPUE!H32 -> 19.342857 | K34: =Effort!J32 -> CLOSED | L34: =Harvest!J32 -> CLOSED | M34: =CPUE!J32 -> CLOSED | N34: =Effort!L32 -> 2365.3621 | O34: =Harvest!L32 -> 38528.11 | P34: =CPUE!L32 -> 16.288462 | Q34: CLOSED | R34: CLOSED | S34: CLOSED | T34: =SUM(E34+H34+N34) -> 7255.4346 | U34: =SUM(F34+I34+O34) -> 128938.71
A35: 44506 | B35: Sat | C35: -1.8 | D35: 0.85625 | E35: =Effort!F33 -> 3066.4567 | F35: =Harvest!F33 -> 58875.968 | G35: =+CPUE!F33 -> 19.2 | H35: =Effort!H33 -> 2199.132 | I35: =Harvest!H33 -> 40526.861 | J35: =CPUE!H33 -> 18.428571 | K35: =Effort!J33 -> 3078.7503 | L35: =Harvest!J33 -> 52338.756 | M35: =CPUE!J33 -> 17 | N35: =Effort!L33 -> CLOSED | O35: =Harvest!L33 -> CLOSED | P35: =CPUE!L33 -> CLOSED | Q35: CLOSED | R35: CLOSED | S35: CLOSED | T35: =SUM(E35+H35+K35) -> 8344.339 | U35: =SUM(F35+I35+L35) -> 151741.58
A36: 44507 | B36: Sun | C36: -1.6 | D36: 0.84930556 | E36: =Effort!F34 -> 1180.5347 | F36: =Harvest!F34 -> 21249.624 | G36: =+CPUE!F34 -> 18 | H36: =Effort!H34 -> 798.23319 | I36: =Harvest!H34 -> 14604.711 | J36: =CPUE!H34 -> 18.296296 | K36: =Effort!J34 -> CLOSED | L36: =Harvest!J34 -> CLOSED | M36: =CPUE!J34 -> CLOSED | N36: =Effort!L34 -> 830.79559 | O36: =Harvest!L34 -> 14303.156 | P36: =CPUE!L34 -> 17.216216 | Q36: CLOSED | R36: CLOSED | S36: CLOSED | T36: =SUM(E36+H36+N36) -> 2809.5634 | U36: =SUM(F36+I36+O36) -> 50157.491
A37: 44508 | B37: Mon | C37: -1.2 | D37: 0.88611111 | E37: =Effort!F35 -> 513.33385 | F37: =Harvest!F35 -> 9753.3431 | G37: =+CPUE!F35 -> 19 | H37: =Effort!H35 -> 574.32224 | I37: =Harvest!H35 -> 11486.445 | J37: =CPUE!H35 -> 20 | K37: =Effort!J35 -> 783.14526 | L37: =Harvest!J35 -> 15299.302 | M37: =CPUE!J35 -> 19.535714 | N37: =Effort!L35 -> CLOSED | O37: =Harvest!L35 -> CLOSED | P37: =CPUE!L35 -> CLOSED | Q37: CLOSED | R37: CLOSED | S37: CLOSED | T37: =SUM(E37+H37+K37) -> 1870.8013 | U37: =SUM(F37+I37+L37) -> 36539.09
A38: 44509 | B38: Tue | C38: -0.6 | D38: 0.92569444 | E38: =Effort!F36 -> 118.04973 | F38: =Harvest!F36 -> 1770.7459 | G38: =+CPUE!F36 -> 15 | H38: =Effort!H36 -> 79.82079 | I38: =Harvest!H36 -> 1197.3118 | J38: =CPUE!H36 -> 15 | K38: =Effort!J36 -> CLOSED | L38: =Harvest!J36 -> CLOSED | M38: =CPUE!J36 -> CLOSED | N38: =Effort!L36 -> 83.076926 | O38: =Harvest!L36 -> 1246.1539 | P38: =CPUE!L36 -> 15 | Q38: CLOSED | R38: CLOSED | S38: CLOSED | T38: =SUM(E38+H38+N38) -> 280.94744 | U38: =SUM(F38+I38+O38) -> 4214.2116
A39: 44510 | B39: Wed | C39: 0 | D39: 0.96944444 | E39: =Effort!F37 -> 63.737983 | F39: =Harvest!F37 -> 828.59378 | G39: =+CPUE!F37 -> 13 | H39: =Effort!H37 -> 61.333333 | I39: =Harvest!H37 -> 797.33333 | J39: =CPUE!H37 -> 13 | K39: =Effort!J37 -> 97.239057 | L39: =Harvest!J37 -> 1269.2256 | M39: =CPUE!J37 -> 13.052632 | N39: =Effort!L37 -> CLOSED | O39: =Harvest!L37 -> CLOSED | P39: =CPUE!L37 -> CLOSED | Q39: CLOSED | R39: CLOSED | S39: CLOSED | T39: =SUM(E39+H39+K39) -> 222.31037 | U39: =SUM(F39+I39+L39) -> 2895.1527
A40: Tide Series Totals | E40: =SUM(E32:E39) -> 12666.766 | F40: =SUM(F32:F39) -> 232055.95 | G40: =+F40/E40 -> 18.320063 | H40: =SUM(H32:H39) -> 7644.6031 | I40: =SUM(I32:I39) -> 142625.82 | J40: =+I40/H40 -> 18.657061 | K40: =SUM(K32:K39) -> 5957.2896 | L40: =SUM(L32:L39) -> 104607.65 | M40: =+L40/K40 -> 17.559605 | N40: =SUM(N32:N39) -> 4569.767 | O40: =SUM(O32:O39) -> 79607.517 | P40: =+O40/N40 -> 17.420476 | T40: =SUM(T32:T39) -> 30838.425 | U40: =SUM(U32:U39) -> 558896.94 | W40: =SUM(H40,K40,N40,Q40,E40) -> 30838.425 | X40: =SUM(R40,O40,L40,I40,F40) -> 558896.94
...

Sheet Summary Table Public
A1: 2021-2022 State (non-Tribal) Recreational Razor Clam Effort, Harvest and CPUE totals.
E2: LONG BEACH | H2: TWIN HARBORS | K2: COPALIS | N2: MOCROCKS | Q2: KALALOCH | T2: DAILY TOTALS | W2: CROSS | X2: CHECK
A3: DATE | B3: DAY | C3: TIDE | D3: TIME | E3: Effort | F3: Harvest | G3: CPUE | H3: Effort | I3: Harvest | J3: CPUE | K3: Effort | L3: Harvest | M3: CPUE | N3: Effort | O3: Harvest | P3: CPUE | Q3: Effort | R3: Harvest | S3: CPUE | T3: Effort | U3: Harvest
A4: 44456 | B4: Fri | C4: -0.4 | D4: 0.1875 | E4: =Effort!F2 -> 629.6976 | F4: =Harvest!F2 -> 12593.952 | G4: =+CPUE!F2 -> 20 | H4: =Effort!H2 -> 303.77096 | I4: =Harvest!H2 -> 6075.4191 | J4: =CPUE!H2 -> 20 | K4: =Effort!J2 -> CLOSED | L4: =Harvest!J2 -> CLOSED | M4: =CPUE!J2 -> CLOSED | N4: =Effort!L2 -> 486.38839 | O4: =Harvest!L2 -> 9619.6814 | P4: =CPUE!L2 -> 19.777778 | Q4: CLOSED | R4: CLOSED | S4: CLOSED | T4: =SUM(E4+H4+N4) -> 1419.8569 | U4: =SUM(F4+I4+O4) -> 28289.052
A5: 44457 | B5: Sat | C5: -0.5 | D5: 0.22361111 | E5: =Effort!F3 -> 1341.6417 | F5: =Harvest!F3 -> 25491.192 | G5: =+CPUE!F3 -> 19 | H5: =Effort!H3 -> 999.37121 | I5: =Harvest!H3 -> 19987.424 | J5: =CPUE!H3 -> 20 | K5: =Effort!J3 -> 1358.205 | L5: =Harvest!J3 -> 26711.365 | M5: =CPUE!J3 -> 19.666667 | N5: =Effort!L3 -> CLOSED | O5: =Harvest!L3 -> CLOSED | P5: =CPUE!L3 -> CLOSED | Q5: CLOSED | R5: CLOSED | S5: CLOSED | T5: =SUM(E5+H5+K5) -> 3699.2179 | U5: =SUM(F5+I5+L5) -> 72189.982
A6: 44458 | B6: Sun | C6: -0.6 | D6: 0.25416667 | E6: =Effort!F4 -> 5552.988 | F6: =Harvest!F4 -> 111059.76 | G6: =+CPUE!F4 -> 20 | H6: =Effort!H4 -> 2499.709 | I6: =Harvest!H4 -> 47195.999 | J6: =CPUE!H4 -> 18.880597 | K6: =Effort!J4 -> CLOSED | L6: =Harvest!J4 -> CLOSED | M6: =CPUE!J4 -> CLOSED | N6: =Effort!L4 -> 4289.2158 | O6: =Harvest!L4 -> 69378.065 | P6: =CPUE!L4 -> 16.175 | Q6: CLOSED | R6: CLOSED | S6: CLOSED | T6: =SUM(E6+H6+N6) -> 12341.913 | U6: =SUM(F6+I6+O6) -> 227633.82
A7: 44459 | B7: Mon | C7: -0.5 | D7: 0.28125 | E7: =Effort!F5 -> 2048.2747 | F7: =Harvest!F5 -> 40965.493 | G7: =+CPUE!F5 -> 20 | H7: =Effort!H5 -> 1523.4637 | I7: =Harvest!H5 -> 29905.028 | J7: =CPUE!H5 -> 19.62963 | K7: =Effort!J5 -> 2070.4779 | L7: =Harvest!J5 -> 41409.558 | M7: =CPUE!J5 -> 20 | N7: =Effort!L5 -> CLOSED | O7: =Harvest!L5 -> CLOSED | P7: =CPUE!L5 -> CLOSED | Q7: CLOSED | R7: CLOSED | S7: CLOSED | T7: =SUM(E7+H7+K7) -> 5642.2163 | U7: =SUM(F7+I7+L7) -> 112280.08
A8: 44460 | B8: Tue | C8: -0.2 | D8: 0.30625 | E8: =Effort!F6 -> 2709.6775 | F8: =Harvest!F6 -> 54193.55 | G8: =+CPUE!F6 -> 20 | H8: =Effort!H6 -> 1307.1692 | I8: =Harvest!H6 -> 24836.215 | J8: =CPUE!H6 -> 19 | K8: =Effort!J6 -> CLOSED | L8: =Harvest!J6 -> CLOSED | M8: =CPUE!J6 -> CLOSED | N8: =Effort!L6 -> 2092.9978 | O8: =Harvest!L6 -> 41859.955 | P8: =CPUE!L6 -> 20 | Q8: CLOSED | R8: CLOSED | S8: CLOSED | T8: =SUM(E8+H8+N8) -> 6109.8445 | U8: =SUM(F8+I8+O8) -> 120889.72
A9: 44461 | B9: Wed | C9: 0.3 | D9: 0.32916667 | E9: =Effort!F7 -> 2938.408 | F9: =Harvest!F7 -> 57115.306 | G9: =+CPUE!F7 -> 19.4375 | H9: =Effort!H7 -> 1560.3865 | I9: =Harvest!H7 -> 29693.237 | J9: =CPUE!H7 -> 19.029412 | K9: =Effort!J7 -> 2970.2603 | L9: =Harvest!J7 -> 52765.8 | M9: =CPUE!J7 -> 17.764706 | N9: =Effort!L7 -> CLOSED | O9: =Harvest!L7 -> CLOSED | P9: =CPUE!L7 -> CLOSED | Q9: CLOSED | R9: CLOSED | S9: CLOSED | T9: =SUM(E9+H9+K9) -> 7469.0548 | U9: =SUM(F9+I9+L9) -> 139574.34
A10: 44462 | B10: Thu | C10: 0.3 | D10: 0.87361111 | E10: =Effort!F8 -> 1635.9814 | F10: =Harvest!F8 -> 30265.655 | G10: =+CPUE!F8 -> 18.5 | H10: =Effort!H8 -> 1534.5886 | I10: =Harvest!H8 -> 28236.43 | J10: =CPUE!H8 -> 18.4 | K10: =Effort!J8 -> CLOSED | L10: =Harvest!J8 -> CLOSED | M10: =CPUE!J8 -> CLOSED | N10: =Effort!L8 -> 1263.6579 | O10: =Harvest!L8 -> 21116.388 | P10: =CPUE!L8 -> 16.710526 | Q10: CLOSED | R10: CLOSED | S10: CLOSED | T10: =SUM(E10+H10+N10) -> 4434.2278 | U10: =SUM(F10+I10+O10) -> 79618.474
A11: 44463 | B11: Fri | C11: 0.4 | D11: 0.9 | E11: =Effort!F9 -> 2161.7359 | F11: =Harvest!F9 -> 39992.114 | G11: =+CPUE!F9 -> 18.5 | H11: =Effort!H9 -> 1607.8537 | I11: =Harvest!H9 -> 29745.294 | J11: =CPUE!H9 -> 18.5 | K11: =Effort!J9 -> 2185.169 | L11: =Harvest!J9 -> 40269.544 | M11: =CPUE!J9 -> 18.428571 | N11: =Effort!L9 -> CLOSED | O11: =Harvest!L9 -> CLOSED | P11: =CPUE!L9 -> CLOSED | Q11: CLOSED | R11: CLOSED | S11: CLOSED | T11: =SUM(E11+H11+K11) -> 5954.7587 | U11: =SUM(F11+I11+L11) -> 110006.95
A12: 44464 | B12: Sat | C12: 0.5 | D12: 0.92708333 | E12: =Effort!F10 -> 3025.612 | F12: =Harvest!F10 -> 57184.066 | G12: =+CPUE!F10 -> 18.9 | H12: =Effort!H10 -> 2889.6192 | I12: =Harvest!H10 -> 47702.402 | J12: =CPUE!H10 -> 16.508197 | K12: =Effort!J10 -> 1608.5394 | L12: =Harvest!J10 -> 32170.787 | M12: =CPUE!J10 -> 20 | N12: =Effort!L10 -> 1124.0876 | O12: =Harvest!L10 -> 18922.142 | P12: =CPUE!L10 -> 16.833333 | Q12: CLOSED | R12: CLOSED | S12: CLOSED | T12: =SUM(E12+H12+N12+K12) -> 8647.8582 | U12: =SUM(F12+I12+O12+L12) -> 155979.4
A13: Tide Series Totals | E13: =SUM(E4:E12) -> 22044.017 | F13: =SUM(F4:F12) -> 428861.09 | G13: =+F13/E13 -> 19.454762 | H13: =SUM(H4:H12) -> 14225.932 | I13: =SUM(I4:I12) -> 263377.45 | J13: =+I13/H13 -> 18.513897 | K13: =SUM(K4:K12) -> 10192.652 | L13: =SUM(L4:L12) -> 193327.06 | M13: =+L13/K13 -> 18.967297 | N13: =SUM(N4:N12) -> 9256.3474 | O13: =SUM(O4:O12) -> 160896.23 | P13: =+O13/N13 -> 17.382259 | T13: =SUM(T4:T12) -> 55718.948 | U13: =SUM(U4:U12) -> 1046461.8 | W13: =SUM(H13,K13,N13,Q13,E13) -> 55718.948 | X13: =SUM(R13,O13,L13,I13,F13) -> 1046461.8
A14: 44472 | B14: Sun | C14: 0.2 | D14: 0.20277778 | E14: =Effort!F12 -> 1307.6099 | F14: =Harvest!F12 -> 18306.539 | G14: =+CPUE!F12 -> 14 | H14: =Effort!H12 -> 939.82647 | I14: =Harvest!H12 -> 13157.571 | J14: =CPUE!H12 -> 14 | K14: =Effort!J12 -> 964.6377 | L14: =Harvest!J12 -> 13628.599 | M14: =CPUE!J12 -> 14.128205 | N14: =Effort!L12 -> CLOSED | O14: =Harvest!L12 -> CLOSED | P14: =CPUE!L12 -> CLOSED | Q14: CLOSED | R14: CLOSED | S14: CLOSED | T14: =SUM(E14+H14+K14) -> 3212.0741 | U14: =SUM(F14+I14+L14) -> 45092.709
A15: 44473 | B15: Mon | C15: 0 | D15: 0.23125 | E15: =Effort!F13 -> 609.67824 | F15: =Harvest!F13 -> 7925.8171 | G15: =+CPUE!F13 -> 13 | H15: =Effort!H13 -> 365.4596 | I15: =Harvest!H13 -> 4750.9748 | J15: =CPUE!H13 -> 13 | K15: =Effort!J13 -> CLOSED | L15: =Harvest!J13 -> CLOSED | M15: =CPUE!J13 -> CLOSED | N15: =Effort!L13 -> 459.00352 | O15: =Harvest!L13 -> 5923.3311 | P15: =CPUE!L13 -> 12.904762 | Q15: CLOSED | R15: CLOSED | S15: CLOSED | T15: =SUM(E15+H15+N15) -> 1434.1414 | U15: =SUM(F15+I15+O15) -> 18600.123
A16: 44474 | B16: Tue | C16: -0.1 | D16: 0.25833333 | E16: =Effort!F14 -> 585.84064 | F16: =Harvest!F14 -> 5682.6542 | G16: =+CPUE!F14 -> 9.7 | H16: =Effort!H14 -> 421.06482 | I16: =Harvest!H14 -> 6365.5094 | J16: =CPUE!H14 -> 15.117647 | K16: =Effort!J14 -> 432.18085 | L16: =Harvest!J14 -> 5618.3511 | M16: =CPUE!J14 -> 13 | N16: =Effort!L14 -> CLOSED | O16: =Harvest!L14 -> CLOSED | P16: =CPUE!L14 -> CLOSED | Q16: CLOSED | R16: CLOSED | S16: CLOSED | T16: =SUM(E16+H16+K16) -> 1439.0863 | U16: =SUM(F16+I16+L16) -> 17666.515
A17: 44475 | B17: Wed | C17: -0.3 | D17: 0.80555556 | E17: =Effort!F15 -> 4061.9161 | F17: =Harvest!F15 -> 77176.407 | G17: =+CPUE!F15 -> 19 | H17: =Effort!H15 -> 2434.8355 | I17: =Harvest!H15 -> 44090.265 | J17: =CPUE!H15 -> 18.108108 | K17: =Effort!J15 -> CLOSED | L17: =Harvest!J15 -> CLOSED | M17: =CPUE!J15 -> CLOSED | N17: =Effort!L15 -> 3058.0619 | O17: =Harvest!L15 -> 60261.808 | P17: =CPUE!L15 -> 19.705882 | Q17: CLOSED | R17: CLOSED | S17: CLOSED | T17: =SUM(E17+H17+N17) -> 9554.8135 | U17: =SUM(F17+I17+O17) -> 181528.48
A18: 44476 | B18: Thu | C18: -0.8 | D18: 0.83611111 | E18: =Effort!F16 -> 3038.1089 | F18: =Harvest!F16 -> 60762.177 | G18: =+CPUE!F16 -> 20 | H18: =Effort!H16 -> 2380.183 | I18: =Harvest!H16 -> 46960.367 | J18: =CPUE!H16 -> 19.72973 | K18: =Effort!J16 -> 2197.3689 | L18: =Harvest!J16 -> 43947.379 | M18: =CPUE!J16 -> 20 | N18: =Effort!L16 -> CLOSED | O18: =Harvest!L16 -> CLOSED | P18: =CPUE!L16 -> CLOSED | Q18: CLOSED | R18: CLOSED | S18: CLOSED | T18: =SUM(E18+H18+K18) -> 7615.6608 | U18: =SUM(F18+I18+L18) -> 151669.92
A19: 44477 | B19: Fri | C19: -1.1 | D19: 0.86805556 | E19: =Effort!F17 -> 5808.8236 | F19: =Harvest!F17 -> 113854.9 | G19: =+CPUE!F17 -> 19.600338 | H19: =Effort!H17 -> 3703.6259 | I19: =Harvest!H17 -> 73352.368 | J19: =CPUE!H17 -> 19.805556 | K19: =Effort!J17 -> CLOSED | L19: =Harvest!J17 -> CLOSED | M19: =CPUE!J17 -> CLOSED | N19: =Effort!L17 -> 4373.242 | O19: =Harvest!L17 -> 82315.7 | P19: =CPUE!L17 -> 18.822581 | Q19: CLOSED | R19: CLOSED | S19: CLOSED | T19: =SUM(E19+H19+N19) -> 13885.691 | U19: =SUM(F19+I19+O19) -> 269522.97
A20: 44478 | B20: Sat | C20: -1.1 | D20: 0.90138889 | E20: =Effort!F18 -> 3158.1864 | F20: =Harvest!F18 -> 48636.07 | G20: =+CPUE!F18 -> 15.4 | H20: =Effort!H18 -> 3311.0506 | I20: =Harvest!H18 -> 49665.759 | J20: =CPUE!H18 -> 15 | K20: =Effort!J18 -> 3398.4617 | L20: =Harvest!J18 -> 46151.109 | M20: =CPUE!J18 -> 13.58 | N20: =Effort!L18 -> CLOSED | O20: =Harvest!L18 -> CLOSED | P20: =CPUE!L18 -> CLOSED | Q20: CLOSED | R20: CLOSED | S20: CLOSED | T20: =SUM(E20+H20+K20) -> 9867.6986 | U20: =SUM(F20+I20+L20) -> 144452.94
A21: 44479 | B21: Sun | C21: -0.8 | D21: 0.93888889 | E21: =Effort!F19 -> 501.34609 | F21: =Harvest!F19 -> 10026.922 | G21: =+CPUE!F19 -> 20 | H21: =Effort!H19 -> 897.81192 | I21: =Harvest!H19 -> 17719.972 | J21: =CPUE!H19 -> 19.736842 | K21: =Effort!J19 -> CLOSED | L21: =Harvest!J19 -> CLOSED | M21: =CPUE!J19 -> CLOSED | N21: =Effort!L19 -> 859.04416 | O21: =Harvest!L19 -> 16536.6 | P21: =CPUE!L19 -> 19.25 | Q21: CLOSED | R21: CLOSED | S21: CLOSED | T21: =SUM(E21+H21+N21) -> 2258.2022 | U21: =SUM(F21+I21+O21) -> 44283.494
A22: 44480 | B22: Mon | C22: -0.4 | D22: 0.98055556 | E22: =Effort!F20 -> 440.0028 | F22: =Harvest!F20 -> 8800.0559 | G22: =+CPUE!F20 -> 20 | H22: =Effort!H20 -> 461.30004 | I22: =Harvest!H20 -> 9226.0008 | J22: =CPUE!H20 -> 20 | K22: =Effort!J20 -> 473.47827 | L22: =Harvest!J20 -> 9469.5654 | M22: =CPUE!J20 -> 20 | N22: =Effort!L20 -> CLOSED | O22: =Harvest!L20 -> CLOSED | P22: =CPUE!L20 -> CLOSED | Q22: CLOSED | R22: CLOSED | S22: CLOSED | T22: =SUM(E22+H22+K22) -> 1374.7811 | U22: =SUM(F22+I22+L22) -> 27495.622
A23: Tide Series Totals | E23: =SUM(E14:E22) -> 19511.513 | F23: =SUM(F14:F22) -> 351171.55 | G23: =+F23/E23 -> 17.998171 | H23: =SUM(H14:H22) -> 14915.158 | I23: =SUM(I14:I22) -> 265288.79 | J23: =+I23/H23 -> 17.786522 | K23: =SUM(K14:K22) -> 7466.1274 | L23: =SUM(L14:L22) -> 118815 | M23: =+L23/K23 -> 15.913873 | N23: =SUM(N14:N22) -> 8749.3515 | O23: =SUM(O14:O22) -> 165037.44 | P23: =+O23/N23 -> 18.862819 | T23: =SUM(T14:T22) -> 50642.149 | U23: =SUM(U14:U22) -> 900312.77 | W23: =SUM(H23,K23,N23,Q23,E23) -> 50642.149 | X23: =SUM(R23,O23,L23,I23,F23) -> 900312.77
A24: 44488 | B24: Tue | C24: 0.3 | D24: 0.78263889 | E24: =Effort!F22 -> 2799.5254 | F24: =Harvest!F22 -> 47342.834 | G24: =+CPUE!F22 -> 16.911021 | H24: =Effort!H22 -> 2333.5404 | I24: =Harvest!H22 -> 41285.715 | J24: =CPUE!H22 -> 17.692308 | K24: =Effort!J22 -> 2476.1742 | L24: =Harvest!J22 -> 31412.039 | M24: =CPUE!J22 -> 12.685714 | N24: =Effort!L22 -> CLOSED | O24: =Harvest!L22 -> CLOSED | P24: =CPUE!L22 -> CLOSED | Q24: CLOSED | R24: CLOSED | S24: CLOSED | T24: =SUM(E24+H24+K24) -> 7609.24 | U24: =SUM(F24+I24+L24) -> 120040.59
A25: 44489 | B25: Wed | C25: 0 | D25: 0.80763889 | E25: =Effort!F23 -> 907.07414 | F25: =Harvest!F23 -> 16327.335 | G25: =+CPUE!F23 -> 18 | H25: =Effort!H23 -> 1084.6211 | I25: =Harvest!H23 -> 15822.708 | J25: =CPUE!H23 -> 14.588235 | K25: =Effort!J23 -> CLOSED | L25: =Harvest!J23 -> CLOSED | M25: =CPUE!J23 -> CLOSED | N25: =Effort!L23 -> 823.09239 | O25: =Harvest!L23 -> 14729.022 | P25: =CPUE!L23 -> 17.894737 | Q25: CLOSED | R25: CLOSED | S25: CLOSED | T25: =SUM(E25+H25+N25) -> 2814.7877 | U25: =SUM(F25+I25+O25) -> 46879.065
A26: 44490 | B26: Thu | C26: -0.1 | D26: 0.83194444 | E26: =Effort!F24 -> 561.50249 | F26: =Harvest!F24 -> 7861.0349 | G26: =+CPUE!F24 -> 14 | H26: =Effort!H24 -> 359.28053 | I26: =Harvest!H24 -> 4067.0556 | J26: =CPUE!H24 -> 11.32 | K26: =Effort!J24 -> 655.9474 | L26: =Harvest!J24 -> 9307.3618 | M26: =CPUE!J24 -> 14.189189 | N26: =Effort!L24 -> CLOSED | O26: =Harvest!L24 -> CLOSED | P26: =CPUE!L24 -> CLOSED | Q26: CLOSED | R26: CLOSED | S26: CLOSED | T26: =SUM(E26+H26+K26) -> 1576.7304 | U26: =SUM(F26+I26+L26) -> 21235.452
A27: 44491 | B27: Fri | C27: -0.1 | D27: 0.85555556 | E27: =Effort!F25 -> 1414.4384 | F27: =Harvest!F25 -> 12447.058 | G27: =+CPUE!F25 -> 8.8 | H27: =Effort!H25 -> 743.55241 | I27: =Harvest!H25 -> 5961.9384 | J27: =CPUE!H25 -> 8.0181818 | K27: =Effort!J25 -> CLOSED | L27: =Harvest!J25 -> CLOSED | M27: =CPUE!J25 -> CLOSED | N27: =Effort!L25 -> 1283.4821 | O27: =Harvest!L25 -> 15071.747 | P27: =CPUE!L25 -> 11.742857 | Q27: CLOSED | R27: CLOSED | S27: CLOSED | T27: =SUM(E27+H27+N27) -> 3441.4729 | U27: =SUM(F27+I27+O27) -> 33480.744
A28: 44492 | B28: Sat | C28: 0 | D28: 0.87986111 | E28: =Effort!F26 -> 1498.9583 | F28: =Harvest!F26 -> 23983.333 | G28: =+CPUE!F26 -> 16 | H28: =Effort!H26 -> 1195.3813 | I28: =Harvest!H26 -> 19474.753 | J28: =CPUE!H26 -> 16.291667 | K28: =Effort!J26 -> 1751.0836 | L28: =Harvest!J26 -> 27757.918 | M28: =CPUE!J26 -> 15.851852 | N28: =Effort!L26 -> CLOSED | O28: =Harvest!L26 -> CLOSED | P28: =CPUE!L26 -> CLOSED | Q28: CLOSED | R28: CLOSED | S28: CLOSED | T28: =SUM(E28+H28+K28) -> 4445.4232 | U28: =SUM(F28+I28+L28) -> 71216.005
A29: 44493 | B29: Sun | C29: 0.2 | D29: 0.90486111 | E29: =Effort!F27 -> 0 | F29: =Harvest!F27 -> 0 | G29: =+CPUE!F27 -> 0 | H29: =Effort!H27 -> 0 | I29: =Harvest!H27 -> 0 | J29: =CPUE!H27 -> 0 | K29: =Effort!J27 -> CLOSED | L29: =Harvest!J27 -> CLOSED | M29: =CPUE!J27 -> CLOSED | N29: =Effort!L27 -> 0 | O29: =Harvest!L27 -> 0 | P29: =CPUE!L27 -> 0 | Q29: CLOSED | R29: CLOSED | S29: CLOSED | T29: =SUM(E29+H29+N29) -> 0 | U29: =SUM(F29+I29+O29) -> 0
A30: 44494 | B30: Mon | C30: 0.5 | D30: 0.93402778 | E30: =Effort!F28 -> 10.797211 | F30: =Harvest!F28 -> 86 | G30: =+CPUE!F28 -> 8 | H30: =Effort!H28 -> 9 | I30: =Harvest!H28 -> 72 | J30: =CPUE!H28 -> 8 | K30: =Effort!J28 -> 9.5501101 | L30: =Harvest!J28 -> 200 | M30: =CPUE!J28 -> 11 | N30: =Effort!L28 -> CLOSED | O30: =Harvest!L28 -> CLOSED | P30: =CPUE!L28 -> CLOSED | Q30: CLOSED | R30: CLOSED | S30: CLOSED | T30: =SUM(E30+H30+K30) -> 29.347321 | U30: =SUM(F30+I30+L30) -> 358
A31: Tide Series Totals | E31: =SUM(E24:E30) -> 7192.296 | F31: =SUM(F24:F30) -> 108047.59 | G31: =+F31/E31 -> 15.022685 | H31: =SUM(H24:H30) -> 5725.3758 | I31: =SUM(I24:I30) -> 86684.171 | J31: =+I31/H31 -> 15.140346 | K31: =SUM(K24:K30) -> 4892.7554 | L31: =SUM(L24:L30) -> 68677.319 | M31: =+L31/K31 -> 14.036532 | N31: =SUM(N24:N30) -> 2106.5745 | O31: =SUM(O24:O30) -> 29800.769 | P31: =+O31/N31 -> 14.146553 | T31: =SUM(T24:T30) -> 19917.002 | U31: =SUM(U24:U30) -> 293209.85 | W31: =SUM(H31,K31,N31,Q31,E31) -> 19917.002 | X31: =SUM(R31,O31,L31,I31,F31) -> 293209.85
