Workbook

Sheet Harvest
A1: Date | B1: Day | C1: Tide | D1: Time | E1: Longbeach | G1: Twin Harbors | I1: Copalis | K1: Mocrocks | M1: Kalaloch | O1: Daily Totals
A2: 44826 | B2: Thu | C2: 0.4 | D2: 0.21041667 | F2: CLOSED | H2: CLOSED | J2: CLOSED | L2: CLOSED | N2: CLOSED | O2: =SUM(F2:N2) -> 0 | Q2: =SUM(O2:O26) -> 557405.82
A3: 44827 | B3: Fri | C3: 0.1 | D3: 0.23680556 | F3: CLOSED | H3: CLOSED | J3: CLOSED | L3: CLOSED | N3: CLOSED | O3: =SUM(F3:N3) -> 0
A4: 44828 | B4: Sat | C4: 0 | D4: 0.26041667 | F4: CLOSED | H4: CLOSED | J4: CLOSED | L4: CLOSED | N4: CLOSED | O4: =SUM(F4:N4) -> 0
A5: 44829 | B5: Sun | C5: 0.1 | D5: 0.28333333 | F5: CLOSED | H5: CLOSED | J5: CLOSED | L5: CLOSED | N5: CLOSED | O5: =SUM(F5:N5) -> 0
A6: 44830 | B6: Mon | C6: 0.3 | D6: 0.30486111 | F6: CLOSED | H6: CLOSED | J6: CLOSED | L6: CLOSED | N6: CLOSED | O6: =SUM(F6:N6) -> 0
A7: 44831 | B7: Tue | C7: -0.1 | D7: 0.85 | F7: CLOSED | H7: CLOSED | J7: CLOSED | L7: CLOSED | N7: CLOSED | O7: =SUM(F7:N7) -> 0
A8: 44832 | B8: Wed | C8: -0.3 | D8: 0.87916667 | F8: =CPUE!F8*Effort!F8 -> 996.9056 | G8: * | H8: =CPUE!H8*Effort!H8 -> 1558.6676 | J8: 1767.6191 | L8: CLOSED | N8: CLOSED | O8: =SUM(F8:N8) -> 4323.1923
A9: 44833 | B9: Thu | C9: -0.4 | D9: 0.91041667 | F9: =CPUE!F9*Effort!F9 -> 3915.393 | H9: 3826.087 | J9: CLOSED | L9: CLOSED | N9: CLOSED | O9: =SUM(F9:N9) -> 7741.4801
A10: 44834 | B10: Fri | C10: -0.2 | D10: 0.94652778 | E10: * | F10: =CPUE!F10*Effort!F10 -> 8603.1261 | H10: 5535 | J10: 8299.6075 | L10: CLOSED | N10: CLOSED | O10: =SUM(F10:N10) -> 22437.734
A12: 44842 | B12: Sat | C12: 0.5 | D12: 0.76458333 | F12: =CPUE!F12*Effort!F12 -> 77650.792 | H12: 69057.748 | J12: CLOSED | L12: CLOSED | N12: CLOSED | O12: =SUM(F12:N12) -> 146708.54
A13: 44843 | B13: Sun | C13: -0.1 | D13: 0.79513889 | E13: * | F13: =CPUE!F13*Effort!F13 -> 37179.628 | H13: 32809.273 | J13: 49687.845 | L13: CLOSED | N13: CLOSED | O13: =SUM(F13:N13) -> 119676.75
A14: 44844 | B14: Mon | C14: -0.5 | D14: 0.82361111 | F14: =CPUE!F14*Effort!F14 -> 18662.155 | G14: * | H14: =CPUE!H14*Effort!H14 -> 16596.951 | J14: CLOSED | L14: CLOSED | N14: CLOSED | O14: =SUM(F14:N14) -> 35259.106
A15: 44845 | B15: Tue | C15: -0.6 | D15: 0.85138889 | F15: =CPUE!F15*Effort!F15 -> 11273.973 | G15: * | H15: =CPUE!H15*Effort!H15 -> 9159.1934 | J15: 14071.326 | L15: CLOSED | N15: CLOSED | O15: =SUM(F15:N15) -> 34504.493
A16: 44846 | B16: Wed | C16: -0.4 | D16: 0.87916667 | E16: * | F16: =CPUE!F16*Effort!F16 -> 5509.1939 | H16: 4812.0402 | J16: CLOSED | L16: CLOSED | N16: CLOSED | O16: =SUM(F16:N16) -> 10321.234
A17: 44847 | B17: Thu | C17: -0.2 | D17: 0.90694444 | F17: =CPUE!F17*Effort!F17 -> 4738.6041 | G17: * | H17: =CPUE!H17*Effort!H17 -> 3933.2697 | J17: 6922.6667 | L17: CLOSED | N17: CLOSED | O17: =SUM(F17:N17) -> 15594.541
A18: 44848 | B18: Fri | C18: 0.3 | D18: 0.93680556 | E18: * | F18: =CPUE!F18*Effort!F18 -> 7737.1677 | H18: 6880.9521 | J18: CLOSED | L18: CLOSED | N18: CLOSED | O18: =SUM(F18:N18) -> 14618.12
A20: 44858 | B20: Mon | C20: 0 | D20: 0.78055556 | F20: =CPUE!F20*Effort!F20 -> 13759.097 | H20: 11335.032 | J20: 17932.356 | L20: CLOSED | N20: CLOSED | O20: =SUM(F20:N20) -> 43026.486
A21: 44859 | B21: Tue | C21: -0.6 | D21: 0.80833333 | F21: =CPUE!F21*Effort!F21 -> 3178.7692 | H21: 5415.1712 | J21: CLOSED | L21: CLOSED | N21: CLOSED | O21: =SUM(F21:N21) -> 8593.9404
A22: 44860 | B22: Wed | C22: -1 | D22: 0.83680556 | F22: =4021.49690744578+6189.89090622317 -> 10211.388 | G22: * | H22: =CPUE!H22*Effort!H22 -> 7474.2518 | J22: 7341.4864 | L22: CLOSED | N22: CLOSED | O22: =SUM(F22:N22) -> 25027.126
A23: 44861 | B23: Thu | C23: -1.1 | D23: 0.86666667 | E23: * | F23: =CPUE!F23*Effort!F23 -> 4884.6479 | H23: 4772.0199 | J23: CLOSED | L23: CLOSED | N23: CLOSED | O23: =SUM(F23:N23) -> 9656.6678
A24: 44862 | B24: Fri | C24: -1 | D24: 0.89930556 | F24: =CPUE!F24*Effort!F24 -> 5233.4364 | G24: * | H24: =CPUE!H24*Effort!H24 -> 8256.3586 | J24: 14229.044 | L24: CLOSED | N24: CLOSED | O24: =SUM(F24:N24) -> 27718.838
A25: 44863 | B25: Sat | C25: -0.7 | D25: 0.93611111 | E25: * | F25: =CPUE!F25*Effort!F25 -> 15968.622 | H25: 15817.892 | J25: CLOSED | L25: CLOSED | N25: CLOSED | O25: =SUM(F25:N25) -> 31786.513
A26: 44864 | B26: Sun | C26: -0.3 | D26: 0.97708333 | E26: * | F26: =CPUE!F26*Effort!F26 -> 146.97852 | G26: * | H26: =CPUE!H26*Effort!H26 -> 114.08908 | J26: 149.99999 | L26: CLOSED | N26: CLOSED | O26: =SUM(F26:N26) -> 411.0676
A28: 44871 | B28: Sun | C28: 0 | D28: 0.71388889 | F28: CLOSED | H28: CLOSED | J28: CLOSED | L28: CLOSED | N28: CLOSED | O28: =SUM(F28:N28) -> 0
A29: 44872 | B29: Mon | C29: -0.5 | D29: 0.74236111 | F29: CLOSED | H29: CLOSED | J29: CLOSED | L29: CLOSED | N29: CLOSED | O29: =SUM(F29:N29) -> 0
A30: 44873 | B30: Tue | C30: -0.7 | D30: 0.76944444 | F30: CLOSED | H30: CLOSED | J30: CLOSED | L30: CLOSED | N30: CLOSED | O30: =SUM(F30:N30) -> 0
A31: 44874 | B31: Wed | C31: -0.7 | D31: 0.79513889 | F31: CLOSED | H31: CLOSED | J31: CLOSED | L31: CLOSED | N31: CLOSED | O31: =SUM(F31:N31) -> 0
A32: 44875 | B32: Thu | C32: -0.6 | D32: 0.82083333 | F32: CLOSED | H32: CLOSED | J32: CLOSED | L32: CLOSED | N32: CLOSED | O32: =SUM(F32:N32) -> 0
A33: 44876 | B33: Fri | C33: -0.2 | D33: 0.84652778 | F33: CLOSED | H33: CLOSED | J33: CLOSED | L33: CLOSED | N33: CLOSED | O33: =SUM(F33:N33) -> 0
A34: 44877 | B34: Sat | C34: 0.1 | D34: 0.87430556 | F34: CLOSED | H34: CLOSED | J34: CLOSED | L34: CLOSED | N34: CLOSED | O34: =SUM(F34:N34) -> 0
A35: 44878 | B35: Sun | C35: 0.5 | D35: 0.90486111 | F35: CLOSED | H35: CLOSED | J35: CLOSED | L35: CLOSED | N35: CLOSED | O35: =SUM(F35:N35) -> 0
A37: 44887 | B37: Tue | C37: -0.6 | D37: 0.72361111 | F37: CLOSED | H37: CLOSED | J37: CLOSED | L37: CLOSED | N37: CLOSED | O37: =SUM(F37:N37) -> 0
A38: 44888 | B38: Wed | C38: -1.2 | D38: 0.75277778 | F38: CLOSED | H38: CLOSED | J38: CLOSED | L38: CLOSED | N38: CLOSED | O38: =SUM(F38:N38) -> 0
A39: 44889 | B39: Thu | C39: -1.6 | D39: 0.78333333 | F39: CLOSED | H39: CLOSED | J39: CLOSED | L39: CLOSED | N39: CLOSED | O39: =SUM(F39:N39) -> 0
A40: 44890 | B40: Fri | C40: -1.6 | D40: 0.81597222 | F40: CLOSED | H40: CLOSED | J40: CLOSED | L40: CLOSED | N40: CLOSED | O40: =SUM(F40:N40) -> 0
... A76: 44946 | B76: Fri | C76: -1.5 | D76: 0.73263889 | F76: CLOSED | H76: CLOSED | J76: CLOSED | L76: CLOSED | N76: CLOSED | O76: =SUM(F76:N76) -> 0
A77: 44947 | B77: Sat | C77: -1.8 | D77: 0.76597222 | F77: CLOSED | H77: CLOSED | J77: 13608.567 | L77: CLOSED | N77: CLOSED | O77: =SUM(F77:N77) -> 13608.567
A78: 44948 | B78: Sun | C78: -1.8 | D78: 0.79722222 | F78: CLOSED | H78: CLOSED | J78: CLOSED | L78: CLOSED | N78: CLOSED | O78: =SUM(F78:N78) -> 0
A79: 44949 | B79: Mon | C79: -1.6 | D79: 0.82916667 | F79: CLOSED | H79: CLOSED | J79: 27755.45 | L79: CLOSED | N79: CLOSED | O79: =SUM(F79:N79) -> 27755.45
...

Sheet Effort
A1: Date | B1: Day | C1: Tide | D1: Time | E1: Longbeach | G1: Twin Harbors | I1: Copalis | K1: Mocrocks | M1: Kalaloch | O1: Daily Totals
A2: 44826 | B2: Thu | C2: 0.4 | D2: 0.21041667 | F2: CLOSED | H2: CLOSED | J2: CLOSED | L2: CLOSED | N2: CLOSED | O2: =SUM(F2:N2) -> 0 | Q2: =SUM(O2:O26) -> 40883.329
A3: 44827 | B3: Fri | C3: 0.1 | D3: 0.23680556 | F3: CLOSED | H3: CLOSED | J3: CLOSED | L3: CLOSED | N3: CLOSED | O3: =SUM(F3:N3) -> 0
A4: 44828 | B4: Sat | C4: 0 | D4: 0.26041667 | F4: CLOSED | H4: CLOSED | J4: CLOSED | L4: CLOSED | N4: CLOSED | O4: =SUM(F4:N4) -> 0
A5: 44829 | B5: Sun | C5: 0.1 | D5: 0.28333333 | F5: CLOSED | H5: CLOSED | J5: CLOSED | L5: CLOSED | N5: CLOSED | O5: =SUM(F5:N5) -> 0
A6: 44830 | B6: Mon | C6: 0.3 | D6: 0.30486111 | F6: CLOSED | H6: CLOSED | J6: CLOSED | L6: CLOSED | N6: CLOSED | O6: =SUM(F6:N6) -> 0
A7: 44831 | B7: Tue | C7: -0.1 | D7: 0.85 | F7: CLOSED | H7: CLOSED | J7: CLOSED | L7: CLOSED | N7: CLOSED | O7: =SUM(F7:N7) -> 0
A8: 44832 | B8: Wed | C8: -0.3 | D8: 0.87916667 | F8: =(1965.57669210003/1431.52098212702*84.0182660750021)+84.0182660750021 -> 199.38112 | G8: * | H8: =H9/F9*F8 -> 194.83345 | J8: 200.86581 | L8: CLOSED | N8: CLOSED | O8: =SUM(F8:N8) -> 595.08038
A9: 44833 | B9: Thu | C9: -0.4 | D9: 0.91041667 | F9: =(1965.57669210003/1431.52098212702*109.99521338519)+109.99521338519 -> 261.0262 | H9: 255.07247 | J9: CLOSED | L9: CLOSED | N9: CLOSED | O9: =SUM(F9:N9) -> 516.09867
A10: 44834 | B10: Fri | C10: -0.2 | D10: 0.94652778 | E10: * | F10: =F8/J8*J10 -> 614.50901 | H10: 378 | J10: 619.08494 | L10: CLOSED | N10: CLOSED | O10: =SUM(F10:N10) -> 1611.5939
A12: 44842 | B12: Sat | C12: 0.5 | D12: 0.76458333 | F12: =(1965.57669210003/1431.52098212702*2256.66747529896)+2256.66747529896 -> 5355.227 | H12: 4762.6033 | J12: CLOSED | L12: CLOSED | N12: CLOSED | O12: =SUM(F12:N12) -> 10117.83
A13: 44843 | B13: Sun | C13: -0.1 | D13: 0.79513889 | E13: * | F13: =F12/H12*H13 -> 2564.1123 | H13: 2280.3608 | J13: 3429.6324 | L13: CLOSED | N13: CLOSED | O13: =SUM(F13:N13) -> 8274.1055
A14: 44844 | B14: Mon | C14: -0.5 | D14: 0.82361111 | F14: =(1965.57669210003/1431.52098212702*524.276282140161)+524.276282140161 -> 1244.1436 | G14: * | H14: =H12/F12*F14 -> 1106.4634 | J14: CLOSED | L14: CLOSED | N14: CLOSED | O14: =SUM(F14:N14) -> 2350.607
A15: 44845 | B15: Tue | C15: -0.6 | D15: 0.85138889 | F15: =(1965.57669210003/1431.52098212702*327.641329647419)+327.641329647419 -> 777.51539 | G15: * | H15: =H13/J13*J15 -> 631.66851 | J15: 950.02105 | L15: CLOSED | N15: CLOSED | O15: =SUM(F15:N15) -> 2359.205
A16: 44846 | B16: Wed | C16: -0.4 | D16: 0.87916667 | E16: * | F16: =F12/H12*H16 -> 393.51385 | H16: 349.96656 | J16: CLOSED | L16: CLOSED | N16: CLOSED | O16: =SUM(F16:N16) -> 743.48042
A17: 44847 | B17: Thu | C17: -0.2 | D17: 0.90694444 | F17: =(1965.57669210003/1431.52098212702*133.121699167157)+133.121699167157 -> 315.90694 | G17: * | H17: =H12/F12*F17 -> 280.94784 | J17: 492.8 | L17: CLOSED | N17: CLOSED | O17: =SUM(F17:N17) -> 1089.6548
A18: 44848 | B18: Fri | C18: 0.3 | D18: 0.93680556 | E18: * | F18: =F12/H12*H18 -> 515.81118 | H18: 458.73014 | J18: CLOSED | L18: CLOSED | N18: CLOSED | O18: =SUM(F18:N18) -> 974.54132
A20: 44858 | B20: Mon | C20: 0 | D20: 0.78055556 | F20: =(480.102341756922/290.211117032169*471.24181687276)+471.24181687276 -> 1250.827 | H20: 970.92904 | J20: 1276.5406 | L20: CLOSED | N20: CLOSED | O20: =SUM(F20:N20) -> 3498.2967
A21: 44859 | B21: Tue | C21: -0.6 | D21: 0.80833333 | F21: =(290.211117032169/480.102341756922*247.648295758035)+247.648295758035 -> 397.34615 | H21: 388.18431 | J21: CLOSED | L21: CLOSED | N21: CLOSED | O21: =SUM(F21:N21) -> 785.53046
A22: 44860 | B22: Wed | C22: -1 | D22: 0.83680556 | F22: =480.102341756922+290.211117032169 -> 770.31346 | G22: * | H22: =H20/F20*F22 -> 597.94015 | J22: 597.74106 | L22: CLOSED | N22: CLOSED | O22: =SUM(F22:N22) -> 1965.9947
A23: 44861 | B23: Thu | C23: -1.1 | D23: 0.86666667 | E23: * | F23: =F21/H21*H23 -> 514.17347 | H23: 502.31788 | J23: CLOSED | L23: CLOSED | N23: CLOSED | O23: =SUM(F23:N23) -> 1016.4914
A24: 44862 | B24: Fri | C24: -1 | D24: 0.89930556 | F24: =(480.102341756922/290.211117032169*303.333341368923)+303.333341368923 -> 805.14405 | G24: * | H24: =H20/J20*J24 -> 825.63586 | J24: 1085.5147 | L24: CLOSED | N24: CLOSED | O24: =SUM(F24:N24) -> 2716.2946
A25: 44863 | B25: Sat | C25: -0.7 | D25: 0.93611111 | E25: * | F25: =F21/H21*H25 -> 1101.2843 | H25: 1075.8913 | J25: CLOSED | L25: CLOSED | N25: CLOSED | O25: =SUM(F25:N25) -> 2177.1756
A26: 44864 | B26: Sun | C26: -0.3 | D26: 0.97708333 | E26: * | F26: =F20/J20*J26 -> 32.661893 | G26: * | H26: =H20/J20*J26 -> 25.35313 | J26: 33.333332 | L26: CLOSED | N26: CLOSED | O26: =SUM(F26:N26) -> 91.348355
A28: 44871 | B28: Sun | C28: 0 | D28: 0.71388889 | F28: CLOSED | H28: CLOSED | J28: CLOSED | L28: CLOSED | N28: CLOSED | O28: =SUM(F28:N28) -> 0
A29: 44872 | B29: Mon | C29: -0.5 | D29: 0.74236111 | F29: CLOSED | H29: CLOSED | J29: CLOSED | L29: CLOSED | N29: CLOSED | O29: =SUM(F29:N29) -> 0
A30: 44873 | B30: Tue | C30: -0.7 | D30: 0.76944444 | F30: CLOSED | H30: CLOSED | J30: CLOSED | L30: CLOSED | N30: CLOSED | O30: =SUM(F30:N30) -> 0
A31: 44874 | B31: Wed | C31: -0.7 | D31: 0.79513889 | F31: CLOSED | H31: CLOSED | J31: CLOSED | L31: CLOSED | N31: CLOSED | O31: =SUM(F31:N31) -> 0
A32: 44875 | B32: Thu | C32: -0.6 | D32: 0.82083333 | F32: CLOSED | H32: CLOSED | J32: CLOSED | L32: CLOSED | N32: CLOSED | O32: =SUM(F32:N32) -> 0
A33: 44876 | B33: Fri | C33: -0.2 | D33: 0.84652778 | F33: CLOSED | H33: CLOSED | J33: CLOSED | L33: CLOSED | N33: CLOSED | O33: =SUM(F33:N33) -> 0
A34: 44877 | B34: Sat | C34: 0.1 | D34: 0.87430556 | F34: CLOSED | H34: CLOSED | J34: CLOSED | L34: CLOSED | N34: CLOSED | O34: =SUM(F34:N34) -> 0
A35: 44878 | B35: Sun | C35: 0.5 | D35: 0.90486111 | F35: CLOSED | H35: CLOSED | J35: CLOSED | L35: CLOSED | N35: CLOSED | O35: =SUM(F35:N35) -> 0
A37: 44887 | B37: Tue | C37: -0.6 | D37: 0.72361111 | F37: CLOSED | H37: CLOSED | J37: CLOSED | L37: CLOSED | N37: CLOSED | O37: =SUM(F37:N37) -> 0
A38: 44888 | B38: Wed | C38: -1.2 | D38: 0.75277778 | F38: CLOSED | H38: CLOSED | J38: CLOSED | L38: CLOSED | N38: CLOSED | O38: =SUM(F38:N38) -> 0
A39: 44889 | B39: Thu | C39: -1.6 | D39: 0.78333333 | F39: CLOSED | H39: CLOSED | J39: CLOSED | L39: CLOSED | N39: CLOSED | O39: =SUM(F39:N39) -> 0
A40: 44890 | B40: Fri | C40: -1.6 | D40: 0.81597222 | F40: CLOSED | H40: CLOSED | J40: CLOSED | L40: CLOSED | N40: CLOSED | O40: =SUM(F40:N40) -> 0
... A76: 44946 | B76: Fri | C76: -1.5 | D76: 0.73263889 | F76: CLOSED | H76: CLOSED | J76: CLOSED | L76: CLOSED | N76: CLOSED | O76: =SUM(F76:N76) -> 0
A77: 44947 | B77: Sat | C77: -1.8 | D77: 0.76597222 | F77: CLOSED | H77: CLOSED | J77: 1999.8252 | L77: CLOSED | N77: CLOSED | O77: =SUM(F77:N77) -> 1999.8252
A78: 44948 | B78: Sun | C78: -1.8 | D78: 0.79722222 | F78: CLOSED | H78: CLOSED | J78: CLOSED | L78: CLOSED | N78: CLOSED | O78: =SUM(F78:N78) -> 0
A79: 44949 | B79: Mon | C79: -1.6 | D79: 0.82916667 | F79: CLOSED | H79: CLOSED | J79: 1930.2351 | L79: CLOSED | N79: CLOSED | O79: =SUM(F79:N79) -> 1930.2351
...

Sheet CPUE
A1: Date | B1: Day | C1: Tide | D1: Time | E1: Longbeach | G1: Twin Harbors | I1: Copalis | K1: Mocrocks | M1: Kalaloch | O1: Daily Totals
A2: 44826 | B2: Thu | C2: 0.4 | D2: 0.21041667 | F2: CLOSED | H2: CLOSED | J2: CLOSED | L2: CLOSED | N2: CLOSED | O2: 0 | Q2: =AVERAGE(O2:O26) -> 9.2497806
A3: 44827 | B3: Fri | C3: 0.1 | D3: 0.23680556 | F3: CLOSED | H3: CLOSED | J3: CLOSED | L3: CLOSED | N3: CLOSED | O3: 0
A4: 44828 | B4: Sat | C4: 0 | D4: 0.26041667 | F4: CLOSED | H4: CLOSED | J4: CLOSED | L4: CLOSED | N4: CLOSED | O4: 0
A5: 44829 | B5: Sun | C5: 0.1 | D5: 0.28333333 | F5: CLOSED | H5: CLOSED | J5: CLOSED | L5: CLOSED | N5: CLOSED | O5: 0
A6: 44830 | B6: Mon | C6: 0.3 | D6: 0.30486111 | F6: CLOSED | H6: CLOSED | J6: CLOSED | L6: CLOSED | N6: CLOSED | O6: 0
A7: 44831 | B7: Tue | C7: -0.1 | D7: 0.85 | F7: CLOSED | H7: CLOSED | J7: CLOSED | L7: CLOSED | N7: CLOSED | O7: 0
A8: 44832 | B8: Wed | C8: -0.3 | D8: 0.87916667 | F8: 5 | G8: * | H8: 8 | J8: =+Harvest!J8/Effort!J8 -> 8.8 | L8: CLOSED | N8: CLOSED | O8: =+Harvest!O8/Effort!O8 -> 7.264888
A9: 44833 | B9: Thu | C9: -0.4 | D9: 0.91041667 | F9: 15 | H9: =+Harvest!H9/Effort!H9 -> 15 | J9: CLOSED | L9: CLOSED | N9: CLOSED | O9: =+Harvest!O9/Effort!O9 -> 15
A10: 44834 | B10: Fri | C10: -0.2 | D10: 0.94652778 | E10: * | F10: 14 | H10: =+Harvest!H10/Effort!H10 -> 14.642857 | J10: =+Harvest!J10/Effort!J10 -> 13.40625 | L10: CLOSED | N10: CLOSED | O10: =+Harvest!O10/Effort!O10 -> 13.922697
A12: 44842 | B12: Sat | C12: 0.5 | D12: 0.76458333 | F12: 14.5 | H12: =+Harvest!H12/Effort!H12 -> 14.5 | J12: CLOSED | L12: CLOSED | N12: CLOSED | O12: =+Harvest!O12/Effort!O12 -> 14.5
A13: 44843 | B13: Sun | C13: -0.1 | D13: 0.79513889 | E13: * | F13: 14.5 | H13: =+Harvest!H13/Effort!H13 -> 14.387755 | J13: =+Harvest!J13/Effort!J13 -> 14.487805 | L13: CLOSED | N13: CLOSED | O13: =+Harvest!O13/Effort!O13 -> 14.46401
A14: 44844 | B14: Mon | C14: -0.5 | D14: 0.82361111 | F14: 15 | G14: * | H14: 15 | J14: CLOSED | L14: CLOSED | N14: CLOSED | O14: =+Harvest!O14/Effort!O14 -> 15
A15: 44845 | B15: Tue | C15: -0.6 | D15: 0.85138889 | F15: 14.5 | G15: * | H15: 14.5 | J15: =+Harvest!J15/Effort!J15 -> 14.811594 | L15: CLOSED | N15: CLOSED | O15: =+Harvest!O15/Effort!O15 -> 14.625475
A16: 44846 | B16: Wed | C16: -0.4 | D16: 0.87916667 | E16: * | F16: 14 | H16: =+Harvest!H16/Effort!H16 -> 13.75 | J16: CLOSED | L16: CLOSED | N16: CLOSED | O16: =+Harvest!O16/Effort!O16 -> 13.882322
A17: 44847 | B17: Thu | C17: -0.2 | D17: 0.90694444 | F17: 15 | G17: * | H17: 14 | J17: =+Harvest!J17/Effort!J17 -> 14.047619 | L17: CLOSED | N17: CLOSED | O17: =+Harvest!O17/Effort!O17 -> 14.311451
A18: 44848 | B18: Fri | C18: 0.3 | D18: 0.93680556 | E18: * | F18: 15 | H18: =+Harvest!H18/Effort!H18 -> 15 | J18: CLOSED | L18: CLOSED | N18: CLOSED | O18: =+Harvest!O18/Effort!O18 -> 15
A20: 44858 | B20: Mon | C20: 0 | D20: 0.78055556 | F20: 11 | H20: =+Harvest!H20/Effort!H20 -> 11.674419 | J20: =+Harvest!J20/Effort!J20 -> 14.047619 | L20: CLOSED | N20: CLOSED | O20: =+Harvest!O20/Effort!O20 -> 12.299267
A21: 44859 | B21: Tue | C21: -0.6 | D21: 0.80833333 | F21: 8 | H21: =+Harvest!H21/Effort!H21 -> 13.95 | J21: CLOSED | L21: CLOSED | N21: CLOSED | O21: =+Harvest!O21/Effort!O21 -> 10.940302
A22: 44860 | B22: Wed | C22: -1 | D22: 0.83680556 | F22: =+Harvest!F22/Effort!F22 -> 13.256146 | G22: * | H22: 12.5 | J22: =+Harvest!J22/Effort!J22 -> 12.282051 | L22: CLOSED | N22: CLOSED | O22: =+Harvest!O22/Effort!O22 -> 12.730007
A23: 44861 | B23: Thu | C23: -1.1 | D23: 0.86666667 | E23: * | F23: 9.5 | H23: =+Harvest!H23/Effort!H23 -> 9.5 | J23: CLOSED | L23: CLOSED | N23: CLOSED | O23: =+Harvest!O23/Effort!O23 -> 9.5
A24: 44862 | B24: Fri | C24: -1 | D24: 0.89930556 | F24: 6.5 | G24: * | H24: 10 | J24: =+Harvest!J24/Effort!J24 -> 13.108108 | L24: CLOSED | N24: CLOSED | O24: =+Harvest!O24/Effort!O24 -> 10.204651
A25: 44863 | B25: Sat | C25: -0.7 | D25: 0.93611111 | E25: * | F25: 14.5 | H25: =+Harvest!H25/Effort!H25 -> 14.702128 | J25: CLOSED | L25: CLOSED | N25: CLOSED | O25: =+Harvest!O25/Effort!O25 -> 14.599885
A26: 44864 | B26: Sun | C26: -0.3 | D26: 0.97708333 | E26: * | F26: 4.5 | G26: * | H26: 4.5 | J26: =+Harvest!J26/Effort!J26 -> 4.5 | L26: CLOSED | N26: CLOSED | O26: =+Harvest!O26/Effort!O26 -> 4.5
A28: 44871 | B28: Sun | C28: 0 | D28: 0.71388889 | F28: CLOSED | H28: CLOSED | J28: CLOSED | L28: CLOSED | N28: CLOSED | O28: =SUM(F28:N28) -> 0
A29: 44872 | B29: Mon | C29: -0.5 | D29: 0.74236111 | F29: CLOSED | H29: CLOSED | J29: CLOSED | L29: CLOSED | N29: CLOSED | O29: =SUM(F29:N29) -> 0
A30: 44873 | B30: Tue | C30: -0.7 | D30: 0.76944444 | F30: CLOSED | H30: CLOSED | J30: CLOSED | L30: CLOSED | N30: CLOSED | O30: =SUM(F30:N30) -> 0
A31: 44874 | B31: Wed | C31: -0.7 | D31: 0.79513889 | F31: CLOSED | H31: CLOSED | J31: CLOSED | L31: CLOSED | N31: CLOSED | O31: =SUM(F31:N31) -> 0
A32: 44875 | B32: Thu | C32: -0.6 | D32: 0.82083333 | F32: CLOSED | H32: CLOSED | J32: CLOSED | L32: CLOSED | N32: CLOSED | O32: =SUM(F32:N32) -> 0
A33: 44876 | B33: Fri | C33: -0.2 | D33: 0.84652778 | F33: CLOSED | H33: CLOSED | J33: CLOSED | L33: CLOSED | N33: CLOSED | O33: =SUM(F33:N33) -> 0
A34: 44877 | B34: Sat | C34: 0.1 | D34: 0.87430556 | F34: CLOSED | H34: CLOSED | J34: CLOSED | L34: CLOSED | N34: CLOSED | O34: =SUM(F34:N34) -> 0
A35: 44878 | B35: Sun | C35: 0.5 | D35: 0.90486111 | F35: CLOSED | H35: CLOSED | J35: CLOSED | L35: CLOSED | N35: CLOSED | O35: =SUM(F35:N35) -> 0
A37: 44887 | B37: Tue | C37: -0.6 | D37: 0.72361111 | F37: CLOSED | H37: CLOSED | J37: CLOSED | L37: CLOSED | N37: CLOSED | O37: =SUM(F37:N37) -> 0
A38: 44888 | B38: Wed | C38: -1.2 | D38: 0.75277778 | F38: CLOSED | H38: CLOSED | J38: CLOSED | L38: CLOSED | N38: CLOSED | O38: =SUM(F38:N38) -> 0
A39: 44889 | B39: Thu | C39: -1.6 | D39: 0.78333333 | F39: CLOSED | H39: CLOSED | J39: CLOSED | L39: CLOSED | N39: CLOSED | O39: =SUM(F39:N39) -> 0
A40: 44890 | B40: Fri | C40: -1.6 | D40: 0.81597222 | F40: CLOSED | H40: CLOSED | J40: CLOSED | L40: CLOSED | N40: CLOSED | O40: =SUM(F40:N40) -> 0
... A76: 44946 | B76: Fri | C76: -1.5 | D76: 0.73263889 | F76: CLOSED | H76: CLOSED | J76: CLOSED | L76: CLOSED | N76: CLOSED | O76: =SUM(F76:N76) -> 0
A77: 44947 | B77: Sat | C77: -1.8 | D77: 0.76597222 | F77: CLOSED | H77: CLOSED | J77: =+Harvest!J77/Effort!J77 -> 6.804878 | L77: CLOSED | N77: CLOSED | O77: =+Harvest!O77/Effort!O77 -> 6.804878
A78: 44948 | B78: Sun | C78: -1.8 | D78: 0.79722222 | F78: CLOSED | H78: CLOSED | J78: CLOSED | L78: CLOSED | N78: CLOSED | O78: =SUM(F78:N78) -> 0
A79: 44949 | B79: Mon | C79: -1.6 | D79: 0.82916667 | F79: CLOSED | H79: CLOSED | J79: =+Harvest!J79/Effort!J79 -> 14.37931 | L79: CLOSED | N79: CLOSED | O79: =+Harvest!O79/Effort!O79 -> 14.37931
...

Sheet Summary Table
A1: 2022-2023 State (non-Tribal) Recreational Razor Clam Effort, Harvest and CPUE totals.
E2: LONG BEACH | H2: TWIN HARBORS | K2: COPALIS | N2: MOCROCKS | Q2: KALALOCH | T2: DAILY TOTALS | W2: CROSS | X2: CHECK
A3: DATE | B3: DAY | C3: TIDE | D3: TIME | E3: Effort | F3: Harvest | G3: CPUE | H3: Effort | I3: Harvest | J3: CPUE | K3: Effort | L3: Harvest | M3: CPUE | N3: Effort | O3: Harvest | P3: CPUE | Q3: Effort | R3: Harvest | S3: CPUE | T3: Effort | U3: Harvest
A4: 44826 | B4: Thu | C4: 0.4 | D4: 0.21041667 | E4: =Effort!F2 -> CLOSED | F4: =Harvest!F2 -> CLOSED | G4: =+CPUE!F2 -> CLOSED | H4: =Effort!H2 -> CLOSED | I4: =Harvest!H2 -> CLOSED | J4: =CPUE!H2 -> CLOSED | K4: =Effort!J2 -> CLOSED | L4: =Harvest!J2 -> CLOSED | M4: =CPUE!J2 -> CLOSED | N4: =Effort!L2 -> CLOSED | O4: =Harvest!L2 -> CLOSED | P4: =CPUE!L2 -> CLOSED | Q4: CLOSED | R4: CLOSED | S4: CLOSED | T4: 0 | U4: 0
A5: 44827 | B5: Fri | C5: 0.1 | D5: 0.23680556 | E5: =Effort!F3 -> CLOSED | F5: =Harvest!F3 -> CLOSED | G5: =+CPUE!F3 -> CLOSED | H5: =Effort!H3 -> CLOSED | I5: =Harvest!H3 -> CLOSED | J5: =CPUE!H3 -> CLOSED | K5: =Effort!J3 -> CLOSED | L5: =Harvest!J3 -> CLOSED | M5: =CPUE!J3 -> CLOSED | N5: =Effort!L3 -> CLOSED | O5: =Harvest!L3 -> CLOSED | P5: =CPUE!L3 -> CLOSED | Q5: CLOSED | R5: CLOSED | S5: CLOSED | T5: 0 | U5: 0
A6: 44828 | B6: Sat | C6: 0 | D6: 0.26041667 | E6: =Effort!F4 -> CLOSED | F6: =Harvest!F4 -> CLOSED | G6: =+CPUE!F4 -> CLOSED | H6: =Effort!H4 -> CLOSED | I6: =Harvest!H4 -> CLOSED | J6: =CPUE!H4 -> CLOSED | K6: =Effort!J4 -> CLOSED | L6: =Harvest!J4 -> CLOSED | M6: =CPUE!J4 -> CLOSED | N6: =Effort!L4 -> CLOSED | O6: =Harvest!L4 -> CLOSED | P6: =CPUE!L4 -> CLOSED | Q6: CLOSED | R6: CLOSED | S6: CLOSED | T6: 0 | U6: 0
A7: 44829 | B7: Sun | C7: 0.1 | D7: 0.28333333 | E7: =Effort!F5 -> CLOSED | F7: =Harvest!F5 -> CLOSED | G7: =+CPUE!F5 -> CLOSED | H7: =Effort!H5 -> CLOSED | I7: =Harvest!H5 -> CLOSED | J7: =CPUE!H5 -> CLOSED | K7: =Effort!J5 -> CLOSED | L7: =Harvest!J5 -> CLOSED | M7: =CPUE!J5 -> CLOSED | N7: =Effort!L5 -> CLOSED | O7: =Harvest!L5 -> CLOSED | P7: =CPUE!L5 -> CLOSED | Q7: CLOSED | R7: CLOSED | S7: CLOSED | T7: 0 | U7: 0
A8: 44830 | B8: Mon | C8: 0.3 | D8: 0.30486111 | E8: =Effort!F6 -> CLOSED | F8: =Harvest!F6 -> CLOSED | G8: =+CPUE!F6 -> CLOSED | H8: =Effort!H6 -> CLOSED | I8: =Harvest!H6 -> CLOSED | J8: =CPUE!H6 -> CLOSED | K8: =Effort!J6 -> CLOSED | L8: =Harvest!J6 -> CLOSED | M8: =CPUE!J6 -> CLOSED | N8: =Effort!L6 -> CLOSED | O8: =Harvest!L6 -> CLOSED | P8: =CPUE!L6 -> CLOSED | Q8: CLOSED | R8: CLOSED | S8: CLOSED | T8: 0 | U8: 0
A9: 44831 | B9: Tue | C9: -0.1 | D9: 0.85 | E9: =Effort!F7 -> CLOSED | F9: =Harvest!F7 -> CLOSED | G9: =+CPUE!F7 -> CLOSED | H9: =Effort!H7 -> CLOSED | I9: =Harvest!H7 -> CLOSED | J9: =CPUE!H7 -> CLOSED | K9: =Effort!J7 -> CLOSED | L9: =Harvest!J7 -> CLOSED | M9: =CPUE!J7 -> CLOSED | N9: =Effort!L7 -> CLOSED | O9: =Harvest!L7 -> CLOSED | P9: =CPUE!L7 -> CLOSED | Q9: CLOSED | R9: CLOSED | S9: CLOSED | T9: 0 | U9: 0
A10: 44832 | B10: Wed | C10: -0.3 | D10: 0.87916667 | E10: =Effort!F8 -> 199.38112 | F10: =Harvest!F8 -> 996.9056 | G10: =+CPUE!F8 -> 5 | H10: =Effort!H8 -> 194.83345 | I10: =Harvest!H8 -> 1558.6676 | J10: =CPUE!H8 -> 8 | K10: =Effort!J8 -> 200.86581 | L10: =Harvest!J8 -> 1767.6191 | M10: =CPUE!J8 -> 8.8 | N10: =Effort!L8 -> CLOSED | O10: =Harvest!L8 -> CLOSED | P10: =CPUE!L8 -> CLOSED | Q10: CLOSED | R10: CLOSED | S10: CLOSED | T10: =SUM(E10+H10+K10) -> 595.08038 | U10: =SUM(F10+I10+L10) -> 4323.1923
A11: 44833 | B11: Thu | C11: -0.4 | D11: 0.91041667 | E11: =Effort!F9 -> 261.0262 | F11: =Harvest!F9 -> 3915.393 | G11: =+CPUE!F9 -> 15 | H11: =Effort!H9 -> 255.07247 | I11: =Harvest!H9 -> 3826.087 | J11: =CPUE!H9 -> 15 | K11: =Effort!J9 -> CLOSED | L11: =Harvest!J9 -> CLOSED | M11: =CPUE!J9 -> CLOSED | N11: =Effort!L9 -> CLOSED | O11: =Harvest!L9 -> CLOSED | P11: =CPUE!L9 -> CLOSED | Q11: CLOSED | R11: CLOSED | S11: CLOSED | T11: =SUM(E11+H11) -> 516.09867 | U11: =SUM(F11+I11) -> 7741.4801
A12: 44834 | B12: Fri | C12: -0.2 | D12: 0.94652778 | E12: =Effort!F10 -> 614.50901 | F12: =Harvest!F10 -> 8603.1261 | G12: =+CPUE!F10 -> 14 | H12: =Effort!H10 -> 378 | I12: =Harvest!H10 -> 5535 | J12: =CPUE!H10 -> 14.642857 | K12: =Effort!J10 -> 619.08494 | L12: =Harvest!J10 -> 8299.6075 | M12: =CPUE!J10 -> 13.40625 | N12: =Effort!L10 -> CLOSED | O12: =Harvest!L10 -> CLOSED | P12: =CPUE!L10 -> CLOSED | Q12: CLOSED | R12: CLOSED | S12: CLOSED | T12: =SUM(E12+H12+K12) -> 1611.5939 | U12: =SUM(F12+I12+L12) -> 22437.734
A13: Tide Series Totals | E13: =SUM(E4:E12) -> 1074.9163 | F13: =SUM(F4:F12) -> 13515.425 | G13: =+F13/E13 -> 12.573467 | H13: =SUM(H4:H12) -> 827.90592 | I13: =SUM(I4:I12) -> 10919.755 | J13: =+I13/H13 -> 13.189608 | K13: =SUM(K4:K12) -> 819.95075 | L13: =SUM(L4:L12) -> 10067.227 | M13: =+L13/K13 -> 12.277843 | N13: =SUM(N4:N12) -> 0 | O13: =SUM(O4:O12) -> 0 | P13: 0 | T13: =SUM(T4:T12) -> 2722.773 | U13: =SUM(U4:U12) -> 34502.406 | W13: =SUM(H13,K13,N13,Q13,E13) -> 2722.773 | X13: =SUM(R13,O13,L13,I13,F13) -> 34502.406
A14: 44842 | B14: Sat | C14: 0.5 | D14: 0.76458333 | E14: =Effort!F12 -> 5355.227 | F14: =Harvest!F12 -> 77650.792 | G14: =+CPUE!F12 -> 14.5 | H14: =Effort!H12 -> 4762.6033 | I14: =Harvest!H12 -> 69057.748 | J14: =CPUE!H12 -> 14.5 | K14: =Effort!J12 -> CLOSED | L14: =Harvest!J12 -> CLOSED | M14: =CPUE!J12 -> CLOSED | N14: =Effort!L12 -> CLOSED | O14: =Harvest!L12 -> CLOSED | P14: =CPUE!L12 -> CLOSED | Q14: CLOSED | R14: CLOSED | S14: CLOSED | T14: =SUM(E14+H14) -> 10117.83 | U14: =SUM(F14+I14) -> 146708.54
A15: 44843 | B15: Sun | C15: -0.1 | D15: 0.79513889 | E15: =Effort!F13 -> 2564.1123 | F15: =Harvest!F13 -> 37179.628 | G15: =+CPUE!F13 -> 14.5 | H15: =Effort!H13 -> 2280.3608 | I15: =Harvest!H13 -> 32809.273 | J15: =CPUE!H13 -> 14.387755 | K15: =Effort!J13 -> 3429.6324 | L15: =Harvest!J13 -> 49687.845 | M15: =CPUE!J13 -> 14.487805 | N15: =Effort!L13 -> CLOSED | O15: =Harvest!L13 -> CLOSED | P15: =CPUE!L13 -> CLOSED | Q15: CLOSED | R15: CLOSED | S15: CLOSED | T15: =SUM(E15+H15+K15) -> 8274.1055 | U15: =SUM(F15+I15+L15) -> 119676.75
A16: 44844 | B16: Mon | C16: -0.5 | D16: 0.82361111 | E16: =Effort!F14 -> 1244.1436 | F16: =Harvest!F14 -> 18662.155 | G16: =+CPUE!F14 -> 15 | H16: =Effort!H14 -> 1106.4634 | I16: =Harvest!H14 -> 16596.951 | J16: =CPUE!H14 -> 15 | K16: =Effort!J14 -> CLOSED | L16: =Harvest!J14 -> CLOSED | M16: =CPUE!J14 -> CLOSED | N16: =Effort!L14 -> CLOSED | O16: =Harvest!L14 -> CLOSED | P16: =CPUE!L14 -> CLOSED | Q16: CLOSED | R16: CLOSED | S16: CLOSED | T16: =SUM(E16+H16) -> 2350.607 | U16: =SUM(F16+I16) -> 35259.106
A17: 44845 | B17: Tue | C17: -0.6 | D17: 0.85138889 | E17: =Effort!F15 -> 777.51539 | F17: =Harvest!F15 -> 11273.973 | G17: =+CPUE!F15 -> 14.5 | H17: =Effort!H15 -> 631.66851 | I17: =Harvest!H15 -> 9159.1934 | J17: =CPUE!H15 -> 14.5 | K17: =Effort!J15 -> 950.02105 | L17: =Harvest!J15 -> 14071.326 | M17: =CPUE!J15 -> 14.811594 | N17: =Effort!L15 -> CLOSED | O17: =Harvest!L15 -> CLOSED | P17: =CPUE!L15 -> CLOSED | Q17: CLOSED | R17: CLOSED | S17: CLOSED | T17: =SUM(E17+H17+K17) -> 2359.205 | U17: =SUM(F17+I17+L17) -> 34504.493
A18: 44846 | B18: Wed | C18: -0.4 | D18: 0.87916667 | E18: =Effort!F16 -> 393.51385 | F18: =Harvest!F16 -> 5509.1939 | G18: =+CPUE!F16 -> 14 | H18: =Effort!H16 -> 349.96656 | I18: =Harvest!H16 -> 4812.0402 | J18: =CPUE!H16 -> 13.75 | K18: =Effort!J16 -> CLOSED | L18: =Harvest!J16 -> CLOSED | M18: =CPUE!J16 -> CLOSED | N18: =Effort!L16 -> CLOSED | O18: =Harvest!L16 -> CLOSED | P18: =CPUE!L16 -> CLOSED | Q18: CLOSED | R18: CLOSED | S18: CLOSED | T18: =SUM(E18+H18) -> 743.48042 | U18: =SUM(F18+I18) -> 10321.234
A19: 44847 | B19: Thu | C19: -0.2 | D19: 0.90694444 | E19: =Effort!F17 -> 315.90694 | F19: =Harvest!F17 -> 4738.6041 | G19: =+CPUE!F17 -> 15 | H19: =Effort!H17 -> 280.94784 | I19: =Harvest!H17 -> 3933.2697 | J19: =CPUE!H17 -> 14 | K19: =Effort!J17 -> 492.8 | L19: =Harvest!J17 -> 6922.6667 | M19: =CPUE!J17 -> 14.047619 | N19: =Effort!L17 -> CLOSED | O19: =Harvest!L17 -> CLOSED | P19: =CPUE!L17 -> CLOSED | Q19: CLOSED | R19: CLOSED | S19: CLOSED | T19: =SUM(E19+H19+K19) -> 1089.6548 | U19: =SUM(F19+I19+L19) -> 15594.541
A20: 44848 | B20: Fri | C20: 0.3 | D20: 0.93680556 | E20: =Effort!F18 -> 515.81118 | F20: =Harvest!F18 -> 7737.1677 | G20: =+CPUE!F18 -> 15 | H20: =Effort!H18 -> 458.73014 | I20: =Harvest!H18 -> 6880.9521 | J20: =CPUE!H18 -> 15 | K20: =Effort!J18 -> CLOSED | L20: =Harvest!J18 -> CLOSED | M20: =CPUE!J18 -> CLOSED | N20: =Effort!L18 -> CLOSED | O20: =Harvest!L18 -> CLOSED | P20: =CPUE!L18 -> CLOSED | Q20: CLOSED | R20: CLOSED | S20: CLOSED | T20: =SUM(E20+H20) -> 974.54132 | U20: =SUM(F20+I20) -> 14618.12
A21: Tide Series Totals | E21: =SUM(E14:E20) -> 11166.23 | F21: =SUM(F14:F20) -> 162751.51 | G21: =+F21/E21 -> 14.575332 | H21: =SUM(H14:H20) -> 9870.7406 | I21: =SUM(I14:I20) -> 143249.43 | J21: =+I21/H21 -> 14.512531 | K21: =SUM(K14:K20) -> 4872.4534 | L21: =SUM(L14:L20) -> 70681.838 | M21: =+L21/K21 -> 14.506416 | N21: =SUM(N12:N20) -> 0 | O21: =SUM(O12:O20) -> 0 | P21: 0 | T21: =SUM(T14:T20) -> 25909.424 | U21: =SUM(U14:U20) -> 376682.78 | W21: =SUM(H21,K21,N21,Q21,E21) -> 25909.424 | X21: =SUM(R21,O21,L21,I21,F21) -> 376682.78
A22: 44858 | B22: Mon | C22: 0 | D22: 0.78055556 | E22: =Effort!F20 -> 1250.827 | F22: =Harvest!F20 -> 13759.097 | G22: =+CPUE!F20 -> 11 | H22: =Effort!H20 -> 970.92904 | I22: =Harvest!H20 -> 11335.032 | J22: =CPUE!H20 -> 11.674419 | K22: =Effort!J20 -> 1276.5406 | L22: =Harvest!J20 -> 17932.356 | M22: =CPUE!J20 -> 14.047619 | N22: =Effort!L20 -> CLOSED | O22: =Harvest!L20 -> CLOSED | P22: =CPUE!L20 -> CLOSED | Q22: CLOSED | R22: CLOSED | S22: CLOSED | T22: =SUM(E22+H22+K22) -> 3498.2967 | U22: =SUM(F22+I22+L22) -> 43026.486
A23: 44859 | B23: Tue | C23: -0.6 | D23: 0.80833333 | E23: =Effort!F21 -> 397.34615 | F23: =Harvest!F21 -> 3178.7692 | G23: =+CPUE!F21 -> 8 | H23: =Effort!H21 -> 388.18431 | I23: =Harvest!H21 -> 5415.1712 | J23: =CPUE!H21 -> 13.95 | K23: =Effort!J21 -> CLOSED | L23: =Harvest!J21 -> CLOSED | M23: =CPUE!J21 -> CLOSED | N23: =Effort!L21 -> CLOSED | O23: =Harvest!L21 -> CLOSED | P23: =CPUE!L21 -> CLOSED | Q23: CLOSED | R23: CLOSED | S23: CLOSED | T23: =SUM(E23+H23) -> 785.53046 | U23: =SUM(F23+I23) -> 8593.9404
A24: 44860 | B24: Wed | C24: -1 | D24: 0.83680556 | E24: =Effort!F22 -> 770.31346 | F24: =Harvest!F22 -> 10211.388 | G24: =+CPUE!F22 -> 13.256146 | H24: =Effort!H22 -> 597.94015 | I24: =Harvest!H22 -> 7474.2518 | J24: =CPUE!H22 -> 12.5 | K24: =Effort!J22 -> 597.74106 | L24: =Harvest!J22 -> 7341.4864 | M24: =CPUE!J22 -> 12.282051 | N24: =Effort!L22 -> CLOSED | O24: =Harvest!L22 -> CLOSED | P24: =CPUE!L22 -> CLOSED | Q24: CLOSED | R24: CLOSED | S24: CLOSED | T24: =SUM(E24+H24+K24) -> 1965.9947 | U24: =SUM(F24+I24+L24) -> 25027.126
A25: 44861 | B25: Thu | C25: -1.1 | D25: 0.86666667 | E25: =Effort!F23 -> 514.17347 | F25: =Harvest!F23 -> 4884.6479 | G25: =+CPUE!F23 -> 9.5 | H25: =Effort!H23 -> 502.31788 | I25: =Harvest!H23 -> 4772.0199 | J25: =CPUE!H23 -> 9.5 | K25: =Effort!J23 -> CLOSED | L25: =Harvest!J23 -> CLOSED | M25: =CPUE!J23 -> CLOSED | N25: =Effort!L23 -> CLOSED | O25: =Harvest!L23 -> CLOSED | P25: =CPUE!L23 -> CLOSED | Q25: CLOSED | R25: CLOSED | S25: CLOSED | T25: =SUM(E25+H25) -> 1016.4914 | U25: =SUM(F25+I25) -> 9656.6678
A26: 44862 | B26: Fri | C26: -1 | D26: 0.89930556 | E26: =Effort!F24 -> 805.14405 | F26: =Harvest!F24 -> 5233.4364 | G26: =+CPUE!F24 -> 6.5 | H26: =Effort!H24 -> 825.63586 | I26: =Harvest!H24 -> 8256.3586 | J26: =CPUE!H24 -> 10 | K26: =Effort!J24 -> 1085.5147 | L26: =Harvest!J24 -> 14229.044 | M26: =CPUE!J24 -> 13.108108 | N26: =Effort!L24 -> CLOSED | O26: =Harvest!L24 -> CLOSED | P26: =CPUE!L24 -> CLOSED | Q26: CLOSED | R26: CLOSED | S26: CLOSED | T26: =SUM(E26+H26+K26) -> 2716.2946 | U26: =SUM(F26+I26+L26) -> 27718.838
A27: 44863 | B27: Sat | C27: -0.7 | D27: 0.93611111 | E27: =Effort!F25 -> 1101.2843 | F27: =Harvest!F25 -> 15968.622 | G27: =+CPUE!F25 -> 14.5 | H27: =Effort!H25 -> 1075.8913 | I27: =Harvest!H25 -> 15817.892 | J27: =CPUE!H25 -> 14.702128 | K27: =Effort!J25 -> CLOSED | L27: =Harvest!J25 -> CLOSED | M27: =CPUE!J25 -> CLOSED | N27: =Effort!L25 -> CLOSED | O27: =Harvest!L25 -> CLOSED | P27: =CPUE!L25 -> CLOSED | Q27: CLOSED | R27: CLOSED | S27: CLOSED | T27: =SUM(E27+H27) -> 2177.1756 | U27: =SUM(F27+I27) -> 31786.513
A28: 44864 | B28: Sun | C28: -0.3 | D28: 0.97708333 | E28: =Effort!F26 -> 32.661893 | F28: =Harvest!F26 -> 146.97852 | G28: =+CPUE!F26 -> 4.5 | H28: =Effort!H26 -> 25.35313 | I28: =Harvest!H26 -> 114.08908 | J28: =CPUE!H26 -> 4.5 | K28: =Effort!J26 -> 33.333332 | L28: =Harvest!J26 -> 149.99999 | M28: =CPUE!J26 -> 4.5 | N28: =Effort!L26 -> CLOSED | O28: =Harvest!L26 -> CLOSED | P28: =CPUE!L26 -> CLOSED | Q28: CLOSED | R28: CLOSED | S28: CLOSED | T28: =SUM(E28+H28+K28) -> 91.348355 | U28: =SUM(F28+I28+L28) -> 411.0676
A29: Tide Series Totals | E29: =SUM(E22:E28) -> 4871.7503 | F29: =SUM(F22:F28) -> 53382.939 | G29: =+F29/E29 -> 10.957651 | H29: =SUM(H22:H28) -> 4386.2517 | I29: =SUM(I22:I28) -> 53184.814 | J29: =+I29/H29 -> 12.125345 | K29: =SUM(K22:K28) -> 2993.1297 | L29: =SUM(L22:L28) -> 39652.886 | M29: =+L29/K29 -> 13.247968 | N29: =SUM(N20:N28) -> 0 | O29: =SUM(O20:O28) -> 0 | P29: 0 | T29: =SUM(T22:T28) -> 12251.132 | U29: =SUM(U22:U28) -> 146220.64 | W29: =SUM(H29,K29,N29,Q29,E29) -> 12251.132 | X29: =SUM(R29,O29,L29,I29,F29) -> 146220.64
A30: 44871 | B30: Sun | C30: 0 | D30: 0.71388889 | E30: =Effort!F28 -> CLOSED | F30: =Harvest!F28 -> CLOSED | G30: =+CPUE!F28 -> CLOSED | H30: =Effort!H28 -> CLOSED | I30: =Harvest!H28 -> CLOSED | J30: =CPUE!H28 -> CLOSED | K30: =Effort!J28 -> CLOSED | L30: =Harvest!J28 -> CLOSED | M30: =CPUE!J28 -> CLOSED | N30: =Effort!L28 -> CLOSED | O30: =Harvest!L28 -> CLOSED | P30: =CPUE!L28 -> CLOSED | Q30: CLOSED | R30: CLOSED | S30: CLOSED | T30: 0 | U30: 0
A31: 44872 | B31: Mon | C31: -0.5 | D31: 0.74236111 | E31: =Effort!F29 -> CLOSED | F31: =Harvest!F29 -> CLOSED | G31: =+CPUE!F29 -> CLOSED | H31: =Effort!H29 -> CLOSED | I31: =Harvest!H29 -> CLOSED | J31: =CPUE!H29 -> CLOSED | K31: =Effort!J29 -> CLOSED | L31: =Harvest!J29 -> CLOSED | M31: =CPUE!J29 -> CLOSED | N31: =Effort!L29 -> CLOSED | O31: =Harvest!L29 -> CLOSED | P31: =CPUE!L29 -> CLOSED | Q31: CLOSED | R31: CLOSED | S31: CLOSED | T31: 0 | U31: 0
A32: 44873 | B32: Tue | C32: -0.7 | D32: 0.76944444 | E32: =Effort!F30 -> CLOSED | F32: =Harvest!F30 -> CLOSED | G32: =+CPUE!F30 -> CLOSED | H32: =Effort!H30 -> CLOSED | I32: =Harvest!H30 -> CLOSED | J32: =CPUE!H30 -> CLOSED | K32: =Effort!J30 -> CLOSED | L32: =Harvest!J30 -> CLOSED | M32: =CPUE!J30 -> CLOSED | N32: =Effort!L30 -> CLOSED | O32: =Harvest!L30 -> CLOSED | P32: =CPUE!L30 -> CLOSED | Q32: CLOSED | R32: CLOSED | S32: CLOSED | T32: 0 | U32: 0
A33: 44874 | B33: Wed | C33: -0.7 | D33: 0.79513889 | E33: =Effort!F31 -> CLOSED | F33: =Harvest!F31 -> CLOSED | G33: =+CPUE!F31 -> CLOSED | H33: =Effort!H31 -> CLOSED | I33: =Harvest!H31 -> CLOSED | J33: =CPUE!H31 -> CLOSED | K33: =Effort!J31 -> CLOSED | L33: =Harvest!J31 -> CLOSED | M33: =CPUE!J31 -> CLOSED | N33: =Effort!L31 -> CLOSED | O33: =Harvest!L31 -> CLOSED | P33: =CPUE!L31 -> CLOSED | Q33: CLOSED | R33: CLOSED | S33: CLOSED | T33: 0 | U33: 0
A34: 44875 | B34: Thu | C34: -0.6 | D34: 0.82083333 | E34: =Effort!F32 -> CLOSED | F34: =Harvest!F32 -> CLOSED | G34: =+CPUE!F32 -> CLOSED | H34: =Effort!H32 -> CLOSED | I34: =Harvest!H32 -> CLOSED | J34: =CPUE!H32 -> CLOSED | K34: =Effort!J32 -> CLOSED | L34: =Harvest!J32 -> CLOSED | M34: =CPUE!J32 -> CLOSED | N34: =Effort!L32 -> CLOSED | O34: =Harvest!L32 -> CLOSED | P34: =CPUE!L32 -> CLOSED | Q34: CLOSED | R34: CLOSED | S34: CLOSED | T34: 0 | U34: 0
A35: 44876 | B35: Fri | C35: -0.2 | D35: 0.84652778 | E35: =Effort!F33 -> CLOSED | F35: =Harvest!F33 -> CLOSED | G35: =+CPUE!F33 -> CLOSED | H35: =Effort!H33 -> CLOSED | I35: =Harvest!H33 -> CLOSED | J35: =CPUE!H33 -> CLOSED | K35: =Effort!J33 -> CLOSED | L35: =Harvest!J33 -> CLOSED | M35: =CPUE!J33 -> CLOSED | N35: =Effort!L33 -> CLOSED | O35: =Harvest!L33 -> CLOSED | P35: =CPUE!L33 -> CLOSED | Q35: CLOSED | R35: CLOSED | S35: CLOSED | T35: 0 | U35: 0
A36: 44877 | B36: Sat | C36: 0.1 | D36: 0.87430556 | E36: =Effort!F34 -> CLOSED | F36: =Harvest!F34 -> CLOSED | G36: =+CPUE!F34 -> CLOSED | H36: =Effort!H34 -> CLOSED | I36: =Harvest!H34 -> CLOSED | J36: =CPUE!H34 -> CLOSED | K36: =Effort!J34 -> CLOSED | L36: =Harvest!J34 -> CLOSED | M36: =CPUE!J34 -> CLOSED | N36: =Effort!L34 -> CLOSED | O36: =Harvest!L34 -> CLOSED | P36: =CPUE!L34 -> CLOSED | Q36: CLOSED | R36: CLOSED | S36: CLOSED | T36: 0 | U36: 0
A37: 44878 | B37: Sun | C37: 0.5 | D37: 0.90486111 | E37: =Effort!F35 -> CLOSED | F37: =Harvest!F35 -> CLOSED | G37: =+CPUE!F35 -> CLOSED | H37: =Effort!H35 -> CLOSED | I37: =Harvest!H35 -> CLOSED | J37: =CPUE!H35 -> CLOSED | K37: =Effort!J35 -> CLOSED | L37: =Harvest!J35 -> CLOSED | M37: =CPUE!J35 -> CLOSED | N37: =Effort!L35 -> CLOSED | O37: =Harvest!L35 -> CLOSED | P37: =CPUE!L35 -> CLOSED | Q37: CLOSED | R37: CLOSED | S37: CLOSED | T37: 0 | U37: 0
A38: Tide Series Totals | E38: =SUM(E30:E37) -> 0 | F38: =SUM(F30:F37) -> 0 | G38: 0 | H38: =SUM(H30:H37) -> 0 | I38: =SUM(I30:I37) -> 0 | J38: 0 | K38: =SUM(K30:K37) -> 0 | L38: =SUM(L30:L37) -> 0 | M38: 0 | N38: =SUM(N29:N37) -> 0 | O38: =SUM(O29:O37) -> 0 | P38: 0 | T38: =SUM(T30:T37) -> 0 | U38: =SUM(U30:U37) -> 0 | W38: =SUM(H38,K38,N38,Q38,E38) -> 0 | X38: =SUM(R38,O38,L38,I38,F38) -> 0
A39: 44887 | B39: Tue | C39: -0.6 | D39: 0.72361111 | E39: =Effort!F37 -> CLOSED | F39: =Harvest!F37 -> CLOSED | G39: =+CPUE!F37 -> CLOSED | H39: =Effort!H37 -> CLOSED | I39: =Harvest!H37 -> CLOSED | J39: =CPUE!H37 -> CLOSED | K39: =Effort!J37 -> CLOSED | L39: =Harvest!J37 -> CLOSED | M39: =CPUE!J37 -> CLOSED | N39: =Effort!L37 -> CLOSED | O39: =Harvest!L37 -> CLOSED | P39: =CPUE!L37 -> CLOSED | Q39: CLOSED | R39: CLOSED | S39: CLOSED | T39: 0 | U39: 0
A40: 44888 | B40: Wed | C40: -1.2 | D40: 0.75277778 | E40: =Effort!F38 -> CLOSED | F40: =Harvest!F38 -> CLOSED | G40: =+CPUE!F38 -> CLOSED | H40: =Effort!H38 -> CLOSED | I40: =Harvest!H38 -> CLOSED | J40: =CPUE!H38 -> CLOSED | K40: =Effort!J38 -> CLOSED | L40: =Harvest!J38 -> CLOSED | M40: =CPUE!J38 -> CLOSED | N40: =Effort!L38 -> CLOSED | O40: =Harvest!L38 -> CLOSED | P40: =CPUE!L38 -> CLOSED | Q40: CLOSED | R40: CLOSED | S40: CLOSED | T40: 0 | U40: 0
...

Sheet Summary Table Public
A1: 2022-2023 State (non-Tribal) Recreational Razor Clam Effort, Harvest and CPUE totals.
E2: LONG BEACH | H2: TWIN HARBORS | K2: COPALIS | N2: MOCROCKS | Q2: KALALOCH | T2: DAILY TOTALS | W2: CROSS | X2: CHECK
A3: DATE | B3: DAY | C3: TIDE | D3: TIME | E3: Effort | F3: Harvest | G3: CPUE | H3: Effort | I3: Harvest | J3: CPUE | K3: Effort | L3: Harvest | M3: CPUE | N3: Effort | O3: Harvest | P3: CPUE | Q3: Effort | R3: Harvest | S3: CPUE | T3: Effort | U3: Harvest
A4: 44826 | B4: Thu | C4: 0.4 | D4: 0.21041667 | E4: =Effort!F2 -> CLOSED | F4: =Harvest!F2 -> CLOSED | G4: =+CPUE!F2 -> CLOSED | H4: =Effort!H2 -> CLOSED | I4: =Harvest!H2 -> CLOSED | J4: =CPUE!H2 -> CLOSED | K4: =Effort!J2 -> CLOSED | L4: =Harvest!J2 -> CLOSED | M4: =CPUE!J2 -> CLOSED | N4: =Effort!L2 -> CLOSED | O4: =Harvest!L2 -> CLOSED | P4: =CPUE!L2 -> CLOSED | Q4: CLOSED | R4: CLOSED | S4: CLOSED | T4: 0 | U4: 0
A5: 44827 | B5: Fri | C5: 0.1 | D5: 0.23680556 | E5: =Effort!F3 -> CLOSED | F5: =Harvest!F3 -> CLOSED | G5: =+CPUE!F3 -> CLOSED | H5: =Effort!H3 -> CLOSED | I5: =Harvest!H3 -> CLOSED | J5: =CPUE!H3 -> CLOSED | K5: =Effort!J3 -> CLOSED | L5: =Harvest!J3 -> CLOSED | M5: =CPUE!J3 -> CLOSED | N5: =Effort!L3 -> CLOSED | O5: =Harvest!L3 -> CLOSED | P5: =CPUE!L3 -> CLOSED | Q5: CLOSED | R5: CLOSED | S5: CLOSED | T5: 0 | U5: 0
A6: 44828 | B6: Sat | C6: 0 | D6: 0.26041667 | E6: =Effort!F4 -> CLOSED | F6: =Harvest!F4 -> CLOSED | G6: =+CPUE!F4 -> CLOSED | H6: =Effort!H4 -> CLOSED | I6: =Harvest!H4 -> CLOSED | J6: =CPUE!H4 -> CLOSED | K6: =Effort!J4 -> CLOSED | L6: =Harvest!J4 -> CLOSED | M6: =CPUE!J4 -> CLOSED | N6: =Effort!L4 -> CLOSED | O6: =Harvest!L4 -> CLOSED | P6: =CPUE!L4 -> CLOSED | Q6: CLOSED | R6: CLOSED | S6: CLOSED | T6: 0 | U6: 0
A7: 44829 | B7: Sun | C7: 0.1 | D7: 0.28333333 | E7: =Effort!F5 -> CLOSED | F7: =Harvest!F5 -> CLOSED | G7: =+CPUE!F5 -> CLOSED | H7: =Effort!H5 -> CLOSED | I7: =Harvest!H5 -> CLOSED | J7: =CPUE!H5 -> CLOSED | K7: =Effort!J5 -> CLOSED | L7: =Harvest!J5 -> CLOSED | M7: =CPUE!J5 -> CLOSED | N7: =Effort!L5 -> CLOSED | O7: =Harvest!L5 -> CLOSED | P7: =CPUE!L5 -> CLOSED | Q7: CLOSED | R7: CLOSED | S7: CLOSED | T7: 0 | U7: 0
A8: 44830 | B8: Mon | C8: 0.3 | D8: 0.30486111 | E8: =Effort!F6 -> CLOSED | F8: =Harvest!F6 -> CLOSED | G8: =+CPUE!F6 -> CLOSED | H8: =Effort!H6 -> CLOSED | I8: =Harvest!H6 -> CLOSED | J8: =CPUE!H6 -> CLOSED | K8: =Effort!J6 -> CLOSED | L8: =Harvest!J6 -> CLOSED | M8: =CPUE!J6 -> CLOSED | N8: =Effort!L6 -> CLOSED | O8: =Harvest!L6 -> CLOSED | P8: =CPUE!L6 -> CLOSED | Q8: CLOSED | R8: CLOSED | S8: CLOSED | T8: 0 | U8: 0
A9: 44831 | B9: Tue | C9: -0.1 | D9: 0.85 | E9: =Effort!F7 -> CLOSED | F9: =Harvest!F7 -> CLOSED | G9: =+CPUE!F7 -> CLOSED | H9: =Effort!H7 -> CLOSED | I9: =Harvest!H7 -> CLOSED | J9: =CPUE!H7 -> CLOSED | K9: =Effort!J7 -> CLOSED | L9: =Harvest!J7 -> CLOSED | M9: =CPUE!J7 -> CLOSED | N9: =Effort!L7 -> CLOSED | O9: =Harvest!L7 -> CLOSED | P9: =CPUE!L7 -> CLOSED | Q9: CLOSED | R9: CLOSED | S9: CLOSED | T9: 0 | U9: 0
A10: 44832 | B10: Wed | C10: -0.3 | D10: 0.87916667 | E10: =Effort!F8 -> 199.38112 | F10: =Harvest!F8 -> 996.9056 | G10: =+CPUE!F8 -> 5 | H10: =Effort!H8 -> 194.83345 | I10: =Harvest!H8 -> 1558.6676 | J10: =CPUE!H8 -> 8 | K10: =Effort!J8 -> 200.86581 | L10: =Harvest!J8 -> 1767.6191 | M10: =CPUE!J8 -> 8.8 | N10: =Effort!L8 -> CLOSED | O10: =Harvest!L8 -> CLOSED | P10: =CPUE!L8 -> CLOSED | Q10: CLOSED | R10: CLOSED | S10: CLOSED | T10: =SUM(E10+H10+K10) -> 595.08038 | U10: =SUM(F10+I10+L10) -> 4323.1923
A11: 44833 | B11: Thu | C11: -0.4 | D11: 0.91041667 | E11: =Effort!F9 -> 261.0262 | F11: =Harvest!F9 -> 3915.393 | G11: =+CPUE!F9 -> 15 | H11: =Effort!H9 -> 255.07247 | I11: =Harvest!H9 -> 3826.087 | J11: =CPUE!H9 -> 15 | K11: =Effort!J9 -> CLOSED | L11: =Harvest!J9 -> CLOSED | M11: =CPUE!J9 -> CLOSED | N11: =Effort!L9 -> CLOSED | O11: =Harvest!L9 -> CLOSED | P11: =CPUE!L9 -> CLOSED | Q11: CLOSED | R11: CLOSED | S11: CLOSED | T11: =SUM(E11+H11) -> 516.09867 | U11: =SUM(F11+I11) -> 7741.4801
A12: 44834 | B12: Fri | C12: -0.2 | D12: 0.94652778 | E12: =Effort!F10 -> 614.50901 | F12: =Harvest!F10 -> 8603.1261 | G12: =+CPUE!F10 -> 14 | H12: =Effort!H10 -> 378 | I12: =Harvest!H10 -> 5535 | J12: =CPUE!H10 -> 14.642857 | K12: =Effort!J10 -> 619.08494 | L12: =Harvest!J10 -> 8299.6075 | M12: =CPUE!J10 -> 13.40625 | N12: =Effort!L10 -> CLOSED | O12: =Harvest!L10 -> CLOSED | P12: =CPUE!L10 -> CLOSED | Q12: CLOSED | R12: CLOSED | S12: CLOSED | T12: =SUM(E12+H12+K12) -> 1611.5939 | U12: =SUM(F12+I12+L12) -> 22437.734
A13: Tide Series Totals | E13: =SUM(E4:E12) -> 1074.9163 | F13: =SUM(F4:F12) -> 13515.425 | G13: =+F13/E13 -> 12.573467 | H13: =SUM(H4:H12) -> 827.90592 | I13: =SUM(I4:I12) -> 10919.755 | J13: =+I13/H13 -> 13.189608 | K13: =SUM(K4:K12) -> 819.95075 | L13: =SUM(L4:L12) -> 10067.227 | M13: =+L13/K13 -> 12.277843 | N13: =SUM(N4:N12) -> 0 | O13: =SUM(O4:O12) -> 0 | P13: 0 | T13: =SUM(T4:T12) -> 2722.773 | U13: =SUM(U4:U12) -> 34502.406 | W13: =SUM(H13,K13,N13,Q13,E13) -> 2722.773 | X13: =SUM(R13,O13,L13,I13,F13) -> 34502.406
A14: 44842 | B14: Sat | C14: 0.5 | D14: 0.76458333 | E14: =Effort!F12 -> 5355.227 | F14: =Harvest!F12 -> 77650.792 | G14: =+CPUE!F12 -> 14.5 | H14: =Effort!H12 -> 4762.6033 | I14: =Harvest!H12 -> 69057.748 | J14: =CPUE!H12 -> 14.5 | K14: =Effort!J12 -> CLOSED | L14: =Harvest!J12 -> CLOSED | M14: =CPUE!J12 -> CLOSED | N14: =Effort!L12 -> CLOSED | O14: =Harvest!L12 -> CLOSED | P14: =CPUE!L12 -> CLOSED | Q14: CLOSED | R14: CLOSED | S14: CLOSED | T14: =SUM(E14+H14) -> 10117.83 | U14: =SUM(F14+I14) -> 146708.54
A15: 44843 | B15: Sun | C15: -0.1 | D15: 0.79513889 | E15: =Effort!F13 -> 2564.1123 | F15: =Harvest!F13 -> 37179.628 | G15: =+CPUE!F13 -> 14.5 | H15: =Effort!H13 -> 2280.3608 | I15: =Harvest!H13 -> 32809.273 | J15: =CPUE!H13 -> 14.387755 | K15: =Effort!J13 -> 3429.6324 | L15: =Harvest!J13 -> 49687.845 | M15: =CPUE!J13 -> 14.487805 | N15: =Effort!L13 -> CLOSED | O15: =Harvest!L13 -> CLOSED | P15: =CPUE!L13 -> CLOSED | Q15: CLOSED | R15: CLOSED | S15: CLOSED | T15: =SUM(E15+H15+K15) -> 8274.1055 | U15: =SUM(F15+I15+L15) -> 119676.75
A16: 44844 | B16: Mon | C16: -0.5 | D16: 0.82361111 | E16: =Effort!F14 -> 1244.1436 | F16: =Harvest!F14 -> 18662.155 | G16: =+CPUE!F14 -> 15 | H16: =Effort!H14 -> 1106.4634 | I16: =Harvest!H14 -> 16596.951 | J16: =CPUE!H14 -> 15 | K16: =Effort!J14 -> CLOSED | L16: =Harvest!J14 -> CLOSED | M16: =CPUE!J14 -> CLOSED | N16: =Effort!L14 -> CLOSED | O16: =Harvest!L14 -> CLOSED | P16: =CPUE!L14 -> CLOSED | Q16: CLOSED | R16: CLOSED | S16: CLOSED | T16: =SUM(E16+H16) -> 2350.607 | U16: =SUM(F16+I16) -> 35259.106
A17: 44845 | B17: Tue | C17: -0.6 | D17: 0.85138889 | E17: =Effort!F15 -> 777.51539 | F17: =Harvest!F15 -> 11273.973 | G17: =+CPUE!F15 -> 14.5 | H17: =Effort!H15 -> 631.66851 | I17: =Harvest!H15 -> 9159.1934 | J17: =CPUE!H15 -> 14.5 | K17: =Effort!J15 -> 950.02105 | L17: =Harvest!J15 -> 14071.326 | M17: =CPUE!J15 -> 14.811594 | N17: =Effort!L15 -> CLOSED | O17: =Harvest!L15 -> CLOSED | P17: =CPUE!L15 -> CLOSED | Q17: CLOSED | R17: CLOSED | S17: CLOSED | T17: =SUM(E17+H17+K17) -> 2359.205 | U17: =SUM(F17+I17+L17) -> 34504.493
A18: 44846 | B18: Wed | C18: -0.4 | D18: 0.87916667 | E18: =Effort!F16 -> 393.51385 | F18: =Harvest!F16 -> 5509.1939 | G18: =+CPUE!F16 -> 14 | H18: =Effort!H16 -> 349.96656 | I18: =Harvest!H16 -> 4812.0402 | J18: =CPUE!H16 -> 13.75 | K18: =Effort!J16 -> CLOSED | L18: =Harvest!J16 -> CLOSED | M18: =CPUE!J16 -> CLOSED | N18: =Effort!L16 -> CLOSED | O18: =Harvest!L16 -> CLOSED | P18: =CPUE!L16 -> CLOSED | Q18: CLOSED | R18: CLOSED | S18: CLOSED | T18: =SUM(E18+H18) -> 743.48042 | U18: =SUM(F18+I18) -> 10321.234
A19: 44847 | B19: Thu | C19: -0.2 | D19: 0.90694444 | E19: =Effort!F17 -> 315.90694 | F19: =Harvest!F17 -> 4738.6041 | G19: =+CPUE!F17 -> 15 | H19: =Effort!H17 -> 280.94784 | I19: =Harvest!H17 -> 3933.2697 | J19: =CPUE!H17 -> 14 | K19: =Effort!J17 -> 492.8 | L19: =Harvest!J17 -> 6922.6667 | M19: =CPUE!J17 -> 14.047619 | N19: =Effort!L17 -> CLOSED | O19: =Harvest!L17 -> CLOSED | P19: =CPUE!L17 -> CLOSED | Q19: CLOSED | R19: CLOSED | S19: CLOSED | T19: =SUM(E19+H19+K19) -> 1089.6548 | U19: =SUM(F19+I19+L19) -> 15594.541
A20: 44848 | B20: Fri | C20: 0.3 | D20: 0.93680556 | E20: =Effort!F18 -> 515.81118 | F20: =Harvest!F18 -> 7737.1677 | G20: =+CPUE!F18 -> 15 | H20: =Effort!H18 -> 458.73014 | I20: =Harvest!H18 -> 6880.9521 | J20: =CPUE!H18 -> 15 | K20: =Effort!J18 -> CLOSED | L20: =Harvest!J18 -> CLOSED | M20: =CPUE!J18 -> CLOSED | N20: =Effort!L18 -> CLOSED | O20: =Harvest!L18 -> CLOSED | P20: =CPUE!L18 -> CLOSED | Q20: CLOSED | R20: CLOSED | S20: CLOSED | T20: =SUM(E20+H20) -> 974.54132 | U20: =SUM(F20+I20) -> 14618.12
A21: Tide Series Totals | E21: =SUM(E14:E20) -> 11166.23 | F21: =SUM(F14:F20) -> 162751.51 | G21: =+F21/E21 -> 14.575332 | H21: =SUM(H14:H20) -> 9870.7406 | I21: =SUM(I14:I20) -> 143249.43 | J21: =+I21/H21 -> 14.512531 | K21: =SUM(K14:K20) -> 4872.4534 | L21: =SUM(L14:L20) -> 70681.838 | M21: =+L21/K21 -> 14.506416 | N21: =SUM(N12:N20) -> 0 | O21: =SUM(O12:O20) -> 0 | P21: 0 | T21: =SUM(T14:T20) -> 25909.424 | U21: =SUM(U14:U20) -> 376682.78 | W21: =SUM(H21,K21,N21,Q21,E21) -> 25909.424 | X21: =SUM(R21,O21,L21,I21,F21) -> 376682.78
A22: 44858 | B22: Mon | C22: 0 | D22: 0.78055556 | E22: =Effort!F20 -> 1250.827 | F22: =Harvest!F20 -> 13759.097 | G22: =+CPUE!F20 -> 11 | H22: =Effort!H20 -> 970.92904 | I22: =Harvest!H20 -> 11335.032 | J22: =CPUE!H20 -> 11.674419 | K22: =Effort!J20 -> 1276.5406 | L22: =Harvest!J20 -> 17932.356 | M22: =CPUE!J20 -> 14.047619 | N22: =Effort!L20 -> CLOSED | O22: =Harvest!L20 -> CLOSED | P22: =CPUE!L20 -> CLOSED | Q22: CLOSED | R22: CLOSED | S22: CLOSED | T22: =SUM(E22+H22+K22) -> 3498.2967 | U22: =SUM(F22+I22+L22) -> 43026.486
A23: 44859 | B23: Tue | C23: -0.6 | D23: 0.80833333 | E23: =Effort!F21 -> 397.34615 | F23: =Harvest!F21 -> 3178.7692 | G23: =+CPUE!F21 -> 8 | H23: =Effort!H21 -> 388.18431 | I23: =Harvest!H21 -> 5415.1712 | J23: =CPUE!H21 -> 13.95 | K23: =Effort!J21 -> CLOSED | L23: =Harvest!J21 -> CLOSED | M23: =CPUE!J21 -> CLOSED | N23: =Effort!L21 -> CLOSED | O23: =Harvest!L21 -> CLOSED | P23: =CPUE!L21 -> CLOSED | Q23: CLOSED | R23: CLOSED | S23: CLOSED | T23: =SUM(E23+H23) -> 785.53046 | U23: =SUM(F23+I23) -> 8593.9404
A24: 44860 | B24: Wed | C24: -1 | D24: 0.83680556 | E24: =Effort!F22 -> 770.31346 | F24: =Harvest!F22 -> 10211.388 | G24: =+CPUE!F22 -> 13.256146 | H24: =Effort!H22 -> 597.94015 | I24: =Harvest!H22 -> 7474.2518 | J24: =CPUE!H22 -> 12.5 | K24: =Effort!J22 -> 597.74106 | L24: =Harvest!J22 -> 7341.4864 | M24: =CPUE!J22 -> 12.282051 | N24: =Effort!L22 -> CLOSED | O24: =Harvest!L22 -> CLOSED | P24: =CPUE!L22 -> CLOSED | Q24: CLOSED | R24: CLOSED | S24: CLOSED | T24: =SUM(E24+H24+K24) -> 1965.9947 | U24: =SUM(F24+I24+L24) -> 25027.126
A25: 44861 | B25: Thu | C25: -1.1 | D25: 0.86666667 | E25: =Effort!F23 -> 514.17347 | F25: =Harvest!F23 -> 4884.6479 | G25: =+CPUE!F23 -> 9.5 | H25: =Effort!H23 -> 502.31788 | I25: =Harvest!H23 -> 4772.0199 | J25: =CPUE!H23 -> 9.5 | K25: =Effort!J23 -> CLOSED | L25: =Harvest!J23 -> CLOSED | M25: =CPUE!J23 -> CLOSED | N25: =Effort!L23 -> CLOSED | O25: =Harvest!L23 -> CLOSED | P25: =CPUE!L23 -> CLOSED | Q25: CLOSED | R25: CLOSED | S25: CLOSED | T25: =SUM(E25+H25) -> 1016.4914 | U25: =SUM(F25+I25) -> 9656.6678
A26: 44862 | B26: Fri | C26: -1 | D26: 0.89930556 | E26: =Effort!F24 -> 805.14405 | F26: =Harvest!F24 -> 5233.4364 | G26: =+CPUE!F24 -> 6.5 | H26: =Effort!H24 -> 825.63586 | I26: =Harvest!H24 -> 8256.3586 | J26: =CPUE!H24 -> 10 | K26: =Effort!J24 -> 1085.5147 | L26: =Harvest!J24 -> 14229.044 | M26: =CPUE!J24 -> 13.108108 | N26: =Effort!L24 -> CLOSED | O26: =Harvest!L24 -> CLOSED | P26: =CPUE!L24 -> CLOSED | Q26: CLOSED | R26: CLOSED | S26: CLOSED | T26: =SUM(E26+H26+K26) -> 2716.2946 | U26: =SUM(F26+I26+L26) -> 27718.838
A27: 44863 | B27: Sat | C27: -0.7 | D27: 0.93611111 | E27: =Effort!F25 -> 1101.2843 | F27: =Harvest!F25 -> 15968.622 | G27: =+CPUE!F25 -> 14.5 | H27: =Effort!H25 -> 1075.8913 | I27: =Harvest!H25 -> 15817.892 | J27: =CPUE!H25 -> 14.702128 | K27: =Effort!J25 -> CLOSED | L27: =Harvest!J25 -> CLOSED | M27: =CPUE!J25 -> CLOSED | N27: =Effort!L25 -> CLOSED | O27: =Harvest!L25 -> CLOSED | P27: =CPUE!L25 -> CLOSED | Q27: CLOSED | R27: CLOSED | S27: CLOSED | T27: =SUM(E27+H27) -> 2177.1756 | U27: =SUM(F27+I27) -> 31786.513
A28: 44864 | B28: Sun | C28: -0.3 | D28: 0.97708333 | E28: =Effort!F26 -> 32.661893 | F28: =Harvest!F26 -> 146.97852 | G28: =+CPUE!F26 -> 4.5 | H28: =Effort!H26 -> 25.35313 | I28: =Harvest!H26 -> 114.08908 | J28: =CPUE!H26 -> 4.5 | K28: =Effort!J26 -> 33.333332 | L28: =Harvest!J26 -> 149.99999 | M28: =CPUE!J26 -> 4.5 | N28: =Effort!L26 -> CLOSED | O28: =Harvest!L26 -> CLOSED | P28: =CPUE!L26 -> CLOSED | Q28: CLOSED | R28: CLOSED | S28: CLOSED | T28: =SUM(E28+H28+K28) -> 91.348355 | U28: =SUM(F28+I28+L28) -> 411.0676
A29: Tide Series Totals | E29: =SUM(E22:E28) -> 4871.7503 | F29: =SUM(F22:F28) -> 53382.939 | G29: =+F29/E29 -> 10.957651 | H29: =SUM(H22:H28) -> 4386.2517 | I29: =SUM(I22:I28) -> 53184.814 | J29: =+I29/H29 -> 12.125345 | K29: =SUM(K22:K28) -> 2993.1297 | L29: =SUM(L22:L28) -> 39652.886 | M29: =+L29/K29 -> 13.247968 | N29: =SUM(N20:N28) -> 0 | O29: =SUM(O20:O28) -> 0 | P29: 0 | T29: =SUM(T22:T28) -> 12251.132 | U29: =SUM(U22:U28) -> 146220.64 | W29: =SUM(H29,K29,N29,Q29,E29) -> 12251.132 | X29: =SUM(R29,O29,L29,I29,F29) -> 146220.64
A30: 44871 | B30: Sun | C30: 0 | D30: 0.71388889 | E30: =Effort!F28 -> CLOSED | F30: =Harvest!F28 -> CLOSED | G30: =+CPUE!F28 -> CLOSED | H30: =Effort!H28 -> CLOSED | I30: =Harvest!H28 -> CLOSED | J30: =CPUE!H28 -> CLOSED | K30: =Effort!J28 -> CLOSED | L30: =Harvest!J28 -> CLOSED | M30: =CPUE!J28 -> CLOSED | N30: =Effort!L28 -> CLOSED | O30: =Harvest!L28 -> CLOSED | P30: =CPUE!L28 -> CLOSED | Q30: CLOSED | R30: CLOSED | S30: CLOSED | T30: 0 | U30: 0
A31: 44872 | B31: Mon | C31: -0.5 | D31: 0.74236111 | E31: =Effort!F29 -> CLOSED | F31: =Harvest!F29 -> CLOSED | G31: =+CPUE!F29 -> CLOSED | H31: =Effort!H29 -> CLOSED | I31: =Harvest!H29 -> CLOSED | J31: =CPUE!H29 -> CLOSED | K31: =Effort!J29 -> CLOSED | L31: =Harvest!J29 -> CLOSED | M31: =CPUE!J29 -> CLOSED | N31: =Effort!L29 -> CLOSED | O31: =Harvest!L29 -> CLOSED | P31: =CPUE!L29 -> CLOSED | Q31: CLOSED | R31: CLOSED | S31: CLOSED | T31: 0 | U31: 0
A32: 44873 | B32: Tue | C32: -0.7 | D32: 0.76944444 | E32: =Effort!F30 -> CLOSED | F32: =Harvest!F30 -> CLOSED | G32: =+CPUE!F30 -> CLOSED | H32: =Effort!H30 -> CLOSED | I32: =Harvest!H30 -> CLOSED | J32: =CPUE!H30 -> CLOSED | K32: =Effort!J30 -> CLOSED | L32: =Harvest!J30 -> CLOSED | M32: =CPUE!J30 -> CLOSED | N32: =Effort!L30 -> CLOSED | O32: =Harvest!L30 -> CLOSED | P32: =CPUE!L30 -> CLOSED | Q32: CLOSED | R32: CLOSED | S32: CLOSED | T32: 0 | U32: 0
A33: 44874 | B33: Wed | C33: -0.7 | D33: 0.79513889 | E33: =Effort!F31 -> CLOSED | F33: =Harvest!F31 -> CLOSED | G33: =+CPUE!F31 -> CLOSED | H33: =Effort!H31 -> CLOSED | I33: =Harvest!H31 -> CLOSED | J33: =CPUE!H31 -> CLOSED | K33: =Effort!J31 -> CLOSED | L33: =Harvest!J31 -> CLOSED | M33: =CPUE!J31 -> CLOSED | N33: =Effort!L31 -> CLOSED | O33: =Harvest!L31 -> CLOSED | P33: =CPUE!L31 -> CLOSED | Q33: CLOSED | R33: CLOSED | S33: CLOSED | T33: 0 | U33: 0
A34: 44875 | B34: Thu | C34: -0.6 | D34: 0.82083333 | E34: =Effort!F32 -> CLOSED | F34: =Harvest!F32 -> CLOSED | G34: =+CPUE!F32 -> CLOSED | H34: =Effort!H32 -> CLOSED | I34: =Harvest!H32 -> CLOSED | J34: =CPUE!H32 -> CLOSED | K34: =Effort!J32 -> CLOSED | L34: =Harvest!J32 -> CLOSED | M34: =CPUE!J32 -> CLOSED | N34: =Effort!L32 -> CLOSED | O34: =Harvest!L32 -> CLOSED | P34: =CPUE!L32 -> CLOSED | Q34: CLOSED | R34: CLOSED | S34: CLOSED | T34: 0 | U34: 0
A35: 44876 | B35: Fri | C35: -0.2 | D35: 0.84652778 | E35: =Effort!F33 -> CLOSED | F35: =Harvest!F33 -> CLOSED | G35: =+CPUE!F33 -> CLOSED | H35: =Effort!H33 -> CLOSED | I35: =Harvest!H33 -> CLOSED | J35: =CPUE!H33 -> CLOSED | K35: =Effort!J33 -> CLOSED | L35: =Harvest!J33 -> CLOSED | M35: =CPUE!J33 -> CLOSED | N35: =Effort!L33 -> CLOSED | O35: =Harvest!L33 -> CLOSED | P35: =CPUE!L33 -> CLOSED | Q35: CLOSED | R35: CLOSED | S35: CLOSED | T35: 0 | U35: 0
A36: 44877 | B36: Sat | C36: 0.1 | D36: 0.87430556 | E36: =Effort!F34 -> CLOSED | F36: =Harvest!F34 -> CLOSED | G36: =+CPUE!F34 -> CLOSED | H36: =Effort!H34 -> CLOSED | I36: =Harvest!H34 -> CLOSED | J36: =CPUE!H34 -> CLOSED | K36: =Effort!J34 -> CLOSED | L36: =Harvest!J34 -> CLOSED | M36: =CPUE!J34 -> CLOSED | N36: =Effort!L34 -> CLOSED | O36: =Harvest!L34 -> CLOSED | P36: =CPUE!L34 -> CLOSED | Q36: CLOSED | R36: CLOSED | S36: CLOSED | T36: 0 | U36: 0
A37: 44878 | B37: Sun | C37: 0.5 | D37: 0.90486111 | E37: =Effort!F35 -> CLOSED | F37: =Harvest!F35 -> CLOSED | G37: =+CPUE!F35 -> CLOSED | H37: =Effort!H35 -> CLOSED | I37: =Harvest!H35 -> CLOSED | J37: =CPUE!H35 -> CLOSED | K37: =Effort!J35 -> CLOSED | L37: =Harvest!J35 -> CLOSED | M37: =CPUE!J35 -> CLOSED | N37: =Effort!L35 -> CLOSED | O37: =Harvest!L35 -> CLOSED | P37: =CPUE!L35 -> CLOSED | Q37: CLOSED | R37: CLOSED | S37: CLOSED | T37: 0 | U37: 0
A38: Tide Series Totals | E38: =SUM(E30:E37) -> 0 | F38: =SUM(F30:F37) -> 0 | G38: 0 | H38: =SUM(H30:H37) -> 0 | I38: =SUM(I30:I37) -> 0 | J38: 0 | K38: =SUM(K30:K37) -> 0 | L38: =SUM(L30:L37) -> 0 | M38: 0 | N38: =SUM(N29:N37) -> 0 | O38: =SUM(O29:O37) -> 0 | P38: 0 | T38: =SUM(T30:T37) -> 0 | U38: =SUM(U30:U37) -> 0 | W38: =SUM(H38,K38,N38,Q38,E38) -> 0 | X38: =SUM(R38,O38,L38,I38,F38) -> 0
A39: 44887 | B39: Tue | C39: -0.6 | D39: 0.72361111 | E39: =Effort!F37 -> CLOSED | F39: =Harvest!F37 -> CLOSED | G39: =+CPUE!F37 -> CLOSED | H39: =Effort!H37 -> CLOSED | I39: =Harvest!H37 -> CLOSED | J39: =CPUE!H37 -> CLOSED | K39: =Effort!J37 -> CLOSED | L39: =Harvest!J37 -> CLOSED | M39: =CPUE!J37 -> CLOSED | N39: =Effort!L37 -> CLOSED | O39: =Harvest!L37 -> CLOSED | P39: =CPUE!L37 -> CLOSED | Q39: CLOSED | R39: CLOSED | S39: CLOSED | T39: 0 | U39: 0
A40: 44888 | B40: Wed | C40: -1.2 | D40: 0.75277778 | E40: =Effort!F38 -> CLOSED | F40: =Harvest!F38 -> CLOSED | G40: =+CPUE!F38 -> CLOSED | H40: =Effort!H38 -> CLOSED | I40: =Harvest!H38 -> CLOSED | J40: =CPUE!H38 -> CLOSED | K40: =Effort!J38 -> CLOSED | L40: =Harvest!J38 -> CLOSED | M40: =CPUE!J38 -> CLOSED | N40: =Effort!L38 -> CLOSED | O40: =Harvest!L38 -> CLOSED | P40: =CPUE!L38 -> CLOSED | Q40: CLOSED | R40: CLOSED | S40: CLOSED | T40: 0 | U40: 0
...

Sheet Tribal Update
A1: 2022-2023 State (non-Tribal) Recreational Razor Clam Effort, Harvest and CPUE totals.
E2: COPALIS | I2: MOCROCKS | M2: KALALOCH | Q2: DAILY TOTALS
A3: DATE | B3: DAY | C3: TIDE | D3: TIME | E3: Effort | F3: Harvest | G3: CPUE | H3: Size (mm) | I3: Effort | J3: Harvest | K3: CPUE | L3: Size (mm) | M3: Effort | N3: Harvest | O3: CPUE | P3: Size (mm) | Q3: Effort | R3: Harvest | T3: CROSS | U3: CHECK
A4: 44826 | B4: Thu | C4: 0.4 | D4: 0.21041667 | E4: =Effort!J2 -> CLOSED | F4: =Harvest!J2 -> CLOSED | G4: =CPUE!J2 -> CLOSED | I4: =Effort!L2 -> CLOSED | J4: =Harvest!L2 -> CLOSED | K4: =CPUE!L2 -> CLOSED | M4: CLOSED | N4: CLOSED | O4: CLOSED | Q4: =SUM(E4,I4) -> 0 | R4: =SUM(F4,J4) -> 0
A5: 44827 | B5: Fri | C5: 0.1 | D5: 0.23680556 | E5: =Effort!J3 -> CLOSED | F5: =Harvest!J3 -> CLOSED | G5: =CPUE!J3 -> CLOSED | I5: =Effort!L3 -> CLOSED | J5: =Harvest!L3 -> CLOSED | K5: =CPUE!L3 -> CLOSED | M5: CLOSED | N5: CLOSED | O5: CLOSED | Q5: =SUM(E5,I5) -> 0 | R5: =SUM(F5,J5) -> 0
A6: 44828 | B6: Sat | C6: 0 | D6: 0.26041667 | E6: =Effort!J4 -> CLOSED | F6: =Harvest!J4 -> CLOSED | G6: =CPUE!J4 -> CLOSED | I6: =Effort!L4 -> CLOSED | J6: =Harvest!L4 -> CLOSED | K6: =CPUE!L4 -> CLOSED | M6: CLOSED | N6: CLOSED | O6: CLOSED | Q6: =SUM(E6,I6) -> 0 | R6: =SUM(F6,J6) -> 0
A7: 44829 | B7: Sun | C7: 0.1 | D7: 0.28333333 | E7: =Effort!J5 -> CLOSED | F7: =Harvest!J5 -> CLOSED | G7: =CPUE!J5 -> CLOSED | I7: =Effort!L5 -> CLOSED | J7: =Harvest!L5 -> CLOSED | K7: =CPUE!L5 -> CLOSED | M7: CLOSED | N7: CLOSED | O7: CLOSED | Q7: =SUM(E7,I7) -> 0 | R7: =SUM(F7,J7) -> 0
A8: 44830 | B8: Mon | C8: 0.3 | D8: 0.30486111 | E8: =Effort!J6 -> CLOSED | F8: =Harvest!J6 -> CLOSED | G8: =CPUE!J6 -> CLOSED | I8: =Effort!L6 -> CLOSED | J8: =Harvest!L6 -> CLOSED | K8: =CPUE!L6 -> CLOSED | M8: CLOSED | N8: CLOSED | O8: CLOSED | Q8: =SUM(E8,I8) -> 0 | R8: =SUM(F8,J8) -> 0
A9: 44831 | B9: Tue | C9: -0.1 | D9: 0.85 | E9: =Effort!J7 -> CLOSED | F9: =Harvest!J7 -> CLOSED | G9: =CPUE!J7 -> CLOSED | I9: =Effort!L7 -> CLOSED | J9: =Harvest!L7 -> CLOSED | K9: =CPUE!L7 -> CLOSED | M9: CLOSED | N9: CLOSED | O9: CLOSED | Q9: =SUM(E9,I9) -> 0 | R9: =SUM(F9,J9) -> 0
