Workbook

Sheet Harvest
A1: Date | B1: Day | C1: Tide | D1: Time | E1: Longbeach | G1: Twin Harbors | I1: Copalis | K1: Mocrocks | M1: Kalaloch | O1: Daily Totals
A2: 45198 | B2: Fri | C2: -0.4 | D2: 0.80416667 | F2: =CPUE!F2*Effort!F2 -> 44532.182 | H2: 41038.749 | J2: CLOSED | L2: CLOSED | N2: CLOSED | O2: =SUM(F2:N2) -> 85570.931
A3: 45199 | B3: Sat | C3: -0.9 | D3: 0.83611111 | E3: * | F3: =CPUE!F3*Effort!F3 -> 63383.997 | H3: 58456.346 | J3: 72769.484 | L3: CLOSED | N3: CLOSED | O3: =SUM(F3:N3) -> 194609.83
A4: 45200 | B4: Sun | C4: -1 | D4: 0.86736111 | E4: * | F4: =CPUE!F4*Effort!F4 -> 30947.925 | H4: 28720.123 | J4: CLOSED | L4: CLOSED | N4: CLOSED | O4: =SUM(F4:N4) -> 59668.048
A5: 45201 | B5: Mon | C5: -0.9 | D5: 0.9 | F5: =CPUE!F5*Effort!F5 -> 394.03044 | G5: * | H5: =CPUE!H5*Effort!H5 -> 2272.9901 | J5: 4367.6468 | L5: CLOSED | N5: CLOSED | O5: =SUM(F5:N5) -> 7034.6673
A7: 45213 | B7: Sat | C7: 0.2 | D7: 0.80347222 | F7: =3482.98267566672+10080.507035801 -> 13563.49 | G7: * | H7: =CPUE!H7*Effort!H7 -> 21041.619 | J7: CLOSED | L7: 22050.241 | N7: CLOSED | O7: =SUM(F7:N7) -> 56655.35
A8: 45214 | B8: Sun | C8: -0.1 | D8: 0.82777778 | E8: * | F8: =CPUE!F8*Effort!F8 -> 6589.0142 | H8: 3269.4336 | J8: 13056.599 | L8: CLOSED | N8: CLOSED | O8: =SUM(F8:N8) -> 22915.047
A9: 45215 | B9: Mon | C9: -0.3 | D9: 0.85277778 | E9: * | F9: =CPUE!F9*Effort!F9 -> 4291.569 | H9: 4238.6005 | J9: CLOSED | L9: 3987.1746 | N9: CLOSED | O9: =SUM(F9:N9) -> 12517.344
A10: 45216 | B10: Tue | C10: -0.4 | D10: 0.87916667 | F10: =CPUE!F10*Effort!F10 -> 4433.0927 | G10: * | H10: =CPUE!H10*Effort!H10 -> 2978.7292 | J10: 5366.364 | L10: CLOSED | N10: CLOSED | O10: =SUM(F10:N10) -> 12778.186
A11: 45217 | B11: Wed | C11: -0.3 | D11: 0.90902778 | F11: CLOSED | H11: CLOSED | J11: CLOSED | L11: 3764.3276 | N11: CLOSED | O11: =SUM(F11:N11) -> 3764.3276
A13: 45226 | B13: Fri | C13: -0.4 | D13: 0.7625 | F13: =12457.2095200709+22290.208749628 -> 34747.418 | G13: * | H13: =CPUE!H13*Effort!H13 -> 35127.886 | J13: CLOSED | L13: 27143.77 | N13: CLOSED | O13: =SUM(F13:N13) -> 97019.074
A14: 45227 | B14: Sat | C14: -1 | D14: 0.79375 | F14: =CPUE!F14*Effort!F14 -> 64588.483 | G14: * | H14: =CPUE!H14*Effort!H14 -> 61989.429 | J14: 88542.046 | L14: CLOSED | N14: CLOSED | O14: =SUM(F14:N14) -> 215119.96
A15: 45228 | B15: Sun | C15: -1.3 | D15: 0.82361111 | E15: * | F15: =CPUE!F15*Effort!F15 -> 28776.205 | H15: 29622.072 | J15: CLOSED | L15: 22419.128 | N15: CLOSED | O15: =SUM(F15:N15) -> 80817.405
A16: 45229 | B16: Mon | C16: -1.3 | D16: 0.85347222 | E16: * | F16: =CPUE!F16*Effort!F16 -> 11622.022 | H16: 11137.627 | J16: 16481.603 | L16: CLOSED | N16: CLOSED | O16: =SUM(F16:N16) -> 39241.252
A17: 45230 | B17: Tue | C17: -1 | D17: 0.88333333 | F17: CLOSED | H17: CLOSED | J17: CLOSED | L17: 3479.6687 | N17: CLOSED | O17: =SUM(F17:N17) -> 3479.6687
A19: 45242 | B19: Sun | C19: -0.3 | D19: 0.74513889 | F19: CLOSED | H19: CLOSED | J19: CLOSED | L19: 7083.4606 | N19: CLOSED | O19: =SUM(F19:N19) -> 7083.4606
A20: 45243 | B20: Mon | C20: -0.7 | D20: 0.77083333 | E20: * | F20: =CPUE!F20*Effort!F20 -> 9528.3861 | H20: 8573.2218 | J20: 9347.6734 | L20: CLOSED | N20: CLOSED | O20: =SUM(F20:N20) -> 27449.281
A21: 45244 | B21: Tue | C21: -0.9 | D21: 0.79791667 | F21: =CPUE!F21*Effort!F21 -> 7177.0006 | H21: 7304.9194 | J21: CLOSED | L21: 8066.667 | N21: CLOSED | O21: =SUM(F21:N21) -> 22548.587
A22: 45245 | B22: Wed | C22: -0.9 | D22: 0.82708333 | F22: =CPUE!F22*Effort!F22 -> 3852.9506 | G22: * | H22: =CPUE!H22*Effort!H22 -> 3419.549 | J22: 6721.8045 | L22: CLOSED | N22: CLOSED | O22: =SUM(F22:N22) -> 13994.304
A23: 45246 | B23: Thu | C23: -0.8 | D23: 0.85902778 | E23: * | F23: =CPUE!F23*Effort!F23 -> 5462.8014 | G23: * | H23: =CPUE!H23*Effort!H23 -> 4915.188 | J23: CLOSED | L23: 4395.6636 | N23: CLOSED | O23: =SUM(F23:N23) -> 14773.653
A24: 45247 | B24: Fri | C24: -0.5 | D24: 0.89375 | F24: CLOSED | H24: CLOSED | J24: 14744.239 | L24: CLOSED | N24: CLOSED | O24: =SUM(F24:N24) -> 14744.239
A25: 45248 | B25: Sat | C25: -0.1 | D25: 0.93194444 | F25: CLOSED | H25: CLOSED | J25: CLOSED | L25: 1406.5974 | N25: CLOSED | O25: =SUM(F25:N25) -> 1406.5974
A27: 45254 | B27: Fri | C27: 0 | D27: 0.67916667 | E27: * | F27: =CPUE!F27*Effort!F27 -> 55077.19 | G27: * | H27: =CPUE!H27*Effort!H27 -> 44285.118 | J27: 68481 | L27: CLOSED | N27: CLOSED | O27: =SUM(F27:N27) -> 167843.31
A28: 45255 | B28: Sat | C28: -0.7 | D28: 0.71180556 | E28: * | F28: =CPUE!F28*Effort!F28 -> 56929.412 | H28: 41807.537 | J28: CLOSED | L28: 59593.015 | N28: CLOSED | O28: =SUM(F28:N28) -> 158329.96
A29: 45256 | B29: Sun | C29: -1.2 | D29: 0.74236111 | F29: =9346.93041058475+17922.0770854152 -> 27269.007 | H29: 21177.905 | J29: 36231.483 | L29: CLOSED | N29: CLOSED | O29: =SUM(F29:N29) -> 84678.395
A30: 45257 | B30: Mon | C30: -1.3 | D30: 0.77152778 | F30: =CPUE!F30*Effort!F30 -> 12578.36 | G30: * | H30: =CPUE!H30*Effort!H30 -> 9201.4962 | J30: CLOSED | L30: 11195.181 | N30: CLOSED | O30: =SUM(F30:N30) -> 32975.038
A31: 45258 | B31: Tue | C31: -1.2 | D31: 0.8 | E31: * | F31: =CPUE!F31*Effort!F31 -> 6256.1078 | G31: * | H31: =CPUE!H31*Effort!H31 -> 5030.2579 | J31: 7689.108 | L31: CLOSED | N31: CLOSED | O31: =SUM(F31:N31) -> 18975.474
A32: 45259 | B32: Wed | C32: -0.8 | D32: 0.82777778 | F32: CLOSED | H32: CLOSED | J32: CLOSED | L32: 2601.46 | N32: CLOSED | O32: =SUM(F32:N32) -> 2601.46
A34: 45273 | B34: Wed | C34: -1.3 | D34: 0.78819444 | E34: * | F34: =CPUE!F34*Effort!F34 -> 8865.2612 | H34: 6081.5171 | J34: CLOSED | L34: 8118.4107 | N34: CLOSED | O34: =SUM(F34:N34) -> 23065.189
A35: 45274 | B35: Thu | C35: -1.3 | D35: 0.81875 | F35: =CPUE!F35*Effort!F35 -> 5284.0545 | G35: * | H35: =CPUE!H35*Effort!H35 -> 4767.7902 | J35: 9305.8264 | L35: CLOSED | N35: CLOSED | O35: =SUM(F35:N35) -> 19357.671
A36: 45275 | B36: Fri | C36: -1.2 | D36: 0.85069444 | F36: =CPUE!F36*Effort!F36 -> 10017.893 | H36: 7867.5154 | J36: CLOSED | L36: 8854.3764 | N36: CLOSED | O36: =SUM(F36:N36) -> 26739.785
A37: 45276 | B37: Sat | C37: -0.8 | D37: 0.88333333 | E37: * | F37: =CPUE!F37*Effort!F37 -> 19930.535 | H37: 6562.5502 | J37: 25719.012 | L37: CLOSED | N37: CLOSED | O37: =SUM(F37:N37) -> 52212.096
A38: 45277 | B38: Sun | C38: -0.3 | D38: 0.91736111 | E38: * | F38: =CPUE!F38*Effort!F38 -> 2196.2504 | G38: * | H38: =CPUE!H38*Effort!H38 -> 2001.4884 | J38: CLOSED | L38: 2618.7129 | N38: CLOSED | O38: =SUM(F38:N38) -> 6816.4518
A40: 45286 | B40: Tue | C40: -0.9 | D40: 0.7625 | F40: =CPUE!F40*Effort!F40 -> 2047.1771 | G40: * | H40: =CPUE!H40*Effort!H40 -> 4960.3469 | J40: 18697.246 | L40: CLOSED | N40: CLOSED | O40: =SUM(F40:N40) -> 25704.77
A41: 45287 | B41: Wed | C41: -0.8 | D41: 0.78958333 | F41: =CPUE!F41*Effort!F41 -> 2148.5392 | H41: 3720.6711 | J41: CLOSED | L41: 8728.3042 | N41: CLOSED | O41: =SUM(F41:N41) -> 14597.515
A42: 45288 | B42: Thu | C42: -0.6 | D42: 0.81597222 | E42: * | F42: =CPUE!F42*Effort!F42 -> 949.30865 | H42: 628.19033 | J42: 3029.8787 | L42: CLOSED | N42: CLOSED | O42: =SUM(F42:N42) -> 4607.3777
A43: 45289 | B43: Fri | C43: -0.3 | D43: 0.84097222 | E43: * | F43: =CPUE!F43*Effort!F43 -> 1818.9855 | H43: 398.88187 | J43: CLOSED | L43: 6242.0674 | N43: CLOSED | O43: =SUM(F43:N43) -> 8459.9348
A45: 45300 | B45: Tue | C45: -0.7 | D45: 0.70972222 | E45: ** | F45: =CPUE!F45*Effort!F45 -> 200 | H45: CLOSED | J45: 247.5 | L45: CLOSED | N45: CLOSED | O45: =SUM(F45:N45) -> 447.5
A46: 45301 | B46: Wed | C46: -1.2 | D46: 0.74027778 | F46: =442.586695744316+535.659629471245 -> 978.24633 | H46: 3251.7513 | J46: CLOSED | L46: 3020.1963 | N46: CLOSED | O46: =SUM(F46:N46) -> 7250.194
A47: 45302 | B47: Thu | C47: -1.5 | D47: 0.76944444 | F47: =CPUE!F47*Effort!F47 -> 347.83294 | G47: * | H47: =CPUE!H47*Effort!H47 -> 633.47379 | J47: CLOSED | L47: 273.84756 | N47: CLOSED | O47: =SUM(F47:N47) -> 1255.1543
...

Sheet Effort
A1: Date | B1: Day | C1: Tide | D1: Time | E1: Longbeach | G1: Twin Harbors | I1: Copalis | K1: Mocrocks | M1: Kalaloch | O1: Daily Totals
A2: 45198 | B2: Fri | C2: -0.4 | D2: 0.80416667 | F2: =(3034.79154607489/2571.1998978297*1370.79060301813)+1370.79060301813 -> 2988.737 | H2: 2761.0168 | J2: CLOSED | L2: CLOSED | N2: CLOSED | O2: =SUM(F2:N2) -> 5749.7538
A3: 45199 | B3: Sat | C3: -0.9 | D3: 0.83611111 | E3: * | F3: =F2/H2*H3 -> 4253.9595 | H3: 3929.8384 | J3: 4894.3943 | L3: CLOSED | N3: CLOSED | O3: =SUM(F3:N3) -> 13078.192
A4: 45200 | B4: Sun | C4: -1 | D4: 0.86736111 | E4: * | F4: =F2/H2*H4 -> 2134.3397 | H4: 1971.7183 | J4: CLOSED | L4: CLOSED | N4: CLOSED | O4: =SUM(F4:N4) -> 4106.058
A5: 45201 | B5: Mon | C5: -0.9 | D5: 0.9 | F5: =(3034.79154607489/2571.1998978297*86.0585241725059)+86.0585241725059 -> 187.63354 | G5: * | H5: =H3/J3*J5 -> 454.59801 | J5: 566.17644 | L5: CLOSED | N5: CLOSED | O5: =SUM(F5:N5) -> 1208.408
A7: 45213 | B7: Sat | C7: 0.2 | D7: 0.80347222 | F7: =1079.72462945668+966.623962337087 -> 2046.3486 | G7: * | H7: =H9/L9*L7 -> 2003.9637 | J7: CLOSED | L7: 1765.4039 | N7: CLOSED | O7: =SUM(F7:N7) -> 5815.7163
A8: 45214 | B8: Sun | C8: -0.1 | D8: 0.82777778 | E8: * | F8: =F10/J10*J8 -> 1317.8028 | H8: 858.22633 | J8: 1476.9908 | L8: CLOSED | N8: CLOSED | O8: =SUM(F8:N8) -> 3653.02
A9: 45215 | B9: Mon | C9: -0.3 | D9: 0.85277778 | E9: * | F9: =F7/L7*L9 -> 330.12069 | H9: 323.28309 | J9: CLOSED | L9: 284.79819 | N9: CLOSED | O9: =SUM(F9:N9) -> 938.20197
A10: 45216 | B10: Tue | C10: -0.4 | D10: 0.87916667 | F10: =(1079.72462945668/966.623962337087*166.193568330958)+166.193568330958 -> 351.83276 | G10: * | H10: =H8/J8*J10 -> 229.13301 | J10: 394.33346 | L10: CLOSED | N10: CLOSED | O10: =SUM(F10:N10) -> 975.29923
A11: 45217 | B11: Wed | C11: -0.3 | D11: 0.90902778 | F11: CLOSED | H11: CLOSED | J11: CLOSED | L11: 407.60235 | N11: CLOSED | O11: =SUM(F11:N11) -> 407.60235
A13: 45226 | B13: Fri | C13: -0.4 | D13: 0.7625 | F13: =884.386071404625+1486.01391664187 -> 2370.4 | G13: * | H13: =H15/L15*L13 -> 2389.6521 | J13: CLOSED | L13: 1854.5433 | N13: CLOSED | O13: =SUM(F13:N13) -> 6614.5954
A14: 45227 | B14: Sat | C14: -1 | D14: 0.79375 | F14: =(884.386071404625/1486.01391664187*2699.38644319373)+2699.38644319373 -> 4305.8988 | G14: * | H14: =H16/J16*J14 -> 4132.6286 | J14: 5902.8031 | L14: CLOSED | N14: CLOSED | O14: =SUM(F14:N14) -> 14341.331
A15: 45228 | B15: Sun | C15: -1.3 | D15: 0.82361111 | E15: * | F15: =F13/L13*L15 -> 1984.5659 | H15: 2000.6843 | J15: CLOSED | L15: 1552.6761 | N15: CLOSED | O15: =SUM(F15:N15) -> 5537.9263
A16: 45229 | B16: Mon | C16: -1.3 | D16: 0.85347222 | E16: * | F16: =F14/J14*J16 -> 801.51879 | H16: 769.26551 | J16: 1098.7735 | L16: CLOSED | N16: CLOSED | O16: =SUM(F16:N16) -> 2669.5578
A17: 45230 | B17: Tue | C17: -1 | D17: 0.88333333 | F17: CLOSED | H17: CLOSED | J17: CLOSED | L17: 239.97715 | N17: CLOSED | O17: =SUM(F17:N17) -> 239.97715
A19: 45242 | B19: Sun | C19: -0.3 | D19: 0.74513889 | F19: CLOSED | H19: CLOSED | J19: CLOSED | L19: 1064.3542 | N19: CLOSED | O19: =SUM(F19:N19) -> 1064.3542
A20: 45243 | B20: Mon | C20: -0.7 | D20: 0.77083333 | E20: * | F20: =F21/H21*H20 -> 952.83861 | H20: 857.32218 | J20: 941.25878 | L20: CLOSED | N20: CLOSED | O20: =SUM(F20:N20) -> 2751.4196
A21: 45244 | B21: Tue | C21: -0.9 | D21: 0.79791667 | F21: =(1079.72462945668/966.623962337087*325.977467359895)+325.977467359895 -> 690.09621 | H21: 620.91815 | J21: CLOSED | L21: 550.00002 | N21: CLOSED | O21: =SUM(F21:N21) -> 1861.0144
A22: 45245 | B22: Wed | C22: -0.9 | D22: 0.82708333 | F22: =(1079.72462945668/966.623962337087*123.809522944513)+123.809522944513 -> 262.10549 | G22: * | H22: =H21/F21*F22 -> 235.83096 | J22: 467.41025 | L22: CLOSED | N22: CLOSED | O22: =SUM(F22:N22) -> 965.3467
A23: 45246 | B23: Thu | C23: -0.8 | D23: 0.85902778 | E23: * | F23: =F21/L21*L23 -> 420.2155 | G23: * | H23: =H21/L21*L23 -> 378.09138 | J23: CLOSED | L23: 334.9077 | N23: CLOSED | O23: =SUM(F23:N23) -> 1133.2146
A24: 45247 | B24: Fri | C24: -0.5 | D24: 0.89375 | F24: CLOSED | H24: CLOSED | J24: 982.94927 | L24: CLOSED | N24: CLOSED | O24: =SUM(F24:N24) -> 982.94927
A25: 45248 | B25: Sat | C25: -0.1 | D25: 0.93194444 | F25: CLOSED | H25: CLOSED | J25: CLOSED | L25: 445.65462 | N25: CLOSED | O25: =SUM(F25:N25) -> 445.65462
A27: 45254 | B27: Fri | C27: 0 | D27: 0.67916667 | E27: * | F27: =F29/J29*J27 -> 3934.085 | G27: * | H27: =H29/J29*J27 -> 3163.2227 | J27: 4790.8518 | L27: CLOSED | N27: CLOSED | O27: =SUM(F27:N27) -> 11888.16
A28: 45255 | B28: Sat | C28: -0.7 | D28: 0.71180556 | E28: * | F28: =F30/L30*L28 -> 4216.9935 | H28: 3195.0476 | J28: CLOSED | L28: 4031.2922 | N28: CLOSED | O28: =SUM(F28:N28) -> 11443.333
A29: 45256 | B29: Sun | C29: -1.2 | D29: 0.74236111 | F29: =761.460725913218+1258.74119997899 -> 2020.2019 | H29: 1624.3545 | J29: 2460.1624 | L29: CLOSED | N29: CLOSED | O29: =SUM(F29:N29) -> 6104.7188
A30: 45257 | B30: Mon | C30: -1.3 | D30: 0.77152778 | F30: =(761.460725913218/1258.74119997899*540.502471535061)+540.502471535061 -> 867.4731 | G30: * | H30: =H28/L28*L30 -> 657.24973 | J30: CLOSED | L30: 829.2727 | N30: CLOSED | O30: =SUM(F30:N30) -> 2353.9955
A31: 45258 | B31: Tue | C31: -1.2 | D31: 0.8 | E31: * | F31: =F29/J29*J31 -> 463.41539 | G31: * | H31: =H29/J29*J31 -> 372.6117 | J31: 564.3382 | L31: CLOSED | N31: CLOSED | O31: =SUM(F31:N31) -> 1400.3653
A32: 45259 | B32: Wed | C32: -0.8 | D32: 0.82777778 | F32: CLOSED | H32: CLOSED | J32: CLOSED | L32: 177.37227 | N32: CLOSED | O32: =SUM(F32:N32) -> 177.37227
A34: 45273 | B34: Wed | C34: -1.3 | D34: 0.78819444 | E34: * | F34: =F36/H36*H34 -> 681.94317 | H34: 621.46891 | J34: CLOSED | L34: 608.8808 | N34: CLOSED | O34: =SUM(F34:N34) -> 1912.2929
A35: 45274 | B35: Thu | C35: -1.3 | D35: 0.81875 | F35: =(761.460725913218/1258.74119997899*325.977467359895)+325.977467359895 -> 523.17371 | G35: * | H35: =H36/F36*F35 -> 476.77902 | J35: 652.6164 | L35: CLOSED | N35: CLOSED | O35: =SUM(F35:N35) -> 1652.5691
A36: 45275 | B36: Fri | C36: -1.2 | D36: 0.85069444 | F36: =(761.460725913218/1258.74119997899*491.489589081676)+491.489589081676 -> 788.81045 | H36: 718.85927 | J36: CLOSED | L36: 952.08349 | N36: CLOSED | O36: =SUM(F36:N36) -> 2459.7532
A37: 45276 | B37: Sat | C37: -0.8 | D37: 0.88333333 | E37: * | F37: =F35/J35*J37 -> 1374.5196 | H37: 493.13961 | J37: 1714.6008 | L37: CLOSED | N37: CLOSED | O37: =SUM(F37:N37) -> 3582.26
A38: 45277 | B38: Sun | C38: -0.3 | D38: 0.91736111 | E38: * | F38: =F36/L36*L38 -> 146.41669 | G38: * | H38: =H36/L36*L38 -> 133.43256 | J38: CLOSED | L38: 176.72296 | N38: CLOSED | O38: =SUM(F38:N38) -> 456.57221
A40: 45286 | B40: Tue | C40: -0.9 | D40: 0.7625 | F40: =(761.460725913218/1258.74119997899*579.794922858213)+579.794922858213 -> 930.53506 | G40: * | H40: =H42/J42*J40 -> 992.06937 | J40: 2092.4715 | L40: CLOSED | N40: CLOSED | O40: =SUM(F40:N40) -> 4015.076
A41: 45287 | B41: Wed | C41: -0.8 | D41: 0.78958333 | F41: =(761.460725913218/1258.74119997899*311.326794669562)+311.326794669562 -> 499.66029 | H41: 607.45651 | J41: CLOSED | L41: 786.33371 | N41: CLOSED | O41: =SUM(F41:N41) -> 1893.4505
A42: 45288 | B42: Thu | C42: -0.6 | D42: 0.81597222 | E42: * | F42: =F40/J40*J42 -> 316.43622 | H42: 337.36147 | J42: 711.56242 | L42: CLOSED | N42: CLOSED | O42: =SUM(F42:N42) -> 1365.3601
A43: 45289 | B43: Fri | C43: -0.3 | D43: 0.84097222 | E43: * | F43: =F41/L41*L43 -> 303.16425 | H43: 325.01486 | J43: CLOSED | L43: 477.10069 | N43: CLOSED | O43: =SUM(F43:N43) -> 1105.2798
A45: 45300 | B45: Tue | C45: -0.7 | D45: 0.70972222 | E45: ** | F45: 50 | H45: CLOSED | J45: 64.166667 | L45: CLOSED | N45: CLOSED | O45: =SUM(F45:N45) -> 114.16667
A46: 45301 | B46: Wed | C46: -1.2 | D46: 0.74027778 | F46: =43.044077368225+41.3080916028028 -> 84.352169 | H46: 342.28962 | J46: CLOSED | L46: 279.32451 | N46: CLOSED | O46: =SUM(F46:N46) -> 705.9663
A47: 45302 | B47: Thu | C47: -1.5 | D47: 0.76944444 | F47: =(43.044077368225/41.3080916028028*56.7790774160956)+56.7790774160956 -> 115.94431 | G47: * | H47: =H50/L50*L47 -> 211.15793 | J47: CLOSED | L47: 100.41077 | N47: CLOSED | O47: =SUM(F47:N47) -> 427.51302
...

Sheet CPUE
A1: Date | B1: Day | C1: Tide | D1: Time | E1: Longbeach | G1: Twin Harbors | I1: Copalis | K1: Mocrocks | M1: Kalaloch | O1: Daily Totals
A2: 45198 | B2: Fri | C2: -0.4 | D2: 0.80416667 | F2: 14.9 | H2: =+Harvest!H2/Effort!H2 -> 14.863636 | J2: CLOSED | L2: CLOSED | N2: CLOSED | O2: =+Harvest!O2/Effort!O2 -> 14.882538
A3: 45199 | B3: Sat | C3: -0.9 | D3: 0.83611111 | E3: * | F3: 14.9 | H3: =+Harvest!H3/Effort!H3 -> 14.875 | J3: =+Harvest!J3/Effort!J3 -> 14.867925 | L3: CLOSED | N3: CLOSED | O3: =+Harvest!O3/Effort!O3 -> 14.880484
A4: 45200 | B4: Sun | C4: -1 | D4: 0.86736111 | E4: * | F4: 14.5 | H4: =+Harvest!H4/Effort!H4 -> 14.566038 | J4: CLOSED | L4: CLOSED | N4: CLOSED | O4: =+Harvest!O4/Effort!O4 -> 14.531711
A5: 45201 | B5: Mon | C5: -0.9 | D5: 0.9 | F5: 2.1 | G5: * | H5: 5 | J5: =+Harvest!J5/Effort!J5 -> 7.7142857 | L5: CLOSED | N5: CLOSED | O5: =+Harvest!O5/Effort!O5 -> 5.8214339
A7: 45213 | B7: Sat | C7: 0.2 | D7: 0.80347222 | F7: =+Harvest!F7/Effort!F7 -> 6.6281423 | G7: * | H7: 10.5 | J7: CLOSED | L7: =+Harvest!L7/Effort!L7 -> 12.490196 | N7: CLOSED | O7: =+Harvest!O7/Effort!O7 -> 9.7417666
A8: 45214 | B8: Sun | C8: -0.1 | D8: 0.82777778 | E8: * | F8: 5 | H8: =+Harvest!H8/Effort!H8 -> 3.8095238 | J8: =+Harvest!J8/Effort!J8 -> 8.84 | L8: CLOSED | N8: CLOSED | O8: =+Harvest!O8/Effort!O8 -> 6.2729048
A9: 45215 | B9: Mon | C9: -0.3 | D9: 0.85277778 | E9: * | F9: 13 | H9: =+Harvest!H9/Effort!H9 -> 13.111111 | J9: CLOSED | L9: =+Harvest!L9/Effort!L9 -> 14 | N9: CLOSED | O9: =+Harvest!O9/Effort!O9 -> 13.341844
A10: 45216 | B10: Tue | C10: -0.4 | D10: 0.87916667 | F10: 12.6 | G10: * | H10: 13 | J10: =+Harvest!J10/Effort!J10 -> 13.608696 | L10: CLOSED | N10: CLOSED | O10: =+Harvest!O10/Effort!O10 -> 13.101811
A11: 45217 | B11: Wed | C11: -0.3 | D11: 0.90902778 | F11: CLOSED | H11: CLOSED | J11: CLOSED | L11: =+Harvest!L11/Effort!L11 -> 9.2352941 | N11: CLOSED | O11: =+Harvest!O11/Effort!O11 -> 9.2352941
A13: 45226 | B13: Fri | C13: -0.4 | D13: 0.7625 | F13: =+Harvest!F13/Effort!F13 -> 14.658884 | G13: * | H13: 14.7 | J13: CLOSED | L13: =+Harvest!L13/Effort!L13 -> 14.636364 | N13: CLOSED | O13: =+Harvest!O13/Effort!O13 -> 14.667424
A14: 45227 | B14: Sat | C14: -1 | D14: 0.79375 | F14: 15 | G14: * | H14: 15 | J14: =+Harvest!J14/Effort!J14 -> 15 | L14: CLOSED | N14: CLOSED | O14: =+Harvest!O14/Effort!O14 -> 15
A15: 45228 | B15: Sun | C15: -1.3 | D15: 0.82361111 | E15: * | F15: 14.5 | H15: =+Harvest!H15/Effort!H15 -> 14.80597 | J15: CLOSED | L15: =+Harvest!L15/Effort!L15 -> 14.439024 | N15: CLOSED | O15: =+Harvest!O15/Effort!O15 -> 14.593442
A16: 45229 | B16: Mon | C16: -1.3 | D16: 0.85347222 | E16: * | F16: 14.5 | H16: =+Harvest!H16/Effort!H16 -> 14.478261 | J16: =+Harvest!J16/Effort!J16 -> 15 | L16: CLOSED | N16: CLOSED | O16: =+Harvest!O16/Effort!O16 -> 14.699533
A17: 45230 | B17: Tue | C17: -1 | D17: 0.88333333 | F17: CLOSED | H17: CLOSED | J17: CLOSED | L17: =+Harvest!L17/Effort!L17 -> 14.5 | N17: CLOSED | O17: =+Harvest!O17/Effort!O17 -> 14.5
A19: 45242 | B19: Sun | C19: -0.3 | D19: 0.74513889 | F19: CLOSED | H19: CLOSED | J19: CLOSED | L19: =+Harvest!L19/Effort!L19 -> 6.6551724 | N19: CLOSED | O19: =+Harvest!O19/Effort!O19 -> 6.6551724
A20: 45243 | B20: Mon | C20: -0.7 | D20: 0.77083333 | E20: * | F20: 10 | H20: =+Harvest!H20/Effort!H20 -> 10 | J20: =+Harvest!J20/Effort!J20 -> 9.9310345 | L20: CLOSED | N20: CLOSED | O20: =+Harvest!O20/Effort!O20 -> 9.9764069
A21: 45244 | B21: Tue | C21: -0.9 | D21: 0.79791667 | F21: 10.4 | H21: =+Harvest!H21/Effort!H21 -> 11.764706 | J21: CLOSED | L21: =+Harvest!L21/Effort!L21 -> 14.666667 | N21: CLOSED | O21: =+Harvest!O21/Effort!O21 -> 12.116288
A22: 45245 | B22: Wed | C22: -0.9 | D22: 0.82708333 | F22: 14.7 | G22: * | H22: 14.5 | J22: =+Harvest!J22/Effort!J22 -> 14.380952 | L22: CLOSED | N22: CLOSED | O22: =+Harvest!O22/Effort!O22 -> 14.496661
A23: 45246 | B23: Thu | C23: -0.8 | D23: 0.85902778 | E23: * | F23: 13 | G23: * | H23: 13 | J23: CLOSED | L23: =+Harvest!L23/Effort!L23 -> 13.125 | N23: CLOSED | O23: =+Harvest!O23/Effort!O23 -> 13.036942
A24: 45247 | B24: Fri | C24: -0.5 | D24: 0.89375 | F24: CLOSED | H24: CLOSED | J24: =+Harvest!J24/Effort!J24 -> 15 | L24: CLOSED | N24: CLOSED | O24: =+Harvest!O24/Effort!O24 -> 15
A25: 45248 | B25: Sat | C25: -0.1 | D25: 0.93194444 | F25: CLOSED | H25: CLOSED | J25: CLOSED | L25: =+Harvest!L25/Effort!L25 -> 3.15625 | N25: CLOSED | O25: =+Harvest!O25/Effort!O25 -> 3.15625
A27: 45254 | B27: Fri | C27: 0 | D27: 0.67916667 | E27: * | F27: 14 | G27: * | H27: 14 | J27: =+Harvest!J27/Effort!J27 -> 14.294118 | L27: CLOSED | N27: CLOSED | O27: =+Harvest!O27/Effort!O27 -> 14.118528
A28: 45255 | B28: Sat | C28: -0.7 | D28: 0.71180556 | E28: * | F28: 13.5 | H28: =+Harvest!H28/Effort!H28 -> 13.085106 | J28: CLOSED | L28: =+Harvest!L28/Effort!L28 -> 14.782609 | N28: CLOSED | O28: =+Harvest!O28/Effort!O28 -> 13.836
A29: 45256 | B29: Sun | C29: -1.2 | D29: 0.74236111 | F29: =+Harvest!F29/Effort!F29 -> 13.498159 | H29: =+Harvest!H29/Effort!H29 -> 13.037736 | J29: =+Harvest!J29/Effort!J29 -> 14.727273 | L29: CLOSED | N29: CLOSED | O29: =+Harvest!O29/Effort!O29 -> 13.870974
A30: 45257 | B30: Mon | C30: -1.3 | D30: 0.77152778 | F30: 14.5 | G30: * | H30: 14 | J30: CLOSED | L30: =+Harvest!L30/Effort!L30 -> 13.5 | N30: CLOSED | O30: =+Harvest!O30/Effort!O30 -> 14.008114
A31: 45258 | B31: Tue | C31: -1.2 | D31: 0.8 | E31: * | F31: 13.5 | G31: * | H31: 13.5 | J31: =+Harvest!J31/Effort!J31 -> 13.625 | L31: CLOSED | N31: CLOSED | O31: =+Harvest!O31/Effort!O31 -> 13.550374
A32: 45259 | B32: Wed | C32: -0.8 | D32: 0.82777778 | F32: CLOSED | H32: CLOSED | J32: CLOSED | L32: =+Harvest!L32/Effort!L32 -> 14.666667 | N32: CLOSED | O32: =+Harvest!O32/Effort!O32 -> 14.666667
A34: 45273 | B34: Wed | C34: -1.3 | D34: 0.78819444 | E34: * | F34: 13 | H34: =+Harvest!H34/Effort!H34 -> 9.7857143 | J34: CLOSED | L34: =+Harvest!L34/Effort!L34 -> 13.333333 | N34: CLOSED | O34: =+Harvest!O34/Effort!O34 -> 12.061536
A35: 45274 | B35: Thu | C35: -1.3 | D35: 0.81875 | F35: 10.1 | G35: * | H35: 10 | J35: =+Harvest!J35/Effort!J35 -> 14.259259 | L35: CLOSED | N35: CLOSED | O35: =+Harvest!O35/Effort!O35 -> 11.713683
A36: 45275 | B36: Fri | C36: -1.2 | D36: 0.85069444 | F36: 12.7 | H36: =+Harvest!H36/Effort!H36 -> 10.944444 | J36: CLOSED | L36: =+Harvest!L36/Effort!L36 -> 9.3 | N36: CLOSED | O36: =+Harvest!O36/Effort!O36 -> 10.870922
A37: 45276 | B37: Sat | C37: -0.8 | D37: 0.88333333 | E37: * | F37: 14.5 | H37: =+Harvest!H37/Effort!H37 -> 13.307692 | J37: =+Harvest!J37/Effort!J37 -> 15 | L37: CLOSED | N37: CLOSED | O37: =+Harvest!O37/Effort!O37 -> 14.575183
A38: 45277 | B38: Sun | C38: -0.3 | D38: 0.91736111 | E38: * | F38: 15 | G38: * | H38: 15 | J38: CLOSED | L38: =+Harvest!L38/Effort!L38 -> 14.818182 | N38: CLOSED | O38: =+Harvest!O38/Effort!O38 -> 14.929625
A40: 45286 | B40: Tue | C40: -0.9 | D40: 0.7625 | F40: 2.2 | G40: * | H40: 5 | J40: =+Harvest!J40/Effort!J40 -> 8.9354839 | L40: CLOSED | N40: CLOSED | O40: =+Harvest!O40/Effort!O40 -> 6.4020631
A41: 45287 | B41: Wed | C41: -0.8 | D41: 0.78958333 | F41: 4.3 | H41: =+Harvest!H41/Effort!H41 -> 6.125 | J41: CLOSED | L41: =+Harvest!L41/Effort!L41 -> 11.1 | N41: CLOSED | O41: =+Harvest!O41/Effort!O41 -> 7.7094777
A42: 45288 | B42: Thu | C42: -0.6 | D42: 0.81597222 | E42: * | F42: 3 | H42: =+Harvest!H42/Effort!H42 -> 1.862069 | J42: =+Harvest!J42/Effort!J42 -> 4.2580645 | L42: CLOSED | N42: CLOSED | O42: =+Harvest!O42/Effort!O42 -> 3.374478
A43: 45289 | B43: Fri | C43: -0.3 | D43: 0.84097222 | E43: * | F43: 6 | H43: =+Harvest!H43/Effort!H43 -> 1.2272727 | J43: CLOSED | L43: =+Harvest!L43/Effort!L43 -> 13.083333 | N43: CLOSED | O43: =+Harvest!O43/Effort!O43 -> 7.6541114
A45: 45300 | B45: Tue | C45: -0.7 | D45: 0.70972222 | E45: ** | F45: 4 | H45: CLOSED | J45: =+Harvest!J45/Effort!J45 -> 3.8571429 | L45: CLOSED | N45: CLOSED | O45: =+Harvest!O45/Effort!O45 -> 3.919708
A46: 45301 | B46: Wed | C46: -1.2 | D46: 0.74027778 | F46: 10.7 | H46: =+Harvest!H46/Effort!H46 -> 9.5 | J46: CLOSED | L46: =+Harvest!L46/Effort!L46 -> 10.8125 | N46: CLOSED | O46: =+Harvest!O46/Effort!O46 -> 10.269887
A47: 45302 | B47: Thu | C47: -1.5 | D47: 0.76944444 | F47: 3 | G47: * | H47: 3 | J47: CLOSED | L47: =+Harvest!L47/Effort!L47 -> 2.7272727 | N47: CLOSED | O47: =+Harvest!O47/Effort!O47 -> 2.935944
...

Sheet Summary Table
A1: 2023-2024 State (non-Tribal) Recreational Razor Clam Effort, Harvest and CPUE totals.
E2: LONG BEACH | H2: TWIN HARBORS | K2: COPALIS | N2: MOCROCKS | Q2: KALALOCH | T2: DAILY TOTALS | W2: CROSS | X2: CHECK
A3: DATE | B3: DAY | C3: TIDE | D3: TIME | E3: Effort | F3: Harvest | G3: CPUE | H3: Effort | I3: Harvest | J3: CPUE | K3: Effort | L3: Harvest | M3: CPUE | N3: Effort | O3: Harvest | P3: CPUE | Q3: Effort | R3: Harvest | S3: CPUE | T3: Effort | U3: Harvest
A4: 45198 | B4: Fri | C4: -0.4 | D4: 0.80416667 | E4: =Effort!F2 -> 2988.737 | F4: =Harvest!F2 -> 44532.182 | G4: =+CPUE!F2 -> 14.9 | H4: =Effort!H2 -> 2761.0168 | I4: =Harvest!H2 -> 41038.749 | J4: =CPUE!H2 -> 14.863636 | K4: =Effort!J2 -> CLOSED | L4: =Harvest!J2 -> CLOSED | M4: =CPUE!J2 -> CLOSED | N4: =Effort!L2 -> CLOSED | O4: =Harvest!L2 -> CLOSED | P4: =CPUE!L2 -> CLOSED | Q4: CLOSED | R4: CLOSED | S4: CLOSED | T4: =SUM(E4,H4,N4) -> 5749.7538 | U4: =SUM(F4,I4,O4) -> 85570.931
A5: 45199 | B5: Sat | C5: -0.9 | D5: 0.83611111 | E5: =Effort!F3 -> 4253.9595 | F5: =Harvest!F3 -> 63383.997 | G5: =+CPUE!F3 -> 14.9 | H5: =Effort!H3 -> 3929.8384 | I5: =Harvest!H3 -> 58456.346 | J5: =CPUE!H3 -> 14.875 | K5: =Effort!J3 -> 4894.3943 | L5: =Harvest!J3 -> 72769.484 | M5: =CPUE!J3 -> 14.867925 | N5: =Effort!L3 -> CLOSED | O5: =Harvest!L3 -> CLOSED | P5: =CPUE!L3 -> CLOSED | Q5: CLOSED | R5: CLOSED | S5: CLOSED | T5: =SUM(E5,H5,K5) -> 13078.192 | U5: =SUM(F5,I5,L5) -> 194609.83
A6: 45200 | B6: Sun | C6: -1 | D6: 0.86736111 | E6: =Effort!F4 -> 2134.3397 | F6: =Harvest!F4 -> 30947.925 | G6: =+CPUE!F4 -> 14.5 | H6: =Effort!H4 -> 1971.7183 | I6: =Harvest!H4 -> 28720.123 | J6: =CPUE!H4 -> 14.566038 | K6: =Effort!J4 -> CLOSED | L6: =Harvest!J4 -> CLOSED | M6: =CPUE!J4 -> CLOSED | N6: =Effort!L4 -> CLOSED | O6: =Harvest!L4 -> CLOSED | P6: =CPUE!L4 -> CLOSED | Q6: CLOSED | R6: CLOSED | S6: CLOSED | T6: =SUM(E6,H6,N6) -> 4106.058 | U6: =SUM(F6,I6,O6) -> 59668.048
A7: 45201 | B7: Mon | C7: -0.9 | D7: 0.9 | E7: =Effort!F5 -> 187.63354 | F7: =Harvest!F5 -> 394.03044 | G7: =+CPUE!F5 -> 2.1 | H7: =Effort!H5 -> 454.59801 | I7: =Harvest!H5 -> 2272.9901 | J7: =CPUE!H5 -> 5 | K7: =Effort!J5 -> 566.17644 | L7: =Harvest!J5 -> 4367.6468 | M7: =CPUE!J5 -> 7.7142857 | N7: =Effort!L5 -> CLOSED | O7: =Harvest!L5 -> CLOSED | P7: =CPUE!L5 -> CLOSED | Q7: CLOSED | R7: CLOSED | S7: CLOSED | T7: =SUM(E7,H7,K7) -> 1208.408 | U7: =SUM(F7,I7,L7) -> 7034.6673
A8: Tide Series Totals | E8: =SUM(E4:E7) -> 9564.6698 | F8: =SUM(F4:F7) -> 139258.13 | G8: =+F8/E8 -> 14.559639 | H8: =SUM(H4:H7) -> 9117.1715 | I8: =SUM(I4:I7) -> 130488.21 | J8: =+I8/H8 -> 14.312357 | K8: =SUM(K4:K7) -> 5460.5707 | L8: =SUM(L4:L7) -> 77137.131 | M8: =+L8/K8 -> 14.126203 | N8: =SUM(N4:N7) -> 0 | O8: 0 | P8: 0 | T8: =SUM(T4:T7) -> 24142.412 | U8: =SUM(U4:U7) -> 346883.47 | W8: =SUM(H8,K8,N8,Q8,E8) -> 24142.412 | X8: =SUM(R8,O8,L8,I8,F8) -> 346883.47
A9: 45213 | B9: Sat | C9: 0.2 | D9: 0.80347222 | E9: =Effort!F7 -> 2046.3486 | F9: =Harvest!F7 -> 13563.49 | G9: =+CPUE!F7 -> 6.6281423 | H9: =Effort!H7 -> 2003.9637 | I9: =Harvest!H7 -> 21041.619 | J9: =CPUE!H7 -> 10.5 | K9: =Effort!J7 -> CLOSED | L9: =Harvest!J7 -> CLOSED | M9: =CPUE!J7 -> CLOSED | N9: =Effort!L7 -> 1765.4039 | O9: =Harvest!L7 -> 22050.241 | P9: =CPUE!L7 -> 12.490196 | Q9: CLOSED | R9: CLOSED | S9: CLOSED | T9: =SUM(E9,H9,N9) -> 5815.7163 | U9: =SUM(F9,I9,O9) -> 56655.35
A10: 45214 | B10: Sun | C10: -0.1 | D10: 0.82777778 | E10: =Effort!F8 -> 1317.8028 | F10: =Harvest!F8 -> 6589.0142 | G10: =+CPUE!F8 -> 5 | H10: =Effort!H8 -> 858.22633 | I10: =Harvest!H8 -> 3269.4336 | J10: =CPUE!H8 -> 3.8095238 | K10: =Effort!J8 -> 1476.9908 | L10: =Harvest!J8 -> 13056.599 | M10: =CPUE!J8 -> 8.84 | N10: =Effort!L8 -> CLOSED | O10: =Harvest!L8 -> CLOSED | P10: =CPUE!L8 -> CLOSED | Q10: CLOSED | R10: CLOSED | S10: CLOSED | T10: =SUM(E10,H10,K10) -> 3653.02 | U10: =SUM(F10,I10,L10) -> 22915.047
A11: 45215 | B11: Mon | C11: -0.3 | D11: 0.85277778 | E11: =Effort!F9 -> 330.12069 | F11: =Harvest!F9 -> 4291.569 | G11: =+CPUE!F9 -> 13 | H11: =Effort!H9 -> 323.28309 | I11: =Harvest!H9 -> 4238.6005 | J11: =CPUE!H9 -> 13.111111 | K11: =Effort!J9 -> CLOSED | L11: =Harvest!J9 -> CLOSED | M11: =CPUE!J9 -> CLOSED | N11: =Effort!L9 -> 284.79819 | O11: =Harvest!L9 -> 3987.1746 | P11: =CPUE!L9 -> 14 | Q11: CLOSED | R11: CLOSED | S11: CLOSED | T11: =SUM(E11,H11,N11) -> 938.20197 | U11: =SUM(F11,I11,O11) -> 12517.344
A12: 45216 | B12: Tue | C12: -0.4 | D12: 0.87916667 | E12: =Effort!F10 -> 351.83276 | F12: =Harvest!F10 -> 4433.0927 | G12: =+CPUE!F10 -> 12.6 | H12: =Effort!H10 -> 229.13301 | I12: =Harvest!H10 -> 2978.7292 | J12: =CPUE!H10 -> 13 | K12: =Effort!J10 -> 394.33346 | L12: =Harvest!J10 -> 5366.364 | M12: =CPUE!J10 -> 13.608696 | N12: =Effort!L10 -> CLOSED | O12: =Harvest!L10 -> CLOSED | P12: =CPUE!L10 -> CLOSED | Q12: CLOSED | R12: CLOSED | S12: CLOSED | T12: =SUM(E12,H12,K12) -> 975.29923 | U12: =SUM(F12,I12,L12) -> 12778.186
A13: 45217 | B13: Wed | C13: -0.3 | D13: 0.90902778 | E13: =Effort!F11 -> CLOSED | F13: =Harvest!F11 -> CLOSED | G13: =+CPUE!F11 -> CLOSED | H13: =Effort!H11 -> CLOSED | I13: =Harvest!H11 -> CLOSED | J13: =CPUE!H11 -> CLOSED | K13: =Effort!J11 -> CLOSED | L13: =Harvest!J11 -> CLOSED | M13: =CPUE!J11 -> CLOSED | N13: =Effort!L11 -> 407.60235 | O13: =Harvest!L11 -> 3764.3276 | P13: =CPUE!L11 -> 9.2352941 | Q13: CLOSED | R13: CLOSED | S13: CLOSED | T13: =SUM(E13,H13,N13) -> 407.60235 | U13: =SUM(F13,I13,O13) -> 3764.3276
A14: Tide Series Totals | E14: =SUM(E9:E13) -> 4046.1049 | F14: =SUM(F9:F13) -> 28877.166 | G14: =+F14/E14 -> 7.1370284 | H14: =SUM(H9:H13) -> 3414.6062 | I14: =SUM(I9:I13) -> 31528.382 | J14: =+I14/H14 -> 9.2333877 | K14: =SUM(K9:K13) -> 1871.3243 | L14: =SUM(L9:L13) -> 18422.963 | M14: =+L14/K14 -> 9.8448799 | N14: =SUM(N9:N13) -> 2457.8045 | O14: =SUM(O9:O13) -> 29801.744 | P14: =+O14/N14 -> 12.125352 | T14: =SUM(T9:T13) -> 11789.84 | U14: =SUM(U9:U13) -> 108630.25 | W14: =SUM(H14,K14,N14,Q14,E14) -> 11789.84 | X14: =SUM(R14,O14,L14,I14,F14) -> 108630.25
A15: 45226 | B15: Fri | C15: -0.4 | D15: 0.7625 | E15: =Effort!F13 -> 2370.4 | F15: =Harvest!F13 -> 34747.418 | G15: =+CPUE!F13 -> 14.658884 | H15: =Effort!H13 -> 2389.6521 | I15: =Harvest!H13 -> 35127.886 | J15: =CPUE!H13 -> 14.7 | K15: =Effort!J13 -> CLOSED | L15: =Harvest!J13 -> CLOSED | M15: =CPUE!J13 -> CLOSED | N15: =Effort!L13 -> 1854.5433 | O15: =Harvest!L13 -> 27143.77 | P15: =CPUE!L13 -> 14.636364 | Q15: CLOSED | R15: CLOSED | S15: CLOSED | T15: =SUM(E15,H15,N15) -> 6614.5954 | U15: =SUM(F15,I15,O15) -> 97019.074
A16: 45227 | B16: Sat | C16: -1 | D16: 0.79375 | E16: =Effort!F14 -> 4305.8988 | F16: =Harvest!F14 -> 64588.483 | G16: =+CPUE!F14 -> 15 | H16: =Effort!H14 -> 4132.6286 | I16: =Harvest!H14 -> 61989.429 | J16: =CPUE!H14 -> 15 | K16: =Effort!J14 -> 5902.8031 | L16: =Harvest!J14 -> 88542.046 | M16: =CPUE!J14 -> 15 | N16: =Effort!L14 -> CLOSED | O16: =Harvest!L14 -> CLOSED | P16: =CPUE!L14 -> CLOSED | Q16: CLOSED | R16: CLOSED | S16: CLOSED | T16: =SUM(E16,H16,K16) -> 14341.331 | U16: =SUM(F16,I16,L16) -> 215119.96
A17: 45228 | B17: Sun | C17: -1.3 | D17: 0.82361111 | E17: =Effort!F15 -> 1984.5659 | F17: =Harvest!F15 -> 28776.205 | G17: =+CPUE!F15 -> 14.5 | H17: =Effort!H15 -> 2000.6843 | I17: =Harvest!H15 -> 29622.072 | J17: =CPUE!H15 -> 14.80597 | K17: =Effort!J15 -> CLOSED | L17: =Harvest!J15 -> CLOSED | M17: =CPUE!J15 -> CLOSED | N17: =Effort!L15 -> 1552.6761 | O17: =Harvest!L15 -> 22419.128 | P17: =CPUE!L15 -> 14.439024 | Q17: CLOSED | R17: CLOSED | S17: CLOSED | T17: =SUM(E17,H17,N17) -> 5537.9263 | U17: =SUM(F17,I17,O17) -> 80817.405
A18: 45229 | B18: Mon | C18: -1.3 | D18: 0.85347222 | E18: =Effort!F16 -> 801.51879 | F18: =Harvest!F16 -> 11622.022 | G18: =+CPUE!F16 -> 14.5 | H18: =Effort!H16 -> 769.26551 | I18: =Harvest!H16 -> 11137.627 | J18: =CPUE!H16 -> 14.478261 | K18: =Effort!J16 -> 1098.7735 | L18: =Harvest!J16 -> 16481.603 | M18: =CPUE!J16 -> 15 | N18: =Effort!L16 -> CLOSED | O18: =Harvest!L16 -> CLOSED | P18: =CPUE!L16 -> CLOSED | Q18: CLOSED | R18: CLOSED | S18: CLOSED | T18: =SUM(E18,H18,K18) -> 2669.5578 | U18: =SUM(F18,I18,L18) -> 39241.252
A19: 45230 | B19: Tue | C19: -1 | D19: 0.88333333 | E19: =Effort!F17 -> CLOSED | F19: =Harvest!F17 -> CLOSED | G19: =+CPUE!F17 -> CLOSED | H19: =Effort!H17 -> CLOSED | I19: =Harvest!H17 -> CLOSED | J19: =CPUE!H17 -> CLOSED | K19: =Effort!J17 -> CLOSED | L19: =Harvest!J17 -> CLOSED | M19: =CPUE!J17 -> CLOSED | N19: =Effort!L17 -> 239.97715 | O19: =Harvest!L17 -> 3479.6687 | P19: =CPUE!L17 -> 14.5 | Q19: CLOSED | R19: CLOSED | S19: CLOSED | T19: =SUM(E19,H19,N19) -> 239.97715 | U19: =SUM(F19,I19,O19) -> 3479.6687
A20: Tide Series Totals | E20: =SUM(E15:E19) -> 9462.3835 | F20: =SUM(F15:F19) -> 139734.13 | G20: =+F20/E20 -> 14.767329 | H20: =SUM(H15:H19) -> 9292.2305 | I20: =SUM(I15:I19) -> 137877.01 | J20: =+I20/H20 -> 14.837881 | K20: =SUM(K15:K19) -> 7001.5766 | L20: =SUM(L15:L19) -> 105023.65 | M20: =+L20/K20 -> 15 | N20: =SUM(N15:N19) -> 3647.1965 | O20: =SUM(O15:O19) -> 53042.567 | P20: =+O20/N20 -> 14.54338 | T20: =SUM(T15:T19) -> 29403.387 | U20: =SUM(U15:U19) -> 435677.36 | W20: =SUM(H20,K20,N20,Q20,E20) -> 29403.387 | X20: =SUM(R20,O20,L20,I20,F20) -> 435677.36
A21: 45242 | B21: Sun | C21: -0.3 | D21: 0.74513889 | E21: =Effort!F19 -> CLOSED | F21: =Harvest!F19 -> CLOSED | G21: =+CPUE!F19 -> CLOSED | H21: =Effort!H19 -> CLOSED | I21: =Harvest!H19 -> CLOSED | J21: =CPUE!H19 -> CLOSED | K21: =Effort!J19 -> CLOSED | L21: =Harvest!J19 -> CLOSED | M21: =CPUE!J19 -> CLOSED | N21: =Effort!L19 -> 1064.3542 | O21: =Harvest!L19 -> 7083.4606 | P21: =CPUE!L19 -> 6.6551724 | Q21: CLOSED | R21: CLOSED | S21: CLOSED | T21: =SUM(E21,H21,N21) -> 1064.3542 | U21: =SUM(F21,I21,O21) -> 7083.4606
A22: 45243 | B22: Mon | C22: -0.7 | D22: 0.77083333 | E22: =Effort!F20 -> 952.83861 | F22: =Harvest!F20 -> 9528.3861 | G22: =+CPUE!F20 -> 10 | H22: =Effort!H20 -> 857.32218 | I22: =Harvest!H20 -> 8573.2218 | J22: =CPUE!H20 -> 10 | K22: =Effort!J20 -> 941.25878 | L22: =Harvest!J20 -> 9347.6734 | M22: =CPUE!J20 -> 9.9310345 | N22: =Effort!L20 -> CLOSED | O22: =Harvest!L20 -> CLOSED | P22: =CPUE!L20 -> CLOSED | Q22: CLOSED | R22: CLOSED | S22: CLOSED | T22: =SUM(E22,H22,K22) -> 2751.4196 | U22: =SUM(F22,I22,L22) -> 27449.281
A23: 45244 | B23: Tue | C23: -0.9 | D23: 0.79791667 | E23: =Effort!F21 -> 690.09621 | F23: =Harvest!F21 -> 7177.0006 | G23: =+CPUE!F21 -> 10.4 | H23: =Effort!H21 -> 620.91815 | I23: =Harvest!H21 -> 7304.9194 | J23: =CPUE!H21 -> 11.764706 | K23: =Effort!J21 -> CLOSED | L23: =Harvest!J21 -> CLOSED | M23: =CPUE!J21 -> CLOSED | N23: =Effort!L21 -> 550.00002 | O23: =Harvest!L21 -> 8066.667 | P23: =CPUE!L21 -> 14.666667 | Q23: CLOSED | R23: CLOSED | S23: CLOSED | T23: =SUM(E23,H23,N23) -> 1861.0144 | U23: =SUM(F23,I23,O23) -> 22548.587
A24: 45245 | B24: Wed | C24: -0.9 | D24: 0.82708333 | E24: =Effort!F22 -> 262.10549 | F24: =Harvest!F22 -> 3852.9506 | G24: =+CPUE!F22 -> 14.7 | H24: =Effort!H22 -> 235.83096 | I24: =Harvest!H22 -> 3419.549 | J24: =CPUE!H22 -> 14.5 | K24: =Effort!J22 -> 467.41025 | L24: =Harvest!J22 -> 6721.8045 | M24: =CPUE!J22 -> 14.380952 | N24: =Effort!L22 -> CLOSED | O24: =Harvest!L22 -> CLOSED | P24: =CPUE!L22 -> CLOSED | Q24: CLOSED | R24: CLOSED | S24: CLOSED | T24: =SUM(E24,H24,K24) -> 965.3467 | U24: =SUM(F24,I24,L24) -> 13994.304
A25: 45246 | B25: Thu | C25: -0.8 | D25: 0.85902778 | E25: =Effort!F23 -> 420.2155 | F25: =Harvest!F23 -> 5462.8014 | G25: =+CPUE!F23 -> 13 | H25: =Effort!H23 -> 378.09138 | I25: =Harvest!H23 -> 4915.188 | J25: =CPUE!H23 -> 13 | K25: =Effort!J23 -> CLOSED | L25: =Harvest!J23 -> CLOSED | M25: =CPUE!J23 -> CLOSED | N25: =Effort!L23 -> 334.9077 | O25: =Harvest!L23 -> 4395.6636 | P25: =CPUE!L23 -> 13.125 | Q25: CLOSED | R25: CLOSED | S25: CLOSED | T25: =SUM(E25,H25,N25) -> 1133.2146 | U25: =SUM(F25,I25,O25) -> 14773.653
A26: 45247 | B26: Fri | C26: -0.5 | D26: 0.89375 | E26: =Effort!F24 -> CLOSED | F26: =Harvest!F24 -> CLOSED | G26: =+CPUE!F24 -> CLOSED | H26: =Effort!H24 -> CLOSED | I26: =Harvest!H24 -> CLOSED | J26: =CPUE!H24 -> CLOSED | K26: =Effort!J24 -> 982.94927 | L26: =Harvest!J24 -> 14744.239 | M26: =CPUE!J24 -> 15 | N26: =Effort!L24 -> CLOSED | O26: =Harvest!L24 -> CLOSED | P26: =CPUE!L24 -> CLOSED | Q26: CLOSED | R26: CLOSED | S26: CLOSED | T26: =SUM(E26,H26,K26) -> 982.94927 | U26: =SUM(F26,I26,L26) -> 14744.239
A27: 45248 | B27: Sat | C27: -0.1 | D27: 0.93194444 | E27: =Effort!F25 -> CLOSED | F27: =Harvest!F25 -> CLOSED | G27: =+CPUE!F25 -> CLOSED | H27: =Effort!H25 -> CLOSED | I27: =Harvest!H25 -> CLOSED | J27: =CPUE!H25 -> CLOSED | K27: =Effort!J25 -> CLOSED | L27: =Harvest!J25 -> CLOSED | M27: =CPUE!J25 -> CLOSED | N27: =Effort!L25 -> 445.65462 | O27: =Harvest!L25 -> 1406.5974 | P27: =CPUE!L25 -> 3.15625 | Q27: CLOSED | R27: CLOSED | S27: CLOSED | T27: =SUM(E27,H27,N27) -> 445.65462 | U27: =SUM(F27,I27,O27) -> 1406.5974
A28: Tide Series Totals | E28: =SUM(E21:E27) -> 2325.2558 | F28: =SUM(F21:F27) -> 26021.139 | G28: =+F28/E28 -> 11.190656 | H28: =SUM(H21:H27) -> 2092.1627 | I28: =SUM(I21:I27) -> 24212.878 | J28: =+I28/H28 -> 11.573134 | K28: =SUM(K21:K27) -> 2391.6183 | L28: =SUM(L21:L27) -> 30813.717 | M28: =+L28/K28 -> 12.884045 | N28: =SUM(N21:N27) -> 2394.9165 | O28: =SUM(O21:O27) -> 20952.389 | P28: =+O28/N28 -> 8.7486926 | T28: =SUM(T21:T27) -> 9203.9533 | U28: =SUM(U21:U27) -> 102000.12 | W28: =SUM(H28,K28,N28,Q28,E28) -> 9203.9533 | X28: =SUM(R28,O28,L28,I28,F28) -> 102000.12
A29: 45254 | B29: Fri | C29: 0 | D29: 0.67916667 | E29: =Effort!F27 -> 3934.085 | F29: =Harvest!F27 -> 55077.19 | G29: =+CPUE!F27 -> 14 | H29: =Effort!H27 -> 3163.2227 | I29: =Harvest!H27 -> 44285.118 | J29: =CPUE!H27 -> 14 | K29: =Effort!J27 -> 4790.8518 | L29: =Harvest!J27 -> 68481 | M29: =CPUE!J27 -> 14.294118 | N29: =Effort!L27 -> CLOSED | O29: =Harvest!L27 -> CLOSED | P29: =CPUE!L27 -> CLOSED | Q29: CLOSED | R29: CLOSED | S29: CLOSED | T29: =SUM(E29,H29,K29) -> 11888.16 | U29: =SUM(F29,I29,L29) -> 167843.31
A30: 45255 | B30: Sat | C30: -0.7 | D30: 0.71180556 | E30: =Effort!F28 -> 4216.9935 | F30: =Harvest!F28 -> 56929.412 | G30: =+CPUE!F28 -> 13.5 | H30: =Effort!H28 -> 3195.0476 | I30: =Harvest!H28 -> 41807.537 | J30: =CPUE!H28 -> 13.085106 | K30: =Effort!J28 -> CLOSED | L30: =Harvest!J28 -> CLOSED | M30: =CPUE!J28 -> CLOSED | N30: =Effort!L28 -> 4031.2922 | O30: =Harvest!L28 -> 59593.015 | P30: =CPUE!L28 -> 14.782609 | Q30: CLOSED | R30: CLOSED | S30: CLOSED | T30: =SUM(E30,H30,N30) -> 11443.333 | U30: =SUM(F30,I30,O30) -> 158329.96
A31: 45256 | B31: Sun | C31: -1.2 | D31: 0.74236111 | E31: =Effort!F29 -> 2020.2019 | F31: =Harvest!F29 -> 27269.007 | G31: =+CPUE!F29 -> 13.498159 | H31: =Effort!H29 -> 1624.3545 | I31: =Harvest!H29 -> 21177.905 | J31: =CPUE!H29 -> 13.037736 | K31: =Effort!J29 -> 2460.1624 | L31: =Harvest!J29 -> 36231.483 | M31: =CPUE!J29 -> 14.727273 | N31: =Effort!L29 -> CLOSED | O31: =Harvest!L29 -> CLOSED | P31: =CPUE!L29 -> CLOSED | Q31: CLOSED | R31: CLOSED | S31: CLOSED | T31: =SUM(E31,H31,K31) -> 6104.7188 | U31: =SUM(F31,I31,L31) -> 84678.395
A32: 45257 | B32: Mon | C32: -1.3 | D32: 0.77152778 | E32: =Effort!F30 -> 867.4731 | F32: =Harvest!F30 -> 12578.36 | G32: =+CPUE!F30 -> 14.5 | H32: =Effort!H30 -> 657.24973 | I32: =Harvest!H30 -> 9201.4962 | J32: =CPUE!H30 -> 14 | K32: =Effort!J30 -> CLOSED | L32: =Harvest!J30 -> CLOSED | M32: =CPUE!J30 -> CLOSED | N32: =Effort!L30 -> 829.2727 | O32: =Harvest!L30 -> 11195.181 | P32: =CPUE!L30 -> 13.5 | Q32: CLOSED | R32: CLOSED | S32: CLOSED | T32: =SUM(E32,H32,N32) -> 2353.9955 | U32: =SUM(F32,I32,O32) -> 32975.038
A33: 45258 | B33: Tue | C33: -1.2 | D33: 0.8 | E33: =Effort!F31 -> 463.41539 | F33: =Harvest!F31 -> 6256.1078 | G33: =+CPUE!F31 -> 13.5 | H33: =Effort!H31 -> 372.6117 | I33: =Harvest!H31 -> 5030.2579 | J33: =CPUE!H31 -> 13.5 | K33: =Effort!J31 -> 564.3382 | L33: =Harvest!J31 -> 7689.108 | M33: =CPUE!J31 -> 13.625 | N33: =Effort!L31 -> CLOSED | O33: =Harvest!L31 -> CLOSED | P33: =CPUE!L31 -> CLOSED | Q33: CLOSED | R33: CLOSED | S33: CLOSED | T33: =SUM(E33,H33,K33) -> 1400.3653 | U33: =SUM(F33,I33,L33) -> 18975.474
A34: 45259 | B34: Wed | C34: -0.8 | D34: 0.82777778 | E34: =Effort!F32 -> CLOSED | F34: =Harvest!F32 -> CLOSED | G34: =+CPUE!F32 -> CLOSED | H34: =Effort!H32 -> CLOSED | I34: =Harvest!H32 -> CLOSED | J34: =CPUE!H32 -> CLOSED | K34: =Effort!J32 -> CLOSED | L34: =Harvest!J32 -> CLOSED | M34: =CPUE!J32 -> CLOSED | N34: =Effort!L32 -> 177.37227 | O34: =Harvest!L32 -> 2601.46 | P34: =CPUE!L32 -> 14.666667 | Q34: CLOSED | R34: CLOSED | S34: CLOSED | T34: =SUM(E34,H34,N34) -> 177.37227 | U34: =SUM(F34,I34,O34) -> 2601.46
A35: Tide Series Totals | E35: =SUM(E29:E34) -> 11502.169 | F35: =SUM(F29:F34) -> 158110.08 | G35: =+F35/E35 -> 13.74611 | H35: =SUM(H29:H34) -> 9012.4862 | I35: =SUM(I29:I34) -> 121502.31 | J35: =+I35/H35 -> 13.481553 | K35: =SUM(K29:K34) -> 7815.3525 | L35: =SUM(L29:L34) -> 112401.59 | M35: =+L35/K35 -> 14.382152 | N35: =SUM(N29:N34) -> 5037.9372 | O35: =SUM(O29:O34) -> 73389.657 | P35: =+O35/N35 -> 14.567402 | T35: =SUM(T29:T34) -> 33367.945 | U35: =SUM(U29:U34) -> 465403.64 | W35: =SUM(H35,K35,N35,Q35,E35) -> 33367.945 | X35: =SUM(R35,O35,L35,I35,F35) -> 465403.64
A36: 45273 | B36: Wed | C36: -1.3 | D36: 0.78819444 | E36: =Effort!F34 -> 681.94317 | F36: =Harvest!F34 -> 8865.2612 | G36: =+CPUE!F34 -> 13 | H36: =Effort!H34 -> 621.46891 | I36: =Harvest!H34 -> 6081.5171 | J36: =CPUE!H34 -> 9.7857143 | K36: =Effort!J34 -> CLOSED | L36: =Harvest!J34 -> CLOSED | M36: =CPUE!J34 -> CLOSED | N36: =Effort!L34 -> 608.8808 | O36: =Harvest!L34 -> 8118.4107 | P36: =CPUE!L34 -> 13.333333 | Q36: CLOSED | R36: CLOSED | S36: CLOSED | T36: =SUM(E36,H36,N36) -> 1912.2929 | U36: =SUM(F36,I36,O36) -> 23065.189
A37: 45274 | B37: Thu | C37: -1.3 | D37: 0.81875 | E37: =Effort!F35 -> 523.17371 | F37: =Harvest!F35 -> 5284.0545 | G37: =+CPUE!F35 -> 10.1 | H37: =Effort!H35 -> 476.77902 | I37: =Harvest!H35 -> 4767.7902 | J37: =CPUE!H35 -> 10 | K37: =Effort!J35 -> 652.6164 | L37: =Harvest!J35 -> 9305.8264 | M37: =CPUE!J35 -> 14.259259 | N37: =Effort!L35 -> CLOSED | O37: =Harvest!L35 -> CLOSED | P37: =CPUE!L35 -> CLOSED | Q37: CLOSED | R37: CLOSED | S37: CLOSED | T37: =SUM(E37,H37,K37) -> 1652.5691 | U37: =SUM(F37,I37,L37) -> 19357.671
A38: 45275 | B38: Fri | C38: -1.2 | D38: 0.85069444 | E38: =Effort!F36 -> 788.81045 | F38: =Harvest!F36 -> 10017.893 | G38: =+CPUE!F36 -> 12.7 | H38: =Effort!H36 -> 718.85927 | I38: =Harvest!H36 -> 7867.5154 | J38: =CPUE!H36 -> 10.944444 | K38: =Effort!J36 -> CLOSED | L38: =Harvest!J36 -> CLOSED | M38: =CPUE!J36 -> CLOSED | N38: =Effort!L36 -> 952.08349 | O38: =Harvest!L36 -> 8854.3764 | P38: =CPUE!L36 -> 9.3 | Q38: CLOSED | R38: CLOSED | S38: CLOSED | T38: =SUM(E38,H38,N38) -> 2459.7532 | U38: =SUM(F38,I38,O38) -> 26739.785
A39: 45276 | B39: Sat | C39: -0.8 | D39: 0.88333333 | E39: =Effort!F37 -> 1374.5196 | F39: =Harvest!F37 -> 19930.535 | G39: =+CPUE!F37 -> 14.5 | H39: =Effort!H37 -> 493.13961 | I39: =Harvest!H37 -> 6562.5502 | J39: =CPUE!H37 -> 13.307692 | K39: =Effort!J37 -> 1714.6008 | L39: =Harvest!J37 -> 25719.012 | M39: =CPUE!J37 -> 15 | N39: =Effort!L37 -> CLOSED | O39: =Harvest!L37 -> CLOSED | P39: =CPUE!L37 -> CLOSED | Q39: CLOSED | R39: CLOSED | S39: CLOSED | T39: =SUM(E39,H39,K39) -> 3582.26 | U39: =SUM(F39,I39,L39) -> 52212.096
A40: 45277 | B40: Sun | C40: -0.3 | D40: 0.91736111 | E40: =Effort!F38 -> 146.41669 | F40: =Harvest!F38 -> 2196.2504 | G40: =+CPUE!F38 -> 15 | H40: =Effort!H38 -> 133.43256 | I40: =Harvest!H38 -> 2001.4884 | J40: =CPUE!H38 -> 15 | K40: =Effort!J38 -> CLOSED | L40: =Harvest!J38 -> CLOSED | M40: =CPUE!J38 -> CLOSED | N40: =Effort!L38 -> 176.72296 | O40: =Harvest!L38 -> 2618.7129 | P40: =CPUE!L38 -> 14.818182 | Q40: CLOSED | R40: CLOSED | S40: CLOSED | T40: =SUM(E40,H40,N40) -> 456.57221 | U40: =SUM(F40,I40,O40) -> 6816.4518
...

Sheet Summary Table Public
A1: 2023-2024 State (non-Tribal) Recreational Razor Clam Effort, Harvest and CPUE totals.
E2: LONG BEACH | H2: TWIN HARBORS | K2: COPALIS | N2: MOCROCKS | Q2: KALALOCH | T2: DAILY TOTALS | W2: CROSS | X2: CHECK
A3: DATE | B3: DAY | C3: TIDE | D3: TIME | E3: Effort | F3: Harvest | G3: CPUE | H3: Effort | I3: Harvest | J3: CPUE | K3: Effort | L3: Harvest | M3: CPUE | N3: Effort | O3: Harvest | P3: CPUE | Q3: Effort | R3: Harvest | S3: CPUE | T3: Effort | U3: Harvest
A4: 44826 | B4: Thu | C4: 0.4 | D4: 0.21041667 | E4: =Effort!F2 -> 2988.737 | F4: =Harvest!F2 -> 44532.182 | G4: =+CPUE!F2 -> 14.9 | H4: =Effort!H2 -> 2761.0168 | I4: =Harvest!H2 -> 41038.749 | J4: =CPUE!H2 -> 14.863636 | K4: =Effort!J2 -> CLOSED | L4: =Harvest!J2 -> CLOSED | M4: =CPUE!J2 -> CLOSED | N4: =Effort!L2 -> CLOSED | O4: =Harvest!L2 -> CLOSED | P4: =CPUE!L2 -> CLOSED | Q4: CLOSED | R4: CLOSED | S4: CLOSED | T4: =SUM(E4,H4,N4) -> 5749.7538 | U4: =SUM(F4,I4,O4) -> 85570.931
A5: 44827 | B5: Fri | C5: 0.1 | D5: 0.23680556 | E5: =Effort!F3 -> 4253.9595 | F5: =Harvest!F3 -> 63383.997 | G5: =+CPUE!F3 -> 14.9 | H5: =Effort!H3 -> 3929.8384 | I5: =Harvest!H3 -> 58456.346 | J5: =CPUE!H3 -> 14.875 | K5: =Effort!J3 -> 4894.3943 | L5: =Harvest!J3 -> 72769.484 | M5: =CPUE!J3 -> 14.867925 | N5: =Effort!L3 -> CLOSED | O5: =Harvest!L3 -> CLOSED | P5: =CPUE!L3 -> CLOSED | Q5: CLOSED | R5: CLOSED | S5: CLOSED | T5: =SUM(E5,H5,K5) -> 13078.192 | U5: =SUM(F5,I5,L5) -> 194609.83
A6: 44828 | B6: Sat | C6: 0 | D6: 0.26041667 | E6: =Effort!F4 -> 2134.3397 | F6: =Harvest!F4 -> 30947.925 | G6: =+CPUE!F4 -> 14.5 | H6: =Effort!H4 -> 1971.7183 | I6: =Harvest!H4 -> 28720.123 | J6: =CPUE!H4 -> 14.566038 | K6: =Effort!J4 -> CLOSED | L6: =Harvest!J4 -> CLOSED | M6: =CPUE!J4 -> CLOSED | N6: =Effort!L4 -> CLOSED | O6: =Harvest!L4 -> CLOSED | P6: =CPUE!L4 -> CLOSED | Q6: CLOSED | R6: CLOSED | S6: CLOSED | T6: =SUM(E6,H6,N6) -> 4106.058 | U6: =SUM(F6,I6,O6) -> 59668.048
A7: 44829 | B7: Sun | C7: 0.1 | D7: 0.28333333 | E7: =Effort!F5 -> 187.63354 | F7: =Harvest!F5 -> 394.03044 | G7: =+CPUE!F5 -> 2.1 | H7: =Effort!H5 -> 454.59801 | I7: =Harvest!H5 -> 2272.9901 | J7: =CPUE!H5 -> 5 | K7: =Effort!J5 -> 566.17644 | L7: =Harvest!J5 -> 4367.6468 | M7: =CPUE!J5 -> 7.7142857 | N7: =Effort!L5 -> CLOSED | O7: =Harvest!L5 -> CLOSED | P7: =CPUE!L5 -> CLOSED | Q7: CLOSED | R7: CLOSED | S7: CLOSED | T7: =SUM(E7,H7,K7) -> 1208.408 | U7: =SUM(F7,I7,L7) -> 7034.6673
A8: Tide Series Totals | E8: =SUM(E4:E7) -> 9564.6698 | F8: =SUM(F4:F7) -> 139258.13 | G8: =+F8/E8 -> 14.559639 | H8: =SUM(H4:H7) -> 9117.1715 | I8: =SUM(I4:I7) -> 130488.21 | J8: =+I8/H8 -> 14.312357 | K8: =SUM(K4:K7) -> 5460.5707 | L8: =SUM(L4:L7) -> 77137.131 | M8: =+L8/K8 -> 14.126203 | N8: =SUM(N4:N7) -> 0 | O8: 0 | P8: 0 | T8: =SUM(T4:T7) -> 24142.412 | U8: =SUM(U4:U7) -> 346883.47 | W8: =SUM(H8,K8,N8,Q8,E8) -> 24142.412 | X8: =SUM(R8,O8,L8,I8,F8) -> 346883.47
A9: 45213 | B9: Sat | C9: 0.2 | D9: 0.80347222 | E9: =Effort!F7 -> 2046.3486 | F9: =Harvest!F7 -> 13563.49 | G9: =+CPUE!F7 -> 6.6281423 | H9: =Effort!H7 -> 2003.9637 | I9: =Harvest!H7 -> 21041.619 | J9: =CPUE!H7 -> 10.5 | K9: =Effort!J7 -> CLOSED | L9: =Harvest!J7 -> CLOSED | M9: =CPUE!J7 -> CLOSED | N9: =Effort!L7 -> 1765.4039 | O9: =Harvest!L7 -> 22050.241 | P9: =CPUE!L7 -> 12.490196 | Q9: CLOSED | R9: CLOSED | S9: CLOSED | T9: =SUM(E9,H9,N9) -> 5815.7163 | U9: =SUM(F9,I9,O9) -> 56655.35
A10: 45214 | B10: Sun | C10: -0.1 | D10: 0.82777778 | E10: =Effort!F8 -> 1317.8028 | F10: =Harvest!F8 -> 6589.0142 | G10: =+CPUE!F8 -> 5 | H10: =Effort!H8 -> 858.22633 | I10: =Harvest!H8 -> 3269.4336 | J10: =CPUE!H8 -> 3.8095238 | K10: =Effort!J8 -> 1476.9908 | L10: =Harvest!J8 -> 13056.599 | M10: =CPUE!J8 -> 8.84 | N10: =Effort!L8 -> CLOSED | O10: =Harvest!L8 -> CLOSED | P10: =CPUE!L8 -> CLOSED | Q10: CLOSED | R10: CLOSED | S10: CLOSED | T10: =SUM(E10,H10,K10) -> 3653.02 | U10: =SUM(F10,I10,L10) -> 22915.047
A11: 45215 | B11: Mon | C11: -0.3 | D11: 0.85277778 | E11: =Effort!F9 -> 330.12069 | F11: =Harvest!F9 -> 4291.569 | G11: =+CPUE!F9 -> 13 | H11: =Effort!H9 -> 323.28309 | I11: =Harvest!H9 -> 4238.6005 | J11: =CPUE!H9 -> 13.111111 | K11: =Effort!J9 -> CLOSED | L11: =Harvest!J9 -> CLOSED | M11: =CPUE!J9 -> CLOSED | N11: =Effort!L9 -> 284.79819 | O11: =Harvest!L9 -> 3987.1746 | P11: =CPUE!L9 -> 14 | Q11: CLOSED | R11: CLOSED | S11: CLOSED | T11: =SUM(E11,H11,N11) -> 938.20197 | U11: =SUM(F11,I11,O11) -> 12517.344
A12: 45216 | B12: Tue | C12: -0.4 | D12: 0.87916667 | E12: =Effort!F10 -> 351.83276 | F12: =Harvest!F10 -> 4433.0927 | G12: =+CPUE!F10 -> 12.6 | H12: =Effort!H10 -> 229.13301 | I12: =Harvest!H10 -> 2978.7292 | J12: =CPUE!H10 -> 13 | K12: =Effort!J10 -> 394.33346 | L12: =Harvest!J10 -> 5366.364 | M12: =CPUE!J10 -> 13.608696 | N12: =Effort!L10 -> CLOSED | O12: =Harvest!L10 -> CLOSED | P12: =CPUE!L10 -> CLOSED | Q12: CLOSED | R12: CLOSED | S12: CLOSED | T12: =SUM(E12,H12,K12) -> 975.29923 | U12: =SUM(F12,I12,L12) -> 12778.186
A13: 45217 | B13: Wed | C13: -0.3 | D13: 0.90902778 | E13: =Effort!F11 -> CLOSED | F13: =Harvest!F11 -> CLOSED | G13: =+CPUE!F11 -> CLOSED | H13: =Effort!H11 -> CLOSED | I13: =Harvest!H11 -> CLOSED | J13: =CPUE!H11 -> CLOSED | K13: =Effort!J11 -> CLOSED | L13: =Harvest!J11 -> CLOSED | M13: =CPUE!J11 -> CLOSED | N13: =Effort!L11 -> 407.60235 | O13: =Harvest!L11 -> 3764.3276 | P13: =CPUE!L11 -> 9.2352941 | Q13: CLOSED | R13: CLOSED | S13: CLOSED | T13: =SUM(E13,H13,N13) -> 407.60235 | U13: =SUM(F13,I13,O13) -> 3764.3276
A14: Tide Series Totals | E14: =SUM(E9:E13) -> 4046.1049 | F14: =SUM(F9:F13) -> 28877.166 | G14: =+F14/E14 -> 7.1370284 | H14: =SUM(H9:H13) -> 3414.6062 | I14: =SUM(I9:I13) -> 31528.382 | J14: =+I14/H14 -> 9.2333877 | K14: =SUM(K9:K13) -> 1871.3243 | L14: =SUM(L9:L13) -> 18422.963 | M14: =+L14/K14 -> 9.8448799 | N14: =SUM(N9:N13) -> 2457.8045 | O14: =SUM(O9:O13) -> 29801.744 | P14: =+O14/N14 -> 12.125352 | T14: =SUM(T9:T13) -> 11789.84 | U14: =SUM(U9:U13) -> 108630.25 | W14: =SUM(H14,K14,N14,Q14,E14) -> 11789.84 | X14: =SUM(R14,O14,L14,I14,F14) -> 108630.25
A15: 45226 | B15: Fri | C15: -0.4 | D15: 0.7625 | E15: =Effort!F13 -> 2370.4 | F15: =Harvest!F13 -> 34747.418 | G15: =+CPUE!F13 -> 14.658884 | H15: =Effort!H13 -> 2389.6521 | I15: =Harvest!H13 -> 35127.886 | J15: =CPUE!H13 -> 14.7 | K15: =Effort!J13 -> CLOSED | L15: =Harvest!J13 -> CLOSED | M15: =CPUE!J13 -> CLOSED | N15: =Effort!L13 -> 1854.5433 | O15: =Harvest!L13 -> 27143.77 | P15: =CPUE!L13 -> 14.636364 | Q15: CLOSED | R15: CLOSED | S15: CLOSED | T15: =SUM(E15,H15,N15) -> 6614.5954 | U15: =SUM(F15,I15,O15) -> 97019.074
A16: 45227 | B16: Sat | C16: -1 | D16: 0.79375 | E16: =Effort!F14 -> 4305.8988 | F16: =Harvest!F14 -> 64588.483 | G16: =+CPUE!F14 -> 15 | H16: =Effort!H14 -> 4132.6286 | I16: =Harvest!H14 -> 61989.429 | J16: =CPUE!H14 -> 15 | K16: =Effort!J14 -> 5902.8031 | L16: =Harvest!J14 -> 88542.046 | M16: =CPUE!J14 -> 15 | N16: =Effort!L14 -> CLOSED | O16: =Harvest!L14 -> CLOSED | P16: =CPUE!L14 -> CLOSED | Q16: CLOSED | R16: CLOSED | S16: CLOSED | T16: =SUM(E16,H16,K16) -> 14341.331 | U16: =SUM(F16,I16,L16) -> 215119.96
A17: 45228 | B17: Sun | C17: -1.3 | D17: 0.82361111 | E17: =Effort!F15 -> 1984.5659 | F17: =Harvest!F15 -> 28776.205 | G17: =+CPUE!F15 -> 14.5 | H17: =Effort!H15 -> 2000.6843 | I17: =Harvest!H15 -> 29622.072 | J17: =CPUE!H15 -> 14.80597 | K17: =Effort!J15 -> CLOSED | L17: =Harvest!J15 -> CLOSED | M17: =CPUE!J15 -> CLOSED | N17: =Effort!L15 -> 1552.6761 | O17: =Harvest!L15 -> 22419.128 | P17: =CPUE!L15 -> 14.439024 | Q17: CLOSED | R17: CLOSED | S17: CLOSED | T17: =SUM(E17,H17,N17) -> 5537.9263 | U17: =SUM(F17,I17,O17) -> 80817.405
A18: 45229 | B18: Mon | C18: -1.3 | D18: 0.85347222 | E18: =Effort!F16 -> 801.51879 | F18: =Harvest!F16 -> 11622.022 | G18: =+CPUE!F16 -> 14.5 | H18: =Effort!H16 -> 769.26551 | I18: =Harvest!H16 -> 11137.627 | J18: =CPUE!H16 -> 14.478261 | K18: =Effort!J16 -> 1098.7735 | L18: =Harvest!J16 -> 16481.603 | M18: =CPUE!J16 -> 15 | N18: =Effort!L16 -> CLOSED | O18: =Harvest!L16 -> CLOSED | P18: =CPUE!L16 -> CLOSED | Q18: CLOSED | R18: CLOSED | S18: CLOSED | T18: =SUM(E18,H18,K18) -> 2669.5578 | U18: =SUM(F18,I18,L18) -> 39241.252
A19: 45230 | B19: Tue | C19: -1 | D19: 0.88333333 | E19: =Effort!F17 -> CLOSED | F19: =Harvest!F17 -> CLOSED | G19: =+CPUE!F17 -> CLOSED | H19: =Effort!H17 -> CLOSED | I19: =Harvest!H17 -> CLOSED | J19: =CPUE!H17 -> CLOSED | K19: =Effort!J17 -> CLOSED | L19: =Harvest!J17 -> CLOSED | M19: =CPUE!J17 -> CLOSED | N19: =Effort!L17 -> 239.97715 | O19: =Harvest!L17 -> 3479.6687 | P19: =CPUE!L17 -> 14.5 | Q19: CLOSED | R19: CLOSED | S19: CLOSED | T19: =SUM(E19,H19,N19) -> 239.97715 | U19: =SUM(F19,I19,O19) -> 3479.6687
A20: Tide Series Totals | E20: =SUM(E15:E19) -> 9462.3835 | F20: =SUM(F15:F19) -> 139734.13 | G20: =+F20/E20 -> 14.767329 | H20: =SUM(H15:H19) -> 9292.2305 | I20: =SUM(I15:I19) -> 137877.01 | J20: =+I20/H20 -> 14.837881 | K20: =SUM(K15:K19) -> 7001.5766 | L20: =SUM(L15:L19) -> 105023.65 | M20: =+L20/K20 -> 15 | N20: =SUM(N15:N19) -> 3647.1965 | O20: =SUM(O15:O19) -> 53042.567 | P20: =+O20/N20 -> 14.54338 | T20: =SUM(T15:T19) -> 29403.387 | U20: =SUM(U15:U19) -> 435677.36 | W20: =SUM(H20,K20,N20,Q20,E20) -> 29403.387 | X20: =SUM(R20,O20,L20,I20,F20) -> 435677.36
A21: 45242 | B21: Sun | C21: -0.3 | D21: 0.74513889 | E21: =Effort!F19 -> CLOSED | F21: =Harvest!F19 -> CLOSED | G21: =+CPUE!F19 -> CLOSED | H21: =Effort!H19 -> CLOSED | I21: =Harvest!H19 -> CLOSED | J21: =CPUE!H19 -> CLOSED | K21: =Effort!J19 -> CLOSED | L21: =Harvest!J19 -> CLOSED | M21: =CPUE!J19 -> CLOSED | N21: =Effort!L19 -> 1064.3542 | O21: =Harvest!L19 -> 7083.4606 | P21: =CPUE!L19 -> 6.6551724 | Q21: CLOSED | R21: CLOSED | S21: CLOSED | T21: =SUM(E21,H21,N21) -> 1064.3542 | U21: =SUM(F21,I21,O21) -> 7083.4606
A22: 45243 | B22: Mon | C22: -0.7 | D22: 0.77083333 | E22: =Effort!F20 -> 952.83861 | F22: =Harvest!F20 -> 9528.3861 | G22: =+CPUE!F20 -> 10 | H22: =Effort!H20 -> 857.32218 | I22: =Harvest!H20 -> 8573.2218 | J22: =CPUE!H20 -> 10 | K22: =Effort!J20 -> 941.25878 | L22: =Harvest!J20 -> 9347.6734 | M22: =CPUE!J20 -> 9.9310345 | N22: =Effort!L20 -> CLOSED | O22: =Harvest!L20 -> CLOSED | P22: =CPUE!L20 -> CLOSED | Q22: CLOSED | R22: CLOSED | S22: CLOSED | T22: =SUM(E22,H22,K22) -> 2751.4196 | U22: =SUM(F22,I22,L22) -> 27449.281
A23: 45244 | B23: Tue | C23: -0.9 | D23: 0.79791667 | E23: =Effort!F21 -> 690.09621 | F23: =Harvest!F21 -> 7177.0006 | G23: =+CPUE!F21 -> 10.4 | H23: =Effort!H21 -> 620.91815 | I23: =Harvest!H21 -> 7304.9194 | J23: =CPUE!H21 -> 11.764706 | K23: =Effort!J21 -> CLOSED | L23: =Harvest!J21 -> CLOSED | M23: =CPUE!J21 -> CLOSED | N23: =Effort!L21 -> 550.00002 | O23: =Harvest!L21 -> 8066.667 | P23: =CPUE!L21 -> 14.666667 | Q23: CLOSED | R23: CLOSED | S23: CLOSED | T23: =SUM(E23,H23,N23) -> 1861.0144 | U23: =SUM(F23,I23,O23) -> 22548.587
A24: 45245 | B24: Wed | C24: -0.9 | D24: 0.82708333 | E24: =Effort!F22 -> 262.10549 | F24: =Harvest!F22 -> 3852.9506 | G24: =+CPUE!F22 -> 14.7 | H24: =Effort!H22 -> 235.83096 | I24: =Harvest!H22 -> 3419.549 | J24: =CPUE!H22 -> 14.5 | K24: =Effort!J22 -> 467.41025 | L24: =Harvest!J22 -> 6721.8045 | M24: =CPUE!J22 -> 14.380952 | N24: =Effort!L22 -> CLOSED | O24: =Harvest!L22 -> CLOSED | P24: =CPUE!L22 -> CLOSED | Q24: CLOSED | R24: CLOSED | S24: CLOSED | T24: =SUM(E24,H24,K24) -> 965.3467 | U24: =SUM(F24,I24,L24) -> 13994.304
A25: 45246 | B25: Thu | C25: -0.8 | D25: 0.85902778 | E25: =Effort!F23 -> 420.2155 | F25: =Harvest!F23 -> 5462.8014 | G25: =+CPUE!F23 -> 13 | H25: =Effort!H23 -> 378.09138 | I25: =Harvest!H23 -> 4915.188 | J25: =CPUE!H23 -> 13 | K25: =Effort!J23 -> CLOSED | L25: =Harvest!J23 -> CLOSED | M25: =CPUE!J23 -> CLOSED | N25: =Effort!L23 -> 334.9077 | O25: =Harvest!L23 -> 4395.6636 | P25: =CPUE!L23 -> 13.125 | Q25: CLOSED | R25: CLOSED | S25: CLOSED | T25: =SUM(E25,H25,N25) -> 1133.2146 | U25: =SUM(F25,I25,O25) -> 14773.653
A26: 45247 | B26: Fri | C26: -0.5 | D26: 0.89375 | E26: =Effort!F24 -> CLOSED | F26: =Harvest!F24 -> CLOSED | G26: =+CPUE!F24 -> CLOSED | H26: =Effort!H24 -> CLOSED | I26: =Harvest!H24 -> CLOSED | J26: =CPUE!H24 -> CLOSED | K26: =Effort!J24 -> 982.94927 | L26: =Harvest!J24 -> 14744.239 | M26: =CPUE!J24 -> 15 | N26: =Effort!L24 -> CLOSED | O26: =Harvest!L24 -> CLOSED | P26: =CPUE!L24 -> CLOSED | Q26: CLOSED | R26: CLOSED | S26: CLOSED | T26: =SUM(E26,H26,K26) -> 982.94927 | U26: =SUM(F26,I26,L26) -> 14744.239
A27: 45248 | B27: Sat | C27: -0.1 | D27: 0.93194444 | E27: =Effort!F25 -> CLOSED | F27: =Harvest!F25 -> CLOSED | G27: =+CPUE!F25 -> CLOSED | H27: =Effort!H25 -> CLOSED | I27: =Harvest!H25 -> CLOSED | J27: =CPUE!H25 -> CLOSED | K27: =Effort!J25 -> CLOSED | L27: =Harvest!J25 -> CLOSED | M27: =CPUE!J25 -> CLOSED | N27: =Effort!L25 -> 445.65462 | O27: =Harvest!L25 -> 1406.5974 | P27: =CPUE!L25 -> 3.15625 | Q27: CLOSED | R27: CLOSED | S27: CLOSED | T27: =SUM(E27,H27,N27) -> 445.65462 | U27: =SUM(F27,I27,O27) -> 1406.5974
A28: Tide Series Totals | E28: =SUM(E21:E27) -> 2325.2558 | F28: =SUM(F21:F27) -> 26021.139 | G28: =+F28/E28 -> 11.190656 | H28: =SUM(H21:H27) -> 2092.1627 | I28: =SUM(I21:I27) -> 24212.878 | J28: =+I28/H28 -> 11.573134 | K28: =SUM(K21:K27) -> 2391.6183 | L28: =SUM(L21:L27) -> 30813.717 | M28: =+L28/K28 -> 12.884045 | N28: =SUM(N21:N27) -> 2394.9165 | O28: =SUM(O21:O27) -> 20952.389 | P28: =+O28/N28 -> 8.7486926 | T28: =SUM(T21:T27) -> 9203.9533 | U28: =SUM(U21:U27) -> 102000.12 | W28: =SUM(H28,K28,N28,Q28,E28) -> 9203.9533 | X28: =SUM(R28,O28,L28,I28,F28) -> 102000.12
A29: 45254 | B29: Fri | C29: 0 | D29: 0.67916667 | E29: =Effort!F27 -> 3934.085 | F29: =Harvest!F27 -> 55077.19 | G29: =+CPUE!F27 -> 14 | H29: =Effort!H27 -> 3163.2227 | I29: =Harvest!H27 -> 44285.118 | J29: =CPUE!H27 -> 14 | K29: =Effort!J27 -> 4790.8518 | L29: =Harvest!J27 -> 68481 | M29: =CPUE!J27 -> 14.294118 | N29: =Effort!L27 -> CLOSED | O29: =Harvest!L27 -> CLOSED | P29: =CPUE!L27 -> CLOSED | Q29: CLOSED | R29: CLOSED | S29: CLOSED | T29: =SUM(E29,H29,K29) -> 11888.16 | U29: =SUM(F29,I29,L29) -> 167843.31
A30: 45255 | B30: Sat | C30: -0.7 | D30: 0.71180556 | E30: =Effort!F28 -> 4216.9935 | F30: =Harvest!F28 -> 56929.412 | G30: =+CPUE!F28 -> 13.5 | H30: =Effort!H28 -> 3195.0476 | I30: =Harvest!H28 -> 41807.537 | J30: =CPUE!H28 -> 13.085106 | K30: =Effort!J28 -> CLOSED | L30: =Harvest!J28 -> CLOSED | M30: =CPUE!J28 -> CLOSED | N30: =Effort!L28 -> 4031.2922 | O30: =Harvest!L28 -> 59593.015 | P30: =CPUE!L28 -> 14.782609 | Q30: CLOSED | R30: CLOSED | S30: CLOSED | T30: =SUM(E30,H30,N30) -> 11443.333 | U30: =SUM(F30,I30,O30) -> 158329.96
A31: 45256 | B31: Sun | C31: -1.2 | D31: 0.74236111 | E31: =Effort!F29 -> 2020.2019 | F31: =Harvest!F29 -> 27269.007 | G31: =+CPUE!F29 -> 13.498159 | H31: =Effort!H29 -> 1624.3545 | I31: =Harvest!H29 -> 21177.905 | J31: =CPUE!H29 -> 13.037736 | K31: =Effort!J29 -> 2460.1624 | L31: =Harvest!J29 -> 36231.483 | M31: =CPUE!J29 -> 14.727273 | N31: =Effort!L29 -> CLOSED | O31: =Harvest!L29 -> CLOSED | P31: =CPUE!L29 -> CLOSED | Q31: CLOSED | R31: CLOSED | S31: CLOSED | T31: =SUM(E31,H31,K31) -> 6104.7188 | U31: =SUM(F31,I31,L31) -> 84678.395
A32: 45257 | B32: Mon | C32: -1.3 | D32: 0.77152778 | E32: =Effort!F30 -> 867.4731 | F32: =Harvest!F30 -> 12578.36 | G32: =+CPUE!F30 -> 14.5 | H32: =Effort!H30 -> 657.24973 | I32: =Harvest!H30 -> 9201.4962 | J32: =CPUE!H30 -> 14 | K32: =Effort!J30 -> CLOSED | L32: =Harvest!J30 -> CLOSED | M32: =CPUE!J30 -> CLOSED | N32: =Effort!L30 -> 829.2727 | O32: =Harvest!L30 -> 11195.181 | P32: =CPUE!L30 -> 13.5 | Q32: CLOSED | R32: CLOSED | S32: CLOSED | T32: =SUM(E32,H32,N32) -> 2353.9955 | U32: =SUM(F32,I32,O32) -> 32975.038
