Workbook

Sheet Harvest
A1: Date | B1: Day | C1: Time | D1: Tide | E1: Longbeach | G1: Twin Harbors | I1: Copalis | K1: Mocrocks | M1: Kalaloch | O1: Daily Totals | P1: Cross Checks
A2: 45568 | B2: Thu | C2: 0.81805556 | D2: 0.33 | F2: =9458.6425924703+9383.4837248434 -> 18842.126 | H2: 23619.442 | J2: CLOSED | L2: 12300.137 | N2: CLOSED | O2: =SUM(F2:N2) -> 54761.705
A3: 45569 | B3: Fri | C3: 0.84027778 | D3: 0.13 | F3: =CPUE!F3*Effort!F3 -> 14049.114 | G3: * | H3: =CPUE!H3*Effort!H3 -> 13725.854 | J3: 25230.491 | L3: CLOSED | N3: CLOSED | O3: =SUM(F3:N3) -> 53005.459
A4: 45570 | B4: Sat | C4: 0.86388889 | D4: 0.07 | E4: * | F4: =CPUE!F4*Effort!F4 -> 22703.455 | H4: 22242.003 | J4: 36243.88 | L4: CLOSED | N4: CLOSED | O4: =SUM(F4:N4) -> 81189.338
A5: 45571 | B5: Sun | C5: 0.88888889 | D5: 0.13 | E5: * | F5: =CPUE!F5*Effort!F5 -> 7087.6567 | G5: * | H5: =CPUE!H5*Effort!H5 -> 7860.0945 | J5: CLOSED | L5: 4043.9007 | N5: CLOSED | O5: =SUM(F5:N5) -> 18991.652
A6: 45572 | B6: Mon | C6: 0.91805556 | D6: 0.3 | F6: =CPUE!F6*Effort!F6 -> 1352.8776 | H6: 2381.8491 | J6: CLOSED | L6: 2649.959 | N6: CLOSED | O6: =SUM(F6:N6) -> 6384.6857 | P6: =SUM(O2:O6) -> 214332.84
A8: 45580 | B8: Tue | C8: 0.72986111 | D8: 0.53 | E8: * | F8: =CPUE!F8*Effort!F8 -> 20236.664 | H8: 15785.039 | J8: CLOSED | L8: 15184.078 | N8: CLOSED | O8: =SUM(F8:N8) -> 51205.782
A9: 45581 | B9: Wed | C9: 0.7625 | D9: -0.48 | F9: =5563.80840522268+9209.35689520854 -> 14773.165 | G9: * | H9: =CPUE!H9*Effort!H9 -> 17850.372 | J9: 23405.395 | L9: CLOSED | N9: CLOSED | O9: =SUM(F9:N9) -> 56028.932
A10: 45582 | B10: Thu | C10: 0.79375 | D10: -1.25 | E10: * | F10: =CPUE!F10*Effort!F10 -> 23661.084 | H10: 24968.308 | J10: 32203.363 | L10: CLOSED | N10: CLOSED | O10: =SUM(F10:N10) -> 80832.755
A11: 45583 | B11: Fri | C11: 0.82569444 | D11: -1.66 | F11: =CPUE!F11*Effort!F11 -> 4340.9791 | H11: 4854.0696 | J11: CLOSED | L11: 2593.8394 | N11: CLOSED | O11: =SUM(F11:N11) -> 11788.888
A12: 45584 | B12: Sat | C12: 0.85763889 | D12: -1.69 | F12: =CPUE!F12*Effort!F12 -> 26102.081 | G12: * | H12: =CPUE!H12*Effort!H12 -> 15623.708 | J12: CLOSED | L12: 13531.58 | N12: CLOSED | O12: =SUM(F12:N12) -> 55257.37
A13: 45585 | B13: Sun | C13: 0.89166667 | D13: -1.36 | E13: * | F13: =CPUE!F13*Effort!F13 -> 5774.0504 | G13: * | H13: =CPUE!H13*Effort!H13 -> 5961.6221 | J13: 7816.8747 | L13: CLOSED | N13: CLOSED | O13: =SUM(F13:N13) -> 19552.547
A14: 45586 | B14: Mon | C14: 0.92777778 | D14: -0.78 | E14: * | F14: =CPUE!F14*Effort!F14 -> 3103.8626 | G14: * | H14: =CPUE!H14*Effort!H14 -> 3204.6926 | J14: 4201.9906 | L14: CLOSED | N14: CLOSED | O14: =SUM(F14:N14) -> 10510.546 | P14: =SUM(O8:O14) -> 285176.82
A16: 45597 | B16: Fri | C16: 0.80208333 | D16: -0.19 | F16: =3682.56655017586+5740.6829602981 -> 9423.2495 | G16: * | H16: =CPUE!H16*Effort!H16 -> 14022.177 | J16: CLOSED | L16: 12543.914 | N16: CLOSED | O16: =SUM(F16:N16) -> 35989.34
A17: 45598 | B17: Sat | C17: 0.82430556 | D17: -0.36 | E17: * | F17: =CPUE!F17*Effort!F17 -> 11016.06 | H17: 15635.399 | J17: CLOSED | L17: 10012.84 | N17: CLOSED | O17: =SUM(F17:N17) -> 36664.3
A18: 45599 | B18: Sun | C18: 0.80694444 | D18: -0.39 | F18: =CPUE!F18*Effort!F18 -> 1353.9635 | H18: 829.48311 | J18: 2243.7703 | L18: CLOSED | N18: CLOSED | O18: =SUM(F18:N18) -> 4427.2169
A19: 45600 | B19: Mon | C19: 0.83333333 | D19: -0.29 | E19: * | F19: =CPUE!F19*Effort!F19 -> 459.98829 | G19: * | H19: =CPUE!H19*Effort!H19 -> 796.40301 | J19: 967.56363 | L19: CLOSED | N19: CLOSED | O19: =SUM(F19:N19) -> 2223.9549
A20: 45601 | B20: Tue | C20: 0.8625 | D20: -0.09 | E20: * | F20: =CPUE!F20*Effort!F20 -> 1033.0321 | H20: 1531.25 | J20: CLOSED | L20: 1098.5194 | N20: CLOSED | O20: =SUM(F20:N20) -> 3662.8016 | P20: =SUM(O16:O20) -> 82967.613
A22: 45609 | B22: Wed | C22: 0.67708333 | D22: -0.17 | F22: =CPUE!F22*Effort!F22 -> 5464.6668 | G22: * | H22: =CPUE!H22*Effort!H22 -> 7697.177 | J22: CLOSED | L22: 7022.8558 | N22: CLOSED | O22: =SUM(F22:N22) -> 20184.7
A23: 45610 | B23: Thu | C23: 0.70972222 | D23: -1.09 | F23: =CPUE!F23*Effort!F23 -> 12973.174 | H23: 16148.674 | J23: CLOSED | L23: 16343.925 | N23: CLOSED | O23: =SUM(F23:N23) -> 45465.773
A24: 45611 | B24: Fri | C24: 0.74166667 | D24: -1.68 | F24: =CPUE!F24*Effort!F24 -> 31750.074 | H24: 31178.814 | J24: 55348.623 | L24: CLOSED | N24: CLOSED | O24: =SUM(F24:N24) -> 118277.51
A25: 45612 | B25: Sat | C25: 0.77291667 | D25: -1.9 | E25: * | F25: =CPUE!F25*Effort!F25 -> 1715.336 | H25: 761.5385 | J25: 6275.2664 | L25: CLOSED | N25: CLOSED | O25: =SUM(F25:N25) -> 8752.1409
A26: 45613 | B26: Sun | C26: 0.80486111 | D26: -1.75 | E26: * | F26: =CPUE!F26*Effort!F26 -> 5284.5613 | G26: * | H26: =CPUE!H26*Effort!H26 -> 6391.6625 | J26: CLOSED | L26: 5487.0924 | N26: CLOSED | O26: =SUM(F26:N26) -> 17163.316
A27: 45614 | B27: Mon | C27: 0.83680556 | D27: -1.31 | F27: =CPUE!F27*Effort!F27 -> 738.53681 | H27: 101.67577 | J27: CLOSED | L27: 1301.6887 | N27: CLOSED | O27: =SUM(F27:N27) -> 2141.9013
A28: 45615 | B28: Tue | C28: 0.87083333 | D28: -0.69 | E28: * | F28: =CPUE!F28*Effort!F28 -> 323.29238 | H28: 335.13095 | I28: * | J28: =CPUE!J28*Effort!J28 -> 595.21221 | L28: CLOSED | N28: CLOSED | O28: =SUM(F28:N28) -> 1253.6356 | P28: =SUM(O22:O28) -> 213238.98
A30: 45625 | B30: Fri | C30: 0.72222222 | D30: -0.07 | E30: * | F30: =CPUE!F30*Effort!F30 -> 27885.267 | H30: 33406.058 | J30: CLOSED | L30: 29980.222 | N30: CLOSED | O30: =SUM(F30:N30) -> 91271.547
A31: 45626 | B31: Sat | C31: 0.74583333 | D31: -0.41 | F31: =CPUE!F31*Effort!F31 -> 25123.385 | G31: * | H31: =CPUE!H31*Effort!H31 -> 28540.891 | J31: CLOSED | L31: 22228.296 | N31: CLOSED | O31: =SUM(F31:N31) -> 75892.572
A32: 45627 | B32: Sun | C32: 0.77083333 | D32: -0.62 | E32: * | F32: =CPUE!F32*Effort!F32 -> 8503.1103 | H32: 10854.881 | J32: 12260.652 | L32: CLOSED | N32: CLOSED | O32: =SUM(F32:N32) -> 31618.644
A33: 45628 | B33: Mon | C33: 0.79583333 | D33: -0.69 | F33: =CPUE!F33*Effort!F33 -> 4187.4099 | G33: * | H33: =CPUE!H33*Effort!H33 -> 4977.7146 | J33: 5327.6279 | L33: CLOSED | N33: CLOSED | O33: =SUM(F33:N33) -> 14492.752
A34: 45629 | B34: Tue | C34: 0.82361111 | D34: -0.63 | F34: =CPUE!F34*Effort!F34 -> 2138.9742 | G34: * | H34: =CPUE!H34*Effort!H34 -> 3273.118 | J34: CLOSED | L34: 2853.4392 | N34: CLOSED | O34: =SUM(F34:N34) -> 8265.5314
A35: 45630 | B35: Wed | C35: 0.85277778 | D35: -0.46 | E35: * | F35: =CPUE!F35*Effort!F35 -> 589.15247 | H35: 1977.0289 | J35: CLOSED | L35: 673.665 | N35: CLOSED | O35: =SUM(F35:N35) -> 3239.8464
A36: 45631 | B36: Thu | C36: 0.88402778 | D36: -0.17 | E36: * | F36: =CPUE!F36*Effort!F36 -> 132.04351 | G36: * | H36: =CPUE!H36*Effort!H36 -> 168.1763 | J36: 213.55744 | L36: CLOSED | N36: CLOSED | O36: =SUM(F36:N36) -> 513.77725 | P36: =SUM(O30:O36) -> 225294.67
A38: 45638 | B38: Thu | C38: 0.66666667 | D38: -0.48 | F38: =2392.46385294185+4677.68239522183 -> 7070.1462 | H38: 11589.709 | J38: 13885.047 | L38: CLOSED | N38: CLOSED | O38: =SUM(F38:N38) -> 32544.902
A39: 45639 | B39: Fri | C39: 0.70138889 | D39: -1.17 | F39: =CPUE!F39*Effort!F39 -> 8521.2579 | G39: * | H39: =CPUE!H39*Effort!H39 -> 7864.6738 | J39: CLOSED | L39: 6384.2995 | N39: CLOSED | O39: =SUM(F39:N39) -> 22770.231
A40: 45640 | B40: Sat | C40: 0.73333333 | D40: -1.55 | E40: * | F40: =CPUE!F40*Effort!F40 -> 8535.6757 | G40: * | H40: =CPUE!H40*Effort!H40 -> 8382.1714 | J40: CLOSED | L40: 7616.5328 | N40: CLOSED | O40: =SUM(F40:N40) -> 24534.38
A41: 45641 | B41: Sun | C41: 0.76458333 | D41: -1.63 | E41: * | F41: =CPUE!F41*Effort!F41 -> 2220.4657 | H41: 2077.9986 | J41: 9629.5708 | L41: CLOSED | N41: CLOSED | O41: =SUM(F41:N41) -> 13928.035
A42: 45642 | B42: Mon | C42: 0.79513889 | D42: -1.45 | F42: =CPUE!F42*Effort!F42 -> 1550.1137 | G42: * | H42: =CPUE!H42*Effort!H42 -> 3365.6544 | J42: 3802.7003 | L42: CLOSED | N42: CLOSED | O42: =SUM(F42:N42) -> 8718.4684
A43: 45643 | B43: Tue | C43: 0.825 | D43: -1.05 | E43: * | F43: =CPUE!F43*Effort!F43 -> 61.098791 | H43: =CPUE!H43*Effort!H43 -> 60 | J43: CLOSED | L43: =CPUE!L43*Effort!L43 -> 56.582421 | N43: CLOSED | O43: =SUM(F43:N43) -> 177.68121
A44: 45644 | B44: Wed | C44: 0.85486111 | D44: -0.51 | E44: * | F44: =CPUE!F44*Effort!F44 -> 875.94256 | H44: 1310.212 | J44: CLOSED | K44: * | L44: =CPUE!L44*Effort!L44 -> 1271.9234 | N44: CLOSED | O44: =SUM(F44:N44) -> 3458.0779 | P44: =SUM(O38:O44) -> 106131.78
A46: 45654 | B46: Sat | C46: 0.70694444 | D46: -0.03 | F46: =CPUE!F46*Effort!F46 -> 3232.7007 | H46: 1903.4875 | J46: 5992.8916 | L46: CLOSED | N46: CLOSED | O46: =SUM(F46:N46) -> 11129.08
...

Sheet Effort
A1: Date | B1: Day | C1: Time | D1: Tide | E1: Longbeach | G1: Twin Harbors | I1: Copalis | K1: Mocrocks | M1: Kalaloch | O1: Daily Totals | P1: Cross Checks
A2: 45568 | B2: Thu | C2: 0.81805556 | D2: 0.33 | F2: =697.411435389515+779.925919986984 -> 1477.3374 | H2: 1638.3428 | J2: CLOSED | L2: 842.90279 | N2: CLOSED | O2: =SUM(F2:N2) -> 3958.5829
A3: 45569 | B3: Fri | C3: 0.84027778 | D3: 0.13 | F3: =(697.411435389515/779.925919986984*494.460203298717)+494.460203298717 -> 936.60758 | G3: * | H3: =H4/J4*J3 -> 915.05695 | J3: 1689.802 | L3: CLOSED | N3: CLOSED | O3: =SUM(F3:N3) -> 3541.4665
A4: 45570 | B4: Sat | C4: 0.86388889 | D4: 0.07 | E4: * | F4: =F3/J3*J4 -> 1621.6754 | H4: 1584.3619 | J4: 2925.7827 | L4: CLOSED | N4: CLOSED | O4: =SUM(F4:N4) -> 6131.82
A5: 45571 | B5: Sun | C5: 0.88888889 | D5: 0.13 | E5: * | F5: =F2/L2*L5 -> 472.51044 | G5: * | H5: =H2/L2*L5 -> 524.0063 | J5: CLOSED | L5: 269.59338 | N5: CLOSED | O5: =SUM(F5:N5) -> 1266.1101
A6: 45572 | B6: Mon | C6: 0.91805556 | D6: 0.3 | F6: =(697.411435389515/779.925919986984*47.6146862435801)+47.6146862435801 -> 90.191841 | H6: 158.78994 | J6: CLOSED | L6: 176.66393 | N6: CLOSED | O6: =SUM(F6:N6) -> 425.64571 | P6: =SUM(O2:O6) -> 15323.625
A8: 45580 | B8: Tue | C8: 0.72986111 | D8: 0.53 | E8: * | F8: =F11/L11*L8 -> 1395.632 | H8: 1116.866 | J8: CLOSED | L8: 1020.3701 | N8: CLOSED | O8: =SUM(F8:N8) -> 3532.8681
A9: 45581 | B9: Wed | C9: 0.7625 | D9: -0.48 | F9: =492.628869212425+659.953914314618 -> 1152.5828 | G9: * | H9: =H10/J10*J9 -> 1190.0248 | J9: 1560.3596 | L9: CLOSED | N9: CLOSED | O9: =SUM(F9:N9) -> 3902.9672
A10: 45582 | B10: Thu | C10: 0.79375 | D10: -1.25 | E10: * | F10: =F9/J9*J10 -> 1631.7989 | H10: 1684.8084 | J10: 2209.1196 | L10: CLOSED | N10: CLOSED | O10: =SUM(F10:N10) -> 5525.7269
A11: 45583 | B11: Fri | C11: 0.82569444 | D11: -1.66 | F11: =(492.628869212425/659.953914314618*710.168046938604)+710.168046938604 -> 1240.2797 | H11: 954.45189 | J11: CLOSED | L11: 906.78938 | N11: CLOSED | O11: =SUM(F11:N11) -> 3101.521
A12: 45584 | B12: Sat | C12: 0.85763889 | D12: -1.69 | F12: =(492.628869212425/659.953914314618+1154.58611555622)+1154.58611555622 -> 2309.9187 | G12: * | H12: =H11/L11*L12 -> 1735.9676 | J12: CLOSED | L12: 1649.2785 | N12: CLOSED | O12: =SUM(F12:N12) -> 5695.1647
A13: 45585 | B13: Sun | C13: 0.89166667 | D13: -1.36 | E13: * | F13: =F9/J9*J13 -> 384.93669 | G13: * | H13: =H10/J10*J13 -> 397.44148 | J13: 521.12498 | L13: CLOSED | N13: CLOSED | O13: =SUM(F13:N13) -> 1303.5031
A14: 45586 | B14: Mon | C14: 0.92777778 | D14: -0.78 | E14: * | F14: =F9/J9*J14 -> 206.92418 | G14: * | H14: =H10/J10*J14 -> 213.64617 | J14: 280.13271 | L14: CLOSED | N14: CLOSED | O14: =SUM(F14:N14) -> 700.70305 | P14: =SUM(O8:O14) -> 23762.454
A16: 45597 | B16: Fri | C16: 0.80208333 | D16: -0.19 | F16: =323.468683461393+445.014182968845 -> 768.48287 | G16: * | H16: =H17/L17*L16 -> 1078.629 | J16: CLOSED | L16: 947.32683 | N16: CLOSED | O16: =SUM(F16:N16) -> 2794.4387
A17: 45598 | B17: Sat | C17: 0.82430556 | D17: -0.36 | E17: * | F17: =F16/L16*L17 -> 847.38926 | H17: 1189.3806 | J17: CLOSED | L17: 1044.5966 | N17: CLOSED | O17: =SUM(F17:N17) -> 3081.3664
A18: 45599 | B18: Sun | C18: 0.80694444 | D18: -0.39 | F18: =(323.468683461393/445.014182968845*150.779839771337)+150.779839771337 -> 260.3776 | H18: 450.80604 | J18: 547.69196 | L18: CLOSED | N18: CLOSED | O18: =SUM(F18:N18) -> 1258.8756
A19: 45600 | B19: Mon | C19: 0.83333333 | D19: -0.29 | E19: * | F19: =F18/J18*J19 -> 51.10981 | G19: * | H19: =H18/J18*J19 -> 88.489223 | J19: 107.50707 | L19: CLOSED | N19: CLOSED | O19: =SUM(F19:N19) -> 247.1061
A20: 45601 | B20: Tue | C20: 0.8625 | D20: -0.09 | E20: * | F20: =F16/L16*L20 -> 79.464009 | H20: 109.375 | J20: CLOSED | L20: 97.957146 | N20: CLOSED | O20: =SUM(F20:N20) -> 286.79616 | P20: =SUM(O16:O20) -> 7668.583
A22: 45609 | B22: Wed | C22: 0.67708333 | D22: -0.17 | F22: =(323.468683461393/445.014182968845*261.527871734743)+261.527871734743 -> 451.62536 | G22: * | H22: =H23/L23*L22 -> 592.09054 | J22: CLOSED | L22: 514.83341 | N22: CLOSED | O22: =SUM(F22:N22) -> 1558.5493
A23: 45610 | B23: Thu | C23: 0.70972222 | D23: -1.09 | F23: =(323.468683461393/445.014182968845*626.043729540562)+626.043729540562 -> 1081.0979 | H23: 1307.5849 | J23: CLOSED | L23: 1136.9687 | N23: CLOSED | O23: =SUM(F23:N23) -> 3525.6515
A24: 45611 | B24: Fri | C24: 0.74166667 | D24: -1.68 | F24: =(323.468683461393/445.014182968845*1225.72527027144)+1225.72527027144 -> 2116.6716 | H24: 2175.2661 | J24: 3896.9949 | L24: CLOSED | N24: CLOSED | O24: =SUM(F24:N24) -> 8188.9326
A25: 45612 | B25: Sat | C25: 0.77291667 | D25: -1.9 | E25: * | F25: =F24/H24*H25 -> 686.13439 | H25: 705.12824 | J25: 2469.621 | L25: CLOSED | N25: CLOSED | O25: =SUM(F25:N25) -> 3860.8836
A26: 45613 | B26: Sun | C26: 0.80486111 | D26: -1.75 | E26: * | F26: =F23/L23*L26 -> 503.29155 | G26: * | H26: =H23/L23*L26 -> 608.72976 | J26: CLOSED | L26: 529.30152 | N26: CLOSED | O26: =SUM(F26:N26) -> 1641.3228
A27: 45614 | B27: Mon | C27: 0.83680556 | D27: -1.31 | F27: =(323.468683461393/445.014182968845*44.5492682811015)+44.5492682811015 -> 76.930917 | H27: 135.5677 | J27: CLOSED | L27: 167.95984 | N27: CLOSED | O27: =SUM(F27:N27) -> 380.45845
A28: 45615 | B28: Tue | C28: 0.87083333 | D28: -0.69 | E28: * | F28: =F24/H24*H28 -> 28.112381 | H28: 28.890599 | I28: * | J28: =J24/H24*H28 -> 51.757584 | L28: CLOSED | N28: CLOSED | O28: =SUM(F28:N28) -> 108.76056 | P28: =SUM(O22:O28) -> 19264.559
A30: 45625 | B30: Fri | C30: 0.72222222 | D30: -0.07 | E30: * | F30: =F31/L31*L30 -> 1991.8048 | H30: 2295.0727 | J30: CLOSED | L30: 2134.1853 | N30: CLOSED | O30: =SUM(F30:N30) -> 6421.0628
A31: 45626 | B31: Sat | C31: 0.74583333 | D31: -0.41 | F31: =(323.468683461393/445.014182968845*1024.5413126656)+1024.5413126656 -> 1769.2525 | G31: * | H31: =H30/L30*L31 -> 2038.635 | J31: CLOSED | L31: 1895.7243 | N31: CLOSED | O31: =SUM(F31:N31) -> 5703.6118
A32: 45627 | B32: Sun | C32: 0.77083333 | D32: -0.62 | E32: * | F32: =F33/J33*J32 -> 607.36502 | H32: 773.56627 | J32: 982.30745 | L32: CLOSED | N32: CLOSED | O32: =SUM(F32:N32) -> 2363.2387
A33: 45628 | B33: Mon | C33: 0.79583333 | D33: -0.69 | F33: =(323.468683461393/445.014182968845*161.656763288622)+161.656763288622 -> 279.16066 | G33: * | H33: =H32/J32*J33 -> 355.55105 | J33: 451.49389 | L33: CLOSED | N33: CLOSED | O33: =SUM(F33:N33) -> 1086.2056
A34: 45629 | B34: Tue | C34: 0.82361111 | D34: -0.63 | F34: =(323.468683461393/445.014182968845*82.5760223285124)+82.5760223285124 -> 142.59828 | G34: * | H34: =H30/L30*L34 -> 233.79414 | J34: CLOSED | L34: 217.40489 | N34: CLOSED | O34: =SUM(F34:N34) -> 593.79732
A35: 45630 | B35: Wed | C35: 0.85277778 | D35: -0.46 | E35: * | F35: =F34/L34*L35 -> 49.09604 | H35: 153.76891 | J35: CLOSED | L35: 74.851666 | N35: CLOSED | O35: =SUM(F35:N35) -> 277.71662
A36: 45631 | B36: Thu | C36: 0.88402778 | D36: -0.17 | E36: * | F36: =F33/J33*J36 -> 26.408701 | G36: * | H36: =H32/J32*J36 -> 33.63526 | J36: 42.711489 | L36: CLOSED | N36: CLOSED | O36: =SUM(F36:N36) -> 102.75545 | P36: =SUM(O30:O36) -> 16548.388
A38: 45638 | B38: Thu | C38: 0.66666667 | D38: -0.48 | F38: =177.219544662359+375.215165392126 -> 552.43471 | H38: 850.62084 | J38: 961.07792 | L38: CLOSED | N38: CLOSED | O38: =SUM(F38:N38) -> 2364.1335
A39: 45639 | B39: Fri | C39: 0.70138889 | D39: -1.17 | F39: =(177.219544662359/375.215165392126*435.162530366129)+435.162530366129 -> 640.69608 | G39: * | H39: =H43/L43*L39 -> 629.1739 | J39: CLOSED | L39: 593.33638 | N39: CLOSED | O39: =SUM(F39:N39) -> 1863.2064
A40: 45640 | B40: Sat | C40: 0.73333333 | D40: -1.55 | E40: * | F40: =F39/L39*L40 -> 1422.6126 | G40: * | H40: =H43/L43*L40 -> 1397.0286 | J40: CLOSED | L40: 1317.4543 | N40: CLOSED | O40: =SUM(F40:N40) -> 4137.0955
A41: 45641 | B41: Sun | C41: 0.76458333 | D41: -1.63 | E41: * | F41: =F42/J42*J41 -> 370.07761 | H41: 438.47677 | J41: 871.55056 | L41: CLOSED | N41: CLOSED | O41: =SUM(F41:N41) -> 1680.1049
A42: 45642 | B42: Mon | C42: 0.79513889 | D42: -1.45 | F42: =(177.219544662359/375.215165392126*109.670986193076)+109.670986193076 -> 161.47018 | G42: * | H42: =H38/J38*J42 -> 336.56544 | J42: 380.27003 | L42: CLOSED | N42: CLOSED | O42: =SUM(F42:N42) -> 878.30564
A43: 45643 | B43: Tue | C43: 0.825 | D43: -1.05 | E43: * | F43: =F39/L39*L43 -> 30.549396 | H43: 30 | J43: CLOSED | L43: 28.291211 | N43: CLOSED | O43: =SUM(F43:N43) -> 88.840606
A44: 45644 | B44: Wed | C44: 0.85486111 | D44: -0.51 | E44: * | F44: =F38/H38*H44 -> 87.594256 | H44: 134.87476 | J44: CLOSED | K44: * | L44: =L43/H43*H44 -> 127.19234 | N44: CLOSED | O44: =SUM(F44:N44) -> 349.66136 | P44: =SUM(O38:O44) -> 11361.348
A46: 45654 | B46: Sat | C46: 0.70694444 | D46: -0.03 | F46: =(574.673086575028/511.6289603577*543.765915741497)+543.765915741497 -> 1154.5359 | H46: 1237.2669 | J46: 2133.0631 | L46: CLOSED | N46: CLOSED | O46: =SUM(F46:N46) -> 4524.866
...

Sheet CPUE
A1: Date | B1: Day | C1: Time | D1: Tide | E1: Longbeach | G1: Twin Harbors | I1: Copalis | K1: Mocrocks | M1: Kalaloch | O1: Daily Totals
A2: 45568 | B2: Thu | C2: 0.81805556 | D2: 0.33 | F2: =+Harvest!F2/Effort!F2 -> 12.754112 | H2: =+Harvest!H2/Effort!H2 -> 14.416667 | J2: CLOSED | L2: =+Harvest!L2/Effort!L2 -> 14.592593 | N2: CLOSED | O2: =+Harvest!O2/Effort!O2 -> 13.833664
A3: 45569 | B3: Fri | C3: 0.84027778 | D3: 0.13 | F3: 15 | G3: * | H3: 15 | J3: =+Harvest!J3/Effort!J3 -> 14.931034 | L3: CLOSED | N3: CLOSED | O3: =+Harvest!O3/Effort!O3 -> 14.967093
A4: 45570 | B4: Sat | C4: 0.86388889 | D4: 0.07 | E4: * | F4: 14 | H4: =+Harvest!H4/Effort!H4 -> 14.038462 | J4: =+Harvest!J4/Effort!J4 -> 12.387755 | L4: CLOSED | N4: CLOSED | O4: =+Harvest!O4/Effort!O4 -> 13.240659
A5: 45571 | B5: Sun | C5: 0.88888889 | D5: 0.13 | E5: * | F5: 15 | G5: * | H5: 15 | J5: CLOSED | L5: =+Harvest!L5/Effort!L5 -> 15 | N5: CLOSED | O5: =+Harvest!O5/Effort!O5 -> 15
A6: 45572 | B6: Mon | C6: 0.91805556 | D6: 0.3 | F6: 15 | H6: =+Harvest!H6/Effort!H6 -> 15 | J6: CLOSED | L6: =+Harvest!L6/Effort!L6 -> 15 | N6: CLOSED | O6: =+Harvest!O6/Effort!O6 -> 15
A8: 45580 | B8: Tue | C8: 0.72986111 | D8: 0.53 | E8: * | F8: 14.5 | H8: =+Harvest!H8/Effort!H8 -> 14.133333 | J8: CLOSED | L8: =+Harvest!L8/Effort!L8 -> 14.880952 | N8: CLOSED | O8: =+Harvest!O8/Effort!O8 -> 14.494111
A9: 45581 | B9: Wed | C9: 0.7625 | D9: -0.48 | F9: =+Harvest!F9/Effort!F9 -> 12.817444 | G9: * | H9: 15 | J9: =+Harvest!J9/Effort!J9 -> 15 | L9: CLOSED | N9: CLOSED | O9: =+Harvest!O9/Effort!O9 -> 14.355471
A10: 45582 | B10: Thu | C10: 0.79375 | D10: -1.25 | E10: * | F10: 14.5 | H10: =+Harvest!H10/Effort!H10 -> 14.819672 | J10: =+Harvest!J10/Effort!J10 -> 14.577465 | L10: CLOSED | N10: CLOSED | O10: =+Harvest!O10/Effort!O10 -> 14.628438
A11: 45583 | B11: Fri | C11: 0.82569444 | D11: -1.66 | F11: 3.5 | H11: =+Harvest!H11/Effort!H11 -> 5.0857143 | J11: CLOSED | L11: =+Harvest!L11/Effort!L11 -> 2.8604651 | N11: CLOSED | O11: =+Harvest!O11/Effort!O11 -> 3.8010022
A12: 45584 | B12: Sat | C12: 0.85763889 | D12: -1.69 | F12: 11.3 | G12: * | H12: 9 | J12: CLOSED | L12: =+Harvest!L12/Effort!L12 -> 8.2045455 | N12: CLOSED | O12: =+Harvest!O12/Effort!O12 -> 9.7025059
A13: 45585 | B13: Sun | C13: 0.89166667 | D13: -1.36 | E13: * | F13: 15 | G13: * | H13: 15 | J13: =+Harvest!J13/Effort!J13 -> 15 | L13: CLOSED | N13: CLOSED | O13: =+Harvest!O13/Effort!O13 -> 15
A14: 45586 | B14: Mon | C14: 0.92777778 | D14: -0.78 | E14: * | F14: 15 | G14: * | H14: 15 | J14: =+Harvest!J14/Effort!J14 -> 15 | L14: CLOSED | N14: CLOSED | O14: =+Harvest!O14/Effort!O14 -> 15
A16: 45597 | B16: Fri | C16: 0.80208333 | D16: -0.19 | F16: =+Harvest!F16/Effort!F16 -> 12.262147 | G16: * | H16: 13 | J16: CLOSED | L16: =+Harvest!L16/Effort!L16 -> 13.241379 | N16: CLOSED | O16: =+Harvest!O16/Effort!O16 -> 12.878916
A17: 45598 | B17: Sat | C17: 0.82430556 | D17: -0.36 | E17: * | F17: 13 | H17: =+Harvest!H17/Effort!H17 -> 13.145833 | J17: CLOSED | L17: =+Harvest!L17/Effort!L17 -> 9.5853659 | N17: CLOSED | O17: =+Harvest!O17/Effort!O17 -> 11.898715
A18: 45599 | B18: Sun | C18: 0.80694444 | D18: -0.39 | F18: 5.2 | H18: =+Harvest!H18/Effort!H18 -> 1.84 | J18: =+Harvest!J18/Effort!J18 -> 4.0967742 | L18: CLOSED | N18: CLOSED | O18: =+Harvest!O18/Effort!O18 -> 3.5168025
A19: 45600 | B19: Mon | C19: 0.83333333 | D19: -0.29 | E19: * | F19: 9 | G19: * | H19: 9 | J19: =+Harvest!J19/Effort!J19 -> 9 | L19: CLOSED | N19: CLOSED | O19: =+Harvest!O19/Effort!O19 -> 9
A20: 45601 | B20: Tue | C20: 0.8625 | D20: -0.09 | E20: * | F20: 13 | H20: =+Harvest!H20/Effort!H20 -> 14 | J20: CLOSED | L20: =+Harvest!L20/Effort!L20 -> 11.214286 | N20: CLOSED | O20: =+Harvest!O20/Effort!O20 -> 12.771446
A22: 45609 | B22: Wed | C22: 0.67708333 | D22: -0.17 | F22: 12.1 | G22: * | H22: 13 | J22: CLOSED | L22: =+Harvest!L22/Effort!L22 -> 13.641026 | N22: CLOSED | O22: =+Harvest!O22/Effort!O22 -> 12.950953
A23: 45610 | B23: Thu | C23: 0.70972222 | D23: -1.09 | F23: 12 | H23: =+Harvest!H23/Effort!H23 -> 12.35 | J23: CLOSED | L23: =+Harvest!L23/Effort!L23 -> 14.375 | N23: CLOSED | O23: =+Harvest!O23/Effort!O23 -> 12.895708
A24: 45611 | B24: Fri | C24: 0.74166667 | D24: -1.68 | F24: 15 | H24: =+Harvest!H24/Effort!H24 -> 14.333333 | J24: =+Harvest!J24/Effort!J24 -> 14.202899 | L24: CLOSED | N24: CLOSED | O24: =+Harvest!O24/Effort!O24 -> 14.443581
A25: 45612 | B25: Sat | C25: 0.77291667 | D25: -1.9 | E25: * | F25: 2.5 | H25: =+Harvest!H25/Effort!H25 -> 1.08 | J25: =+Harvest!J25/Effort!J25 -> 2.5409836 | L25: CLOSED | N25: CLOSED | O25: =+Harvest!O25/Effort!O25 -> 2.2668751
A26: 45613 | B26: Sun | C26: 0.80486111 | D26: -1.75 | E26: * | F26: 10.5 | G26: * | H26: 10.5 | J26: CLOSED | L26: =+Harvest!L26/Effort!L26 -> 10.366667 | N26: CLOSED | O26: =+Harvest!O26/Effort!O26 -> 10.457002
A27: 45614 | B27: Mon | C27: 0.83680556 | D27: -1.31 | F27: 9.6 | H27: 8 | J27: CLOSED | L27: =+Harvest!L27/Effort!L27 -> 7.75 | N27: CLOSED | O27: =+Harvest!O27/Effort!O27 -> 5.6297904
A28: 45615 | B28: Tue | C28: 0.87083333 | D28: -0.69 | E28: * | F28: 11.5 | H28: =+Harvest!H28/Effort!H28 -> 11.6 | I28: * | J28: 11.5 | L28: CLOSED | N28: CLOSED | O28: =+Harvest!O28/Effort!O28 -> 11.526563
A30: 45625 | B30: Fri | C30: 0.72222222 | D30: -0.07 | E30: * | F30: 14 | H30: =+Harvest!H30/Effort!H30 -> 14.555556 | J30: CLOSED | L30: =+Harvest!L30/Effort!L30 -> 14.047619 | N30: CLOSED | O30: =+Harvest!O30/Effort!O30 -> 14.214399
A31: 45626 | B31: Sat | C31: 0.74583333 | D31: -0.41 | F31: 14.2 | G31: * | H31: 14 | J31: CLOSED | L31: =+Harvest!L31/Effort!L31 -> 11.72549 | N31: CLOSED | O31: =+Harvest!O31/Effort!O31 -> 13.306055
A32: 45627 | B32: Sun | C32: 0.77083333 | D32: -0.62 | E32: * | F32: 14 | H32: =+Harvest!H32/Effort!H32 -> 14.032258 | J32: =+Harvest!J32/Effort!J32 -> 12.481481 | L32: CLOSED | N32: CLOSED | O32: =+Harvest!O32/Effort!O32 -> 13.379369
A33: 45628 | B33: Mon | C33: 0.79583333 | D33: -0.69 | F33: 15 | G33: * | H33: 14 | J33: =+Harvest!J33/Effort!J33 -> 11.8 | L33: CLOSED | N33: CLOSED | O33: =+Harvest!O33/Effort!O33 -> 13.34255
A34: 45629 | B34: Tue | C34: 0.82361111 | D34: -0.63 | F34: 15 | G34: * | H34: 14 | J34: CLOSED | L34: =+Harvest!L34/Effort!L34 -> 13.125 | N34: CLOSED | O34: =+Harvest!O34/Effort!O34 -> 13.919786
A35: 45630 | B35: Wed | C35: 0.85277778 | D35: -0.46 | E35: * | F35: 12 | H35: =+Harvest!H35/Effort!H35 -> 12.857143 | J35: CLOSED | L35: =+Harvest!L35/Effort!L35 -> 9 | N35: CLOSED | O35: =+Harvest!O35/Effort!O35 -> 11.666015
A36: 45631 | B36: Thu | C36: 0.88402778 | D36: -0.17 | E36: * | F36: 5 | G36: * | H36: 5 | J36: =+Harvest!J36/Effort!J36 -> 5 | L36: CLOSED | N36: CLOSED | O36: =+Harvest!O36/Effort!O36 -> 5
A38: 45638 | B38: Thu | C38: 0.66666667 | D38: -0.48 | F38: =+Harvest!F38/Effort!F38 -> 12.798157 | H38: =+Harvest!H38/Effort!H38 -> 13.625 | J38: =+Harvest!J38/Effort!J38 -> 14.447368 | L38: CLOSED | N38: CLOSED | O38: =+Harvest!O38/Effort!O38 -> 13.766102
A39: 45639 | B39: Fri | C39: 0.70138889 | D39: -1.17 | F39: 13.3 | G39: * | H39: 12.5 | J39: CLOSED | L39: =+Harvest!L39/Effort!L39 -> 10.76 | N39: CLOSED | O39: =+Harvest!O39/Effort!O39 -> 12.220993
A40: 45640 | B40: Sat | C40: 0.73333333 | D40: -1.55 | E40: * | F40: 6 | G40: * | H40: 6 | J40: CLOSED | L40: =+Harvest!L40/Effort!L40 -> 5.78125 | N40: CLOSED | O40: =+Harvest!O40/Effort!O40 -> 5.9303393
A41: 45641 | B41: Sun | C41: 0.76458333 | D41: -1.63 | E41: * | F41: 6 | H41: =+Harvest!H41/Effort!H41 -> 4.7391304 | J41: =+Harvest!J41/Effort!J41 -> 11.04878 | L41: CLOSED | N41: CLOSED | O41: =+Harvest!O41/Effort!O41 -> 8.2899793
A42: 45642 | B42: Mon | C42: 0.79513889 | D42: -1.45 | F42: 9.6 | G42: * | H42: 10 | J42: =+Harvest!J42/Effort!J42 -> 10 | L42: CLOSED | N42: CLOSED | O42: =+Harvest!O42/Effort!O42 -> 9.9264629
A43: 45643 | B43: Tue | C43: 0.825 | D43: -1.05 | E43: * | F43: 2 | H43: 2 | J43: CLOSED | L43: 2 | N43: CLOSED | O43: =+Harvest!O43/Effort!O43 -> 2
A44: 45644 | B44: Wed | C44: 0.85486111 | D44: -0.51 | E44: * | F44: 10 | H44: =+Harvest!H44/Effort!H44 -> 9.7142857 | J44: CLOSED | K44: * | L44: 10 | N44: CLOSED | O44: =+Harvest!O44/Effort!O44 -> 9.8897915
A46: 45654 | B46: Sat | C46: 0.70694444 | D46: -0.03 | F46: 2.8 | H46: =+Harvest!H46/Effort!H46 -> 1.5384615 | J46: =+Harvest!J46/Effort!J46 -> 2.8095238 | L46: CLOSED | N46: CLOSED | O46: =+Harvest!O46/Effort!O46 -> 2.459538
...

Sheet Summary Table
A1: 2024-2025 State (non-Tribal) Recreational Razor Clam Effort, Harvest and CPUE totals.
E2: LONG BEACH | H2: TWIN HARBORS | K2: COPALIS | N2: MOCROCKS | Q2: KALALOCH | T2: DAILY TOTALS | W2: CROSS | X2: CHECK
A3: DATE | B3: DAY | C3: TIME | D3: TIDE | E3: Effort | F3: Harvest | G3: CPUE | H3: Effort | I3: Harvest | J3: CPUE | K3: Effort | L3: Harvest | M3: CPUE | N3: Effort | O3: Harvest | P3: CPUE | Q3: Effort | R3: Harvest | S3: CPUE | T3: Effort | U3: Harvest
A4: 45568 | B4: Thu | C4: 0.81805556 | D4: 0.33 | E4: =Effort!F2 -> 1477.3374 | F4: =Harvest!F2 -> 18842.126 | G4: =+CPUE!F2 -> 12.754112 | H4: =Effort!H2 -> 1638.3428 | I4: =Harvest!H2 -> 23619.442 | J4: =CPUE!H2 -> 14.416667 | K4: =Effort!J2 -> CLOSED | L4: =Harvest!J2 -> CLOSED | M4: =CPUE!J2 -> CLOSED | N4: =Effort!L2 -> 842.90279 | O4: =Harvest!L2 -> 12300.137 | P4: =CPUE!L2 -> 14.592593 | Q4: CLOSED | R4: CLOSED | S4: CLOSED | T4: =SUM(E4,H4,K4,N4) -> 3958.5829 | U4: =SUM(F4,I4,L4,O4) -> 54761.705
A5: 45569 | B5: Fri | C5: 0.84027778 | D5: 0.13 | E5: =Effort!F3 -> 936.60758 | F5: =Harvest!F3 -> 14049.114 | G5: =+CPUE!F3 -> 15 | H5: =Effort!H3 -> 915.05695 | I5: =Harvest!H3 -> 13725.854 | J5: =CPUE!H3 -> 15 | K5: =Effort!J3 -> 1689.802 | L5: =Harvest!J3 -> 25230.491 | M5: =CPUE!J3 -> 14.931034 | N5: =Effort!L3 -> CLOSED | O5: =Harvest!L3 -> CLOSED | P5: =CPUE!L3 -> CLOSED | Q5: CLOSED | R5: CLOSED | S5: CLOSED | T5: =SUM(E5,H5,K5,N5) -> 3541.4665 | U5: =SUM(F5,I5,L5,O5) -> 53005.459
A6: 45570 | B6: Sat | C6: 0.86388889 | D6: 0.07 | E6: =Effort!F4 -> 1621.6754 | F6: =Harvest!F4 -> 22703.455 | G6: =+CPUE!F4 -> 14 | H6: =Effort!H4 -> 1584.3619 | I6: =Harvest!H4 -> 22242.003 | J6: =CPUE!H4 -> 14.038462 | K6: =Effort!J4 -> 2925.7827 | L6: =Harvest!J4 -> 36243.88 | M6: =CPUE!J4 -> 12.387755 | N6: =Effort!L4 -> CLOSED | O6: =Harvest!L4 -> CLOSED | P6: =CPUE!L4 -> CLOSED | Q6: CLOSED | R6: CLOSED | S6: CLOSED | T6: =SUM(E6,H6,K6,N6) -> 6131.82 | U6: =SUM(F6,I6,L6,O6) -> 81189.338
A7: 45571 | B7: Sun | C7: 0.88888889 | D7: 0.13 | E7: =Effort!F5 -> 472.51044 | F7: =Harvest!F5 -> 7087.6567 | G7: =+CPUE!F5 -> 15 | H7: =Effort!H5 -> 524.0063 | I7: =Harvest!H5 -> 7860.0945 | J7: =CPUE!H5 -> 15 | K7: =Effort!J5 -> CLOSED | L7: =Harvest!J5 -> CLOSED | M7: =CPUE!J5 -> CLOSED | N7: =Effort!L5 -> 269.59338 | O7: =Harvest!L5 -> 4043.9007 | P7: =CPUE!L5 -> 15 | Q7: CLOSED | R7: CLOSED | S7: CLOSED | T7: =SUM(E7,H7,K7,N7) -> 1266.1101 | U7: =SUM(F7,I7,L7,O7) -> 18991.652
A8: 45572 | B8: Mon | C8: 0.91805556 | D8: 0.3 | E8: =Effort!F6 -> 90.191841 | F8: =Harvest!F6 -> 1352.8776 | G8: =+CPUE!F6 -> 15 | H8: =Effort!H6 -> 158.78994 | I8: =Harvest!H6 -> 2381.8491 | J8: =CPUE!H6 -> 15 | K8: =Effort!J6 -> CLOSED | L8: =Harvest!J6 -> CLOSED | M8: =CPUE!J6 -> CLOSED | N8: =Effort!L6 -> 176.66393 | O8: =Harvest!L6 -> 2649.959 | P8: =CPUE!L6 -> 15 | Q8: CLOSED | R8: CLOSED | S8: CLOSED | T8: =SUM(E8,H8,K8,N8) -> 425.64571 | U8: =SUM(F8,I8,L8,O8) -> 6384.6857
A9: Tide Series Totals | E9: =SUM(E4:E8) -> 4598.3226 | F9: =SUM(F4:F8) -> 64035.23 | G9: =+F9/E9 -> 13.92578 | H9: =SUM(H4:H8) -> 4820.5578 | I9: =SUM(I4:I8) -> 69829.243 | J9: =+I9/H9 -> 14.485718 | K9: =SUM(K4:K8) -> 4615.5847 | L9: =SUM(L4:L8) -> 61474.371 | M9: =+L9/K9 -> 13.31887 | N9: =SUM(N4:N8) -> 1289.1601 | O9: =SUM(O4:O8) -> 18993.997 | P9: =+O9/N9 -> 14.733621 | T9: =SUM(T4:T8) -> 15323.625 | U9: =SUM(U4:U8) -> 214332.84 | W9: =SUM(H9,K9,N9,Q9,E9) -> 15323.625 | X9: =SUM(R9,O9,L9,I9,F9) -> 214332.84
A10: 45580 | B10: Tue | C10: 0.72986111 | D10: 0.53 | E10: =Effort!F8 -> 1395.632 | F10: =Harvest!F8 -> 20236.664 | G10: =+CPUE!F8 -> 14.5 | H10: =Effort!H8 -> 1116.866 | I10: =Harvest!H8 -> 15785.039 | J10: =CPUE!H8 -> 14.133333 | K10: =Effort!J8 -> CLOSED | L10: =Harvest!J8 -> CLOSED | M10: =CPUE!J8 -> CLOSED | N10: =Effort!L8 -> 1020.3701 | O10: =Harvest!L8 -> 15184.078 | P10: =CPUE!L8 -> 14.880952 | Q10: CLOSED | R10: CLOSED | S10: CLOSED | T10: =SUM(E10,H10,K10,N10) -> 3532.8681 | U10: =SUM(F10,I10,L10,O10) -> 51205.782
A11: 45581 | B11: Wed | C11: 0.7625 | D11: -0.48 | E11: =Effort!F9 -> 1152.5828 | F11: =Harvest!F9 -> 14773.165 | G11: =+CPUE!F9 -> 12.817444 | H11: =Effort!H9 -> 1190.0248 | I11: =Harvest!H9 -> 17850.372 | J11: =CPUE!H9 -> 15 | K11: =Effort!J9 -> 1560.3596 | L11: =Harvest!J9 -> 23405.395 | M11: =CPUE!J9 -> 15 | N11: =Effort!L9 -> CLOSED | O11: =Harvest!L9 -> CLOSED | P11: =CPUE!L9 -> CLOSED | Q11: CLOSED | R11: CLOSED | S11: CLOSED | T11: =SUM(E11,H11,K11,N11) -> 3902.9672 | U11: =SUM(F11,I11,L11,O11) -> 56028.932
A12: 45582 | B12: Thu | C12: 0.79375 | D12: -1.25 | E12: =Effort!F10 -> 1631.7989 | F12: =Harvest!F10 -> 23661.084 | G12: =+CPUE!F10 -> 14.5 | H12: =Effort!H10 -> 1684.8084 | I12: =Harvest!H10 -> 24968.308 | J12: =CPUE!H10 -> 14.819672 | K12: =Effort!J10 -> 2209.1196 | L12: =Harvest!J10 -> 32203.363 | M12: =CPUE!J10 -> 14.577465 | N12: =Effort!L10 -> CLOSED | O12: =Harvest!L10 -> CLOSED | P12: =CPUE!L10 -> CLOSED | Q12: CLOSED | R12: CLOSED | S12: CLOSED | T12: =SUM(E12,H12,K12,N12) -> 5525.7269 | U12: =SUM(F12,I12,L12,O12) -> 80832.755
A13: 45583 | B13: Fri | C13: 0.82569444 | D13: -1.66 | E13: =Effort!F11 -> 1240.2797 | F13: =Harvest!F11 -> 4340.9791 | G13: =+CPUE!F11 -> 3.5 | H13: =Effort!H11 -> 954.45189 | I13: =Harvest!H11 -> 4854.0696 | J13: =CPUE!H11 -> 5.0857143 | K13: =Effort!J11 -> CLOSED | L13: =Harvest!J11 -> CLOSED | M13: =CPUE!J11 -> CLOSED | N13: =Effort!L11 -> 906.78938 | O13: =Harvest!L11 -> 2593.8394 | P13: =CPUE!L11 -> 2.8604651 | Q13: CLOSED | R13: CLOSED | S13: CLOSED | T13: =SUM(E13,H13,K13,N13) -> 3101.521 | U13: =SUM(F13,I13,L13,O13) -> 11788.888
A14: 45584 | B14: Sat | C14: 0.85763889 | D14: -1.69 | E14: =Effort!F12 -> 2309.9187 | F14: =Harvest!F12 -> 26102.081 | G14: =+CPUE!F12 -> 11.3 | H14: =Effort!H12 -> 1735.9676 | I14: =Harvest!H12 -> 15623.708 | J14: =CPUE!H12 -> 9 | K14: =Effort!J12 -> CLOSED | L14: =Harvest!J12 -> CLOSED | M14: =CPUE!J12 -> CLOSED | N14: =Effort!L12 -> 1649.2785 | O14: =Harvest!L12 -> 13531.58 | P14: =CPUE!L12 -> 8.2045455 | Q14: CLOSED | R14: CLOSED | S14: CLOSED | T14: =SUM(E14,H14,K14,N14) -> 5695.1647 | U14: =SUM(F14,I14,L14,O14) -> 55257.37
A15: 45585 | B15: Sun | C15: 0.89166667 | D15: -1.36 | E15: =Effort!F13 -> 384.93669 | F15: =Harvest!F13 -> 5774.0504 | G15: =+CPUE!F13 -> 15 | H15: =Effort!H13 -> 397.44148 | I15: =Harvest!H13 -> 5961.6221 | J15: =CPUE!H13 -> 15 | K15: =Effort!J13 -> 521.12498 | L15: =Harvest!J13 -> 7816.8747 | M15: =CPUE!J13 -> 15 | N15: =Effort!L13 -> CLOSED | O15: =Harvest!L13 -> CLOSED | P15: =CPUE!L13 -> CLOSED | Q15: CLOSED | R15: CLOSED | S15: CLOSED | T15: =SUM(E15,H15,K15,N15) -> 1303.5031 | U15: =SUM(F15,I15,L15,O15) -> 19552.547
A16: 45586 | B16: Mon | C16: 0.92777778 | D16: -0.78 | E16: =Effort!F14 -> 206.92418 | F16: =Harvest!F14 -> 3103.8626 | G16: =+CPUE!F14 -> 15 | H16: =Effort!H14 -> 213.64617 | I16: =Harvest!H14 -> 3204.6926 | J16: =CPUE!H14 -> 15 | K16: =Effort!J14 -> 280.13271 | L16: =Harvest!J14 -> 4201.9906 | M16: =CPUE!J14 -> 15 | N16: =Effort!L14 -> CLOSED | O16: =Harvest!L14 -> CLOSED | P16: =CPUE!L14 -> CLOSED | Q16: CLOSED | R16: CLOSED | S16: CLOSED | T16: =SUM(E16,H16,K16,N16) -> 700.70305 | U16: =SUM(F16,I16,L16,O16) -> 10510.546
A17: Tide Series Totals | E17: =SUM(E10:E16) -> 8322.073 | F17: =SUM(F10:F16) -> 97991.887 | G17: =+F17/E17 -> 11.774937 | H17: =SUM(H10:H16) -> 7293.2063 | I17: =SUM(I10:I16) -> 88247.811 | J17: =+I17/H17 -> 12.100002 | K17: =SUM(K10:K16) -> 4570.7369 | L17: =SUM(L10:L16) -> 67627.623 | M17: =+L17/K17 -> 14.795781 | N17: =SUM(N10:N16) -> 3576.4379 | O17: =SUM(O10:O16) -> 31309.498 | P17: =+O17/N17 -> 8.7543804 | T17: =SUM(T10:T16) -> 23762.454 | U17: =SUM(U10:U16) -> 285176.82 | W17: =SUM(H17,K17,N17,Q17,E17) -> 23762.454 | X17: =SUM(R17,O17,L17,I17,F17) -> 285176.82
A18: 45597 | B18: Fri | C18: 0.80208333 | D18: -0.19 | E18: =Effort!F16 -> 768.48287 | F18: =Harvest!F16 -> 9423.2495 | G18: =+CPUE!F16 -> 12.262147 | H18: =Effort!H16 -> 1078.629 | I18: =Harvest!H16 -> 14022.177 | J18: =CPUE!H16 -> 13 | K18: =Effort!J16 -> CLOSED | L18: =Harvest!J16 -> CLOSED | M18: =CPUE!J16 -> CLOSED | N18: =Effort!L16 -> 947.32683 | O18: =Harvest!L16 -> 12543.914 | P18: =CPUE!L16 -> 13.241379 | Q18: CLOSED | R18: CLOSED | S18: CLOSED | T18: =SUM(E18,H18,K18,N18) -> 2794.4387 | U18: =SUM(F18,I18,L18,O18) -> 35989.34
A19: 45598 | B19: Sat | C19: 0.82430556 | D19: -0.36 | E19: =Effort!F17 -> 847.38926 | F19: =Harvest!F17 -> 11016.06 | G19: =+CPUE!F17 -> 13 | H19: =Effort!H17 -> 1189.3806 | I19: =Harvest!H17 -> 15635.399 | J19: =CPUE!H17 -> 13.145833 | K19: =Effort!J17 -> CLOSED | L19: =Harvest!J17 -> CLOSED | M19: =CPUE!J17 -> CLOSED | N19: =Effort!L17 -> 1044.5966 | O19: =Harvest!L17 -> 10012.84 | P19: =CPUE!L17 -> 9.5853659 | Q19: CLOSED | R19: CLOSED | S19: CLOSED | T19: =SUM(E19,H19,K19,N19) -> 3081.3664 | U19: =SUM(F19,I19,L19,O19) -> 36664.3
A20: 45599 | B20: Sun | C20: 0.80694444 | D20: -0.39 | E20: =Effort!F18 -> 260.3776 | F20: =Harvest!F18 -> 1353.9635 | G20: =+CPUE!F18 -> 5.2 | H20: =Effort!H18 -> 450.80604 | I20: =Harvest!H18 -> 829.48311 | J20: =CPUE!H18 -> 1.84 | K20: =Effort!J18 -> 547.69196 | L20: =Harvest!J18 -> 2243.7703 | M20: =CPUE!J18 -> 4.0967742 | N20: =Effort!L18 -> CLOSED | O20: =Harvest!L18 -> CLOSED | P20: =CPUE!L18 -> CLOSED | Q20: CLOSED | R20: CLOSED | S20: CLOSED | T20: =SUM(E20,H20,K20,N20) -> 1258.8756 | U20: =SUM(F20,I20,L20,O20) -> 4427.2169
A21: 45600 | B21: Mon | C21: 0.83333333 | D21: -0.29 | E21: =Effort!F19 -> 51.10981 | F21: =Harvest!F19 -> 459.98829 | G21: =+CPUE!F19 -> 9 | H21: =Effort!H19 -> 88.489223 | I21: =Harvest!H19 -> 796.40301 | J21: =CPUE!H19 -> 9 | K21: =Effort!J19 -> 107.50707 | L21: =Harvest!J19 -> 967.56363 | M21: =CPUE!J19 -> 9 | N21: =Effort!L19 -> CLOSED | O21: =Harvest!L19 -> CLOSED | P21: =CPUE!L19 -> CLOSED | Q21: CLOSED | R21: CLOSED | S21: CLOSED | T21: =SUM(E21,H21,K21,N21) -> 247.1061 | U21: =SUM(F21,I21,L21,O21) -> 2223.9549
A22: 45601 | B22: Tue | C22: 0.8625 | D22: -0.09 | E22: =Effort!F20 -> 79.464009 | F22: =Harvest!F20 -> 1033.0321 | G22: =+CPUE!F20 -> 13 | H22: =Effort!H20 -> 109.375 | I22: =Harvest!H20 -> 1531.25 | J22: =CPUE!H20 -> 14 | K22: =Effort!J20 -> CLOSED | L22: =Harvest!J20 -> CLOSED | M22: =CPUE!J20 -> CLOSED | N22: =Effort!L20 -> 97.957146 | O22: =Harvest!L20 -> 1098.5194 | P22: =CPUE!L20 -> 11.214286 | Q22: CLOSED | R22: CLOSED | S22: CLOSED | T22: =SUM(E22,H22,K22,N22) -> 286.79616 | U22: =SUM(F22,I22,L22,O22) -> 3662.8016
A23: Tide Series Totals | E23: =SUM(E18:E22) -> 2006.8235 | F23: =SUM(F18:F22) -> 23286.294 | G23: =+F23/E23 -> 11.603558 | H23: =SUM(H18:H22) -> 2916.6798 | I23: =SUM(I18:I22) -> 32814.712 | J23: =+I23/H23 -> 11.250708 | K23: =SUM(K18:K22) -> 655.19903 | L23: =SUM(L18:L22) -> 3211.3339 | M23: =+L23/K23 -> 4.9013105 | N23: =SUM(N18:N22) -> 2089.8806 | O23: =SUM(O18:O22) -> 23655.274 | P23: =+O23/N23 -> 11.31896 | T23: =SUM(T18:T22) -> 7668.583 | U23: =SUM(U18:U22) -> 82967.613 | W23: =SUM(H23,K23,N23,Q23,E23) -> 7668.583 | X23: =SUM(R23,O23,L23,I23,F23) -> 82967.613
A24: 45609 | B24: Wed | C24: 0.67708333 | D24: -0.17 | E24: =Effort!F22 -> 451.62536 | F24: =Harvest!F22 -> 5464.6668 | G24: =+CPUE!F22 -> 12.1 | H24: =Effort!H22 -> 592.09054 | I24: =Harvest!H22 -> 7697.177 | J24: =CPUE!H22 -> 13 | K24: =Effort!J22 -> CLOSED | L24: =Harvest!J22 -> CLOSED | M24: =CPUE!J22 -> CLOSED | N24: =Effort!L22 -> 514.83341 | O24: =Harvest!L22 -> 7022.8558 | P24: =CPUE!L22 -> 13.641026 | Q24: CLOSED | R24: CLOSED | S24: CLOSED | T24: =SUM(E24,H24,K24,N24) -> 1558.5493 | U24: =SUM(F24,I24,L24,O24) -> 20184.7
A25: 45610 | B25: Thu | C25: 0.70972222 | D25: -1.09 | E25: =Effort!F23 -> 1081.0979 | F25: =Harvest!F23 -> 12973.174 | G25: =+CPUE!F23 -> 12 | H25: =Effort!H23 -> 1307.5849 | I25: =Harvest!H23 -> 16148.674 | J25: =CPUE!H23 -> 12.35 | K25: =Effort!J23 -> CLOSED | L25: =Harvest!J23 -> CLOSED | M25: =CPUE!J23 -> CLOSED | N25: =Effort!L23 -> 1136.9687 | O25: =Harvest!L23 -> 16343.925 | P25: =CPUE!L23 -> 14.375 | Q25: CLOSED | R25: CLOSED | S25: CLOSED | T25: =SUM(E25,H25,K25,N25) -> 3525.6515 | U25: =SUM(F25,I25,L25,O25) -> 45465.773
A26: 45611 | B26: Fri | C26: 0.74166667 | D26: -1.68 | E26: =Effort!F24 -> 2116.6716 | F26: =Harvest!F24 -> 31750.074 | G26: =+CPUE!F24 -> 15 | H26: =Effort!H24 -> 2175.2661 | I26: =Harvest!H24 -> 31178.814 | J26: =CPUE!H24 -> 14.333333 | K26: =Effort!J24 -> 3896.9949 | L26: =Harvest!J24 -> 55348.623 | M26: =CPUE!J24 -> 14.202899 | N26: =Effort!L24 -> CLOSED | O26: =Harvest!L24 -> CLOSED | P26: =CPUE!L24 -> CLOSED | Q26: CLOSED | R26: CLOSED | S26: CLOSED | T26: =SUM(E26,H26,K26,N26) -> 8188.9326 | U26: =SUM(F26,I26,L26,O26) -> 118277.51
A27: 45612 | B27: Sat | C27: 0.77291667 | D27: -1.9 | E27: =Effort!F25 -> 686.13439 | F27: =Harvest!F25 -> 1715.336 | G27: =+CPUE!F25 -> 2.5 | H27: =Effort!H25 -> 705.12824 | I27: =Harvest!H25 -> 761.5385 | J27: =CPUE!H25 -> 1.08 | K27: =Effort!J25 -> 2469.621 | L27: =Harvest!J25 -> 6275.2664 | M27: =CPUE!J25 -> 2.5409836 | N27: =Effort!L25 -> CLOSED | O27: =Harvest!L25 -> CLOSED | P27: =CPUE!L25 -> CLOSED | Q27: CLOSED | R27: CLOSED | S27: CLOSED | T27: =SUM(E27,H27,K27,N27) -> 3860.8836 | U27: =SUM(F27,I27,L27,O27) -> 8752.1409
A28: 45613 | B28: Sun | C28: 0.80486111 | D28: -1.75 | E28: =Effort!F26 -> 503.29155 | F28: =Harvest!F26 -> 5284.5613 | G28: =+CPUE!F26 -> 10.5 | H28: =Effort!H26 -> 608.72976 | I28: =Harvest!H26 -> 6391.6625 | J28: =CPUE!H26 -> 10.5 | K28: =Effort!J26 -> CLOSED | L28: =Harvest!J26 -> CLOSED | M28: =CPUE!J26 -> CLOSED | N28: =Effort!L26 -> 529.30152 | O28: =Harvest!L26 -> 5487.0924 | P28: =CPUE!L26 -> 10.366667 | Q28: CLOSED | R28: CLOSED | S28: CLOSED | T28: =SUM(E28,H28,K28,N28) -> 1641.3228 | U28: =SUM(F28,I28,L28,O28) -> 17163.316
A29: 45614 | B29: Mon | C29: 0.83680556 | D29: -1.31 | E29: =Effort!F27 -> 76.930917 | F29: =Harvest!F27 -> 738.53681 | G29: =+CPUE!F27 -> 9.6 | H29: =Effort!H27 -> 135.5677 | I29: =Harvest!H27 -> 101.67577 | J29: =CPUE!H27 -> 8 | K29: =Effort!J27 -> CLOSED | L29: =Harvest!J27 -> CLOSED | M29: =CPUE!J27 -> CLOSED | N29: =Effort!L27 -> 167.95984 | O29: =Harvest!L27 -> 1301.6887 | P29: =CPUE!L27 -> 7.75 | Q29: CLOSED | R29: CLOSED | S29: CLOSED | T29: =SUM(E29,H29,K29,N29) -> 380.45845 | U29: =SUM(F29,I29,L29,O29) -> 2141.9013
A30: 45615 | B30: Tue | C30: 0.87083333 | D30: -0.69 | E30: =Effort!F28 -> 28.112381 | F30: =Harvest!F28 -> 323.29238 | G30: =+CPUE!F28 -> 11.5 | H30: =Effort!H28 -> 28.890599 | I30: =Harvest!H28 -> 335.13095 | J30: =CPUE!H28 -> 11.6 | K30: =Effort!J28 -> 51.757584 | L30: =Harvest!J28 -> 595.21221 | M30: =CPUE!J28 -> 11.5 | N30: =Effort!L28 -> CLOSED | O30: =Harvest!L28 -> CLOSED | P30: =CPUE!L28 -> CLOSED | Q30: CLOSED | R30: CLOSED | S30: CLOSED | T30: =SUM(E30,H30,K30,N30) -> 108.76056 | U30: =SUM(F30,I30,L30,O30) -> 1253.6356
A31: Tide Series Totals | E31: =SUM(E24:E30) -> 4943.864 | F31: =SUM(F24:F30) -> 58249.641 | G31: =+F31/E31 -> 11.782209 | H31: =SUM(H24:H30) -> 5553.2579 | I31: =SUM(I24:I30) -> 62614.673 | J31: =+I31/H31 -> 11.275304 | K31: =SUM(K24:K30) -> 6418.3735 | L31: =SUM(L24:L30) -> 62219.102 | M31: =+L31/K31 -> 9.6939049 | N31: =SUM(N24:N30) -> 2349.0635 | O31: =SUM(O24:O30) -> 30155.562 | P31: =+O31/N31 -> 12.83727 | T31: =SUM(T24:T30) -> 19264.559 | U31: =SUM(U24:U30) -> 213238.98 | W31: =SUM(H31,K31,N31,Q31,E31) -> 19264.559 | X31: =SUM(R31,O31,L31,I31,F31) -> 213238.98
A32: 45625 | B32: Fri | C32: 0.72222222 | D32: -0.07 | E32: =Effort!F30 -> 1991.8048 | F32: =Harvest!F30 -> 27885.267 | G32: =+CPUE!F30 -> 14 | H32: =Effort!H30 -> 2295.0727 | I32: =Harvest!H30 -> 33406.058 | J32: =CPUE!H30 -> 14.555556 | K32: =Effort!J30 -> CLOSED | L32: =Harvest!J30 -> CLOSED | M32: =CPUE!J30 -> CLOSED | N32: =Effort!L30 -> 2134.1853 | O32: =Harvest!L30 -> 29980.222 | P32: =CPUE!L30 -> 14.047619 | Q32: CLOSED | R32: CLOSED | S32: CLOSED | T32: =SUM(E32,H32,K32,N32) -> 6421.0628 | U32: =SUM(F32,I32,L32,O32) -> 91271.547
A33: 45626 | B33: Sat | C33: 0.74583333 | D33: -0.41 | E33: =Effort!F31 -> 1769.2525 | F33: =Harvest!F31 -> 25123.385 | G33: =+CPUE!F31 -> 14.2 | H33: =Effort!H31 -> 2038.635 | I33: =Harvest!H31 -> 28540.891 | J33: =CPUE!H31 -> 14 | K33: =Effort!J31 -> CLOSED | L33: =Harvest!J31 -> CLOSED | M33: =CPUE!J31 -> CLOSED | N33: =Effort!L31 -> 1895.7243 | O33: =Harvest!L31 -> 22228.296 | P33: =CPUE!L31 -> 11.72549 | Q33: CLOSED | R33: CLOSED | S33: CLOSED | T33: =SUM(E33,H33,K33,N33) -> 5703.6118 | U33: =SUM(F33,I33,L33,O33) -> 75892.572
A34: 45627 | B34: Sun | C34: 0.77083333 | D34: -0.62 | E34: =Effort!F32 -> 607.36502 | F34: =Harvest!F32 -> 8503.1103 | G34: =+CPUE!F32 -> 14 | H34: =Effort!H32 -> 773.56627 | I34: =Harvest!H32 -> 10854.881 | J34: =CPUE!H32 -> 14.032258 | K34: =Effort!J32 -> 982.30745 | L34: =Harvest!J32 -> 12260.652 | M34: =CPUE!J32 -> 12.481481 | N34: =Effort!L32 -> CLOSED | O34: =Harvest!L32 -> CLOSED | P34: =CPUE!L32 -> CLOSED | Q34: CLOSED | R34: CLOSED | S34: CLOSED | T34: =SUM(E34,H34,K34,N34) -> 2363.2387 | U34: =SUM(F34,I34,L34,O34) -> 31618.644
A35: 45628 | B35: Mon | C35: 0.79583333 | D35: -0.69 | E35: =Effort!F33 -> 279.16066 | F35: =Harvest!F33 -> 4187.4099 | G35: =+CPUE!F33 -> 15 | H35: =Effort!H33 -> 355.55105 | I35: =Harvest!H33 -> 4977.7146 | J35: =CPUE!H33 -> 14 | K35: =Effort!J33 -> 451.49389 | L35: =Harvest!J33 -> 5327.6279 | M35: =CPUE!J33 -> 11.8 | N35: =Effort!L33 -> CLOSED | O35: =Harvest!L33 -> CLOSED | P35: =CPUE!L33 -> CLOSED | Q35: CLOSED | R35: CLOSED | S35: CLOSED | T35: =SUM(E35,H35,K35,N35) -> 1086.2056 | U35: =SUM(F35,I35,L35,O35) -> 14492.752
A36: 45629 | B36: Tue | C36: 0.82361111 | D36: -0.63 | E36: =Effort!F34 -> 142.59828 | F36: =Harvest!F34 -> 2138.9742 | G36: =+CPUE!F34 -> 15 | H36: =Effort!H34 -> 233.79414 | I36: =Harvest!H34 -> 3273.118 | J36: =CPUE!H34 -> 14 | K36: =Effort!J34 -> CLOSED | L36: =Harvest!J34 -> CLOSED | M36: =CPUE!J34 -> CLOSED | N36: =Effort!L34 -> 217.40489 | O36: =Harvest!L34 -> 2853.4392 | P36: =CPUE!L34 -> 13.125 | Q36: CLOSED | R36: CLOSED | S36: CLOSED | T36: =SUM(E36,H36,K36,N36) -> 593.79732 | U36: =SUM(F36,I36,L36,O36) -> 8265.5314
A37: 45630 | B37: Wed | C37: 0.85277778 | D37: -0.46 | E37: =Effort!F35 -> 49.09604 | F37: =Harvest!F35 -> 589.15247 | G37: =+CPUE!F35 -> 12 | H37: =Effort!H35 -> 153.76891 | I37: =Harvest!H35 -> 1977.0289 | J37: =CPUE!H35 -> 12.857143 | K37: =Effort!J35 -> CLOSED | L37: =Harvest!J35 -> CLOSED | M37: =CPUE!J35 -> CLOSED | N37: =Effort!L35 -> 74.851666 | O37: =Harvest!L35 -> 673.665 | P37: =CPUE!L35 -> 9 | Q37: CLOSED | R37: CLOSED | S37: CLOSED | T37: =SUM(E37,H37,K37,N37) -> 277.71662 | U37: =SUM(F37,I37,L37,O37) -> 3239.8464
A38: 45631 | B38: Thu | C38: 0.88402778 | D38: -0.17 | E38: =Effort!F36 -> 26.408701 | F38: =Harvest!F36 -> 132.04351 | G38: =+CPUE!F36 -> 5 | H38: =Effort!H36 -> 33.63526 | I38: =Harvest!H36 -> 168.1763 | J38: =CPUE!H36 -> 5 | K38: =Effort!J36 -> 42.711489 | L38: =Harvest!J36 -> 213.55744 | M38: =CPUE!J36 -> 5 | N38: =Effort!L36 -> CLOSED | O38: =Harvest!L36 -> CLOSED | P38: =CPUE!L36 -> CLOSED | Q38: CLOSED | R38: CLOSED | S38: CLOSED | T38: =SUM(E38,H38,K38,N38) -> 102.75545 | U38: =SUM(F38,I38,L38,O38) -> 513.77725
A39: Tide Series Totals | E39: =SUM(E32:E38) -> 4865.686 | F39: =SUM(F32:F38) -> 68559.342 | G39: =+F39/E39 -> 14.090376 | H39: =SUM(H32:H38) -> 5884.0234 | I39: =SUM(I32:I38) -> 83197.868 | J39: =+I39/H39 -> 14.139622 | K39: =SUM(K32:K38) -> 1476.5128 | L39: =SUM(L32:L38) -> 17801.838 | M39: =+L39/K39 -> 12.056677 | N39: =SUM(N32:N38) -> 4322.1661 | O39: =SUM(O32:O38) -> 55735.623 | P39: =+O39/N39 -> 12.895299 | T39: =SUM(T32:T38) -> 16548.388 | U39: =SUM(U32:U38) -> 225294.67 | W39: =SUM(H39,K39,N39,Q39,E39) -> 16548.388 | X39: =SUM(R39,O39,L39,I39,F39) -> 225294.67
A40: 45638 | B40: Thu | C40: 0.66666667 | D40: -0.48 | E40: =Effort!F38 -> 552.43471 | F40: =Harvest!F38 -> 7070.1462 | G40: =+CPUE!F38 -> 12.798157 | H40: =Effort!H38 -> 850.62084 | I40: =Harvest!H38 -> 11589.709 | J40: =CPUE!H38 -> 13.625 | K40: =Effort!J38 -> 961.07792 | L40: =Harvest!J38 -> 13885.047 | M40: =CPUE!J38 -> 14.447368 | N40: =Effort!L38 -> CLOSED | O40: =Harvest!L38 -> CLOSED | P40: =CPUE!L38 -> CLOSED | Q40: CLOSED | R40: CLOSED | S40: CLOSED | T40: =SUM(E40,H40,K40,N40) -> 2364.1335 | U40: =SUM(F40,I40,L40,O40) -> 32544.902
...

Sheet Summary Table Public
A1: 2024-2025 State (non-Tribal) Recreational Razor Clam Effort, Harvest and CPUE totals.
E2: LONG BEACH | H2: TWIN HARBORS | K2: COPALIS | N2: MOCROCKS | Q2: KALALOCH | T2: DAILY TOTALS | W2: CROSS | X2: CHECK
A3: DATE | B3: DAY | C3: TIME | D3: TIDE | E3: Effort | F3: Harvest | G3: CPUE | H3: Effort | I3: Harvest | J3: CPUE | K3: Effort | L3: Harvest | M3: CPUE | N3: Effort | O3: Harvest | P3: CPUE | Q3: Effort | R3: Harvest | S3: CPUE | T3: Effort | U3: Harvest
A4: 45568 | B4: Thu | C4: 0.81805556 | D4: 0.33 | E4: =Effort!F2 -> 1477.3374 | F4: =Harvest!F2 -> 18842.126 | G4: =+CPUE!F2 -> 12.754112 | H4: =Effort!H2 -> 1638.3428 | I4: =Harvest!H2 -> 23619.442 | J4: =CPUE!H2 -> 14.416667 | K4: =Effort!J2 -> CLOSED | L4: =Harvest!J2 -> CLOSED | M4: =CPUE!J2 -> CLOSED | N4: =Effort!L2 -> 842.90279 | O4: =Harvest!L2 -> 12300.137 | P4: =CPUE!L2 -> 14.592593 | Q4: CLOSED | R4: CLOSED | S4: CLOSED | T4: =SUM(E4,H4,K4,N4) -> 3958.5829 | U4: =SUM(F4,I4,L4,O4) -> 54761.705
A5: 45569 | B5: Fri | C5: 0.84027778 | D5: 0.13 | E5: =Effort!F3 -> 936.60758 | F5: =Harvest!F3 -> 14049.114 | G5: =+CPUE!F3 -> 15 | H5: =Effort!H3 -> 915.05695 | I5: =Harvest!H3 -> 13725.854 | J5: =CPUE!H3 -> 15 | K5: =Effort!J3 -> 1689.802 | L5: =Harvest!J3 -> 25230.491 | M5: =CPUE!J3 -> 14.931034 | N5: =Effort!L3 -> CLOSED | O5: =Harvest!L3 -> CLOSED | P5: =CPUE!L3 -> CLOSED | Q5: CLOSED | R5: CLOSED | S5: CLOSED | T5: =SUM(E5,H5,K5,N5) -> 3541.4665 | U5: =SUM(F5,I5,L5,O5) -> 53005.459
A6: 45570 | B6: Sat | C6: 0.86388889 | D6: 0.07 | E6: =Effort!F4 -> 1621.6754 | F6: =Harvest!F4 -> 22703.455 | G6: =+CPUE!F4 -> 14 | H6: =Effort!H4 -> 1584.3619 | I6: =Harvest!H4 -> 22242.003 | J6: =CPUE!H4 -> 14.038462 | K6: =Effort!J4 -> 2925.7827 | L6: =Harvest!J4 -> 36243.88 | M6: =CPUE!J4 -> 12.387755 | N6: =Effort!L4 -> CLOSED | O6: =Harvest!L4 -> CLOSED | P6: =CPUE!L4 -> CLOSED | Q6: CLOSED | R6: CLOSED | S6: CLOSED | T6: =SUM(E6,H6,K6,N6) -> 6131.82 | U6: =SUM(F6,I6,L6,O6) -> 81189.338
A7: 45571 | B7: Sun | C7: 0.88888889 | D7: 0.13 | E7: =Effort!F5 -> 472.51044 | F7: =Harvest!F5 -> 7087.6567 | G7: =+CPUE!F5 -> 15 | H7: =Effort!H5 -> 524.0063 | I7: =Harvest!H5 -> 7860.0945 | J7: =CPUE!H5 -> 15 | K7: =Effort!J5 -> CLOSED | L7: =Harvest!J5 -> CLOSED | M7: =CPUE!J5 -> CLOSED | N7: =Effort!L5 -> 269.59338 | O7: =Harvest!L5 -> 4043.9007 | P7: =CPUE!L5 -> 15 | Q7: CLOSED | R7: CLOSED | S7: CLOSED | T7: =SUM(E7,H7,K7,N7) -> 1266.1101 | U7: =SUM(F7,I7,L7,O7) -> 18991.652
A8: 45572 | B8: Mon | C8: 0.91805556 | D8: 0.3 | E8: =Effort!F6 -> 90.191841 | F8: =Harvest!F6 -> 1352.8776 | G8: =+CPUE!F6 -> 15 | H8: =Effort!H6 -> 158.78994 | I8: =Harvest!H6 -> 2381.8491 | J8: =CPUE!H6 -> 15 | K8: =Effort!J6 -> CLOSED | L8: =Harvest!J6 -> CLOSED | M8: =CPUE!J6 -> CLOSED | N8: =Effort!L6 -> 176.66393 | O8: =Harvest!L6 -> 2649.959 | P8: =CPUE!L6 -> 15 | Q8: CLOSED | R8: CLOSED | S8: CLOSED | T8: =SUM(E8,H8,K8,N8) -> 425.64571 | U8: =SUM(F8,I8,L8,O8) -> 6384.6857
A9: Tide Series Totals | E9: =SUM(E4:E8) -> 4598.3226 | F9: =SUM(F4:F8) -> 64035.23 | G9: =+F9/E9 -> 13.92578 | H9: =SUM(H4:H8) -> 4820.5578 | I9: =SUM(I4:I8) -> 69829.243 | J9: =+I9/H9 -> 14.485718 | K9: =SUM(K4:K8) -> 4615.5847 | L9: =SUM(L4:L8) -> 61474.371 | M9: =+L9/K9 -> 13.31887 | N9: =SUM(N4:N8) -> 1289.1601 | O9: =SUM(O4:O8) -> 18993.997 | P9: =+O9/N9 -> 14.733621 | T9: =SUM(T4:T8) -> 15323.625 | U9: =SUM(U4:U8) -> 214332.84 | W9: =SUM(H9,K9,N9,Q9,E9) -> 15323.625 | X9: =SUM(R9,O9,L9,I9,F9) -> 214332.84
A10: 45580 | B10: Tue | C10: 0.72986111 | D10: 0.53 | E10: =Effort!F8 -> 1395.632 | F10: =Harvest!F8 -> 20236.664 | G10: =+CPUE!F7 -> 0 | H10: =Effort!H8 -> 1116.866 | I10: =Harvest!H8 -> 15785.039 | J10: =CPUE!H8 -> 14.133333 | K10: =Effort!J8 -> CLOSED | L10: =Harvest!J8 -> CLOSED | M10: =CPUE!J8 -> CLOSED | N10: =Effort!L8 -> 1020.3701 | O10: =Harvest!L8 -> 15184.078 | P10: =CPUE!L8 -> 14.880952 | Q10: CLOSED | R10: CLOSED | S10: CLOSED | T10: =SUM(E10,H10,K10,N10) -> 3532.8681 | U10: =SUM(F10,I10,L10,O10) -> 51205.782
A11: 45581 | B11: Wed | C11: 0.7625 | D11: -0.48 | E11: =Effort!F9 -> 1152.5828 | F11: =Harvest!F9 -> 14773.165 | G11: =+CPUE!F8 -> 14.5 | H11: =Effort!H9 -> 1190.0248 | I11: =Harvest!H9 -> 17850.372 | J11: =CPUE!H9 -> 15 | K11: =Effort!J9 -> 1560.3596 | L11: =Harvest!J9 -> 23405.395 | M11: =CPUE!J9 -> 15 | N11: =Effort!L9 -> CLOSED | O11: =Harvest!L9 -> CLOSED | P11: =CPUE!L9 -> CLOSED | Q11: CLOSED | R11: CLOSED | S11: CLOSED | T11: =SUM(E11,H11,K11,N11) -> 3902.9672 | U11: =SUM(F11,I11,L11,O11) -> 56028.932
A12: 45582 | B12: Thu | C12: 0.79375 | D12: -1.25 | E12: =Effort!F10 -> 1631.7989 | F12: =Harvest!F10 -> 23661.084 | G12: =+CPUE!F9 -> 12.817444 | H12: =Effort!H10 -> 1684.8084 | I12: =Harvest!H10 -> 24968.308 | J12: =CPUE!H10 -> 14.819672 | K12: =Effort!J10 -> 2209.1196 | L12: =Harvest!J10 -> 32203.363 | M12: =CPUE!J10 -> 14.577465 | N12: =Effort!L10 -> CLOSED | O12: =Harvest!L10 -> CLOSED | P12: =CPUE!L10 -> CLOSED | Q12: CLOSED | R12: CLOSED | S12: CLOSED | T12: =SUM(E12,H12,K12,N12) -> 5525.7269 | U12: =SUM(F12,I12,L12,O12) -> 80832.755
A13: 45583 | B13: Fri | C13: 0.82569444 | D13: -1.66 | E13: =Effort!F11 -> 1240.2797 | F13: =Harvest!F11 -> 4340.9791 | G13: =+CPUE!F10 -> 14.5 | H13: =Effort!H11 -> 954.45189 | I13: =Harvest!H11 -> 4854.0696 | J13: =CPUE!H11 -> 5.0857143 | K13: =Effort!J11 -> CLOSED | L13: =Harvest!J11 -> CLOSED | M13: =CPUE!J11 -> CLOSED | N13: =Effort!L11 -> 906.78938 | O13: =Harvest!L11 -> 2593.8394 | P13: =CPUE!L11 -> 2.8604651 | Q13: CLOSED | R13: CLOSED | S13: CLOSED | T13: =SUM(E13,H13,K13,N13) -> 3101.521 | U13: =SUM(F13,I13,L13,O13) -> 11788.888
A14: 45584 | B14: Sat | C14: 0.85763889 | D14: -1.69 | E14: =Effort!F12 -> 2309.9187 | F14: =Harvest!F12 -> 26102.081 | G14: =+CPUE!F11 -> 3.5 | H14: =Effort!H12 -> 1735.9676 | I14: =Harvest!H12 -> 15623.708 | J14: =CPUE!H12 -> 9 | K14: =Effort!J12 -> CLOSED | L14: =Harvest!J12 -> CLOSED | M14: =CPUE!J12 -> CLOSED | N14: =Effort!L12 -> 1649.2785 | O14: =Harvest!L12 -> 13531.58 | P14: =CPUE!L12 -> 8.2045455 | Q14: CLOSED | R14: CLOSED | S14: CLOSED | T14: =SUM(E14,H14,K14,N14) -> 5695.1647 | U14: =SUM(F14,I14,L14,O14) -> 55257.37
A15: 45585 | B15: Sun | C15: 0.89166667 | D15: -1.36 | E15: =Effort!F13 -> 384.93669 | F15: =Harvest!F13 -> 5774.0504 | G15: =+CPUE!F12 -> 11.3 | H15: =Effort!H13 -> 397.44148 | I15: =Harvest!H13 -> 5961.6221 | J15: =CPUE!H13 -> 15 | K15: =Effort!J13 -> 521.12498 | L15: =Harvest!J13 -> 7816.8747 | M15: =CPUE!J13 -> 15 | N15: =Effort!L13 -> CLOSED | O15: =Harvest!L13 -> CLOSED | P15: =CPUE!L13 -> CLOSED | Q15: CLOSED | R15: CLOSED | S15: CLOSED | T15: =SUM(E15,H15,K15,N15) -> 1303.5031 | U15: =SUM(F15,I15,L15,O15) -> 19552.547
A16: 45586 | B16: Mon | C16: 0.92777778 | D16: -0.78 | E16: =Effort!F14 -> 206.92418 | F16: =Harvest!F14 -> 3103.8626 | G16: =+CPUE!F13 -> 15 | H16: =Effort!H14 -> 213.64617 | I16: =Harvest!H14 -> 3204.6926 | J16: =CPUE!H14 -> 15 | K16: =Effort!J14 -> 280.13271 | L16: =Harvest!J14 -> 4201.9906 | M16: =CPUE!J14 -> 15 | N16: =Effort!L14 -> CLOSED | O16: =Harvest!L14 -> CLOSED | P16: =CPUE!L14 -> CLOSED | Q16: CLOSED | R16: CLOSED | S16: CLOSED | T16: =SUM(E16,H16,K16,N16) -> 700.70305 | U16: =SUM(F16,I16,L16,O16) -> 10510.546
A17: Tide Series Totals | E17: =SUM(E10:E16) -> 8322.073 | F17: =SUM(F10:F16) -> 97991.887 | G17: =+F17/E17 -> 11.774937 | H17: =SUM(H10:H16) -> 7293.2063 | I17: =SUM(I10:I16) -> 88247.811 | J17: =+I17/H17 -> 12.100002 | K17: =SUM(K10:K16) -> 4570.7369 | L17: =SUM(L10:L16) -> 67627.623 | M17: =+L17/K17 -> 14.795781 | N17: =SUM(N10:N16) -> 3576.4379 | O17: =SUM(O10:O16) -> 31309.498 | P17: =+O17/N17 -> 8.7543804 | T17: =SUM(T10:T16) -> 23762.454 | U17: =SUM(U10:U16) -> 285176.82 | W17: =SUM(H17,K17,N17,Q17,E17) -> 23762.454 | X17: =SUM(R17,O17,L17,I17,F17) -> 285176.82
A18: 45597 | B18: Fri | C18: 0.80208333 | D18: -0.19 | E18: =Effort!F16 -> 768.48287 | F18: =Harvest!F16 -> 9423.2495 | G18: =+CPUE!F16 -> 12.262147 | H18: =Effort!H16 -> 1078.629 | I18: =Harvest!H16 -> 14022.177 | J18: =CPUE!H16 -> 13 | K18: =Effort!J16 -> CLOSED | L18: =Harvest!J16 -> CLOSED | M18: =CPUE!J16 -> CLOSED | N18: =Effort!L16 -> 947.32683 | O18: =Harvest!L16 -> 12543.914 | P18: =CPUE!L16 -> 13.241379 | Q18: CLOSED | R18: CLOSED | S18: CLOSED | T18: =SUM(E18,H18,K18,N18) -> 2794.4387 | U18: =SUM(F18,I18,L18,O18) -> 35989.34
A19: 45598 | B19: Sat | C19: 0.82430556 | D19: -0.36 | E19: =Effort!F17 -> 847.38926 | F19: =Harvest!F17 -> 11016.06 | G19: =+CPUE!F17 -> 13 | H19: =Effort!H17 -> 1189.3806 | I19: =Harvest!H17 -> 15635.399 | J19: =CPUE!H17 -> 13.145833 | K19: =Effort!J17 -> CLOSED | L19: =Harvest!J17 -> CLOSED | M19: =CPUE!J17 -> CLOSED | N19: =Effort!L17 -> 1044.5966 | O19: =Harvest!L17 -> 10012.84 | P19: =CPUE!L17 -> 9.5853659 | Q19: CLOSED | R19: CLOSED | S19: CLOSED | T19: =SUM(E19,H19,K19,N19) -> 3081.3664 | U19: =SUM(F19,I19,L19,O19) -> 36664.3
A20: 45599 | B20: Sun | C20: 0.80694444 | D20: -0.39 | E20: =Effort!F18 -> 260.3776 | F20: =Harvest!F18 -> 1353.9635 | G20: =+CPUE!F18 -> 5.2 | H20: =Effort!H18 -> 450.80604 | I20: =Harvest!H18 -> 829.48311 | J20: =CPUE!H18 -> 1.84 | K20: =Effort!J18 -> 547.69196 | L20: =Harvest!J18 -> 2243.7703 | M20: =CPUE!J18 -> 4.0967742 | N20: =Effort!L18 -> CLOSED | O20: =Harvest!L18 -> CLOSED | P20: =CPUE!L18 -> CLOSED | Q20: CLOSED | R20: CLOSED | S20: CLOSED | T20: =SUM(E20,H20,K20,N20) -> 1258.8756 | U20: =SUM(F20,I20,L20,O20) -> 4427.2169
A21: 45600 | B21: Mon | C21: 0.83333333 | D21: -0.29 | E21: =Effort!F19 -> 51.10981 | F21: =Harvest!F19 -> 459.98829 | G21: =+CPUE!F19 -> 9 | H21: =Effort!H19 -> 88.489223 | I21: =Harvest!H19 -> 796.40301 | J21: =CPUE!H19 -> 9 | K21: =Effort!J19 -> 107.50707 | L21: =Harvest!J19 -> 967.56363 | M21: =CPUE!J19 -> 9 | N21: =Effort!L19 -> CLOSED | O21: =Harvest!L19 -> CLOSED | P21: =CPUE!L19 -> CLOSED | Q21: CLOSED | R21: CLOSED | S21: CLOSED | T21: =SUM(E21,H21,K21,N21) -> 247.1061 | U21: =SUM(F21,I21,L21,O21) -> 2223.9549
A22: 45601 | B22: Tue | C22: 0.8625 | D22: -0.09 | E22: =Effort!F20 -> 79.464009 | F22: =Harvest!F20 -> 1033.0321 | G22: =+CPUE!F20 -> 13 | H22: =Effort!H20 -> 109.375 | I22: =Harvest!H20 -> 1531.25 | J22: =CPUE!H20 -> 14 | K22: =Effort!J20 -> CLOSED | L22: =Harvest!J20 -> CLOSED | M22: =CPUE!J20 -> CLOSED | N22: =Effort!L20 -> 97.957146 | O22: =Harvest!L20 -> 1098.5194 | P22: =CPUE!L20 -> 11.214286 | Q22: CLOSED | R22: CLOSED | S22: CLOSED | T22: =SUM(E22,H22,K22,N22) -> 286.79616 | U22: =SUM(F22,I22,L22,O22) -> 3662.8016
A23: Tide Series Totals | E23: =SUM(E18:E22) -> 2006.8235 | F23: =SUM(F18:F22) -> 23286.294 | G23: =+F23/E23 -> 11.603558 | H23: =SUM(H18:H22) -> 2916.6798 | I23: =SUM(I18:I22) -> 32814.712 | J23: =+I23/H23 -> 11.250708 | K23: =SUM(K18:K22) -> 655.19903 | L23: =SUM(L18:L22) -> 3211.3339 | M23: =+L23/K23 -> 4.9013105 | N23: =SUM(N18:N22) -> 2089.8806 | O23: =SUM(O18:O22) -> 23655.274 | P23: =+O23/N23 -> 11.31896 | T23: =SUM(T18:T22) -> 7668.583 | U23: =SUM(U18:U22) -> 82967.613 | W23: =SUM(H23,K23,N23,Q23,E23) -> 7668.583 | X23: =SUM(R23,O23,L23,I23,F23) -> 82967.613
A24: 45609 | B24: Wed | C24: 0.67708333 | D24: -0.17 | E24: =Effort!F22 -> 451.62536 | F24: =Harvest!F22 -> 5464.6668 | G24: =+CPUE!F22 -> 12.1 | H24: =Effort!H22 -> 592.09054 | I24: =Harvest!H22 -> 7697.177 | J24: =CPUE!H22 -> 13 | K24: =Effort!J22 -> CLOSED | L24: =Harvest!J22 -> CLOSED | M24: =CPUE!J22 -> CLOSED | N24: =Effort!L22 -> 514.83341 | O24: =Harvest!L22 -> 7022.8558 | P24: =CPUE!L22 -> 13.641026 | Q24: CLOSED | R24: CLOSED | S24: CLOSED | T24: =SUM(E24,H24,K24,N24) -> 1558.5493 | U24: =SUM(F24,I24,L24,O24) -> 20184.7
A25: 45610 | B25: Thu | C25: 0.70972222 | D25: -1.09 | E25: =Effort!F23 -> 1081.0979 | F25: =Harvest!F23 -> 12973.174 | G25: =+CPUE!F23 -> 12 | H25: =Effort!H23 -> 1307.5849 | I25: =Harvest!H23 -> 16148.674 | J25: =CPUE!H23 -> 12.35 | K25: =Effort!J23 -> CLOSED | L25: =Harvest!J23 -> CLOSED | M25: =CPUE!J23 -> CLOSED | N25: =Effort!L23 -> 1136.9687 | O25: =Harvest!L23 -> 16343.925 | P25: =CPUE!L23 -> 14.375 | Q25: CLOSED | R25: CLOSED | S25: CLOSED | T25: =SUM(E25,H25,K25,N25) -> 3525.6515 | U25: =SUM(F25,I25,L25,O25) -> 45465.773
A26: 45611 | B26: Fri | C26: 0.74166667 | D26: -1.68 | E26: =Effort!F24 -> 2116.6716 | F26: =Harvest!F24 -> 31750.074 | G26: =+CPUE!F24 -> 15 | H26: =Effort!H24 -> 2175.2661 | I26: =Harvest!H24 -> 31178.814 | J26: =CPUE!H24 -> 14.333333 | K26: =Effort!J24 -> 3896.9949 | L26: =Harvest!J24 -> 55348.623 | M26: =CPUE!J24 -> 14.202899 | N26: =Effort!L24 -> CLOSED | O26: =Harvest!L24 -> CLOSED | P26: =CPUE!L24 -> CLOSED | Q26: CLOSED | R26: CLOSED | S26: CLOSED | T26: =SUM(E26,H26,K26,N26) -> 8188.9326 | U26: =SUM(F26,I26,L26,O26) -> 118277.51
A27: 45612 | B27: Sat | C27: 0.77291667 | D27: -1.9 | E27: =Effort!F25 -> 686.13439 | F27: =Harvest!F25 -> 1715.336 | G27: =+CPUE!F25 -> 2.5 | H27: =Effort!H25 -> 705.12824 | I27: =Harvest!H25 -> 761.5385 | J27: =CPUE!H25 -> 1.08 | K27: =Effort!J25 -> 2469.621 | L27: =Harvest!J25 -> 6275.2664 | M27: =CPUE!J25 -> 2.5409836 | N27: =Effort!L25 -> CLOSED | O27: =Harvest!L25 -> CLOSED | P27: =CPUE!L25 -> CLOSED | Q27: CLOSED | R27: CLOSED | S27: CLOSED | T27: =SUM(E27,H27,K27,N27) -> 3860.8836 | U27: =SUM(F27,I27,L27,O27) -> 8752.1409
A28: 45613 | B28: Sun | C28: 0.80486111 | D28: -1.75 | E28: =Effort!F26 -> 503.29155 | F28: =Harvest!F26 -> 5284.5613 | G28: =+CPUE!F26 -> 10.5 | H28: =Effort!H26 -> 608.72976 | I28: =Harvest!H26 -> 6391.6625 | J28: =CPUE!H26 -> 10.5 | K28: =Effort!J26 -> CLOSED | L28: =Harvest!J26 -> CLOSED | M28: =CPUE!J26 -> CLOSED | N28: =Effort!L26 -> 529.30152 | O28: =Harvest!L26 -> 5487.0924 | P28: =CPUE!L26 -> 10.366667 | Q28: CLOSED | R28: CLOSED | S28: CLOSED | T28: =SUM(E28,H28,K28,N28) -> 1641.3228 | U28: =SUM(F28,I28,L28,O28) -> 17163.316
