Workbook

Sheet Harvest
A1: Date | B1: Day | C1: Tide | D1: Time | E1: Longbeach | G1: Twin Harbors | I1: Copalis | K1: Mocrocks | M1: Kalaloch | O1: Daily Totals
A2: 45936 | B2: Mon | C2: -0.21 | D2: 0.77430556 | E2: * | F2: =+Effort!F2*CPUE!F2 -> 25248.804 | H2: 27015.574 | J2: CLOSED | L2: 22619.962 | N2: CLOSED | O2: =SUM(F2:N2) -> 74884.34
A3: 45937 | B3: Tue | C3: -0.95 | D3: 0.80416667 | F3: =11674.7548001086+15401.7856066792 -> 27076.54 | G3: * | H3: =+Effort!H3*CPUE!H3 -> 21796.967 | J3: CLOSED | L3: 17526.232 | N3: CLOSED | O3: =SUM(F3:N3) -> 66399.74
A4: 45938 | B4: Wed | C4: -1.41 | D4: 0.83472222 | F4: =+Effort!F4*CPUE!F4 -> 11317.153 | G4: * | H4: =+Effort!H4*CPUE!H4 -> 14245.958 | J4: 24105.802 | L4: CLOSED | N4: CLOSED | O4: =SUM(F4:N4) -> 49668.913
A5: 45939 | B5: Thu | C5: -1.51 | D5: 0.86736111 | E5: * | F5: =+Effort!F5*CPUE!F5 -> 8680.7079 | H5: 11610.169 | J5: 8857.6225 | L5: CLOSED | N5: CLOSED | O5: =SUM(F5:N5) -> 29148.5
A6: 45940 | B6: Fri | C6: -1.28 | D6: 0.90277778 | F6: =+Effort!F6*CPUE!F6 -> 12330.508 | H6: 13193.328 | J6: CLOSED | L6: 18312.923 | N6: CLOSED | O6: =SUM(F6:N6) -> 43836.758
A7: 45941 | B7: Sat | C7: -0.81 | D7: 0.94236111 | E7: * | F7: =+Effort!F7*CPUE!F7 -> 10205.529 | H7: 9367.3512 | J7: CLOSED | L7: 10681.043 | N7: CLOSED | O7: =SUM(F7:N7) -> 30253.923
A8: 45942 | B8: Sun | C8: -0.23 | D8: 0.98680556 | E8: * | F8: =+Effort!F8*CPUE!F8 -> 580.75474 | G8: * | H8: =+Effort!H8*CPUE!H8 -> 956.86256 | J8: 977.31234 | L8: CLOSED | N8: CLOSED | O8: =SUM(F8:N8) -> 2514.9296
A10: 45950 | B10: Mon | C10: 0.19 | D10: 0.77777778 | F10: =+Effort!F10*CPUE!F10 -> 14795.872 | H10: 13766.619 | J10: 11601.391 | L10: CLOSED | N10: CLOSED | O10: =SUM(F10:N10) -> 40163.882
A11: 45951 | B11: Tue | C11: -0.12 | D11: 0.80069444 | E11: * | F11: =+Effort!F11*CPUE!F11 -> 7133.2311 | G11: * | H11: =+Effort!H11*CPUE!H11 -> 6230.8725 | J11: 5646.0409 | L11: CLOSED | N11: CLOSED | O11: =SUM(F11:N11) -> 19010.145
A12: 45952 | B12: Wed | C12: -0.28 | D12: 0.82291667 | F12: =+Effort!F12*CPUE!F12 -> 4722.1851 | H12: 2551.606 | J12: CLOSED | L12: 4770.4549 | N12: CLOSED | O12: =SUM(F12:N12) -> 12044.246
A13: 45953 | B13: Thu | C13: -0.27 | D13: 0.84583333 | E13: * | F13: =+Effort!F13*CPUE!F13 -> 180.40573 | G13: * | H13: =+Effort!H13*CPUE!H13 -> 157.58428 | J13: CLOSED | L13: =+Effort!L13*CPUE!L13 -> 172.35943 | N13: CLOSED | O13: =SUM(F13:N13) -> 510.34944
A14: 45954 | B14: Fri | C14: -0.12 | D14: 0.87013889 | F14: =+Effort!F14*CPUE!F14 -> 583.32028 | G14: * | H14: =+Effort!H14*CPUE!H14 -> 509.52987 | J14: 1135.2747 | L14: CLOSED | N14: CLOSED | O14: =SUM(F14:N14) -> 2228.1248
A15: 45955 | B15: Sat | C15: 0.14 | D15: 0.89652778 | E15: * | F15: =+Effort!F15*CPUE!F15 -> 19.186937 | H15: =+Effort!H15*CPUE!H15 -> 16.759777 | J15: =+Effort!J15*CPUE!J15 -> 98.666183 | L15: CLOSED | N15: CLOSED | O15: =SUM(F15:N15) -> 134.6129
A16: 45956 | B16: Sun | C16: 0.47 | D16: 0.92708333 | E16: * | F16: =+Effort!F16*CPUE!F16 -> 558.17791 | G16: * | H16: =+Effort!H16*CPUE!H16 -> 487.56803 | J16: CLOSED | L16: 524.39452 | N16: CLOSED | O16: =SUM(F16:N16) -> 1570.1405
A18: 45964 | B18: Mon | C18: -0.1 | D18: 0.6875 | F18: =+Effort!F18*CPUE!F18 -> 12243.407 | G18: * | H18: =+Effort!H18*CPUE!H18 -> 8709.8269 | J18: CLOSED | L18: 8445.1126 | N18: CLOSED | O18: =SUM(F18:N18) -> 29398.347
A19: 45965 | B19: Tue | C19: -1.1 | D19: 0.71875 | E19: * | F19: =+Effort!F19*CPUE!F19 -> 6954.198 | H19: 13075.811 | J19: CLOSED | L19: 10552.259 | N19: CLOSED | O19: =SUM(F19:N19) -> 30582.268
A20: 45966 | B20: Wed | C20: -1.7 | D20: 0.75069444 | F20: =+Effort!F20*CPUE!F20 -> 3032.967 | G20: * | H20: =+Effort!H20*CPUE!H20 -> 1877.9885 | J20: 4263.8123 | L20: CLOSED | N20: CLOSED | O20: =SUM(F20:N20) -> 9174.7678
A21: 45967 | B21: Thu | C21: -2 | D21: 0.78194444 | E21: * | F21: =+Effort!F21*CPUE!F21 -> 807.72137 | H21: 538.60638 | J21: 787.90672 | L21: CLOSED | N21: CLOSED | O21: =SUM(F21:N21) -> 2134.2345
A22: 45968 | B22: Fri | C22: -1.9 | D22: 0.81527778 | F22: =+Effort!F22*CPUE!F22 -> 15757.943 | G22: * | H22: =+Effort!H22*CPUE!H22 -> 25604.08 | J22: CLOSED | L22: 25541.031 | N22: CLOSED | O22: =SUM(F22:N22) -> 66903.055
A23: 45969 | B23: Sat | C23: -1.5 | D23: 0.85069444 | E23: * | F23: =+Effort!F23*CPUE!F23 -> 16021.053 | H23: 34860.537 | J23: CLOSED | L23: 25695.579 | N23: CLOSED | O23: =SUM(F23:N23) -> 76577.17
A24: 45970 | B24: Sun | C24: -0.9 | D24: 0.88819444 | E24: * | F24: =+Effort!F24*CPUE!F24 -> 4119.1639 | G24: * | H24: =+Effort!H24*CPUE!H24 -> 2550.5527 | J24: 5778.3333 | L24: CLOSED | N24: CLOSED | O24: =SUM(F24:N24) -> 12448.05
A26: 45979 | B26: Tue | C26: -0.02 | D26: 0.72083333 | E26: * | F26: =+Effort!F26*CPUE!F26 -> 5906.8219 | G26: * | H26: =+Effort!H26*CPUE!H26 -> 10815.994 | J26: 12349.08 | L26: CLOSED | N26: CLOSED | O26: =SUM(F26:N26) -> 29071.896
A27: 45980 | B27: Wed | C27: -0.3 | D27: 0.74444444 | F27: =+Effort!F27*CPUE!F27 -> 11935.693 | H27: 9720.6704 | J27: CLOSED | L27: 3194.8882 | N27: CLOSED | O27: =SUM(F27:N27) -> 24851.252
A28: 45981 | B28: Thu | C28: -0.43 | D28: 0.76736111 | E28: * | F28: =+Effort!F28*CPUE!F28 -> 620.29634 | H28: 908.66071 | J28: CLOSED | L28: 633.57667 | N28: CLOSED | O28: =SUM(F28:N28) -> 2162.5337
A29: 45982 | B29: Fri | C29: -0.41 | D29: 0.79097222 | F29: =+Effort!F29*CPUE!F29 -> 4153.2342 | H29: 7435.9956 | J29: 6100.165 | L29: CLOSED | N29: CLOSED | O29: =SUM(F29:N29) -> 17689.395
A30: 45983 | B30: Sat | C30: -0.29 | D30: 0.81527778 | E30: * | F30: =+Effort!F30*CPUE!F30 -> 4068.6224 | G30: * | H30: =+Effort!H30*CPUE!H30 -> 7450.0628 | J30: 8301.9086 | L30: CLOSED | N30: CLOSED | O30: =SUM(F30:N30) -> 19820.594
A31: 45984 | B31: Sun | C31: -0.09 | D31: 0.84166667 | E31: * | F31: =+Effort!F31*CPUE!F31 -> 3456.067 | G31: * | H31: =+Effort!H31*CPUE!H31 -> 2373.4283 | J31: CLOSED | L31: 1237.9563 | N31: CLOSED | O31: =SUM(F31:N31) -> 7067.4516
A33: 45993 | B33: Tue | C33: -0.59 | D33: 0.67430556 | E33: * | F33: =+Effort!F33*CPUE!F33 -> 14333.704 | G33: * | H33: =+Effort!H33*CPUE!H33 -> 13385.462 | J33: 18749.225 | L33: CLOSED | N33: CLOSED | O33: =SUM(F33:N33) -> 46468.391
A34: 45994 | B34: Wed | C34: -1.4 | D34: 0.70763889 | F34: =9133.9285325411+10388.3125215894 -> 19522.241 | H34: 16497.789 | J34: CLOSED | L34: 17248.161 | N34: CLOSED | O34: =SUM(F34:N34) -> 53268.191
A35: 45995 | B35: Thu | C35: -1.9 | D35: 0.74097222 | E35: * | F35: =+Effort!F35*CPUE!F35 -> 6786.5011 | G35: * | H35: =+Effort!H35*CPUE!H35 -> 5721.9606 | J35: CLOSED | L35: 6162.3041 | N35: CLOSED | O35: =SUM(F35:N35) -> 18670.766
A36: 45996 | B36: Fri | C36: -2.05 | D36: 0.77361111 | F36: =+Effort!F36*CPUE!F36 -> 12079.725 | H36: 7364.8019 | J36: 13765.44 | L36: CLOSED | N36: CLOSED | O36: =SUM(F36:N36) -> 33209.968
A37: 45997 | B37: Sat | C37: -1.86 | D37: 0.80694444 | E37: * | F37: =+Effort!F37*CPUE!F37 -> 14088.679 | G37: * | H37: =+Effort!H37*CPUE!H37 -> 13156.647 | J37: 18799.854 | L37: CLOSED | N37: CLOSED | O37: =SUM(F37:N37) -> 46045.179
A38: 45998 | B38: Sun | C38: -1.41 | D38: 0.84027778 | E38: * | F38: =+Effort!F38*CPUE!F38 -> 2402.8207 | G38: * | H38: =+Effort!H38*CPUE!H38 -> 2025.9108 | J38: CLOSED | L38: 2056.2771 | N38: CLOSED | O38: =SUM(F38:N38) -> 6485.0087
A39: 45999 | B39: Mon | C39: -0.78 | D39: 0.87430556 | E39: * | F39: =+Effort!F39*CPUE!F39 -> 84.57929 | G39: * | H39: =+Effort!H39*CPUE!H39 -> 71.312059 | J39: CLOSED | L39: 57.14286 | N39: CLOSED | O39: =SUM(F39:N39) -> 213.03421
A41: 46009 | B41: Thu | C41: -0.2 | D41: 0.73194444 | E41: * | F41: =+Effort!F41*CPUE!F41 -> 926.67379 | H41: 851.69489 | J41: 654.79847 | L41: CLOSED | N41: CLOSED | O41: =SUM(F41:N41) -> 2433.1671
A42: 46010 | B42: Fri | C42: -0.38 | D42: 0.75625 | F42: =+Effort!F42*CPUE!F42 -> 1738.6782 | G42: * | H42: =+Effort!H42*CPUE!H42 -> 1657.1837 | J42: CLOSED | L42: 591.1164 | N42: CLOSED | O42: =SUM(F42:N42) -> 3986.9783
A43: 46011 | B43: Sat | C43: -0.45 | D43: 0.78055556 | E43: * | F43: =+Effort!F43*CPUE!F43 -> 2809.979 | G43: * | H43: =+Effort!H43*CPUE!H43 -> 2678.271 | J43: CLOSED | L43: 1177.6322 | N43: CLOSED | O43: =SUM(F43:N43) -> 6665.8822
A44: 46012 | B44: Sun | C44: -0.44 | D44: 0.80486111 | F44: =+Effort!F44*CPUE!F44 -> 1327.4464 | H44: 1128.1607 | J44: 2407.9176 | L44: CLOSED | N44: CLOSED | O44: =SUM(F44:N44) -> 4863.5247
A45: 46013 | B45: Mon | C45: -0.33 | D45: 0.82916667 | E45: * | F45: =+Effort!F45*CPUE!F45 -> 268.83478 | G45: * | H45: =+Effort!H45*CPUE!H45 -> 256.23407 | J45: 497.60415 | L45: CLOSED | N45: CLOSED | O45: =SUM(F45:N45) -> 1022.673
...

Sheet Effort
A1: Date | B1: Day | C1: Tide | D1: Time | E1: Longbeach | G1: Twin Harbors | I1: Copalis | K1: Mocrocks | M1: Kalaloch | O1: Daily Totals
A2: 45936 | B2: Mon | C2: -0.21 | D2: 0.77430556 | E2: * | F2: =F6/H6*H2 -> 1683.2536 | H2: 1801.0383 | J2: CLOSED | L2: 1507.9975 | N2: CLOSED | O2: =SUM(F2:N2) -> 4992.2893
A3: 45937 | B3: Tue | C3: -0.95 | D3: 0.80416667 | F3: =778.316986673906+1071.4285639429 -> 1849.7456 | G3: * | H3: =H2/L2*L3 -> 1556.9262 | J3: CLOSED | L3: 1303.6041 | N3: CLOSED | O3: =SUM(F3:N3) -> 4710.2759
A4: 45938 | B4: Wed | C4: -1.41 | D4: 0.83472222 | F4: =(778.316986673906/1071.4285639429*550.860285622338)+550.860285622338 -> 951.02128 | G4: * | H4: =H6/F6*F4 -> 1017.5684 | J4: 1621.4665 | L4: CLOSED | N4: CLOSED | O4: =SUM(F4:N4) -> 3590.0562
A5: 45939 | B5: Thu | C5: -1.51 | D5: 0.86736111 | E5: * | F5: =F6/H6*H5 -> 723.39233 | H5: 774.01127 | J5: 800.95523 | L5: CLOSED | N5: CLOSED | O5: =SUM(F5:N5) -> 2298.3588
A6: 45940 | B6: Fri | C6: -1.28 | D6: 0.90277778 | F6: =(778.316986673906/1071.4285639429*476.146862435801)+476.146862435801 -> 822.03384 | H6: 879.55517 | J6: CLOSED | L6: 1246.548 | N6: CLOSED | O6: =SUM(F6:N6) -> 2948.137
A7: 45941 | B7: Sat | C7: -0.81 | D7: 0.94236111 | E7: * | F7: =F6/H6*H7 -> 850.46078 | H7: 909.97126 | J7: CLOSED | L7: 717.812 | N7: CLOSED | O7: =SUM(F7:N7) -> 2478.244
A8: 45942 | B8: Sun | C8: -0.23 | D8: 0.98680556 | E8: * | F8: =F4/J4*J8 -> 82.964963 | G8: * | H8: =H5/J5*J8 -> 136.69465 | J8: 141.4531 | L8: CLOSED | N8: CLOSED | O8: =SUM(F8:N8) -> 361.11272
A10: 45950 | B10: Mon | C10: 0.19 | D10: 0.77777778 | F10: =F14/H14*H10 -> 1087.9318 | H10: 950.30766 | J10: 858.62272 | L10: CLOSED | N10: CLOSED | O10: =SUM(F10:N10) -> 2896.8621
A11: 45951 | B11: Tue | C11: -0.12 | D11: 0.80069444 | E11: * | F11: =F10/J10*J11 -> 951.09748 | G11: * | H11: =H10/J10*J11 -> 830.78301 | J11: 750.62972 | L11: CLOSED | N11: CLOSED | O11: =SUM(F11:N11) -> 2532.5102
A12: 45952 | B12: Wed | C12: -0.28 | D12: 0.82291667 | F12: =(778.316986673906/1071.4285639429*193.988115946347)+193.988115946347 -> 334.90675 | H12: 292.54082 | J12: CLOSED | L12: 319.96954 | N12: CLOSED | O12: =SUM(F12:N12) -> 947.4171
A13: 45953 | B13: Thu | C13: -0.27 | D13: 0.84583333 | E13: * | F13: =F12/L12*L13 -> 90.202864 | G13: * | H13: =H12/L12*L13 -> 78.792141 | J13: CLOSED | L13: 86.179716 | N13: CLOSED | O13: =SUM(F13:N13) -> 255.17472
A14: 45954 | B14: Fri | C14: -0.12 | D14: 0.87013889 | F14: =(778.316986673906/1071.4285639429*84.4691861500275)+84.4691861500275 -> 145.83007 | G14: * | H14: =H12/F12*F14 -> 127.38247 | J14: 283.81866 | L14: CLOSED | N14: CLOSED | O14: =SUM(F14:N14) -> 557.0312
A15: 45955 | B15: Sat | C15: 0.14 | D15: 0.89652778 | E15: * | F15: =F12/H12*H15 -> 19.186937 | H15: 16.759777 | J15: 98.666183 | L15: CLOSED | N15: CLOSED | O15: =SUM(F15:N15) -> 134.6129
A16: 45956 | B16: Sun | C16: 0.47 | D16: 0.92708333 | E16: * | F16: =F12/L12*L16 -> 46.514826 | G16: * | H16: =H12/L12*L16 -> 40.630669 | J16: CLOSED | L16: 44.440213 | N16: CLOSED | O16: =SUM(F16:N16) -> 131.58571
A18: 45964 | B18: Mon | C18: -0.1 | D18: 0.6875 | F18: =(190.476189145405/188.644687326699*441.458709771157)+441.458709771157 -> 887.20343 | G18: * | H18: =H19/L19*L18 -> 645.17236 | J18: CLOSED | L18: 636.84455 | N18: CLOSED | O18: =SUM(F18:N18) -> 2169.2203
A19: 45965 | B19: Tue | C19: -1.1 | D19: 0.71875 | E19: * | F19: =F22/L22*L19 -> 556.33584 | H19: 903.95477 | J19: CLOSED | L19: 892.28663 | N19: CLOSED | O19: =SUM(F19:N19) -> 2352.5772
A20: 45966 | B20: Wed | C20: -1.7 | D20: 0.75069444 | F20: =190.476189145405+188.644687326699 -> 379.12088 | G20: * | H20: =H21/J21*J20 -> 234.74856 | J20: 522.09946 | L20: CLOSED | N20: CLOSED | O20: =SUM(F20:N20) -> 1135.9689
A21: 45967 | B21: Thu | C21: -2 | D21: 0.78194444 | E21: * | F21: =F20/J20*J21 -> 403.86069 | H21: 250.06725 | J21: 556.16945 | L21: CLOSED | N21: CLOSED | O21: =SUM(F21:N21) -> 1210.0974
A22: 45968 | B22: Fri | C22: -1.9 | D22: 0.81527778 | F22: =(190.476189145405/188.644687326699*580.80805369401)+580.80805369401 -> 1167.255 | G22: * | H22: =H18/L18*L22 -> 1896.5985 | J22: CLOSED | L22: 1872.1175 | N22: CLOSED | O22: =SUM(F22:N22) -> 4935.971
A23: 45969 | B23: Sat | C23: -1.5 | D23: 0.85069444 | E23: * | F23: =F22/L22*L23 -> 1104.9002 | H23: 2324.0358 | J23: CLOSED | L23: 1772.1089 | N23: CLOSED | O23: =SUM(F23:N23) -> 5201.045
A24: 45970 | B24: Sun | C24: -0.9 | D24: 0.88819444 | E24: * | F24: =F20/J20*J24 -> 392.30132 | G24: * | H24: =H21/J21*J24 -> 242.90978 | J24: 540.25068 | L24: CLOSED | N24: CLOSED | O24: =SUM(F24:N24) -> 1175.4618
A26: 45979 | B26: Tue | C26: -0.02 | D26: 0.72083333 | E26: * | F26: =F29/J29*J26 -> 393.78813 | G26: * | H26: =H29/J29*J26 -> 721.06624 | J26: 829.8582 | L26: CLOSED | N26: CLOSED | O26: =SUM(F26:N26) -> 1944.7126
A27: 45980 | B27: Wed | C27: -0.3 | D27: 0.74444444 | F27: =(190.476189145405/188.644687326699*430.363510278513)+430.363510278513 -> 864.90531 | H27: 648.04469 | J27: CLOSED | L27: 319.48882 | N27: CLOSED | O27: =SUM(F27:N27) -> 1832.4388
A28: 45981 | B28: Thu | C28: -0.43 | D28: 0.76736111 | E28: * | F28: =F29/H29*H28 -> 206.76545 | H28: 378.60863 | J28: CLOSED | L28: 203.64964 | N28: CLOSED | O28: =SUM(F28:N28) -> 789.02372
A29: 45982 | B29: Fri | C29: -0.41 | D29: 0.79097222 | F29: =(190.476189145405/188.644687326699*137.772340604537)+137.772340604537 -> 276.88228 | H29: 506.9997 | J29: 583.49405 | L29: CLOSED | N29: CLOSED | O29: =SUM(F29:N29) -> 1367.376
A30: 45983 | B30: Sat | C30: -0.29 | D30: 0.81527778 | E30: * | F30: =F29/J29*J30 -> 581.23178 | G30: * | H30: =H29/J29*J30 -> 1064.2947 | J30: 1224.8718 | L30: CLOSED | N30: CLOSED | O30: =SUM(F30:N30) -> 2870.3982
A31: 45984 | B31: Sun | C31: -0.09 | D31: 0.84166667 | E31: * | F31: =F27/L27*L31 -> 576.01117 | G31: * | H31: =H28/L28*L31 -> 395.57138 | J31: CLOSED | L31: 212.77373 | N31: CLOSED | O31: =SUM(F31:N31) -> 1184.3563
A33: 45993 | B33: Tue | C33: -0.59 | D33: 0.67430556 | E33: * | F33: =F36/J36*J33 -> 955.58029 | G33: * | H33: =H36/J36*J33 -> 892.36414 | J33: 1269.4788 | L33: CLOSED | N33: CLOSED | O33: =SUM(F33:N33) -> 3117.4232
A34: 45994 | B34: Wed | C34: -1.4 | D34: 0.70763889 | F34: =608.928568836074+695.545762784605 -> 1304.4743 | H34: 1099.8526 | J34: CLOSED | L34: 1233.8476 | N34: CLOSED | O34: =SUM(F34:N34) -> 3638.1745
A35: 45995 | B35: Thu | C35: -1.9 | D35: 0.74097222 | E35: * | F35: =F34/L34*L35 -> 542.92009 | G35: * | H35: =H34/L34*L35 -> 457.75685 | J35: CLOSED | L35: 513.52535 | N35: CLOSED | O35: =SUM(F35:N35) -> 1514.2023
A36: 45996 | B36: Fri | C36: -2.05 | D36: 0.77361111 | F36: =(608.928568836074/695.545762784605*429.393999690455)+429.393999690455 -> 805.31502 | H36: 752.03963 | J36: 1069.8529 | L36: CLOSED | N36: CLOSED | O36: =SUM(F36:N36) -> 2627.2075
A37: 45997 | B37: Sat | C37: -1.86 | D37: 0.80694444 | E37: * | F37: =F36/J36*J37 -> 1127.0943 | G37: * | H37: =H36/J36*J37 -> 1052.5317 | J37: 1497.3335 | L37: CLOSED | N37: CLOSED | O37: =SUM(F37:N37) -> 3676.9595
A38: 45998 | B38: Sun | C38: -1.41 | D38: 0.84027778 | E38: * | F38: =F34/L34*L38 -> 228.84007 | G38: * | H38: =H34/L34*L38 -> 192.94388 | J38: CLOSED | L38: 216.45023 | N38: CLOSED | O38: =SUM(F38:N38) -> 638.23418
A39: 45999 | B39: Mon | C39: -0.78 | D39: 0.87430556 | E39: * | F39: =F34/L34*L39 -> 12.082756 | G39: * | H39: =H34/L34*L39 -> 10.187437 | J39: CLOSED | L39: 11.428572 | N39: CLOSED | O39: =SUM(F39:N39) -> 33.698765
A41: 46009 | B41: Thu | C41: -0.2 | D41: 0.73194444 | E41: * | F41: =F44/H44*H41 -> 132.38197 | H41: 126.17702 | J41: 147.32965 | L41: CLOSED | N41: CLOSED | O41: =SUM(F41:N41) -> 405.88864
A42: 46010 | B42: Fri | C42: -0.38 | D42: 0.75625 | F42: =(608.928568836074/695.545762784605*132.437612931347)+132.437612931347 -> 248.3826 | G42: * | H42: =H44/F44*F42 -> 236.74052 | J42: CLOSED | L42: 155.55695 | N42: CLOSED | O42: =SUM(F42:N42) -> 640.68007
A43: 46011 | B43: Sat | C43: -0.45 | D43: 0.78055556 | E43: * | F43: =F42/L42*L43 -> 401.42558 | G43: * | H43: =H42/L42*L43 -> 382.61014 | J43: CLOSED | L43: 251.40464 | N43: CLOSED | O43: =SUM(F43:N43) -> 1035.4403
A44: 46012 | B44: Sun | C44: -0.44 | D44: 0.80486111 | F44: =(608.928568836074/695.545762784605*47.1862984734357)+47.1862984734357 -> 88.496427 | H44: 84.348462 | J44: 196.5647 | L44: CLOSED | N44: CLOSED | O44: =SUM(F44:N44) -> 369.40959
A45: 46013 | B45: Mon | C45: -0.33 | D45: 0.82916667 | E45: * | F45: =F44/J44*J45 -> 38.404968 | G45: * | H45: =H44/J44*J45 -> 36.604868 | J45: 85.303569 | L45: CLOSED | N45: CLOSED | O45: =SUM(F45:N45) -> 160.3134
...

Sheet CPUE
A1: Date | B1: Day | C1: Tide | D1: Time | E1: Longbeach | G1: Twin Harbors | I1: Copalis | K1: Mocrocks | M1: Kalaloch | O1: Daily Totals
A2: 45936 | B2: Mon | C2: -0.21 | D2: 0.77430556 | E2: * | F2: 15 | H2: =+Harvest!H2/Effort!H2 -> 15 | J2: CLOSED | L2: =+Harvest!L2/Effort!L2 -> 15 | N2: CLOSED | O2: =+Harvest!O2/Effort!O2 -> 15
A3: 45937 | B3: Tue | C3: -0.95 | D3: 0.80416667 | F3: =+Harvest!F3/Effort!F3 -> 14.637981 | G3: * | H3: 14 | J3: CLOSED | L3: =+Harvest!L3/Effort!L3 -> 13.444444 | N3: CLOSED | O3: =+Harvest!O3/Effort!O3 -> 14.096784
A4: 45938 | B4: Wed | C4: -1.41 | D4: 0.83472222 | F4: 11.9 | G4: * | H4: 14 | J4: =+Harvest!J4/Effort!J4 -> 14.866667 | L4: CLOSED | N4: CLOSED | O4: =+Harvest!O4/Effort!O4 -> 13.835135
A5: 45939 | B5: Thu | C5: -1.51 | D5: 0.86736111 | E5: * | F5: 12 | H5: =+Harvest!H5/Effort!H5 -> 15 | J5: =+Harvest!J5/Effort!J5 -> 11.058824 | L5: CLOSED | N5: CLOSED | O5: =+Harvest!O5/Effort!O5 -> 12.68231
A6: 45940 | B6: Fri | C6: -1.28 | D6: 0.90277778 | F6: 15 | H6: =+Harvest!H6/Effort!H6 -> 15 | J6: CLOSED | L6: =+Harvest!L6/Effort!L6 -> 14.690909 | N6: CLOSED | O6: =+Harvest!O6/Effort!O6 -> 14.869308
A7: 45941 | B7: Sat | C7: -0.81 | D7: 0.94236111 | E7: * | F7: 12 | H7: =+Harvest!H7/Effort!H7 -> 10.294118 | J7: CLOSED | L7: =+Harvest!L7/Effort!L7 -> 14.88 | N7: CLOSED | O7: =+Harvest!O7/Effort!O7 -> 12.207806
A8: 45942 | B8: Sun | C8: -0.23 | D8: 0.98680556 | E8: * | F8: 7 | G8: * | H8: 7 | J8: =+Harvest!J8/Effort!J8 -> 6.9090909 | L8: CLOSED | N8: CLOSED | O8: =+Harvest!O8/Effort!O8 -> 6.9643896
A10: 45950 | B10: Mon | C10: 0.19 | D10: 0.77777778 | F10: 13.6 | H10: =+Harvest!H10/Effort!H10 -> 14.486486 | J10: =+Harvest!J10/Effort!J10 -> 13.511628 | L10: CLOSED | N10: CLOSED | O10: =+Harvest!O10/Effort!O10 -> 13.864616
A11: 45951 | B11: Tue | C11: -0.12 | D11: 0.80069444 | E11: * | F11: 7.5 | G11: * | H11: 7.5 | J11: =+Harvest!J11/Effort!J11 -> 7.5217391 | L11: CLOSED | N11: CLOSED | O11: =+Harvest!O11/Effort!O11 -> 7.5064434
A12: 45952 | B12: Wed | C12: -0.28 | D12: 0.82291667 | F12: 14.1 | H12: =+Harvest!H12/Effort!H12 -> 8.7222222 | J12: CLOSED | L12: =+Harvest!L12/Effort!L12 -> 14.909091 | N12: CLOSED | O12: =+Harvest!O12/Effort!O12 -> 12.712718
A13: 45953 | B13: Thu | C13: -0.27 | D13: 0.84583333 | E13: * | F13: 2 | G13: * | H13: 2 | J13: CLOSED | L13: 2 | N13: CLOSED | O13: =+Harvest!O13/Effort!O13 -> 2
A14: 45954 | B14: Fri | C14: -0.12 | D14: 0.87013889 | F14: 4 | G14: * | H14: 4 | J14: =+Harvest!J14/Effort!J14 -> 4 | L14: CLOSED | N14: CLOSED | O14: =+Harvest!O14/Effort!O14 -> 4
A15: 45955 | B15: Sat | C15: 0.14 | D15: 0.89652778 | E15: * | F15: 1 | H15: 1 | J15: 1 | L15: CLOSED | N15: CLOSED | O15: =+Harvest!O15/Effort!O15 -> 1
A16: 45956 | B16: Sun | C16: 0.47 | D16: 0.92708333 | E16: * | F16: 12 | G16: * | H16: 12 | J16: CLOSED | L16: =+Harvest!L16/Effort!L16 -> 11.8 | N16: CLOSED | O16: =+Harvest!O16/Effort!O16 -> 11.932454
A18: 45964 | B18: Mon | C18: -0.1 | D18: 0.6875 | F18: 13.8 | G18: * | H18: 13.5 | J18: CLOSED | L18: =+Harvest!L18/Effort!L18 -> 13.26087 | N18: CLOSED | O18: =+Harvest!O18/Effort!O18 -> 13.552494
A19: 45965 | B19: Tue | C19: -1.1 | D19: 0.71875 | E19: * | F19: 12.5 | H19: =+Harvest!H19/Effort!H19 -> 14.465116 | J19: CLOSED | L19: =+Harvest!L19/Effort!L19 -> 11.826087 | N19: CLOSED | O19: =+Harvest!O19/Effort!O19 -> 12.999475
A20: 45966 | B20: Wed | C20: -1.7 | D20: 0.75069444 | F20: 8 | G20: * | H20: 8 | J20: =+Harvest!J20/Effort!J20 -> 8.1666667 | L20: CLOSED | N20: CLOSED | O20: =+Harvest!O20/Effort!O20 -> 8.0766012
A21: 45967 | B21: Thu | C21: -2 | D21: 0.78194444 | E21: * | F21: 2 | H21: =+Harvest!H21/Effort!H21 -> 2.1538462 | J21: =+Harvest!J21/Effort!J21 -> 1.4166667 | L21: CLOSED | N21: CLOSED | O21: =+Harvest!O21/Effort!O21 -> 1.7636882
A22: 45968 | B22: Fri | C22: -1.9 | D22: 0.81527778 | F22: 13.5 | G22: * | H22: 13.5 | J22: CLOSED | L22: =+Harvest!L22/Effort!L22 -> 13.642857 | N22: CLOSED | O22: =+Harvest!O22/Effort!O22 -> 13.554183
A23: 45969 | B23: Sat | C23: -1.5 | D23: 0.85069444 | E23: * | F23: 14.5 | H23: =+Harvest!H23/Effort!H23 -> 15 | J23: CLOSED | L23: =+Harvest!L23/Effort!L23 -> 14.5 | N23: CLOSED | O23: =+Harvest!O23/Effort!O23 -> 14.72342
A24: 45970 | B24: Sun | C24: -0.9 | D24: 0.88819444 | E24: * | F24: 10.5 | G24: * | H24: 10.5 | J24: =+Harvest!J24/Effort!J24 -> 10.695652 | L24: CLOSED | N24: CLOSED | O24: =+Harvest!O24/Effort!O24 -> 10.589923
A26: 45979 | B26: Tue | C26: -0.02 | D26: 0.72083333 | E26: * | F26: 15 | G26: * | H26: 15 | J26: =+Harvest!J26/Effort!J26 -> 14.880952 | L26: CLOSED | N26: CLOSED | O26: =+Harvest!O26/Effort!O26 -> 14.949199
A27: 45980 | B27: Wed | C27: -0.3 | D27: 0.74444444 | F27: 13.8 | H27: =+Harvest!H27/Effort!H27 -> 15 | J27: CLOSED | L27: =+Harvest!L27/Effort!L27 -> 10 | N27: CLOSED | O27: =+Harvest!O27/Effort!O27 -> 13.561845
A28: 45981 | B28: Thu | C28: -0.43 | D28: 0.76736111 | E28: * | F28: 3 | H28: =+Harvest!H28/Effort!H28 -> 2.4 | J28: CLOSED | L28: =+Harvest!L28/Effort!L28 -> 3.1111111 | N28: CLOSED | O28: =+Harvest!O28/Effort!O28 -> 2.7407715
A29: 45982 | B29: Fri | C29: -0.41 | D29: 0.79097222 | F29: 15 | H29: =+Harvest!H29/Effort!H29 -> 14.666667 | J29: =+Harvest!J29/Effort!J29 -> 10.454545 | L29: CLOSED | N29: CLOSED | O29: =+Harvest!O29/Effort!O29 -> 12.936745
A30: 45983 | B30: Sat | C30: -0.29 | D30: 0.81527778 | E30: * | F30: 7 | G30: * | H30: 7 | J30: =+Harvest!J30/Effort!J30 -> 6.7777778 | L30: CLOSED | N30: CLOSED | O30: =+Harvest!O30/Effort!O30 -> 6.9051721
A31: 45984 | B31: Sun | C31: -0.09 | D31: 0.84166667 | E31: * | F31: 6 | G31: * | H31: 6 | J31: CLOSED | L31: =+Harvest!L31/Effort!L31 -> 5.8181818 | N31: CLOSED | O31: =+Harvest!O31/Effort!O31 -> 5.9673357
A33: 45993 | B33: Tue | C33: -0.59 | D33: 0.67430556 | E33: * | F33: 15 | G33: * | H33: 15 | J33: =+Harvest!J33/Effort!J33 -> 14.769231 | L33: CLOSED | N33: CLOSED | O33: =+Harvest!O33/Effort!O33 -> 14.906026
A34: 45994 | B34: Wed | C34: -1.4 | D34: 0.70763889 | F34: =+Harvest!F34/Effort!F34 -> 14.9656 | H34: =+Harvest!H34/Effort!H34 -> 15 | J34: CLOSED | L34: =+Harvest!L34/Effort!L34 -> 13.979167 | N34: CLOSED | O34: =+Harvest!O34/Effort!O34 -> 14.641461
A35: 45995 | B35: Thu | C35: -1.9 | D35: 0.74097222 | E35: * | F35: 12.5 | G35: * | H35: 12.5 | J35: CLOSED | L35: =+Harvest!L35/Effort!L35 -> 12 | N35: CLOSED | O35: =+Harvest!O35/Effort!O35 -> 12.33043
A36: 45996 | B36: Fri | C36: -2.05 | D36: 0.77361111 | F36: 15 | H36: =+Harvest!H36/Effort!H36 -> 9.7931034 | J36: =+Harvest!J36/Effort!J36 -> 12.866667 | L36: CLOSED | N36: CLOSED | O36: =+Harvest!O36/Effort!O36 -> 12.640786
A37: 45997 | B37: Sat | C37: -1.86 | D37: 0.80694444 | E37: * | F37: 12.5 | G37: * | H37: 12.5 | J37: =+Harvest!J37/Effort!J37 -> 12.555556 | L37: CLOSED | N37: CLOSED | O37: =+Harvest!O37/Effort!O37 -> 12.522623
A38: 45998 | B38: Sun | C38: -1.41 | D38: 0.84027778 | E38: * | F38: 10.5 | G38: * | H38: 10.5 | J38: CLOSED | L38: =+Harvest!L38/Effort!L38 -> 9.5 | N38: CLOSED | O38: =+Harvest!O38/Effort!O38 -> 10.160861
A39: 45999 | B39: Mon | C39: -0.78 | D39: 0.87430556 | E39: * | F39: 7 | G39: * | H39: 7 | J39: CLOSED | L39: =+Harvest!L39/Effort!L39 -> 5 | N39: CLOSED | O39: =+Harvest!O39/Effort!O39 -> 6.3217216
A41: 46009 | B41: Thu | C41: -0.2 | D41: 0.73194444 | E41: * | F41: 7 | H41: =+Harvest!H41/Effort!H41 -> 6.75 | J41: =+Harvest!J41/Effort!J41 -> 4.4444444 | L41: CLOSED | N41: CLOSED | O41: =+Harvest!O41/Effort!O41 -> 5.9946667
A42: 46010 | B42: Fri | C42: -0.38 | D42: 0.75625 | F42: 7 | G42: * | H42: 7 | J42: CLOSED | L42: =+Harvest!L42/Effort!L42 -> 3.8 | N42: CLOSED | O42: =+Harvest!O42/Effort!O42 -> 6.2230409
A43: 46011 | B43: Sat | C43: -0.45 | D43: 0.78055556 | E43: * | F43: 7 | G43: * | H43: 7 | J43: CLOSED | L43: =+Harvest!L43/Effort!L43 -> 4.6842105 | N43: CLOSED | O43: =+Harvest!O43/Effort!O43 -> 6.4377269
A44: 46012 | B44: Sun | C44: -0.44 | D44: 0.80486111 | F44: 15 | H44: =+Harvest!H44/Effort!H44 -> 13.375 | J44: =+Harvest!J44/Effort!J44 -> 12.25 | L44: CLOSED | N44: CLOSED | O44: =+Harvest!O44/Effort!O44 -> 13.16567
A45: 46013 | B45: Mon | C45: -0.33 | D45: 0.82916667 | E45: * | F45: 7 | G45: * | H45: 7 | J45: =+Harvest!J45/Effort!J45 -> 5.8333333 | L45: CLOSED | N45: CLOSED | O45: =+Harvest!O45/Effort!O45 -> 6.3792108
...

Sheet Summary Table
A1: 2025-2026 State (non-Tribal) Recreational Razor Clam Effort, Harvest and CPUE totals.
E2: LONG BEACH | H2: TWIN HARBORS | K2: COPALIS | N2: MOCROCKS | Q2: KALALOCH | T2: DAILY TOTALS | W2: CROSS | X2: CHECK
A3: DATE | B3: DAY | C3: TIDE | D3: TIME | E3: Effort | F3: Harvest | G3: CPUE | H3: Effort | I3: Harvest | J3: CPUE | K3: Effort | L3: Harvest | M3: CPUE | N3: Effort | O3: Harvest | P3: CPUE | Q3: Effort | R3: Harvest | S3: CPUE | T3: Effort | U3: Harvest
A4: 45936 | B4: Mon | C4: -0.21 | D4: 0.77430556 | E4: =Effort!F2 -> 1683.2536 | F4: =Harvest!F2 -> 25248.804 | G4: =+CPUE!F2 -> 15 | H4: =Effort!H2 -> 1801.0383 | I4: =Harvest!H2 -> 27015.574 | J4: =CPUE!H2 -> 15 | K4: =Effort!J2 -> CLOSED | L4: =Harvest!J2 -> CLOSED | M4: =CPUE!J2 -> CLOSED | N4: =Effort!L2 -> 1507.9975 | O4: =Harvest!L2 -> 22619.962 | P4: =CPUE!L2 -> 15 | Q4: CLOSED | R4: CLOSED | S4: CLOSED | T4: =SUM(E4,H4,K4,N4) -> 4992.2893 | U4: =SUM(F4,I4,L4,O4) -> 74884.34
A5: 45937 | B5: Tue | C5: -0.95 | D5: 0.80416667 | E5: =Effort!F3 -> 1849.7456 | F5: =Harvest!F3 -> 27076.54 | G5: =+CPUE!F3 -> 14.637981 | H5: =Effort!H3 -> 1556.9262 | I5: =Harvest!H3 -> 21796.967 | J5: =CPUE!H3 -> 14 | K5: =Effort!J3 -> CLOSED | L5: =Harvest!J3 -> CLOSED | M5: =CPUE!J3 -> CLOSED | N5: =Effort!L3 -> 1303.6041 | O5: =Harvest!L3 -> 17526.232 | P5: =CPUE!L3 -> 13.444444 | Q5: CLOSED | R5: CLOSED | S5: CLOSED | T5: =SUM(E5,H5,K5,N5) -> 4710.2759 | U5: =SUM(F5,I5,L5,O5) -> 66399.74
A6: 45938 | B6: Wed | C6: -1.41 | D6: 0.83472222 | E6: =Effort!F4 -> 951.02128 | F6: =Harvest!F4 -> 11317.153 | G6: =+CPUE!F4 -> 11.9 | H6: =Effort!H4 -> 1017.5684 | I6: =Harvest!H4 -> 14245.958 | J6: =CPUE!H4 -> 14 | K6: =Effort!J4 -> 1621.4665 | L6: =Harvest!J4 -> 24105.802 | M6: =CPUE!J4 -> 14.866667 | N6: =Effort!L4 -> CLOSED | O6: =Harvest!L4 -> CLOSED | P6: =CPUE!L4 -> CLOSED | Q6: CLOSED | R6: CLOSED | S6: CLOSED | T6: =SUM(E6,H6,K6,N6) -> 3590.0562 | U6: =SUM(F6,I6,L6,O6) -> 49668.913
A7: 45939 | B7: Thu | C7: -1.51 | D7: 0.86736111 | E7: =Effort!F5 -> 723.39233 | F7: =Harvest!F5 -> 8680.7079 | G7: =+CPUE!F5 -> 12 | H7: =Effort!H5 -> 774.01127 | I7: =Harvest!H5 -> 11610.169 | J7: =CPUE!H5 -> 15 | K7: =Effort!J5 -> 800.95523 | L7: =Harvest!J5 -> 8857.6225 | M7: =CPUE!J5 -> 11.058824 | N7: =Effort!L5 -> CLOSED | O7: =Harvest!L5 -> CLOSED | P7: =CPUE!L5 -> CLOSED | Q7: CLOSED | R7: CLOSED | S7: CLOSED | T7: =SUM(E7,H7,K7,N7) -> 2298.3588 | U7: =SUM(F7,I7,L7,O7) -> 29148.5
A8: 45940 | B8: Fri | C8: -1.28 | D8: 0.90277778 | E8: =Effort!F6 -> 822.03384 | F8: =Harvest!F6 -> 12330.508 | G8: =+CPUE!F6 -> 15 | H8: =Effort!H6 -> 879.55517 | I8: =Harvest!H6 -> 13193.328 | J8: =CPUE!H6 -> 15 | K8: =Effort!J6 -> CLOSED | L8: =Harvest!J6 -> CLOSED | M8: =CPUE!J6 -> CLOSED | N8: =Effort!L6 -> 1246.548 | O8: =Harvest!L6 -> 18312.923 | P8: =CPUE!L6 -> 14.690909 | Q8: CLOSED | R8: CLOSED | S8: CLOSED | T8: =SUM(E8,H8,K8,N8) -> 2948.137 | U8: =SUM(F8,I8,L8,O8) -> 43836.758
A9: 45941 | B9: Sat | C9: -0.81 | D9: 0.94236111 | E9: =Effort!F7 -> 850.46078 | F9: =Harvest!F7 -> 10205.529 | G9: =+CPUE!F7 -> 12 | H9: =Effort!H7 -> 909.97126 | I9: =Harvest!H7 -> 9367.3512 | J9: =CPUE!H7 -> 10.294118 | K9: =Effort!J7 -> CLOSED | L9: =Harvest!J7 -> CLOSED | M9: =CPUE!J7 -> CLOSED | N9: =Effort!L7 -> 717.812 | O9: =Harvest!L7 -> 10681.043 | P9: =CPUE!L7 -> 14.88 | Q9: CLOSED | R9: CLOSED | S9: CLOSED | T9: =SUM(E9,H9,K9,N9) -> 2478.244 | U9: =SUM(F9,I9,L9,O9) -> 30253.923
A10: 45942 | B10: Sun | C10: -0.23 | D10: 0.98680556 | E10: =Effort!F8 -> 82.964963 | F10: =Harvest!F8 -> 580.75474 | G10: =+CPUE!F8 -> 7 | H10: =Effort!H8 -> 136.69465 | I10: =Harvest!H8 -> 956.86256 | J10: =CPUE!H8 -> 7 | K10: =Effort!J8 -> 141.4531 | L10: =Harvest!J8 -> 977.31234 | M10: =CPUE!J8 -> 6.9090909 | N10: =Effort!L8 -> CLOSED | O10: =Harvest!L8 -> CLOSED | P10: =CPUE!L8 -> CLOSED | Q10: CLOSED | R10: CLOSED | S10: CLOSED | T10: =SUM(E10,H10,K10,N10) -> 361.11272 | U10: =SUM(F10,I10,L10,O10) -> 2514.9296
A11: Tide Series Totals | E11: =SUM(E4:E10) -> 6962.8723 | F11: =SUM(F4:F10) -> 95439.997 | G11: =+F11/E11 -> 13.706987 | H11: =SUM(H4:H10) -> 7075.7653 | I11: =SUM(I4:I10) -> 98186.21 | J11: =+I11/H11 -> 13.876409 | K11: =SUM(K4:K10) -> 2563.8748 | L11: =SUM(L4:L10) -> 33940.737 | M11: =+L11/K11 -> 13.238063 | N11: =SUM(N4:N10) -> 4775.9615 | O11: =SUM(O4:O10) -> 69140.16 | P11: =+O11/N11 -> 14.4767 | T11: =SUM(T4:T10) -> 21378.474 | U11: =SUM(U4:U10) -> 296707.1 | W11: =SUM(H11,K11,N11,Q11,E11) -> 21378.474 | X11: =SUM(R11,O11,L11,I11,F11) -> 296707.1
A12: 45950 | B12: Mon | C12: 0.19 | D12: 0.77777778 | E12: =Effort!F10 -> 1087.9318 | F12: =Harvest!F10 -> 14795.872 | G12: =+CPUE!F10 -> 13.6 | H12: =Effort!H10 -> 950.30766 | I12: =Harvest!H10 -> 13766.619 | J12: =CPUE!H10 -> 14.486486 | K12: =Effort!J10 -> 858.62272 | L12: =Harvest!J10 -> 11601.391 | M12: =CPUE!J10 -> 13.511628 | N12: =Effort!L10 -> CLOSED | O12: =Harvest!L10 -> CLOSED | P12: =CPUE!L10 -> CLOSED | Q12: CLOSED | R12: CLOSED | S12: CLOSED | T12: =SUM(E12,H12,K12,N12) -> 2896.8621 | U12: =SUM(F12,I12,L12,O12) -> 40163.882
A13: 45951 | B13: Tue | C13: -0.12 | D13: 0.80069444 | E13: =Effort!F11 -> 951.09748 | F13: =Harvest!F11 -> 7133.2311 | G13: =+CPUE!F11 -> 7.5 | H13: =Effort!H11 -> 830.78301 | I13: =Harvest!H11 -> 6230.8725 | J13: =CPUE!H11 -> 7.5 | K13: =Effort!J11 -> 750.62972 | L13: =Harvest!J11 -> 5646.0409 | M13: =CPUE!J11 -> 7.5217391 | N13: =Effort!L11 -> CLOSED | O13: =Harvest!L11 -> CLOSED | P13: =CPUE!L11 -> CLOSED | Q13: CLOSED | R13: CLOSED | S13: CLOSED | T13: =SUM(E13,H13,K13,N13) -> 2532.5102 | U13: =SUM(F13,I13,L13,O13) -> 19010.145
A14: 45952 | B14: Wed | C14: -0.28 | D14: 0.82291667 | E14: =Effort!F12 -> 334.90675 | F14: =Harvest!F12 -> 4722.1851 | G14: =+CPUE!F12 -> 14.1 | H14: =Effort!H12 -> 292.54082 | I14: =Harvest!H12 -> 2551.606 | J14: =CPUE!H12 -> 8.7222222 | K14: =Effort!J12 -> CLOSED | L14: =Harvest!J12 -> CLOSED | M14: =CPUE!J12 -> CLOSED | N14: =Effort!L12 -> 319.96954 | O14: =Harvest!L12 -> 4770.4549 | P14: =CPUE!L12 -> 14.909091 | Q14: CLOSED | R14: CLOSED | S14: CLOSED | T14: =SUM(E14,H14,K14,N14) -> 947.4171 | U14: =SUM(F14,I14,L14,O14) -> 12044.246
A15: 45953 | B15: Thu | C15: -0.27 | D15: 0.84583333 | E15: =Effort!F13 -> 90.202864 | F15: =Harvest!F13 -> 180.40573 | G15: =+CPUE!F13 -> 2 | H15: =Effort!H13 -> 78.792141 | I15: =Harvest!H13 -> 157.58428 | J15: =CPUE!H13 -> 2 | K15: =Effort!J13 -> CLOSED | L15: =Harvest!J13 -> CLOSED | M15: =CPUE!J13 -> CLOSED | N15: =Effort!L13 -> 86.179716 | O15: =Harvest!L13 -> 172.35943 | P15: =CPUE!L13 -> 2 | Q15: CLOSED | R15: CLOSED | S15: CLOSED | T15: =SUM(E15,H15,K15,N15) -> 255.17472 | U15: =SUM(F15,I15,L15,O15) -> 510.34944
A16: 45954 | B16: Fri | C16: -0.12 | D16: 0.87013889 | E16: =Effort!F14 -> 145.83007 | F16: =Harvest!F14 -> 583.32028 | G16: =+CPUE!F14 -> 4 | H16: =Effort!H14 -> 127.38247 | I16: =Harvest!H14 -> 509.52987 | J16: =CPUE!H14 -> 4 | K16: =Effort!J14 -> 283.81866 | L16: =Harvest!J14 -> 1135.2747 | M16: =CPUE!J14 -> 4 | N16: =Effort!L14 -> CLOSED | O16: =Harvest!L14 -> CLOSED | P16: =CPUE!L14 -> CLOSED | Q16: CLOSED | R16: CLOSED | S16: CLOSED | T16: =SUM(E16,H16,K16,N16) -> 557.0312 | U16: =SUM(F16,I16,L16,O16) -> 2228.1248
A17: 45955 | B17: Sat | C17: 0.14 | D17: 0.89652778 | E17: =Effort!F15 -> 19.186937 | F17: =Harvest!F15 -> 19.186937 | G17: =+CPUE!F15 -> 1 | H17: =Effort!H15 -> 16.759777 | I17: =Harvest!H15 -> 16.759777 | J17: =CPUE!H15 -> 1 | K17: =Effort!J15 -> 98.666183 | L17: =Harvest!J15 -> 98.666183 | M17: =CPUE!J15 -> 1 | N17: =Effort!L15 -> CLOSED | O17: =Harvest!L15 -> CLOSED | P17: =CPUE!L15 -> CLOSED | Q17: CLOSED | R17: CLOSED | S17: CLOSED | T17: =SUM(E17,H17,K17,N17) -> 134.6129 | U17: =SUM(F17,I17,L17,O17) -> 134.6129
A18: 45956 | B18: Sun | C18: 0.47 | D18: 0.92708333 | E18: =Effort!F16 -> 46.514826 | F18: =Harvest!F16 -> 558.17791 | G18: =+CPUE!F16 -> 12 | H18: =Effort!H16 -> 40.630669 | I18: =Harvest!H16 -> 487.56803 | J18: =CPUE!H16 -> 12 | K18: =Effort!J16 -> CLOSED | L18: =Harvest!J16 -> CLOSED | M18: =CPUE!J16 -> CLOSED | N18: =Effort!L16 -> 44.440213 | O18: =Harvest!L16 -> 524.39452 | P18: =CPUE!L16 -> 11.8 | Q18: CLOSED | R18: CLOSED | S18: CLOSED | T18: =SUM(E18,H18,K18,N18) -> 131.58571 | U18: =SUM(F18,I18,L18,O18) -> 1570.1405
A19: Tide Series Totals | E19: =SUM(E12:E18) -> 2675.6707 | F19: =SUM(F12:F18) -> 27992.379 | G19: =+F19/E19 -> 10.461818 | H19: =SUM(H12:H18) -> 2337.1965 | I19: =SUM(I12:I18) -> 23720.54 | J19: =+I19/H19 -> 10.149142 | K19: =SUM(K12:K18) -> 1991.7373 | L19: =SUM(L12:L18) -> 18481.373 | M19: =+L19/K19 -> 9.2790212 | N19: =SUM(N12:N18) -> 450.58947 | O19: =SUM(O12:O18) -> 5467.2089 | P19: =+O19/N19 -> 12.133459 | T19: =SUM(T12:T18) -> 7455.194 | U19: =SUM(U12:U18) -> 75661.5 | W19: =SUM(H19,K19,N19,Q19,E19) -> 7455.194 | X19: =SUM(R19,O19,L19,I19,F19) -> 75661.5
A20: 45964 | B20: Mon | C20: -0.1 | D20: 0.6875 | E20: =Effort!F18 -> 887.20343 | F20: =Harvest!F18 -> 12243.407 | G20: =+CPUE!F18 -> 13.8 | H20: =Effort!H18 -> 645.17236 | I20: =Harvest!H18 -> 8709.8269 | J20: =CPUE!H18 -> 13.5 | K20: =Effort!J18 -> CLOSED | L20: =Harvest!J18 -> CLOSED | M20: =CPUE!J18 -> CLOSED | N20: =Effort!L18 -> 636.84455 | O20: =Harvest!L18 -> 8445.1126 | P20: =CPUE!L18 -> 13.26087 | Q20: CLOSED | R20: CLOSED | S20: CLOSED | T20: =SUM(E20,H20,K20,N20) -> 2169.2203 | U20: =SUM(F20,I20,L20,O20) -> 29398.347
A21: 45965 | B21: Tue | C21: -1.1 | D21: 0.71875 | E21: =Effort!F19 -> 556.33584 | F21: =Harvest!F19 -> 6954.198 | G21: =+CPUE!F19 -> 12.5 | H21: =Effort!H19 -> 903.95477 | I21: =Harvest!H19 -> 13075.811 | J21: =CPUE!H19 -> 14.465116 | K21: =Effort!J19 -> CLOSED | L21: =Harvest!J19 -> CLOSED | M21: =CPUE!J19 -> CLOSED | N21: =Effort!L19 -> 892.28663 | O21: =Harvest!L19 -> 10552.259 | P21: =CPUE!L19 -> 11.826087 | Q21: CLOSED | R21: CLOSED | S21: CLOSED | T21: =SUM(E21,H21,K21,N21) -> 2352.5772 | U21: =SUM(F21,I21,L21,O21) -> 30582.268
A22: 45966 | B22: Wed | C22: -1.7 | D22: 0.75069444 | E22: =Effort!F20 -> 379.12088 | F22: =Harvest!F20 -> 3032.967 | G22: =+CPUE!F20 -> 8 | H22: =Effort!H20 -> 234.74856 | I22: =Harvest!H20 -> 1877.9885 | J22: =CPUE!H20 -> 8 | K22: =Effort!J20 -> 522.09946 | L22: =Harvest!J20 -> 4263.8123 | M22: =CPUE!J20 -> 8.1666667 | N22: =Effort!L20 -> CLOSED | O22: =Harvest!L20 -> CLOSED | P22: =CPUE!L20 -> CLOSED | Q22: CLOSED | R22: CLOSED | S22: CLOSED | T22: =SUM(E22,H22,K22,N22) -> 1135.9689 | U22: =SUM(F22,I22,L22,O22) -> 9174.7678
A23: 45967 | B23: Thu | C23: -2 | D23: 0.78194444 | E23: =Effort!F21 -> 403.86069 | F23: =Harvest!F21 -> 807.72137 | G23: =+CPUE!F21 -> 2 | H23: =Effort!H21 -> 250.06725 | I23: =Harvest!H21 -> 538.60638 | J23: =CPUE!H21 -> 2.1538462 | K23: =Effort!J21 -> 556.16945 | L23: =Harvest!J21 -> 787.90672 | M23: =CPUE!J21 -> 1.4166667 | N23: =Effort!L21 -> CLOSED | O23: =Harvest!L21 -> CLOSED | P23: =CPUE!L21 -> CLOSED | Q23: CLOSED | R23: CLOSED | S23: CLOSED | T23: =SUM(E23,H23,K23,N23) -> 1210.0974 | U23: =SUM(F23,I23,L23,O23) -> 2134.2345
A24: 45968 | B24: Fri | C24: -1.9 | D24: 0.81527778 | E24: =Effort!F22 -> 1167.255 | F24: =Harvest!F22 -> 15757.943 | G24: =+CPUE!F22 -> 13.5 | H24: =Effort!H22 -> 1896.5985 | I24: =Harvest!H22 -> 25604.08 | J24: =CPUE!H22 -> 13.5 | K24: =Effort!J22 -> CLOSED | L24: =Harvest!J22 -> CLOSED | M24: =CPUE!J22 -> CLOSED | N24: =Effort!L22 -> 1872.1175 | O24: =Harvest!L22 -> 25541.031 | P24: =CPUE!L22 -> 13.642857 | Q24: CLOSED | R24: CLOSED | S24: CLOSED | T24: =SUM(E24,H24,K24,N24) -> 4935.971 | U24: =SUM(F24,I24,L24,O24) -> 66903.055
A25: 45969 | B25: Sat | C25: -1.5 | D25: 0.85069444 | E25: =Effort!F23 -> 1104.9002 | F25: =Harvest!F23 -> 16021.053 | G25: =+CPUE!F23 -> 14.5 | H25: =Effort!H23 -> 2324.0358 | I25: =Harvest!H23 -> 34860.537 | J25: =CPUE!H23 -> 15 | K25: =Effort!J23 -> CLOSED | L25: =Harvest!J23 -> CLOSED | M25: =CPUE!J23 -> CLOSED | N25: =Effort!L23 -> 1772.1089 | O25: =Harvest!L23 -> 25695.579 | P25: =CPUE!L23 -> 14.5 | Q25: CLOSED | R25: CLOSED | S25: CLOSED | T25: =SUM(E25,H25,K25,N25) -> 5201.045 | U25: =SUM(F25,I25,L25,O25) -> 76577.17
A26: 45970 | B26: Sun | C26: -0.9 | D26: 0.88819444 | E26: =Effort!F24 -> 392.30132 | F26: =Harvest!F24 -> 4119.1639 | G26: =+CPUE!F24 -> 10.5 | H26: =Effort!H24 -> 242.90978 | I26: =Harvest!H24 -> 2550.5527 | J26: =CPUE!H24 -> 10.5 | K26: =Effort!J24 -> 540.25068 | L26: =Harvest!J24 -> 5778.3333 | M26: =CPUE!J24 -> 10.695652 | N26: =Effort!L24 -> CLOSED | O26: =Harvest!L24 -> CLOSED | P26: =CPUE!L24 -> CLOSED | Q26: CLOSED | R26: CLOSED | S26: CLOSED | T26: =SUM(E26,H26,K26,N26) -> 1175.4618 | U26: =SUM(F26,I26,L26,O26) -> 12448.05
A27: Tide Series Totals | E27: =SUM(E20:E26) -> 4890.9774 | F27: =SUM(F20:F26) -> 58936.454 | G27: =+F27/E27 -> 12.050036 | H27: =SUM(H20:H26) -> 6497.4871 | I27: =SUM(I20:I26) -> 87217.403 | J27: =+I27/H27 -> 13.423251 | K27: =SUM(K20:K26) -> 1618.5196 | L27: =SUM(L20:L26) -> 10830.052 | M27: =+L27/K27 -> 6.6913323 | N27: =SUM(N20:N26) -> 5173.3576 | O27: =SUM(O20:O26) -> 70233.983 | P27: =+O27/N27 -> 13.576093 | T27: =SUM(T20:T26) -> 18180.342 | U27: =SUM(U20:U26) -> 227217.89 | W27: =SUM(H27,K27,N27,Q27,E27) -> 18180.342 | X27: =SUM(R27,O27,L27,I27,F27) -> 227217.89
A28: 45979 | B28: Tue | C28: -0.02 | D28: 0.72083333 | E28: =Effort!F26 -> 393.78813 | F28: =Harvest!F26 -> 5906.8219 | G28: =+CPUE!F26 -> 15 | H28: =Effort!H26 -> 721.06624 | I28: =Harvest!H26 -> 10815.994 | J28: =CPUE!H26 -> 15 | K28: =Effort!J26 -> 829.8582 | L28: =Harvest!J26 -> 12349.08 | M28: =CPUE!J26 -> 14.880952 | N28: =Effort!L26 -> CLOSED | O28: =Harvest!L26 -> CLOSED | P28: =CPUE!L26 -> CLOSED | Q28: CLOSED | R28: CLOSED | S28: CLOSED | T28: =SUM(E28,H28,K28,N28) -> 1944.7126 | U28: =SUM(F28,I28,L28,O28) -> 29071.896
A29: 45980 | B29: Wed | C29: -0.3 | D29: 0.74444444 | E29: =Effort!F27 -> 864.90531 | F29: =Harvest!F27 -> 11935.693 | G29: =+CPUE!F27 -> 13.8 | H29: =Effort!H27 -> 648.04469 | I29: =Harvest!H27 -> 9720.6704 | J29: =CPUE!H27 -> 15 | K29: =Effort!J27 -> CLOSED | L29: =Harvest!J27 -> CLOSED | M29: =CPUE!J27 -> CLOSED | N29: =Effort!L27 -> 319.48882 | O29: =Harvest!L27 -> 3194.8882 | P29: =CPUE!L27 -> 10 | Q29: CLOSED | R29: CLOSED | S29: CLOSED | T29: =SUM(E29,H29,K29,N29) -> 1832.4388 | U29: =SUM(F29,I29,L29,O29) -> 24851.252
A30: 45981 | B30: Thu | C30: -0.43 | D30: 0.76736111 | E30: =Effort!F28 -> 206.76545 | F30: =Harvest!F28 -> 620.29634 | G30: =+CPUE!F28 -> 3 | H30: =Effort!H28 -> 378.60863 | I30: =Harvest!H28 -> 908.66071 | J30: =CPUE!H28 -> 2.4 | K30: =Effort!J28 -> CLOSED | L30: =Harvest!J28 -> CLOSED | M30: =CPUE!J28 -> CLOSED | N30: =Effort!L28 -> 203.64964 | O30: =Harvest!L28 -> 633.57667 | P30: =CPUE!L28 -> 3.1111111 | Q30: CLOSED | R30: CLOSED | S30: CLOSED | T30: =SUM(E30,H30,K30,N30) -> 789.02372 | U30: =SUM(F30,I30,L30,O30) -> 2162.5337
A31: 45982 | B31: Fri | C31: -0.41 | D31: 0.79097222 | E31: =Effort!F29 -> 276.88228 | F31: =Harvest!F29 -> 4153.2342 | G31: =+CPUE!F29 -> 15 | H31: =Effort!H29 -> 506.9997 | I31: =Harvest!H29 -> 7435.9956 | J31: =CPUE!H29 -> 14.666667 | K31: =Effort!J29 -> 583.49405 | L31: =Harvest!J29 -> 6100.165 | M31: =CPUE!J29 -> 10.454545 | N31: =Effort!L29 -> CLOSED | O31: =Harvest!L29 -> CLOSED | P31: =CPUE!L29 -> CLOSED | Q31: CLOSED | R31: CLOSED | S31: CLOSED | T31: =SUM(E31,H31,K31,N31) -> 1367.376 | U31: =SUM(F31,I31,L31,O31) -> 17689.395
A32: 45983 | B32: Sat | C32: -0.29 | D32: 0.81527778 | E32: =Effort!F30 -> 581.23178 | F32: =Harvest!F30 -> 4068.6224 | G32: =+CPUE!F30 -> 7 | H32: =Effort!H30 -> 1064.2947 | I32: =Harvest!H30 -> 7450.0628 | J32: =CPUE!H30 -> 7 | K32: =Effort!J30 -> 1224.8718 | L32: =Harvest!J30 -> 8301.9086 | M32: =CPUE!J30 -> 6.7777778 | N32: =Effort!L30 -> CLOSED | O32: =Harvest!L30 -> CLOSED | P32: =CPUE!L30 -> CLOSED | Q32: CLOSED | R32: CLOSED | S32: CLOSED | T32: =SUM(E32,H32,K32,N32) -> 2870.3982 | U32: =SUM(F32,I32,L32,O32) -> 19820.594
A33: 45984 | B33: Sun | C33: -0.09 | D33: 0.84166667 | E33: =Effort!F31 -> 576.01117 | F33: =Harvest!F31 -> 3456.067 | G33: =+CPUE!F31 -> 6 | H33: =Effort!H31 -> 395.57138 | I33: =Harvest!H31 -> 2373.4283 | J33: =CPUE!H31 -> 6 | K33: =Effort!J31 -> CLOSED | L33: =Harvest!J31 -> CLOSED | M33: =CPUE!J31 -> CLOSED | N33: =Effort!L31 -> 212.77373 | O33: =Harvest!L31 -> 1237.9563 | P33: =CPUE!L31 -> 5.8181818 | Q33: CLOSED | R33: CLOSED | S33: CLOSED | T33: =SUM(E33,H33,K33,N33) -> 1184.3563 | U33: =SUM(F33,I33,L33,O33) -> 7067.4516
A34: Tide Series Totals | E34: =SUM(E28:E33) -> 2899.5841 | F34: =SUM(F28:F33) -> 30140.735 | G34: =+F34/E34 -> 10.394848 | H34: =SUM(H28:H33) -> 3714.5853 | I34: =SUM(I28:I33) -> 38704.811 | J34: =+I34/H34 -> 10.419686 | K34: =SUM(K28:K33) -> 2638.224 | L34: =SUM(L28:L33) -> 26751.154 | M34: =+L34/K34 -> 10.139834 | N34: =SUM(N28:N33) -> 735.91219 | O34: =SUM(O28:O33) -> 5066.4211 | P34: =+O34/N34 -> 6.8845457 | T34: =SUM(T28:T33) -> 9988.3056 | U34: =SUM(U28:U33) -> 100663.12 | W34: =SUM(H34,K34,N34,Q34,E34) -> 9988.3056 | X34: =SUM(R34,O34,L34,I34,F34) -> 100663.12
A35: 45993 | B35: Tue | C35: -0.59 | D35: 0.67430556 | E35: =Effort!F33 -> 955.58029 | F35: =Harvest!F33 -> 14333.704 | G35: =+CPUE!F33 -> 15 | H35: =Effort!H33 -> 892.36414 | I35: =Harvest!H33 -> 13385.462 | J35: =CPUE!H33 -> 15 | K35: =Effort!J33 -> 1269.4788 | L35: =Harvest!J33 -> 18749.225 | M35: =CPUE!J33 -> 14.769231 | N35: =Effort!L33 -> CLOSED | O35: =Harvest!L33 -> CLOSED | P35: =CPUE!L33 -> CLOSED | Q35: CLOSED | R35: CLOSED | S35: CLOSED | T35: =SUM(E35,H35,K35,N35) -> 3117.4232 | U35: =SUM(F35,I35,L35,O35) -> 46468.391
A36: 45994 | B36: Wed | C36: -1.4 | D36: 0.70763889 | E36: =Effort!F34 -> 1304.4743 | F36: =Harvest!F34 -> 19522.241 | G36: =+CPUE!F34 -> 14.9656 | H36: =Effort!H34 -> 1099.8526 | I36: =Harvest!H34 -> 16497.789 | J36: =CPUE!H34 -> 15 | K36: =Effort!J34 -> CLOSED | L36: =Harvest!J34 -> CLOSED | M36: =CPUE!J34 -> CLOSED | N36: =Effort!L34 -> 1233.8476 | O36: =Harvest!L34 -> 17248.161 | P36: =CPUE!L34 -> 13.979167 | Q36: CLOSED | R36: CLOSED | S36: CLOSED | T36: =SUM(E36,H36,K36,N36) -> 3638.1745 | U36: =SUM(F36,I36,L36,O36) -> 53268.191
A37: 45995 | B37: Thu | C37: -1.9 | D37: 0.74097222 | E37: =Effort!F35 -> 542.92009 | F37: =Harvest!F35 -> 6786.5011 | G37: =+CPUE!F35 -> 12.5 | H37: =Effort!H35 -> 457.75685 | I37: =Harvest!H35 -> 5721.9606 | J37: =CPUE!H35 -> 12.5 | K37: =Effort!J35 -> CLOSED | L37: =Harvest!J35 -> CLOSED | M37: =CPUE!J35 -> CLOSED | N37: =Effort!L35 -> 513.52535 | O37: =Harvest!L35 -> 6162.3041 | P37: =CPUE!L35 -> 12 | Q37: CLOSED | R37: CLOSED | S37: CLOSED | T37: =SUM(E37,H37,K37,N37) -> 1514.2023 | U37: =SUM(F37,I37,L37,O37) -> 18670.766
A38: 45996 | B38: Fri | C38: -2.05 | D38: 0.77361111 | E38: =Effort!F36 -> 805.31502 | F38: =Harvest!F36 -> 12079.725 | G38: =+CPUE!F36 -> 15 | H38: =Effort!H36 -> 752.03963 | I38: =Harvest!H36 -> 7364.8019 | J38: =CPUE!H36 -> 9.7931034 | K38: =Effort!J36 -> 1069.8529 | L38: =Harvest!J36 -> 13765.44 | M38: =CPUE!J36 -> 12.866667 | N38: =Effort!L36 -> CLOSED | O38: =Harvest!L36 -> CLOSED | P38: =CPUE!L36 -> CLOSED | Q38: CLOSED | R38: CLOSED | S38: CLOSED | T38: =SUM(E38,H38,K38,N38) -> 2627.2075 | U38: =SUM(F38,I38,L38,O38) -> 33209.968
A39: 45997 | B39: Sat | C39: -1.86 | D39: 0.80694444 | E39: =Effort!F37 -> 1127.0943 | F39: =Harvest!F37 -> 14088.679 | G39: =+CPUE!F37 -> 12.5 | H39: =Effort!H37 -> 1052.5317 | I39: =Harvest!H37 -> 13156.647 | J39: =CPUE!H37 -> 12.5 | K39: =Effort!J37 -> 1497.3335 | L39: =Harvest!J37 -> 18799.854 | M39: =CPUE!J37 -> 12.555556 | N39: =Effort!L37 -> CLOSED | O39: =Harvest!L37 -> CLOSED | P39: =CPUE!L37 -> CLOSED | Q39: CLOSED | R39: CLOSED | S39: CLOSED | T39: =SUM(E39,H39,K39,N39) -> 3676.9595 | U39: =SUM(F39,I39,L39,O39) -> 46045.179
A40: 45998 | B40: Sun | C40: -1.41 | D40: 0.84027778 | E40: =Effort!F38 -> 228.84007 | F40: =Harvest!F38 -> 2402.8207 | G40: =+CPUE!F38 -> 10.5 | H40: =Effort!H38 -> 192.94388 | I40: =Harvest!H38 -> 2025.9108 | J40: =CPUE!H38 -> 10.5 | K40: =Effort!J38 -> CLOSED | L40: =Harvest!J38 -> CLOSED | M40: =CPUE!J38 -> CLOSED | N40: =Effort!L38 -> 216.45023 | O40: =Harvest!L38 -> 2056.2771 | P40: =CPUE!L38 -> 9.5 | Q40: CLOSED | R40: CLOSED | S40: CLOSED | T40: =SUM(E40,H40,K40,N40) -> 638.23418 | U40: =SUM(F40,I40,L40,O40) -> 6485.0087
...

Sheet Summary Table Public
A1: 2025-2026 State (non-Tribal) Recreational Razor Clam Effort, Harvest and CPUE totals.
E2: LONG BEACH | H2: TWIN HARBORS | K2: COPALIS | N2: MOCROCKS | Q2: KALALOCH | T2: DAILY TOTALS | W2: CROSS | X2: CHECK
A3: DATE | B3: DAY | C3: TIDE | D3: TIME | E3: Effort | F3: Harvest | G3: CPUE | H3: Effort | I3: Harvest | J3: CPUE | K3: Effort | L3: Harvest | M3: CPUE | N3: Effort | O3: Harvest | P3: CPUE | Q3: Effort | R3: Harvest | S3: CPUE | T3: Effort | U3: Harvest
A4: 45936 | B4: Mon | C4: -0.21 | D4: 0.77430556 | E4: =Effort!F2 -> 1683.2536 | F4: =Harvest!F2 -> 25248.804 | G4: =+CPUE!F2 -> 15 | H4: =Effort!H2 -> 1801.0383 | I4: =Harvest!H2 -> 27015.574 | J4: =CPUE!H2 -> 15 | K4: =Effort!J2 -> CLOSED | L4: =Harvest!J2 -> CLOSED | M4: =CPUE!J2 -> CLOSED | N4: =Effort!L2 -> 1507.9975 | O4: =Harvest!L2 -> 22619.962 | P4: =CPUE!L2 -> 15 | Q4: CLOSED | R4: CLOSED | S4: CLOSED | T4: =SUM(E4,H4,K4,N4) -> 4992.2893 | U4: =SUM(F4,I4,L4,O4) -> 74884.34
A5: 45937 | B5: Tue | C5: -0.95 | D5: 0.80416667 | E5: =Effort!F3 -> 1849.7456 | F5: =Harvest!F3 -> 27076.54 | G5: =+CPUE!F3 -> 14.637981 | H5: =Effort!H3 -> 1556.9262 | I5: =Harvest!H3 -> 21796.967 | J5: =CPUE!H3 -> 14 | K5: =Effort!J3 -> CLOSED | L5: =Harvest!J3 -> CLOSED | M5: =CPUE!J3 -> CLOSED | N5: =Effort!L3 -> 1303.6041 | O5: =Harvest!L3 -> 17526.232 | P5: =CPUE!L3 -> 13.444444 | Q5: CLOSED | R5: CLOSED | S5: CLOSED | T5: =SUM(E5,H5,K5,N5) -> 4710.2759 | U5: =SUM(F5,I5,L5,O5) -> 66399.74
A6: 45938 | B6: Wed | C6: -1.41 | D6: 0.83472222 | E6: =Effort!F4 -> 951.02128 | F6: =Harvest!F4 -> 11317.153 | G6: =+CPUE!F4 -> 11.9 | H6: =Effort!H4 -> 1017.5684 | I6: =Harvest!H4 -> 14245.958 | J6: =CPUE!H4 -> 14 | K6: =Effort!J4 -> 1621.4665 | L6: =Harvest!J4 -> 24105.802 | M6: =CPUE!J4 -> 14.866667 | N6: =Effort!L4 -> CLOSED | O6: =Harvest!L4 -> CLOSED | P6: =CPUE!L4 -> CLOSED | Q6: CLOSED | R6: CLOSED | S6: CLOSED | T6: =SUM(E6,H6,K6,N6) -> 3590.0562 | U6: =SUM(F6,I6,L6,O6) -> 49668.913
A7: 45939 | B7: Thu | C7: -1.51 | D7: 0.86736111 | E7: =Effort!F5 -> 723.39233 | F7: =Harvest!F5 -> 8680.7079 | G7: =+CPUE!F5 -> 12 | H7: =Effort!H5 -> 774.01127 | I7: =Harvest!H5 -> 11610.169 | J7: =CPUE!H5 -> 15 | K7: =Effort!J5 -> 800.95523 | L7: =Harvest!J5 -> 8857.6225 | M7: =CPUE!J5 -> 11.058824 | N7: =Effort!L5 -> CLOSED | O7: =Harvest!L5 -> CLOSED | P7: =CPUE!L5 -> CLOSED | Q7: CLOSED | R7: CLOSED | S7: CLOSED | T7: =SUM(E7,H7,K7,N7) -> 2298.3588 | U7: =SUM(F7,I7,L7,O7) -> 29148.5
A8: 45940 | B8: Fri | C8: -1.28 | D8: 0.90277778 | E8: =Effort!F6 -> 822.03384 | F8: =Harvest!F6 -> 12330.508 | G8: =+CPUE!F6 -> 15 | H8: =Effort!H6 -> 879.55517 | I8: =Harvest!H6 -> 13193.328 | J8: =CPUE!H6 -> 15 | K8: =Effort!J6 -> CLOSED | L8: =Harvest!J6 -> CLOSED | M8: =CPUE!J6 -> CLOSED | N8: =Effort!L6 -> 1246.548 | O8: =Harvest!L6 -> 18312.923 | P8: =CPUE!L6 -> 14.690909 | Q8: CLOSED | R8: CLOSED | S8: CLOSED | T8: =SUM(E8,H8,K8,N8) -> 2948.137 | U8: =SUM(F8,I8,L8,O8) -> 43836.758
A9: 45941 | B9: Sat | C9: -0.81 | D9: 0.94236111 | E9: =Effort!F7 -> 850.46078 | F9: =Harvest!F7 -> 10205.529 | G9: =+CPUE!F7 -> 12 | H9: =Effort!H7 -> 909.97126 | I9: =Harvest!H7 -> 9367.3512 | J9: =CPUE!H7 -> 10.294118 | K9: =Effort!J7 -> CLOSED | L9: =Harvest!J7 -> CLOSED | M9: =CPUE!J7 -> CLOSED | N9: =Effort!L7 -> 717.812 | O9: =Harvest!L7 -> 10681.043 | P9: =CPUE!L7 -> 14.88 | Q9: CLOSED | R9: CLOSED | S9: CLOSED | T9: =SUM(E9,H9,K9,N9) -> 2478.244 | U9: =SUM(F9,I9,L9,O9) -> 30253.923
A10: 45942 | B10: Sun | C10: -0.23 | D10: 0.98680556 | E10: =Effort!F8 -> 82.964963 | F10: =Harvest!F8 -> 580.75474 | G10: =+CPUE!F8 -> 7 | H10: =Effort!H8 -> 136.69465 | I10: =Harvest!H8 -> 956.86256 | J10: =CPUE!H8 -> 7 | K10: =Effort!J8 -> 141.4531 | L10: =Harvest!J8 -> 977.31234 | M10: =CPUE!J8 -> 6.9090909 | N10: =Effort!L8 -> CLOSED | O10: =Harvest!L8 -> CLOSED | P10: =CPUE!L8 -> CLOSED | Q10: CLOSED | R10: CLOSED | S10: CLOSED | T10: =SUM(E10,H10,K10,N10) -> 361.11272 | U10: =SUM(F10,I10,L10,O10) -> 2514.9296
A11: Tide Series Totals | E11: =SUM(E4:E10) -> 6962.8723 | F11: =SUM(F4:F10) -> 95439.997 | G11: =+F11/E11 -> 13.706987 | H11: =SUM(H4:H10) -> 7075.7653 | I11: =SUM(I4:I10) -> 98186.21 | J11: =+I11/H11 -> 13.876409 | K11: =SUM(K4:K10) -> 2563.8748 | L11: =SUM(L4:L10) -> 33940.737 | M11: =+L11/K11 -> 13.238063 | N11: =SUM(N4:N10) -> 4775.9615 | O11: =SUM(O4:O10) -> 69140.16 | P11: 0 | T11: =SUM(T4:T10) -> 21378.474 | U11: =SUM(U4:U10) -> 296707.1 | W11: =SUM(H11,K11,N11,Q11,E11) -> 21378.474 | X11: =SUM(R11,O11,L11,I11,F11) -> 296707.1
A12: 45950 | B12: Mon | C12: 0.19 | D12: 0.77777778 | E12: =Effort!F10 -> 1087.9318 | F12: =Harvest!F10 -> 14795.872 | G12: =+CPUE!F10 -> 13.6 | H12: =Effort!H10 -> 950.30766 | I12: =Harvest!H10 -> 13766.619 | J12: =CPUE!H10 -> 14.486486 | K12: =Effort!J10 -> 858.62272 | L12: =Harvest!J10 -> 11601.391 | M12: =CPUE!J10 -> 13.511628 | N12: =Effort!L10 -> CLOSED | O12: =Harvest!L10 -> CLOSED | P12: =CPUE!L10 -> CLOSED | Q12: CLOSED | R12: CLOSED | S12: CLOSED | T12: =SUM(E12,H12,K12,N12) -> 2896.8621 | U12: =SUM(F12,I12,L12,O12) -> 40163.882
A13: 45951 | B13: Tue | C13: -0.12 | D13: 0.80069444 | E13: =Effort!F11 -> 951.09748 | F13: =Harvest!F11 -> 7133.2311 | G13: =+CPUE!F11 -> 7.5 | H13: =Effort!H11 -> 830.78301 | I13: =Harvest!H11 -> 6230.8725 | J13: =CPUE!H11 -> 7.5 | K13: =Effort!J11 -> 750.62972 | L13: =Harvest!J11 -> 5646.0409 | M13: =CPUE!J11 -> 7.5217391 | N13: =Effort!L11 -> CLOSED | O13: =Harvest!L11 -> CLOSED | P13: =CPUE!L11 -> CLOSED | Q13: CLOSED | R13: CLOSED | S13: CLOSED | T13: =SUM(E13,H13,K13,N13) -> 2532.5102 | U13: =SUM(F13,I13,L13,O13) -> 19010.145
A14: 45952 | B14: Wed | C14: -0.28 | D14: 0.82291667 | E14: =Effort!F12 -> 334.90675 | F14: =Harvest!F12 -> 4722.1851 | G14: =+CPUE!F12 -> 14.1 | H14: =Effort!H12 -> 292.54082 | I14: =Harvest!H12 -> 2551.606 | J14: =CPUE!H12 -> 8.7222222 | K14: =Effort!J12 -> CLOSED | L14: =Harvest!J12 -> CLOSED | M14: =CPUE!J12 -> CLOSED | N14: =Effort!L12 -> 319.96954 | O14: =Harvest!L12 -> 4770.4549 | P14: =CPUE!L12 -> 14.909091 | Q14: CLOSED | R14: CLOSED | S14: CLOSED | T14: =SUM(E14,H14,K14,N14) -> 947.4171 | U14: =SUM(F14,I14,L14,O14) -> 12044.246
A15: 45953 | B15: Thu | C15: -0.27 | D15: 0.84583333 | E15: =Effort!F13 -> 90.202864 | F15: =Harvest!F13 -> 180.40573 | G15: =+CPUE!F13 -> 2 | H15: =Effort!H13 -> 78.792141 | I15: =Harvest!H13 -> 157.58428 | J15: =CPUE!H13 -> 2 | K15: =Effort!J13 -> CLOSED | L15: =Harvest!J13 -> CLOSED | M15: =CPUE!J13 -> CLOSED | N15: =Effort!L13 -> 86.179716 | O15: =Harvest!L13 -> 172.35943 | P15: =CPUE!L13 -> 2 | Q15: CLOSED | R15: CLOSED | S15: CLOSED | T15: =SUM(E15,H15,K15,N15) -> 255.17472 | U15: =SUM(F15,I15,L15,O15) -> 510.34944
A16: 45954 | B16: Fri | C16: -0.12 | D16: 0.87013889 | E16: =Effort!F14 -> 145.83007 | F16: =Harvest!F14 -> 583.32028 | G16: =+CPUE!F14 -> 4 | H16: =Effort!H14 -> 127.38247 | I16: =Harvest!H14 -> 509.52987 | J16: =CPUE!H14 -> 4 | K16: =Effort!J14 -> 283.81866 | L16: =Harvest!J14 -> 1135.2747 | M16: =CPUE!J14 -> 4 | N16: =Effort!L14 -> CLOSED | O16: =Harvest!L14 -> CLOSED | P16: =CPUE!L14 -> CLOSED | Q16: CLOSED | R16: CLOSED | S16: CLOSED | T16: =SUM(E16,H16,K16,N16) -> 557.0312 | U16: =SUM(F16,I16,L16,O16) -> 2228.1248
A17: 45955 | B17: Sat | C17: 0.14 | D17: 0.89652778 | E17: =Effort!F15 -> 19.186937 | F17: =Harvest!F15 -> 19.186937 | G17: =+CPUE!F15 -> 1 | H17: =Effort!H15 -> 16.759777 | I17: =Harvest!H15 -> 16.759777 | J17: =CPUE!H15 -> 1 | K17: =Effort!J15 -> 98.666183 | L17: =Harvest!J15 -> 98.666183 | M17: =CPUE!J15 -> 1 | N17: =Effort!L15 -> CLOSED | O17: =Harvest!L15 -> CLOSED | P17: =CPUE!L15 -> CLOSED | Q17: CLOSED | R17: CLOSED | S17: CLOSED | T17: =SUM(E17,H17,K17,N17) -> 134.6129 | U17: =SUM(F17,I17,L17,O17) -> 134.6129
A18: 45956 | B18: Sun | C18: 0.47 | D18: 0.92708333 | E18: =Effort!F16 -> 46.514826 | F18: =Harvest!F16 -> 558.17791 | G18: =+CPUE!F16 -> 12 | H18: =Effort!H16 -> 40.630669 | I18: =Harvest!H16 -> 487.56803 | J18: =CPUE!H16 -> 12 | K18: =Effort!J16 -> CLOSED | L18: =Harvest!J16 -> CLOSED | M18: =CPUE!J16 -> CLOSED | N18: =Effort!L16 -> 44.440213 | O18: =Harvest!L16 -> 524.39452 | P18: =CPUE!L16 -> 11.8 | Q18: CLOSED | R18: CLOSED | S18: CLOSED | T18: =SUM(E18,H18,K18,N18) -> 131.58571 | U18: =SUM(F18,I18,L18,O18) -> 1570.1405
A19: Tide Series Totals | E19: =SUM(E12:E18) -> 2675.6707 | F19: =SUM(F12:F18) -> 27992.379 | G19: =+F19/E19 -> 10.461818 | H19: =SUM(H12:H18) -> 2337.1965 | I19: =SUM(I12:I18) -> 23720.54 | J19: =+I19/H19 -> 10.149142 | K19: =SUM(K12:K18) -> 1991.7373 | L19: =SUM(L12:L18) -> 18481.373 | M19: =+L19/K19 -> 9.2790212 | N19: =SUM(N12:N18) -> 450.58947 | O19: =SUM(O12:O18) -> 5467.2089 | P19: =+O19/N19 -> 12.133459 | T19: =SUM(T12:T18) -> 7455.194 | U19: =SUM(U12:U18) -> 75661.5 | W19: =SUM(H19,K19,N19,Q19,E19) -> 7455.194 | X19: =SUM(R19,O19,L19,I19,F19) -> 75661.5
A20: 45964 | B20: Mon | C20: -0.1 | D20: 0.6875 | E20: =Effort!F18 -> 887.20343 | F20: =Harvest!F18 -> 12243.407 | G20: =+CPUE!F18 -> 13.8 | H20: =Effort!H18 -> 645.17236 | I20: =Harvest!H18 -> 8709.8269 | J20: =CPUE!H18 -> 13.5 | K20: =Effort!J18 -> CLOSED | L20: =Harvest!J18 -> CLOSED | M20: =CPUE!J18 -> CLOSED | N20: =Effort!L18 -> 636.84455 | O20: =Harvest!L18 -> 8445.1126 | P20: =CPUE!L18 -> 13.26087 | Q20: CLOSED | R20: CLOSED | S20: CLOSED | T20: =SUM(E20,H20,K20,N20) -> 2169.2203 | U20: =SUM(F20,I20,L20,O20) -> 29398.347
A21: 45965 | B21: Tue | C21: -1.1 | D21: 0.71875 | E21: =Effort!F19 -> 556.33584 | F21: =Harvest!F19 -> 6954.198 | G21: =+CPUE!F19 -> 12.5 | H21: =Effort!H19 -> 903.95477 | I21: =Harvest!H19 -> 13075.811 | J21: =CPUE!H19 -> 14.465116 | K21: =Effort!J19 -> CLOSED | L21: =Harvest!J19 -> CLOSED | M21: =CPUE!J19 -> CLOSED | N21: =Effort!L19 -> 892.28663 | O21: =Harvest!L19 -> 10552.259 | P21: =CPUE!L19 -> 11.826087 | Q21: CLOSED | R21: CLOSED | S21: CLOSED | T21: =SUM(E21,H21,K21,N21) -> 2352.5772 | U21: =SUM(F21,I21,L21,O21) -> 30582.268
A22: 45966 | B22: Wed | C22: -1.7 | D22: 0.75069444 | E22: =Effort!F20 -> 379.12088 | F22: =Harvest!F20 -> 3032.967 | G22: =+CPUE!F20 -> 8 | H22: =Effort!H20 -> 234.74856 | I22: =Harvest!H20 -> 1877.9885 | J22: =CPUE!H20 -> 8 | K22: =Effort!J20 -> 522.09946 | L22: =Harvest!J20 -> 4263.8123 | M22: =CPUE!J20 -> 8.1666667 | N22: =Effort!L20 -> CLOSED | O22: =Harvest!L20 -> CLOSED | P22: =CPUE!L20 -> CLOSED | Q22: CLOSED | R22: CLOSED | S22: CLOSED | T22: =SUM(E22,H22,K22,N22) -> 1135.9689 | U22: =SUM(F22,I22,L22,O22) -> 9174.7678
A23: 45967 | B23: Thu | C23: -2 | D23: 0.78194444 | E23: =Effort!F21 -> 403.86069 | F23: =Harvest!F21 -> 807.72137 | G23: =+CPUE!F21 -> 2 | H23: =Effort!H21 -> 250.06725 | I23: =Harvest!H21 -> 538.60638 | J23: =CPUE!H21 -> 2.1538462 | K23: =Effort!J21 -> 556.16945 | L23: =Harvest!J21 -> 787.90672 | M23: =CPUE!J21 -> 1.4166667 | N23: =Effort!L21 -> CLOSED | O23: =Harvest!L21 -> CLOSED | P23: =CPUE!L21 -> CLOSED | Q23: CLOSED | R23: CLOSED | S23: CLOSED | T23: =SUM(E23,H23,K23,N23) -> 1210.0974 | U23: =SUM(F23,I23,L23,O23) -> 2134.2345
A24: 45968 | B24: Fri | C24: -1.9 | D24: 0.81527778 | E24: =Effort!F22 -> 1167.255 | F24: =Harvest!F22 -> 15757.943 | G24: =+CPUE!F22 -> 13.5 | H24: =Effort!H22 -> 1896.5985 | I24: =Harvest!H22 -> 25604.08 | J24: =CPUE!H22 -> 13.5 | K24: =Effort!J22 -> CLOSED | L24: =Harvest!J22 -> CLOSED | M24: =CPUE!J22 -> CLOSED | N24: =Effort!L22 -> 1872.1175 | O24: =Harvest!L22 -> 25541.031 | P24: =CPUE!L22 -> 13.642857 | Q24: CLOSED | R24: CLOSED | S24: CLOSED | T24: =SUM(E24,H24,K24,N24) -> 4935.971 | U24: =SUM(F24,I24,L24,O24) -> 66903.055
A25: 45969 | B25: Sat | C25: -1.5 | D25: 0.85069444 | E25: =Effort!F23 -> 1104.9002 | F25: =Harvest!F23 -> 16021.053 | G25: =+CPUE!F23 -> 14.5 | H25: =Effort!H23 -> 2324.0358 | I25: =Harvest!H23 -> 34860.537 | J25: =CPUE!H23 -> 15 | K25: =Effort!J23 -> CLOSED | L25: =Harvest!J23 -> CLOSED | M25: =CPUE!J23 -> CLOSED | N25: =Effort!L23 -> 1772.1089 | O25: =Harvest!L23 -> 25695.579 | P25: =CPUE!L23 -> 14.5 | Q25: CLOSED | R25: CLOSED | S25: CLOSED | T25: =SUM(E25,H25,K25,N25) -> 5201.045 | U25: =SUM(F25,I25,L25,O25) -> 76577.17
A26: 45970 | B26: Sun | C26: -0.9 | D26: 0.88819444 | E26: =Effort!F24 -> 392.30132 | F26: =Harvest!F24 -> 4119.1639 | G26: =+CPUE!F24 -> 10.5 | H26: =Effort!H24 -> 242.90978 | I26: =Harvest!H24 -> 2550.5527 | J26: =CPUE!H24 -> 10.5 | K26: =Effort!J24 -> 540.25068 | L26: =Harvest!J24 -> 5778.3333 | M26: =CPUE!J24 -> 10.695652 | N26: =Effort!L24 -> CLOSED | O26: =Harvest!L24 -> CLOSED | P26: =CPUE!L24 -> CLOSED | Q26: CLOSED | R26: CLOSED | S26: CLOSED | T26: =SUM(E26,H26,K26,N26) -> 1175.4618 | U26: =SUM(F26,I26,L26,O26) -> 12448.05
A27: Tide Series Totals | E27: =SUM(E20:E26) -> 4890.9774 | F27: =SUM(F20:F26) -> 58936.454 | G27: =+F27/E27 -> 12.050036 | H27: =SUM(H20:H26) -> 6497.4871 | I27: =SUM(I20:I26) -> 87217.403 | J27: =+I27/H27 -> 13.423251 | K27: =SUM(K20:K26) -> 1618.5196 | L27: =SUM(L20:L26) -> 10830.052 | M27: =+L27/K27 -> 6.6913323 | N27: =SUM(N20:N26) -> 5173.3576 | O27: =SUM(O20:O26) -> 70233.983 | P27: =+O27/N27 -> 13.576093 | T27: =SUM(T20:T26) -> 18180.342 | U27: =SUM(U20:U26) -> 227217.89 | W27: =SUM(H27,K27,N27,Q27,E27) -> 18180.342 | X27: =SUM(R27,O27,L27,I27,F27) -> 227217.89
A28: 45979 | B28: Tue | C28: -0.02 | D28: 0.72083333 | E28: =Effort!F26 -> 393.78813 | F28: =Harvest!F26 -> 5906.8219 | G28: =+CPUE!F26 -> 15 | H28: =Effort!H26 -> 721.06624 | I28: =Harvest!H26 -> 10815.994 | J28: =CPUE!H26 -> 15 | K28: =Effort!J26 -> 829.8582 | L28: =Harvest!J26 -> 12349.08 | M28: =CPUE!J26 -> 14.880952 | N28: =Effort!L26 -> CLOSED | O28: =Harvest!L26 -> CLOSED | P28: =CPUE!L26 -> CLOSED | Q28: CLOSED | R28: CLOSED | S28: CLOSED | T28: =SUM(E28,H28,K28,N28) -> 1944.7126 | U28: =SUM(F28,I28,L28,O28) -> 29071.896
A29: 45980 | B29: Wed | C29: -0.3 | D29: 0.74444444 | E29: =Effort!F27 -> 864.90531 | F29: =Harvest!F27 -> 11935.693 | G29: =+CPUE!F27 -> 13.8 | H29: =Effort!H27 -> 648.04469 | I29: =Harvest!H27 -> 9720.6704 | J29: =CPUE!H27 -> 15 | K29: =Effort!J27 -> CLOSED | L29: =Harvest!J27 -> CLOSED | M29: =CPUE!J27 -> CLOSED | N29: =Effort!L27 -> 319.48882 | O29: =Harvest!L27 -> 3194.8882 | P29: =CPUE!L27 -> 10 | Q29: CLOSED | R29: CLOSED | S29: CLOSED | T29: =SUM(E29,H29,K29,N29) -> 1832.4388 | U29: =SUM(F29,I29,L29,O29) -> 24851.252
