Workbook

Sheet Observations
A1: Ingress-Egress Datasheet Transcription - Tidy Observations
A2: Source File | B2: PDF Page | C2: Datasheet ID | D2: Beach | E2: Access Point | F2: Date | G2: Sampler | H2: Row Number | I2: Row Type | J2: Time Start | K2: Time End | L2: Relative Start | M2: Relative End | N2: Cars On Raw | O2: Cars On | P2: Cars Off Raw | Q2: Cars Off | R2: Entry Status | S2: Transcription Note | T2: Cumulative Cars On | U2: Cumulative Cars Off | V2: Calculated Vehicles in Area
A3: 2022-2026-Copalis-Mocrocks.pdf | B3: 1 | C3: P01 | D3: Copalis Beach | E3: Ocean City North | F3: 44653 | G3: Bryce | H3: 1 | I3: Prior to Start | J3: Prior to Start | N3: 0 | O3: 0 | P3: 0 | Q3: 0 | R3: Observed | T3: =IF(R3<>"Observed","",SUMIFS($O$3:O3,$C$3:C3,C3,$R$3:R3,"Observed")) -> 0 | U3: =IF(R3<>"Observed","",SUMIFS($Q$3:Q3,$C$3:C3,C3,$R$3:R3,"Observed")) -> 0 | V3: =IF(R3<>"Observed","",T3-U3) -> 0
A4: 2022-2026-Copalis-Mocrocks.pdf | B4: 1 | C4: P01 | D4: Copalis Beach | E4: Ocean City North | F4: 44653 | G4: Bryce | H4: 2 | I4: 15-minute interval | J4: 0507 | K4: 0522 | L4: 3:00 | M4: 2:45 | N4: 3 | O4: 3 | P4: 0 | Q4: 0 | R4: Observed | T4: =IF(R4<>"Observed","",SUMIFS($O$3:O4,$C$3:C4,C4,$R$3:R4,"Observed")) -> 3 | U4: =IF(R4<>"Observed","",SUMIFS($Q$3:Q4,$C$3:C4,C4,$R$3:R4,"Observed")) -> 0 | V4: =IF(R4<>"Observed","",T4-U4) -> 3
A5: 2022-2026-Copalis-Mocrocks.pdf | B5: 1 | C5: P01 | D5: Copalis Beach | E5: Ocean City North | F5: 44653 | G5: Bryce | H5: 3 | I5: 15-minute interval | J5: 0522 | K5: 0537 | L5: 2:45 | M5: 2:30 | N5: 4 | O5: 4 | P5: 0 | Q5: 0 | R5: Observed | T5: =IF(R5<>"Observed","",SUMIFS($O$3:O5,$C$3:C5,C5,$R$3:R5,"Observed")) -> 7 | U5: =IF(R5<>"Observed","",SUMIFS($Q$3:Q5,$C$3:C5,C5,$R$3:R5,"Observed")) -> 0 | V5: =IF(R5<>"Observed","",T5-U5) -> 7
A6: 2022-2026-Copalis-Mocrocks.pdf | B6: 1 | C6: P01 | D6: Copalis Beach | E6: Ocean City North | F6: 44653 | G6: Bryce | H6: 4 | I6: 15-minute interval | J6: 0537 | K6: 0552 | L6: 2:30 | M6: 2:15 | N6: 15 | O6: 15 | P6: 0 | Q6: 0 | R6: Observed | T6: =IF(R6<>"Observed","",SUMIFS($O$3:O6,$C$3:C6,C6,$R$3:R6,"Observed")) -> 22 | U6: =IF(R6<>"Observed","",SUMIFS($Q$3:Q6,$C$3:C6,C6,$R$3:R6,"Observed")) -> 0 | V6: =IF(R6<>"Observed","",T6-U6) -> 22
A7: 2022-2026-Copalis-Mocrocks.pdf | B7: 1 | C7: P01 | D7: Copalis Beach | E7: Ocean City North | F7: 44653 | G7: Bryce | H7: 5 | I7: 15-minute interval | J7: 0552 | K7: 0607 | L7: 2:15 | M7: 2:00 | N7: 10 | O7: 10 | P7: 1 | Q7: 1 | R7: Observed | T7: =IF(R7<>"Observed","",SUMIFS($O$3:O7,$C$3:C7,C7,$R$3:R7,"Observed")) -> 32 | U7: =IF(R7<>"Observed","",SUMIFS($Q$3:Q7,$C$3:C7,C7,$R$3:R7,"Observed")) -> 1 | V7: =IF(R7<>"Observed","",T7-U7) -> 31
A8: 2022-2026-Copalis-Mocrocks.pdf | B8: 1 | C8: P01 | D8: Copalis Beach | E8: Ocean City North | F8: 44653 | G8: Bryce | H8: 6 | I8: 15-minute interval | J8: 0607 | K8: 0622 | L8: 2:00 | M8: 1:45 | N8: 26 | O8: 26 | P8: 1 | Q8: 1 | R8: Observed | T8: =IF(R8<>"Observed","",SUMIFS($O$3:O8,$C$3:C8,C8,$R$3:R8,"Observed")) -> 58 | U8: =IF(R8<>"Observed","",SUMIFS($Q$3:Q8,$C$3:C8,C8,$R$3:R8,"Observed")) -> 2 | V8: =IF(R8<>"Observed","",T8-U8) -> 56
A9: 2022-2026-Copalis-Mocrocks.pdf | B9: 1 | C9: P01 | D9: Copalis Beach | E9: Ocean City North | F9: 44653 | G9: Bryce | H9: 7 | I9: 15-minute interval | J9: 0622 | K9: 0637 | L9: 1:45 | M9: 1:30 | N9: 51 | O9: 51 | P9: 0 | Q9: 0 | R9: Observed | T9: =IF(R9<>"Observed","",SUMIFS($O$3:O9,$C$3:C9,C9,$R$3:R9,"Observed")) -> 109 | U9: =IF(R9<>"Observed","",SUMIFS($Q$3:Q9,$C$3:C9,C9,$R$3:R9,"Observed")) -> 2 | V9: =IF(R9<>"Observed","",T9-U9) -> 107
A10: 2022-2026-Copalis-Mocrocks.pdf | B10: 1 | C10: P01 | D10: Copalis Beach | E10: Ocean City North | F10: 44653 | G10: Bryce | H10: 8 | I10: 15-minute interval | J10: 0637 | K10: 0652 | L10: 1:30 | M10: 1:15 | N10: 59 | O10: 59 | P10: 3 | Q10: 3 | R10: Observed | T10: =IF(R10<>"Observed","",SUMIFS($O$3:O10,$C$3:C10,C10,$R$3:R10,"Observed")) -> 168 | U10: =IF(R10<>"Observed","",SUMIFS($Q$3:Q10,$C$3:C10,C10,$R$3:R10,"Observed")) -> 5 | V10: =IF(R10<>"Observed","",T10-U10) -> 163
A11: 2022-2026-Copalis-Mocrocks.pdf | B11: 1 | C11: P01 | D11: Copalis Beach | E11: Ocean City North | F11: 44653 | G11: Bryce | H11: 9 | I11: 15-minute interval | J11: 0652 | K11: 0707 | L11: 1:15 | M11: 1:00 | N11: 74 | O11: 74 | P11: 4 | Q11: 4 | R11: Observed | T11: =IF(R11<>"Observed","",SUMIFS($O$3:O11,$C$3:C11,C11,$R$3:R11,"Observed")) -> 242 | U11: =IF(R11<>"Observed","",SUMIFS($Q$3:Q11,$C$3:C11,C11,$R$3:R11,"Observed")) -> 9 | V11: =IF(R11<>"Observed","",T11-U11) -> 233
A12: 2022-2026-Copalis-Mocrocks.pdf | B12: 1 | C12: P01 | D12: Copalis Beach | E12: Ocean City North | F12: 44653 | G12: Bryce | H12: 10 | I12: 15-minute interval | J12: 0707 | K12: 0722 | L12: 1:00 | M12: 0:45 | N12: 64 | O12: 64 | P12: 17 | Q12: 17 | R12: Observed | T12: =IF(R12<>"Observed","",SUMIFS($O$3:O12,$C$3:C12,C12,$R$3:R12,"Observed")) -> 306 | U12: =IF(R12<>"Observed","",SUMIFS($Q$3:Q12,$C$3:C12,C12,$R$3:R12,"Observed")) -> 26 | V12: =IF(R12<>"Observed","",T12-U12) -> 280
A13: 2022-2026-Copalis-Mocrocks.pdf | B13: 1 | C13: P01 | D13: Copalis Beach | E13: Ocean City North | F13: 44653 | G13: Bryce | H13: 11 | I13: 15-minute interval | J13: 0722 | K13: 0737 | L13: 0:45 | M13: 0:30 | N13: 47 | O13: 47 | P13: 34 | Q13: 34 | R13: Observed | T13: =IF(R13<>"Observed","",SUMIFS($O$3:O13,$C$3:C13,C13,$R$3:R13,"Observed")) -> 353 | U13: =IF(R13<>"Observed","",SUMIFS($Q$3:Q13,$C$3:C13,C13,$R$3:R13,"Observed")) -> 60 | V13: =IF(R13<>"Observed","",T13-U13) -> 293
A14: 2022-2026-Copalis-Mocrocks.pdf | B14: 1 | C14: P01 | D14: Copalis Beach | E14: Ocean City North | F14: 44653 | G14: Bryce | H14: 12 | I14: 15-minute interval | J14: 0737 | K14: 0752 | L14: 0:30 | M14: 0:15 | N14: 18 | O14: 18 | P14: 37 | Q14: 37 | R14: Observed | T14: =IF(R14<>"Observed","",SUMIFS($O$3:O14,$C$3:C14,C14,$R$3:R14,"Observed")) -> 371 | U14: =IF(R14<>"Observed","",SUMIFS($Q$3:Q14,$C$3:C14,C14,$R$3:R14,"Observed")) -> 97 | V14: =IF(R14<>"Observed","",T14-U14) -> 274
A15: 2022-2026-Copalis-Mocrocks.pdf | B15: 1 | C15: P01 | D15: Copalis Beach | E15: Ocean City North | F15: 44653 | G15: Bryce | H15: 13 | I15: 15-minute interval | J15: 0752 | K15: 0807 | L15: 0:15 | M15: 0:00 | N15: 14 | O15: 14 | P15: 49 | Q15: 49 | R15: Observed | T15: =IF(R15<>"Observed","",SUMIFS($O$3:O15,$C$3:C15,C15,$R$3:R15,"Observed")) -> 385 | U15: =IF(R15<>"Observed","",SUMIFS($Q$3:Q15,$C$3:C15,C15,$R$3:R15,"Observed")) -> 146 | V15: =IF(R15<>"Observed","",T15-U15) -> 239
... A19: 2022-2026-Copalis-Mocrocks.pdf | B19: 1 | C19: P01 | D19: Copalis Beach | E19: Ocean City North | F19: 44653 | G19: Bryce | H19: 17 | I19: 15-minute interval | J19: 0852 | K19: 0907 | L19: 0:45 | M19: 1:00 | N19: 7 | O19: 7 | P19: 21 | Q19: 21 | R19: Observed | T19: =IF(R19<>"Observed","",SUMIFS($O$3:O19,$C$3:C19,C19,$R$3:R19,"Observed")) -> 426 | U19: =IF(R19<>"Observed","",SUMIFS($Q$3:Q19,$C$3:C19,C19,$R$3:R19,"Observed")) -> 301 | V19: =IF(R19<>"Observed","",T19-U19) -> 125
A20: 2022-2026-Copalis-Mocrocks.pdf | B20: 2 | C20: P02 | D20: Mocrocks | E20: Roosevelt App. South | F20: 44654 | G20: Clayton | H20: 1 | I20: Prior to Start | J20: Prior to Start | N20: 2 | O20: 2 | Q20: 0 | R20: Observed | S20: Cars Off source cell blank; treated as 0. | T20: =IF(R20<>"Observed","",SUMIFS($O$3:O20,$C$3:C20,C20,$R$3:R20,"Observed")) -> 2 | U20: =IF(R20<>"Observed","",SUMIFS($Q$3:Q20,$C$3:C20,C20,$R$3:R20,"Observed")) -> 0 | V20: =IF(R20<>"Observed","",T20-U20) -> 2
A21: 2022-2026-Copalis-Mocrocks.pdf | B21: 2 | C21: P02 | D21: Mocrocks | E21: Roosevelt App. South | F21: 44654 | G21: Clayton | H21: 2 | I21: 15-minute interval | J21: 0545 | K21: 0600 | L21: 3:00 | M21: 2:45 | N21: 0 | O21: 0 | P21: 0 | Q21: 0 | R21: Observed | S21: Dashes interpreted as 0. | T21: =IF(R21<>"Observed","",SUMIFS($O$3:O21,$C$3:C21,C21,$R$3:R21,"Observed")) -> 2 | U21: =IF(R21<>"Observed","",SUMIFS($Q$3:Q21,$C$3:C21,C21,$R$3:R21,"Observed")) -> 0 | V21: =IF(R21<>"Observed","",T21-U21) -> 2
A22: 2022-2026-Copalis-Mocrocks.pdf | B22: 2 | C22: P02 | D22: Mocrocks | E22: Roosevelt App. South | F22: 44654 | G22: Clayton | H22: 3 | I22: 15-minute interval | J22: 0600 | K22: 0615 | L22: 2:45 | M22: 2:30 | N22: 1 | O22: 1 | P22: 0 | Q22: 0 | R22: Observed | T22: =IF(R22<>"Observed","",SUMIFS($O$3:O22,$C$3:C22,C22,$R$3:R22,"Observed")) -> 3 | U22: =IF(R22<>"Observed","",SUMIFS($Q$3:Q22,$C$3:C22,C22,$R$3:R22,"Observed")) -> 0 | V22: =IF(R22<>"Observed","",T22-U22) -> 3
A23: 2022-2026-Copalis-Mocrocks.pdf | B23: 2 | C23: P02 | D23: Mocrocks | E23: Roosevelt App. South | F23: 44654 | G23: Clayton | H23: 4 | I23: 15-minute interval | J23: 0615 | K23: 0630 | L23: 2:30 | M23: 2:15 | N23: 6 | O23: 6 | P23: 0 | Q23: 0 | R23: Observed | T23: =IF(R23<>"Observed","",SUMIFS($O$3:O23,$C$3:C23,C23,$R$3:R23,"Observed")) -> 9 | U23: =IF(R23<>"Observed","",SUMIFS($Q$3:Q23,$C$3:C23,C23,$R$3:R23,"Observed")) -> 0 | V23: =IF(R23<>"Observed","",T23-U23) -> 9
A24: 2022-2026-Copalis-Mocrocks.pdf | B24: 2 | C24: P02 | D24: Mocrocks | E24: Roosevelt App. South | F24: 44654 | G24: Clayton | H24: 5 | I24: 15-minute interval | J24: 0630 | K24: 0645 | L24: 2:15 | M24: 2:00 | N24: 15 | O24: 15 | P24: 1 | Q24: 1 | R24: Observed | T24: =IF(R24<>"Observed","",SUMIFS($O$3:O24,$C$3:C24,C24,$R$3:R24,"Observed")) -> 24 | U24: =IF(R24<>"Observed","",SUMIFS($Q$3:Q24,$C$3:C24,C24,$R$3:R24,"Observed")) -> 1 | V24: =IF(R24<>"Observed","",T24-U24) -> 23
A25: 2022-2026-Copalis-Mocrocks.pdf | B25: 2 | C25: P02 | D25: Mocrocks | E25: Roosevelt App. South | F25: 44654 | G25: Clayton | H25: 6 | I25: 15-minute interval | J25: 0645 | K25: 0700 | L25: 2:00 | M25: 1:45 | N25: 25 | O25: 25 | P25: 0 | Q25: 0 | R25: Observed | T25: =IF(R25<>"Observed","",SUMIFS($O$3:O25,$C$3:C25,C25,$R$3:R25,"Observed")) -> 49 | U25: =IF(R25<>"Observed","",SUMIFS($Q$3:Q25,$C$3:C25,C25,$R$3:R25,"Observed")) -> 1 | V25: =IF(R25<>"Observed","",T25-U25) -> 48
A26: 2022-2026-Copalis-Mocrocks.pdf | B26: 2 | C26: P02 | D26: Mocrocks | E26: Roosevelt App. South | F26: 44654 | G26: Clayton | H26: 7 | I26: 15-minute interval | J26: 0700 | K26: 0715 | L26: 1:45 | M26: 1:30 | N26: 31 | O26: 31 | P26: 0 | Q26: 0 | R26: Observed | T26: =IF(R26<>"Observed","",SUMIFS($O$3:O26,$C$3:C26,C26,$R$3:R26,"Observed")) -> 80 | U26: =IF(R26<>"Observed","",SUMIFS($Q$3:Q26,$C$3:C26,C26,$R$3:R26,"Observed")) -> 1 | V26: =IF(R26<>"Observed","",T26-U26) -> 79
A27: 2022-2026-Copalis-Mocrocks.pdf | B27: 2 | C27: P02 | D27: Mocrocks | E27: Roosevelt App. South | F27: 44654 | G27: Clayton | H27: 8 | I27: 15-minute interval | J27: 0715 | K27: 0730 | L27: 1:30 | M27: 1:15 | N27: 38 | O27: 38 | P27: 1 | Q27: 1 | R27: Observed | T27: =IF(R27<>"Observed","",SUMIFS($O$3:O27,$C$3:C27,C27,$R$3:R27,"Observed")) -> 118 | U27: =IF(R27<>"Observed","",SUMIFS($Q$3:Q27,$C$3:C27,C27,$R$3:R27,"Observed")) -> 2 | V27: =IF(R27<>"Observed","",T27-U27) -> 116
A28: 2022-2026-Copalis-Mocrocks.pdf | B28: 2 | C28: P02 | D28: Mocrocks | E28: Roosevelt App. South | F28: 44654 | G28: Clayton | H28: 9 | I28: 15-minute interval | J28: 0730 | K28: 0745 | L28: 1:15 | M28: 1:00 | N28: 27 | O28: 27 | P28: 8 | Q28: 8 | R28: Observed | T28: =IF(R28<>"Observed","",SUMIFS($O$3:O28,$C$3:C28,C28,$R$3:R28,"Observed")) -> 145 | U28: =IF(R28<>"Observed","",SUMIFS($Q$3:Q28,$C$3:C28,C28,$R$3:R28,"Observed")) -> 10 | V28: =IF(R28<>"Observed","",T28-U28) -> 135
A29: 2022-2026-Copalis-Mocrocks.pdf | B29: 2 | C29: P02 | D29: Mocrocks | E29: Roosevelt App. South | F29: 44654 | G29: Clayton | H29: 10 | I29: 15-minute interval | J29: 0745 | K29: 0800 | L29: 1:00 | M29: 0:45 | N29: 28 | O29: 28 | P29: 10 | Q29: 10 | R29: Observed | T29: =IF(R29<>"Observed","",SUMIFS($O$3:O29,$C$3:C29,C29,$R$3:R29,"Observed")) -> 173 | U29: =IF(R29<>"Observed","",SUMIFS($Q$3:Q29,$C$3:C29,C29,$R$3:R29,"Observed")) -> 20 | V29: =IF(R29<>"Observed","",T29-U29) -> 153
A30: 2022-2026-Copalis-Mocrocks.pdf | B30: 2 | C30: P02 | D30: Mocrocks | E30: Roosevelt App. South | F30: 44654 | G30: Clayton | H30: 11 | I30: 15-minute interval | J30: 0800 | K30: 0815 | L30: 0:45 | M30: 0:30 | N30: 23 | O30: 23 | P30: 19 | Q30: 19 | R30: Observed | T30: =IF(R30<>"Observed","",SUMIFS($O$3:O30,$C$3:C30,C30,$R$3:R30,"Observed")) -> 196 | U30: =IF(R30<>"Observed","",SUMIFS($Q$3:Q30,$C$3:C30,C30,$R$3:R30,"Observed")) -> 39 | V30: =IF(R30<>"Observed","",T30-U30) -> 157
A31: 2022-2026-Copalis-Mocrocks.pdf | B31: 2 | C31: P02 | D31: Mocrocks | E31: Roosevelt App. South | F31: 44654 | G31: Clayton | H31: 12 | I31: 15-minute interval | J31: 0815 | K31: 0830 | L31: 0:30 | M31: 0:15 | N31: 20 | O31: 20 | P31: 22 | Q31: 22 | R31: Observed | T31: =IF(R31<>"Observed","",SUMIFS($O$3:O31,$C$3:C31,C31,$R$3:R31,"Observed")) -> 216 | U31: =IF(R31<>"Observed","",SUMIFS($Q$3:Q31,$C$3:C31,C31,$R$3:R31,"Observed")) -> 61 | V31: =IF(R31<>"Observed","",T31-U31) -> 155
A32: 2022-2026-Copalis-Mocrocks.pdf | B32: 2 | C32: P02 | D32: Mocrocks | E32: Roosevelt App. South | F32: 44654 | G32: Clayton | H32: 13 | I32: 15-minute interval | J32: 0830 | K32: 0845 | L32: 0:15 | M32: 0:00 | N32: 6 | O32: 6 | P32: 17 | Q32: 17 | R32: Observed | T32: =IF(R32<>"Observed","",SUMIFS($O$3:O32,$C$3:C32,C32,$R$3:R32,"Observed")) -> 222 | U32: =IF(R32<>"Observed","",SUMIFS($Q$3:Q32,$C$3:C32,C32,$R$3:R32,"Observed")) -> 78 | V32: =IF(R32<>"Observed","",T32-U32) -> 144
A33: 2022-2026-Copalis-Mocrocks.pdf | B33: 2 | C33: P02 | D33: Mocrocks | E33: Roosevelt App. South | F33: 44654 | G33: Clayton | H33: 14 | I33: 15-minute interval | J33: 0845 | K33: 0900 | L33: 0:00 | M33: 0:15 | N33: 5 | O33: 5 | P33: 34 | Q33: 34 | R33: Observed | T33: =IF(R33<>"Observed","",SUMIFS($O$3:O33,$C$3:C33,C33,$R$3:R33,"Observed")) -> 227 | U33: =IF(R33<>"Observed","",SUMIFS($Q$3:Q33,$C$3:C33,C33,$R$3:R33,"Observed")) -> 112 | V33: =IF(R33<>"Observed","",T33-U33) -> 115
... A36: 2022-2026-Copalis-Mocrocks.pdf | B36: 2 | C36: P02 | D36: Mocrocks | E36: Roosevelt App. South | F36: 44654 | G36: Clayton | H36: 17 | I36: 15-minute interval | J36: 0930 | K36: 0945 | L36: 0:45 | M36: 1:00 | N36: 0 | O36: 0 | P36: 21 | Q36: 21 | R36: Observed | T36: =IF(R36<>"Observed","",SUMIFS($O$3:O36,$C$3:C36,C36,$R$3:R36,"Observed")) -> 239 | U36: =IF(R36<>"Observed","",SUMIFS($Q$3:Q36,$C$3:C36,C36,$R$3:R36,"Observed")) -> 198 | V36: =IF(R36<>"Observed","",T36-U36) -> 41
A37: 2022-2026-Copalis-Mocrocks.pdf | B37: 3 | C37: P03 | D37: Copalis Beach | E37: Ocean City North | F37: 45040 | G37: Bryce | H37: 1 | I37: Prior to Start | J37: Prior to Start | N37: 3 | O37: 3 | Q37: 0 | R37: Observed | S37: Cars Off source cell blank; treated as 0. | T37: =IF(R37<>"Observed","",SUMIFS($O$3:O37,$C$3:C37,C37,$R$3:R37,"Observed")) -> 3 | U37: =IF(R37<>"Observed","",SUMIFS($Q$3:Q37,$C$3:C37,C37,$R$3:R37,"Observed")) -> 0 | V37: =IF(R37<>"Observed","",T37-U37) -> 3
A38: 2022-2026-Copalis-Mocrocks.pdf | B38: 3 | C38: P03 | D38: Copalis Beach | E38: Ocean City North | F38: 45040 | G38: Bryce | H38: 2 | I38: 15-minute interval | J38: 0714 | K38: 0729 | L38: 3:00 | M38: 2:45 | N38: 5 | O38: 5 | Q38: 0 | R38: Observed | S38: Cars Off source cell blank; treated as 0. | T38: =IF(R38<>"Observed","",SUMIFS($O$3:O38,$C$3:C38,C38,$R$3:R38,"Observed")) -> 8 | U38: =IF(R38<>"Observed","",SUMIFS($Q$3:Q38,$C$3:C38,C38,$R$3:R38,"Observed")) -> 0 | V38: =IF(R38<>"Observed","",T38-U38) -> 8
A39: 2022-2026-Copalis-Mocrocks.pdf | B39: 3 | C39: P03 | D39: Copalis Beach | E39: Ocean City North | F39: 45040 | G39: Bryce | H39: 3 | I39: 15-minute interval | J39: 0729 | K39: 0744 | L39: 2:45 | M39: 2:30 | N39: 4 | O39: 4 | Q39: 0 | R39: Observed | S39: Cars Off source cell blank; treated as 0. | T39: =IF(R39<>"Observed","",SUMIFS($O$3:O39,$C$3:C39,C39,$R$3:R39,"Observed")) -> 12 | U39: =IF(R39<>"Observed","",SUMIFS($Q$3:Q39,$C$3:C39,C39,$R$3:R39,"Observed")) -> 0 | V39: =IF(R39<>"Observed","",T39-U39) -> 12
A40: 2022-2026-Copalis-Mocrocks.pdf | B40: 3 | C40: P03 | D40: Copalis Beach | E40: Ocean City North | F40: 45040 | G40: Bryce | H40: 4 | I40: 15-minute interval | J40: 0744 | K40: 0759 | L40: 2:30 | M40: 2:15 | N40: 6 | O40: 6 | Q40: 0 | R40: Observed | S40: Cars Off source cell blank; treated as 0. | T40: =IF(R40<>"Observed","",SUMIFS($O$3:O40,$C$3:C40,C40,$R$3:R40,"Observed")) -> 18 | U40: =IF(R40<>"Observed","",SUMIFS($Q$3:Q40,$C$3:C40,C40,$R$3:R40,"Observed")) -> 0 | V40: =IF(R40<>"Observed","",T40-U40) -> 18
A41: 2022-2026-Copalis-Mocrocks.pdf | B41: 3 | C41: P03 | D41: Copalis Beach | E41: Ocean City North | F41: 45040 | G41: Bryce | H41: 5 | I41: 15-minute interval | J41: 0759 | K41: 0814 | L41: 2:15 | M41: 2:00 | N41: 22 | O41: 22 | Q41: 0 | R41: Observed | S41: Cars Off source cell blank; treated as 0. | T41: =IF(R41<>"Observed","",SUMIFS($O$3:O41,$C$3:C41,C41,$R$3:R41,"Observed")) -> 40 | U41: =IF(R41<>"Observed","",SUMIFS($Q$3:Q41,$C$3:C41,C41,$R$3:R41,"Observed")) -> 0 | V41: =IF(R41<>"Observed","",T41-U41) -> 40
A42: 2022-2026-Copalis-Mocrocks.pdf | B42: 3 | C42: P03 | D42: Copalis Beach | E42: Ocean City North | F42: 45040 | G42: Bryce | H42: 6 | I42: 15-minute interval | J42: 0814 | K42: 0829 | L42: 2:00 | M42: 1:45 | N42: 39 | O42: 39 | P42: 1 | Q42: 1 | R42: Observed | T42: =IF(R42<>"Observed","",SUMIFS($O$3:O42,$C$3:C42,C42,$R$3:R42,"Observed")) -> 79 | U42: =IF(R42<>"Observed","",SUMIFS($Q$3:Q42,$C$3:C42,C42,$R$3:R42,"Observed")) -> 1 | V42: =IF(R42<>"Observed","",T42-U42) -> 78
A43: 2022-2026-Copalis-Mocrocks.pdf | B43: 3 | C43: P03 | D43: Copalis Beach | E43: Ocean City North | F43: 45040 | G43: Bryce | H43: 7 | I43: 15-minute interval | J43: 0829 | K43: 0844 | L43: 1:45 | M43: 1:30 | N43: 35 | O43: 35 | P43: 0 | Q43: 0 | R43: Observed | T43: =IF(R43<>"Observed","",SUMIFS($O$3:O43,$C$3:C43,C43,$R$3:R43,"Observed")) -> 114 | U43: =IF(R43<>"Observed","",SUMIFS($Q$3:Q43,$C$3:C43,C43,$R$3:R43,"Observed")) -> 1 | V43: =IF(R43<>"Observed","",T43-U43) -> 113
A44: 2022-2026-Copalis-Mocrocks.pdf | B44: 3 | C44: P03 | D44: Copalis Beach | E44: Ocean City North | F44: 45040 | G44: Bryce | H44: 8 | I44: 15-minute interval | J44: 0844 | K44: 0859 | L44: 1:30 | M44: 1:15 | N44: 25 | O44: 25 | P44: 2 | Q44: 2 | R44: Observed | T44: =IF(R44<>"Observed","",SUMIFS($O$3:O44,$C$3:C44,C44,$R$3:R44,"Observed")) -> 139 | U44: =IF(R44<>"Observed","",SUMIFS($Q$3:Q44,$C$3:C44,C44,$R$3:R44,"Observed")) -> 3 | V44: =IF(R44<>"Observed","",T44-U44) -> 136
A45: 2022-2026-Copalis-Mocrocks.pdf | B45: 3 | C45: P03 | D45: Copalis Beach | E45: Ocean City North | F45: 45040 | G45: Bryce | H45: 9 | I45: 15-minute interval | J45: 0859 | K45: 0914 | L45: 1:15 | M45: 1:00 | N45: 23 | O45: 23 | P45: 2 | Q45: 2 | R45: Observed | T45: =IF(R45<>"Observed","",SUMIFS($O$3:O45,$C$3:C45,C45,$R$3:R45,"Observed")) -> 162 | U45: =IF(R45<>"Observed","",SUMIFS($Q$3:Q45,$C$3:C45,C45,$R$3:R45,"Observed")) -> 5 | V45: =IF(R45<>"Observed","",T45-U45) -> 157
...

Sheet Datasheet Metadata
A1: Datasheet Metadata and Balance Check
A2: Source File | B2: PDF Page | C2: Datasheet ID | D2: Beach | E2: Access Point | F2: Date | G2: Sampler | H2: Tide Height | I2: Tide Unit | J2: Tide Time (as written) | K2: Solar Event | L2: Solar Time (as written) | M2: Weather / Wind / Surf | N2: Count Left Raw | O2: Discrepancy Raw | P2: Count Left Interpreted | Q2: Page Notes | R2: Total Cars On | S2: Total Cars Off | T2: Calculated Balance | U2: Calculated Absolute Discrepancy | V2: Review
A3: 2022-2026-Copalis-Mocrocks.pdf | B3: 1 | C3: P01 | D3: Copalis Beach | E3: Ocean City North | F3: 44653 | G3: Bryce | H3: 0 | I3: ft | J3: 8:07 AM | K3: Sunrise | L3: 6:51 AM | N3: 132 | P3: 132 | R3: =SUMIF(Observations!$C:$C,$C3,Observations!$O:$O) -> 426 | S3: =SUMIF(Observations!$C:$C,$C3,Observations!$Q:$Q) -> 301 | T3: =R3-S3 -> 125 | U3: =IF(P3="","",ABS(T3-P3)) -> 7 | V3: =IF(P3="","No reported count",IF(U3=0,"Balance matches","Review difference")) -> Review difference
A4: 2022-2026-Copalis-Mocrocks.pdf | B4: 2 | C4: P02 | D4: Mocrocks | E4: Roosevelt App. South | F4: 44654 | G4: Clayton | H4: -0.1 | I4: ft | J4: 8:45 AM (printed 8:07 AM crossed out) | K4: Sunrise | L4: 6:49 AM | N4: 43 | O4: 2 | P4: 43 | R4: =SUMIF(Observations!$C:$C,$C4,Observations!$O:$O) -> 239 | S4: =SUMIF(Observations!$C:$C,$C4,Observations!$Q:$Q) -> 198 | T4: =R4-S4 -> 41 | U4: =IF(P4="","",ABS(T4-P4)) -> 2 | V4: =IF(P4="","No reported count",IF(U4=0,"Balance matches","Review difference")) -> Review difference
A5: 2022-2026-Copalis-Mocrocks.pdf | B5: 3 | C5: P03 | D5: Copalis Beach | E5: Ocean City North | F5: 45040 | G5: Bryce | H5: -0.4 | I5: ft | J5: 10:14 AM | K5: Sunrise | L5: 6:13 AM | N5: 51 | P5: 51 | Q5: Handwritten page note: "Dan? Hymer (360) 581-9796" (name uncertain). | R5: =SUMIF(Observations!$C:$C,$C5,Observations!$O:$O) -> 212 | S5: =SUMIF(Observations!$C:$C,$C5,Observations!$Q:$Q) -> 171 | T5: =R5-S5 -> 41 | U5: =IF(P5="","",ABS(T5-P5)) -> 10 | V5: =IF(P5="","No reported count",IF(U5=0,"Balance matches","Review difference")) -> Review difference
A6: 2022-2026-Copalis-Mocrocks.pdf | B6: 4 | C6: P04 | D6: Mocrocks | E6: Roosevelt App. South | F6: 45041 | G6: JG | H6: 0.1 | I6: ft | J6: 11:01 AM | K6: Sunrise | L6: 6:11 AM | M6: Sunny, low+ surf, northern wind 0-5 mph. Sunny changed to cloudy at low tide. | N6: 34 | O6: 3 | P6: 34 | Q6: Margin notes: "Plane"; "Few people came up & distracted me. I believe the 3 missing cars belong here." Total Cars On "219" written below table. | R6: =SUMIF(Observations!$C:$C,$C6,Observations!$O:$O) -> 219 | S6: =SUMIF(Observations!$C:$C,$C6,Observations!$Q:$Q) -> 182 | T6: =R6-S6 -> 37 | U6: =IF(P6="","",ABS(T6-P6)) -> 3 | V6: =IF(P6="","No reported count",IF(U6=0,"Balance matches","Review difference")) -> Review difference
A7: 2022-2026-Copalis-Mocrocks.pdf | B7: 5 | C7: P05 | D7: Mocrocks | E7: Roosevelt App. South | F7: 45368 | G7: Chase | H7: 0.9 | I7: ft | J7: 1:23 PM (1323) | K7: Sunrise | L7: 7:23 AM | M7: Overcast, 49°F, 7 mph NW, low+ to moderate surf conditions. | N7: 303 | P7: 303 | Q7: Notes: "@1010" at left; "5 planes @1434" below table. | R7: =SUMIF(Observations!$C:$C,$C7,Observations!$O:$O) -> 663 | S7: =SUMIF(Observations!$C:$C,$C7,Observations!$Q:$Q) -> 445 | T7: =R7-S7 -> 218 | U7: =IF(P7="","",ABS(T7-P7)) -> 85 | V7: =IF(P7="","No reported count",IF(U7=0,"Balance matches","Review difference")) -> Review difference
A8: 2022-2026-Copalis-Mocrocks.pdf | B8: 6 | C8: P06 | D8: Copalis Beach | E8: Ocean City North | F8: 45358 | G8: Chase | H8: -0.5 | I8: ft | J8: 4:15 PM (1615) | K8: Sunset | L8: 6:11 PM | M8: 47°F, high 48°F, low 41°F; mostly sunny, precipitation 0%; humidity 58%; wind 7 mph from south; 3-4 ft surf. | N8: 36 | P8: 36 | R8: =SUMIF(Observations!$C:$C,$C8,Observations!$O:$O) -> 289 | S8: =SUMIF(Observations!$C:$C,$C8,Observations!$Q:$Q) -> 271 | T8: =R8-S8 -> 18 | U8: =IF(P8="","",ABS(T8-P8)) -> 18 | V8: =IF(P8="","No reported count",IF(U8=0,"Balance matches","Review difference")) -> Review difference
A9: 2022-2026-Copalis-Mocrocks.pdf | B9: 7 | C9: P07 | D9: Mocrocks | E9: Roosevelt App. South | F9: 45359 | G9: M. Joseph | H9: -0.8 | I9: ft | J9: 5:00 PM (1700) | K9: Sunset | L9: 6:12 PM | M9: Overcast, moderately low surf, west wind 10-15 knots, about 50°F. | O9: 73 | P9: 73 | Q9: Handwritten note above table appears to read "leave @ 1845" (uncertain). The value 73 was entered on the discrepancy line; interpreted as count of cars left because the count line is blank. | R9: =SUMIF(Observations!$C:$C,$C9,Observations!$O:$O) -> 307 | S9: =SUMIF(Observations!$C:$C,$C9,Observations!$Q:$Q) -> 227 | T9: =R9-S9 -> 80 | U9: =IF(P9="","",ABS(T9-P9)) -> 7 | V9: =IF(P9="","No reported count",IF(U9=0,"Balance matches","Review difference")) -> Review difference
A10: 2022-2026-Copalis-Mocrocks.pdf | B10: 8 | C10: P08 | D10: Copalis Beach | E10: Ocean City North | F10: 45366 | G10: BB/CF | H10: 0.1 | I10: ft | J10: 11:08 AM (1108) | K10: Sunrise | L10: 7:27 AM | N10: 149 | P10: 149 | R10: =SUMIF(Observations!$C:$C,$C10,Observations!$O:$O) -> 375 | S10: =SUMIF(Observations!$C:$C,$C10,Observations!$Q:$Q) -> 246 | T10: =R10-S10 -> 129 | U10: =IF(P10="","",ABS(T10-P10)) -> 20 | V10: =IF(P10="","No reported count",IF(U10=0,"Balance matches","Review difference")) -> Review difference
A11: 2022-2026-Copalis-Mocrocks.pdf | B11: 9 | C11: P09 | D11: Copalis Beach | E11: Ocean City North | F11: 45582 | G11: Clayton | H11: -1.3 | I11: ft | J11: 7:03 PM (1903) | K11: Sunset | L11: 6:24 PM (1824) | N11: 23 | P11: 23 | Q11: Note below table: "@1920". | R11: =SUMIF(Observations!$C:$C,$C11,Observations!$O:$O) -> 291 | S11: =SUMIF(Observations!$C:$C,$C11,Observations!$Q:$Q) -> 266 | T11: =R11-S11 -> 25 | U11: =IF(P11="","",ABS(T11-P11)) -> 2 | V11: =IF(P11="","No reported count",IF(U11=0,"Balance matches","Review difference")) -> Review difference
A12: 2022-2026-Copalis-Mocrocks.pdf | B12: 10 | C12: P10 | D12: Mocrocks Beach | E12: Roosevelt Beach Rd. South | F12: 45597 | G12: Bryce | H12: -0.2 | I12: ft | J12: 7:15 PM (1915) | K12: Sunset | L12: 5:59 PM (1759) | N12: 12 | P12: 12 | R12: =SUMIF(Observations!$C:$C,$C12,Observations!$O:$O) -> 107 | S12: =SUMIF(Observations!$C:$C,$C12,Observations!$Q:$Q) -> 91 | T12: =R12-S12 -> 16 | U12: =IF(P12="","",ABS(T12-P12)) -> 4 | V12: =IF(P12="","No reported count",IF(U12=0,"Balance matches","Review difference")) -> Review difference
A13: 2022-2026-Copalis-Mocrocks.pdf | B13: 11 | C13: P11 | D13: Mocrocks Beach | E13: Roosevelt Beach Rd. South | F13: 45716 | G13: Bryce B. | H13: -0.6 | I13: ft | J13: 6:39 PM (1839) | K13: Sunset | L13: 6:00 PM (1800) | M13: 6 ft W swell, 5 kt E wind, overcast and foggy but still visible. | N13: 14 | P13: 14 | R13: =SUMIF(Observations!$C:$C,$C13,Observations!$O:$O) -> 235 | S13: =SUMIF(Observations!$C:$C,$C13,Observations!$Q:$Q) -> 219 | T13: =R13-S13 -> 16 | U13: =IF(P13="","",ABS(T13-P13)) -> 2 | V13: =IF(P13="","No reported count",IF(U13=0,"Balance matches","Review difference")) -> Review difference
A14: 2022-2026-Copalis-Mocrocks.pdf | B14: 12 | C14: P12 | D14: Copalis Beach | E14: Ocean City North | F14: 45730 | G14: Chase | H14: 0.4 | I14: ft | J14: 7:30 PM (1930) | K14: Sunset | L14: 7:21 PM (1921) | M14: 45°F, partly cloudy with rain; high 47°F, low 39°F; 15 mph SE; surf 4-5 ft, low+ to moderate swell. | N14: 19 | P14: 19 | Q14: Note below table: "@1945-2000". | R14: =SUMIF(Observations!$C:$C,$C14,Observations!$O:$O) -> 59 | S14: =SUMIF(Observations!$C:$C,$C14,Observations!$Q:$Q) -> 44 | T14: =R14-S14 -> 15 | U14: =IF(P14="","",ABS(T14-P14)) -> 4 | V14: =IF(P14="","No reported count",IF(U14=0,"Balance matches","Review difference")) -> Review difference
A15: 2022-2026-Copalis-Mocrocks.pdf | B15: 13 | C15: P13 | D15: Copalis Beach | E15: Ocean City North | F15: 46038 | G15: BB DW | H15: 0 | I15: ft | J15: 5:14 PM (1714) | K15: Sunset | L15: 4:56 PM (1656) | M15: 5 kt E, 4 ft W, clear and sunny. | N15: 28 | P15: 28 | Q15: Two middle interval end times appear malformed on source; normalized to the expected 15-minute sequence. | R15: =SUMIF(Observations!$C:$C,$C15,Observations!$O:$O) -> 186 | S15: =SUMIF(Observations!$C:$C,$C15,Observations!$Q:$Q) -> 164 | T15: =R15-S15 -> 22 | U15: =IF(P15="","",ABS(T15-P15)) -> 6 | V15: =IF(P15="","No reported count",IF(U15=0,"Balance matches","Review difference")) -> Review difference
A16: 2022-2026-Copalis-Mocrocks.pdf | B16: 14 | C16: P14 | D16: Copalis Beach | E16: Ocean City North | F16: 46102 | G16: BB | H16: 0 | I16: ft | J16: 8:43 AM (0843) | K16: Sunrise | L16: 7:15 AM (0715) | M16: 7 ft W, 10-second period swell; 5-10 kt WNW; partly cloudy/sunny. | N16: 129 | P16: 129 | Q16: Notes: "@954" below table; right-margin notation appears to read "342/11" (uncertain). | R16: =SUMIF(Observations!$C:$C,$C16,Observations!$O:$O) -> 368 | S16: =SUMIF(Observations!$C:$C,$C16,Observations!$Q:$Q) -> 241 | T16: =R16-S16 -> 127 | U16: =IF(P16="","",ABS(T16-P16)) -> 2 | V16: =IF(P16="","No reported count",IF(U16=0,"Balance matches","Review difference")) -> Review difference
A17: 2022-2026-Copalis-Mocrocks.pdf | B17: 15 | C17: P15 | D17: Mocrocks Beach | E17: Roosevelt Beach Rd. South | F17: 46145 | G17: Bryce | H17: -0.8 | I17: ft | J17: 8:08 PM (0808) [AM/PM conflicts with 24-hour time and morning intervals] | K17: Sunrise | L17: 5:57 AM (0557) | M17: 5-10 kt NE, 5 ft W, sunny and clear. | N17: 176 | P17: 176 | Q17: Tide time contains a source inconsistency: printed PM, but 24-hour value 0808 and intervals indicate morning. | R17: =SUMIF(Observations!$C:$C,$C17,Observations!$O:$O) -> 327 | S17: =SUMIF(Observations!$C:$C,$C17,Observations!$Q:$Q) -> 156 | T17: =R17-S17 -> 171 | U17: =IF(P17="","",ABS(T17-P17)) -> 5 | V17: =IF(P17="","No reported count",IF(U17=0,"Balance matches","Review difference")) -> Review difference

Sheet Data Dictionary
A1: Transcription Conventions and Review Notes
A3: Field / Topic | B3: Meaning | C3: Convention Used | D3: Review Guidance
A4: Raw count fields | B4: Exactly what appears in the handwritten count cell. | C4: Numbers, blanks, dashes, X marks, and overwritten values are retained as text. | D4: Use these fields when auditing against the PDF.
A5: Parsed count fields | B5: Numeric values used for calculations. | C5: Clear numbers are numeric. Blank cells that clearly represented zero are parsed as 0 and noted. Crossed-out or unobserved rows remain blank. | D5: Filter Entry Status and Transcription Note before analysis.
A6: Entry Status | B6: Whether the interval was usable. | C6: Observed, Not recorded, or Crossed out. | D6: Only Observed rows contribute to calculated totals.
A7: Cumulative columns | B7: Running ingress, egress, and vehicle balance. | C7: Formula-driven and reset by Datasheet ID. | D7: These are calculated fields, not handwritten values.
A8: Calculated discrepancy | B8: Absolute difference between calculated balance and interpreted final count. | C8: Formula-driven in Datasheet Metadata. | D8: A nonzero result may reflect counting error, late start, early stop, or an unrecorded interval.
A9: Page 6 overwrite | B9: Cars On for 1545-1600. | C9: Transcribed as 32 from the visible correction and exact balance check. | D9: Review PDF page 6 if a different interpretation is preferred.
A10: Page 7 final count | B10: The number 73 is written on the discrepancy line while the count line is blank. | C10: Count Left Interpreted is 73; raw fields preserve the original placement. | D10: Review PDF page 7.
A11: Page 13 times | B11: Two printed/handwritten interval end times appear malformed. | C11: Normalized to the expected 15-minute sequence: 1729-1744 and 1744-1759. | D11: Source wording is retained in row notes.
A12: Page 15 tide time | B12: Printed AM/PM conflicts with the 24-hour value and morning intervals. | C12: Tide time is retained exactly as written, with the conflict noted. | D12: Treat the event as 0808 unless source documentation says otherwise.
A13: Source | B13: Original scanned datasheets. | C13: 2022-2026-Copalis-Mocrocks.pdf, pages 1-15. | D13: PDF page number is included on every record.
